[META]
version=2.0
spawnOnBlockType=1,2,3,12
spawnSunlight=True
spawnDarkness=True
spawnWater=False
spawnLava=False
underFill=True
randomRotation=True
dig=True
tree=False
branch=False
needsFoundation=True
rarity=30
collisionPercentage=0
spawnElevationMin=0
spawnElevationMax=128
spawnInBiome=Grassland
[DATA]
-1,-4,0:17.1
-1,-3,0:17.1
-2,-2,0:17.1
-1,-2,0:17.1
-4,-1,0:17.1
-3,-1,0:17.1
-2,-1,0:17.1
-1,-1,0:17.1
0,-1,0:17.1
-3,0,0:17.1
-2,0,0:17.1
-1,0,0:17.1
0,0,0:17.1
1,0,0:17.1
2,0,0:17.1
-2,1,0:17.1
-2,2,0:17.1
-1,-2,1:17.1
-2,-1,1:17.1
-1,-1,1:17.1
0,-1,1:17.1
-3,0,1:17.1
-2,0,1:17.1
-1,0,1:17.1
-2,1,1:17.1
-2,-1,2:17.1
-1,-1,2:17.1
-2,0,2:17.1
-1,0,2:17.1
-3,-1,3:86.1
-2,-1,3:17.1
-1,-1,3:17.1
0,-1,3:17.1
2,-4,4:18
3,-4,4:18
4,-4,4:18
-2,-3,4:17.1
-1,-3,4:18
1,-3,4:18
2,-3,4:17.1
3,-3,4:17.1
4,-3,4:17.1
5,-3,4:18
-2,-2,4:17.1
-1,-2,4:17.1
0,-2,4:91.2
1,-2,4:17.1
2,-2,4:17.1
3,-2,4:18
4,-2,4:18
-3,-1,4:17.1
-2,-1,4:17.1
-1,-1,4:17.1
0,-1,4:17.1
1,-1,4:18
2,-1,4:18
-2,0,4:17.1
-1,0,4:17.1
-1,1,4:17.1
-6,-6,5:18
-5,-6,5:18
-6,-5,5:18
-5,-5,5:17.1
-5,-4,5:17.1
-4,-4,5:17.1
-3,-4,5:18
1,-4,5:18
4,-4,5:18
-5,-3,5:18
-4,-3,5:17.1
-3,-3,5:17.1
-2,-3,5:18
-1,-3,5:18
0,-3,5:18
1,-3,5:18
2,-3,5:91.2
3,-3,5:18
4,-3,5:18
5,-3,5:18
-4,-2,5:17.1
-3,-2,5:17.1
-2,-2,5:18
0,-2,5:18
2,-2,5:18
-4,-1,5:18
-3,-1,5:17.1
-2,-1,5:17.1
-1,-1,5:17.1
0,-1,5:18
1,-1,5:18
-2,0,5:17.1
-1,0,5:17.1
0,0,5:18
1,0,5:17.1
2,0,5:18
-2,1,5:30
-1,1,5:17.1
0,1,5:17.1
1,1,5:17.1
2,1,5:18
-1,2,5:91.0
0,2,5:17.1
0,3,5:17.1
1,3,5:18
0,4,5:17.1
1,4,5:17.1
2,4,5:18
1,5,5:17.1
2,5,5:18
1,6,5:17.1
-5,-5,6:18
-6,-4,6:18
-5,-4,6:18
-4,-4,6:18
-4,-3,6:18
1,-3,6:18
2,-3,6:18
-4,-2,6:18
-3,-2,6:18
-1,-2,6:18
2,-2,6:18
-3,-1,6:91.0
-2,-1,6:17.1
-1,-1,6:17.1
-2,0,6:17.1
-1,0,6:17.1
0,0,6:18
1,0,6:91.3
-2,1,6:17.1
-1,1,6:18
0,1,6:18
1,1,6:18
2,1,6:18
-3,2,6:17.1
-2,2,6:17.1
-1,2,6:17.1
0,2,6:18
1,2,6:18
-4,3,6:17.1
-3,3,6:17.1
-2,3,6:18
-1,3,6:18
0,3,6:18
1,3,6:18
0,4,6:18
1,4,6:18
1,5,6:18
2,5,6:18
1,6,6:18
1,-4,7:18
0,-3,7:18
1,-3,7:17.1
2,-3,7:18
3,-3,7:18
0,-2,7:17.1
1,-2,7:17.1
2,-2,7:18
-3,-1,7:30
-2,-1,7:17.1
-1,-1,7:17.1
0,-1,7:17.1
1,-1,7:18
2,-1,7:18
-2,0,7:17.1
-1,0,7:17.1
1,0,7:18
-2,1,7:18
-4,2,7:18
-3,2,7:18
-2,2,7:18
-1,2,7:18
1,2,7:18
-5,3,7:18
-4,3,7:17.1
-3,3,7:18
-1,3,7:18
-5,4,7:17.1
-4,4,7:17.1
-3,4,7:18
-5,5,7:18
-4,5,7:18
-3,5,7:18
0,-4,8:18
2,-4,8:18
0,-3,8:18
2,-3,8:18
0,-2,8:18
1,-2,8:18
-3,-1,8:17.1
-2,-1,8:17.1
-1,-1,8:17.1
0,-1,8:18
-3,0,8:18
-1,0,8:17.1
0,0,8:18
-2,2,8:18
-4,3,8:18
-4,4,8:18
-4,5,8:18
-2,-1,9:17.1
-1,-1,9:17.1
-1,0,9:17.1
-3,-1,10:18
-2,-1,10:17.1
-1,-1,10:17.1
-4,0,10:18
-3,0,10:18
-2,0,10:17.1
-1,0,10:17.1
0,0,10:18
1,0,10:18
-3,1,10:17.1
-2,1,10:17.1
0,1,10:18
1,1,10:18
2,1,10:18
-4,2,10:18
-3,2,10:17.1
-2,2,10:18
-4,3,10:18
-3,3,10:18
-2,-1,11:17.1
-1,-1,11:17.1
-2,0,11:18
-1,0,11:17.1
0,0,11:18
1,0,11:30
-3,1,11:18
-2,1,11:18
0,1,11:18
-3,2,11:18
-2,-2,12:30
-2,-1,12:17.1
-1,-1,12:17.1
0,-1,12:18
-2,0,12:18
-1,0,12:17.1
0,0,12:17.1
1,0,12:18
-2,1,12:18
-1,1,12:18
0,1,12:17.1
1,1,12:17.1
2,1,12:18
3,1,12:18
-2,2,12:18
0,2,12:18
1,2,12:17.1
2,2,12:18
-2,3,12:18
1,3,12:18
1,-4,13:18
1,-3,13:17.1
-2,-2,13:18
-1,-2,13:18
0,-2,13:91.2
1,-2,13:17.1
2,-2,13:18
-3,-1,13:18
-2,-1,13:17.1
-1,-1,13:17.1
0,-1,13:17.1
1,-1,13:18
-2,0,13:18
0,0,13:30
1,0,13:18
2,0,13:18
-1,1,13:18
0,1,13:18
1,1,13:86.3
1,2,13:18
-1,-3,14:18
0,-3,14:18
1,-3,14:18
-2,-2,14:18
-1,-2,14:18
0,-2,14:18
1,-2,14:18
-3,-1,14:18
-2,-1,14:17.1
-1,-1,14:17.1
0,-1,14:18
-1,0,14:18
-1,1,14:18
-3,-1,15:18
-2,-1,15:17.1
-1,-1,15:18
-3,-2,16:17.1
-4,-1,16:18
-3,-1,16:17.1
-2,-1,16:17.1
-1,-1,16:18
-3,0,16:18
-2,0,16:18
-3,1,16:30
-3,-2,17:18
-3,-1,17:18
-2,-1,17:17.1
-1,-1,17:18
-3,0,17:18
-2,0,17:17.1
-1,0,17:17.1
0,0,17:18
-3,1,17:18
-2,1,17:18
-1,1,17:18
0,1,17:18
-2,2,17:18
-2,-3,18:18
-4,-2,18:18
-3,-2,18:18
-2,-2,18:18
-1,-2,18:18
-3,-1,18:18
-2,-1,18:17.1
-1,-1,18:18
-3,0,18:18
-2,0,18:18
-1,0,18:18
-1,1,18:18
-2,-2,19:18
-2,-1,19:18
-2,-1,20:18
