[META]
version=2.0
spawnOnBlockType=87
spawnSunlight=True
spawnDarkness=True
spawnWater=False
spawnLava=False
underFill=True
randomRotation=True
dig=True
tree=False
branch=False
needsFoundation=True
rarity=15
collisionPercentage=0
spawnElevationMin=0
spawnElevationMax=110
spawnInBiome=Hell
[DATA]
0,0,0:17.0
1,-1,-1:17.0
0,0,-1:17.0
-1,-1,-1:17.0
-1,1,-1:17.0
1,1,-1:17.0
0,0,1:17.0
0,0,2:17.0
-1,0,2:17.0
1,0,2:17.0
2,0,3:17.0
-2,0,3:17.0
-2,-1,3:17.0
0,0,3:17.0
3,0,3:17.0
-3,-1,4:17.0
-2,-2,4:17.0
3,1,4:17.0
2,-1,4:17.0
0,0,4:17.0
0,1,4:17.0
0,2,4:17.0
0,0,5:17.0
0,-1,5:17.0
0,-2,5:17.0
0,3,5:17.0
-2,-3,5:17.0
-2,-2,5:17.0
2,-1,5:17.0
2,-2,5:17.0
3,1,5:17.0
3,2,5:17.0
4,2,5:17.0
0,4,5:17.0
-3,0,5:17.0
-4,0,5:17.0
0,0,6:17.0
0,-3,6:17.0
0,-4,6:17.0
-2,-3,6:17.0
-2,-4,6:17.0
-4,0,6:17.0
-4,-1,6:17.0
2,-2,6:17.0
3,-2,6:17.0
4,2,6:17.0
4,3,6:17.0
0,4,6:17.0
-1,4,6:17.0
-1,5,6:17.0
-3,1,6:17.0
-3,2,6:17.0
0,0,7:17.0
0,-1,7:17.0
-1,-1,7:17.0
0,1,7:17.0
1,1,7:17.0
1,2,7:17.0
-2,-4,7:18.0
-1,5,7:18.0
3,-2,7:18.0
-3,-1,8:17.0
-2,-1,8:17.0
-1,-2,8:17.0
1,2,8:17.0
1,3,8:17.0
0,3,8:17.0
-1,1,8:17.0
-2,1,8:17.0
-2,2,8:17.0
1,-1,8:17.0
2,-1,8:17.0
2,-2,8:17.0
3,-2,8:17.0
-1,-3,8:17.0
0,0,8:17.0
-1,-3,9:17.0
-1,-4,9:17.0
0,-4,9:17.0
-3,-1,9:17.0
-4,-1,9:17.0
-4,0,9:17.0
-2,2,9:17.0
-3,2,9:17.0
-3,3,9:17.0
1,3,9:17.0
2,3,9:17.0
2,4,9:17.0
3,-2,9:17.0
3,-3,9:17.0
0,0,9:17.0
1,-1,9:17.0
1,0,9:17.0
0,0,10:17.0
-4,-1,10:18.0
2,4,10:18.0
3,-3,10:18.0
0,0,11:17.0
0,-1,11:17.0
0,1,11:17.0
1,1,11:17.0
0,-2,11:17.0
1,-2,11:17.0
1,-3,11:17.0
-1,0,11:17.0
-2,0,11:17.0
-2,1,11:17.0
0,0,12:17.0
1,-3,12:18.0
-2,1,12:18.0
