[META]
version=2.0
spawnOnBlockType=87
spawnSunlight=True
spawnDarkness=False
spawnWater=False
spawnLava=False
underFill=True
randomRotation=True
dig=True
tree=False
branch=False
needsFoundation=True
rarity=15
collisionPercentage=0
spawnElevationMin=0
spawnElevationMax=85
spawnInBiome=Hell
[DATA]
0,0,0:17.1
-1,1,0:17.1
-1,-1,0:17.1
1,-1,0:17.1
1,1,0:17.1
0,0,1:17.1
0,0,2:17.1
0,0,3:17.1
0,0,4:17.1
0,-1,4:17.1
0,-2,4:17.1
0,0,5:17.1
0,-2,5:17.1
0,0,6:17.1
0,1,6:17.1
-1,2,6:17.1
0,0,7:17.1
-1,2,7:17.1
0,0,8:17.1
0,0,9:17.1
0,0,10:17.1
-1,-1,10:17.1
1,1,10:17.1
1,-1,10:17.1
2,-2,10:17.1
-2,-2,10:17.1
-1,1,10:17.1
0,0,11:17.1
-1,1,11:17.1
2,-2,11:17.1
2,2,11:17.1
-2,-2,11:17.1
-2,2,11:17.1
-2,2,12:17.1
-2,-2,12:17.1
2,-3,12:17.1
3,2,12:17.1
2,2,12:17.1
2,-2,12:17.1
-1,1,12:17.1
-3,-3,12:17.1
0,0,12:17.1
-3,-3,13:17.1
2,-3,13:17.1
-2,2,13:17.1
3,2,13:17.1
0,0,13:17.1
0,-1,13:17.1
1,0,13:17.1
-2,2,14:17.1
-3,-3,14:17.1
2,-3,14:17.1
3,2,14:17.1
0,0,14:17.1
0,-2,14:17.1
2,0,14:17.1
-3,-3,15:17.1
2,-3,15:17.1
-2,2,15:17.1
3,2,15:17.1
2,0,15:17.1
0,-2,15:17.1
0,0,15:17.1
-2,0,15:17.1
-2,0,16:17.1
0,0,16:17.1
0,-2,16:17.1
2,0,16:17.1
0,0,17:17.1
