[META]
version=2.0
spawnOnBlockType=3,2
spawnSunlight=True
spawnDarkness=True
spawnWater=False
spawnLava=False
underFill=True
randomRotation=True
dig=True
tree=False
branch=False
needsFoundation=True
rarity=250
collisionPercentage=2
spawnElevationMin=0
spawnElevationMax=128
spawnInBiome=Urwald
[DATA]
-1,0,0:17.0
-1,1,0:17.0
0,1,0:17.0
0,0,0:17.0
-2,1,0:31.1
-1,-1,0:31.1
1,0,0:31.1
0,2,0:31.1
1,-1,-1:17.0
1,0,-1:17.0
0,0,-1:17.0
-1,0,-1:17.0
-1,-1,-1:17.0
-2,-1,-1:17.0
-1,1,-1:17.0
-2,1,-1:17.0
-2,2,-1:17.0
0,1,-1:17.0
0,2,-1:17.0
1,2,-1:17.0
-1,0,1:17.0
-1,-1,1:17.0
0,0,1:17.0
1,0,1:17.0
0,1,1:17.0
0,2,1:17.0
-1,1,1:17.0
-2,1,1:17.0
-2,1,2:17.0
-1,-1,2:17.0
1,0,2:17.0
0,2,2:17.0
-1,0,2:31.1
-1,1,2:31.1
0,1,2:31.1
0,0,2:31.1
-1,-1,3:17.0
-1,-2,3:17.0
-2,1,3:17.0
-3,1,3:17.0
0,2,3:17.0
0,3,3:17.0
1,0,3:17.0
2,0,3:17.0
0,3,4:17.0
-3,1,4:17.0
-4,1,4:17.0
0,4,4:17.0
2,0,4:17.0
3,0,4:17.0
-1,-2,4:17.0
-1,-3,4:17.0
-2,1,4:31.1
-1,-1,4:31.1
0,2,4:31.1
1,0,4:31.1
0,4,5:17.0
-4,1,5:17.0
-1,-3,5:17.0
3,0,5:17.0
-2,-3,5:18.1
-1,-4,5:18.1
0,-3,5:18.1
-4,0,5:18.1
-5,1,5:18.1
-4,2,5:18.1
-1,4,5:18.1
0,5,5:18.1
1,4,5:18.1
3,1,5:18.1
4,0,5:18.1
3,-1,5:18.1
2,0,5:18.1
-1,-2,5:18.1
0,3,5:18.1
-3,1,5:18.1
-4,1,6:17.0
-5,1,6:17.0
0,4,6:17.0
-1,-3,6:17.0
-1,-4,6:17.0
3,0,6:17.0
4,0,6:17.0
3,1,6:17.0
2,1,6:17.0
-1,4,6:17.0
-1,3,6:17.0
-2,3,6:17.0
4,-1,6:17.0
5,0,6:17.0
-1,-5,6:17.0
-2,-5,6:17.0
-2,-6,6:17.0
0,-4,6:17.0
1,-4,6:17.0
1,-5,6:17.0
-5,0,6:17.0
-4,2,6:17.0
0,5,6:17.0
0,6,6:17.0
1,6,6:17.0
-6,0,6:17.0
-4,3,6:17.0
-5,3,6:17.0
-3,-6,6:17.0
5,1,6:17.0
3,2,6:17.0
-1,6,6:17.0
-5,4,6:17.0
1,-6,6:106.1
-3,-7,6:106.1
1,5,6:106.1
-1,5,6:106.1
5,-1,6:106.1
-5,2,6:106.1
-5,-1,6:106.1
-1,2,6:106.1
-5,5,6:106.4
0,7,6:106.4
1,-3,6:106.4
4,1,6:106.4
3,3,6:106.4
-6,3,6:106.8
-7,0,6:106.8
1,1,6:106.8
-3,-5,6:106.8
-4,-6,6:106.8
-2,-4,6:106.8
3,-1,6:106.8
2,0,6:106.8
-2,6,6:106.8
-3,3,6:106.8
-6,4,6:106.8
-6,1,6:106.8
-6,0,7:17.0
-5,4,7:17.0
-1,6,7:17.0
1,6,7:17.0
-2,3,7:17.0
2,1,7:17.0
5,1,7:17.0
4,-1,7:17.0
-1,-3,7:17.0
-3,-6,7:17.0
1,-5,7:17.0
-1,-5,7:17.0
-4,1,7:17.0
0,4,7:17.0
-2,-6,7:18.1
-2,-7,7:18.1
-3,-7,7:18.1
-4,-7,7:18.1
-4,-6,7:18.1
-3,-5,7:18.1
-4,-5,7:18.1
0,-5,7:18.1
0,-6,7:18.1
1,-6,7:18.1
2,-6,7:18.1
2,-5,7:18.1
2,-4,7:18.1
1,-4,7:18.1
-2,-3,7:18.1
-2,-2,7:18.1
-1,-2,7:18.1
0,-2,7:18.1
0,-3,7:18.1
-2,-4,7:18.1
2,0,7:18.1
1,0,7:18.1
1,1,7:18.1
1,2,7:18.1
2,2,7:18.1
4,1,7:18.1
4,2,7:18.1
5,2,7:18.1
6,2,7:18.1
6,1,7:18.1
6,0,7:18.1
5,0,7:18.1
5,-1,7:18.1
5,-2,7:18.1
4,-2,7:18.1
3,-2,7:18.1
3,-1,7:18.1
3,1,7:18.1
-5,-1,7:18.1
-6,-1,7:18.1
-7,-1,7:18.1
-7,0,7:18.1
-7,1,7:18.1
-6,1,7:18.1
-6,4,7:18.1
-6,5,7:18.1
-5,5,7:18.1
-4,5,7:18.1
-4,4,7:18.1
-4,0,7:18.1
-3,0,7:18.1
-3,1,7:18.1
-3,3,7:18.1
-2,4,7:18.1
0,3,7:18.1
1,3,7:18.1
1,4,7:18.1
2,6,7:18.1
2,7,7:18.1
1,7,7:18.1
0,6,7:18.1
-1,7,7:18.1
-2,7,7:18.1
-2,6,7:18.1
-1,5,7:106.1
1,5,7:106.1
-5,3,7:106.1
-1,-4,7:106.1
3,3,7:106.4
0,7,7:106.4
1,-3,7:106.4
-4,2,7:106.4
0,5,7:106.4
4,0,7:106.4
-2,-5,7:106.8
-5,4,8:17.0
-4,1,8:17.0
-6,0,8:17.0
-2,3,8:17.0
-1,6,8:17.0
0,4,8:17.0
1,6,8:17.0
2,1,8:17.0
4,-1,8:17.0
5,1,8:17.0
1,-5,8:17.0
-1,-3,8:17.0
-1,-5,8:17.0
-3,-6,8:17.0
-5,0,8:18.1
-6,-1,8:18.1
-7,0,8:18.1
-6,1,8:18.1
-5,1,8:18.1
-4,0,8:18.1
-3,1,8:18.1
-4,2,8:18.1
-5,3,8:18.1
-6,4,8:18.1
-5,5,8:18.1
-4,4,8:18.1
-4,3,8:18.1
-3,3,8:18.1
-2,4,8:18.1
-1,4,8:18.1
-1,3,8:18.1
-2,2,8:18.1
0,3,8:18.1
1,4,8:18.1
0,5,8:18.1
-2,6,8:18.1
-1,7,8:18.1
0,6,8:18.1
1,7,8:18.1
2,6,8:18.1
1,1,8:18.1
3,-1,8:18.1
4,-2,8:18.1
5,-1,8:18.1
6,1,8:18.1
5,2,8:18.1
4,1,8:18.1
4,0,8:18.1
-2,-4,8:18.1
-1,-4,8:18.1
0,-4,8:18.1
1,-4,8:18.1
2,-5,8:18.1
1,-6,8:18.1
-1,-6,8:18.1
-2,-6,8:18.1
-3,-7,8:18.1
-4,-6,8:18.1
-3,-5,8:18.1
0,-5,8:18.1
0,-3,8:18.1
-1,-2,8:18.1
-2,-3,8:18.1
-1,5,8:106.1
1,5,8:106.1
2,0,8:106.1
5,0,8:106.1
0,7,8:106.4
1,-3,8:106.4
-6,0,9:18.1
-5,4,9:18.1
-4,1,9:18.1
-2,3,9:18.1
0,4,9:18.1
-1,6,9:18.1
1,6,9:18.1
2,1,9:18.1
4,-1,9:18.1
5,1,9:18.1
-1,-3,9:18.1
1,-5,9:18.1
-1,-5,9:18.1
-3,-6,9:18.1
