[META]
version=2.0
spawnOnBlockType=3,2
spawnSunlight=True
spawnDarkness=True
spawnWater=False
spawnLava=False
underFill=False
randomRotation=True
dig=False
tree=True
branch=False
needsFoundation=True
rarity=100
collisionPercentage=2
spawnElevationMin=0
spawnElevationMax=100
spawnInBiome=Urwald,Forest
[DATA]
0,0,0:5
1,-1,0:5
-1,-1,0:5
-1,1,0:5
1,1,0:5
0,0,1:5
0,0,2:5
0,0,3:5
-1,-1,3:18.0
1,-1,3:18.0
-1,1,3:18.0
1,1,3:18.2
0,0,4:5
0,-1,4:5
1,1,4:5
2,2,4:5
-1,-2,4:5
1,-1,4:5
2,-2,4:5
-1,0,4:5
-1,1,4:5
-2,2,4:5
-1,-3,4:5
-2,-4,4:5
3,-1,4:5
4,-2,4:5
3,3,4:5
4,2,4:5
0,-4,4:5
-1,3,4:5
-3,1,4:5
4,-3,4:5
-2,-5,4:18.0
-3,-4,4:18.0
-3,-5,4:18.0
1,-4,4:18.0
1,-5,4:18.0
0,-5,4:18.0
4,-4,4:18.0
5,-4,4:18.0
5,-3,4:18.0
5,-1,4:18.0
2,-3,4:18.0
-2,-1,4:18.0
-2,0,4:18.0
-4,0,4:18.0
-4,1,4:18.0
-3,2,4:18.0
-2,4,4:18.0
-1,4,4:18.0
0,4,4:18.0
0,3,4:18.0
2,3,4:18.0
2,4,4:18.0
3,4,4:18.0
4,4,4:18.0
4,3,4:18.0
5,2,4:18.0
4,1,4:18.0
5,1,4:18.0
3,1,4:18.0
1,2,4:18.0
-3,-2,4:18.0
4,-5,4:18.0
-1,-4,4:18.2
3,-4,4:18.2
6,-2,4:18.2
-2,3,4:18.2
0,0,5:5
-1,-4,5:18.0
-3,2,5:18.0
-1,2,5:18.0
2,1,5:18.0
2,-1,5:18.0
3,-2,5:18.0
3,2,5:18.0
-1,-1,5:18.0
-2,1,5:18.0
1,0,5:18.0
0,-2,5:18.0
0,1,5:18.0
-2,0,5:18.0
-2,-3,5:18.0
4,-1,5:18.0
4,-3,5:18.0
-2,-4,5:18.2
-1,-3,5:18.2
0,-4,5:18.2
-1,-2,5:18.2
0,-1,5:18.2
-1,0,5:18.2
-1,1,5:18.2
-3,1,5:18.2
-2,2,5:18.2
-1,3,5:18.2
1,1,5:18.2
1,-1,5:18.2
2,-2,5:18.2
3,-1,5:18.2
4,-2,5:18.2
2,2,5:18.2
3,3,5:18.2
4,2,5:18.2
0,0,6:5
-1,-1,6:5
-2,-2,6:5
1,-1,6:5
2,0,6:5
-1,1,6:5
-2,2,6:5
-1,-3,6:18.0
1,-2,6:18.0
3,0,6:18.0
0,2,6:18.0
-2,0,6:18.0
-3,3,6:18.0
-3,-3,6:18.0
-3,-1,6:18.0
2,-2,6:18.0
1,1,6:18.0
2,-3,6:18.0
2,2,6:18.0
-3,1,6:18.0
-4,-1,6:18.0
-2,3,6:18.2
-2,-3,7:5
1,-2,7:5
2,-3,7:5
3,1,7:5
2,2,7:5
-3,1,7:5
-2,3,7:5
0,0,7:5
-2,-2,7:18.2
-1,-1,7:18.2
-1,1,7:18.2
-2,2,7:18.2
1,-1,7:18.2
2,0,7:18.2
-4,1,7:18.2
-2,4,7:18.2
-1,4,7:18.2
-2,-4,7:18.2
2,-4,7:18.2
3,-3,7:18.2
4,1,7:18.2
3,2,7:18.2
1,3,7:18.2
2,3,7:18.2
1,-3,7:18.2
0,0,8:5
-1,-3,8:18.0
-2,-4,8:18.0
-3,-3,8:18.0
-2,-2,8:18.0
-3,0,8:18.0
-4,1,8:18.0
-2,1,8:18.0
-3,2,8:18.0
-1,3,8:18.0
-1,4,8:18.0
-2,4,8:18.0
1,-1,8:18.0
2,-2,8:18.0
3,-3,8:18.0
3,-4,8:18.0
2,-4,8:18.0
1,-3,8:18.0
0,-1,8:18.0
2,1,8:18.0
3,0,8:18.0
4,1,8:18.0
3,2,8:18.0
2,3,8:18.0
1,2,8:18.0
-2,-3,8:18.2
1,-2,8:18.2
2,-3,8:18.2
-3,1,8:18.2
-2,3,8:18.2
2,2,8:18.2
3,1,8:18.2
0,0,9:5
0,-1,10:5
0,-2,10:5
1,-3,10:5
0,0,10:5
0,1,10:5
-1,2,10:5
-1,3,10:5
0,4,10:5
-1,-1,10:5
-2,-2,10:18.0
1,1,10:5
2,0,10:5
2,2,10:5
-2,3,10:5
-3,4,10:5
-2,-3,10:18.0
-3,-3,10:18.0
-3,-2,10:18.0
-3,3,10:18.0
-2,4,10:18.0
-3,5,10:18.0
-4,4,10:18.0
1,-2,10:18.0
2,-2,10:18.0
2,-3,10:18.0
2,-4,10:18.0
1,-4,10:18.0
0,-3,10:18.0
1,0,10:18.0
3,0,10:18.0
3,1,10:18.0
3,-1,10:18.0
2,3,10:18.0
1,3,10:18.0
-1,1,10:18.0
-2,1,10:18.0
-1,5,10:18.0
0,5,10:18.0
1,5,10:18.0
-2,0,10:18.2
-3,-1,10:18.2
-1,-4,10:18.2
3,2,10:18.2
4,3,10:18.2
-3,2,10:18.2
0,0,11:5
-2,-3,11:18.0
-3,-3,11:18.0
-3,-2,11:18.0
-2,-2,11:18.0
1,-3,11:18.0
2,-2,11:18.0
1,-4,11:18.0
-1,0,11:18.0
0,-2,11:18.0
3,0,11:18.0
4,1,11:18.0
2,2,11:18.0
2,3,11:18.0
3,3,11:18.0
2,4,11:18.0
0,3,11:18.0
0,4,11:18.0
0,5,11:18.0
-1,4,11:18.0
-3,3,11:18.0
-3,2,11:18.0
-2,2,11:18.0
-2,3,11:18.0
-3,5,11:18.0
-1,-1,11:18.2
0,-1,11:18.2
2,0,11:18.2
1,1,11:18.2
0,1,11:18.2
-1,2,11:18.2
-1,3,11:18.2
-3,4,11:18.2
0,0,12:5
0,0,13:5
1,-1,13:5
-1,-1,13:5
-2,-1,13:5
1,1,13:5
0,2,13:5
2,-2,13:5
-1,-2,13:18.0
-3,0,13:18.0
2,0,13:18.0
2,2,13:18.0
-1,3,13:18.0
0,3,13:18.0
1,-3,13:18.0
2,-3,13:18.0
3,-2,13:18.0
-1,1,13:18.0
-3,-2,13:18.0
-1,2,13:18.2
1,3,13:18.2
2,-1,13:18.2
2,1,13:18.2
0,-2,13:18.2
-4,-1,13:18.2
-2,-3,13:18.2
-2,1,13:18.2
-2,-2,14:18.0
-3,-1,14:18.0
-2,0,14:18.0
2,-3,14:18.0
3,-3,14:18.0
3,-1,14:18.0
2,2,14:18.0
-1,2,14:18.0
0,3,14:18.0
0,0,14:18.0
0,-1,14:18.0
1,0,14:18.0
-1,1,14:18.0
-2,-1,14:18.2
-1,-1,14:18.2
0,2,14:18.2
1,1,14:18.2
1,-1,14:18.2
2,-2,14:18.2
-1,0,15:18.0
0,0,15:18.0
1,1,15:18.0
0,0,16:18.0
