[META]
version=2.0
spawnOnBlockType=9
spawnSunlight=True
spawnDarkness=True
spawnWater=True
spawnLava=False
underFill=True
randomRotation=True
dig=True
tree=False
branch=False
needsFoundation=True
rarity=999
collisionPercentage=10
spawnElevationMin=64
spawnElevationMax=68
spawnInBiome=Swampland
[DATA]
0,0,0:17.0
-1,0,0:17.0
-1,1,0:17.0
0,1,0:17.0
-3,0,0:17.0
0,3,0:17.0
-1,-2,0:17.0
2,0,0:17.0
3,0,0:17.0
0,2,0:17.0
-1,3,0:17.0
-3,1,0:17.0
-1,-3,0:17.0
-2,-1,-2:3
-1,-1,-2:3
0,-1,-2:3
-2,0,-2:3
-1,0,-2:3
0,0,-2:3
-1,1,-2:3
0,1,-2:3
-3,0,-2:3
0,3,-2:3
2,0,-2:3
-1,-3,-2:3
-4,0,-2:3
0,4,-2:3
3,0,-2:3
4,0,-2:3
3,1,-2:3
-1,3,-2:3
1,4,-2:3
-4,2,-2:3
-3,1,-2:3
-2,-3,-2:3
0,-3,-2:3
-1,-4,-2:3
-5,3,-2:3
-4,3,-2:3
-3,3,-2:3
-3,2,-2:3
-2,2,-2:3
-2,1,-2:3
-3,-1,-2:3
-4,-1,-2:3
-5,-1,-2:3
-5,0,-2:3
-5,1,-2:3
-4,1,-2:3
-5,2,-2:3
-2,3,-2:3
-2,4,-2:3
-1,4,-2:3
-1,5,-2:3
0,5,-2:3
1,5,-2:3
2,5,-2:3
2,4,-2:3
2,3,-2:3
1,3,-2:3
1,2,-2:3
0,2,-2:3
-1,2,-2:3
2,1,-2:3
2,2,-2:3
3,2,-2:3
4,2,-2:3
4,1,-2:3
5,1,-2:3
5,0,-2:3
5,-1,-2:3
4,-1,-2:3
3,-1,-2:3
2,-1,-2:3
1,-1,-2:3
1,0,-2:3
1,1,-2:3
1,-4,-2:3
0,-4,-2:3
0,-5,-2:3
-1,-5,-2:3
-2,-5,-2:3
-2,-4,-2:3
-3,-4,-2:3
-3,-3,-2:3
-3,-2,-2:3
-2,-2,-2:3
-1,-2,-2:3
0,-2,-2:3
1,-2,-2:3
1,-3,-2:3
0,0,1:17.0
-1,0,1:17.0
-1,1,1:17.0
0,1,1:17.0
0,2,1:17.0
-2,0,1:17.0
-1,-1,1:17.0
1,0,1:17.0
-1,-2,1:17.0
0,0,2:17.0
-1,0,2:17.0
-1,1,2:17.0
0,1,2:17.0
-3,-4,2:106.4
-5,0,2:106.2
-2,5,2:106.1
-1,5,2:106.1
2,5,2:106.1
4,1,2:106.8
4,3,2:106.8
-1,-4,2:106.4
3,-4,2:106.4
4,-3,2:106.8
-5,-2,2:106.2
-5,4,2:106.2
-5,2,2:106.2
0,0,3:17.0
-1,0,3:17.0
-1,1,3:17.0
0,1,3:17.0
-3,-4,3:106.4
0,-4,3:106.4
-5,0,3:106.2
-2,5,3:106.1
-1,5,3:106.1
2,5,3:106.1
4,1,3:106.8
4,3,3:106.8
-1,-4,3:106.4
3,-4,3:106.4
4,-3,3:106.8
-5,-2,3:106.2
-5,4,3:106.2
-5,2,3:106.2
0,0,4:17.0
-1,0,4:17.0
-1,1,4:17.0
0,1,4:17.0
-3,-4,4:106.4
0,-4,4:106.4
-5,0,4:106.2
-2,5,4:106.1
-1,5,4:106.1
2,5,4:106.1
4,1,4:106.8
4,2,4:106.8
4,3,4:106.8
-1,-4,4:106.4
3,-4,4:106.4
4,-3,4:106.8
-5,-2,4:106.2
-5,4,4:106.2
-5,1,4:106.2
-5,2,4:106.2
0,0,5:17.0
-1,0,5:17.0
-1,1,5:17.0
0,1,5:17.0
-3,-4,5:106.4
0,-4,5:106.4
-5,0,5:106.2
-2,5,5:106.1
-1,5,5:106.1
2,5,5:106.1
4,1,5:106.8
4,2,5:106.8
4,3,5:106.8
-1,-4,5:106.4
3,-4,5:106.4
4,-3,5:106.8
-5,-2,5:106.2
-5,4,5:106.2
-5,1,5:106.2
-5,2,5:106.2
0,0,6:17.0
-1,0,6:17.0
-1,1,6:17.0
0,1,6:17.0
-4,-2,6:18.0
-4,-1,6:18.0
-4,0,6:18.0
-4,1,6:18.0
-4,2,6:18.0
-4,3,6:18.0
-4,4,6:18.0
-3,4,6:18.0
-2,4,6:18.0
-1,4,6:18.0
1,4,6:18.0
2,4,6:18.0
3,3,6:18.0
3,2,6:18.0
3,1,6:18.0
3,0,6:18.0
3,-2,6:18.0
3,-3,6:18.0
2,-3,6:18.0
0,-3,6:18.0
-1,-3,6:18.0
-2,-3,6:18.0
-3,-3,6:18.0
-3,-2,6:18.0
-2,-2,6:18.0
-1,-2,6:18.0
0,-2,6:18.0
1,-2,6:18.0
1,-1,6:18.0
2,-1,6:18.0
2,0,6:18.0
2,-2,6:18.0
1,0,6:18.0
1,1,6:18.0
2,1,6:18.0
2,2,6:18.0
2,3,6:18.0
1,3,6:18.0
1,2,6:18.0
0,3,6:18.0
-1,2,6:18.0
-2,2,6:18.0
0,2,6:18.0
-1,3,6:18.0
-2,3,6:18.0
-3,3,6:18.0
-3,2,6:18.0
-3,1,6:18.0
-3,0,6:18.0
-3,-1,6:18.0
-2,-1,6:18.0
-1,-1,6:18.0
0,-1,6:18.0
-2,0,6:18.0
-2,1,6:18.0
4,3,6:106.8
4,2,6:106.8
4,1,6:106.8
-2,5,6:106.1
-1,5,6:106.1
2,5,6:106.1
0,-4,6:106.4
-3,-4,6:106.4
-5,0,6:106.2
-1,-4,6:106.4
3,-4,6:106.4
4,-3,6:106.8
-5,1,6:106.2
-5,2,6:106.2
-5,-2,6:106.2
-5,4,6:106.2
0,0,7:17.0
-1,0,7:17.0
-1,1,7:17.0
0,1,7:17.0
-3,-2,7:18.0
-3,-1,7:18.0
-3,0,7:18.0
-3,1,7:18.0
-3,2,7:18.0
-3,3,7:18.0
-2,3,7:18.0
-1,3,7:18.0
0,3,7:18.0
1,3,7:18.0
2,3,7:18.0
2,2,7:18.0
2,1,7:18.0
2,0,7:18.0
2,-1,7:18.0
2,-2,7:18.0
1,-2,7:18.0
0,-2,7:18.0
-1,-2,7:18.0
-2,-2,7:18.0
-2,-1,7:18.0
-1,-1,7:18.0
0,-1,7:18.0
1,-1,7:18.0
1,0,7:18.0
1,1,7:18.0
1,2,7:18.0
0,2,7:18.0
-1,2,7:18.0
-2,2,7:18.0
-2,1,7:18.0
-2,0,7:18.0
-3,-3,7:18.0
-2,-3,7:18.0
-1,-3,7:18.0
0,-3,7:18.0
2,-3,7:18.0
3,-2,7:18.0
3,0,7:18.0
3,1,7:18.0
3,2,7:18.0
3,3,7:18.0
2,4,7:18.0
1,4,7:18.0
-1,4,7:18.0
-3,4,7:18.0
-2,4,7:18.0
-4,3,7:18.0
-4,2,7:18.0
-4,1,7:18.0
-4,0,7:18.0
-4,-2,7:18.0
-2,5,7:106.1
2,5,7:106.1
4,2,7:106.8
4,1,7:106.8
0,-4,7:106.4
-1,-4,7:106.4
-5,-2,7:106.2
-5,1,7:106.2
-5,2,7:106.2
-5,0,7:18.0
-5,4,7:18.0
-1,5,7:18.0
-3,-4,7:18.0
3,-4,7:18.0
4,-3,7:18.0
4,3,7:18.0
-4,4,7:18.0
-3,5,7:18.0
0,4,7:18.0
3,-3,7:18.0
0,0,8:17.0
-1,0,8:17.0
-1,1,8:17.0
0,1,8:17.0
-2,-1,8:18.0
-1,-1,8:18.0
0,-1,8:18.0
1,-1,8:18.0
1,0,8:18.0
1,1,8:18.0
1,2,8:18.0
0,2,8:18.0
-1,2,8:18.0
-2,2,8:18.0
-2,1,8:18.0
-2,0,8:18.0
-3,0,8:18.0
-3,1,8:18.0
-1,-2,8:18.0
0,-2,8:18.0
2,0,8:18.0
2,1,8:18.0
-1,3,8:18.0
0,3,8:18.0
-3,2,8:18.0
-2,3,8:18.0
1,3,8:18.0
2,3,8:18.0
2,2,8:18.0
2,-1,8:18.0
1,-2,8:18.0
-2,-2,8:18.0
-3,-2,8:18.0
-3,-1,8:18.0
-5,-2,8:18.0
-5,1,8:18.0
-5,2,8:18.0
-2,5,8:18.0
2,5,8:18.0
4,2,8:18.0
4,1,8:18.0
0,-4,8:18.0
-1,-4,8:18.0
-2,-3,8:18.0
-1,-3,8:18.0
0,-3,8:18.0
-2,4,8:18.0
-1,4,8:18.0
-3,3,8:18.0
-4,2,8:18.0
-4,1,8:18.0
3,0,8:18.0
3,1,8:18.0
3,2,8:18.0
-4,-1,8:18.0
-4,-2,8:18.0
-4,3,8:18.0
1,4,8:18.0
2,4,8:18.0
2,-2,8:18.0
-3,4,8:18.0
2,-3,8:18.0
3,-3,8:18.0
0,0,-1:17.0
-1,0,-1:17.0
-1,1,-1:17.0
0,1,-1:17.0
-3,0,-1:17.0
0,3,-1:17.0
2,0,-1:17.0
-1,-3,-1:17.0
-4,0,-1:17.0
0,4,-1:17.0
3,0,-1:17.0
4,0,-1:17.0
3,1,-1:17.0
-1,3,-1:17.0
1,4,-1:17.0
-4,2,-1:17.0
-3,1,-1:17.0
-2,-3,-1:17.0
0,-3,-1:17.0
-1,-4,-1:17.0
-1,0,9:18.0
-1,1,9:18.0
0,1,9:18.0
0,0,9:18.0
-2,-1,9:18.0
-1,-1,9:18.0
0,-1,9:18.0
1,-1,9:18.0
1,0,9:18.0
1,1,9:18.0
1,2,9:18.0
0,2,9:18.0
-1,2,9:18.0
-2,2,9:18.0
-2,1,9:18.0
-2,0,9:18.0
-3,0,9:18.0
-3,1,9:18.0
-1,3,9:18.0
0,3,9:18.0
2,1,9:18.0
2,0,9:18.0
-1,-2,9:18.0
0,-2,9:18.0
-3,2,9:18.0
-2,3,9:18.0
-1,-3,9:18.0
-2,-2,9:18.0
2,2,9:18.0
1,3,9:18.0
-3,-1,9:18.0
-1,0,10:18.0
-1,1,10:18.0
0,1,10:18.0
0,0,10:18.0
-2,1,10:18.0
0,2,10:18.0
-1,-1,10:18.0
1,1,10:18.0
-1,0,11:18.0
-1,1,11:18.0
0,1,11:18.0
0,0,11:18.0
