[META]
version=2.0
spawnOnBlockType=12
spawnSunlight=True
spawnDarkness=True
spawnWater=False
spawnLava=False
underFill=True
randomRotation=True
dig=False
tree=True
branch=False
rarity=120
collisionPercentage=2
spawnElevationMin=0
spawnElevationMax=120
spawnInBiome=Desert,DesertCaveFloor
[DATA]
0,0,0:17.0
0,0,1:17.0
0,0,2:17.0
1,0,2:17.0
-1,0,2:17.0
-2,0,2:17.0
2,0,2:17.0
0,0,3:17.0
0,-1,3:17.0
0,1,3:17.0
0,2,3:17.0
0,-2,3:17.0
-2,0,3:81
2,0,3:81
0,-2,4:81
0,0,4:81
0,2,4:81
-2,0,4:81
2,0,4:81
0,-2,5:81
0,0,5:81
0,2,5:81
-2,0,5:81
2,0,5:81
0,-2,6:81
0,0,6:81
0,2,6:81
0,0,7:81
0,2,7:81
0,-2,7:81
0,0,8:81
