[META]
version=2.0
spawnOnBlockType=2
spawnSunlight=True
spawnDarkness=True
spawnWater=False
spawnLava=False
underFill=False
randomRotation=True
dig=True
tree=False
branch=False
needsFoundation=True
rarity=10
collisionPercentage=20
spawnElevationMin=0
spawnElevationMax=102
groupId=Ruins
groupFrequencyMin=20
groupFrequencyMax=35
groupSeperationMin=5
groupSeperationMax=60
branchLimit=6
spawnInBiome=Jungle
[DATA]
-1,-1,-5:1.5
0,-1,-5:1.5
-1,0,-5:1.5
0,0,-5:1.5
-2,-2,-4:3.5
-1,-2,-4:1.5
0,-2,-4:1.5
1,-2,-4:3.5
-3,-1,-4:3.5
-2,-1,-4:1.5
-1,-1,-4:98.0
0,-1,-4:98.0
1,-1,-4:1.5
-3,0,-4:3.5
-2,0,-4:1.5
-1,0,-4:98.0
0,0,-4:98.0
1,0,-4:1.5
2,0,-4:3.5
-2,1,-4:3.5
-1,1,-4:1.5
0,1,-4:1.5
1,1,-4:3.5
0,2,-4:3.5
-3,-3,-3:3.5
-2,-3,-3:3.5
-1,-3,-3:1.5
0,-3,-3:1.5
1,-3,-3:3.5
2,-3,-3:3.5
-3,-2,-3:3.5
-2,-2,-3:1.5
-1,-2,-3:98.0
0,-2,-3:98.0
1,-2,-3:1.5
2,-2,-3:3.5
-4,-1,-3:3.5
-3,-1,-3:1.5
-2,-1,-3:98.0
-1,-1,-3:22.0
0,-1,-3:22.0
1,-1,-3:98.0
2,-1,-3:1.5
-4,0,-3:3.5
-3,0,-3:1.5
-2,0,-3:98.0
-1,0,-3:22.0
0,0,-3:22.0
1,0,-3:98.0
2,0,-3:1.5
3,0,-3:3.5
-3,1,-3:3.5
-2,1,-3:1.5
-1,1,-3:98.0
0,1,-3:98.0
1,1,-3:1.5
2,1,-3:3.5
3,1,-3:3.5
-3,2,-3:3.5
-2,2,-3:3.5
-1,2,-3:1.5
0,2,-3:1.5
1,2,-3:3.5
2,2,-3:3.5
0,3,-3:3.5
1,3,-3:3.5
-3,-5,-2:3.5
-2,-5,-2:3.5
-4,-4,-2:3.5
-3,-4,-2:3.5
-2,-4,-2:3.5
-1,-4,-2:3.5
0,-4,-2:3.5
1,-4,-2:3.5
2,-4,-2:3.5
3,-4,-2:3.5
-5,-3,-2:3.5
-4,-3,-2:3.5
-3,-3,-2:3.5
-2,-3,-2:3.5
-1,-3,-2:3.5
0,-3,-2:3.5
1,-3,-2:3.5
2,-3,-2:3.5
3,-3,-2:3.5
4,-3,-2:3.5
-4,-2,-2:3.5
-3,-2,-2:3.5
-2,-2,-2:3.5
-1,-2,-2:89.5
0,-2,-2:89.5
1,-2,-2:3.5
2,-2,-2:3.5
3,-2,-2:3.5
-5,-1,-2:3.5
-4,-1,-2:3.5
-3,-1,-2:3.5
-2,-1,-2:89.5
-1,-1,-2:9.8
0,-1,-2:9.8
1,-1,-2:89.5
2,-1,-2:3.5
3,-1,-2:3.5
-5,0,-2:3.5
-4,0,-2:3.5
-3,0,-2:3.5
-2,0,-2:89.5
-1,0,-2:9.8
0,0,-2:9.8
1,0,-2:89.5
2,0,-2:3.5
3,0,-2:3.5
-4,1,-2:3.5
-3,1,-2:3.5
-2,1,-2:3.5
-1,1,-2:89.5
0,1,-2:89.5
1,1,-2:3.5
2,1,-2:3.5
3,1,-2:3.5
4,1,-2:3.5
-5,2,-2:3.5
-4,2,-2:3.5
-3,2,-2:3.5
-2,2,-2:3.5
-1,2,-2:3.5
0,2,-2:3.5
1,2,-2:3.5
2,2,-2:3.5
3,2,-2:3.5
-4,3,-2:3.5
-3,3,-2:3.5
-2,3,-2:3.5
-1,3,-2:3.5
0,3,-2:3.5
1,3,-2:3.5
2,3,-2:3.5
3,3,-2:3.5
1,4,-2:3.5
-4,-5,-1:2.5
-3,-5,-1:2.5
-2,-5,-1:2.5
-1,-5,-1:2.5
1,-5,-1:2.5
2,-5,-1:2.5
-5,-4,-1:2.5
-4,-4,-1:98.3
-3,-4,-1:98.0
-2,-4,-1:98.0
-1,-4,-1:98.2
0,-4,-1:98.0
1,-4,-1:98.0
2,-4,-1:98.1
3,-4,-1:98.3
4,-4,-1:2.5
-5,-3,-1:2.5
-4,-3,-1:98.0
-3,-3,-1:98.3
-2,-3,-1:98.0
-1,-3,-1:98.0
0,-3,-1:98.0
1,-3,-1:98.0
2,-3,-1:98.3
3,-3,-1:98.0
4,-3,-1:2.5
-5,-2,-1:2.5
-4,-2,-1:98.0
-3,-2,-1:98.2
-2,-2,-1:98.2
-1,-2,-1:98.3
0,-2,-1:98.3
1,-2,-1:98.0
2,-2,-1:98.0
3,-2,-1:2.5
4,-2,-1:2.5
-5,-1,-1:2.5
-4,-1,-1:98.1
-3,-1,-1:98.0
-2,-1,-1:98.3
-1,-1,-1:9.0
0,-1,-1:9.0
1,-1,-1:98.3
2,-1,-1:98.0
3,-1,-1:2.5
-5,0,-1:2.5
-4,0,-1:98.1
-3,0,-1:98.0
-2,0,-1:98.3
-1,0,-1:9.0
0,0,-1:9.0
1,0,-1:98.3
2,0,-1:98.0
3,0,-1:98.1
4,0,-1:2.5
-5,1,-1:2.5
-4,1,-1:2.5
-3,1,-1:98.0
-2,1,-1:98.0
-1,1,-1:98.3
0,1,-1:98.3
1,1,-1:98.1
2,1,-1:98.1
3,1,-1:98.1
4,1,-1:2.5
-5,2,-1:2.5
-4,2,-1:98.0
-3,2,-1:98.3
-2,2,-1:98.0
-1,2,-1:98.2
0,2,-1:98.0
1,2,-1:98.0
2,2,-1:98.3
3,2,-1:98.1
4,2,-1:2.5
-5,3,-1:2.5
-4,3,-1:98.3
-3,3,-1:98.0
-2,3,-1:98.2
-1,3,-1:98.2
0,3,-1:98.2
1,3,-1:98.0
2,3,-1:2.5
3,3,-1:98.3
-3,4,-1:2.5
-2,4,-1:2.5
0,4,-1:2.5
1,4,-1:2.5
2,4,-1:2.5
-4,-4,0:98.3
3,-4,0:98.3
-2,-2,0:98.2
-1,-2,0:98.3
0,-2,0:98.3
1,-2,0:98.0
-2,-1,0:98.3
1,-1,0:98.3
-2,0,0:98.3
1,0,0:98.3
-2,1,0:98.0
-1,1,0:98.3
0,1,0:98.3
1,1,0:98.1
-4,3,0:98.3
3,3,0:98.3
-4,-4,1:44.0
3,-4,1:44.0
-2,-2,1:98.0
-1,-2,1:98.3
0,-2,1:98.3
1,-2,1:98.0
-2,-1,1:98.3
1,-1,1:98.3
-2,0,1:98.3
1,0,1:98.3
-2,1,1:98.0
-1,1,1:98.3
0,1,1:98.3
1,1,1:98.0
-4,3,1:44.0
3,3,1:44.0
-2,-2,2:98.0
-1,-2,2:44.13
0,-2,2:44.13
1,-2,2:98.0
-2,-1,2:44.13
1,-1,2:44.13
-2,0,2:44.13
-1,0,2:30.0
1,0,2:44.13
-2,1,2:98.0
-1,1,2:44.13
0,1,2:44.13
1,1,2:98.0
-1,-2,3:109.2
0,-2,3:109.2
-2,-1,3:109.0
1,-1,3:109.1
-2,0,3:109.0
-1,0,3:30.0
1,0,3:109.1
-1,1,3:109.3
0,1,3:109.3
-1,-1,4:44.0
0,-1,4:44.0
-1,0,4:44.0
0,0,4:44.0
1,4,0:31.1
0,4,0:31.2
-2,4,0:31.1
-3,4,0:31.1
2,3,0:31.1
-5,2,0:31.2
4,1,0:31.1
-4,1,0:31.1
4,0,0:31.2
3,-1,0:31.1
-5,-1,0:31.1
4,-2,0:31.2
-5,-2,0:31.2
4,-3,0:31.1
-5,-3,0:31.1
4,-4,0:31.1
2,-5,0:31.1
1,-5,0:31.2
-2,-5,0:31.1
-3,-5,0:31.2
-4,-5,0:31.1
