[META]
version=2.0
spawnOnBlockType=2
spawnSunlight=True
spawnDarkness=True
spawnWater=False
spawnLava=False
underFill=False
randomRotation=True
dig=True
tree=False
branch=False
needsFoundation=True
rarity=10
collisionPercentage=50
spawnElevationMin=0
spawnElevationMax=102
groupId=Ruins
groupFrequencyMin=20
groupFrequencyMax=35
groupSeperationMin=5
groupSeperationMax=60
branchLimit=6
spawnInBiome=Jungle
[DATA]
-2,-2,-4:48.0
-1,-2,-4:48.0
0,-2,-4:48.0
-1,-1,-4:48.0
0,-1,-4:48.0
1,-1,-4:48.0
0,0,-4:48.0
1,0,-4:48.0
1,1,-4:48.0
-2,-3,-3:48.0
-1,-3,-3:48.0
0,-3,-3:48.0
1,-3,-3:48.0
-3,-2,-3:3.0
1,-2,-3:3.5
2,-2,-3:48.0
-2,-1,-3:3.0
2,-1,-3:48.0
-1,0,-3:3.0
2,0,-3:48.0
0,1,-3:3.0
2,1,-3:48.0
1,2,-3:3.0
-1,-4,-2:3.5
0,-4,-2:3.5
1,-4,-2:3.5
2,-4,-2:3.5
-3,-3,-2:3.0
-2,-3,-2:48.0
-1,-3,-2:48.0
0,-3,-2:48.0
1,-3,-2:48.0
2,-3,-2:3.5
3,-3,-2:3.5
-4,-2,-2:3.0
2,-2,-2:48.0
3,-2,-2:3.5
-3,-1,-2:3.0
2,-1,-2:48.0
3,-1,-2:3.5
-2,0,-2:3.0
2,0,-2:48.0
3,0,-2:3.5
-1,1,-2:3.0
2,1,-2:48.0
3,1,-2:3.5
0,2,-2:3.0
2,2,-2:3.0
1,3,-2:3.0
-1,-5,-1:2.0
0,-5,-1:2.0
1,-5,-1:2.0
2,-5,-1:4.0
3,-5,-1:2.0
-2,-4,-1:2.0
-1,-4,-1:2.0
0,-4,-1:2.0
1,-4,-1:2.0
2,-4,-1:2.0
3,-4,-1:2.0
4,-4,-1:4.0
-3,-3,-1:2.0
-2,-3,-1:3.0
-1,-3,-1:3.0
0,-3,-1:3.0
1,-3,-1:3.0
2,-3,-1:3.0
3,-3,-1:4.0
4,-3,-1:2.0
-5,-2,-1:2.0
-4,-2,-1:2.0
-3,-2,-1:48.0
-2,-2,-1:48.0
-1,-2,-1:2.0
0,-2,-1:48.0
1,-2,-1:48.0
2,-2,-1:3.0
3,-2,-1:2.0
4,-2,-1:2.0
-4,-1,-1:2.0
-3,-1,-1:2.0
-2,-1,-1:48.0
-1,-1,-1:48.0
0,-1,-1:2.0
1,-1,-1:48.0
2,-1,-1:3.0
3,-1,-1:2.0
4,-1,-1:2.0
-3,0,-1:48.0
-2,0,-1:2.0
-1,0,-1:48.0
0,0,-1:2.0
1,0,-1:48.0
2,0,-1:3.0
3,0,-1:2.0
4,0,-1:2.0
-2,1,-1:48.0
-1,1,-1:2.0
0,1,-1:48.0
1,1,-1:2.0
2,1,-1:2.0
3,1,-1:2.0
4,1,-1:2.0
-1,2,-1:2.0
0,2,-1:2.0
1,2,-1:2.0
2,2,-1:2.0
3,2,-1:2.0
0,3,-1:2.0
1,3,-1:2.0
2,3,-1:2.0
1,4,-1:2.0
-2,-3,0:98.2
-1,-3,0:98.1
0,-3,0:98.1
1,-3,0:98.2
2,-3,0:98.1
2,-2,0:98.2
2,-1,0:98.1
2,0,0:98.1
-1,-3,1:109.0
2,-3,1:98.2
2,0,1:109.3
0,-3,2:109.0
1,-3,2:98.2
2,-3,2:98.1
2,-2,2:98.1
2,-1,2:109.3
1,-3,3:98.2
2,-3,3:98.1
2,-4,3:106.1
1,-4,3:106.1
3,-2,2:106.2
3,-3,2:106.2
2,-4,2:106.1
1,-4,2:106.1
3,-2,1:106.2
3,-3,1:106.2
2,-4,1:106.1
1,-4,1:106.1
2,2,0:31.2
0,2,0:31.1
1,1,0:31.1
-1,1,0:31.1
3,0,0:106.2
0,0,0:31.1
-2,0,0:31.1
3,-1,0:31.2
0,-1,0:31.1
-3,-1,0:31.1
-4,-1,0:31.1
3,-2,0:106.2
-1,-2,0:31.1
-4,-2,0:31.1
2,-4,0:106.1
1,-4,0:106.1
3,-5,0:31.2
-1,-5,0:31.2
