[META]
version=2.0
spawnOnBlockType=2
spawnSunlight=True
spawnDarkness=True
spawnWater=False
spawnLava=False
underFill=False
randomRotation=True
dig=True
tree=False
branch=False
needsFoundation=True
rarity=10
collisionPercentage=70
spawnElevationMin=0
spawnElevationMax=102
groupId=Ruins
groupFrequencyMin=20
groupFrequencyMax=35
groupSeperationMin=5
groupSeperationMax=60
branchLimit=6
spawnInBiome=Jungle
[DATA]
0,-2,-8:1.0
1,-2,-8:1.0
-2,-1,-8:1.0
-1,-1,-8:1.0
0,-1,-8:1.0
1,-1,-8:1.0
2,-1,-8:1.0
-2,0,-8:1.0
-1,0,-8:1.0
0,0,-8:1.0
1,0,-8:1.0
2,0,-8:1.0
-2,1,-8:1.0
-1,1,-8:1.0
0,1,-8:1.0
1,1,-8:1.0
-1,2,-8:1.0
0,2,-8:1.0
1,2,-8:1.0
0,3,-8:1.0
0,-3,-7:1.0
1,-3,-7:1.0
-2,-2,-7:1.0
-1,-2,-7:1.0
0,-2,-7:1.0
1,-2,-7:1.0
2,-2,-7:3.0
-2,-1,-7:1.0
-1,-1,-7:1.0
0,-1,-7:1.0
1,-1,-7:1.0
2,-1,-7:1.0
-3,0,-7:1.0
-2,0,-7:1.0
-1,0,-7:1.0
0,0,-7:1.0
1,0,-7:1.0
2,0,-7:1.0
3,0,-7:1.0
-2,1,-7:1.0
-1,1,-7:1.0
0,1,-7:1.0
1,1,-7:1.0
2,1,-7:1.0
-2,2,-7:1.0
-1,2,-7:1.0
0,2,-7:1.0
1,2,-7:1.0
-1,3,-7:1.0
0,3,-7:1.0
1,3,-7:1.0
0,4,-7:1.0
-1,-4,-6:1.0
0,-4,-6:1.0
-2,-3,-6:1.0
-1,-3,-6:1.0
0,-3,-6:1.0
1,-3,-6:1.0
2,-3,-6:3.0
-2,-2,-6:1.0
-1,-2,-6:1.0
0,-2,-6:1.0
1,-2,-6:1.0
2,-2,-6:1.0
3,-2,-6:3.0
-3,-1,-6:1.0
-2,-1,-6:1.0
-1,-1,-6:98.1
0,-1,-6:98.1
1,-1,-6:98.1
2,-1,-6:1.0
3,-1,-6:1.0
-4,0,-6:1.0
-3,0,-6:1.0
-2,0,-6:1.0
-1,0,-6:98.1
0,0,-6:98.1
1,0,-6:98.1
2,0,-6:1.0
3,0,-6:1.0
4,0,-6:1.0
-3,1,-6:1.0
-2,1,-6:1.0
-1,1,-6:98.1
0,1,-6:98.1
1,1,-6:98.1
2,1,-6:1.0
3,1,-6:1.0
-2,2,-6:1.0
-1,2,-6:1.0
0,2,-6:1.0
1,2,-6:1.0
2,2,-6:1.0
-2,3,-6:1.0
-1,3,-6:1.0
0,3,-6:1.0
1,3,-6:3.0
2,3,-6:3.0
-1,4,-6:1.0
0,4,-6:1.0
1,4,-6:1.0
0,5,-6:1.0
0,-5,-5:3.0
1,-5,-5:1.0
-2,-4,-5:3.0
-1,-4,-5:1.0
0,-4,-5:1.0
1,-4,-5:1.0
2,-4,-5:1.0
-3,-3,-5:3.0
-2,-3,-5:3.0
-1,-3,-5:1.0
0,-3,-5:1.0
1,-3,-5:1.0
2,-3,-5:1.0
3,-3,-5:3.0
-3,-2,-5:1.0
-2,-2,-5:1.0
-1,-2,-5:98.1
0,-2,-5:98.1
1,-2,-5:98.1
2,-2,-5:1.0
3,-2,-5:1.0
4,-2,-5:3.0
-4,-1,-5:1.0
-3,-1,-5:1.0
-2,-1,-5:98.2
-1,-1,-5:9.0
0,-1,-5:9.0
1,-1,-5:9.0
2,-1,-5:98.1
3,-1,-5:1.0
4,-1,-5:1.0
-5,0,-5:1.0
-4,0,-5:1.0
-3,0,-5:1.0
-2,0,-5:98.2
-1,0,-5:9.0
0,0,-5:9.0
1,0,-5:9.0
2,0,-5:98.1
3,0,-5:1.0
4,0,-5:1.0
5,0,-5:1.0
-4,1,-5:1.0
-3,1,-5:1.0
-2,1,-5:98.2
-1,1,-5:9.0
0,1,-5:9.0
1,1,-5:9.0
2,1,-5:98.1
3,1,-5:1.0
4,1,-5:1.0
-3,2,-5:3.0
-2,2,-5:1.0
-1,2,-5:98.1
0,2,-5:98.1
1,2,-5:98.1
2,2,-5:1.0
3,2,-5:1.0
-3,3,-5:3.0
-2,3,-5:1.0
-1,3,-5:1.0
0,3,-5:1.0
1,3,-5:3.0
2,3,-5:1.0
-2,4,-5:1.0
-1,4,-5:1.0
0,4,-5:1.0
1,4,-5:1.0
2,4,-5:3.0
-1,5,-5:1.0
0,5,-5:1.0
1,5,-5:1.0
0,6,-5:1.0
0,-6,-4:3.0
-2,-5,-4:3.0
-1,-5,-4:1.0
0,-5,-4:3.0
1,-5,-4:3.0
2,-5,-4:3.0
-3,-4,-4:3.0
-2,-4,-4:1.0
-1,-4,-4:1.0
0,-4,-4:3.0
1,-4,-4:3.0
2,-4,-4:3.0
3,-4,-4:3.0
-4,-3,-4:3.0
-3,-3,-4:3.0
-2,-3,-4:3.0
-1,-3,-4:1.0
0,-3,-4:1.0
1,-3,-4:3.0
2,-3,-4:3.0
3,-3,-4:1.0
4,-3,-4:3.0
-5,-2,-4:3.0
-4,-2,-4:3.0
-3,-2,-4:1.0
-2,-2,-4:3.0
-1,-2,-4:98.1
0,-2,-4:98.1
1,-2,-4:98.1
2,-2,-4:1.0
3,-2,-4:3.0
4,-2,-4:3.0
5,-2,-4:3.0
-5,-1,-4:3.0
-4,-1,-4:1.0
-3,-1,-4:1.0
-2,-1,-4:98.1
2,-1,-4:98.1
3,-1,-4:3.0
4,-1,-4:1.0
5,-1,-4:3.0
-5,0,-4:1.0
-4,0,-4:1.0
-3,0,-4:1.0
-2,0,-4:98.2
2,0,-4:98.1
3,0,-4:1.0
4,0,-4:1.0
5,0,-4:1.0
6,0,-4:3.0
-5,1,-4:1.0
-4,1,-4:1.0
-3,1,-4:1.0
-2,1,-4:98.1
2,1,-4:98.1
3,1,-4:1.0
4,1,-4:1.0
5,1,-4:1.0
-4,2,-4:3.0
-3,2,-4:1.0
-2,2,-4:1.0
-1,2,-4:98.1
0,2,-4:98.1
1,2,-4:98.1
2,2,-4:1.0
3,2,-4:1.0
4,2,-4:1.0
-4,3,-4:3.0
-3,3,-4:1.0
-2,3,-4:3.0
-1,3,-4:1.0
0,3,-4:1.0
1,3,-4:1.0
2,3,-4:1.0
3,3,-4:1.0
4,3,-4:3.0
-3,4,-4:3.0
-2,4,-4:3.0
-1,4,-4:3.0
0,4,-4:1.0
1,4,-4:1.0
2,4,-4:1.0
3,4,-4:3.0
-2,5,-4:3.0
-1,5,-4:3.0
0,5,-4:3.0
1,5,-4:1.0
2,5,-4:3.0
-1,6,-4:3.0
0,6,-4:1.0
0,7,-4:1.0
0,-7,-3:3.0
1,-7,-3:3.0
-2,-6,-3:3.0
-1,-6,-3:3.0
0,-6,-3:3.0
1,-6,-3:3.0
2,-6,-3:3.0
-3,-5,-3:3.0
-2,-5,-3:3.0
-1,-5,-3:3.0
0,-5,-3:3.0
1,-5,-3:3.0
2,-5,-3:3.0
3,-5,-3:3.0
-4,-4,-3:3.0
-3,-4,-3:3.0
-2,-4,-3:3.0
-1,-4,-3:3.0
0,-4,-3:3.0
1,-4,-3:3.0
2,-4,-3:3.0
3,-4,-3:3.0
4,-4,-3:98.0
-5,-3,-3:3.0
-4,-3,-3:3.0
-3,-3,-3:3.0
-2,-3,-3:3.0
-1,-3,-3:3.0
0,-3,-3:3.0
1,-3,-3:3.0
2,-3,-3:3.0
3,-3,-3:3.0
4,-3,-3:3.0
5,-3,-3:3.0
-5,-2,-3:3.0
-4,-2,-3:3.0
-3,-2,-3:3.0
-2,-2,-3:3.0
-1,-2,-3:3.0
0,-2,-3:3.0
1,-2,-3:3.0
2,-2,-3:3.0
3,-2,-3:3.0
4,-2,-3:3.0
5,-2,-3:3.0
-6,-1,-3:3.0
-5,-1,-3:3.0
-4,-1,-3:3.0
-3,-1,-3:3.0
-2,-1,-3:3.0
-1,-1,-3:1.0
0,-1,-3:98.1
1,-1,-3:1.0
2,-1,-3:1.0
3,-1,-3:3.0
4,-1,-3:3.0
5,-1,-3:3.0
6,-1,-3:3.0
-6,0,-3:3.0
-5,0,-3:3.0
-4,0,-3:3.0
-3,0,-3:3.0
-2,0,-3:1.0
-1,0,-3:98.0
1,0,-3:98.1
2,0,-3:1.0
3,0,-3:3.0
4,0,-3:3.0
5,0,-3:3.0
6,0,-3:3.0
-5,1,-3:3.0
-4,1,-3:3.0
-3,1,-3:3.0
-2,1,-3:3.0
-1,1,-3:1.0
0,1,-3:98.1
1,1,-3:98.0
2,1,-3:1.0
3,1,-3:3.0
4,1,-3:3.0
5,1,-3:3.0
6,1,-3:3.0
-5,2,-3:3.0
-4,2,-3:3.0
-3,2,-3:3.0
-2,2,-3:3.0
-1,2,-3:3.0
0,2,-3:98.2
1,2,-3:3.0
2,2,-3:3.0
3,2,-3:3.0
4,2,-3:3.0
5,2,-3:3.0
-5,3,-3:3.0
-4,3,-3:3.0
-3,3,-3:3.0
-2,3,-3:3.0
-1,3,-3:3.0
0,3,-3:3.0
1,3,-3:3.0
2,3,-3:3.0
3,3,-3:3.0
4,3,-3:3.0
5,3,-3:3.0
-4,4,-3:3.0
-3,4,-3:3.0
-2,4,-3:3.0
-1,4,-3:3.0
0,4,-3:3.0
1,4,-3:3.0
2,4,-3:3.0
3,4,-3:3.0
4,4,-3:3.0
-3,5,-3:3.0
-2,5,-3:3.0
-1,5,-3:3.0
0,5,-3:3.0
1,5,-3:3.0
2,5,-3:3.0
3,5,-3:3.0
-2,6,-3:3.0
-1,6,-3:3.0
0,6,-3:3.0
1,6,-3:3.0
2,6,-3:3.0
-1,7,-3:3.0
0,7,-3:3.0
1,7,-3:3.0
-1,-8,-2:3.0
0,-8,-2:3.0
1,-8,-2:3.0
-2,-7,-2:3.0
-1,-7,-2:3.0
0,-7,-2:3.0
1,-7,-2:3.0
2,-7,-2:3.0
-3,-6,-2:3.0
-2,-6,-2:3.0
-1,-6,-2:3.0
0,-6,-2:3.0
1,-6,-2:3.0
2,-6,-2:3.0
3,-6,-2:3.0
-4,-5,-2:98.1
-3,-5,-2:3.0
-2,-5,-2:3.0
-1,-5,-2:3.0
0,-5,-2:3.0
1,-5,-2:3.0
2,-5,-2:3.0
3,-5,-2:3.0
4,-5,-2:98.1
-5,-4,-2:98.1
-4,-4,-2:98.1
-3,-4,-2:98.1
-2,-4,-2:3.0
-1,-4,-2:3.0
0,-4,-2:3.0
1,-4,-2:3.0
2,-4,-2:3.0
3,-4,-2:98.1
4,-4,-2:98.1
5,-4,-2:98.1
-6,-3,-2:3.0
-5,-3,-2:3.0
-4,-3,-2:98.1
-3,-3,-2:3.0
-2,-3,-2:3.0
-1,-3,-2:3.0
0,-3,-2:3.0
1,-3,-2:3.0
2,-3,-2:3.0
3,-3,-2:3.0
4,-3,-2:98.0
5,-3,-2:3.0
6,-3,-2:3.0
-6,-2,-2:3.0
-5,-2,-2:3.0
-4,-2,-2:3.0
-3,-2,-2:3.0
-2,-2,-2:3.0
-1,-2,-2:98.0
0,-2,-2:3.0
1,-2,-2:3.0
2,-2,-2:3.0
3,-2,-2:3.0
4,-2,-2:3.0
5,-2,-2:3.0
6,-2,-2:3.0
-7,-1,-2:3.0
-6,-1,-2:3.0
-5,-1,-2:3.0
-4,-1,-2:3.0
-3,-1,-2:3.0
-2,-1,-2:98.0
-1,-1,-2:98.1
0,-1,-2:98.1
1,-1,-2:3.0
2,-1,-2:3.0
3,-1,-2:3.0
4,-1,-2:3.0
5,-1,-2:3.0
6,-1,-2:3.0
7,-1,-2:3.0
-7,0,-2:3.0
-6,0,-2:3.0
-5,0,-2:3.0
-4,0,-2:3.0
-3,0,-2:98.0
-2,0,-2:98.0
-1,0,-2:98.1
1,0,-2:98.1
2,0,-2:98.0
3,0,-2:3.0
4,0,-2:3.0
5,0,-2:3.0
6,0,-2:3.0
7,0,-2:3.0
-6,1,-2:3.0
-5,1,-2:3.0
-4,1,-2:3.0
-3,1,-2:3.0
-2,1,-2:3.0
-1,1,-2:98.1
0,1,-2:98.1
1,1,-2:98.0
2,1,-2:3.0
3,1,-2:3.0
4,1,-2:3.0
5,1,-2:3.0
6,1,-2:3.0
-6,2,-2:3.0
-5,2,-2:3.0
-4,2,-2:3.0
-3,2,-2:3.0
-2,2,-2:3.0
-1,2,-2:3.0
0,2,-2:98.1
1,2,-2:3.0
2,2,-2:3.0
3,2,-2:3.0
4,2,-2:3.0
5,2,-2:3.0
6,2,-2:3.0
-6,3,-2:3.0
-5,3,-2:3.0
-4,3,-2:98.1
-3,3,-2:3.0
-2,3,-2:3.0
-1,3,-2:3.0
0,3,-2:3.0
1,3,-2:3.0
2,3,-2:3.0
3,3,-2:3.0
4,3,-2:98.1
5,3,-2:3.0
6,3,-2:3.0
-5,4,-2:98.1
-4,4,-2:98.1
-3,4,-2:98.1
-2,4,-2:3.0
-1,4,-2:3.0
0,4,-2:98.2
1,4,-2:3.0
2,4,-2:3.0
3,4,-2:98.1
4,4,-2:98.1
5,4,-2:98.1
-4,5,-2:98.1
-3,5,-2:3.0
-2,5,-2:3.0
-1,5,-2:3.0
0,5,-2:3.0
1,5,-2:3.0
2,5,-2:3.0
3,5,-2:3.0
4,5,-2:98.1
-3,6,-2:3.0
-2,6,-2:3.0
-1,6,-2:3.0
0,6,-2:3.0
1,6,-2:3.0
2,6,-2:3.0
3,6,-2:3.0
-2,7,-2:3.0
-1,7,-2:3.0
0,7,-2:3.0
1,7,-2:3.0
2,7,-2:3.0
-1,8,-2:3.0
0,8,-2:3.0
1,8,-2:3.0
0,-9,-1:2.0
1,-9,-1:2.0
-2,-8,-1:2.5
-1,-8,-1:2.5
0,-8,-1:2.0
1,-8,-1:2.0
2,-8,-1:2.0
-3,-7,-1:2.0
-2,-7,-1:2.0
-1,-7,-1:2.0
0,-7,-1:2.0
1,-7,-1:2.0
2,-7,-1:2.0
3,-7,-1:2.0
-4,-6,-1:2.0
-3,-6,-1:2.0
-2,-6,-1:2.0
-1,-6,-1:98.0
0,-6,-1:2.0
1,-6,-1:2.0
2,-6,-1:98.1
3,-6,-1:3.0
4,-6,-1:2.0
-5,-5,-1:98.1
-4,-5,-1:98.1
-3,-5,-1:98.1
-2,-5,-1:2.0
-1,-5,-1:98.0
0,-5,-1:98.2
1,-5,-1:98.1
2,-5,-1:98.1
3,-5,-1:98.1
4,-5,-1:98.1
5,-5,-1:98.1
-6,-4,-1:2.0
-5,-4,-1:98.1
-3,-4,-1:98.1
-2,-4,-1:2.0
-1,-4,-1:98.1
0,-4,-1:98.1
1,-4,-1:98.1
2,-4,-1:3.0
3,-4,-1:98.1
5,-4,-1:98.1
6,-4,-1:2.0
-6,-3,-1:2.0
-5,-3,-1:98.1
-4,-3,-1:98.1
-3,-3,-1:98.1
-2,-3,-1:2.0
-1,-3,-1:2.0
0,-3,-1:98.2
1,-3,-1:98.1
2,-3,-1:98.1
3,-3,-1:3.0
4,-3,-1:98.1
5,-3,-1:98.1
6,-3,-1:2.0
-7,-2,-1:2.0
-6,-2,-1:3.0
-5,-2,-1:2.0
-4,-2,-1:98.0
-3,-2,-1:2.0
-2,-2,-1:98.2
-1,-2,-1:98.0
0,-2,-1:98.1
1,-2,-1:98.1
2,-2,-1:98.2
3,-2,-1:3.0
4,-2,-1:2.0
5,-2,-1:2.0
6,-2,-1:2.0
7,-2,-1:2.0
-7,-1,-1:2.0
-6,-1,-1:43.5
-5,-1,-1:98.0
-4,-1,-1:98.1
-3,-1,-1:98.1
-2,-1,-1:98.0
-1,-1,-1:98.2
0,-1,-1:98.1
1,-1,-1:98.2
2,-1,-1:98.0
3,-1,-1:2.0
4,-1,-1:98.1
5,-1,-1:98.1
6,-1,-1:2.0
7,-1,-1:2.0
-7,0,-1:2.0
-6,0,-1:2.0
-5,0,-1:3.0
-4,0,-1:98.0
-3,0,-1:98.2
-2,0,-1:98.0
-1,0,-1:98.1
1,0,-1:98.1
2,0,-1:98.0
3,0,-1:98.2
4,0,-1:3.0
5,0,-1:98.2
6,0,-1:109.1
7,0,-1:98.1
-7,1,-1:2.0
-6,1,-1:98.1
-5,1,-1:3.0
-4,1,-1:98.0
-3,1,-1:98.1
-2,1,-1:98.1
-1,1,-1:98.2
0,1,-1:98.1
1,1,-1:98.2
2,1,-1:98.1
3,1,-1:98.0
4,1,-1:98.1
5,1,-1:98.1
6,1,-1:98.1
7,1,-1:2.0
-7,2,-1:2.0
-6,2,-1:2.0
-5,2,-1:3.0
-4,2,-1:2.0
-3,2,-1:3.0
-2,2,-1:98.0
-1,2,-1:98.0
0,2,-1:98.1
1,2,-1:98.1
2,2,-1:98.2
3,2,-1:17.0
4,2,-1:3.0
5,2,-1:2.0
6,2,-1:2.0
7,2,-1:2.0
-6,3,-1:3.0
-5,3,-1:98.1
-4,3,-1:98.1
-3,3,-1:98.1
-2,3,-1:98.1
-1,3,-1:98.1
0,3,-1:98.1
1,3,-1:98.0
2,3,-1:98.1
3,3,-1:98.1
4,3,-1:98.1
5,3,-1:98.1
6,3,-1:2.0
-6,4,-1:2.0
-5,4,-1:98.1
-3,4,-1:98.1
-2,4,-1:98.1
-1,4,-1:98.0
0,4,-1:98.1
1,4,-1:98.0
2,4,-1:98.1
3,4,-1:98.1
5,4,-1:98.1
6,4,-1:2.0
-5,5,-1:98.1
-4,5,-1:98.1
-3,5,-1:98.1
-2,5,-1:3.0
-1,5,-1:3.0
0,5,-1:98.2
1,5,-1:98.0
2,5,-1:2.0
3,5,-1:98.1
4,5,-1:98.1
5,5,-1:98.1
-4,6,-1:2.0
-3,6,-1:17.0
-2,6,-1:98.1
-1,6,-1:98.1
0,6,-1:98.0
1,6,-1:2.0
2,6,-1:3.0
3,6,-1:3.0
4,6,-1:2.0
-3,7,-1:98.0
-2,7,-1:2.0
-1,7,-1:2.0
0,7,-1:98.0
1,7,-1:2.0
2,7,-1:2.0
3,7,-1:2.0
-2,8,-1:2.0
-1,8,-1:2.0
0,8,-1:2.0
1,8,-1:2.0
2,8,-1:2.0
-1,9,-1:2.0
0,9,-1:2.5
1,9,-1:2.0
1,-6,0:18.12
2,-6,0:18.12
3,-6,0:109.2
-5,-5,0:98.1
-3,-5,0:98.0
0,-5,0:18.12
1,-5,0:18.12
2,-5,0:18.12
3,-5,0:98.1
5,-5,0:98.1
-5,-4,0:44.5
-3,-4,0:44.5
0,-4,0:18.12
1,-4,0:18.12
2,-4,0:17.0
3,-4,0:44.5
5,-4,0:44.5
-5,-3,0:98.1
-4,-3,0:44.5
-3,-3,0:44.5
2,-3,0:18.12
3,-3,0:98.1
4,-3,0:44.5
5,-3,0:98.1
-6,-2,0:109.3
-4,-2,0:109.0
3,-2,0:98.1
4,-2,0:18.12
-1,-1,0:98.2
0,-1,0:98.1
1,-1,0:98.2
3,-1,0:18.12
4,-1,0:18.12
5,-1,0:18.12
-6,0,0:44.5
-5,0,0:44.5
-1,0,0:98.1
1,0,0:98.1
2,0,0:109.1
3,0,0:18.12
4,0,0:17.0
5,0,0:18.12
6,0,0:18.12
-6,1,0:44.5
-5,1,0:98.0
-4,1,0:109.1
-1,1,0:98.2
0,1,0:98.1
2,1,0:18.12
3,1,0:18.12
4,1,0:18.12
5,1,0:18.12
-5,2,0:98.2
-3,2,0:44.5
0,2,0:44.5
1,2,0:18.12
2,2,0:18.12
3,2,0:18.12
4,2,0:109.3
-6,3,0:109.0
-5,3,0:98.0
-4,3,0:44.5
-3,3,0:98.1
2,3,0:18.12
3,3,0:98.1
4,3,0:44.5
5,3,0:98.1
-5,4,0:44.5
-3,4,0:44.5
-2,4,0:109.0
-1,4,0:109.0
3,4,0:44.5
-5,5,0:98.1
-4,5,0:44.5
-3,5,0:98.1
-2,5,0:17.0
-1,5,0:17.0
2,5,0:44.5
3,5,0:98.1
4,5,0:44.5
5,5,0:98.1
-3,6,0:17.0
2,6,0:98.0
3,6,0:98.0
2,-6,1:18.12
-5,-5,1:98.0
-4,-5,1:109.2
-3,-5,1:98.1
0,-5,1:18.12
1,-5,1:18.12
2,-5,1:18.12
3,-5,1:98.1
4,-5,1:109.2
5,-5,1:98.1
0,-4,1:18.12
1,-4,1:18.12
2,-4,1:17.0
3,-4,1:109.0
4,-4,1:98.1
5,-4,1:109.1
-5,-3,1:98.1
-4,-3,1:109.3
1,-3,1:18.12
2,-3,1:18.12
3,-3,1:98.1
4,-3,1:109.3
5,-3,1:98.1
4,-2,1:18.12
-1,-1,1:98.0
0,-1,1:44.5
1,-1,1:98.0
3,-1,1:18.12
4,-1,1:18.12
5,-1,1:18.12
-1,0,1:44.5
2,0,1:18.12
3,0,1:18.12
4,0,1:17.0
5,0,1:18.12
-5,1,1:109.0
3,1,1:18.12
4,1,1:18.12
5,1,1:18.12
2,2,1:18.12
3,2,1:18.12
4,2,1:18.12
-5,3,1:98.1
-4,3,1:109.2
-3,3,1:98.1
3,3,1:98.1
4,3,1:109.2
5,3,1:98.1
-3,4,1:109.1
-2,4,1:98.0
3,4,1:109.0
4,4,1:98.1
-5,5,1:98.0
-4,5,1:109.3
-3,5,1:98.1
-2,5,1:17.0
-1,5,1:17.0
3,5,1:98.1
4,5,1:109.3
5,5,1:98.1
-3,6,1:17.0
-2,6,1:17.0
-3,-5,2:98.1
1,-5,2:18.12
2,-5,2:18.12
3,-5,2:98.1
1,-4,2:18.12
2,-4,2:17.0
-5,-3,2:98.1
1,-3,2:18.12
2,-3,2:18.12
3,-3,2:98.1
5,-3,2:98.1
-1,-1,2:98.2
1,-1,2:98.2
3,-1,2:18.12
4,-1,2:18.12
2,0,2:18.12
3,0,2:18.12
4,0,2:17.0
5,0,2:18.12
4,1,2:18.12
3,2,2:18.12
-5,3,2:98.1
-3,3,2:98.1
3,3,2:98.0
5,3,2:98.0
4,4,2:98.2
-5,5,2:98.1
-3,5,2:98.1
-2,5,2:17.0
5,5,2:98.1
-2,6,2:17.0
-2,7,2:18.4
-4,-5,3:109.2
-3,-5,3:98.2
2,-5,3:18.12
3,-5,3:98.2
-4,-4,3:98.0
-3,-4,3:109.1
1,-4,3:18.12
2,-4,3:18.12
3,-4,3:109.0
4,-4,3:98.0
5,-4,3:109.1
-5,-3,3:98.1
-4,-3,3:109.3
-3,-3,3:98.2
2,-3,3:18.12
3,-3,3:98.1
4,-3,3:109.3
5,-3,3:98.2
4,-1,3:18.12
3,0,3:18.12
4,0,3:17.0
5,0,3:18.12
4,1,3:18.12
-5,3,3:98.1
-4,3,3:109.2
-3,3,3:98.1
3,3,3:98.2
4,3,3:109.2
5,3,3:98.0
-3,4,3:109.1
3,4,3:109.0
4,4,3:98.0
5,4,3:109.1
-5,5,3:98.2
-4,5,3:109.3
-3,5,3:98.2
-2,5,3:17.0
5,5,3:98.2
-3,6,3:18.12
-2,6,3:17.0
-1,6,3:18.12
-2,7,3:18.12
-5,-5,4:44.5
-4,-5,4:109.2
-3,-5,4:109.2
3,-5,4:109.2
4,-5,4:109.2
-5,-4,4:109.0
-4,-4,4:98.2
-3,-4,4:98.0
2,-4,4:18.12
3,-4,4:98.1
4,-4,4:98.2
5,-4,4:109.1
-5,-3,4:109.0
-4,-3,4:98.0
-3,-3,4:44.5
3,-3,4:44.5
4,-3,4:98.0
5,-3,4:109.1
4,0,4:18.12
-5,3,4:109.0
-4,3,4:98.1
-3,3,4:44.5
3,3,4:44.5
5,3,4:44.5
-5,4,4:109.0
-4,4,4:98.2
-3,4,4:109.0
-2,4,4:18.12
3,4,4:98.0
4,4,4:98.2
5,4,4:109.1
-5,5,4:44.5
-4,5,4:109.3
-3,5,4:109.3
-2,5,4:17.0
-1,5,4:18.12
3,5,4:109.3
4,5,4:109.3
5,5,4:44.5
-3,6,4:18.12
-2,6,4:18.12
-1,6,4:18.12
-4,-4,5:44.5
-3,-4,5:98.0
-2,-4,5:109.0
2,-4,5:109.1
3,-4,5:98.1
4,-4,5:44.5
-4,-3,5:98.1
-3,-3,5:98.0
3,-3,5:98.0
4,-3,5:98.0
-4,-2,5:109.2
4,-2,5:109.2
-2,3,5:18.12
3,3,5:98.0
4,3,5:98.1
-4,4,5:44.5
-3,4,5:98.0
-2,4,5:18.12
2,4,5:109.1
3,4,5:98.1
4,4,5:44.5
-3,5,5:18.12
-2,5,5:17.0
-1,5,5:18.12
-2,6,5:18.12
-1,6,5:18.12
-3,-4,6:44.5
-2,-4,6:98.0
-1,-4,6:109.0
2,-4,6:98.0
3,-4,6:44.5
-4,-3,6:44.5
-3,-3,6:44.5
-2,-3,6:98.0
2,-3,6:98.0
3,-3,6:44.5
4,-3,6:44.5
-4,-2,6:98.0
-3,-2,6:98.0
-2,-2,6:98.0
-1,-2,6:109.0
1,-2,6:109.1
2,-2,6:98.0
3,-2,6:98.0
4,-2,6:98.0
-4,-1,6:109.2
-2,-1,6:109.2
2,-1,6:109.2
4,-1,6:109.2
2,1,6:109.3
-2,2,6:98.0
-1,2,6:18.12
1,2,6:109.1
2,2,6:98.0
3,2,6:98.1
4,2,6:98.1
-2,3,6:98.0
-1,3,6:18.12
0,3,6:18.12
2,3,6:98.0
3,3,6:44.5
4,3,6:44.5
-3,4,6:44.5
-2,4,6:18.12
-1,4,6:18.12
0,4,6:18.12
1,4,6:109.1
2,4,6:98.1
3,4,6:44.5
-3,5,6:18.12
-2,5,6:17.0
-1,5,6:17.0
0,5,6:18.12
-2,6,6:18.12
-1,6,6:18.12
-2,-4,7:44.5
-1,-4,7:98.0
0,-4,7:44.5
1,-4,7:98.1
2,-4,7:44.5
-2,-3,7:44.5
-1,-3,7:98.0
1,-3,7:98.0
2,-3,7:44.5
-4,-2,7:44.5
-3,-2,7:44.5
-2,-2,7:44.5
-1,-2,7:98.0
1,-2,7:98.0
2,-2,7:44.5
3,-2,7:44.5
4,-2,7:44.5
-4,-1,7:98.0
-3,-1,7:98.0
-2,-1,7:98.0
1,-1,7:98.0
2,-1,7:98.0
3,-1,7:98.0
4,-1,7:98.0
4,0,7:44.5
-3,1,7:98.0
-2,1,7:98.0
-1,1,7:98.0
1,1,7:98.0
2,1,7:98.0
3,1,7:98.0
4,1,7:98.0
-2,2,7:44.5
-1,2,7:98.0
1,2,7:98.0
3,2,7:44.5
4,2,7:44.5
-2,3,7:44.5
-1,3,7:98.0
1,3,7:98.0
2,3,7:44.5
-2,4,7:44.5
-1,4,7:98.1
0,4,7:44.5
1,4,7:98.1
2,4,7:44.5
-2,5,7:18.12
-1,5,7:17.0
0,5,7:18.12
-1,-4,8:44.5
0,-4,8:98.0
1,-4,8:44.5
-1,-3,8:44.5
0,-3,8:98.1
1,-3,8:44.5
-1,-2,8:44.5
0,-2,8:98.0
1,-2,8:44.5
-4,-1,8:44.5
-3,-1,8:44.5
-2,-1,8:44.5
1,-1,8:44.5
2,-1,8:44.5
3,-1,8:44.5
4,-1,8:44.5
-4,0,8:98.1
-3,0,8:98.1
-2,0,8:98.1
2,0,8:98.1
3,0,8:98.1
4,0,8:98.0
-3,1,8:44.5
-2,1,8:44.5
-1,1,8:44.5
1,1,8:44.5
2,1,8:44.5
3,1,8:44.5
4,1,8:44.5
-1,2,8:44.5
0,2,8:98.1
1,2,8:44.5
-1,3,8:44.5
0,3,8:98.1
1,3,8:44.5
-1,4,8:44.5
0,4,8:98.1
1,4,8:44.5
-1,5,8:17.0
0,5,8:18.4
-1,4,9:18.12
0,4,9:17.0
1,4,9:18.12
-2,5,9:18.12
-1,5,9:17.0
0,5,9:17.0
1,5,9:18.12
-1,6,9:18.12
0,6,9:18.12
0,4,10:17.0
-1,5,10:18.12
0,5,10:18.12
0,2,11:17.0
0,3,11:17.0
0,4,11:17.0
0,0,12:18.4
0,1,12:18.12
1,1,12:18.12
2,1,12:18.4
-1,2,12:18.12
0,2,12:17.0
1,2,12:18.12
2,2,12:18.12
-2,3,12:18.12
-1,3,12:18.12
0,3,12:18.12
-2,4,12:18.4
-1,4,12:18.12
0,4,12:18.12
0,-1,13:18.12
-1,0,13:18.12
0,0,13:17.0
1,0,13:18.12
2,0,13:18.12
-1,1,13:18.12
0,1,13:17.0
1,1,13:18.12
2,1,13:17.0
3,1,13:18.12
4,1,13:18.12
-2,2,13:18.12
-1,2,13:18.12
0,2,13:17.0
1,2,13:17.0
2,2,13:17.0
3,2,13:18.12
-2,3,13:18.12
-1,3,13:17.0
0,3,13:17.0
1,3,13:18.12
2,3,13:18.12
-3,4,13:18.12
-2,4,13:17.0
-1,4,13:17.0
0,4,13:18.12
1,4,13:18.12
-2,5,13:18.12
-1,5,13:18.12
0,5,13:18.12
0,-4,14:18.12
-1,-3,14:18.12
0,-3,14:18.12
1,-3,14:18.12
-2,-2,14:18.12
-1,-2,14:18.12
0,-2,14:18.12
1,-2,14:18.12
2,-2,14:18.12
3,-2,14:18.12
4,-2,14:18.12
-2,-1,14:18.12
-1,-1,14:18.12
0,-1,14:18.12
1,-1,14:18.12
2,-1,14:18.12
3,-1,14:18.12
4,-1,14:18.12
5,-1,14:18.12
-3,0,14:18.12
-2,0,14:18.12
-1,0,14:18.12
0,0,14:17.0
1,0,14:18.12
2,0,14:18.12
3,0,14:18.12
4,0,14:18.12
5,0,14:18.12
6,0,14:18.12
-3,1,14:18.12
-2,1,14:18.12
-1,1,14:18.12
0,1,14:18.12
1,1,14:18.12
2,1,14:17.0
3,1,14:17.0
4,1,14:17.0
5,1,14:18.12
6,1,14:18.12
7,1,14:18.4
-4,2,14:18.12
-3,2,14:18.12
-2,2,14:18.12
-1,2,14:18.12
0,2,14:18.12
1,2,14:18.12
2,2,14:18.12
3,2,14:18.12
4,2,14:18.12
5,2,14:18.12
6,2,14:18.12
-5,3,14:18.12
-4,3,14:18.12
-3,3,14:18.12
-2,3,14:18.12
-1,3,14:18.12
0,3,14:18.12
1,3,14:18.12
2,3,14:18.12
3,3,14:18.12
4,3,14:18.12
5,3,14:18.12
-5,4,14:18.12
-4,4,14:18.12
-3,4,14:18.12
-2,4,14:17.0
-1,4,14:18.12
0,4,14:18.12
1,4,14:18.12
2,4,14:18.12
3,4,14:18.12
4,4,14:18.12
-4,5,14:18.12
-3,5,14:18.12
-2,5,14:18.12
-1,5,14:18.12
0,5,14:18.12
-3,6,14:18.12
-2,6,14:18.12
-1,6,14:18.12
-2,7,14:18.12
0,-3,15:18.12
-1,-2,15:18.4
0,-2,15:18.12
1,-2,15:18.12
2,-2,15:18.12
-1,-1,15:18.12
0,-1,15:18.12
1,-1,15:18.12
2,-1,15:18.12
3,-1,15:18.4
4,-1,15:18.12
-2,0,15:18.12
-1,0,15:18.12
0,0,15:17.0
1,0,15:18.12
2,0,15:18.12
3,0,15:18.12
4,0,15:18.12
5,0,15:18.12
-2,1,15:18.12
-1,1,15:18.12
0,1,15:18.12
1,1,15:18.12
2,1,15:18.12
3,1,15:18.12
4,1,15:17.0
5,1,15:18.12
6,1,15:18.12
-3,2,15:18.12
-2,2,15:18.12
-1,2,15:18.12
0,2,15:18.12
1,2,15:18.12
2,2,15:18.12
3,2,15:18.12
4,2,15:18.12
5,2,15:18.12
-4,3,15:18.4
-3,3,15:18.12
-2,3,15:18.12
-1,3,15:18.12
0,3,15:18.12
1,3,15:18.12
2,3,15:18.12
3,3,15:18.12
-4,4,15:18.12
-3,4,15:18.12
-2,4,15:18.12
-1,4,15:18.12
0,4,15:18.12
-3,5,15:18.12
-2,5,15:18.12
-1,5,15:18.12
-2,6,15:18.4
0,-1,16:18.12
1,-1,16:18.12
2,-1,16:18.12
-1,0,16:18.12
0,0,16:18.12
1,0,16:18.12
2,0,16:18.12
3,0,16:18.12
4,0,16:18.12
0,1,16:18.12
1,1,16:18.12
2,1,16:18.12
3,1,16:18.12
4,1,16:18.12
5,1,16:18.12
-2,2,16:18.12
1,2,16:18.12
2,2,16:18.12
3,2,16:18.12
4,2,16:18.12
-3,3,16:18.12
-2,3,16:18.12
0,3,16:18.12
-2,4,16:18.12
0,0,17:18.12
2,0,17:18.12
4,1,17:18.12
-2,3,17:18.4
-3,2,16:106.8
-2,0,16:106.8
-1,6,15:106.4
-3,6,15:106.4
0,5,15:106.2
-4,5,15:106.8
2,4,15:106.4
1,4,15:106.4
-5,4,15:106.8
5,3,15:106.4
4,3,15:106.4
-5,3,15:106.8
6,2,15:106.4
-4,2,15:106.1
7,1,15:106.2
-3,1,15:106.1
6,0,15:106.2
-3,0,15:106.8
5,-1,15:106.2
-2,-1,15:106.1
4,-2,15:106.1
-2,-2,15:106.8
1,-3,15:106.1
-1,-3,15:106.1
-2,8,14:106.4
-1,7,14:106.4
-3,7,14:106.8
0,6,14:106.4
-4,6,14:106.8
4,5,14:106.4
3,5,14:106.4
2,5,14:106.4
1,5,14:106.2
-5,5,14:106.8
5,4,14:106.2
-6,4,14:106.8
6,3,14:106.2
-6,3,14:106.8
7,2,14:106.4
-4,1,14:106.8
7,0,14:106.2
-4,0,14:106.8
6,-1,14:106.2
-3,-1,14:106.8
5,-2,14:106.2
-3,-2,14:106.8
2,-3,14:106.1
-2,-3,14:106.8
-1,-4,14:106.8
0,-5,14:106.1
-2,8,13:106.4
-1,7,13:106.4
-3,7,13:106.8
0,6,13:106.4
-2,6,13:106.4
-4,6,13:106.8
2,5,13:106.4
1,5,13:106.2
-3,5,13:106.8
-5,5,13:106.8
5,4,13:106.2
2,4,13:106.2
-4,4,13:106.8
-6,4,13:106.8
6,3,13:106.2
-3,3,13:106.1
-6,3,13:106.8
7,2,13:106.4
4,2,13:106.2
-3,2,13:106.8
5,1,13:106.2
-2,1,13:106.1
7,0,13:106.2
4,0,13:106.1
3,0,13:106.2
-2,0,13:106.8
-4,0,13:106.8
6,-1,13:106.2
2,-1,13:106.1
1,-1,13:106.2
-1,-1,13:106.1
-3,-2,13:106.8
2,-3,13:106.1
-2,-3,13:106.8
-1,-4,13:106.8
0,-5,13:106.1
-2,8,12:106.4
-1,7,12:106.4
-3,7,12:106.8
0,6,12:106.4
-2,6,12:106.4
-4,6,12:106.8
2,5,12:106.4
1,5,12:106.2
0,5,12:106.4
-1,5,12:106.4
-2,5,12:106.4
-3,5,12:106.8
-5,5,12:106.8
5,4,12:106.2
2,4,12:106.2
-4,4,12:106.8
-6,4,12:106.8
1,3,12:106.4
-3,3,12:106.9
7,2,12:106.4
4,2,12:106.2
3,2,12:106.2
-2,2,12:106.8
-3,2,12:106.8
5,1,12:106.2
3,1,12:106.2
-1,1,12:106.8
-2,1,12:106.1
7,0,12:106.2
4,0,12:106.1
3,0,12:106.2
2,0,12:106.1
-2,0,12:106.8
-4,0,12:106.8
6,-1,12:106.2
2,-1,12:106.1
1,-1,12:106.2
0,-1,12:106.1
-1,-1,12:106.1
-3,-2,12:106.8
2,-3,12:106.1
-2,-3,12:106.8
-1,-4,12:106.8
0,-5,12:106.1
-2,8,11:106.4
0,6,11:106.4
-2,6,11:106.4
-4,6,11:106.8
2,5,11:106.4
1,5,11:106.2
0,5,11:106.4
-1,5,11:106.4
-2,5,11:106.4
-3,5,11:106.8
-5,5,11:106.8
5,4,11:106.2
2,4,11:106.2
1,4,11:106.2
-4,4,11:106.8
1,3,11:106.6
-3,3,11:106.9
7,2,11:106.4
3,2,11:106.2
1,2,11:106.2
-2,2,11:106.8
-3,2,11:106.8
3,1,11:106.2
-1,1,11:106.8
2,0,11:106.1
-2,0,11:106.8
2,-1,11:106.1
1,-1,11:106.2
0,-1,11:106.1
-1,-1,11:106.1
-3,-2,11:106.8
2,-3,11:106.1
-2,-3,11:106.8
-1,-4,11:106.8
0,-5,11:106.1
0,6,10:106.4
-1,6,10:106.4
-4,6,10:106.8
1,5,10:106.2
-2,5,10:106.4
-3,5,10:106.8
5,4,10:106.2
1,4,10:106.2
-4,4,10:106.8
1,3,10:106.6
-3,3,10:106.9
7,2,10:106.4
3,2,10:106.2
1,2,10:106.2
-2,2,10:106.8
-3,2,10:106.8
3,1,10:106.2
-1,1,10:106.8
2,0,10:106.1
1,-1,10:106.2
0,-1,10:106.1
-1,-1,10:106.1
-2,-3,10:106.8
0,7,9:106.4
-1,7,9:106.4
1,6,9:106.2
-2,6,9:106.4
-4,6,9:106.8
2,5,9:106.2
-3,5,9:106.8
2,4,9:106.2
1,3,9:106.6
-3,3,9:106.9
7,2,9:106.4
1,2,9:106.2
-2,2,9:106.8
-3,2,9:106.8
-1,1,9:106.8
-1,-1,9:106.1
0,7,8:106.4
-1,7,8:106.4
1,6,8:106.2
0,6,8:106.4
-1,6,8:106.4
-2,6,8:106.4
2,5,8:106.2
1,5,8:106.2
-3,5,8:106.8
-3,3,8:106.9
-2,2,8:106.8
-3,2,8:106.8
5,0,8:106.2
-5,0,8:106.8
0,7,7:106.4
-1,7,7:106.4
0,6,7:106.4
-1,6,7:106.4
-2,6,7:106.4
2,5,7:106.2
1,5,7:106.2
-3,5,7:106.8
0,3,7:106.8
-3,3,7:106.9
0,2,7:106.8
5,1,7:106.2
0,1,7:106.8
-4,1,7:106.8
5,0,7:106.2
3,0,7:106.4
2,0,7:106.4
1,0,7:106.4
-1,0,7:106.1
-2,0,7:106.1
-3,0,7:106.4
-5,0,7:106.8
5,-1,7:106.2
-1,-1,7:106.4
-5,-1,7:106.8
1,-5,7:106.1
-1,-5,7:106.1
0,7,6:106.4
-1,7,6:106.4
0,6,6:106.4
-3,6,6:106.8
2,5,6:106.4
1,5,6:106.2
-3,3,6:106.9
5,2,6:106.2
-3,2,6:106.8
5,1,6:106.2
4,1,6:106.1
3,1,6:106.1
0,1,6:106.8
-2,1,6:106.1
5,0,6:106.2
3,0,6:106.4
2,0,6:106.4
1,0,6:106.4
-1,0,6:106.1
-2,0,6:106.1
-3,0,6:106.4
-5,0,6:106.8
5,-1,6:106.2
-1,-1,6:106.4
-3,-1,6:106.4
-5,-1,6:106.8
5,-2,6:106.2
-5,-2,6:106.8
2,-5,6:106.1
1,-5,6:106.1
-2,-5,6:106.1
0,7,5:106.4
-1,7,5:106.4
-2,7,5:106.4
-3,6,5:106.4
3,5,5:106.4
2,5,5:106.4
1,5,5:106.2
5,3,5:106.2
2,3,5:106.8
-3,3,5:106.9
5,2,5:106.2
5,1,5:106.2
4,1,5:106.1
3,1,5:106.1
0,1,5:106.8
-2,1,5:106.1
5,0,5:106.2
3,0,5:106.4
2,0,5:106.4
-2,0,5:106.1
-3,0,5:106.4
-5,0,5:106.8
-1,-1,5:106.4
-3,-1,5:106.4
-5,-1,5:106.8
5,-2,5:106.2
-3,-2,5:106.4
-5,-2,5:106.8
3,-5,5:106.1
2,-5,5:106.1
1,-5,5:106.1
-2,-5,5:106.1
-3,-5,5:106.1
-1,7,4:106.4
-2,7,4:106.4
-3,7,4:106.4
2,5,4:106.4
2,4,4:106.8
2,3,4:106.8
5,2,4:106.2
-4,2,4:106.1
3,1,4:106.1
0,1,4:106.8
-2,1,4:106.1
5,0,4:106.2
2,0,4:106.4
-2,0,4:106.1
-3,0,4:106.4
-5,0,4:106.8
-3,-1,4:106.4
-5,-1,4:106.8
5,-2,4:106.2
4,-2,4:106.4
-3,-2,4:106.4
-4,-2,4:106.4
-5,-2,4:106.8
-2,-4,4:106.2
1,-5,4:106.1
-2,-5,4:106.1
-2,8,3:106.4
-1,7,3:106.4
-3,7,3:106.4
5,6,3:106.4
-5,6,3:106.4
6,5,3:106.2
2,5,3:106.4
-6,5,3:106.8
2,4,3:106.8
-5,4,3:106.1
6,3,3:106.2
2,3,3:106.8
-6,3,3:106.8
5,2,3:106.1
-3,2,3:106.1
-4,2,3:106.1
-5,2,3:106.1
3,1,3:106.1
0,1,3:106.8
-2,1,3:106.1
-5,0,3:106.8
-3,-1,3:106.4
-5,-1,3:106.8
5,-2,3:106.6
4,-2,3:106.4
3,-2,3:106.4
-3,-2,3:106.4
-5,-2,3:106.12
6,-3,3:106.2
-2,-3,3:106.2
-6,-3,3:106.8
0,-4,3:106.8
-2,-4,3:106.2
-5,-4,3:106.1
4,-5,3:106.1
1,-5,3:106.1
-2,-5,3:106.2
3,-6,3:106.1
2,-6,3:106.1
-3,-6,3:106.1
-2,8,2:106.4
-1,7,2:106.4
-3,7,2:106.4
5,6,2:106.4
-1,6,2:106.2
-3,6,2:106.4
-5,6,2:106.4
6,5,2:106.2
-6,5,2:106.8
5,4,2:106.4
2,4,2:106.8
-5,4,2:106.1
6,3,2:106.2
2,3,2:106.8
-6,3,2:106.8
5,2,2:106.1
-3,2,2:106.1
-4,2,2:106.1
-5,2,2:106.1
1,0,2:106.4
-1,0,2:106.4
-5,0,2:106.8
2,-1,2:106.2
-2,-1,2:106.8
-3,-1,2:106.4
-5,-1,2:106.8
5,-2,2:106.4
4,-2,2:106.4
3,-2,2:106.4
1,-2,2:106.1
-1,-2,2:106.1
-3,-2,2:106.4
-5,-2,2:106.12
6,-3,2:106.2
-2,-3,2:106.2
-6,-3,2:106.8
5,-4,2:106.1
0,-4,2:106.8
-5,-4,2:106.1
4,-5,2:106.1
-2,-5,2:106.2
3,-6,2:106.1
2,-6,2:106.1
1,-6,2:106.1
-3,-6,2:106.1
-2,8,1:106.4
-1,7,1:106.4
-2,7,1:106.4
-3,7,1:106.4
5,6,1:106.4
-1,6,1:106.2
-5,6,1:106.4
6,5,1:106.2
0,5,1:106.2
-6,5,1:106.8
5,4,1:106.4
2,4,1:106.8
-5,4,1:106.1
6,3,1:106.2
2,3,1:106.8
-6,3,1:106.8
5,2,1:106.1
-3,2,1:106.1
-5,2,1:106.1
1,0,1:106.4
-5,0,1:106.8
2,-1,1:106.2
-2,-1,1:106.8
-3,-1,1:106.4
-5,-1,1:106.8
5,-2,1:106.4
3,-2,1:106.4
1,-2,1:106.1
-1,-2,1:106.1
-3,-2,1:106.4
-5,-2,1:106.12
6,-3,1:106.2
-2,-3,1:106.2
-6,-3,1:106.8
-1,-4,1:106.8
-5,-4,1:106.1
6,-5,1:106.2
-1,-5,1:106.8
-2,-5,1:106.2
-6,-5,1:106.8
5,-6,1:106.1
3,-6,1:106.1
1,-6,1:106.1
0,-6,1:106.1
-3,-6,1:106.1
-5,-6,1:106.1
2,-7,1:106.1
1,9,0:31.1
-1,9,0:37.0
2,8,0:31.1
0,8,0:31.1
-1,8,0:31.1
-2,8,0:31.1
3,7,0:31.1
2,7,0:38.0
1,7,0:31.1
-1,7,0:31.1
-2,7,0:106.4
-3,7,0:106.4
5,6,0:106.4
4,6,0:31.1
-1,6,0:106.2
-4,6,0:31.1
-5,6,0:106.4
6,5,0:106.2
0,5,0:106.2
-6,5,0:106.8
6,4,0:31.1
5,4,0:106.4
2,4,0:106.8
-6,4,0:31.1
6,3,0:31.1
7,2,0:31.1
6,2,0:38.0
5,2,0:31.1
-6,2,0:37.0
-7,2,0:31.1
7,1,0:31.1
-7,1,0:38.0
-2,0,0:106.8
-7,0,0:31.1
7,-1,0:37.0
6,-1,0:31.1
2,-1,0:106.2
-2,-1,0:106.8
-3,-1,0:106.4
-5,-1,0:106.8
-7,-1,0:31.1
7,-2,0:31.1
6,-2,0:31.1
5,-2,0:31.1
1,-2,0:106.1
-1,-2,0:106.1
-3,-2,0:31.1
-5,-2,0:106.12
-7,-2,0:31.1
6,-3,0:31.1
-1,-3,0:31.1
-2,-3,0:106.2
-6,-3,0:31.1
6,-4,0:31.1
-1,-4,0:106.8
-2,-4,0:31.1
-6,-4,0:31.1
6,-5,0:106.2
-2,-5,0:106.2
-6,-5,0:106.8
5,-6,0:106.1
4,-6,0:31.1
0,-6,0:31.1
-2,-6,0:31.1
-3,-6,0:31.1
-4,-6,0:31.1
-5,-6,0:106.1
3,-7,0:31.1
2,-7,0:31.1
1,-7,0:106.1
0,-7,0:31.1
-1,-7,0:31.1
-2,-7,0:31.1
-3,-7,0:31.1
2,-8,0:31.1
1,-8,0:31.1
0,-8,0:31.1
1,-9,0:31.1
0,-9,0:31.1
