[META]
version=2.0
spawnOnBlockType=2
spawnSunlight=True
spawnDarkness=True
spawnWater=False
spawnLava=False
underFill=False
randomRotation=True
dig=True
tree=False
branch=False
needsFoundation=True
rarity=10
collisionPercentage=70
spawnElevationMin=0
spawnElevationMax=102
groupId=Ruins
groupFrequencyMin=20
groupFrequencyMax=35
groupSeperationMin=5
groupSeperationMax=60
branchLimit=6
spawnInBiome=Jungle
[DATA]
-2,0,0:98.2
-3,1,0:98.2
-4,0,0:98.2
-4,2,0:98.2
-2,2,0:98.2
2,0,0:98.2
0,0,-2:1
-3,0,-2:1
-2,0,-2:1
-1,0,-2:1
1,0,-2:1
3,0,-2:1
2,0,-2:1
2,-1,-2:1
1,-1,-2:1
0,-1,-2:1
-1,-1,-2:1
-2,-1,-2:1
-2,1,-2:1
-1,1,-2:1
0,1,-2:1
1,1,-2:1
2,1,-2:1
3,1,-2:2
3,-1,-2:2
-3,-1,-2:2
-3,1,-2:2
2,2,-2:2
1,2,-2:2
-2,2,-2:2
-1,2,-2:2
0,2,-2:2
-2,-2,-2:2
-1,-2,-2:2
0,-2,-2:2
1,-2,-2:2
2,-2,-2:2
-2,-1,-1:98.2
-2,1,-1:98.2
-1,1,-1:98.2
1,-1,-1:98.2
2,-1,-1:98.2
2,1,-1:98.2
-3,-1,-1:98.1
-3,0,-1:98.1
-3,1,-1:98.1
-2,0,-1:98.1
-1,0,-1:98.1
-1,-1,-1:98.1
0,-1,-1:98.1
0,1,-1:98.1
1,1,-1:98.1
1,0,-1:98.1
2,0,-1:98.1
3,0,-1:98.1
3,-1,-1:98.1
3,1,-1:98.1
-2,0,1:98.2
2,0,1:98.2
-2,0,2:98.1
2,0,2:98.2
2,0,3:98.1
0,0,4:98.2
1,0,4:98.1
3,0,4:98.1
2,0,4:98.2
-2,0,-3:3
-1,0,-3:3
0,0,-3:3
1,0,-3:3
2,0,-3:3
1,-1,-3:3
0,-1,-3:3
-1,-1,-3:3
-1,1,-3:3
0,1,-3:3
1,1,-3:3
