[META]
version=2.0
spawnOnBlockType=2
spawnSunlight=True
spawnDarkness=True
spawnWater=False
spawnLava=False
underFill=False
randomRotation=True
dig=True
tree=False
branch=False
needsFoundation=True
rarity=10
collisionPercentage=10
spawnElevationMin=0
spawnElevationMax=102
groupId=Ruins
groupFrequencyMin=20
groupFrequencyMax=35
groupSeperationMin=5
groupSeperationMax=60
branchLimit=6
spawnInBiome=Jungle
[DATA]
-1,-5,0:98.1
0,-5,0:98.1
1,-5,0:98.0
-2,-4,0:98.0
-1,-4,0:98.0
0,-4,0:98.1
1,-4,0:98.0
2,-4,0:98.1
-2,-3,0:98.0
-1,-3,0:98.1
0,-3,0:98.1
1,-3,0:98.0
2,-3,0:109.1
-4,-2,0:17.0
-3,-2,0:98.0
-2,-2,0:98.0
-1,-2,0:98.0
0,-2,0:9
1,-2,0:98.0
2,-2,0:98.0
3,-2,0:98.0
-3,-1,0:44.5
-1,-1,0:98.1
0,-1,0:9
1,-1,0:98.1
3,-1,0:44.5
-3,0,0:98.1
-2,0,0:44.5
-1,0,0:109.3
0,0,0:9
1,0,0:109.3
2,0,0:44.5
3,0,0:98.1
1,5,0:31.1
0,5,0:31.1
-1,5,0:31.1
2,4,0:31.2
-2,4,0:31.1
3,3,0:31.1
-3,3,0:31.1
4,2,0:31.1
-2,2,0:106.4
-4,2,0:37
5,1,0:31.2
4,1,0:31.1
0,1,0:106.4
-1,1,0:106.2
-4,1,0:31.1
-5,1,0:37
5,0,0:31.1
4,0,0:31.1
-4,0,0:31.2
-5,0,0:106.8
5,-1,0:31.1
4,-1,0:31.1
-4,-1,0:31.1
-5,-1,0:31.1
-5,-2,0:31.1
-6,-2,0:106.8
5,-3,0:31.1
4,-3,0:31.1
3,-3,0:106.2
-3,-3,0:106.8
-4,-3,0:31.1
-5,-3,0:31.1
4,-4,0:31.1
3,-4,0:106.2
-3,-4,0:106.8
-4,-4,0:31.1
-5,-4,0:106.8
-3,-5,0:106.8
-4,-5,0:106.1
2,-6,0:31.1
1,-6,0:31.1
0,-6,0:106.1
-1,-6,0:31.1
-2,-6,0:31.1
-1,-2,-5:1
0,-2,-5:1
1,-2,-5:1
-1,-1,-5:1
0,-1,-5:1
1,-1,-5:1
-1,0,-5:1
0,0,-5:1
1,0,-5:1
0,1,-5:1
-2,-3,-4:3
-1,-3,-4:1
0,-3,-4:3
1,-3,-4:1
2,-3,-4:3
-2,-2,-4:1
-1,-2,-4:3
0,-2,-4:3
1,-2,-4:3
2,-2,-4:1
-2,-1,-4:3
-1,-1,-4:3
0,-1,-4:3
1,-1,-4:3
2,-1,-4:1
-2,0,-4:1
-1,0,-4:3
0,0,-4:3
1,0,-4:3
2,0,-4:1
-1,1,-4:3
0,1,-4:3
1,1,-4:3
0,2,-4:3
-2,-4,-3:3
-1,-4,-3:3
0,-4,-3:1
1,-4,-3:3
2,-4,-3:3
-3,-3,-3:3
-2,-3,-3:3
-1,-3,-3:3
0,-3,-3:3
1,-3,-3:3
2,-3,-3:3
3,-3,-3:1
-3,-2,-3:3
-2,-2,-3:3
-1,-2,-3:3
0,-2,-3:3
1,-2,-3:3
2,-2,-3:3
3,-2,-3:3
-3,-1,-3:3
-2,-1,-3:3
-1,-1,-3:3
0,-1,-3:3
1,-1,-3:3
2,-1,-3:3
3,-1,-3:3
-3,0,-3:3
-2,0,-3:3
-1,0,-3:3
0,0,-3:3
1,0,-3:3
2,0,-3:3
3,0,-3:3
-2,1,-3:3
-1,1,-3:3
0,1,-3:3
1,1,-3:3
2,1,-3:1
-1,2,-3:3
0,2,-3:3
1,2,-3:3
0,3,-3:3
-2,-5,-2:3
-1,-5,-2:3
0,-5,-2:3
1,-5,-2:3
2,-5,-2:3
-3,-4,-2:3
-2,-4,-2:3
-1,-4,-2:3
0,-4,-2:3
1,-4,-2:3
2,-4,-2:3
3,-4,-2:3
-4,-3,-2:3
-3,-3,-2:3
-2,-3,-2:3
-1,-3,-2:3
0,-3,-2:3
1,-3,-2:3
2,-3,-2:3
3,-3,-2:3
4,-3,-2:3
-4,-2,-2:3
-3,-2,-2:3
-2,-2,-2:3
-1,-2,-2:3
0,-2,-2:3
1,-2,-2:3
2,-2,-2:3
3,-2,-2:3
4,-2,-2:3
-4,-1,-2:3
-3,-1,-2:3
-2,-1,-2:98.1
-1,-1,-2:3
0,-1,-2:3
1,-1,-2:3
2,-1,-2:98.1
3,-1,-2:3
4,-1,-2:3
-4,0,-2:3
-3,0,-2:3
-2,0,-2:98.1
-1,0,-2:3
0,0,-2:98.1
1,0,-2:3
2,0,-2:98.1
3,0,-2:3
4,0,-2:3
-4,1,-2:3
-3,1,-2:3
-2,1,-2:3
-1,1,-2:98.1
0,1,-2:98.1
1,1,-2:98.1
2,1,-2:98.1
3,1,-2:3
4,1,-2:3
-3,2,-2:3
-2,2,-2:3
-1,2,-2:98.1
0,2,-2:98.1
1,2,-2:98.1
2,2,-2:3
3,2,-2:3
-2,3,-2:3
-1,3,-2:3
0,3,-2:3
1,3,-2:3
2,3,-2:3
-1,4,-2:3
0,4,-2:3
1,4,-2:3
-2,-6,-1:2
-1,-6,-1:2
0,-6,-1:2
1,-6,-1:2
2,-6,-1:2
-3,-5,-1:2
-2,-5,-1:98.0
-1,-5,-1:98.0
0,-5,-1:98.0
1,-5,-1:98.1
2,-5,-1:98.1
3,-5,-1:2
-4,-4,-1:2
-3,-4,-1:98.1
-2,-4,-1:3
-1,-4,-1:3
0,-4,-1:3
1,-4,-1:3
2,-4,-1:3
3,-4,-1:98.1
4,-4,-1:2
-5,-3,-1:2
-4,-3,-1:2
-3,-3,-1:98.1
-2,-3,-1:3
-1,-3,-1:3
0,-3,-1:3
1,-3,-1:3
2,-3,-1:3
3,-3,-1:98.1
4,-3,-1:2
5,-3,-1:2
-5,-2,-1:2
-4,-2,-1:17.0
-3,-2,-1:98.0
-2,-2,-1:98.1
-1,-2,-1:3
0,-2,-1:98.1
1,-2,-1:3
2,-2,-1:98.1
3,-2,-1:98.1
4,-2,-1:2
5,-2,-1:2
-5,-1,-1:2
-4,-1,-1:2
-3,-1,-1:98.1
-2,-1,-1:89
-1,-1,-1:98.1
0,-1,-1:98.1
1,-1,-1:98.1
2,-1,-1:89
3,-1,-1:98.1
4,-1,-1:2
5,-1,-1:2
-5,0,-1:2
-4,0,-1:2
-3,0,-1:98.1
-2,0,-1:98.1
-1,0,-1:98.1
0,0,-1:9
1,0,-1:98.1
2,0,-1:98.1
3,0,-1:98.0
4,0,-1:2
5,0,-1:2
-5,1,-1:2
-4,1,-1:2
-3,1,-1:98.1
-2,1,-1:98.1
-1,1,-1:9
0,1,-1:9
1,1,-1:9
2,1,-1:98.1
3,1,-1:98.0
4,1,-1:2
5,1,-1:2
-4,2,-1:2
-3,2,-1:98.0
-2,2,-1:98.1
-1,2,-1:9
0,2,-1:9
1,2,-1:9
2,2,-1:98.1
3,2,-1:98.0
4,2,-1:2
-3,3,-1:2
-2,3,-1:98.1
-1,3,-1:98.1
0,3,-1:98.1
1,3,-1:98.1
2,3,-1:98.1
3,3,-1:2
-2,4,-1:2
-1,4,-1:98.0
0,4,-1:98.0
1,4,-1:98.0
2,4,-1:2
-1,5,-1:2
0,5,-1:2
1,5,-1:2
-2,-5,1:44.5
-1,-5,1:98.2
0,-5,1:98.1
1,-5,1:98.2
2,-5,1:44.5
-2,-4,1:98.0
-1,-4,1:98.0
0,-4,1:98.1
1,-4,1:98.0
2,-4,1:98.1
-2,-3,1:98.1
-1,-3,1:98.1
0,-3,1:9
1,-3,1:98.1
2,-3,1:98.1
-4,-2,1:17.0
-2,-2,1:98.0
-1,-2,1:98.1
0,-2,1:9
1,-2,1:98.1
2,-2,1:98.0
3,-2,1:44.5
-3,-1,1:109.0
-2,-1,1:98.0
-1,-1,1:98.1
0,-1,1:98.1
1,-1,1:98.0
2,-1,1:98.1
3,-1,1:109.1
-3,0,1:44.5
-2,0,1:109.3
-1,0,1:44.5
1,0,1:44.5
2,0,1:109.3
3,0,1:44.5
-2,2,1:106.4
0,1,1:106.4
-1,1,1:106.2
-4,1,1:106.4
-5,0,1:106.8
-5,-1,1:106.4
-6,-2,1:106.8
3,-3,1:106.2
-3,-3,1:106.8
-5,-3,1:106.1
3,-4,1:106.2
-3,-4,1:106
-5,-4,1:106.8
-3,-5,1:106.8
-4,-5,1:106.1
0,-6,1:106.1
-2,-6,1:106.1
-2,-5,2:44.5
-1,-5,2:109.2
1,-5,2:109.2
2,-5,2:44.5
-4,-4,2:18
-2,-4,2:98.0
-1,-4,2:98.0
0,-4,2:98.1
1,-4,2:98.0
2,-4,2:98.0
-2,-3,2:98.2
-1,-3,2:98.1
0,-3,2:9
1,-3,2:98.1
2,-3,2:98.2
-5,-2,2:18
-4,-2,2:17.0
-2,-2,2:44.5
-1,-2,2:98.0
0,-2,2:98.1
1,-2,2:98.0
2,-2,2:44.5
-1,-1,2:98.2
0,-1,2:23.3
1,-1,2:98.2
-2,2,2:106.4
0,1,2:106.4
-1,1,2:106.2
-4,1,2:106.4
1,0,2:106.2
-1,0,2:106.2
-3,0,2:106.8
-5,0,2:106.8
2,-1,2:106.2
-5,-1,2:106.4
-6,-2,2:106.8
3,-3,2:106.2
-3,-3,2:106.8
-5,-3,2:106.1
3,-4,2:106.2
-3,-4,2:106.1
-5,-4,2:106.8
0,-5,2:106.1
-3,-5,2:106.8
-4,-5,2:106.1
-2,-6,2:106.1
-2,-5,3:18
-4,-4,3:18
-1,-4,3:44.5
0,-4,3:109.2
1,-4,3:44.5
-1,-3,3:109.0
0,-3,3:98.1
1,-3,3:109.1
-5,-2,3:18
-4,-2,3:17.0
-3,-2,3:17.0
-1,-2,3:109.0
0,-2,3:98.1
1,-2,3:109.1
-1,-1,3:44.5
0,-1,3:109.3
1,-1,3:44.5
-4,0,3:18
-2,1,3:18
-2,2,3:106.4
0,1,3:106.4
-1,1,3:106.2
-4,1,3:106.4
1,0,3:106.2
-1,0,3:106.2
-3,0,3:106.8
-5,0,3:106.8
-5,-1,3:106.4
2,-2,3:106.2
-6,-2,3:106.8
-5,-3,3:106.1
-3,-4,3:106.1
0,-5,3:106.1
-3,-5,3:106.8
-4,-5,3:106.1
-2,-6,3:106.1
-2,-5,4:18
-4,-4,4:18
0,-4,4:18
0,-3,4:109.2
-5,-2,4:18
-3,-2,4:17.0
-2,-2,4:17.0
0,-2,4:109.3
1,-2,4:18
-4,0,4:18
0,0,4:18
-2,1,4:18
-2,2,4:106.4
0,1,4:106.4
-1,1,4:106.2
-4,1,4:106.4
1,0,4:106.2
-1,0,4:106.2
-3,0,4:106.8
-5,0,4:106.8
-5,-1,4:106.4
2,-2,4:106.2
-6,-2,4:106.8
1,-3,4:106.1
-5,-3,4:106.1
-1,-4,4:106.1
-3,-4,4:106.1
0,-5,4:106.1
-3,-5,4:106.8
-4,-5,4:106.1
-2,-6,4:106.1
-2,-5,5:18
-4,-4,5:18
-2,-4,5:18
0,-4,5:18
-3,-3,5:18
-2,-3,5:18
-1,-3,5:18
-5,-2,5:18
-4,-2,5:18
-3,-2,5:18
-2,-2,5:17.0
-1,-2,5:18
0,-2,5:18
1,-2,5:18
-3,-1,5:18
-2,-1,5:18
-1,-1,5:18
-4,0,5:18
-2,0,5:18
0,0,5:18
-2,1,5:18
-2,2,5:106.4
0,1,5:106.4
-1,1,5:106.2
-4,1,5:106.4
1,0,5:106.2
-1,0,5:106.2
-3,0,5:106.8
-5,0,5:106.8
2,-2,5:106.2
-6,-2,5:106.8
1,-3,5:106.1
0,-3,5:106.1
-5,-3,5:106.1
-1,-4,5:106.1
-3,-4,5:106.1
0,-5,5:106.1
-3,-5,5:106.8
-4,-5,5:106.1
-2,-6,5:106.1
-2,-4,6:18
-3,-3,6:18
-2,-3,6:18
-1,-3,6:18
-4,-2,6:18
-3,-2,6:18
-2,-2,6:18
-1,-2,6:18
0,-2,6:18
-3,-1,6:18
-2,-1,6:18
-1,-1,6:18
-2,0,6:18
-1,0,6:106.2
-3,0,6:106.8
0,-3,6:106.1
-1,-4,6:106.1
-3,-4,6:106.1
-2,-2,7:18
