[META]
version=2.0
spawnOnBlockType=2
spawnSunlight=True
spawnDarkness=True
spawnWater=False
spawnLava=False
underFill=False
randomRotation=True
dig=True
tree=False
branch=False
needsFoundation=True
rarity=10
collisionPercentage=70
spawnElevationMin=0
spawnElevationMax=102
groupId=Ruins
groupFrequencyMin=20
groupFrequencyMax=35
groupSeperationMin=5
groupSeperationMax=60
branchLimit=6
spawnInBiome=Jungle
[DATA]
-2,-2,0:43.0
-1,-2,0:43.0
0,-2,0:43.0
1,-2,0:43.0
-2,-1,0:43.0
-1,-1,0:98.0
0,-1,0:98.0
1,-1,0:43.0
-2,0,0:43.0
-1,0,0:98.0
0,0,0:98.0
1,0,0:43.0
-2,1,0:43.0
-1,1,0:43.0
0,1,0:43.0
1,1,0:43.0
-3,1,0:106.8
-3,0,0:106.8
-3,-1,0:106.8
-3,-3,-3:3
-2,-3,-3:3
-1,-3,-3:3
0,-3,-3:3
1,-3,-3:3
2,-3,-3:3
-3,-2,-3:3
-2,-2,-3:3
-1,-2,-3:3
0,-2,-3:3
1,-2,-3:3
2,-2,-3:3
-3,-1,-3:3
-2,-1,-3:3
-1,-1,-3:3
0,-1,-3:3
1,-1,-3:3
2,-1,-3:3
-3,0,-3:3
-2,0,-3:3
-1,0,-3:3
0,0,-3:3
1,0,-3:3
2,0,-3:3
-3,1,-3:3
-2,1,-3:3
-1,1,-3:3
0,1,-3:3
1,1,-3:3
2,1,-3:3
-3,2,-3:3
-2,2,-3:3
-1,2,-3:3
0,2,-3:3
1,2,-3:3
-3,-3,-2:3
-2,-3,-2:3
-1,-3,-2:3
0,-3,-2:3
1,-3,-2:3
2,-3,-2:3
-3,-2,-2:3
-2,-2,-2:3
-1,-2,-2:3
0,-2,-2:3
1,-2,-2:3
2,-2,-2:3
-3,-1,-2:3
-2,-1,-2:3
-1,-1,-2:3
0,-1,-2:3
1,-1,-2:3
2,-1,-2:3
-3,0,-2:3
-2,0,-2:3
-1,0,-2:3
0,0,-2:3
1,0,-2:3
2,0,-2:3
-3,1,-2:3
-2,1,-2:3
-1,1,-2:3
0,1,-2:3
1,1,-2:3
2,1,-2:3
-3,2,-2:3
-2,2,-2:3
-1,2,-2:3
0,2,-2:3
1,2,-2:3
2,2,-2:3
-3,-3,-1:43.0
-2,-3,-1:43.0
-1,-3,-1:43.0
0,-3,-1:43.0
1,-3,-1:43.0
2,-3,-1:43.0
-3,-2,-1:43.0
-2,-2,-1:3
-1,-2,-1:3
0,-2,-1:3
1,-2,-1:3
2,-2,-1:43.0
-3,-1,-1:43.0
-2,-1,-1:3
-1,-1,-1:3
0,-1,-1:3
1,-1,-1:3
2,-1,-1:43.0
-3,0,-1:43.0
-2,0,-1:3
-1,0,-1:3
0,0,-1:3
1,0,-1:3
2,0,-1:43.0
-3,1,-1:43.0
-2,1,-1:3
-1,1,-1:3
0,1,-1:3
1,1,-1:3
2,1,-1:43.0
-3,2,-1:43.0
-2,2,-1:43.0
-1,2,-1:43.0
0,2,-1:43.0
1,2,-1:43.0
2,2,-1:43.0
-1,-2,1:98.1
0,-2,1:98.0
-2,-1,1:98.0
-1,-1,1:98.0
0,-1,1:98.0
1,-1,1:98.0
-2,0,1:98.1
-1,0,1:98.0
0,0,1:98.0
1,0,1:98.0
-1,1,1:98.0
0,1,1:98.1
-2,1,1:106.4
-3,0,1:106.8
-1,-1,2:98.1
0,-1,2:98.0
-1,0,2:98.0
0,0,2:98.1
-1,1,2:106.4
-2,0,2:106.8
-1,-1,3:98.1
0,-1,3:98.0
0,0,3:98.1
-1,1,3:106.4
-2,0,3:106.8
-1,-1,4:98.2
0,-1,4:98.2
0,0,4:98.2
-1,2,4:106.4
-1,1,4:106.4
-2,0,4:106.8
-1,-1,5:98.0
0,-1,5:98.0
-1,0,5:98.0
0,0,5:98.0
-1,2,5:106.4
-1,1,5:106.4
-2,0,5:106.8
-1,-1,6:98.0
0,-1,6:98.0
-1,0,6:98.0
0,0,6:98.0
-1,2,6:106.4
-1,1,6:106.4
-2,1,6:106.4
-2,0,6:106.8
-1,-2,7:98.0
0,-2,7:98.0
-2,-1,7:98.0
-1,-1,7:98.0
0,-1,7:98.0
1,-1,7:98.0
-2,0,7:98.0
-1,0,7:98.0
0,0,7:98.0
1,0,7:98.0
-1,1,7:98.0
0,1,7:98.0
-1,2,7:106.4
-2,1,7:106.4
-2,-2,8:43.0
-1,-2,8:43.0
0,-2,8:43.0
1,-2,8:43.0
-2,-1,8:43.0
-1,-1,8:44.0
0,-1,8:44.0
1,-1,8:43.0
-2,0,8:43.0
-1,0,8:44.0
0,0,8:44.0
1,0,8:43.0
-2,1,8:43.0
-1,1,8:43.0
0,1,8:43.0
1,1,8:43.0
-3,-3,9:44.0
-2,-3,9:44.0
-1,-3,9:44.0
0,-3,9:44.0
1,-3,9:44.0
2,-3,9:44.0
-3,-2,9:44.0
-2,-2,9:44.0
-1,-2,9:44.0
0,-2,9:44.0
1,-2,9:44.0
2,-2,9:44.0
-3,-1,9:44.0
-2,-1,9:44.0
1,-1,9:44.0
2,-1,9:44.0
-3,0,9:44.0
-2,0,9:44.0
1,0,9:44.0
2,0,9:44.0
-3,1,9:44.0
-2,1,9:44.0
-1,1,9:44.0
0,1,9:44.0
1,1,9:44.0
2,1,9:44.0
-3,2,9:44.0
-2,2,9:44.0
-1,2,9:44.0
0,2,9:44.0
1,2,9:44.0
2,2,9:44.0
