[META]
version=2.0
spawnOnBlockType=12,2
spawnSunlight=True
spawnDarkness=True
spawnWater=False
spawnLava=False
underFill=True
randomRotation=True
dig=True
tree=True
branch=False
needsFoundation=True
rarity=10
collisionPercentage=5
spawnElevationMin=0
spawnElevationMax=200
spawnInBiome=DesertOasis
[DATA]
0,0,0:17.1
0,-1,0:17.1
0,-2,0:17.1
0,-3,0:17.1
0,1,0:17.1
0,2,0:17.1
0,3,0:17.1
1,0,0:17.1
2,0,0:17.1
3,0,0:17.1
-1,0,0:17.1
-2,0,0:17.1
-3,0,0:17.1
-2,1,0:17.1
-1,1,0:17.1
-1,2,0:17.1
-1,-1,0:17.1
-1,-2,0:17.1
-2,-1,0:17.1
1,-2,0:17.1
1,-1,0:17.1
2,-1,0:17.1
1,1,0:17.1
2,1,0:17.1
1,2,0:17.1
0,4,0:17.1
-4,0,0:17.1
0,-4,0:17.1
4,0,0:17.1
-1,-1,1:17.1
0,-1,1:17.1
0,0,1:17.1
-1,0,1:17.1
0,1,1:17.1
1,1,1:17.1
1,0,1:17.1
1,-1,1:17.1
-1,1,1:17.1
2,0,1:17.1
3,0,1:17.1
0,2,1:17.1
0,3,1:17.1
-2,0,1:17.1
-3,0,1:17.1
0,-2,1:17.1
0,-3,1:17.1
-2,0,2:17.1
-1,0,2:17.1
0,0,2:17.1
1,0,2:17.1
2,0,2:17.1
0,-2,2:17.1
0,-1,2:17.1
0,1,2:17.1
0,2,2:17.1
-1,1,2:17.1
-1,-1,2:17.1
1,-1,2:17.1
1,1,2:17.1
-1,0,3:17.1
0,0,3:17.1
1,0,3:17.1
0,-1,3:17.1
0,1,3:17.1
-1,-1,3:17.1
1,-1,3:17.1
1,1,3:17.1
-1,1,3:17.1
-1,0,4:17.1
-1,-1,4:17.1
-1,1,4:17.1
0,1,4:17.1
0,0,4:17.1
0,-1,4:17.1
1,-1,4:17.1
1,0,4:17.1
1,1,4:17.1
-1,0,5:17.1
-1,-1,5:17.1
0,-1,5:17.1
0,0,5:17.1
-1,1,5:17.1
0,1,5:17.1
1,1,5:17.1
1,0,5:17.1
1,-1,5:17.1
-1,-1,6:17.1
-1,0,6:17.1
-1,1,6:17.1
0,1,6:17.1
0,0,6:17.1
0,-1,6:17.1
1,-1,6:17.1
1,0,6:17.1
1,1,6:17.1
-1,0,7:17.1
0,-1,7:17.1
0,0,7:17.1
0,1,7:17.1
1,0,7:17.1
0,-2,7:18.0
-2,0,7:18.0
2,0,7:18.0
0,2,7:18.0
-1,3,7:18.0
3,1,7:18.0
1,-3,7:18.0
-3,0,7:18.0
1,-4,7:18.0
0,-5,7:18.0
4,1,7:18.0
5,2,7:18.0
-1,4,7:18.0
-2,5,7:18.0
-4,0,7:18.0
-4,-1,7:18.0
-5,-1,7:18.0
4,0,7:18.0
5,-1,7:18.0
5,-2,7:18.0
-1,0,8:17.1
0,0,8:17.1
0,-1,8:17.1
1,0,8:17.1
0,1,8:17.1
-1,0,9:17.1
0,0,9:17.1
1,0,9:17.1
0,1,9:17.1
0,-1,9:17.1
0,2,9:18.0
-1,3,9:18.0
1,-2,9:18.0
1,-3,9:18.0
-2,0,9:18.0
-3,0,9:18.0
-3,-1,9:18.0
2,1,9:18.0
3,0,9:18.0
-4,-1,9:18.0
-5,-1,9:18.0
-5,-2,9:18.0
-1,4,9:18.0
-1,5,9:18.0
0,5,9:18.0
-1,6,9:18.0
-2,5,9:18.0
-3,6,9:18.0
4,0,9:18.0
5,0,9:18.0
5,1,9:18.0
6,1,9:18.0
4,-1,9:18.0
4,-2,9:18.0
1,-4,9:18.0
0,-4,9:18.0
0,-5,9:18.0
-1,-5,9:18.0
2,-4,9:18.0
0,-6,9:18.0
-6,0,9:18.0
1,6,9:18.0
-1,0,10:17.1
0,0,10:17.1
0,-1,10:17.1
1,0,10:17.1
0,1,10:17.1
-1,0,11:17.1
0,0,11:17.1
1,0,11:17.1
0,1,11:17.1
0,-1,11:17.1
-1,0,12:17.1
0,0,12:17.1
1,0,12:17.1
0,-1,12:17.1
0,1,12:17.1
0,-2,12:17.1
0,2,12:17.1
-2,0,12:17.1
2,0,12:17.1
-3,-1,12:18.0
-1,2,12:18.0
2,-1,12:18.0
0,-3,12:18.0
1,3,12:18.0
-3,1,12:18.0
3,1,12:18.0
-2,0,13:17.1
0,-2,13:17.1
2,0,13:17.1
0,2,13:17.1
-1,2,13:17.1
3,1,13:17.1
-1,-3,13:17.1
-3,0,13:17.1
3,-1,13:17.1
3,-2,13:17.1
0,0,13:17.1
0,-1,13:18.0
-1,0,13:18.0
0,1,13:18.0
1,0,13:18.0
4,-3,13:18.0
2,-3,13:18.0
0,-4,13:18.0
-2,-4,13:18.0
-4,-1,13:18.0
-4,1,13:18.0
-2,3,13:18.0
-1,3,13:18.0
-3,1,13:18.0
2,2,13:18.0
4,0,13:18.0
4,2,13:18.0
5,-2,13:18.0
2,3,13:18.0
1,-5,13:18.0
-2,4,13:18.0
-1,-3,14:17.1
-3,0,14:17.1
-1,2,14:17.1
3,-2,14:17.1
3,1,14:17.1
0,0,14:17.1
-3,-1,14:18.0
-4,1,14:18.0
0,2,14:18.0
-2,0,14:18.0
0,-2,14:18.0
2,0,14:18.0
3,-1,14:18.0
4,-3,14:18.0
0,-4,14:18.0
-2,-4,14:18.0
-2,3,14:18.0
3,2,14:18.0
4,1,14:18.0
-1,-4,15:17.1
-1,-3,15:17.1
-3,0,15:17.1
-4,0,15:17.1
-1,2,15:17.1
-1,3,15:17.1
3,1,15:17.1
4,1,15:17.1
3,-2,15:17.1
3,-3,15:17.1
0,0,15:17.1
-4,-1,15:18.0
-4,1,15:18.0
0,3,15:18.0
-2,3,15:18.0
0,-4,15:18.0
-2,-4,15:18.0
4,-4,15:18.0
2,-3,15:18.0
5,0,15:18.0
4,2,15:18.0
2,0,15:18.0
0,-1,15:18.0
-1,0,15:18.0
-5,0,15:18.0
-4,0,16:17.1
-5,1,16:17.1
-4,-1,16:17.1
-1,-4,16:17.1
-1,-5,16:17.1
0,-5,16:17.1
3,-3,16:17.1
4,-3,16:17.1
4,1,16:17.1
4,2,16:17.1
-1,3,16:17.1
0,3,16:17.1
0,4,16:17.1
-6,2,16:17.1
0,0,16:17.1
-5,-2,16:18.0
1,5,16:18.0
1,2,16:18.0
-2,4,16:18.0
-1,2,16:18.0
1,-1,16:18.0
-1,-1,16:18.0
-1,-3,16:18.0
1,-6,16:18.0
-2,-6,16:18.0
5,-4,16:18.0
3,-4,16:18.0
5,0,16:18.0
3,3,16:18.0
5,3,16:18.0
-4,2,16:18.0
-6,0,16:18.0
-7,2,16:18.0
-6,3,16:18.0
-6,-3,16:18.0
-2,-4,16:18.0
-3,0,16:18.0
3,-2,16:18.0
3,1,16:18.0
6,-3,16:18.0
-3,5,16:18.0
3,4,16:18.0
0,0,17:17.1
-1,-1,17:17.1
1,1,17:17.1
-1,1,17:17.1
-6,2,17:17.1
-5,3,17:18.0
0,4,17:17.1
1,4,17:17.1
0,-5,17:17.1
0,-6,17:17.1
4,-3,17:17.1
5,-4,17:17.1
4,2,17:17.1
5,3,17:17.1
2,-2,17:17.1
-4,-2,17:17.1
-5,-3,17:17.1
-4,-1,17:17.1
-4,0,17:18.0
-5,1,17:18.0
-1,3,17:18.0
0,3,17:18.0
-1,-4,17:18.0
-1,-5,17:18.0
3,-3,17:18.0
4,1,17:18.0
6,4,17:18.0
6,2,17:18.0
4,4,17:18.0
2,3,17:18.0
-1,5,17:18.0
-4,2,17:18.0
-6,4,17:18.0
-7,1,17:18.0
-6,-4,17:18.0
-4,-4,17:18.0
-6,-2,17:18.0
1,-7,17:18.0
-1,-7,17:18.0
1,-5,17:18.0
5,-5,17:18.0
6,-3,17:18.0
1,-1,17:18.0
-2,-2,17:18.0
-2,2,17:18.0
0,-2,17:18.0
2,1,17:18.0
0,2,17:18.0
1,5,17:18.0
2,6,17:18.0
-5,-4,18:17.1
-5,-3,18:17.1
0,-7,18:17.1
0,-6,18:17.1
1,-7,18:17.1
5,-4,18:17.1
6,-5,18:17.1
2,-2,18:17.1
2,-3,18:17.1
2,-4,18:17.1
4,-3,18:17.1
4,-2,18:17.1
1,-4,18:17.1
-4,-2,18:17.1
-3,-3,18:17.1
-6,2,18:17.1
-6,1,18:17.1
-7,1,18:17.1
-5,3,18:17.1
-4,4,18:17.1
-4,2,18:17.1
0,0,18:17.1
-1,-1,18:17.1
-1,-2,18:17.1
-1,1,18:17.1
-1,2,18:17.1
-2,2,18:17.1
1,1,18:17.1
2,1,18:17.1
4,2,18:17.1
4,1,18:17.1
5,0,18:17.1
5,3,18:17.1
6,4,18:17.1
0,4,18:17.1
-1,5,18:17.1
2,5,18:17.1
-4,-5,18:18.0
-5,-6,18:18.0
2,-7,18:18.0
2,-6,18:18.0
0,-8,18:18.0
-1,-6,18:18.0
3,-4,18:18.0
5,-2,18:18.0
6,-4,18:18.0
7,-5,18:18.0
6,-6,18:18.0
4,-5,18:18.0
1,-3,18:18.0
3,-1,18:18.0
1,-1,18:18.0
1,-5,18:18.0
-2,-4,18:18.0
-6,-3,18:18.0
-6,-2,18:18.0
-4,-1,18:18.0
-3,-1,18:18.0
-3,2,18:18.0
-2,3,18:18.0
0,3,18:18.0
-2,0,18:18.0
2,2,18:18.0
2,0,18:18.0
4,3,18:18.0
6,-1,18:18.0
6,1,18:18.0
6,3,18:18.0
7,5,18:18.0
5,5,18:18.0
3,5,18:18.0
1,6,18:18.0
-2,6,18:18.0
-3,5,18:18.0
-5,5,18:18.0
-6,3,18:18.0
-7,2,18:18.0
-7,0,18:18.0
-5,0,18:18.0
-1,-8,18:18.0
3,6,18:18.0
0,7,18:18.0
-3,-6,18:18.0
0,-5,18:18.0
1,4,18:18.0
-7,0,19:18.0
-7,1,19:18.0
-7,2,19:18.0
-6,1,19:18.0
-5,1,19:18.0
-5,3,19:18.0
-6,4,19:18.0
-4,4,19:18.0
-4,5,19:18.0
-4,2,19:18.0
-3,2,19:18.0
-3,1,19:18.0
-2,2,19:18.0
-2,3,19:18.0
0,4,19:18.0
-1,5,19:18.0
-2,6,19:18.0
0,6,19:18.0
-1,2,19:18.0
-1,1,19:18.0
0,0,19:18.0
-1,-1,19:18.0
-1,-2,19:18.0
-3,-3,19:18.0
-4,-2,19:18.0
-5,-3,19:18.0
-5,-4,19:18.0
-5,-5,19:18.0
-4,-5,19:18.0
0,-6,19:18.0
0,-7,19:18.0
2,-7,19:18.0
1,-7,19:18.0
-1,-7,19:18.0
3,-7,19:18.0
2,-6,19:18.0
1,-4,19:18.0
0,-5,19:18.0
2,-4,19:18.0
2,-3,19:18.0
2,-2,19:18.0
1,-2,19:18.0
3,-2,19:18.0
4,-2,19:18.0
4,-3,19:18.0
5,-4,19:18.0
6,-5,19:18.0
6,-6,19:18.0
7,-4,19:18.0
4,-7,19:18.0
-6,-6,19:18.0
-6,2,19:18.0
-7,3,19:18.0
-6,5,19:18.0
-7,6,19:18.0
-2,7,19:18.0
1,7,19:18.0
2,5,19:18.0
3,6,19:18.0
4,6,19:18.0
4,7,19:18.0
5,5,19:18.0
6,4,19:18.0
5,3,19:18.0
4,2,19:18.0
4,1,19:18.0
5,0,19:18.0
2,1,19:18.0
1,1,19:18.0
2,0,19:18.0
6,-1,19:18.0
7,0,19:18.0
6,3,19:18.0
2,4,19:18.0
1,5,19:18.0
0,0,20:18.0
-1,-1,20:18.0
0,-2,20:18.0
1,-3,20:18.0
-1,-4,20:18.0
0,-5,20:18.0
2,-4,20:18.0
4,-3,20:18.0
3,-3,20:18.0
3,-1,20:18.0
2,-2,20:18.0
2,0,20:18.0
1,1,20:18.0
-1,1,20:18.0
-3,-1,20:18.0
-3,0,20:18.0
-3,1,20:18.0
-4,-2,20:18.0
-3,-2,20:18.0
-3,-3,20:18.0
-5,-3,20:18.0
-5,1,20:18.0
-5,0,20:18.0
-6,-1,20:18.0
-5,2,20:18.0
-4,2,20:18.0
-6,2,20:18.0
-5,3,20:18.0
-3,3,20:18.0
-3,2,20:18.0
-2,2,20:18.0
-2,3,20:18.0
-1,4,20:18.0
0,4,20:18.0
0,2,20:18.0
-1,2,20:18.0
1,2,20:18.0
2,3,20:18.0
2,4,20:18.0
3,4,20:18.0
3,3,20:18.0
3,2,20:18.0
2,1,20:18.0
3,1,20:18.0
-1,5,20:18.0
-3,5,20:18.0
-4,4,20:18.0
-3,-4,20:18.0
-4,-5,20:18.0
2,5,20:18.0
-1,-1,21:18.0
-2,-1,21:18.0
-2,-2,21:18.0
-1,-2,21:18.0
0,0,21:18.0
-1,1,21:18.0
-2,2,21:18.0
-3,1,21:18.0
-4,0,21:18.0
0,2,21:18.0
1,3,21:18.0
1,1,21:18.0
2,1,21:18.0
2,0,21:18.0
1,-1,21:18.0
-2,3,21:18.0
-2,4,21:18.0
-3,3,21:18.0
-2,-3,21:18.0
1,-2,21:18.0
2,-2,21:18.0
-4,2,21:18.0
0,0,22:18.0
-1,-1,22:18.0
-1,1,22:18.0
-2,2,22:18.0
-2,-2,22:18.0
1,-1,22:18.0
2,-2,22:18.0
1,1,22:18.0
2,2,22:18.0
0,0,23:18.0
-1,-1,23:18.0
1,1,23:18.0
1,-1,23:18.0
-1,1,23:18.0
0,0,24:18.0
