[META]
version=2.0
spawnOnBlockType=2
spawnSunlight=True
spawnDarkness=True
spawnWater=False
spawnLava=False
underFill=False
randomRotation=True
dig=True
tree=False
branch=False
needsFoundation=True
rarity=1
collisionPercentage=70
spawnElevationMin=0
spawnElevationMax=102
groupId=Ruins
groupFrequencyMin=20
groupFrequencyMax=35
groupSeperationMin=5
groupSeperationMax=60
branchLimit=6
spawnInBiome=All
[DATA]
-2,0,0:98.1
-1,0,0:44.5
0,0,0:98.1
-2,1,0:44.5
0,1,0:44.5
-2,2,0:98.1
-1,2,0:44.5
0,2,0:98.1
0,3,0:31.1
-1,3,0:31.1
-2,3,0:31.1
1,2,0:31.1
-3,2,0:31.1
2,1,0:31.1
1,1,0:31.1
-3,1,0:31.1
3,0,0:31.1
2,0,0:31.2
-3,0,0:31.1
3,-1,0:31.1
-1,-1,0:83
-2,-1,0:31.1
3,-2,0:31.1
0,-2,0:83
-1,-2,0:31.1
2,-3,0:31.1
1,-3,0:31.2
0,-3,0:31.1
0,-1,-4:1
1,-1,-4:1
-1,0,-4:1
0,0,-4:1
0,-2,-3:3
1,-2,-3:3
0,-1,-3:3
1,-1,-3:1
-1,0,-3:3
0,0,-3:3
1,0,-3:3
-2,1,-3:3
-1,1,-3:3
0,1,-3:3
-1,2,-3:3
1,-3,-2:3
0,-2,-2:3
1,-2,-2:3
2,-2,-2:3
-1,-1,-2:3
0,-1,-2:3
1,-1,-2:3
2,-1,-2:3
-2,0,-2:3
-1,0,-2:3
0,0,-2:3
1,0,-2:3
2,0,-2:3
-2,1,-2:3
-1,1,-2:98.1
0,1,-2:3
1,1,-2:3
-2,2,-2:3
-1,2,-2:3
0,2,-2:3
0,-3,-1:2
1,-3,-1:2
2,-3,-1:2
-1,-2,-1:2
0,-2,-1:2
1,-2,-1:9
2,-2,-1:9
3,-2,-1:2
-2,-1,-1:2
-1,-1,-1:2
0,-1,-1:9
1,-1,-1:9
2,-1,-1:9
3,-1,-1:2
-3,0,-1:2
-2,0,-1:98.1
-1,0,-1:98.1
0,0,-1:98.1
1,0,-1:9
2,0,-1:2
3,0,-1:2
-3,1,-1:2
-2,1,-1:98.1
-1,1,-1:89
0,1,-1:98.1
1,1,-1:2
2,1,-1:2
-3,2,-1:2
-2,2,-1:98.1
-1,2,-1:98.1
0,2,-1:98.1
1,2,-1:2
-2,3,-1:2
-1,3,-1:2
0,3,-1:2
-2,0,1:98.1
-1,0,1:44.5
0,0,1:98.1
-2,1,1:44.5
0,1,1:44.5
-2,2,1:98.1
-1,2,1:44.5
0,2,1:98.1
-1,-1,1:83
-2,0,2:44.5
-1,0,2:109.2
0,0,2:44.5
-2,1,2:109.0
-1,1,2:98.0
0,1,2:109.1
-2,2,2:44.5
-1,2,2:109.3
0,2,2:44.5
-1,-1,2:83
