[META]
version=2.0
spawnOnBlockType=2
spawnSunlight=True
spawnDarkness=True
spawnWater=False
spawnLava=False
underFill=False
randomRotation=True
dig=True
tree=False
branch=False
needsFoundation=True
rarity=1
collisionPercentage=50
spawnElevationMin=0
spawnElevationMax=102
groupId=Ruins
groupFrequencyMin=20
groupFrequencyMax=35
groupSeperationMin=5
groupSeperationMax=60
branchLimit=6
spawnInBiome=All
[DATA]
-1,-3,0:17.1
-1,-2,0:13
0,-2,0:17.1
-2,-1,0:109.0
-1,-1,0:13
0,-1,0:17.1
1,-1,0:109.0
-2,0,0:17.1
-1,0,0:17.1
0,0,0:17.1
1,0,0:17.1
2,0,0:17.1
-3,1,0:17.1
-2,1,0:109.0
-1,1,0:17.1
1,1,0:109.0
0,2,0:31.2
-1,2,0:31.2
-2,2,0:31.2
2,1,0:31.2
-3,0,0:31.2
2,-1,0:31.2
-4,-1,0:31.2
-2,-2,0:31.2
0,-3,0:31.2
-1,0,-4:3
0,0,-4:17.1
0,1,-4:3
-1,-1,-3:3
0,-1,-3:17.1
1,-1,-3:3
-2,0,-3:3
-1,0,-3:17.1
0,0,-3:17.1
1,0,-3:17.1
-2,1,-3:3
-1,1,-3:3
0,1,-3:17.1
1,1,-3:3
-1,2,-3:3
0,2,-3:3
-1,-2,-2:3
0,-2,-2:17.1
1,-2,-2:3
-3,-1,-2:3
-2,-1,-2:17.1
-1,-1,-2:17.1
0,-1,-2:17.1
1,-1,-2:3
2,-1,-2:3
-3,0,-2:3
-2,0,-2:17.0
-1,0,-2:17.0
0,0,-2:17.1
1,0,-2:17.1
2,0,-2:3
-3,1,-2:17.1
-2,1,-2:17.1
-1,1,-2:17.0
0,1,-2:17.1
1,1,-2:3
2,1,-2:3
-2,2,-2:3
-1,2,-2:17.1
0,2,-2:3
1,2,-2:17.1
1,3,-2:3
-2,-3,-1:17.1
-1,-3,-1:17.1
1,-3,-1:17.1
-3,-2,-1:17.1
-2,-2,-1:2
-1,-2,-1:3
0,-2,-1:17.0
1,-2,-1:2
2,-2,-1:17.1
-3,-1,-1:2
-2,-1,-1:17.0
-1,-1,-1:3
0,-1,-1:17.0
1,-1,-1:3
2,-1,-1:2
3,-1,-1:17.1
-4,0,-1:17.1
-3,0,-1:2
-2,0,-1:3
-1,0,-1:17.0
0,0,-1:3
1,0,-1:17.0
2,0,-1:17.0
3,0,-1:17.1
-3,1,-1:17.0
-2,1,-1:17.0
-1,1,-1:17.0
0,1,-1:2
1,1,-1:17.0
2,1,-1:2
-2,2,-1:2
-1,2,-1:2
0,2,-1:2
1,2,-1:17.1
-1,3,-1:17.1
1,3,-1:17.1
-1,-1,1:98.1
0,-1,1:98.0
1,-1,1:98.0
-1,0,1:98.1
0,0,1:17.1
1,0,1:98.1
-1,1,1:98.1
0,1,1:98.1
1,1,1:98.1
1,-2,1:106.1
-2,-1,2:44.5
-1,-1,2:98.1
1,-1,2:98.0
0,0,2:17.1
-2,1,2:44.5
-1,1,2:98.1
1,1,2:98.1
0,-1,2:106
1,-2,2:106.1
0,-4,2:106.1
-1,-1,3:109.2
1,-1,3:109.2
-1,0,3:23.4
0,0,3:17.1
-1,1,3:109.3
0,1,3:17.1
1,1,3:109.3
-1,3,3:106.8
0,-1,3:106.1
0,-4,3:106.1
-1,0,4:44.5
0,0,4:44.5
1,0,4:44.5
0,1,4:17.1
-1,3,4:106.8
1,1,4:106.2
-1,1,4:106.8
0,-1,4:106.1
-3,-1,4:106.1
0,-4,4:106.1
0,0,5:17.1
0,1,5:17.1
-1,3,5:106.8
3,1,5:106.4
1,0,5:106.2
-1,0,5:106.8
0,-1,5:106.1
-3,-1,5:106.1
0,-4,5:106.1
0,0,6:17.1
1,3,6:106.4
-1,3,6:106.8
3,1,6:106.4
0,1,6:106.4
-3,1,6:106.8
1,0,6:106.2
-1,0,6:106.8
0,-1,6:106.1
-3,-1,6:106.1
0,-4,6:106.1
0,0,7:17.1
0,4,7:106.4
1,3,7:106.4
-1,3,7:106.8
3,1,7:106.4
0,1,7:106.4
-3,1,7:106.8
1,0,7:106.2
-1,0,7:106.8
0,-1,7:106.1
-3,-1,7:106.1
-2,-2,7:106.1
0,-4,7:106.1
0,0,8:17.1
0,4,8:106.4
1,3,8:106.4
-1,3,8:106.8
2,2,8:106.2
3,1,8:106.4
-3,1,8:106.8
4,0,8:106.2
-1,0,8:106.8
-4,0,8:106.8
3,-1,8:106.2
0,-1,8:106.1
-3,-1,8:106.1
2,-2,8:106.2
-2,-2,8:106.1
1,-3,8:106.2
-1,-3,8:106.1
0,-4,8:106.1
0,-3,9:18
-1,-2,9:18
0,-2,9:18
1,-2,9:18
-2,-1,9:18
-1,-1,9:18
0,-1,9:18
1,-1,9:18
2,-1,9:18
-3,0,9:18
-2,0,9:18
-1,0,9:18
0,0,9:17.1
1,0,9:18
2,0,9:18
3,0,9:18
-2,1,9:18
-1,1,9:18
0,1,9:18
1,1,9:18
2,1,9:18
-1,2,9:18
0,2,9:18
1,2,9:18
0,3,9:18
0,4,9:106.4
1,3,9:106.4
-1,3,9:106.8
2,2,9:106.2
-2,2,9:106.8
3,1,9:106.4
-3,1,9:106.8
4,0,9:106.2
-4,0,9:106.8
3,-1,9:106.2
-3,-1,9:106.1
2,-2,9:106.2
-2,-2,9:106.1
1,-3,9:106.2
-1,-3,9:106.1
0,-4,9:106.1
0,-2,10:18
-1,-1,10:18
0,-1,10:18
1,-1,10:18
-2,0,10:18
-1,0,10:18
0,0,10:18
1,0,10:18
2,0,10:18
-1,1,10:18
0,1,10:18
1,1,10:18
0,2,10:18
