[META]
version=2.0
spawnOnBlockType=2
spawnSunlight=True
spawnDarkness=True
spawnWater=False
spawnLava=False
underFill=False
randomRotation=True
dig=True
tree=False
branch=False
needsFoundation=True
rarity=30
collisionPercentage=5
spawnElevationMin=0
spawnElevationMax=102
groupId=Ruins
groupFrequencyMin=20
groupFrequencyMax=35
groupSeperationMin=5
groupSeperationMax=60
branchLimit=6
spawnInBiome=All
[DATA]
0,0,-11:1.5
1,0,-11:1.5
2,0,-11:1.5
3,0,-11:1.5
0,1,-11:1.5
1,1,-11:1.5
2,1,-11:1.5
3,1,-11:1.5
0,2,-11:14.5
1,2,-11:14.5
2,2,-11:1.5
3,2,-11:1.5
-1,-1,-10:1.5
0,-1,-10:1.5
1,-1,-10:1.5
2,-1,-10:1.5
3,-1,-10:14.5
4,-1,-10:14.5
-1,0,-10:1.5
0,0,-10:1.5
1,0,-10:1.5
2,0,-10:1.5
3,0,-10:1.5
4,0,-10:1.5
-1,1,-10:1.5
0,1,-10:1.5
1,1,-10:1.5
2,1,-10:1.5
3,1,-10:1.5
4,1,-10:1.5
-1,2,-10:14.5
0,2,-10:14.5
1,2,-10:1.5
2,2,-10:1.5
3,2,-10:1.5
4,2,-10:1.5
-1,3,-10:14.5
0,3,-10:14.5
1,3,-10:1.5
2,3,-10:1.5
3,3,-10:1.5
4,3,-10:1.5
-2,-2,-9:1.5
-1,-2,-9:1.5
0,-2,-9:1.5
1,-2,-9:1.5
2,-2,-9:1.5
3,-2,-9:14.5
4,-2,-9:14.5
5,-2,-9:14.5
-2,-1,-9:1.5
-1,-1,-9:1.5
0,-1,-9:1.5
1,-1,-9:1.5
2,-1,-9:1.5
3,-1,-9:14.5
4,-1,-9:14.5
5,-1,-9:14.5
-2,0,-9:1.5
-1,0,-9:1.5
0,0,-9:1.5
1,0,-9:1.5
2,0,-9:1.5
3,0,-9:1.5
4,0,-9:1.5
5,0,-9:16.5
-2,1,-9:1.5
-1,1,-9:1.5
0,1,-9:1.5
1,1,-9:1.5
2,1,-9:1.5
3,1,-9:1.5
4,1,-9:1.5
5,1,-9:1.5
-2,2,-9:1.5
-1,2,-9:1.5
0,2,-9:1.5
1,2,-9:1.5
2,2,-9:1.5
3,2,-9:1.5
4,2,-9:1.5
5,2,-9:1.5
-2,3,-9:1.5
-1,3,-9:1.5
0,3,-9:1.5
1,3,-9:1.5
2,3,-9:1.5
3,3,-9:1.5
4,3,-9:1.5
5,3,-9:1.5
-2,4,-9:1.5
-1,4,-9:1.5
0,4,-9:1.5
1,4,-9:16.5
2,4,-9:1.5
3,4,-9:1.5
4,4,-9:1.5
5,4,-9:1.5
0,-4,-8:3.5
1,-4,-8:3.5
2,-4,-8:3.5
3,-4,-8:3.5
-3,-3,-8:1.5
-2,-3,-8:1.5
-1,-3,-8:1.5
0,-3,-8:1.5
1,-3,-8:1.5
2,-3,-8:1.5
3,-3,-8:1.5
4,-3,-8:1.5
5,-3,-8:1.5
6,-3,-8:1.5
-3,-2,-8:1.5
-2,-2,-8:1.5
-1,-2,-8:1.5
0,-2,-8:1.5
1,-2,-8:1.5
2,-2,-8:1.5
3,-2,-8:1.5
4,-2,-8:1.5
5,-2,-8:1.5
6,-2,-8:1.5
-3,-1,-8:1.5
-2,-1,-8:1.5
-1,-1,-8:1.5
0,-1,-8:1.5
1,-1,-8:1.5
2,-1,-8:1.5
3,-1,-8:1.5
4,-1,-8:1.5
5,-1,-8:1.5
6,-1,-8:1.5
-3,0,-8:1.5
-2,0,-8:1.5
-1,0,-8:1.5
0,0,-8:1.5
1,0,-8:1.5
2,0,-8:1.5
3,0,-8:1.5
4,0,-8:1.5
5,0,-8:1.5
6,0,-8:1.5
-3,1,-8:1.5
-2,1,-8:1.5
-1,1,-8:1.5
0,1,-8:1.5
1,1,-8:1.5
2,1,-8:1.5
3,1,-8:1.5
4,1,-8:1.5
5,1,-8:1.5
6,1,-8:16.5
-3,2,-8:1.5
-2,2,-8:1.5
-1,2,-8:1.5
0,2,-8:1.5
1,2,-8:1.5
2,2,-8:1.5
3,2,-8:1.5
4,2,-8:1.5
5,2,-8:1.5
6,2,-8:1.5
-3,3,-8:1.5
-2,3,-8:1.5
-1,3,-8:1.5
0,3,-8:1.5
1,3,-8:1.5
2,3,-8:1.5
3,3,-8:1.5
4,3,-8:1.5
5,3,-8:1.5
6,3,-8:1.5
-3,4,-8:1.5
-2,4,-8:1.5
-1,4,-8:1.5
0,4,-8:1.5
1,4,-8:1.5
2,4,-8:1.5
3,4,-8:1.5
4,4,-8:1.5
5,4,-8:1.5
6,4,-8:1.5
-3,5,-8:1.5
-2,5,-8:1.5
-1,5,-8:1.5
0,5,-8:16.5
1,5,-8:16.5
2,5,-8:16.5
3,5,-8:16.5
4,5,-8:1.5
5,5,-8:1.5
6,5,-8:1.5
3,6,-8:16.5
2,-5,-7:3.5
-4,-4,-7:1.5
-3,-4,-7:1.5
-2,-4,-7:1.5
-1,-4,-7:1.5
0,-4,-7:1.5
1,-4,-7:1.5
2,-4,-7:1.5
3,-4,-7:1.5
4,-4,-7:1.5
5,-4,-7:1.5
6,-4,-7:1.5
7,-4,-7:1.5
-4,-3,-7:1.5
-3,-3,-7:1.5
-2,-3,-7:1.5
-1,-3,-7:1.5
0,-3,-7:1.5
1,-3,-7:1.5
2,-3,-7:1.5
3,-3,-7:1.5
4,-3,-7:1.5
5,-3,-7:1.5
6,-3,-7:1.5
7,-3,-7:1.5
-5,-2,-7:3.5
-4,-2,-7:1.5
-3,-2,-7:1.5
-2,-2,-7:1.5
-1,-2,-7:1.5
0,-2,-7:1.5
1,-2,-7:1.5
2,-2,-7:1.5
3,-2,-7:1.5
4,-2,-7:1.5
5,-2,-7:1.5
6,-2,-7:1.5
7,-2,-7:1.5
-5,-1,-7:3.5
-4,-1,-7:1.5
-3,-1,-7:1.5
-2,-1,-7:1.5
-1,-1,-7:1.5
0,-1,-7:1.5
1,-1,-7:1.5
2,-1,-7:1.5
3,-1,-7:1.5
4,-1,-7:1.5
5,-1,-7:1.5
6,-1,-7:1.5
7,-1,-7:1.5
-4,0,-7:1.5
-3,0,-7:1.5
-2,0,-7:1.5
-1,0,-7:1.5
0,0,-7:1.5
1,0,-7:1.5
2,0,-7:1.5
3,0,-7:1.5
4,0,-7:1.5
5,0,-7:1.5
6,0,-7:1.5
7,0,-7:1.5
-4,1,-7:16.5
-3,1,-7:1.5
-2,1,-7:1.5
-1,1,-7:1.5
0,1,-7:1.5
1,1,-7:1.5
2,1,-7:1.5
3,1,-7:1.5
4,1,-7:1.5
5,1,-7:1.5
6,1,-7:1.5
7,1,-7:1.5
-4,2,-7:16.5
-3,2,-7:1.5
-2,2,-7:1.5
-1,2,-7:1.5
0,2,-7:1.5
1,2,-7:1.5
2,2,-7:1.5
3,2,-7:1.5
4,2,-7:1.5
5,2,-7:1.5
6,2,-7:1.5
7,2,-7:1.5
-4,3,-7:16.5
-3,3,-7:1.5
-2,3,-7:1.5
-1,3,-7:1.5
0,3,-7:1.5
1,3,-7:1.5
2,3,-7:1.5
3,3,-7:1.5
4,3,-7:1.5
5,3,-7:1.5
6,3,-7:1.5
7,3,-7:1.5
-4,4,-7:16.5
-3,4,-7:1.5
-2,4,-7:1.5
-1,4,-7:1.5
0,4,-7:1.5
1,4,-7:1.5
2,4,-7:1.5
3,4,-7:1.5
4,4,-7:1.5
5,4,-7:1.5
6,4,-7:1.5
7,4,-7:1.5
-4,5,-7:1.5
-3,5,-7:1.5
-2,5,-7:1.5
-1,5,-7:1.5
0,5,-7:1.5
1,5,-7:1.5
2,5,-7:1.5
3,5,-7:1.5
4,5,-7:1.5
5,5,-7:1.5
6,5,-7:1.5
7,5,-7:1.5
-4,6,-7:1.5
-3,6,-7:1.5
-2,6,-7:1.5
-1,6,-7:1.5
0,6,-7:16.5
1,6,-7:16.5
2,6,-7:16.5
3,6,-7:1.5
4,6,-7:1.5
5,6,-7:1.5
6,6,-7:1.5
7,6,-7:1.5
0,-6,-6:3.5
1,-6,-6:3.5
-5,-5,-6:1.5
-4,-5,-6:1.5
-3,-5,-6:1.5
-2,-5,-6:1.5
-1,-5,-6:1.5
0,-5,-6:1.5
1,-5,-6:1.5
2,-5,-6:1.5
3,-5,-6:1.5
4,-5,-6:1.5
5,-5,-6:1.5
6,-5,-6:1.5
7,-5,-6:1.5
8,-5,-6:1.5
-5,-4,-6:1.5
-4,-4,-6:1.5
-3,-4,-6:1.5
-2,-4,-6:1.5
-1,-4,-6:1.5
0,-4,-6:1.5
1,-4,-6:1.5
2,-4,-6:1.5
3,-4,-6:1.5
4,-4,-6:1.5
5,-4,-6:1.5
6,-4,-6:1.5
7,-4,-6:1.5
8,-4,-6:1.5
-6,-3,-6:3.5
-5,-3,-6:1.5
-4,-3,-6:1.5
-3,-3,-6:1.5
-2,-3,-6:1.5
-1,-3,-6:1.5
0,-3,-6:1.5
1,-3,-6:1.5
2,-3,-6:1.5
3,-3,-6:1.5
4,-3,-6:1.5
5,-3,-6:1.5
6,-3,-6:1.5
7,-3,-6:1.5
8,-3,-6:1.5
-6,-2,-6:3.5
-5,-2,-6:1.5
-4,-2,-6:1.5
-3,-2,-6:1.5
-2,-2,-6:1.5
-1,-2,-6:1.5
0,-2,-6:1.5
1,-2,-6:1.5
2,-2,-6:1.5
3,-2,-6:1.5
4,-2,-6:1.5
5,-2,-6:1.5
6,-2,-6:1.5
7,-2,-6:1.5
8,-2,-6:1.5
-5,-1,-6:1.5
-4,-1,-6:1.5
-3,-1,-6:1.5
-2,-1,-6:1.5
-1,-1,-6:1.5
0,-1,-6:1.5
1,-1,-6:1.5
2,-1,-6:1.5
3,-1,-6:1.5
4,-1,-6:1.5
5,-1,-6:1.5
6,-1,-6:1.5
7,-1,-6:1.5
8,-1,-6:1.5
-5,0,-6:1.5
-4,0,-6:1.5
-3,0,-6:1.5
-2,0,-6:1.5
-1,0,-6:1.5
0,0,-6:1.5
1,0,-6:1.5
2,0,-6:1.5
3,0,-6:1.5
4,0,-6:1.5
5,0,-6:1.5
6,0,-6:1.5
7,0,-6:1.5
8,0,-6:1.5
-5,1,-6:1.5
-4,1,-6:1.5
-3,1,-6:1.5
-2,1,-6:1.5
-1,1,-6:1.5
0,1,-6:1.5
1,1,-6:1.5
2,1,-6:1.5
3,1,-6:1.5
4,1,-6:1.5
5,1,-6:1.5
6,1,-6:1.5
7,1,-6:1.5
8,1,-6:1.5
-5,2,-6:16.5
-4,2,-6:1.5
-3,2,-6:1.5
-2,2,-6:1.5
-1,2,-6:1.5
0,2,-6:1.5
1,2,-6:1.5
2,2,-6:1.5
3,2,-6:1.5
4,2,-6:1.5
5,2,-6:1.5
6,2,-6:1.5
7,2,-6:1.5
8,2,-6:1.5
-5,3,-6:16.5
-4,3,-6:1.5
-3,3,-6:1.5
-2,3,-6:1.5
-1,3,-6:1.5
0,3,-6:1.5
1,3,-6:1.5
2,3,-6:1.5
3,3,-6:1.5
4,3,-6:1.5
5,3,-6:1.5
6,3,-6:1.5
7,3,-6:1.5
8,3,-6:1.5
-5,4,-6:1.5
-4,4,-6:1.5
-3,4,-6:1.5
-2,4,-6:1.5
-1,4,-6:1.5
0,4,-6:1.5
1,4,-6:1.5
2,4,-6:1.5
3,4,-6:1.5
4,4,-6:1.5
5,4,-6:1.5
6,4,-6:1.5
7,4,-6:1.5
8,4,-6:1.5
-5,5,-6:1.5
-4,5,-6:1.5
-3,5,-6:1.5
-2,5,-6:1.5
-1,5,-6:1.5
0,5,-6:1.5
1,5,-6:1.5
2,5,-6:1.5
3,5,-6:1.5
4,5,-6:1.5
5,5,-6:1.5
6,5,-6:1.5
8,5,-6:1.5
-5,6,-6:1.5
-4,6,-6:1.5
-3,6,-6:1.5
-2,6,-6:1.5
-1,6,-6:1.5
0,6,-6:1.5
1,6,-6:1.5
2,6,-6:1.5
3,6,-6:1.5
4,6,-6:1.5
5,6,-6:1.5
6,6,-6:1.5
7,6,-6:1.5
8,6,-6:1.5
-5,7,-6:1.5
-4,7,-6:1.5
-3,7,-6:1.5
-2,7,-6:1.5
-1,7,-6:1.5
0,7,-6:1.5
1,7,-6:1.5
2,7,-6:1.5
3,7,-6:1.5
4,7,-6:1.5
5,7,-6:1.5
6,7,-6:1.5
7,7,-6:1.5
8,7,-6:1.5
-1,-7,-5:3.5
-6,-6,-5:1.5
-5,-6,-5:1.5
-4,-6,-5:1.5
-3,-6,-5:1.5
-2,-6,-5:1.5
-1,-6,-5:1.5
0,-6,-5:1.5
1,-6,-5:1.5
2,-6,-5:1.5
3,-6,-5:1.5
4,-6,-5:1.5
5,-6,-5:1.5
6,-6,-5:1.5
7,-6,-5:1.5
8,-6,-5:1.5
9,-6,-5:1.5
-6,-5,-5:1.5
4,-5,-5:98.0
5,-5,-5:98.0
6,-5,-5:98.0
7,-5,-5:98.0
8,-5,-5:98.0
9,-5,-5:1.5
-6,-4,-5:1.5
-5,-4,-5:98.0
-4,-4,-5:98.0
-3,-4,-5:98.0
-2,-4,-5:98.0
-1,-4,-5:98.0
0,-4,-5:98.0
1,-4,-5:98.0
2,-4,-5:98.0
3,-4,-5:98.0
4,-4,-5:98.0
5,-4,-5:98.0
6,-4,-5:98.0
7,-4,-5:98.0
8,-4,-5:98.0
9,-4,-5:1.5
-7,-3,-5:3.5
-6,-3,-5:1.5
-5,-3,-5:98.0
-4,-3,-5:98.0
-3,-3,-5:98.0
-2,-3,-5:98.0
-1,-3,-5:98.0
0,-3,-5:98.0
1,-3,-5:98.0
2,-3,-5:98.0
3,-3,-5:98.0
4,-3,-5:98.0
5,-3,-5:98.0
6,-3,-5:98.0
7,-3,-5:98.0
8,-3,-5:98.0
9,-3,-5:1.5
-7,-2,-5:3.5
-6,-2,-5:1.5
-5,-2,-5:98.0
-4,-2,-5:98.0
-3,-2,-5:43.3
-2,-2,-5:43.3
-1,-2,-5:43.3
0,-2,-5:43.3
1,-2,-5:43.3
2,-2,-5:43.3
3,-2,-5:43.3
4,-2,-5:43.3
5,-2,-5:98.0
6,-2,-5:98.0
7,-2,-5:98.0
8,-2,-5:98.0
9,-2,-5:1.5
-6,-1,-5:1.5
-5,-1,-5:98.0
-4,-1,-5:98.0
-3,-1,-5:98.0
-2,-1,-5:98.0
-1,-1,-5:17.3
0,-1,-5:98.0
1,-1,-5:98.0
2,-1,-5:98.0
3,-1,-5:98.0
4,-1,-5:98.0
5,-1,-5:98.0
6,-1,-5:98.0
7,-1,-5:98.0
8,-1,-5:98.0
9,-1,-5:1.5
-6,0,-5:3.5
-5,0,-5:98.0
-4,0,-5:98.0
-3,0,-5:98.0
-2,0,-5:98.0
-1,0,-5:98.0
0,0,-5:98.0
1,0,-5:98.0
2,0,-5:98.0
3,0,-5:98.0
4,0,-5:98.0
5,0,-5:98.0
6,0,-5:98.0
7,0,-5:98.0
8,0,-5:98.0
9,0,-5:1.5
-6,1,-5:1.5
-5,1,-5:98.0
-4,1,-5:98.0
-3,1,-5:1.5
-2,1,-5:98.0
-1,1,-5:98.0
0,1,-5:1.5
1,1,-5:1.5
2,1,-5:1.5
3,1,-5:1.5
4,1,-5:98.0
5,1,-5:98.0
6,1,-5:98.0
7,1,-5:98.0
8,1,-5:98.0
9,1,-5:1.5
-6,2,-5:1.5
-5,2,-5:1.5
-4,2,-5:1.5
-3,2,-5:1.5
-2,2,-5:1.5
-1,2,-5:1.5
0,2,-5:1.5
1,2,-5:1.5
2,2,-5:1.5
3,2,-5:1.5
4,2,-5:98.0
5,2,-5:98.0
9,2,-5:1.5
-6,3,-5:16.5
-5,3,-5:1.5
-4,3,-5:1.5
-3,3,-5:1.5
-2,3,-5:1.5
-1,3,-5:1.5
0,3,-5:1.5
1,3,-5:1.5
2,3,-5:1.5
3,3,-5:1.5
4,3,-5:98.0
5,3,-5:98.0
9,3,-5:1.5
-6,4,-5:1.5
-5,4,-5:1.5
-4,4,-5:1.5
-3,4,-5:1.5
-2,4,-5:1.5
-1,4,-5:1.5
0,4,-5:1.5
1,4,-5:1.5
2,4,-5:1.5
3,4,-5:1.5
4,4,-5:98.0
5,4,-5:98.0
9,4,-5:1.5
-6,5,-5:1.5
-5,5,-5:1.5
-4,5,-5:1.5
-3,5,-5:1.5
-2,5,-5:1.5
-1,5,-5:1.5
0,5,-5:1.5
1,5,-5:1.5
2,5,-5:1.5
3,5,-5:1.5
4,5,-5:98.0
5,5,-5:98.0
9,5,-5:1.5
-7,6,-5:3.5
-6,6,-5:1.5
-5,6,-5:1.5
-4,6,-5:1.5
-3,6,-5:1.5
-2,6,-5:1.5
-1,6,-5:1.5
0,6,-5:1.5
1,6,-5:1.5
2,6,-5:1.5
3,6,-5:1.5
4,6,-5:98.0
5,6,-5:98.0
6,6,-5:98.0
7,6,-5:98.0
8,6,-5:98.0
9,6,-5:1.5
-7,7,-5:3.5
-6,7,-5:1.5
-5,7,-5:1.5
-4,7,-5:1.5
-3,7,-5:1.5
-2,7,-5:1.5
-1,7,-5:1.5
0,7,-5:1.5
1,7,-5:1.5
2,7,-5:1.5
3,7,-5:1.5
4,7,-5:98.0
5,7,-5:98.0
6,7,-5:98.0
7,7,-5:98.0
8,7,-5:98.0
9,7,-5:1.5
-7,8,-5:1.5
-6,8,-5:1.5
-5,8,-5:1.5
-4,8,-5:1.5
-3,8,-5:1.5
-2,8,-5:1.5
-1,8,-5:1.5
0,8,-5:1.5
1,8,-5:1.5
2,8,-5:1.5
3,8,-5:1.5
4,8,-5:1.5
5,8,-5:1.5
6,8,-5:1.5
7,8,-5:1.5
8,8,-5:1.5
9,8,-5:1.5
-3,9,-5:3.5
-2,9,-5:3.5
-1,9,-5:3.5
0,9,-5:3.5
1,9,-5:3.5
2,9,-5:3.5
-7,-7,-4:3.5
-6,-7,-4:3.5
-5,-7,-4:3.5
-4,-7,-4:3.5
-3,-7,-4:3.5
-2,-7,-4:3.5
-1,-7,-4:3.5
0,-7,-4:3.5
1,-7,-4:3.5
2,-7,-4:3.5
3,-7,-4:3.5
4,-7,-4:3.5
5,-7,-4:3.5
6,-7,-4:3.5
7,-7,-4:3.5
8,-7,-4:3.5
9,-7,-4:3.5
10,-7,-4:3.5
-7,-6,-4:1.5
-6,-6,-4:1.5
-5,-6,-4:1.5
-4,-6,-4:1.5
-3,-6,-4:1.5
-2,-6,-4:1.5
-1,-6,-4:1.5
0,-6,-4:1.5
1,-6,-4:1.5
2,-6,-4:1.5
3,-6,-4:1.5
4,-6,-4:1.5
5,-6,-4:1.5
6,-6,-4:1.5
7,-6,-4:1.5
8,-6,-4:1.5
9,-6,-4:1.5
10,-6,-4:1.5
-7,-5,-4:1.5
-6,-5,-4:3.5
-5,-5,-4:98.0
-4,-5,-4:98.0
-3,-5,-4:98.0
-2,-5,-4:98.0
-1,-5,-4:98.0
0,-5,-4:98.0
1,-5,-4:98.0
2,-5,-4:98.0
3,-5,-4:98.0
4,-5,-4:98.0
5,-5,-4:98.0
6,-5,-4:98.0
7,-5,-4:98.0
8,-5,-4:98.0
9,-5,-4:98.0
10,-5,-4:1.5
-8,-4,-4:3.5
-7,-4,-4:1.5
-6,-4,-4:3.5
-5,-4,-4:98.0
6,-4,-4:98.0
9,-4,-4:98.0
10,-4,-4:1.5
-7,-3,-4:1.5
-6,-3,-4:3.5
-5,-3,-4:98.0
-4,-3,-4:109.3
9,-3,-4:98.0
10,-3,-4:1.5
-7,-2,-4:1.5
-5,-2,-4:98.0
-4,-2,-4:98.1
6,-2,-4:98.0
9,-2,-4:98.0
10,-2,-4:1.5
-7,-1,-4:1.5
-6,-1,-4:3.5
-5,-1,-4:98.0
-4,-1,-4:109.2
6,-1,-4:98.0
8,-1,-4:44.5
9,-1,-4:98.0
10,-1,-4:1.5
-7,0,-4:1.5
-6,0,-4:3.5
-5,0,-4:98.0
-1,0,-4:17.3
1,0,-4:17.3
6,0,-4:98.0
7,0,-4:44.5
9,0,-4:98.0
10,0,-4:1.5
-7,1,-4:1.5
-6,1,-4:3.5
-5,1,-4:98.0
-4,1,-4:98.0
-3,1,-4:98.0
-2,1,-4:98.0
-1,1,-4:98.0
0,1,-4:98.0
1,1,-4:98.0
2,1,-4:98.0
3,1,-4:98.0
6,1,-4:98.0
9,1,-4:98.0
10,1,-4:1.5
-7,2,-4:1.5
-6,2,-4:3.5
-5,2,-4:1.5
-4,2,-4:1.5
-3,2,-4:1.5
-2,2,-4:1.5
-1,2,-4:1.5
0,2,-4:1.5
1,2,-4:1.5
2,2,-4:1.5
3,2,-4:98.0
6,2,-4:98.0
7,2,-4:98.0
8,2,-4:98.0
9,2,-4:98.0
10,2,-4:1.5
-7,3,-4:1.5
-6,3,-4:3.5
-5,3,-4:3.5
-4,3,-4:3.5
-3,3,-4:3.5
-2,3,-4:3.5
-1,3,-4:3.5
0,3,-4:1.5
1,3,-4:1.5
2,3,-4:1.5
3,3,-4:98.0
6,3,-4:98.0
7,3,-4:98.0
8,3,-4:98.0
9,3,-4:98.0
10,3,-4:1.5
-7,4,-4:1.5
-6,4,-4:3.5
-5,4,-4:3.5
-4,4,-4:3.5
-3,4,-4:3.5
-2,4,-4:3.5
-1,4,-4:3.5
0,4,-4:3.5
1,4,-4:1.5
2,4,-4:1.5
3,4,-4:98.0
6,4,-4:98.0
7,4,-4:98.0
8,4,-4:98.0
9,4,-4:98.0
10,4,-4:1.5
-7,5,-4:1.5
-6,5,-4:3.5
-5,5,-4:3.5
-4,5,-4:3.5
-3,5,-4:3.5
-2,5,-4:3.5
-1,5,-4:3.5
0,5,-4:3.5
1,5,-4:3.5
2,5,-4:1.5
3,5,-4:98.0
6,5,-4:98.0
7,5,-4:109.3
8,5,-4:109.3
9,5,-4:98.0
10,5,-4:1.5
-7,6,-4:1.5
-6,6,-4:1.5
-5,6,-4:1.5
-4,6,-4:1.5
-3,6,-4:1.5
-2,6,-4:1.5
-1,6,-4:1.5
0,6,-4:1.5
1,6,-4:1.5
2,6,-4:1.5
3,6,-4:98.0
8,6,-4:43.5
9,6,-4:98.0
10,6,-4:1.5
-8,7,-4:3.5
-7,7,-4:1.5
-6,7,-4:3.5
-5,7,-4:1.5
-4,7,-4:1.5
-3,7,-4:1.5
-2,7,-4:1.5
-1,7,-4:1.5
0,7,-4:1.5
1,7,-4:1.5
2,7,-4:1.5
3,7,-4:98.0
8,7,-4:98.0
9,7,-4:98.0
10,7,-4:1.5
-7,8,-4:1.5
-6,8,-4:1.5
-5,8,-4:1.5
-4,8,-4:1.5
-3,8,-4:1.5
-2,8,-4:1.5
-1,8,-4:1.5
0,8,-4:1.5
1,8,-4:1.5
2,8,-4:1.5
3,8,-4:98.0
4,8,-4:98.0
5,8,-4:98.0
6,8,-4:98.0
7,8,-4:98.0
8,8,-4:98.0
9,8,-4:98.0
10,8,-4:1.5
-8,9,-4:1.5
-7,9,-4:1.5
-6,9,-4:1.5
-5,9,-4:1.5
-4,9,-4:1.5
-3,9,-4:1.5
-2,9,-4:1.5
-1,9,-4:1.5
0,9,-4:1.5
1,9,-4:1.5
2,9,-4:1.5
3,9,-4:1.5
4,9,-4:1.5
5,9,-4:1.5
6,9,-4:1.5
7,9,-4:1.5
8,9,-4:1.5
9,9,-4:1.5
-2,10,-4:3.5
-1,10,-4:3.5
0,10,-4:3.5
-7,-8,-3:3.5
-6,-8,-3:3.5
-5,-8,-3:3.5
-4,-8,-3:3.5
-3,-8,-3:3.5
-2,-8,-3:3.5
-1,-8,-3:3.5
0,-8,-3:3.5
1,-8,-3:3.5
2,-8,-3:3.5
3,-8,-3:3.5
4,-8,-3:3.5
5,-8,-3:3.5
6,-8,-3:3.5
7,-8,-3:3.5
8,-8,-3:3.5
9,-8,-3:3.5
10,-8,-3:3.5
-8,-7,-3:3.5
-7,-7,-3:3.5
-6,-7,-3:3.5
-5,-7,-3:3.5
-4,-7,-3:3.5
-3,-7,-3:3.5
-2,-7,-3:3.5
-1,-7,-3:3.5
0,-7,-3:3.5
1,-7,-3:3.5
2,-7,-3:3.5
3,-7,-3:3.5
4,-7,-3:3.5
5,-7,-3:3.5
6,-7,-3:3.5
7,-7,-3:3.5
8,-7,-3:3.5
9,-7,-3:3.5
10,-7,-3:3.5
11,-7,-3:3.5
-8,-6,-3:3.5
-7,-6,-3:3.5
-6,-6,-3:3.5
-5,-6,-3:3.5
-4,-6,-3:3.5
-3,-6,-3:3.5
-2,-6,-3:3.5
-1,-6,-3:3.5
0,-6,-3:3.5
1,-6,-3:3.5
2,-6,-3:3.5
3,-6,-3:3.5
4,-6,-3:3.5
5,-6,-3:3.5
6,-6,-3:3.5
7,-6,-3:3.5
8,-6,-3:3.5
9,-6,-3:3.5
10,-6,-3:3.5
11,-6,-3:3.5
-8,-5,-3:3.5
-7,-5,-3:3.5
-6,-5,-3:3.5
-5,-5,-3:98.0
-4,-5,-3:98.0
-3,-5,-3:98.0
-2,-5,-3:98.0
-1,-5,-3:98.0
0,-5,-3:98.0
1,-5,-3:98.0
2,-5,-3:98.0
3,-5,-3:98.0
4,-5,-3:98.0
5,-5,-3:98.0
6,-5,-3:98.0
7,-5,-3:98.0
8,-5,-3:98.0
9,-5,-3:98.0
10,-5,-3:3.5
11,-5,-3:3.5
-8,-4,-3:3.5
-7,-4,-3:3.5
-6,-4,-3:3.5
-5,-4,-3:98.0
6,-4,-3:98.0
9,-4,-3:98.0
10,-4,-3:3.5
11,-4,-3:3.5
-8,-3,-3:3.5
-7,-3,-3:3.5
-6,-3,-3:3.5
-5,-3,-3:98.2
-4,-3,-3:98.2
9,-3,-3:98.0
10,-3,-3:3.5
11,-3,-3:3.5
-8,-2,-3:3.5
-7,-2,-3:3.5
-6,-2,-3:3.5
-5,-2,-3:98.0
-4,-2,-3:42.0
6,-2,-3:98.0
9,-2,-3:98.0
10,-2,-3:3.5
11,-2,-3:3.5
-8,-1,-3:3.5
-7,-1,-3:3.5
-6,-1,-3:3.5
-5,-1,-3:98.2
-4,-1,-3:98.2
6,-1,-3:98.0
9,-1,-3:98.0
10,-1,-3:3.5
11,-1,-3:3.5
-8,0,-3:3.5
-7,0,-3:3.5
-6,0,-3:3.5
-5,0,-3:98.0
0,0,-3:17.3
1,0,-3:17.3
6,0,-3:98.0
9,0,-3:98.0
10,0,-3:3.5
11,0,-3:3.5
-8,1,-3:3.5
-7,1,-3:3.5
-6,1,-3:3.5
-5,1,-3:98.0
-4,1,-3:98.0
-3,1,-3:98.0
-2,1,-3:98.0
-1,1,-3:98.0
0,1,-3:98.0
1,1,-3:98.0
2,1,-3:98.0
3,1,-3:98.0
6,1,-3:98.0
9,1,-3:98.0
10,1,-3:3.5
11,1,-3:3.5
-8,2,-3:3.5
-7,2,-3:3.5
-6,2,-3:3.5
-5,2,-3:3.5
-4,2,-3:3.5
-3,2,-3:3.5
-2,2,-3:3.5
-1,2,-3:3.5
0,2,-3:3.5
1,2,-3:3.5
2,2,-3:3.5
3,2,-3:98.0
6,2,-3:98.0
7,2,-3:98.0
8,2,-3:98.0
9,2,-3:98.0
10,2,-3:3.5
11,2,-3:3.5
-8,3,-3:3.5
-7,3,-3:3.5
-6,3,-3:3.5
-5,3,-3:3.5
-4,3,-3:3.5
-3,3,-3:3.5
-2,3,-3:3.5
-1,3,-3:3.5
0,3,-3:3.5
1,3,-3:3.5
2,3,-3:3.5
3,3,-3:98.0
6,3,-3:98.0
7,3,-3:98.0
8,3,-3:98.0
9,3,-3:98.0
10,3,-3:3.5
11,3,-3:3.5
-8,4,-3:3.5
-7,4,-3:3.5
-6,4,-3:3.5
-5,4,-3:3.5
-4,4,-3:3.5
-3,4,-3:3.5
-2,4,-3:3.5
-1,4,-3:3.5
0,4,-3:3.5
1,4,-3:3.5
2,4,-3:3.5
3,4,-3:98.0
6,4,-3:98.0
7,4,-3:109.3
8,4,-3:109.3
9,4,-3:98.0
10,4,-3:3.5
11,4,-3:3.5
-8,5,-3:3.5
-7,5,-3:3.5
-6,5,-3:3.5
-5,5,-3:3.5
-4,5,-3:3.5
-3,5,-3:3.5
-2,5,-3:3.5
-1,5,-3:3.5
0,5,-3:3.5
1,5,-3:3.5
2,5,-3:3.5
3,5,-3:98.0
6,5,-3:98.0
9,5,-3:98.0
10,5,-3:3.5
11,5,-3:3.5
-8,6,-3:3.5
-7,6,-3:3.5
-6,6,-3:3.5
-5,6,-3:3.5
-4,6,-3:3.5
-3,6,-3:3.5
-2,6,-3:3.5
-1,6,-3:3.5
0,6,-3:3.5
1,6,-3:3.5
2,6,-3:3.5
3,6,-3:98.0
9,6,-3:98.0
10,6,-3:3.5
11,6,-3:3.5
-8,7,-3:3.5
-7,7,-3:3.5
-5,7,-3:3.5
-4,7,-3:3.5
-3,7,-3:3.5
-2,7,-3:3.5
-1,7,-3:3.5
0,7,-3:3.5
1,7,-3:3.5
2,7,-3:3.5
3,7,-3:98.0
8,7,-3:44.5
9,7,-3:98.0
10,7,-3:3.5
11,7,-3:3.5
-9,8,-3:3.5
-8,8,-3:3.5
-7,8,-3:3.5
-6,8,-3:3.5
-5,8,-3:3.5
-4,8,-3:3.5
-3,8,-3:3.5
-2,8,-3:3.5
-1,8,-3:3.5
0,8,-3:3.5
1,8,-3:3.5
2,8,-3:3.5
3,8,-3:98.0
4,8,-3:98.0
5,8,-3:98.0
6,8,-3:98.0
7,8,-3:98.0
8,8,-3:98.0
9,8,-3:98.0
10,8,-3:3.5
-8,9,-3:3.5
-7,9,-3:3.5
-6,9,-3:3.5
-5,9,-3:3.5
-4,9,-3:3.5
-3,9,-3:3.5
-2,9,-3:3.5
-1,9,-3:3.5
0,9,-3:3.5
1,9,-3:3.5
2,9,-3:3.5
3,9,-3:3.5
4,9,-3:3.5
5,9,-3:3.5
6,9,-3:3.5
7,9,-3:3.5
8,9,-3:3.5
9,9,-3:3.5
-9,10,-3:3.5
-8,10,-3:3.5
-7,10,-3:3.5
-6,10,-3:3.5
-5,10,-3:3.5
-4,10,-3:3.5
-3,10,-3:3.5
-2,10,-3:3.5
-1,10,-3:3.5
0,10,-3:3.5
1,10,-3:3.5
2,10,-3:3.5
3,10,-3:3.5
4,10,-3:3.5
5,10,-3:3.5
6,10,-3:3.5
7,10,-3:3.5
8,10,-3:3.5
0,11,-3:3.5
-7,-9,-2:3.5
-6,-9,-2:3.5
-5,-9,-2:3.5
-4,-9,-2:3.5
-3,-9,-2:3.5
-2,-9,-2:3.5
-1,-9,-2:3.5
0,-9,-2:3.5
1,-9,-2:3.5
2,-9,-2:3.5
3,-9,-2:3.5
4,-9,-2:3.5
5,-9,-2:3.5
6,-9,-2:3.5
7,-9,-2:3.5
8,-9,-2:3.5
9,-9,-2:3.5
10,-9,-2:3.5
-10,-8,-2:3.5
-9,-8,-2:3.5
-8,-8,-2:3.5
-7,-8,-2:3.5
-6,-8,-2:3.5
-5,-8,-2:3.5
-4,-8,-2:3.5
-3,-8,-2:3.5
-2,-8,-2:3.5
-1,-8,-2:3.5
0,-8,-2:3.5
1,-8,-2:3.5
2,-8,-2:3.5
3,-8,-2:3.5
4,-8,-2:3.5
5,-8,-2:3.5
6,-8,-2:3.5
7,-8,-2:3.5
8,-8,-2:3.5
9,-8,-2:3.5
10,-8,-2:3.5
11,-8,-2:3.5
-9,-7,-2:3.5
-8,-7,-2:3.5
-7,-7,-2:3.5
-6,-7,-2:3.5
-5,-7,-2:3.5
-4,-7,-2:3.5
-3,-7,-2:3.5
-2,-7,-2:3.5
-1,-7,-2:3.5
0,-7,-2:3.5
1,-7,-2:3.5
2,-7,-2:3.5
3,-7,-2:3.5
4,-7,-2:3.5
5,-7,-2:3.5
6,-7,-2:3.5
7,-7,-2:3.5
8,-7,-2:3.5
9,-7,-2:3.5
10,-7,-2:3.5
11,-7,-2:3.5
12,-7,-2:3.5
-9,-6,-2:3.5
-8,-6,-2:3.5
-7,-6,-2:3.5
-6,-6,-2:3.5
-5,-6,-2:3.5
-4,-6,-2:3.5
-3,-6,-2:3.5
-2,-6,-2:3.5
-1,-6,-2:3.5
0,-6,-2:3.5
1,-6,-2:3.5
2,-6,-2:3.5
3,-6,-2:3.5
4,-6,-2:3.5
5,-6,-2:3.5
6,-6,-2:3.5
7,-6,-2:3.5
8,-6,-2:3.5
9,-6,-2:3.5
10,-6,-2:3.5
11,-6,-2:3.5
12,-6,-2:3.5
-9,-5,-2:3.5
-8,-5,-2:3.5
-7,-5,-2:3.5
-6,-5,-2:3.5
-5,-5,-2:98.0
-4,-5,-2:98.0
-3,-5,-2:98.0
-2,-5,-2:98.0
-1,-5,-2:98.0
0,-5,-2:98.0
1,-5,-2:98.0
2,-5,-2:98.0
3,-5,-2:98.0
4,-5,-2:98.0
5,-5,-2:98.0
6,-5,-2:98.0
7,-5,-2:98.0
8,-5,-2:98.0
9,-5,-2:98.0
10,-5,-2:3.5
11,-5,-2:3.5
12,-5,-2:3.5
-9,-4,-2:3.5
-8,-4,-2:3.5
-7,-4,-2:3.5
-6,-4,-2:3.5
-5,-4,-2:98.0
6,-4,-2:98.0
9,-4,-2:98.0
10,-4,-2:3.5
11,-4,-2:3.5
12,-4,-2:3.5
-9,-3,-2:3.5
-8,-3,-2:3.5
-7,-3,-2:3.5
-6,-3,-2:3.5
-5,-3,-2:98.0
-4,-3,-2:109.7
6,-3,-2:98.0
9,-3,-2:98.0
10,-3,-2:3.5
11,-3,-2:3.5
12,-3,-2:3.5
-9,-2,-2:3.5
-8,-2,-2:3.5
-7,-2,-2:3.5
-6,-2,-2:3.5
-5,-2,-2:98.2
-4,-2,-2:98.2
6,-2,-2:98.0
9,-2,-2:98.0
10,-2,-2:3.5
11,-2,-2:3.5
12,-2,-2:3.5
-9,-1,-2:3.5
-8,-1,-2:3.5
-7,-1,-2:3.5
-6,-1,-2:3.5
-5,-1,-2:98.0
-4,-1,-2:109.6
6,-1,-2:98.0
9,-1,-2:98.0
10,-1,-2:3.5
11,-1,-2:3.5
12,-1,-2:3.5
-9,0,-2:3.5
-8,0,-2:3.5
-7,0,-2:3.5
-6,0,-2:3.5
-5,0,-2:98.0
0,0,-2:17.3
9,0,-2:98.0
10,0,-2:3.5
11,0,-2:3.5
12,0,-2:3.5
-9,1,-2:3.5
-8,1,-2:3.5
-7,1,-2:3.5
-6,1,-2:3.5
-5,1,-2:98.0
-4,1,-2:98.0
-3,1,-2:98.0
-2,1,-2:98.0
-1,1,-2:98.0
0,1,-2:98.0
1,1,-2:98.0
2,1,-2:98.0
3,1,-2:98.0
6,1,-2:98.0
9,1,-2:98.0
10,1,-2:3.5
11,1,-2:3.5
12,1,-2:3.5
-9,2,-2:3.5
-8,2,-2:3.5
-7,2,-2:3.5
-6,2,-2:3.5
-5,2,-2:3.5
-4,2,-2:3.5
-3,2,-2:3.5
-2,2,-2:3.5
-1,2,-2:3.5
0,2,-2:3.5
1,2,-2:3.5
2,2,-2:3.5
3,2,-2:98.0
6,2,-2:98.0
7,2,-2:98.0
8,2,-2:98.0
9,2,-2:98.0
10,2,-2:3.5
11,2,-2:3.5
12,2,-2:3.5
-9,3,-2:3.5
-8,3,-2:3.5
-7,3,-2:3.5
-6,3,-2:3.5
-5,3,-2:3.5
-4,3,-2:3.5
-3,3,-2:3.5
-2,3,-2:3.5
-1,3,-2:3.5
0,3,-2:3.5
1,3,-2:3.5
2,3,-2:3.5
3,3,-2:98.0
6,3,-2:98.0
7,3,-2:109.3
8,3,-2:44.5
9,3,-2:98.0
10,3,-2:3.5
11,3,-2:3.5
12,3,-2:3.5
-9,4,-2:3.5
-8,4,-2:3.5
-7,4,-2:3.5
-6,4,-2:3.5
-5,4,-2:3.5
-4,4,-2:3.5
-3,4,-2:3.5
-2,4,-2:3.5
-1,4,-2:3.5
0,4,-2:3.5
1,4,-2:3.5
2,4,-2:3.5
3,4,-2:98.0
6,4,-2:98.0
9,4,-2:98.0
10,4,-2:3.5
11,4,-2:3.5
12,4,-2:3.5
-9,5,-2:3.5
-8,5,-2:3.5
-7,5,-2:3.5
-6,5,-2:3.5
-5,5,-2:3.5
-4,5,-2:3.5
-3,5,-2:3.5
-2,5,-2:3.5
-1,5,-2:3.5
0,5,-2:3.5
1,5,-2:3.5
2,5,-2:3.5
3,5,-2:98.0
6,5,-2:98.0
9,5,-2:98.0
10,5,-2:3.5
11,5,-2:3.5
12,5,-2:3.5
-9,6,-2:3.5
-8,6,-2:3.5
-6,6,-2:3.5
-5,6,-2:3.5
-4,6,-2:3.5
-3,6,-2:3.5
-2,6,-2:3.5
-1,6,-2:3.5
0,6,-2:3.5
1,6,-2:3.5
2,6,-2:3.5
3,6,-2:98.0
9,6,-2:98.0
10,6,-2:3.5
11,6,-2:3.5
12,6,-2:3.5
-9,7,-2:3.5
-8,7,-2:3.5
-7,7,-2:3.5
-6,7,-2:3.5
-5,7,-2:3.5
-4,7,-2:3.5
-3,7,-2:3.5
-2,7,-2:3.5
-1,7,-2:3.5
0,7,-2:3.5
1,7,-2:3.5
2,7,-2:3.5
3,7,-2:98.0
9,7,-2:98.0
10,7,-2:3.5
11,7,-2:3.5
12,7,-2:3.5
-9,8,-2:3.5
-8,8,-2:3.5
-6,8,-2:3.5
-5,8,-2:3.5
-4,8,-2:3.5
-3,8,-2:3.5
-2,8,-2:3.5
-1,8,-2:3.5
0,8,-2:3.5
1,8,-2:3.5
2,8,-2:3.5
3,8,-2:98.0
4,8,-2:98.0
5,8,-2:98.0
6,8,-2:98.0
7,8,-2:98.0
8,8,-2:98.0
9,8,-2:98.0
10,8,-2:3.5
11,8,-2:3.5
-9,9,-2:3.5
-8,9,-2:3.5
-7,9,-2:3.5
-6,9,-2:3.5
-5,9,-2:3.5
-4,9,-2:3.5
-3,9,-2:3.5
-2,9,-2:3.5
-1,9,-2:3.5
0,9,-2:3.5
1,9,-2:3.5
2,9,-2:3.5
3,9,-2:3.5
4,9,-2:3.5
5,9,-2:3.5
6,9,-2:3.5
7,9,-2:3.5
8,9,-2:3.5
9,9,-2:3.5
10,9,-2:3.5
-9,10,-2:3.5
-8,10,-2:3.5
-7,10,-2:3.5
-6,10,-2:3.5
-5,10,-2:3.5
-4,10,-2:3.5
-3,10,-2:3.5
-2,10,-2:3.5
-1,10,-2:3.5
0,10,-2:3.5
1,10,-2:3.5
2,10,-2:3.5
3,10,-2:3.5
4,10,-2:3.5
5,10,-2:3.5
6,10,-2:3.5
7,10,-2:3.5
8,10,-2:3.5
9,10,-2:3.5
-9,11,-2:3.5
-8,11,-2:3.5
-7,11,-2:3.5
-6,11,-2:3.5
-5,11,-2:3.5
-4,11,-2:3.5
-3,11,-2:3.5
-2,11,-2:3.5
-1,11,-2:3.5
0,11,-2:3.5
1,11,-2:3.5
2,11,-2:3.5
3,11,-2:3.5
4,11,-2:3.5
6,11,-2:3.5
-7,-10,-1:2.5
-6,-10,-1:2.5
-5,-10,-1:2.5
-4,-10,-1:2.5
-3,-10,-1:2.5
-2,-10,-1:2.5
-1,-10,-1:2.5
0,-10,-1:17.3
1,-10,-1:2.5
2,-10,-1:2.5
3,-10,-1:2.5
4,-10,-1:2.5
5,-10,-1:17.3
6,-10,-1:2.5
7,-10,-1:17.3
8,-10,-1:3.0
9,-10,-1:2.5
10,-10,-1:2.5
11,-10,-1:2.5
-10,-9,-1:2.5
-9,-9,-1:2.5
-8,-9,-1:2.5
-7,-9,-1:2.5
-6,-9,-1:3.0
-5,-9,-1:98.1
-4,-9,-1:3.0
-3,-9,-1:3.0
-2,-9,-1:3.0
-1,-9,-1:3.0
0,-9,-1:3.0
1,-9,-1:3.0
2,-9,-1:3.0
3,-9,-1:3.0
4,-9,-1:3.0
5,-9,-1:17.3
6,-9,-1:3.0
7,-9,-1:3.0
8,-9,-1:3.0
9,-9,-1:3.0
10,-9,-1:3.0
11,-9,-1:3.0
12,-9,-1:2.5
-12,-8,-1:2.5
-11,-8,-1:2.5
-10,-8,-1:3.0
-9,-8,-1:3.0
-8,-8,-1:3.0
-7,-8,-1:3.0
-6,-8,-1:3.0
-5,-8,-1:3.0
-4,-8,-1:98.0
-3,-8,-1:3.0
-2,-8,-1:3.0
-1,-8,-1:3.0
0,-8,-1:2.0
1,-8,-1:3.0
2,-8,-1:3.0
3,-8,-1:3.0
4,-8,-1:3.0
5,-8,-1:3.0
6,-8,-1:3.0
7,-8,-1:3.0
8,-8,-1:3.0
9,-8,-1:3.0
10,-8,-1:3.0
11,-8,-1:3.0
12,-8,-1:2.0
13,-8,-1:2.0
-13,-7,-1:2.5
-12,-7,-1:2.5
-11,-7,-1:2.5
-10,-7,-1:98.0
-9,-7,-1:2.0
-8,-7,-1:3.0
-7,-7,-1:3.0
-6,-7,-1:3.0
-5,-7,-1:3.0
-4,-7,-1:3.0
-3,-7,-1:98.0
-2,-7,-1:98.0
-1,-7,-1:3.0
0,-7,-1:3.0
1,-7,-1:3.0
2,-7,-1:3.0
3,-7,-1:3.0
4,-7,-1:3.0
5,-7,-1:3.0
6,-7,-1:3.0
7,-7,-1:3.0
8,-7,-1:3.0
9,-7,-1:3.0
10,-7,-1:3.0
11,-7,-1:3.0
12,-7,-1:2.0
13,-7,-1:2.0
-13,-6,-1:2.5
-12,-6,-1:2.5
-11,-6,-1:2.5
-10,-6,-1:98.0
-9,-6,-1:2.0
-8,-6,-1:3.0
-7,-6,-1:3.0
-6,-6,-1:3.0
-5,-6,-1:3.0
-4,-6,-1:3.0
-3,-6,-1:3.0
-2,-6,-1:98.0
-1,-6,-1:3.0
0,-6,-1:3.0
1,-6,-1:3.0
2,-6,-1:3.0
3,-6,-1:3.0
4,-6,-1:3.0
5,-6,-1:3.0
6,-6,-1:3.0
7,-6,-1:3.0
8,-6,-1:3.0
9,-6,-1:3.0
10,-6,-1:3.0
11,-6,-1:3.0
12,-6,-1:2.0
13,-6,-1:2.0
-13,-5,-1:2.5
-12,-5,-1:3.0
-11,-5,-1:2.5
-10,-5,-1:98.0
-9,-5,-1:2.0
-8,-5,-1:3.0
-7,-5,-1:3.0
-6,-5,-1:3.0
-5,-5,-1:3.0
-4,-5,-1:3.0
-3,-5,-1:3.0
-2,-5,-1:3.0
-1,-5,-1:98.0
0,-5,-1:3.0
1,-5,-1:3.0
2,-5,-1:3.0
3,-5,-1:3.0
4,-5,-1:3.0
5,-5,-1:3.0
6,-5,-1:3.0
7,-5,-1:3.0
8,-5,-1:3.0
9,-5,-1:3.0
10,-5,-1:3.0
11,-5,-1:98.0
12,-5,-1:2.0
13,-5,-1:2.0
-13,-4,-1:2.5
-12,-4,-1:3.0
-11,-4,-1:2.5
-10,-4,-1:98.0
-9,-4,-1:2.0
-8,-4,-1:3.0
-7,-4,-1:3.0
-6,-4,-1:3.0
-5,-4,-1:3.0
-4,-4,-1:3.0
-3,-4,-1:3.0
-2,-4,-1:3.0
-1,-4,-1:3.0
0,-4,-1:98.0
1,-4,-1:3.0
2,-4,-1:3.0
3,-4,-1:3.0
4,-4,-1:3.0
5,-4,-1:3.0
6,-4,-1:3.0
7,-4,-1:3.0
8,-4,-1:3.0
9,-4,-1:98.0
10,-4,-1:98.0
11,-4,-1:3.0
12,-4,-1:17.3
13,-4,-1:2.0
-12,-3,-1:3.0
-11,-3,-1:3.0
-10,-3,-1:2.0
-9,-3,-1:2.0
-8,-3,-1:3.0
-7,-3,-1:3.0
-6,-3,-1:3.0
-5,-3,-1:3.0
-4,-3,-1:3.0
-3,-3,-1:3.0
-2,-3,-1:3.0
-1,-3,-1:3.0
0,-3,-1:3.0
1,-3,-1:98.0
2,-3,-1:3.0
3,-3,-1:3.0
4,-3,-1:3.0
5,-3,-1:3.0
6,-3,-1:3.0
7,-3,-1:3.0
8,-3,-1:98.0
9,-3,-1:3.0
10,-3,-1:3.0
11,-3,-1:3.0
12,-3,-1:2.0
13,-3,-1:2.0
-11,-2,-1:2.5
-10,-2,-1:2.0
-9,-2,-1:2.0
-8,-2,-1:2.0
-7,-2,-1:2.0
-6,-2,-1:3.0
-5,-2,-1:3.0
-4,-2,-1:3.0
-3,-2,-1:3.0
-2,-2,-1:3.0
-1,-2,-1:3.0
0,-2,-1:3.0
1,-2,-1:3.0
2,-2,-1:3.0
3,-2,-1:3.0
4,-2,-1:3.0
5,-2,-1:3.0
6,-2,-1:3.0
7,-2,-1:98.0
8,-2,-1:98.0
9,-2,-1:3.0
10,-2,-1:3.0
11,-2,-1:3.0
12,-2,-1:2.0
13,-2,-1:2.0
-10,-1,-1:3.0
-9,-1,-1:2.0
-8,-1,-1:2.0
-7,-1,-1:2.0
-6,-1,-1:2.0
-5,-1,-1:2.0
-4,-1,-1:2.0
-3,-1,-1:3.0
-2,-1,-1:3.0
-1,-1,-1:2.0
0,-1,-1:3.0
1,-1,-1:2.0
2,-1,-1:2.0
3,-1,-1:3.0
4,-1,-1:3.0
5,-1,-1:3.0
6,-1,-1:98.0
7,-1,-1:98.0
8,-1,-1:98.0
9,-1,-1:3.0
10,-1,-1:3.0
11,-1,-1:3.0
12,-1,-1:2.0
13,-1,-1:2.0
-10,0,-1:2.0
-9,0,-1:2.0
-8,0,-1:2.0
-7,0,-1:2.0
-6,0,-1:2.0
-5,0,-1:3.0
-4,0,-1:3.0
-3,0,-1:3.0
-2,0,-1:3.0
-1,0,-1:2.0
0,0,-1:17.3
1,0,-1:2.5
2,0,-1:2.5
3,0,-1:3.0
4,0,-1:3.0
5,0,-1:98.0
6,0,-1:98.0
7,0,-1:98.0
8,0,-1:98.0
9,0,-1:3.0
10,0,-1:3.0
11,0,-1:3.0
12,0,-1:2.0
13,0,-1:2.0
-10,1,-1:2.0
-9,1,-1:2.0
-8,1,-1:2.0
-7,1,-1:2.0
-6,1,-1:17.3
-5,1,-1:2.0
-4,1,-1:17.3
-3,1,-1:2.0
-2,1,-1:2.0
-1,1,-1:2.0
0,1,-1:3.0
1,1,-1:2.0
2,1,-1:2.0
3,1,-1:3.0
4,1,-1:98.0
5,1,-1:98.0
6,1,-1:98.0
7,1,-1:98.0
8,1,-1:98.0
9,1,-1:3.0
10,1,-1:3.0
11,1,-1:3.0
12,1,-1:2.0
13,1,-1:2.0
-10,2,-1:2.0
-9,2,-1:2.0
-8,2,-1:2.0
-7,2,-1:2.0
-6,2,-1:2.0
-5,2,-1:2.0
-4,2,-1:2.0
-3,2,-1:2.0
-2,2,-1:2.0
-1,2,-1:2.5
0,2,-1:17.3
1,2,-1:2.0
2,2,-1:2.0
3,2,-1:3.0
4,2,-1:98.0
5,2,-1:98.0
6,2,-1:98.0
7,2,-1:109.3
8,2,-1:109.3
9,2,-1:98.0
10,2,-1:3.0
11,2,-1:3.0
12,2,-1:17.3
13,2,-1:2.0
-10,3,-1:3.0
-9,3,-1:2.0
-8,3,-1:2.0
-7,3,-1:2.0
-6,3,-1:2.0
-5,3,-1:2.0
-4,3,-1:2.0
-3,3,-1:2.0
-2,3,-1:2.0
-1,3,-1:17.3
0,3,-1:2.0
1,3,-1:2.0
2,3,-1:17.3
3,3,-1:2.0
4,3,-1:98.0
5,3,-1:98.0
6,3,-1:98.0
9,3,-1:98.0
10,3,-1:3.0
11,3,-1:3.0
12,3,-1:2.0
13,3,-1:2.0
-10,4,-1:2.0
-9,4,-1:2.0
-8,4,-1:2.0
-7,4,-1:2.0
-6,4,-1:2.0
-5,4,-1:2.0
-4,4,-1:2.0
-3,4,-1:2.0
-2,4,-1:2.0
-1,4,-1:2.0
0,4,-1:2.0
1,4,-1:17.3
2,4,-1:2.0
3,4,-1:3.0
4,4,-1:98.0
5,4,-1:98.0
6,4,-1:98.0
9,4,-1:98.0
10,4,-1:3.0
11,4,-1:3.0
12,4,-1:2.0
13,4,-1:2.0
-10,5,-1:2.0
-9,5,-1:2.0
-8,5,-1:2.0
-7,5,-1:2.0
-6,5,-1:2.0
-5,5,-1:17.3
-4,5,-1:2.0
-3,5,-1:2.0
-2,5,-1:2.0
-1,5,-1:2.0
0,5,-1:2.0
1,5,-1:2.0
2,5,-1:2.0
3,5,-1:2.0
4,5,-1:98.0
5,5,-1:98.0
6,5,-1:98.0
9,5,-1:98.0
10,5,-1:3.0
11,5,-1:3.0
12,5,-1:2.0
13,5,-1:2.0
-10,6,-1:2.0
-9,6,-1:2.0
-8,6,-1:3.0
-7,6,-1:3.0
-6,6,-1:3.0
-5,6,-1:2.0
-4,6,-1:2.0
-3,6,-1:2.0
-2,6,-1:2.0
-1,6,-1:2.0
0,6,-1:2.0
1,6,-1:2.0
2,6,-1:3.0
3,6,-1:2.0
4,6,-1:98.0
5,6,-1:98.0
6,6,-1:98.0
7,6,-1:98.0
9,6,-1:98.0
10,6,-1:3.0
11,6,-1:3.0
12,6,-1:2.0
-10,7,-1:2.5
-9,7,-1:3.0
-8,7,-1:3.0
-7,7,-1:3.0
-6,7,-1:3.0
-5,7,-1:3.0
-4,7,-1:2.0
-3,7,-1:2.0
-2,7,-1:2.0
-1,7,-1:3.0
0,7,-1:2.0
1,7,-1:2.0
2,7,-1:3.0
3,7,-1:2.0
4,7,-1:98.0
5,7,-1:98.1
6,7,-1:98.0
7,7,-1:98.0
8,7,-1:98.0
9,7,-1:2.0
10,7,-1:3.0
11,7,-1:3.0
12,7,-1:2.0
-10,8,-1:2.0
-9,8,-1:3.0
-8,8,-1:3.0
-7,8,-1:2.0
-6,8,-1:3.0
-5,8,-1:3.0
-4,8,-1:2.0
-3,8,-1:2.0
-2,8,-1:3.0
-1,8,-1:2.0
0,8,-1:2.0
1,8,-1:17.3
2,8,-1:2.0
3,8,-1:2.0
4,8,-1:3.0
5,8,-1:3.0
6,8,-1:3.0
7,8,-1:3.0
8,8,-1:3.0
9,8,-1:3.0
10,8,-1:3.0
11,8,-1:3.0
12,8,-1:2.0
-10,9,-1:2.0
-9,9,-1:3.0
-8,9,-1:3.0
-7,9,-1:3.0
-6,9,-1:3.0
-5,9,-1:3.0
-4,9,-1:2.0
-3,9,-1:2.0
-2,9,-1:2.0
-1,9,-1:2.0
0,9,-1:2.0
1,9,-1:2.0
2,9,-1:2.0
3,9,-1:2.0
4,9,-1:3.0
5,9,-1:2.0
6,9,-1:2.0
7,9,-1:2.0
8,9,-1:2.0
9,9,-1:2.0
10,9,-1:2.0
11,9,-1:2.0
-10,10,-1:2.0
-9,10,-1:2.0
-8,10,-1:3.0
-7,10,-1:3.0
-6,10,-1:3.0
-5,10,-1:2.0
-4,10,-1:3.0
-3,10,-1:2.0
-2,10,-1:3.0
-1,10,-1:3.0
0,10,-1:3.0
1,10,-1:2.0
2,10,-1:2.0
3,10,-1:2.0
4,10,-1:2.0
5,10,-1:98.2
6,10,-1:2.0
7,10,-1:2.0
8,10,-1:2.0
9,10,-1:3.0
10,10,-1:2.0
-9,11,-1:2.0
-8,11,-1:2.0
-7,11,-1:2.0
-6,11,-1:2.0
-5,11,-1:2.0
-4,11,-1:2.0
-3,11,-1:2.0
-2,11,-1:2.0
-1,11,-1:2.0
0,11,-1:2.0
1,11,-1:2.0
2,11,-1:2.0
3,11,-1:2.0
4,11,-1:2.0
5,11,-1:2.0
6,11,-1:2.0
7,11,-1:2.0
8,11,-1:2.0
9,11,-1:2.0
-8,12,-1:2.0
-7,12,-1:2.0
-6,12,-1:2.0
-5,12,-1:2.0
-4,12,-1:2.0
-3,12,-1:2.0
-2,12,-1:2.0
-1,12,-1:2.0
0,12,-1:2.0
1,12,-1:2.0
2,12,-1:2.0
3,12,-1:2.0
-1,-10,0:18.15
0,-10,0:18.15
1,-10,0:18.15
5,-10,0:18.15
6,-10,0:18.15
7,-10,0:18.15
8,-10,0:17.3
9,-10,0:18.15
-6,-9,0:98.0
-4,-9,0:98.1
-3,-9,0:98.0
-2,-9,0:98.0
-1,-9,0:98.0
0,-9,0:17.3
1,-9,0:98.0
2,-9,0:98.0
3,-9,0:98.0
4,-9,0:98.0
5,-9,0:98.0
6,-9,0:98.0
7,-9,0:98.0
8,-9,0:98.0
9,-9,0:17.3
10,-9,0:98.0
11,-9,0:98.0
-10,-8,0:98.0
-9,-8,0:98.0
-8,-8,0:98.2
-7,-8,0:98.2
-6,-8,0:44.5
-5,-8,0:44.5
-3,-8,0:44.5
-2,-8,0:44.5
-1,-8,0:44.5
0,-8,0:18.14
1,-8,0:44.5
2,-8,0:44.5
3,-8,0:44.5
4,-8,0:44.5
5,-8,0:44.5
6,-8,0:44.5
7,-8,0:44.5
8,-8,0:44.5
9,-8,0:44.5
10,-8,0:43.5
11,-8,0:98.0
-12,-7,0:98.0
-9,-7,0:44.5
-8,-7,0:44.5
-7,-7,0:44.5
-6,-7,0:44.5
-5,-7,0:44.5
-4,-7,0:44.5
-1,-7,0:44.5
0,-7,0:44.5
1,-7,0:44.5
2,-7,0:44.5
3,-7,0:109.1
4,-7,0:43.5
5,-7,0:44.5
6,-7,0:109.1
7,-7,0:44.5
8,-7,0:44.5
9,-7,0:43.5
10,-7,0:44.5
11,-7,0:98.0
-12,-6,0:98.0
-9,-6,0:44.5
-8,-6,0:44.5
-7,-6,0:44.5
-6,-6,0:44.5
-5,-6,0:44.5
-4,-6,0:44.5
-3,-6,0:44.5
-1,-6,0:44.5
0,-6,0:44.5
1,-6,0:44.5
2,-6,0:44.5
3,-6,0:17.3
4,-6,0:44.5
5,-6,0:98.2
6,-6,0:44.5
7,-6,0:44.5
8,-6,0:44.5
9,-6,0:44.5
10,-6,0:44.5
11,-6,0:98.0
-12,-5,0:98.0
-9,-5,0:44.5
-8,-5,0:44.5
-7,-5,0:44.5
-6,-5,0:44.5
-5,-5,0:44.5
-4,-5,0:44.5
-3,-5,0:44.5
-2,-5,0:44.5
0,-5,0:44.5
1,-5,0:44.5
2,-5,0:44.5
3,-5,0:44.5
4,-5,0:44.5
5,-5,0:44.5
6,-5,0:44.5
7,-5,0:44.5
8,-5,0:44.5
9,-5,0:44.5
10,-5,0:44.5
-12,-4,0:98.0
-9,-4,0:44.5
-8,-4,0:44.5
-7,-4,0:44.5
-6,-4,0:44.5
-5,-4,0:44.5
-4,-4,0:44.5
-3,-4,0:44.5
-2,-4,0:44.5
-1,-4,0:44.5
1,-4,0:44.5
2,-4,0:44.5
3,-4,0:44.5
4,-4,0:44.5
5,-4,0:44.5
6,-4,0:44.5
7,-4,0:17.3
8,-4,0:44.5
11,-4,0:98.0
12,-4,0:18.13
-12,-3,0:98.0
-11,-3,0:43.5
-9,-3,0:44.5
-8,-3,0:98.2
-7,-3,0:98.2
-6,-3,0:44.5
-5,-3,0:44.5
-4,-3,0:44.5
-3,-3,0:44.5
-2,-3,0:44.5
-1,-3,0:44.5
0,-3,0:44.5
2,-3,0:44.5
3,-3,0:44.5
4,-3,0:17.3
5,-3,0:44.5
6,-3,0:44.5
7,-3,0:44.5
9,-3,0:44.5
10,-3,0:44.5
11,-3,0:98.0
12,-3,0:18.5
-6,-2,0:98.2
-5,-2,0:98.0
-4,-2,0:98.0
-3,-2,0:98.0
-2,-2,0:98.0
-1,-2,0:98.0
0,-2,0:98.0
1,-2,0:98.0
2,-2,0:98.0
3,-2,0:98.0
4,-2,0:98.0
5,-2,0:44.5
6,-2,0:44.5
8,-2,0:44.5
9,-2,0:44.5
10,-2,0:44.5
11,-2,0:98.1
-10,-1,0:98.3
-6,-1,0:44.5
-5,-1,0:44.5
-4,-1,0:44.5
-3,-1,0:44.5
-2,-1,0:17.3
-1,-1,0:44.5
0,-1,0:17.3
1,-1,0:44.5
2,-1,0:44.5
3,-1,0:17.3
4,-1,0:98.0
5,-1,0:44.5
7,-1,0:44.5
8,-1,0:44.5
9,-1,0:44.5
10,-1,0:44.5
11,-1,0:98.1
-5,0,0:17.3
-4,0,0:17.3
-3,0,0:17.3
-2,0,0:17.3
0,0,0:17.3
3,0,0:17.3
4,0,0:98.0
6,0,0:44.5
7,0,0:44.5
8,0,0:44.5
9,0,0:44.5
10,0,0:44.5
11,0,0:98.0
12,0,0:18.14
0,1,0:17.3
3,1,0:17.3
4,1,0:98.0
5,1,0:44.5
6,1,0:44.5
7,1,0:44.5
8,1,0:44.5
9,1,0:44.5
10,1,0:44.5
11,1,0:98.0
12,1,0:18.14
13,1,0:18.14
-2,2,0:18.15
3,2,0:17.3
4,2,0:98.0
5,2,0:44.5
6,2,0:44.5
9,2,0:44.5
10,2,0:44.5
11,2,0:98.0
12,2,0:17.3
13,2,0:18.14
-10,3,0:98.3
-1,3,0:18.15
2,3,0:18.15
3,3,0:17.3
4,3,0:98.0
5,3,0:44.5
6,3,0:43.5
9,3,0:44.5
10,3,0:44.5
11,3,0:98.0
-1,4,0:18.15
2,4,0:18.15
3,4,0:17.3
4,4,0:98.0
5,4,0:44.5
6,4,0:44.5
9,4,0:44.5
10,4,0:44.5
11,4,0:98.0
-8,5,0:44.5
-7,5,0:44.5
-6,5,0:44.5
-5,5,0:18.15
3,5,0:44.5
4,5,0:98.0
5,5,0:44.5
6,5,0:44.5
9,5,0:43.5
10,5,0:44.5
11,5,0:98.0
-9,6,0:44.5
-8,6,0:98.1
-7,6,0:43.5
-6,6,0:98.0
-5,6,0:44.5
-3,6,0:44.5
2,6,0:17.3
3,6,0:44.5
4,6,0:98.0
5,6,0:44.5
6,6,0:44.5
7,6,0:44.5
9,6,0:43.5
10,6,0:44.5
11,6,0:98.1
-10,7,0:44.5
-9,7,0:98.0
-8,7,0:98.1
-7,7,0:98.0
-6,7,0:98.0
-5,7,0:98.0
-4,7,0:44.5
-1,7,0:98.0
2,7,0:17.3
3,7,0:44.5
4,7,0:98.0
5,7,0:98.1
6,7,0:44.5
7,7,0:44.5
8,7,0:44.5
9,7,0:44.5
10,7,0:44.5
11,7,0:98.0
-10,8,0:44.5
-9,8,0:43.5
-8,8,0:98.0
-7,8,0:98.1
-6,8,0:98.0
-5,8,0:43.5
-4,8,0:44.5
-2,8,0:98.0
-1,8,0:44.5
3,8,0:44.5
4,8,0:98.2
5,8,0:98.0
6,8,0:98.0
7,8,0:43.5
8,8,0:98.0
9,8,0:98.0
10,8,0:98.0
11,8,0:98.2
-10,9,0:44.5
-9,9,0:98.0
-8,9,0:98.0
-7,9,0:98.0
-6,9,0:98.0
-5,9,0:98.0
-4,9,0:44.5
0,9,0:98.0
4,9,0:98.2
9,9,0:44.5
-9,10,0:44.5
-8,10,0:98.0
-7,10,0:43.5
-6,10,0:98.0
-5,10,0:44.5
-4,10,0:98.1
-3,10,0:98.1
-2,10,0:98.0
-1,10,0:98.0
0,10,0:98.2
1,10,0:98.0
9,10,0:98.1
-8,11,0:44.5
-7,11,0:44.5
-6,11,0:44.5
-1,11,0:98.0
0,11,0:98.0
1,11,0:98.0
2,11,0:98.0
7,11,0:44.5
3,12,0:44.5
0,-10,1:18.15
7,-10,1:18.15
8,-10,1:18.7
9,-10,1:18.15
10,-10,1:18.15
-6,-9,1:98.0
-3,-9,1:98.0
-1,-9,1:18.6
0,-9,1:98.0
1,-9,1:18.15
3,-9,1:98.1
5,-9,1:18.15
6,-9,1:98.0
7,-9,1:18.15
9,-9,1:17.3
10,-9,1:98.0
11,-9,1:98.1
-9,-8,1:98.0
-8,-8,1:98.2
-7,-8,1:98.2
0,-8,1:18.14
11,-8,1:98.0
4,-7,1:109.3
9,-7,1:44.5
11,-7,1:98.0
3,-6,1:17.3
-12,-5,1:98.0
-12,-4,1:98.0
7,-4,1:17.3
11,-4,1:98.0
12,-4,1:18.13
-12,-3,1:98.0
-11,-3,1:44.5
-8,-3,1:98.2
-7,-3,1:98.2
4,-3,1:17.3
-6,-2,1:98.2
-3,-2,1:98.0
0,-2,1:98.0
3,-2,1:98.0
4,-2,1:98.0
-10,-1,1:98.3
-3,-1,1:17.3
-2,-1,1:17.3
0,-1,1:17.3
3,-1,1:17.3
4,-1,1:98.0
11,-1,1:98.1
12,1,1:18.14
4,2,1:98.0
11,2,1:98.0
12,2,1:17.3
13,2,1:18.14
-10,3,1:98.3
-1,3,1:18.15
10,3,1:18.14
11,3,1:18.14
12,3,1:18.14
2,4,1:18.15
3,4,1:17.3
10,4,1:18.6
-5,5,1:18.15
3,5,1:17.3
4,5,1:98.0
9,5,1:44.5
11,5,1:98.1
-8,6,1:98.1
-6,6,1:98.1
-5,6,1:18.15
-9,7,1:98.0
-5,7,1:98.0
-1,7,1:98.0
4,8,1:98.2
5,8,1:98.1
7,8,1:43.5
8,8,1:98.1
9,8,1:98.0
10,8,1:98.1
11,8,1:98.2
-9,9,1:98.0
-5,9,1:98.1
-8,10,1:98.0
-6,10,1:98.0
-4,10,1:98.0
-2,10,1:98.0
-1,10,1:98.0
0,10,1:98.2
9,-10,2:18.15
10,-10,2:18.15
-6,-9,2:98.0
-3,-9,2:98.0
0,-9,2:98.0
3,-9,2:98.0
6,-9,2:98.0
7,-9,2:18.15
9,-9,2:98.0
10,-9,2:98.0
11,-9,2:98.1
-8,-8,2:98.2
-7,-8,2:98.2
0,-8,2:18.14
11,-8,2:98.0
-8,-7,2:98.0
11,-7,2:98.0
3,-6,2:17.3
-12,-4,2:98.0
-8,-4,2:98.0
6,-4,2:30.0
7,-4,2:17.3
11,-4,2:98.0
-12,-3,2:98.0
-8,-3,2:98.2
-7,-3,2:98.2
4,-3,2:17.3
-6,-2,2:98.2
-3,-2,2:98.1
0,-2,2:98.0
3,-2,2:98.0
4,-2,2:98.0
-10,-1,2:98.3
-2,-1,2:17.3
0,-1,2:17.3
3,-1,2:17.3
4,-1,2:98.0
11,-1,2:98.0
12,1,2:18.14
4,2,2:98.0
10,2,2:18.14
11,2,2:98.0
12,2,2:17.3
13,2,2:18.14
-10,3,2:98.3
4,3,2:30.0
9,3,2:18.14
10,3,2:17.3
11,3,2:17.3
12,3,2:18.14
3,4,2:18.15
10,4,2:18.14
11,4,2:18.14
3,5,2:17.3
4,5,2:98.0
11,5,2:98.1
-8,6,2:98.0
-6,6,2:98.0
-5,6,2:18.15
-9,7,2:98.0
-5,7,2:98.1
4,8,2:98.2
5,8,2:43.5
8,8,2:43.5
9,8,2:44.5
10,8,2:98.0
11,8,2:98.2
-9,9,2:98.1
-5,9,2:98.1
-8,10,2:98.0
-6,10,2:98.0
9,-10,3:18.7
-6,-9,3:98.0
-5,-9,3:98.1
-4,-9,3:98.1
-3,-9,3:98.1
-2,-9,3:98.0
-1,-9,3:98.0
0,-9,3:98.0
1,-9,3:98.0
2,-9,3:98.0
3,-9,3:98.0
4,-9,3:98.0
5,-9,3:98.0
6,-9,3:98.0
7,-9,3:98.0
8,-9,3:98.0
9,-9,3:98.0
10,-9,3:98.0
11,-9,3:98.0
-8,-8,3:98.2
-7,-8,3:98.2
-1,-8,3:18.14
0,-8,3:18.6
11,-8,3:98.0
-8,-7,3:98.0
11,-7,3:98.0
-8,-6,3:98.0
3,-6,3:17.3
11,-6,3:98.0
-8,-5,3:98.0
11,-5,3:98.0
6,-4,3:17.3
7,-4,3:17.3
11,-4,3:98.0
-12,-3,3:98.0
-8,-3,3:98.2
-7,-3,3:98.2
3,-3,3:30.0
4,-3,3:17.3
11,-3,3:98.0
-6,-2,3:98.0
-5,-2,3:98.0
-4,-2,3:98.1
-3,-2,3:98.0
-2,-2,3:98.0
-1,-2,3:98.0
0,-2,3:98.1
1,-2,3:98.0
2,-2,3:98.0
3,-2,3:98.0
4,-2,3:98.0
11,-2,3:98.1
-10,-1,3:98.3
-2,-1,3:17.3
0,-1,3:17.3
3,-1,3:17.3
4,-1,3:98.0
11,-1,3:98.1
-10,0,3:109.7
4,0,3:98.0
11,0,3:98.0
4,1,3:98.0
11,1,3:98.0
-10,2,3:109.6
4,2,3:98.0
9,2,3:18.6
10,2,3:18.14
11,2,3:98.0
12,2,3:18.6
-10,3,3:98.3
4,3,3:98.0
9,3,3:18.14
10,3,3:17.3
11,3,3:98.0
4,4,3:98.0
10,4,3:18.14
11,4,3:98.0
3,5,3:17.3
4,5,3:98.0
11,5,3:98.0
-8,6,3:98.1
-7,6,3:98.0
-6,6,3:98.0
-5,6,3:18.7
4,6,3:98.0
11,6,3:98.0
-9,7,3:98.0
-5,7,3:98.0
4,7,3:98.0
11,7,3:98.0
-9,8,3:98.0
-5,8,3:98.0
4,8,3:98.0
5,8,3:44.5
6,8,3:44.5
7,8,3:44.5
8,8,3:43.5
10,8,3:98.0
11,8,3:98.0
-9,9,3:98.1
-5,9,3:98.0
-8,10,3:98.1
-7,10,3:98.0
-6,10,3:98.0
-6,-9,4:98.0
-5,-9,4:109.2
-4,-9,4:109.2
-3,-9,4:109.2
-2,-9,4:109.2
-1,-9,4:109.2
0,-9,4:109.2
1,-9,4:109.2
2,-9,4:109.2
3,-9,4:109.2
4,-9,4:109.2
7,-9,4:109.2
8,-9,4:109.2
9,-9,4:109.2
10,-9,4:109.2
11,-9,4:98.0
-8,-8,4:98.2
-7,-8,4:98.2
-6,-8,4:30.0
-2,-8,4:18.6
0,-8,4:18.14
10,-8,4:30.0
11,-8,4:109.1
-8,-7,4:98.0
11,-7,4:109.1
-8,-6,4:98.0
3,-6,4:17.3
11,-6,4:109.1
-8,-5,4:98.0
3,-5,4:17.3
11,-5,4:109.1
-8,-4,4:98.0
6,-4,4:17.3
11,-4,4:109.1
-8,-3,4:98.2
-7,-3,4:98.2
-6,-3,4:30.0
3,-3,4:17.3
11,-3,4:109.1
-6,-2,4:98.0
-5,-2,4:109.3
-3,-2,4:109.3
-2,-2,4:17.3
-1,-2,4:17.3
0,-2,4:109.3
1,-2,4:98.1
2,-2,4:109.3
3,-2,4:17.3
4,-2,4:98.0
11,-2,4:109.1
-10,-1,4:109.2
1,-1,4:17.3
4,-1,4:109.0
5,-1,4:98.0
11,-1,4:109.1
-10,0,4:98.3
4,0,4:109.0
5,0,4:30.0
10,0,4:18.14
11,0,4:109.1
-10,1,4:98.3
4,1,4:109.0
9,1,4:18.14
10,1,4:18.14
11,1,4:109.1
-10,2,4:98.3
4,2,4:109.0
9,2,4:18.14
10,2,4:17.3
11,2,4:109.1
-10,3,4:109.3
4,3,4:109.0
10,3,4:18.14
11,3,4:109.1
4,4,4:109.0
11,4,4:109.1
4,5,4:109.0
11,5,4:109.1
-8,6,4:98.1
-7,6,4:23.2
-6,6,4:98.0
4,6,4:109.0
11,6,4:109.1
-9,7,4:98.1
-5,7,4:98.0
4,7,4:109.0
10,7,4:30.0
11,7,4:109.1
-9,8,4:23.4
-5,8,4:23.5
10,8,4:98.1
11,8,4:109.1
-9,9,4:98.0
-8,10,4:98.1
-7,10,4:23.3
-6,10,4:98.0
-8,-8,5:109.2
-7,-8,5:109.2
-6,-8,5:98.0
-5,-8,5:109.2
-4,-8,5:109.2
-3,-8,5:109.2
-2,-8,5:109.2
-1,-8,5:109.2
0,-8,5:17.3
1,-8,5:109.2
2,-8,5:109.2
3,-8,5:109.2
6,-8,5:109.2
7,-8,5:109.2
8,-8,5:109.2
9,-8,5:109.2
10,-8,5:98.0
-8,-7,5:98.0
-6,-7,5:98.0
-5,-7,5:30.0
10,-7,5:109.1
-8,-6,5:98.0
10,-6,5:109.1
-8,-5,5:98.0
3,-5,5:17.3
10,-5,5:109.1
-8,-4,5:98.0
-6,-4,5:98.0
5,-4,5:17.3
6,-4,5:17.3
10,-4,5:109.1
-9,-3,5:109.3
-8,-3,5:109.3
-7,-3,5:109.3
-6,-3,5:98.0
-5,-3,5:109.3
-4,-3,5:109.3
-2,-3,5:109.3
-1,-3,5:109.3
0,-3,5:17.3
1,-3,5:109.3
2,-3,5:109.3
3,-3,5:17.3
4,-3,5:109.3
5,-3,5:98.0
10,-3,5:109.1
1,-2,5:17.3
3,-2,5:17.3
5,-2,5:109.0
10,-2,5:109.1
5,-1,5:109.0
10,-1,5:109.1
-10,0,5:44.5
5,0,5:109.0
10,0,5:109.1
-10,1,5:98.3
5,1,5:109.0
10,1,5:109.1
-10,2,5:44.5
5,2,5:109.0
10,2,5:109.1
5,3,5:109.0
10,3,5:109.1
5,4,5:109.0
10,4,5:109.1
5,5,5:109.0
10,5,5:109.1
-8,6,5:98.0
-7,6,5:98.1
-6,6,5:98.0
5,6,5:109.0
10,6,5:109.1
-9,7,5:98.1
-8,7,5:98.0
-6,7,5:98.0
-5,7,5:98.1
5,7,5:109.0
10,7,5:109.1
-9,8,5:98.0
-6,8,5:98.0
10,8,5:109.1
-9,9,5:98.0
-8,9,5:98.0
-6,9,5:98.0
-8,10,5:98.0
-7,10,5:98.0
1,-8,6:17.3
-8,-7,6:109.2
-7,-7,6:109.2
-6,-7,6:98.2
-5,-7,6:98.2
-4,-7,6:98.2
-3,-7,6:98.2
-2,-7,6:98.2
-1,-7,6:98.2
0,-7,6:98.2
1,-7,6:98.2
2,-7,6:98.2
3,-7,6:98.2
5,-7,6:98.2
6,-7,6:98.2
7,-7,6:98.2
8,-7,6:98.2
9,-7,6:98.2
-8,-6,6:98.0
-7,-6,6:30.0
8,-6,6:30.0
9,-6,6:98.2
-8,-5,6:98.0
3,-5,6:17.3
9,-5,6:98.2
-9,-4,6:109.3
-8,-4,6:109.3
-7,-4,6:109.3
-6,-4,6:98.2
-5,-4,6:98.2
-4,-4,6:98.2
-3,-4,6:98.2
-2,-4,6:98.2
-1,-4,6:98.2
0,-4,6:98.2
1,-4,6:98.2
2,-4,6:98.2
3,-4,6:98.2
4,-4,6:98.2
5,-4,6:17.3
6,-4,6:98.2
9,-4,6:98.2
-5,-3,6:17.3
-4,-3,6:17.3
1,-3,6:17.3
2,-3,6:17.3
3,-3,6:17.3
6,-3,6:98.2
9,-3,6:98.2
6,-2,6:98.2
9,-2,6:98.2
6,-1,6:98.2
9,-1,6:98.2
6,0,6:98.2
9,0,6:98.2
6,1,6:98.2
9,1,6:98.2
6,2,6:98.2
9,2,6:98.2
6,3,6:98.2
9,3,6:98.2
6,4,6:98.2
9,4,6:98.2
6,5,6:98.2
9,5,6:98.2
-7,6,6:98.2
6,6,6:98.2
9,6,6:98.2
-8,7,6:98.0
-7,7,6:98.0
-6,7,6:98.0
9,7,6:98.2
-9,8,6:98.2
-8,8,6:98.0
-6,8,6:98.0
9,8,6:98.2
-8,9,6:98.1
-7,9,6:98.0
-7,10,6:98.2
-6,-7,7:98.0
-5,-7,7:109.2
-4,-7,7:109.2
-3,-7,7:109.2
-2,-7,7:109.2
-1,-7,7:109.2
0,-7,7:109.2
1,-7,7:109.2
2,-7,7:17.3
4,-7,7:109.2
5,-7,7:109.2
6,-7,7:109.2
7,-7,7:109.2
8,-7,7:109.2
-8,-6,7:109.2
-7,-6,7:109.2
-6,-6,7:98.0
3,-6,7:30.0
8,-6,7:98.0
9,-6,7:109.1
-8,-5,7:109.3
-7,-5,7:109.3
-6,-5,7:98.0
3,-5,7:17.3
9,-5,7:109.1
-6,-4,7:98.0
-5,-4,7:109.3
-4,-4,7:109.3
-3,-4,7:109.3
-2,-4,7:109.3
-1,-4,7:109.3
0,-4,7:109.3
1,-4,7:109.3
2,-4,7:109.3
3,-4,7:17.3
4,-4,7:17.3
5,-4,7:109.3
6,-4,7:98.0
9,-4,7:109.1
-3,-3,7:17.3
-2,-3,7:17.3
3,-3,7:17.3
6,-3,7:109.0
9,-3,7:109.1
6,-2,7:109.0
9,-2,7:109.1
6,-1,7:109.0
9,-1,7:109.1
6,0,7:109.0
9,0,7:109.1
6,1,7:109.0
9,1,7:109.1
6,2,7:109.0
9,2,7:109.1
6,3,7:109.0
9,3,7:109.1
6,4,7:109.0
9,4,7:109.1
6,5,7:109.0
9,5,7:109.1
-7,6,7:98.2
9,6,7:109.1
-8,7,7:98.0
-7,7,7:98.0
-6,7,7:98.1
9,7,7:109.1
-9,8,7:98.2
-8,8,7:98.0
-8,9,7:98.1
-7,9,7:98.0
-7,10,7:98.2
5,-7,8:17.3
6,-7,8:17.3
-6,-6,8:98.0
-5,-6,8:109.2
-4,-6,8:109.2
-3,-6,8:109.2
-2,-6,8:109.2
-1,-6,8:109.2
0,-6,8:109.2
1,-6,8:109.2
2,-6,8:17.3
3,-6,8:109.2
4,-6,8:109.2
5,-6,8:17.3
6,-6,8:109.2
7,-6,8:109.2
-6,-5,8:98.0
-5,-5,8:109.3
-4,-5,8:109.3
-3,-5,8:109.3
-2,-5,8:109.3
-1,-5,8:109.3
0,-5,8:109.3
1,-5,8:109.3
2,-5,8:109.3
3,-5,8:109.3
4,-5,8:109.3
5,-5,8:109.3
6,-5,8:109.3
7,-5,8:98.0
8,-5,8:109.1
-6,-4,8:17.3
-5,-4,8:17.3
-4,-4,8:17.3
-1,-4,8:17.3
0,-4,8:17.3
1,-4,8:17.3
2,-4,8:17.3
3,-4,8:17.3
4,-4,8:17.3
7,-4,8:109.0
8,-4,8:109.1
-1,-3,8:17.3
7,-3,8:109.0
8,-3,8:109.1
7,-2,8:109.0
8,-2,8:109.1
7,-1,8:109.0
8,-1,8:109.1
7,0,8:109.0
8,0,8:109.1
7,1,8:109.0
8,1,8:109.1
7,2,8:109.0
8,2,8:109.1
7,3,8:109.0
8,3,8:109.1
7,4,8:109.0
8,4,8:109.1
8,5,8:109.1
8,6,8:109.1
-8,7,8:98.0
-7,7,8:98.0
-6,7,8:98.0
-8,8,8:98.1
-8,9,8:98.1
4,-6,9:17.3
3,-5,9:17.3
4,-5,9:17.3
3,-4,9:17.3
4,-4,9:17.3
-8,7,9:98.0
-7,7,9:98.0
-8,8,9:44.5
3,-5,10:17.3
4,-5,10:17.3
3,-4,10:17.3
4,-4,10:17.3
-8,7,10:98.0
3,-5,11:17.3
4,-5,11:17.3
3,-4,11:17.3
4,-4,11:17.3
3,-5,12:17.3
4,-5,12:17.3
2,-4,12:18.7
3,-4,12:17.3
4,-4,12:17.3
3,-5,13:17.3
4,-5,13:17.3
2,-4,13:18.15
3,-4,13:17.3
4,-4,13:17.3
3,-6,14:18.15
4,-6,14:18.15
2,-5,14:18.15
3,-5,14:17.3
4,-5,14:17.3
5,-5,14:18.15
3,-4,14:18.7
4,-4,14:17.3
3,-6,15:17.3
4,-6,15:17.3
5,-6,15:17.3
6,-6,15:18.15
7,-6,15:18.7
3,-5,15:17.3
4,-5,15:17.3
5,-5,15:17.3
6,-5,15:18.15
7,-5,15:18.15
3,-4,15:18.15
4,-4,15:17.3
4,-6,16:17.3
5,-6,16:17.3
4,-5,16:17.3
5,-5,16:17.3
6,-5,16:18.15
4,-6,17:17.3
5,-6,17:17.3
4,-5,17:17.3
5,-5,17:17.3
6,-5,17:17.3
4,-4,17:18.15
5,-4,17:18.15
4,-6,18:17.3
5,-6,18:17.3
4,-5,18:17.3
5,-5,18:17.3
6,-5,18:17.3
5,-4,18:18.15
5,-6,19:17.3
6,-6,19:17.3
4,-5,19:18.15
5,-5,19:17.3
6,-5,19:17.3
5,-4,19:18.15
5,-6,20:17.3
6,-6,20:17.3
4,-5,20:18.7
5,-5,20:17.3
6,-5,20:17.3
5,-4,20:18.15
6,-7,21:17.3
5,-6,21:17.3
6,-6,21:17.3
7,-6,21:17.3
4,-5,21:18.15
5,-5,21:17.3
6,-5,21:17.3
5,-4,21:18.15
6,-4,21:18.15
5,-7,22:18.15
6,-7,22:17.3
7,-7,22:17.3
5,-6,22:18.15
6,-6,22:17.3
7,-6,22:17.3
5,-5,22:18.15
6,-5,22:18.15
7,-5,22:18.15
6,-8,23:18.15
4,-7,23:18.15
5,-7,23:18.15
6,-7,23:17.3
7,-7,23:17.3
8,-7,23:18.15
5,-6,23:18.15
6,-6,23:17.3
7,-6,23:17.3
8,-6,23:18.15
6,-5,23:18.15
5,-9,24:18.15
6,-9,24:18.15
7,-9,24:18.4
4,-8,24:18.12
5,-8,24:18.15
6,-8,24:17.3
7,-8,24:17.3
5,-7,24:18.15
6,-7,24:17.3
7,-7,24:17.3
8,-7,24:18.12
6,-6,24:18.15
7,-6,24:18.7
3,-10,25:18.12
5,-10,25:18.15
6,-10,25:18.15
3,-9,25:18.12
4,-9,25:18.15
5,-9,25:17.3
6,-9,25:17.3
3,-8,25:18.12
4,-8,25:18.15
5,-8,25:17.3
6,-8,25:17.3
7,-8,25:18.15
9,-8,25:18.12
5,-7,25:18.7
6,-7,25:18.15
7,-7,25:17.3
8,-7,25:17.3
9,-7,25:18.12
6,-6,25:18.15
7,-6,25:18.15
8,-6,25:18.12
10,-6,25:18.12
11,-6,25:18.12
11,-5,25:18.12
1,-11,26:18.12
3,-11,26:18.12
4,-11,26:18.4
1,-10,26:18.12
2,-10,26:18.12
3,-10,26:17.3
4,-10,26:18.15
5,-10,26:18.15
6,-10,26:18.15
1,-9,26:18.12
2,-9,26:18.4
3,-9,26:17.3
4,-9,26:17.3
5,-9,26:17.3
6,-9,26:17.3
7,-9,26:18.15
3,-8,26:18.12
4,-8,26:18.12
5,-8,26:17.3
6,-8,26:17.3
7,-8,26:18.15
8,-8,26:18.15
9,-8,26:18.15
5,-7,26:18.15
6,-7,26:18.15
7,-7,26:18.12
8,-7,26:17.3
9,-7,26:17.3
10,-7,26:18.15
7,-6,26:18.15
8,-6,26:18.12
9,-6,26:17.3
10,-6,26:17.3
11,-6,26:18.12
9,-5,26:18.15
10,-5,26:17.3
11,-5,26:17.3
12,-5,26:18.4
10,-4,26:18.12
12,-4,26:18.12
10,-3,26:18.12
-1,-12,27:18.12
1,-12,27:18.4
0,-11,27:18.12
1,-11,27:17.3
2,-11,27:18.15
3,-11,27:18.15
0,-10,27:18.12
1,-10,27:17.3
2,-10,27:17.3
3,-10,27:17.3
4,-10,27:18.15
6,-10,27:18.15
1,-9,27:18.12
2,-9,27:18.12
3,-9,27:18.15
4,-9,27:18.15
5,-9,27:18.15
6,-9,27:17.3
7,-9,27:18.15
4,-8,27:18.15
5,-8,27:17.3
6,-8,27:17.3
7,-8,27:18.15
8,-8,27:18.15
5,-7,27:18.15
6,-7,27:18.15
7,-7,27:18.15
8,-7,27:18.15
9,-7,27:18.15
7,-6,27:18.7
9,-6,27:18.15
10,-6,27:18.15
11,-6,27:18.15
9,-5,27:18.15
10,-5,27:18.15
11,-5,27:17.3
12,-5,27:18.12
9,-4,27:18.15
11,-4,27:18.12
12,-4,27:17.3
13,-4,27:18.12
11,-3,27:18.15
12,-3,27:18.12
13,-3,27:18.12
-1,-13,28:18.4
-2,-12,28:18.12
-1,-12,28:17.3
0,-12,28:18.12
1,-12,28:18.12
-1,-11,28:18.12
0,-11,28:17.3
1,-11,28:17.3
2,-11,28:18.15
0,-10,28:18.12
1,-10,28:18.15
2,-10,28:18.15
3,-10,28:18.15
5,-10,28:18.12
6,-10,28:18.15
0,-9,28:18.12
1,-9,28:18.12
3,-9,28:18.15
4,-9,28:18.15
5,-9,28:18.15
6,-9,28:17.3
7,-9,28:18.15
4,-8,28:18.15
5,-8,28:17.3
6,-8,28:17.3
7,-8,28:18.15
8,-8,28:18.15
5,-7,28:18.15
6,-7,28:18.15
8,-7,28:18.15
9,-7,28:18.15
10,-6,28:18.15
10,-5,28:18.15
11,-5,28:18.15
12,-5,28:18.12
13,-5,28:18.12
10,-4,28:18.15
12,-4,28:18.15
13,-4,28:17.3
14,-4,28:18.12
11,-3,28:18.15
12,-3,28:18.12
13,-3,28:17.3
12,-2,28:18.15
13,-2,28:18.12
-3,-13,29:18.7
-2,-13,29:17.3
-1,-13,29:18.12
-3,-12,29:18.12
-2,-12,29:17.3
-1,-12,29:17.3
0,-12,29:18.12
-2,-11,29:18.12
-1,-11,29:18.12
0,-11,29:18.12
1,-11,29:18.15
2,-11,29:18.12
5,-11,29:18.12
6,-11,29:18.15
2,-10,29:18.12
3,-10,29:18.15
4,-10,29:18.15
5,-10,29:17.3
6,-10,29:17.3
7,-10,29:18.15
2,-9,29:18.7
4,-9,29:18.7
5,-9,29:18.15
6,-9,29:17.3
7,-9,29:18.15
5,-8,29:18.15
6,-8,29:18.15
7,-8,29:18.15
8,-8,29:18.15
6,-7,29:18.15
7,-7,29:18.15
8,-7,29:17.3
7,-6,29:18.15
8,-6,29:18.15
10,-6,29:18.15
13,-4,29:18.15
12,-3,29:18.7
13,-3,29:18.15
14,-3,29:18.15
-2,-13,30:18.15
-2,-12,30:18.12
-1,-12,30:18.12
5,-12,30:18.15
2,-11,30:18.15
4,-11,30:18.15
5,-11,30:17.3
6,-11,30:18.15
2,-10,30:18.15
3,-10,30:18.15
4,-10,30:18.15
5,-10,30:17.3
6,-10,30:18.15
4,-9,30:18.15
5,-9,30:18.15
6,-9,30:18.15
6,-8,30:18.15
8,-8,30:18.15
7,-7,30:18.15
8,-7,30:17.3
9,-7,30:18.15
8,-6,30:18.15
9,-6,30:18.15
10,-6,30:18.7
4,-12,31:18.15
5,-12,31:18.12
3,-11,31:18.15
4,-11,31:17.3
5,-11,31:17.3
6,-11,31:18.15
4,-10,31:18.15
5,-10,31:18.15
6,-10,31:18.7
4,-9,31:18.15
5,-9,31:17.3
6,-9,31:18.15
4,-8,31:18.7
5,-8,31:18.15
6,-8,31:18.15
7,-8,31:18.7
8,-8,31:18.15
7,-7,31:18.15
8,-7,31:18.15
9,-7,31:18.15
8,-6,31:18.15
9,-6,31:17.3
10,-6,31:18.15
11,-6,31:18.15
9,-5,31:18.15
4,-13,32:18.12
3,-12,32:18.15
4,-12,32:17.3
3,-11,32:18.15
4,-11,32:18.15
5,-11,32:18.15
5,-10,32:18.15
6,-10,32:18.15
3,-9,32:18.15
4,-9,32:18.15
5,-9,32:17.3
6,-9,32:18.15
3,-8,32:18.15
4,-8,32:18.15
5,-8,32:18.15
6,-8,32:18.15
7,-8,32:18.15
5,-7,32:18.15
7,-7,32:18.15
8,-7,32:18.15
9,-7,32:18.15
10,-7,32:18.15
9,-6,32:18.15
10,-6,32:18.15
9,-5,32:18.7
10,-5,32:17.3
11,-5,32:18.15
10,-4,32:18.15
3,-13,33:18.12
4,-13,33:18.12
4,-12,33:17.3
5,-12,33:18.15
4,-11,33:18.15
5,-10,33:18.15
6,-10,33:18.15
3,-9,33:18.15
4,-9,33:18.15
5,-9,33:17.3
6,-9,33:18.15
3,-8,33:18.15
4,-8,33:17.3
5,-8,33:18.15
6,-8,33:18.15
7,-8,33:18.15
3,-7,33:18.15
4,-7,33:18.15
10,-5,33:18.15
3,-14,34:18.4
4,-14,34:18.15
2,-13,34:18.15
3,-13,34:17.3
4,-13,34:17.3
5,-13,34:18.15
3,-12,34:18.15
4,-12,34:18.15
5,-10,34:18.15
4,-9,34:18.7
5,-9,34:17.3
6,-9,34:18.15
7,-9,34:18.15
3,-8,34:18.15
4,-8,34:17.3
5,-8,34:18.15
2,-7,34:18.15
3,-7,34:17.3
4,-7,34:17.3
5,-7,34:18.15
3,-6,34:18.15
4,-6,34:18.15
4,-14,35:18.15
3,-13,35:18.15
4,-13,35:18.15
5,-10,35:18.15
6,-10,35:18.15
5,-9,35:18.15
6,-9,35:17.3
7,-9,35:18.15
4,-8,35:18.15
6,-8,35:18.15
2,-7,35:18.15
3,-7,35:18.15
4,-7,35:18.15
5,-7,35:18.15
2,-6,35:18.15
3,-6,35:17.3
4,-6,35:18.15
3,-5,35:18.7
7,-10,36:18.7
6,-9,36:18.15
7,-9,36:17.3
8,-9,36:18.15
7,-8,36:18.15
1,-7,36:18.15
2,-7,36:18.15
3,-7,36:18.15
4,-7,36:18.15
1,-6,36:18.15
2,-6,36:17.3
3,-6,36:18.15
2,-5,36:18.15
3,-5,36:18.15
5,-10,37:18.15
6,-10,37:18.15
7,-10,37:18.15
8,-10,37:18.15
5,-9,37:18.7
6,-9,37:18.15
7,-9,37:17.3
8,-9,37:18.15
9,-9,37:18.7
7,-8,37:18.15
2,-7,37:18.15
1,-6,37:18.15
2,-6,37:17.3
3,-6,37:18.15
2,-5,37:18.15
7,-9,38:18.7
2,-6,38:18.15
1,-5,38:18.15
2,-5,38:17.3
3,-5,38:18.7
2,-4,38:18.15
2,-6,39:18.15
2,-5,39:18.15
2,-5,12:106.8
4,-6,12:106.1
3,-6,12:106.1
3,-3,11:106.4
2,-5,11:106.8
4,-6,11:106.1
3,-6,11:106.1
-7,7,10:106.2
-9,7,10:106.8
-8,6,10:106.1
3,-3,10:106.4
2,-4,10:106.8
2,-5,10:106.8
4,-6,10:106.1
3,-6,10:106.1
-9,7,9:106.8
-8,6,9:106.1
3,-3,9:106.4
2,-4,9:106.8
2,-5,9:106.8
3,-6,9:106.1
4,-7,9:106.1
-9,7,8:106.8
-6,6,8:106.1
-8,6,8:106.1
3,-3,8:106.4
-7,-4,8:106.8
-7,-5,8:106.8
-7,-6,8:106.8
4,-7,8:106.1
-7,11,7:106.4
-8,10,7:106.4
-9,9,7:106.4
-9,7,7:106.8
-6,6,7:106.1
-8,6,7:106.1
-2,-2,7:106.4
-3,-2,7:106.4
-6,-3,7:106.4
-7,-4,7:106.8
-7,11,6:106.4
-8,10,6:106.4
-9,9,6:106.4
10,7,6:106.2
-9,7,6:106.8
10,6,6:106.2
-6,6,6:106.1
-8,6,6:106.1
10,5,6:106.2
10,4,6:106.2
10,3,6:106.2
8,0,6:106.8
8,-1,6:106.8
7,-1,6:106.2
3,-2,6:106.4
1,-2,6:106.4
-2,-2,6:106.4
-3,-2,6:106.4
-5,-2,6:106.4
10,-3,6:106.2
0,-3,6:106.8
-6,-3,6:106.4
8,-4,6:106.8
10,-5,6:106.2
-1,-5,6:106.1
-3,-5,6:106.1
-7,-5,6:106.2
10,-6,6:106.2
-9,-6,6:106.8
10,-7,6:106.2
5,-8,6:106.1
2,-8,6:106.3
-1,-8,6:106.1
-4,-8,6:106.1
-5,-8,6:106.1
-6,-8,6:106.1
1,-9,6:106.1
-7,11,5:106.4
-6,5,5:106.1
-7,5,5:106.1
8,0,5:106.8
8,-1,5:106.8
7,-1,5:106.2
-2,-2,5:106.4
-3,-2,5:106.4
-5,-2,5:106.4
8,-4,5:106.8
-1,-5,5:106.1
-3,-5,5:106.1
-7,-5,5:106.2
-7,-6,5:106.2
-9,-6,5:106.8
5,-8,5:106.1
1,-9,5:106.1
-6,11,4:106.4
-7,11,4:106.4
-6,5,4:106.1
-7,5,4:106.1
8,1,4:106.8
-11,1,4:106.8
8,0,4:106.8
1,0,4:106.4
8,-1,4:106.8
7,-1,4:106.2
3,-1,4:106.4
-7,-2,4:106.4
-8,-2,4:106.4
-9,-3,4:106.8
8,-4,4:106.8
-9,-4,4:106.8
2,-5,4:106.8
-1,-5,4:106.1
-3,-5,4:106.1
-7,-5,4:106.2
-7,-6,4:106.2
-9,-6,4:106.8
-7,-7,4:106.2
-9,-7,4:106.8
5,-8,4:106.1
12,-9,4:106.2
-8,-9,4:106.1
-6,11,3:106.4
-7,11,3:106.4
10,9,3:106.4
-4,9,3:106.2
12,8,3:106.2
3,7,3:106.8
12,6,3:106.2
10,6,3:106.8
3,6,3:106.8
-9,6,3:106.1
12,5,3:106.2
10,5,3:106.8
2,5,3:106.8
-6,5,3:106.1
-7,5,3:106.1
5,4,3:106.2
3,4,3:106.8
8,3,3:106.8
3,3,3:106.8
3,2,3:106.8
10,1,3:106.8
8,1,3:106.8
3,1,3:106.8
10,0,3:106.8
8,0,3:106.8
3,0,3:106.4
1,0,3:106.4
0,0,3:106.4
8,-1,3:106.8
7,-1,3:106.2
2,-1,3:106.8
-3,-1,3:106.4
-4,-1,3:106.4
-5,-1,3:106.4
-6,-1,3:106.4
12,-2,3:106.2
-7,-2,3:106.4
-8,-2,3:106.4
10,-3,3:106.8
-1,-3,3:106.1
-9,-3,3:106.8
-11,-3,3:106.2
-13,-3,3:106.8
12,-4,3:106.2
10,-4,3:106.8
8,-4,3:106.8
5,-4,3:106.8
-9,-4,3:106.8
12,-5,3:106.2
10,-5,3:106.8
7,-5,3:106.1
2,-5,3:106.8
-1,-5,3:106.1
-3,-5,3:106.1
-7,-5,3:106.2
12,-6,3:106.2
-7,-6,3:106.2
-9,-6,3:106.8
12,-7,3:106.2
-7,-7,3:106.2
-9,-7,3:106.8
6,-8,3:106.4
5,-8,3:106.1
-9,-8,3:106.8
12,-9,3:106.2
-8,-9,3:106.1
11,-10,3:106.1
10,-10,3:106.1
7,-10,3:106.1
6,-10,3:106.1
3,-10,3:106.1
0,-10,3:106.1
-3,-10,3:106.1
-4,-10,3:106.1
-6,-10,3:106.1
-6,11,2:106.4
-7,11,2:106.4
11,9,2:106.4
10,9,2:106.4
4,9,2:106.4
-4,9,2:106.2
12,8,2:106.2
3,7,2:106.8
12,6,2:106.2
10,6,2:106.8
3,6,2:106.8
-9,6,2:106.1
12,5,2:106.2
10,5,2:106.8
5,5,2:106.2
2,5,2:106.8
-6,5,2:106.1
-7,5,2:106.1
5,4,2:106.2
8,3,2:106.8
3,3,2:106.8
3,2,2:106.8
13,1,2:106.1
10,1,2:106.8
8,1,2:106.8
3,1,2:106.8
12,0,2:106.1
10,0,2:106.8
8,0,2:106.8
3,0,2:106.4
1,0,2:106.4
0,0,2:106.4
8,-1,2:106.8
7,-1,2:106.2
2,-1,2:106.8
-3,-1,2:106.4
-4,-1,2:106.4
-5,-1,2:106.4
-6,-1,2:106.4
-9,-1,2:106.2
12,-2,2:106.2
-7,-2,2:106.4
-8,-2,2:106.4
10,-3,2:106.8
-1,-3,2:106.1
-9,-3,2:106.8
-11,-3,2:106.2
-13,-3,2:106.8
12,-4,2:106.2
10,-4,2:106.8
8,-4,2:106.8
5,-4,2:106.8
-9,-4,2:106.8
-11,-4,2:106.2
-13,-4,2:106.8
12,-5,2:106.2
10,-5,2:106.8
7,-5,2:106.1
2,-5,2:106.8
-1,-5,2:106.1
-3,-5,2:106.1
-7,-5,2:106.2
12,-6,2:106.2
2,-6,2:106.8
-7,-6,2:106.2
-9,-6,2:106.8
12,-7,2:106.2
-7,-7,2:106.2
-9,-7,2:106.8
6,-8,2:106.4
5,-8,2:106.1
-3,-8,2:106.4
-9,-8,2:106.8
12,-9,2:106.2
-8,-9,2:106.1
11,-10,2:106.1
7,-10,2:106.1
6,-10,2:106.1
3,-10,2:106.1
0,-10,2:106.1
-3,-10,2:106.1
-4,-10,2:106.1
-6,-10,2:106.1
-6,11,1:106.4
-7,11,1:106.4
11,9,1:106.4
10,9,1:106.4
4,9,1:106.4
-4,9,1:106.2
12,8,1:106.2
3,8,1:106.8
3,7,1:106.8
12,6,1:106.2
10,6,1:106.8
3,6,1:106.8
-9,6,1:106.9
12,5,1:106.2
10,5,1:106.8
5,5,1:106.2
2,5,1:106.8
-6,5,1:106.1
-7,5,1:106.1
-8,5,1:106.1
5,4,1:106.2
8,3,1:106.8
3,3,1:106.8
-9,3,1:106.2
-11,3,1:106.8
10,2,1:106.8
3,2,1:106.8
13,1,1:106.1
10,1,1:106.8
8,1,1:106.8
3,1,1:106.8
12,0,1:106.1
10,0,1:106.8
8,0,1:106.8
3,0,1:106.4
1,0,1:106.4
0,0,1:106.4
-10,0,1:106.4
12,-1,1:106.2
8,-1,1:106.8
2,-1,1:106.8
-4,-1,1:106.4
-5,-1,1:106.4
-6,-1,1:106.4
-9,-1,1:106.2
12,-2,1:106.2
-7,-2,1:106.4
-8,-2,1:106.4
10,-3,1:106.8
-1,-3,1:106.1
-9,-3,1:106.8
-13,-3,1:106.8
10,-4,1:106.8
8,-4,1:106.10
5,-4,1:106.8
-9,-4,1:106.8
-11,-4,1:106.2
-13,-4,1:106.8
12,-5,1:106.2
10,-5,1:106.8
7,-5,1:106.1
2,-5,1:106.8
-1,-5,1:106.1
-3,-5,1:106.1
-7,-5,1:106.2
-11,-5,1:106.2
12,-6,1:106.2
2,-6,1:106.8
-7,-6,1:106.2
-9,-6,1:106.8
12,-7,1:106.2
-7,-7,1:106.2
-9,-7,1:106.8
12,-8,1:106.2
6,-8,1:106.4
5,-8,1:106.1
-3,-8,1:106.4
12,-9,1:106.2
-8,-9,1:106.1
-9,-9,1:106.1
11,-10,1:106.1
6,-10,1:106.1
3,-10,1:106.1
-3,-10,1:106.1
-4,-10,1:106.1
-6,-10,1:106.1
-2,12,0:31.1
-3,12,0:31.1
-4,12,0:31.1
-5,12,0:37.0
-8,12,0:31.1
9,11,0:31.1
8,11,0:31.1
6,11,0:31.1
4,11,0:31.2
3,11,0:31.1
-2,11,0:31.1
-3,11,0:37.0
-4,11,0:31.1
-9,11,0:31.1
10,10,0:31.1
8,10,0:31.1
7,10,0:31.1
6,10,0:31.1
3,10,0:31.1
2,10,0:37.0
-10,10,0:31.1
11,9,0:31.1
10,9,0:37.0
8,9,0:31.1
7,9,0:31.1
6,9,0:31.1
5,9,0:31.2
3,9,0:31.1
2,9,0:31.1
1,9,0:37.0
12,8,0:106.2
2,8,0:31.1
0,8,0:31.1
12,7,0:31.1
1,7,0:31.1
0,7,0:31.1
-2,7,0:37.0
12,6,0:31.1
1,6,0:37.0
0,6,0:31.1
-1,6,0:31.1
-2,6,0:31.1
-10,6,0:31.1
13,5,0:31.1
12,5,0:31.1
2,5,0:106.8
1,5,0:31.1
0,5,0:31.1
-1,5,0:31.1
-2,5,0:31.1
-3,5,0:31.1
-4,5,0:31.1
-9,5,0:31.1
-10,5,0:37.0
13,4,0:31.1
12,4,0:31.1
-2,4,0:31.1
-3,4,0:31.1
-4,4,0:37.0
-5,4,0:31.1
-7,4,0:31.1
-10,4,0:106.4
13,3,0:31.1
12,3,0:31.2
8,3,0:106.8
1,3,0:31.1
0,3,0:31.1
-2,3,0:31.1
-3,3,0:37.0
-4,3,0:31.1
-5,3,0:31.1
-6,3,0:31.1
-7,3,0:31.1
-8,3,0:31.1
-9,3,0:106.2
-11,3,0:106.8
2,2,0:31.1
1,2,0:31.1
-1,2,0:31.1
-3,2,0:31.1
-4,2,0:31.1
-5,2,0:31.1
-6,2,0:31.1
-7,2,0:31.1
-9,2,0:31.1
-10,2,0:106.1
2,1,0:31.1
1,1,0:38.0
-7,1,0:31.1
-8,1,0:31.1
-10,1,0:31.1
13,0,0:31.1
1,0,0:31.2
-7,0,0:31.1
-10,0,0:106.4
13,-1,0:31.1
12,-1,0:31.1
-8,-1,0:31.1
-9,-1,0:106.2
13,-2,0:31.1
12,-2,0:37.0
-7,-2,0:106.4
-8,-2,0:106.4
-9,-2,0:31.2
13,-3,0:31.1
-10,-3,0:106.2
-13,-3,0:106.8
10,-4,0:106.8
-11,-4,0:31.1
-13,-4,0:106.8
13,-5,0:31.1
12,-5,0:106.2
-1,-5,0:106.1
-11,-5,0:38.0
13,-6,0:31.1
12,-6,0:106.2
-11,-6,0:31.1
-13,-6,0:106.8
13,-7,0:37.0
12,-7,0:31.1
-11,-7,0:31.1
13,-8,0:37.0
12,-8,0:31.1
-11,-8,0:31.1
12,-9,0:31.2
-8,-9,0:106.1
-9,-9,0:31.1
-10,-9,0:31.1
11,-10,0:106.1
4,-10,0:31.2
3,-10,0:106.1
2,-10,0:106.1
-2,-10,0:106.1
-3,-10,0:106.1
-4,-10,0:106.1
-6,-10,0:31.2
8,5,-1:106.8
8,4,-1:106.8
8,3,-1:106.8
8,5,-2:106.8
8,4,-2:106.8
-4,0,-2:76.1
-13,-3,-2:106.0
-4,-4,-2:76.1
-12,-4,-2:106.0
-13,-4,-2:106.0
-13,-5,-2:106.0
8,6,-3:106.8
8,5,-3:106.8
-6,-2,-4:76.1
