[META]
version=2.0
spawnOnBlockType=2
spawnSunlight=True
spawnDarkness=True
spawnWater=False
spawnLava=False
underFill=False
randomRotation=True
dig=False
tree=False
branch=False
needsFoundation=True
rarity=500
collisionPercentage=80
spawnElevationMin=0
spawnElevationMax=245
spawnInBiome=Plains
[DATA]
0,0,0:17.0
0,-1,0:17.0
-1,0,0:17.0
0,1,0:17.0
1,0,0:17.0
0,-2,0:17.0
-1,-1,0:17.0
-2,0,0:17.0
1,1,0:17.0
1,-1,0:31.2
-2,-1,0:31.2
0,2,0:31.2
-1,1,0:31.1
-3,0,0:31.1
-1,-2,0:31.1
1,-2,0:31.1
2,0,0:31.1
1,2,0:31.1
0,3,0:31.1
3,1,0:31.1
-2,1,0:31.2
2,1,0:31.2
3,0,0:31.2
0,-3,0:31.1
2,-1,0:31.1
2,2,0:31.1
1,3,0:31.1
-1,2,0:31.1
-6,-2,0:18.0
6,0,0:18.0
5,4,0:18.1
0,7,0:18.0
-5,-2,0:106.2
-7,-2,0:18.0
-6,-3,0:18.0
-6,-1,0:18.0
-4,-2,0:18.0
-5,-3,0:18.0
-5,-1,0:18.0
-6,0,0:18.0
2,-7,0:18.2
3,-7,0:18.2
3,-6,0:18.2
6,1,0:18.0
6,2,0:18.0
5,1,0:18.0
7,-1,0:18.0
7,0,0:18.0
4,5,0:18.1
3,5,0:18.1
3,6,0:18.1
5,5,0:18.1
-2,6,0:18.0
-1,6,0:18.0
0,6,0:18.0
1,7,0:18.0
4,7,0:18.1
4,6,0:18.1
5,6,0:18.1
-1,5,0:18.0
0,5,0:18.0
1,6,0:18.0
4,-6,0:18.2
3,-5,0:18.2
4,-4,0:18.2
3,-4,0:18.2
2,-6,0:18.2
1,-6,0:18.2
1,-5,0:18.2
4,-5,0:106.1
-1,7,0:18.0
4,1,0:30
0,0,1:17.0
-1,0,1:17.0
0,-1,1:17.0
0,1,1:17.0
1,0,1:17.0
-3,2,1:106.2
-1,-6,1:106.1
3,0,1:106.1
4,-5,1:106.1
-5,-2,1:106.2
3,7,1:106.4
-1,6,1:18.0
-1,5,1:18.0
-1,7,1:18.0
0,6,1:18.0
1,7,1:18.0
1,6,1:18.0
0,7,1:18.0
6,1,1:18.0
7,0,1:18.0
5,1,1:18.0
4,6,1:18.1
3,6,1:18.1
5,5,1:18.1
4,5,1:18.1
2,6,1:30
-6,-2,1:18.0
-4,-2,1:18.0
-5,-3,1:18.0
0,0,2:17.0
-1,0,2:17.0
0,-1,2:17.0
0,1,2:17.0
1,0,2:17.0
3,0,2:106.1
3,7,2:106.4
-3,2,2:106.2
-1,-6,2:106.1
-1,6,2:18.0
1,7,2:18.0
0,0,3:17.0
0,-1,3:17.0
0,1,3:17.0
1,0,3:17.0
3,7,3:106.4
3,0,3:106.1
-1,-6,3:106.1
-3,2,3:106.2
0,0,4:17.0
0,-1,4:17.0
1,0,4:17.0
3,7,4:106.4
3,0,4:106.1
-1,-6,4:106.1
-3,2,4:106.2
0,0,5:17.0
0,-1,5:17.0
3,7,5:106.4
3,0,5:106.1
-1,-6,5:106.1
-3,2,5:106.2
0,0,6:17.0
0,-1,6:17.0
3,7,6:106.4
3,0,6:106.1
-1,-6,6:106.1
-3,2,6:106.2
0,0,7:17.0
0,-1,7:17.0
3,7,7:106.4
3,0,7:106.1
-1,-6,7:106.1
-3,2,7:106.2
0,0,8:17.0
-1,-6,8:106.1
3,7,8:106.4
3,0,8:106.1
-3,2,8:106.2
0,0,9:17.0
-1,-6,9:106.1
3,7,9:106.4
3,0,9:106.1
-3,2,9:106.2
0,0,10:17.0
3,0,10:106.1
-1,-1,10:106.2
-1,-6,10:106.1
3,7,10:106.4
-3,2,10:106.2
0,0,11:17.0
3,0,11:106.1
-1,-1,11:106.2
-1,-6,11:106.1
3,7,11:106.4
-3,2,11:106.2
0,0,12:17.0
-1,1,12:17.0
3,0,12:106.1
-1,-1,12:106.2
3,7,12:106.4
-1,-6,12:106.1
-3,2,12:106.2
0,0,13:17.0
0,2,13:17.0
-1,-2,13:17.0
1,0,13:17.0
3,0,13:106.1
-1,-1,13:106.2
3,7,13:106.4
-1,-6,13:106.1
-3,2,13:106.2
0,0,14:17.0
2,0,14:17.0
-2,-1,14:17.0
0,-3,14:17.0
-1,2,14:17.0
1,3,14:17.0
3,-1,14:17.0
3,0,14:106.1
-1,-1,14:106.2
3,7,14:106.4
-1,-6,14:106.1
-3,2,14:106.2
0,0,15:17.0
-2,2,15:17.0
1,4,15:17.0
-3,-1,15:17.0
1,-4,15:17.0
-1,-4,15:17.0
3,1,15:17.0
-3,-2,15:18.0
-2,-2,15:18.0
-2,-3,15:18.0
-2,-4,15:18.0
-1,-5,15:18.0
0,-5,15:18.0
1,-5,15:18.0
2,-5,15:18.0
2,-4,15:18.0
2,-3,15:18.0
3,-3,15:18.0
3,-2,15:18.0
4,-1,15:18.0
4,-2,15:18.0
4,0,15:18.0
4,2,15:18.0
4,1,15:18.0
3,2,15:18.0
3,3,15:18.0
2,3,15:18.0
2,4,15:18.0
1,5,15:18.0
0,4,15:18.0
-1,4,15:18.0
-1,3,15:18.0
-2,3,15:18.0
-3,2,15:106.2
-3,1,15:18.0
-3,0,15:18.0
-4,-1,15:18.0
-4,1,15:18.0
-4,2,15:18.0
-4,0,15:18.0
-4,3,15:18.0
-3,3,15:18.0
-3,4,15:18.0
-2,4,15:18.0
-4,-2,15:18.0
-3,-3,15:18.0
-2,-1,15:18.0
0,-4,15:18.0
-1,-3,15:18.0
1,-3,15:18.0
0,3,15:18.0
1,3,15:18.0
0,5,15:18.0
2,5,15:18.0
3,4,15:18.0
3,0,15:106.1
3,7,15:106.4
-1,-6,15:106.1
0,2,15:17.0
0,-2,15:17.0
2,-2,15:17.0
0,0,16:17.0
-3,3,16:17.0
-3,-2,16:17.0
2,-4,16:17.0
-1,-5,16:17.0
3,0,16:18.0
1,5,16:17.0
-3,-4,16:18.0
-3,-3,16:18.0
-4,-3,16:18.0
-4,-2,16:17.0
-4,-1,16:18.0
-5,-2,16:18.0
-5,-1,16:17.0
-5,0,16:18.0
-6,0,16:18.0
-6,1,16:18.0
-6,2,16:18.0
-6,3,16:18.0
-5,3,16:18.0
-5,2,16:18.0
-5,1,16:18.0
-4,3,16:18.0
-4,4,16:18.0
-5,4,16:18.0
-4,5,16:18.0
-3,5,16:18.0
-3,4,16:17.0
-2,5,16:18.0
-1,6,16:18.0
0,6,16:18.0
0,5,16:18.0
-1,5,16:18.0
1,6,16:18.0
2,6,16:18.0
2,5,16:17.0
3,5,16:18.0
4,5,16:18.0
4,4,16:18.0
5,4,16:18.0
5,3,16:18.0
5,2,16:18.0
6,2,16:18.0
6,1,16:18.0
6,0,16:18.0
5,0,16:18.0
5,-1,16:17.0
5,-2,16:18.0
5,-3,16:18.0
4,-3,16:18.0
4,-4,16:18.0
4,-5,16:18.0
3,-5,16:18.0
2,-5,16:18.0
2,-6,16:18.0
1,-6,16:18.0
0,-6,16:17.0
-1,-6,16:106.1
-2,-6,16:18.0
-2,-5,16:18.0
-2,-4,16:18.0
-2,-3,16:18.0
-1,-4,16:18.0
-1,-3,16:18.0
-1,-2,16:18.0
0,-3,16:18.0
0,-4,16:18.0
0,-5,16:18.0
1,-5,16:18.0
1,-4,16:18.0
1,-3,16:18.0
1,-2,16:18.0
2,-2,16:18.0
2,-3,16:18.0
3,-3,16:18.0
3,-4,16:17.0
4,-2,16:18.0
3,-2,16:18.0
4,-1,16:18.0
3,-1,16:18.0
2,-1,16:18.0
1,-1,16:18.0
0,-2,16:18.0
0,-1,16:18.0
-1,-1,16:18.0
-2,-2,16:18.0
-2,-1,16:18.0
-2,0,16:18.0
-3,0,16:18.0
-3,-1,16:18.0
-4,0,16:18.0
-4,1,16:18.0
-4,2,16:17.0
-3,2,16:106.2
-3,1,16:18.0
-2,2,16:18.0
-2,1,16:18.0
-1,1,16:18.0
-1,0,16:18.0
-1,2,16:18.0
-2,3,16:18.0
-2,4,16:18.0
-1,4,16:18.0
-1,3,16:18.0
0,3,16:18.0
0,4,16:18.0
1,4,16:18.0
1,3,16:18.0
2,3,16:18.0
2,4,16:18.0
3,4,16:18.0
3,3,16:18.0
4,3,16:18.0
4,2,16:17.0
5,1,16:18.0
4,0,16:17.0
4,1,16:18.0
3,2,16:18.0
2,2,16:18.0
2,1,16:18.0
2,0,16:18.0
1,2,16:18.0
1,1,16:18.0
0,1,16:18.0
0,2,16:18.0
3,1,16:18.0
1,0,16:18.0
-6,-1,16:18.0
-6,-2,16:17.0
-5,-3,16:18.0
-5,-4,16:18.0
-4,-4,16:18.0
-4,-5,16:18.0
-3,-5,16:18.0
-3,-6,16:18.0
-2,-7,16:18.0
-1,-7,16:18.0
0,-7,16:18.0
1,-7,16:18.0
2,-7,16:18.0
3,-6,16:18.0
4,-6,16:18.0
5,-5,16:18.0
5,-4,16:18.0
6,-4,16:18.0
6,-3,16:18.0
6,-2,16:18.0
6,-1,16:18.0
7,-1,16:18.0
7,-2,16:18.0
7,0,16:18.0
7,1,16:18.0
6,3,16:18.0
6,4,16:18.0
5,5,16:18.0
3,6,16:18.0
7,2,16:18.0
-2,6,16:18.0
-3,6,16:18.0
0,7,16:18.0
1,7,16:18.0
2,7,16:18.0
-1,7,16:18.0
4,6,16:18.0
3,7,16:106.4
-7,2,16:18.0
-7,1,16:18.0
-7,-1,16:18.0
-6,-3,16:18.0
-7,-2,16:18.0
-7,0,16:18.0
-7,-3,16:18.0
-6,-4,16:18.0
-5,-5,16:18.0
-4,-6,16:18.0
-3,-7,16:18.0
-3,-2,17:18.0
-3,3,17:18.0
-1,-5,17:18.0
2,-4,17:18.0
3,0,17:18.0
1,5,17:18.0
0,5,17:18.0
0,4,17:18.0
-1,4,17:18.0
-1,3,17:18.0
-2,3,17:18.0
-3,2,17:18.0
-3,1,17:18.0
-3,0,17:18.0
-3,-1,17:18.0
-2,-2,17:18.0
-2,-3,17:18.0
-2,-4,17:18.0
-1,-4,17:18.0
0,-4,17:18.0
1,-4,17:18.0
1,-3,17:18.0
1,-2,17:18.0
2,-2,17:18.0
2,-1,17:18.0
2,0,17:18.0
2,-3,17:18.0
1,-1,17:18.0
1,0,17:18.0
1,1,17:18.0
2,1,17:18.0
2,2,17:18.0
2,3,17:18.0
2,4,17:18.0
1,4,17:18.0
0,3,17:18.0
0,2,17:18.0
1,2,17:18.0
1,3,17:18.0
0,1,17:18.0
0,0,17:18.0
0,-1,17:18.0
0,-2,17:18.0
0,-3,17:18.0
-1,-2,17:18.0
-1,-1,17:18.0
-1,0,17:18.0
-1,1,17:18.0
-1,2,17:18.0
-1,-3,17:18.0
-2,-1,17:18.0
-2,0,17:18.0
-2,1,17:18.0
-2,2,17:18.0
0,-5,17:18.0
1,-5,17:18.0
3,-1,17:18.0
3,1,17:18.0
3,2,17:18.0
3,-2,17:18.0
-2,4,17:18.0
-4,0,17:18.0
-4,1,17:18.0
4,0,17:18.0
4,-1,17:18.0
4,1,17:18.0
3,-3,17:18.0
4,-2,17:18.0
-4,-2,17:18.0
-4,-1,17:18.0
-3,-3,17:18.0
-3,-4,17:18.0
-1,-6,17:18.0
0,-6,17:18.0
1,-6,17:18.0
2,-6,17:18.0
2,-5,17:18.0
3,-4,17:18.0
4,-4,17:18.0
4,-3,17:18.0
5,-2,17:18.0
5,-1,17:18.0
5,0,17:18.0
5,1,17:18.0
4,2,17:18.0
4,3,17:18.0
3,3,17:18.0
2,5,17:18.0
3,5,17:18.0
3,4,17:18.0
-1,5,17:18.0
-2,5,17:18.0
-3,4,17:18.0
-2,-5,17:18.0
3,-5,17:18.0
4,4,17:18.0
0,6,17:18.0
1,6,17:18.0
3,6,17:106.4
0,0,18:18.0
-1,0,18:18.0
-2,0,18:18.0
-1,1,18:18.0
0,1,18:18.0
1,1,18:18.0
1,0,18:18.0
2,0,18:18.0
1,-1,18:18.0
0,-1,18:18.0
0,-2,18:18.0
-1,-1,18:18.0
0,2,18:18.0
1,2,18:18.0
-1,2,18:18.0
0,3,18:18.0
-2,1,18:18.0
2,1,18:18.0
2,-1,18:18.0
1,-2,18:18.0
0,-3,18:18.0
-1,-2,18:18.0
-2,-1,18:18.0
-1,3,18:18.0
1,-3,18:18.0
2,-2,18:18.0
3,-1,18:18.0
3,0,18:18.0
3,1,18:18.0
2,-3,18:18.0
0,-4,18:18.0
1,-4,18:18.0
-1,-3,18:18.0
2,2,18:18.0
1,3,18:18.0
-2,0,-1:17.0
-1,0,-1:17.0
0,0,-1:17.0
1,0,-1:17.0
2,0,-1:2
-3,0,-1:2
-2,-1,-1:2
-1,-1,-1:17.0
0,-2,-1:17.0
0,-3,-1:2
0,-1,-1:17.0
1,-1,-1:2
1,-2,-1:2
1,1,-1:17.0
2,1,-1:2
1,2,-1:2
0,2,-1:2
0,1,-1:17.0
-1,1,-1:2
-1,2,-1:2
-2,1,-1:2
2,-1,-1:2
2,2,-1:2
3,0,-1:2
0,3,-1:2
1,3,-1:2
3,1,-1:2
-1,-2,-1:2
-6,-2,-1:17.0
6,1,-1:17.0
4,5,-1:17.0
0,6,-1:17.0
3,-6,-1:17.0
0,5,-1:2
-1,4,-1:2
-1,3,-1:2
0,4,-1:2
1,4,-1:2
3,4,-1:2
2,3,-1:2
2,4,-1:2
5,1,-1:2
5,0,-1:2
4,0,-1:2
4,1,-1:2
2,-5,-1:2
2,-3,-1:2
1,-4,-1:2
-5,-2,-1:2
-4,-1,-1:2
-2,-2,-1:2
-4,0,-1:2
-3,-1,-1:2
1,-3,-1:2
2,-2,-1:2
2,-4,-1:2
-2,3,-1:2
-3,1,-1:2
3,-1,-1:2
3,-5,-1:2
-5,-1,-1:2
-4,-2,-1:2
-3,0,-2:17.0
-1,-2,-2:17.0
0,-3,-2:17.0
2,1,-2:17.0
2,2,-2:17.0
0,1,-2:17.0
-1,2,-2:17.0
-2,2,-2:17.0
-2,0,-2:17.0
0,-2,-2:17.0
0,2,-2:17.0
0,5,-2:3
-1,4,-2:3
0,3,-2:3
3,5,-2:3
4,4,-2:3
-1,3,-2:3
1,4,-2:3
2,4,-2:3
2,3,-2:3
1,1,-2:3
1,-1,-2:3
-1,-1,-2:3
0,0,-2:3
-1,1,-2:3
-3,1,-2:3
-3,-1,-2:3
-4,-1,-2:3
-5,-2,-2:3
1,-3,-2:3
2,-5,-2:3
3,-4,-2:3
2,-3,-2:3
1,-2,-2:3
2,-1,-2:3
3,0,-2:3
4,1,-2:3
5,1,-2:3
4,2,-2:3
3,3,-2:3
2,0,-2:3
1,2,-2:3
3,1,-2:3
-2,0,-3:3
-2,-1,-3:3
0,-2,-3:3
1,-3,-3:3
-1,-2,-3:3
0,1,-3:3
-1,3,-3:3
-2,1,-3:3
-1,2,-3:3
0,2,-3:3
2,1,-3:3
1,0,-3:3
0,-1,-3:3
-1,0,-3:3
1,-1,-3:3
1,2,-3:3
