[META]
version=2.0
spawnOnBlockType=2
spawnSunlight=True
spawnDarkness=True
spawnWater=False
spawnLava=False
underFill=False
randomRotation=True
dig=False
tree=false
branch=False
needsFoundation=True
rarity=500
collisionPercentage=80
spawnElevationMin=0
spawnElevationMax=245
spawnInBiome=Plains
[DATA]
0,0,0:17.0
-2,-1,0:31.1
0,1,0:17.0
0,-1,0:17.0
-1,0,0:17.0
1,0,0:17.0
1,2,0:31.1
-1,-1,0:17.0
0,-2,0:31.1
1,-1,0:31.1
2,0,0:31.1
1,1,0:31.2
-1,1,0:31.1
-2,0,0:31.2
-5,-4,0:18.1
-5,-5,0:18.1
-4,-5,0:18.1
-4,-4,0:18.1
2,-1,0:31.2
0,-3,0:31.2
-2,-2,0:31.2
-1,2,0:31.2
1,3,0:31.2
2,1,0:31.1
3,0,0:31.1
1,-2,0:31.1
-1,-2,0:31.1
-3,0,0:31.1
-2,1,0:31.1
0,2,0:31.1
2,2,0:31.1
-1,4,0:18.0
-1,5,0:18.0
0,5,0:18.0
0,6,0:18.0
1,6,0:18.0
1,5,0:18.0
4,6,0:18.0
4,5,0:18.0
5,5,0:18.0
5,4,0:18.0
6,4,0:18.0
6,3,0:18.0
5,-3,0:18.2
6,-3,0:18.2
6,-2,0:18.2
7,-2,0:18.2
7,-1,0:18.2
6,-1,0:18.2
1,-6,0:18.0
2,-6,0:18.0
3,-6,0:18.0
3,-5,0:18.0
2,-5,0:18.0
4,-6,0:18.0
-5,3,0:18.0
-5,2,0:18.0
-6,2,0:18.0
-6,1,0:18.0
-5,4,0:18.0
-4,4,0:18.0
-4,5,0:18.0
-6,4,0:18.0
-7,4,0:18.0
-4,2,0:18.0
-3,2,0:18.0
2,5,0:18.0
5,6,0:18.0
6,5,0:18.0
-1,-4,0:18.2
-2,-4,0:18.2
-1,-5,0:18.2
-2,-3,0:18.2
-1,-3,0:18.2
0,-4,0:18.2
6,0,0:18.2
0,7,0:106.4
5,-2,0:106.4
4,4,0:106.4
5,3,0:30
-4,3,0:31.2
3,3,0:31.2
4,-2,0:31.2
1,-5,0:31.2
-3,-4,0:31.2
0,4,0:31.2
0,3,0:31.1
3,4,0:31.1
2,3,0:31.1
4,-1,0:31.1
3,-1,0:31.1
3,-2,0:31.1
1,-4,0:31.1
-3,-3,0:31.1
-3,1,0:31.1
-4,1,0:31.1
0,0,12:17.0
-1,0,12:17.0
2,1,12:106.4
0,-1,12:106.1
0,7,12:106.4
-4,1,12:106.8
4,-2,12:106.2
-2,-3,12:106.1
1,-7,12:106.1
0,0,11:17.0
-1,0,11:17.0
-1,-1,11:106.8
0,-1,11:106.1
0,7,11:106.4
-4,1,11:106.8
4,-2,11:106.2
-2,-3,11:106.1
1,-7,11:106.1
0,0,10:17.0
-1,0,10:17.0
0,-1,10:17.0
-1,-1,10:106.8
0,7,10:106.4
-4,1,10:106.8
4,-2,10:106.2
-2,-3,10:106.1
1,-7,10:106.1
0,0,9:17.0
-1,0,9:17.0
0,-1,9:17.0
-1,-1,9:106.8
0,7,9:106.4
-4,1,9:106.8
4,-2,9:106.2
-2,-3,9:106.1
1,-7,9:106.1
0,0,8:17.0
-1,0,8:17.0
0,-1,8:17.0
-1,-1,8:106.8
0,7,8:106.4
-4,1,8:106.8
4,-2,8:106.2
-2,-3,8:106.1
1,-7,8:106.1
0,0,7:17.0
-1,0,7:17.0
0,-1,7:17.0
-1,-1,7:106.8
0,7,7:106.4
-4,1,7:106.8
4,-2,7:106.2
1,-7,7:106.1
-2,-3,7:106.1
0,0,6:17.0
-1,0,6:17.0
0,-1,6:17.0
-1,-1,6:106.8
0,7,6:106.4
-4,1,6:106.8
4,-2,6:106.2
-2,-3,6:106.1
1,-7,6:106.1
0,0,5:17.0
-1,0,5:17.0
0,-1,5:17.0
-1,-1,5:106.8
0,7,5:106.4
-4,1,5:106.8
4,-2,5:106.2
1,-7,5:106.1
-2,-3,5:106.1
0,0,4:17.0
-1,0,4:17.0
0,-1,4:17.0
0,7,4:106.4
-4,1,4:106.8
4,-2,4:106.2
-2,-3,4:106.1
1,-7,4:106.1
0,0,3:17.0
-1,0,3:17.0
0,-1,3:17.0
1,0,3:17.0
0,7,3:106.4
-4,1,3:106.8
4,-2,3:106.2
-2,-3,3:106.1
0,0,2:17.0
-1,0,2:17.0
0,-1,2:17.0
1,0,2:17.0
0,7,2:106.4
-4,1,2:106.8
4,-2,2:106.2
-2,-3,2:106.1
-5,3,2:18.0
0,0,1:17.0
-1,0,1:17.0
0,-1,1:17.0
1,0,1:17.0
-4,1,1:106.8
-2,-3,1:106.1
-4,-4,1:18.1
-4,-3,1:18.1
-3,-3,1:18.1
-5,3,1:18.0
-5,2,1:18.0
-6,2,1:18.0
-5,4,1:18.0
-6,4,1:18.0
-4,4,1:18.0
-4,2,1:18.0
0,5,1:18.0
0,4,1:18.0
-1,5,1:18.0
-1,6,1:18.0
1,5,1:18.0
1,4,1:18.0
4,5,1:18.0
4,4,1:18.0
5,4,1:18.0
5,5,1:18.0
6,4,1:18.0
-1,-4,1:18.2
-1,-3,1:18.2
0,-4,1:18.2
6,-2,1:18.2
6,-1,1:18.2
5,-1,1:18.2
5,-2,1:18.2
5,-3,1:18.2
6,0,1:18.2
0,7,1:106.4
-3,-4,1:30
4,-5,1:30
3,-5,1:18.0
4,-6,1:18.0
0,0,13:17.0
-1,0,13:17.0
2,1,13:106.4
0,-1,13:106.1
0,7,13:106.4
-4,1,13:106.8
4,-2,13:106.2
-2,-3,13:106.1
1,-7,13:106.1
0,0,18:17.0
0,1,18:17.0
1,-1,18:17.0
-1,0,18:17.0
-2,-3,18:106.1
2,1,18:106.4
0,7,18:106.4
1,-7,18:106.1
4,-2,18:106.2
-4,1,18:106.8
0,-1,18:106.1
0,-2,19:17.0
0,2,19:17.0
0,0,19:17.0
-2,1,19:17.0
-1,0,19:17.0
-2,-3,19:106.1
2,1,19:106.4
0,7,19:106.4
1,-7,19:106.1
4,-2,19:106.2
-4,1,19:106.8
0,-1,19:106.1
0,0,20:17.0
-2,1,20:17.0
1,-1,20:17.0
2,2,20:17.0
0,-3,20:17.0
0,3,20:17.0
-3,1,20:18.0
-2,0,20:18.0
-2,2,20:18.0
-1,3,20:18.0
0,4,20:18.0
1,3,20:18.0
2,3,20:18.0
3,2,20:18.0
2,1,20:106.4
2,-1,20:18.0
1,-2,20:18.0
2,0,20:17.0
0,-4,20:18.0
1,-3,20:18.0
-1,-3,20:18.0
-1,-2,20:18.0
2,-2,20:18.0
3,-1,20:18.0
3,0,20:18.0
3,1,20:18.0
-2,-1,20:18.0
-2,-2,20:18.0
-3,-1,20:18.0
-3,0,20:18.0
-3,2,20:18.0
-2,3,20:18.0
-4,2,20:18.0
1,2,20:18.0
-1,2,20:18.0
-2,-3,20:106.1
0,7,20:106.4
1,-7,20:106.1
4,-2,20:106.2
-4,1,20:106.8
0,-1,20:106.1
0,0,21:17.0
-3,1,21:17.0
-4,2,21:17.0
0,4,21:17.0
2,3,21:17.0
3,2,21:17.0
4,1,21:17.0
-1,-3,21:17.0
1,-3,21:17.0
-2,-2,21:17.0
-2,-4,21:17.0
0,5,21:18.0
-1,4,21:18.0
-1,3,21:18.0
-3,3,21:18.0
-2,3,21:18.0
-4,3,21:18.0
-5,2,21:18.0
-4,1,21:106.8
-4,0,21:18.0
-3,-4,21:18.0
-3,-2,21:18.0
-3,-1,21:18.0
-2,-5,21:18.0
-1,-4,21:18.0
3,-3,21:18.0
2,-3,21:18.0
4,-2,21:106.2
4,-1,21:18.0
4,0,21:18.0
3,0,21:17.0
5,1,21:18.0
4,2,21:18.0
3,3,21:18.0
2,4,21:18.0
1,4,21:18.0
1,-4,21:18.0
-2,-3,21:106.1
0,-3,21:18.0
3,-2,21:18.0
-3,0,21:18.0
-3,2,21:18.0
0,3,21:18.0
-1,-5,21:18.0
0,-4,21:18.0
1,-5,21:18.0
2,-5,21:18.0
2,-4,21:18.0
3,-4,21:18.0
4,-3,21:18.0
5,-2,21:18.0
5,-1,21:18.0
5,0,21:18.0
5,2,21:18.0
4,3,21:18.0
3,4,21:18.0
2,5,21:18.0
1,5,21:18.0
-1,5,21:18.0
-2,4,21:18.0
-3,4,21:18.0
-5,3,21:18.0
-5,1,21:18.0
-4,-1,21:18.0
-4,-2,21:18.0
-4,-3,21:18.0
-3,-3,21:18.0
0,7,21:106.4
1,-7,21:106.1
-5,0,21:18.0
-5,-1,21:17.0
-6,0,21:18.0
-5,-2,21:18.0
-6,-1,21:18.0
-6,1,21:18.0
0,0,22:17.0
-2,-1,22:17.0
-4,0,22:17.0
-3,-3,22:17.0
-3,-4,22:17.0
-3,3,22:17.0
-1,3,22:17.0
-1,4,22:17.0
3,3,22:17.0
3,0,22:17.0
4,0,22:17.0
2,-2,22:17.0
3,-2,22:17.0
3,-3,22:17.0
1,-4,22:17.0
0,1,22:18.0
0,2,22:18.0
0,3,22:18.0
0,4,22:18.0
1,0,22:18.0
2,0,22:18.0
5,0,22:18.0
-5,0,22:18.0
-3,0,22:18.0
-2,0,22:18.0
-1,0,22:18.0
0,-5,22:18.0
0,-4,22:18.0
0,-3,22:18.0
0,-2,22:18.0
0,-1,22:18.0
1,-5,22:18.0
-2,-5,22:18.0
-1,-4,22:18.0
-1,-3,22:18.0
-2,-3,22:18.0
-2,-4,22:18.0
-2,-2,22:18.0
-1,-2,22:18.0
-1,-1,22:18.0
-3,-5,22:18.0
-4,-4,22:18.0
-4,-3,22:18.0
-4,-2,22:18.0
-4,-1,22:18.0
-5,-1,22:18.0
-3,-1,22:18.0
-3,-2,22:18.0
-5,1,22:18.0
-4,3,22:18.0
-4,2,22:18.0
-4,1,22:18.0
-3,4,22:18.0
-2,4,22:18.0
-2,3,22:18.0
-2,2,22:18.0
-2,1,22:18.0
-3,1,22:18.0
-1,1,22:18.0
-1,2,22:18.0
-3,2,22:18.0
-1,5,22:18.0
1,3,22:18.0
1,2,22:18.0
1,1,22:18.0
1,-1,22:18.0
1,-2,22:18.0
1,-3,22:18.0
2,3,22:18.0
2,2,22:18.0
2,1,22:18.0
2,-1,22:18.0
3,4,22:18.0
4,2,22:18.0
4,1,22:18.0
3,1,22:18.0
3,2,22:18.0
5,2,22:18.0
5,1,22:18.0
2,-4,22:18.0
2,-3,22:18.0
3,-4,22:18.0
4,-3,22:18.0
4,-2,22:106.2
4,-1,22:18.0
3,-1,22:18.0
5,-1,22:18.0
4,3,22:18.0
0,5,22:18.0
1,4,22:18.0
2,4,22:18.0
1,5,22:18.0
-5,2,22:18.0
-4,4,22:18.0
-3,5,22:18.0
-2,5,22:18.0
-1,6,22:18.0
0,6,22:18.0
1,6,22:18.0
2,5,22:18.0
3,5,22:18.0
4,4,22:18.0
5,3,22:18.0
6,2,22:18.0
6,1,22:18.0
6,0,22:18.0
6,-1,22:18.0
5,-2,22:18.0
5,-3,22:18.0
4,-4,22:18.0
3,-5,22:18.0
2,-5,22:18.0
1,-6,22:18.0
0,-6,22:18.0
-1,-5,22:18.0
-2,-6,22:18.0
-3,-6,22:18.0
-4,-5,22:18.0
-5,-4,22:18.0
-5,-3,22:18.0
-5,-2,22:18.0
-6,-1,22:18.0
-6,0,22:18.0
-6,1,22:18.0
-6,2,22:18.0
-5,3,22:18.0
-6,-2,22:18.0
2,-6,22:18.0
4,-5,22:18.0
5,-4,22:18.0
6,-2,22:18.0
6,-3,22:18.0
3,-6,22:18.0
7,0,22:18.0
7,-1,22:18.0
7,1,22:18.0
5,4,22:18.0
4,5,22:18.0
3,6,22:18.0
2,6,22:18.0
-2,6,22:18.0
-4,5,22:18.0
-5,4,22:18.0
0,7,22:106.4
1,-7,22:106.1
-7,0,22:18.0
-7,-1,22:18.0
-7,-2,22:18.0
-6,-3,22:18.0
-6,3,22:18.0
-7,2,22:18.0
-6,-4,22:18.0
-5,-5,22:18.0
0,0,23:18.0
-1,0,23:18.0
-2,0,23:18.0
-3,0,23:18.0
-4,0,23:18.0
-5,0,23:18.0
1,0,23:18.0
2,0,23:18.0
3,0,23:18.0
4,0,23:18.0
5,0,23:18.0
0,1,23:18.0
0,2,23:18.0
0,3,23:18.0
0,4,23:18.0
0,5,23:18.0
0,-1,23:18.0
0,-2,23:18.0
0,-3,23:18.0
0,-4,23:18.0
0,-5,23:18.0
1,-5,23:18.0
-1,-5,23:18.0
-2,-5,23:18.0
-5,-1,23:18.0
-5,2,23:18.0
-5,1,23:18.0
-1,5,23:18.0
1,5,23:18.0
5,-1,23:18.0
5,1,23:18.0
5,2,23:18.0
4,3,23:18.0
3,4,23:18.0
2,4,23:18.0
-2,4,23:18.0
-3,3,23:18.0
-4,3,23:18.0
-4,-2,23:18.0
-4,-3,23:18.0
-3,-4,23:18.0
2,-4,23:18.0
3,-4,23:18.0
4,-3,23:18.0
4,-2,23:18.0
-3,-2,23:18.0
-3,-3,23:18.0
-2,-3,23:18.0
-2,-4,23:18.0
-1,-4,23:18.0
-1,-3,23:18.0
-1,-2,23:18.0
-1,-1,23:18.0
-2,-1,23:18.0
-3,-1,23:18.0
-4,-1,23:18.0
-2,-2,23:18.0
-4,1,23:18.0
-3,1,23:18.0
-2,1,23:18.0
-1,1,23:18.0
-1,2,23:18.0
-2,2,23:18.0
-3,2,23:18.0
-4,2,23:18.0
-2,3,23:18.0
-1,3,23:18.0
-1,4,23:18.0
1,4,23:18.0
2,3,23:18.0
1,3,23:18.0
1,2,23:18.0
1,1,23:18.0
2,1,23:18.0
3,1,23:18.0
4,1,23:18.0
4,2,23:18.0
3,2,23:18.0
3,3,23:18.0
2,2,23:18.0
3,-1,23:18.0
4,-1,23:18.0
2,-1,23:18.0
1,-1,23:18.0
1,-2,23:18.0
2,-3,23:18.0
2,-2,23:18.0
3,-2,23:18.0
3,-3,23:18.0
1,-3,23:18.0
1,-4,23:18.0
0,6,23:106.4
1,-6,23:106.1
-3,0,24:18.0
-2,0,24:18.0
-1,0,24:18.0
0,0,24:18.0
1,0,24:18.0
2,0,24:18.0
0,-3,24:18.0
0,-2,24:18.0
0,-1,24:18.0
0,1,24:18.0
0,2,24:18.0
0,3,24:18.0
1,2,24:18.0
1,1,24:18.0
1,-2,24:18.0
1,-1,24:18.0
2,-1,24:18.0
2,1,24:18.0
-3,1,24:18.0
-2,-1,24:18.0
-2,1,24:18.0
-2,2,24:18.0
-1,3,24:18.0
-1,2,24:18.0
-1,1,24:18.0
-1,-1,24:18.0
-1,-2,24:18.0
-1,0,14:17.0
0,0,14:17.0
2,1,14:106.4
0,-1,14:106.1
0,7,14:106.4
-4,1,14:106.8
4,-2,14:106.2
-2,-3,14:106.1
1,-7,14:106.1
0,0,15:17.0
-1,0,15:17.0
2,1,15:106.4
0,-1,15:106.1
0,7,15:106.4
-4,1,15:106.8
4,-2,15:106.2
-2,-3,15:106.1
1,-7,15:106.1
0,0,16:17.0
-1,0,16:17.0
-2,-3,16:106.1
2,1,16:106.4
1,-7,16:106.1
0,-1,16:106.1
0,7,16:106.4
-4,1,16:106.8
4,-2,16:106.2
0,0,17:17.0
-1,0,17:17.0
-2,-3,17:106.1
2,1,17:106.4
1,-7,17:106.1
0,-1,17:106.1
0,7,17:106.4
-4,1,17:106.8
4,-2,17:106.2
-1,-1,-1:17.0
-1,0,-1:17.0
0,0,-1:17.0
0,-1,-1:17.0
0,1,-1:17.0
1,0,-1:17.0
0,-2,-1:2
1,-1,-1:2
2,0,-1:2
1,1,-1:2
1,2,-1:2
-1,1,-1:2
-2,0,-1:2
-2,-1,-1:2
0,5,-1:17.0
-5,3,-1:17.0
-4,-4,-1:17.0
1,-6,-1:17.0
6,-2,-1:17.0
5,5,-1:17.0
-1,-4,-1:17.0
-1,-2,-1:2
0,-3,-1:2
1,-2,-1:2
2,-1,-1:2
3,0,-1:2
2,1,-1:2
2,2,-1:2
1,3,-1:2
0,2,-1:2
-1,2,-1:2
-2,1,-1:2
-3,0,-1:2
-2,-2,-1:2
-1,-3,-1:2
-5,2,-1:2
-4,3,-1:2
-4,2,-1:2
-3,1,-1:2
-4,1,-1:2
-3,2,-1:2
0,4,-1:2
-1,4,-1:2
0,3,-1:2
4,4,-1:2
3,4,-1:2
3,3,-1:2
2,3,-1:2
4,5,-1:2
5,-2,-1:2
3,-2,-1:2
4,-2,-1:2
3,-1,-1:2
1,-4,-1:2
1,-5,-1:2
0,-4,-1:2
-3,-3,-1:2
-2,-3,-1:2
-3,-4,-1:2
4,-1,-1:2
0,5,-2:3
0,4,-2:3
-5,3,-2:3
-4,-4,-2:3
-3,-3,-2:3
1,-6,-2:3
1,-5,-2:3
-1,-4,-2:3
6,-2,-2:3
5,-2,-2:3
4,4,-2:3
-4,2,-2:3
0,0,-2:3
2,0,-2:3
3,-1,-2:3
1,1,-2:3
2,2,-2:3
0,2,-2:3
1,-1,-2:3
-1,-1,-2:3
-1,1,-2:3
-3,1,-2:3
-2,0,-2:3
-2,-2,-2:3
0,-2,-2:3
3,3,-2:3
