[META]
version=2.0
spawnOnBlockType=8,9
spawnSunlight=True
spawnDarkness=True
spawnWater=False
spawnLava=False
underFill=False
randomRotation=True
dig=True
tree=False
branch=False
needsFoundation=True
rarity=100
collisionPercentage=10
spawnElevationMin=0
spawnElevationMax=100
spawnInBiome=Forest3
[DATA]
-1,0,0:17.0
0,0,0:18
-1,1,0:17.0
-1,-2,-6:17.0
-2,-1,-6:17.0
-1,-1,-6:17.0
0,-1,-6:17.0
-2,1,-6:17.0
-1,1,-6:17.0
0,1,-6:17.0
-1,2,-6:17.0
-1,-2,-5:17.0
-2,-1,-5:17.0
-1,-1,-5:17.0
0,-1,-5:17.0
-2,1,-5:17.0
-1,1,-5:17.0
0,1,-5:17.0
-1,2,-5:17.0
-1,-2,-4:17.0
-2,-1,-4:17.0
-1,-1,-4:17.0
0,-1,-4:17.0
-2,0,-4:17.0
-1,0,-4:17.0
-2,1,-4:17.0
-1,1,-4:17.0
0,1,-4:17.0
-1,2,-4:17.0
-2,-1,-3:17.0
-1,-1,-3:17.0
-2,0,-3:17.0
-1,0,-3:17.0
0,0,-3:17.0
-1,1,-3:17.0
0,1,-3:17.0
-1,2,-3:17.0
-1,-1,-2:17.0
-2,0,-2:17.0
-1,0,-2:17.0
0,0,-2:17.0
-1,1,-2:17.0
0,1,-2:17.0
-1,0,-1:17.0
0,0,-1:17.0
-1,1,-1:17.0
-1,0,1:17.0
-1,1,1:18
-1,2,1:106.4
0,1,1:106.2
-2,1,1:106.8
0,0,1:106.2
-2,0,1:106.8
-1,-1,1:106.1
-1,0,2:17.0
-1,1,2:106.4
0,0,2:106.2
-2,0,2:106.8
-1,-1,2:106.1
-1,0,3:18
