[META]
version=2.0
spawnOnBlockType=2
spawnSunlight=True
spawnDarkness=True
spawnWater=False
spawnLava=False
underFill=False
randomRotation=True
dig=True
tree=True
branch=False
needsFoundation=True
rarity=200
collisionPercentage=50
spawnElevationMin=0
spawnElevationMax=200
spawnInBiome=Forest2
[DATA]
-2,-2,-3:3.0
-1,-2,-3:17.3
-2,-1,-3:3.0
-1,-1,-3:17.3
0,-1,-3:3.0
-2,0,-3:3.0
-1,0,-3:3.0
0,0,-3:3.0
1,0,-3:3.5
2,0,-3:3.5
-1,1,-3:17.3
-1,-3,-2:17.3
-3,-2,-2:3.5
-2,-2,-2:3.0
-1,-2,-2:3.0
0,-2,-2:3.0
1,-2,-2:3.5
-4,-1,-2:3.5
-3,-1,-2:3.0
-2,-1,-2:17.3
-1,-1,-2:3.0
0,-1,-2:17.3
1,-1,-2:3.0
2,-1,-2:3.5
-3,0,-2:3.0
-2,0,-2:3.0
-1,0,-2:3.0
0,0,-2:3.0
1,0,-2:3.0
2,0,-2:3.5
3,0,-2:3.5
-3,1,-2:3.5
-2,1,-2:3.0
-1,1,-2:3.0
0,1,-2:17.3
1,1,-2:3.0
2,1,-2:3.5
-3,2,-2:3.5
-2,2,-2:3.5
-1,2,-2:3.0
0,2,-2:3.0
1,2,-2:3.5
-2,3,-2:3.5
-1,3,-2:3.5
0,3,-2:3.5
-2,-4,-1:2.5
-1,-4,-1:2.5
0,-4,-1:2.5
-3,-3,-1:2.5
-2,-3,-1:2.0
-1,-3,-1:17.3
0,-3,-1:2.0
1,-3,-1:2.5
-4,-2,-1:2.5
-3,-2,-1:2.0
-2,-2,-1:2.0
-1,-2,-1:17.3
0,-2,-1:17.3
1,-2,-1:17.3
2,-2,-1:2.5
-4,-1,-1:2.5
-3,-1,-1:2.0
-2,-1,-1:17.3
-1,-1,-1:17.3
1,-1,-1:17.3
2,-1,-1:2.0
-4,0,-1:2.5
-3,0,-1:17.3
-2,0,-1:17.3
-1,0,-1:17.3
0,0,-1:17.3
1,0,-1:3.0
2,0,-1:2.0
3,0,-1:2.5
-3,1,-1:2.0
-2,1,-1:3.0
-1,1,-1:17.3
0,1,-1:17.3
1,1,-1:2.0
2,1,-1:2.0
3,1,-1:17.3
-3,2,-1:2.5
-2,2,-1:17.3
-1,2,-1:2.0
0,2,-1:3.0
1,2,-1:2.0
2,2,-1:2.5
-2,3,-1:2.5
-1,3,-1:2.5
0,3,-1:2.5
1,3,-1:2.5
-2,4,-1:2.5
-1,4,-1:2.5
0,4,-1:2.5
-3,-3,0:18.4
-2,-3,0:18.3
-1,-3,0:17.3
-2,-2,0:18.3
-1,-2,0:17.3
0,-2,0:17.3
-2,-1,0:17.3
-1,-1,0:17.3
1,-1,0:17.3
-2,0,0:17.3
-1,0,0:17.3
0,0,0:17.3
1,0,0:17.3
-3,1,0:18.3
-2,1,0:17.3
-1,1,0:17.3
0,1,0:17.3
3,1,0:18.3
0,2,0:17.3
-2,3,0:18.5
-2,4,0:18.3
-1,4,0:18.3
-2,-3,1:18.3
-1,-3,1:17.3
-2,-2,1:18.3
-1,-2,1:17.3
0,-2,1:17.3
-2,-1,1:17.3
-1,-1,1:17.3
1,-1,1:17.3
-2,0,1:17.3
-1,0,1:17.3
0,0,1:17.3
1,0,1:17.3
-3,1,1:18.3
-2,1,1:17.3
-1,1,1:17.3
0,1,1:17.3
3,1,1:18.3
-2,4,1:18.3
-3,-2,2:18.3
-2,-2,2:18.3
-1,-2,2:17.3
0,-2,2:17.3
-2,-1,2:17.3
-1,-1,2:17.3
1,-1,2:17.3
-2,0,2:17.3
-1,0,2:17.3
0,0,2:17.3
3,0,2:18.6
-3,1,2:18.3
-2,1,2:18.3
-1,1,2:17.3
0,1,2:17.3
3,1,2:18.3
-1,-3,3:18.3
-1,-2,3:17.3
0,-2,3:17.3
-3,-1,3:18.3
-2,-1,3:17.3
-1,-1,3:17.3
1,-1,3:17.3
-2,0,3:17.3
-1,0,3:17.3
0,0,3:17.3
-2,1,3:18.4
-1,1,3:17.3
0,1,3:17.3
0,-3,4:18.3
-1,-2,4:17.3
0,-2,4:17.3
-1,-1,4:17.3
1,-1,4:17.3
-3,0,4:18.3
-2,0,4:17.3
-1,0,4:17.3
0,0,4:17.3
-1,1,4:17.3
-1,-2,5:17.3
0,-2,5:17.3
1,-2,5:18.3
-1,-1,5:17.3
1,-1,5:17.3
-2,0,5:17.3
-1,0,5:17.3
0,0,5:17.3
-2,1,5:18.3
-1,1,5:17.3
-1,-2,6:17.3
0,-2,6:17.3
-1,-1,6:17.3
1,-1,6:17.3
-1,0,6:17.3
0,0,6:17.3
-1,-2,7:17.3
0,-2,7:17.3
-1,-1,7:17.3
1,-1,7:17.3
-1,0,7:17.3
0,0,7:17.3
-1,-2,8:17.3
0,-2,8:17.3
-1,-1,8:17.3
0,-1,8:17.3
0,0,8:17.3
-1,-2,9:17.3
-1,-1,9:17.3
0,-1,9:17.3
0,0,9:17.3
-1,-2,10:17.3
-1,-1,10:17.3
0,-1,10:17.3
0,0,10:17.3
-1,-2,11:17.3
-1,-1,11:17.3
0,0,11:17.3
-5,-5,12:18.3
-1,-1,12:17.3
0,0,12:17.3
-5,-5,13:18.3
-1,-1,13:17.3
0,0,13:17.3
-5,-5,14:18.3
4,-4,14:18.3
-1,-1,14:17.3
0,0,14:17.3
-4,4,14:18.3
5,4,14:18.3
-5,-5,15:18.3
4,-4,15:18.3
-1,-1,15:17.3
-1,0,15:17.3
0,0,15:17.3
-1,1,15:17.3
-4,4,15:18.3
5,4,15:18.3
-5,-5,16:18.3
4,-4,16:18.3
-1,-2,16:17.3
-1,-1,16:17.3
-1,0,16:17.3
0,0,16:17.3
-1,1,16:18.3
1,1,16:17.3
-2,2,16:17.3
-4,4,16:18.3
5,4,16:18.3
-5,-5,17:18.3
1,-5,17:18.3
2,-5,17:18.3
3,-5,17:18.3
4,-5,17:18.3
5,-5,17:18.3
-6,-4,17:18.3
-5,-4,17:18.3
-4,-4,17:17.3
-3,-4,17:18.3
-2,-4,17:18.3
0,-4,17:18.3
1,-4,17:17.3
2,-4,17:18.3
3,-4,17:18.3
4,-4,17:18.3
-4,-3,17:18.3
-3,-3,17:17.3
-2,-3,17:17.3
0,-3,17:18.3
1,-3,17:17.3
2,-3,17:18.3
-4,-2,17:18.3
-1,-2,17:18.3
1,-2,17:17.3
2,-2,17:17.3
-1,-1,17:18.3
0,-1,17:18.3
-1,0,17:18.3
1,1,17:18.3
2,1,17:18.3
4,1,17:18.3
5,1,17:18.3
-2,2,17:18.3
-1,2,17:18.3
1,2,17:18.3
2,2,17:17.3
3,2,17:17.3
4,2,17:18.3
5,2,17:18.3
6,2,17:18.3
-4,3,17:18.3
-3,3,17:17.3
-2,3,17:18.3
-1,3,17:18.3
0,3,17:17.3
2,3,17:18.3
3,3,17:18.3
4,3,17:18.3
5,3,17:18.3
-4,4,17:17.3
-3,4,17:17.3
-2,4,17:18.3
-1,4,17:18.3
3,4,17:18.3
4,4,17:17.3
5,4,17:18.3
-3,5,17:18.3
-2,5,17:18.3
-1,5,17:18.3
2,-8,18:18.3
3,-8,18:18.3
1,-7,18:18.3
2,-7,18:18.3
3,-7,18:18.3
4,-7,18:18.3
-5,-6,18:18.3
-4,-6,18:18.3
0,-6,18:18.3
1,-6,18:18.3
2,-6,18:18.3
3,-6,18:17.3
4,-6,18:18.3
5,-6,18:18.3
-6,-5,18:18.3
-5,-5,18:18.3
-4,-5,18:18.3
-3,-5,18:18.3
0,-5,18:18.3
1,-5,18:17.3
2,-5,18:18.3
3,-5,18:18.3
4,-5,18:18.3
5,-5,18:18.3
-7,-4,18:18.3
-6,-4,18:18.3
-5,-4,18:18.3
-4,-4,18:17.3
-3,-4,18:18.3
1,-4,18:18.3
2,-4,18:18.3
3,-4,18:18.3
4,-4,18:18.3
5,-4,18:18.3
6,-4,18:18.4
-8,-3,18:18.3
-7,-3,18:18.3
-6,-3,18:17.3
-5,-3,18:18.3
-4,-3,18:18.3
-3,-3,18:18.3
-2,-3,18:18.3
1,-3,18:18.3
2,-3,18:18.3
3,-3,18:18.3
4,-3,18:18.3
5,-3,18:18.3
-7,-2,18:18.3
-6,-2,18:18.3
-5,-2,18:18.3
-4,-2,18:18.3
-3,-2,18:18.3
1,-2,18:18.3
3,-2,18:17.3
4,-2,18:18.3
-6,-1,18:18.3
-3,-1,18:18.3
-2,-1,18:18.3
1,-1,18:18.3
3,-1,18:18.3
4,-1,18:18.3
3,0,18:18.3
4,0,18:18.3
5,0,18:18.3
-4,1,18:18.3
-3,1,18:18.3
-2,1,18:18.3
2,1,18:18.3
3,1,18:18.3
4,1,18:18.3
5,1,18:18.3
-4,2,18:18.3
-3,2,18:18.3
-2,2,18:18.3
2,2,18:18.3
3,2,18:18.3
4,2,18:17.3
5,2,18:18.3
6,2,18:18.3
-5,3,18:18.3
-4,3,18:18.3
-3,3,18:18.3
-2,3,18:18.3
-1,3,18:18.3
1,3,18:18.3
2,3,18:18.3
3,3,18:18.3
4,3,18:18.3
5,3,18:18.3
6,3,18:18.3
-6,4,18:18.3
-5,4,18:18.3
-4,4,18:17.3
-3,4,18:18.3
-2,4,18:18.3
-1,4,18:18.3
0,4,18:18.3
2,4,18:18.3
3,4,18:18.3
4,4,18:18.3
5,4,18:18.3
-6,5,18:18.3
-5,5,18:18.3
-4,5,18:18.3
-3,5,18:18.3
-2,5,18:18.3
-1,5,18:18.3
0,5,18:18.3
3,5,18:18.3
-6,6,18:18.3
-5,6,18:18.3
-4,6,18:18.3
-3,6,18:17.3
-2,6,18:18.3
-1,6,18:18.3
-5,7,18:18.3
-3,7,18:18.3
-2,7,18:18.3
2,-7,19:18.4
3,-7,19:18.3
1,-6,19:18.3
2,-6,19:18.3
3,-6,19:18.3
4,-6,19:18.3
-5,-5,19:18.3
-4,-5,19:18.3
1,-5,19:18.3
2,-5,19:18.3
3,-5,19:18.3
4,-5,19:18.3
5,-5,19:18.3
6,-5,19:18.3
-7,-4,19:18.3
-6,-4,19:17.3
-5,-4,19:18.3
-4,-4,19:18.3
-3,-4,19:18.3
1,-4,19:18.3
2,-4,19:18.3
3,-4,19:18.3
4,-4,19:18.3
5,-4,19:18.3
-7,-3,19:18.3
-6,-3,19:18.3
-5,-3,19:18.3
-4,-3,19:18.3
-3,-3,19:18.3
-2,-3,19:18.3
2,-3,19:18.3
3,-3,19:18.3
4,-3,19:18.3
-5,-2,19:18.3
-4,-2,19:18.3
-3,-2,19:18.3
-2,-2,19:18.3
1,-2,19:18.3
3,-2,19:18.3
-6,-1,19:18.3
-3,-1,19:18.3
-2,-1,19:18.3
-3,0,19:18.3
-2,0,19:18.3
4,0,19:18.3
-3,1,19:17.3
2,1,19:18.3
3,1,19:18.3
4,1,19:18.3
5,1,19:18.3
6,1,19:18.4
-3,2,19:18.3
1,2,19:18.3
2,2,19:18.3
3,2,19:18.3
4,2,19:18.3
5,2,19:18.3
6,2,19:17.3
7,2,19:18.3
-4,3,19:18.3
-3,3,19:18.3
-2,3,19:18.3
-1,3,19:18.3
3,3,19:17.3
4,3,19:18.3
5,3,19:18.3
-5,4,19:18.3
-4,4,19:18.3
-3,4,19:18.3
-2,4,19:18.3
3,4,19:18.3
4,4,19:18.3
-6,5,19:18.3
-5,5,19:18.3
-4,5,19:18.3
-3,5,19:18.3
-2,5,19:18.3
-1,5,19:18.3
-5,6,19:18.3
-4,6,19:18.3
-3,6,19:18.3
-2,6,19:18.3
-3,7,19:18.3
2,-5,20:18.3
3,-5,20:18.3
-6,-4,20:18.3
-5,-4,20:18.3
-4,-4,20:18.3
3,-4,20:18.3
4,-4,20:18.3
-6,-3,20:18.3
-5,-3,20:18.3
-4,-3,20:18.3
-2,-3,20:18.3
3,-3,20:18.3
4,-3,20:18.3
-5,-2,20:18.3
-4,-2,20:18.3
-3,-2,20:18.3
-6,-1,20:18.3
-3,-1,20:18.3
2,1,20:18.3
3,1,20:18.3
4,1,20:18.3
-3,2,20:18.3
-2,2,20:18.3
3,2,20:18.3
4,2,20:18.3
5,2,20:18.3
6,2,20:18.3
-3,3,20:18.3
-2,3,20:18.3
-1,3,20:18.3
3,3,20:18.3
4,3,20:18.3
5,3,20:18.3
-5,4,20:18.3
-4,4,20:18.3
-3,4,20:18.3
-2,4,20:18.3
-5,5,20:18.3
-4,5,20:18.3
-3,5,20:18.3
-2,5,20:18.3
-1,5,20:18.3
-5,-3,21:18.3
-4,-3,21:18.4
3,-3,21:18.4
-3,-1,21:18.3
4,2,21:18.3
3,3,21:18.3
-3,4,21:18.3
-3,-5,17:106.1
-4,-5,17:106.3
-5,-6,17:106.1
6,4,16:106.2
-3,4,16:106.2
-5,4,16:106.8
5,3,16:106.1
-2,3,16:106.4
4,1,16:106.0
4,-3,16:106.4
3,-4,16:106.8
2,-4,16:106.0
2,-5,16:106.0
-3,-5,16:106.1
-4,-5,16:106.3
-5,-6,16:106.1
5,5,15:106.4
6,4,15:106.2
-3,4,15:106.2
-5,4,15:106.8
5,3,15:106.1
-2,3,15:106.4
4,-3,15:106.4
3,-4,15:106.8
-3,-5,15:106.1
-4,-5,15:106.3
-5,-6,15:106.1
5,5,14:106.4
6,4,14:106.2
-3,4,14:106.2
-5,4,14:106.8
5,3,14:106.1
-2,3,14:106.4
4,-3,14:106.4
3,-4,14:106.8
-3,-5,14:106.1
-4,-5,14:106.3
-5,-6,14:106.1
5,5,13:106.4
6,4,13:106.2
-3,4,13:106.2
-5,4,13:106.8
5,3,13:106.1
-2,3,13:106.4
4,-3,13:106.4
3,-4,13:106.8
-3,-5,13:106.1
-4,-5,13:106.3
-6,-5,13:106.8
-5,-6,13:106.1
5,5,12:106.4
6,4,12:106.2
-3,4,12:106.2
-5,4,12:106.8
5,3,12:106.1
4,-3,12:106.4
3,-4,12:106.8
-3,-5,12:106.1
-4,-5,12:106.3
-6,-5,12:106.8
-5,-6,12:106.1
5,5,11:106.4
6,4,11:106.2
-3,4,11:106.2
-5,4,11:106.8
5,3,11:106.1
-2,-2,11:106.8
4,-3,11:106.4
3,-4,11:106.8
-3,-5,11:106.1
-4,-5,11:106.3
-6,-5,11:106.8
-5,-6,11:106.1
5,5,10:106.4
6,4,10:106.2
-3,4,10:106.2
-5,4,10:106.8
5,3,10:106.1
-2,-2,10:106.8
4,-3,10:106.4
3,-4,10:106.8
-3,-5,10:106.1
-4,-5,10:106.3
-6,-5,10:106.8
-5,-6,10:106.1
5,5,9:106.4
6,4,9:106.2
-5,4,9:106.8
5,3,9:106.1
-2,-2,9:106.8
4,-3,9:106.4
3,-4,9:106.8
-3,-5,9:106.1
-4,-5,9:106.3
-6,-5,9:106.8
-5,-6,9:106.1
5,5,8:106.4
5,3,8:106.1
-2,-2,8:106.8
4,-3,8:106.4
3,-4,8:106.8
-4,-5,8:106.2
5,5,7:106.4
5,3,7:106.1
2,-1,7:106.2
-2,-2,7:106.8
4,-3,7:106.4
3,-4,7:106.8
-4,-5,7:106.2
2,-1,6:106.2
-2,-2,6:106.8
4,-3,6:106.4
3,-4,6:106.8
-1,2,5:106.4
2,-1,5:106.2
-2,-2,5:106.8
3,-4,5:106.8
-1,2,4:106.4
2,-1,4:106.2
1,-2,4:106.2
-2,-2,4:106.8
-1,-3,4:106.1
3,-4,4:106.8
-1,2,3:106.4
1,1,3:106.2
1,0,3:106.4
2,-1,3:106.2
1,-2,3:106.2
-2,-2,3:106.8
3,2,2:106.4
-1,2,2:106.4
4,1,2:106.2
2,1,2:106.8
1,1,2:106.2
4,0,2:106.2
2,0,2:106.8
1,0,2:106.4
3,-1,2:106.1
2,-1,2:106.2
-3,-1,2:106.8
1,-2,2:106.2
0,-3,2:106.1
-3,-3,2:106.1
-1,4,1:106.2
-1,2,1:106.4
1,1,1:106.2
4,0,1:106.2
2,0,1:106.8
3,-1,1:106.1
-3,-1,1:106.8
1,-2,1:106.2
0,-3,1:106.1
1,3,0:38.5
-1,3,0:106.2
-3,3,0:106.8
2,2,0:6.8
-1,2,0:106.4
-3,2,0:31.1
1,1,0:106.2
2,0,0:31.0
-4,0,0:31.1
3,-1,0:106.1
-3,-1,0:106.8
-4,-1,0:31.2
2,-2,0:31.2
1,-2,0:106.2
-3,-2,0:31.1
-4,-2,0:31.1
1,-3,0:38.5
0,-3,0:106.3
0,-4,0:31.2
-1,-4,0:31.1
-2,-4,0:31.1
