[META]
version=2.0
spawnOnBlockType=2,12
spawnSunlight=True
spawnDarkness=True
spawnWater=False
spawnLava=False
underFill=False
randomRotation=True
dig=False
tree=True
branch=False
needsFoundation=True
rarity=20
collisionPercentage=2
spawnElevationMin=0
spawnElevationMax=245
spawnInBiome=Plains
[DATA]
0,0,0:17.0
2,-1,0:31.1
0,-1,0:31.1
-1,0,0:31.1
-2,2,0:31.1
0,2,0:31.1
2,1,0:31.1
1,0,0:31.1
0,0,1:17.0
0,0,2:17.0
0,0,3:17.0
0,0,4:17.0
0,0,5:17.0
0,0,6:17.0
-1,1,6:17.0
0,-1,6:17.0
0,0,7:17.0
-2,1,7:17.0
1,1,7:17.0
0,-2,7:17.0
0,0,8:17.0
1,1,8:17.0
2,2,8:17.0
-2,2,8:17.0
0,-3,8:17.0
-2,-4,8:17.0
0,0,9:17.0
-3,2,9:17.0
4,2,9:17.0
3,3,9:17.0
4,-1,9:17.0
0,-4,9:17.0
-1,-3,9:17.0
1,-3,9:17.0
-2,-3,9:17.0
-3,-3,9:17.0
-2,-5,9:17.0
-3,-6,9:17.0
-3,-4,9:18.0
-3,-5,9:18.0
-4,-6,9:18.0
-4,-5,9:18.0
-5,-5,9:18.0
-5,-4,9:18.0
-6,-5,9:18.0
-6,-4,9:18.0
-6,-3,9:18.0
-6,-2,9:18.0
-7,-2,9:18.0
-7,-1,9:18.0
-7,0,9:18.0
-7,1,9:18.0
-7,2,9:18.0
-6,1,9:18.0
-6,3,9:18.0
-5,4,9:18.0
-5,5,9:18.0
-4,5,9:18.0
-4,6,9:18.0
-5,3,9:18.0
-6,2,9:18.0
-3,6,9:18.0
-2,6,9:18.0
-1,6,9:18.0
4,4,9:18.0
5,4,9:18.0
4,5,9:18.0
3,5,9:18.0
2,5,9:18.0
1,5,9:18.0
1,6,9:18.0
0,6,9:18.0
6,4,9:18.0
6,3,9:18.0
7,3,9:18.0
7,2,9:18.0
7,1,9:18.0
7,0,9:18.0
7,-1,9:18.0
-3,-7,9:18.0
-2,-7,9:18.0
-2,-6,9:18.0
-1,-6,9:18.0
-1,-7,9:18.0
0,-7,9:18.0
1,-7,9:18.0
2,-7,9:18.0
2,-8,9:18.0
3,-8,9:18.0
4,-7,9:18.0
4,-6,9:18.0
5,-5,9:18.0
6,-4,9:18.0
6,-3,9:18.0
7,-2,9:18.0
3,-7,9:18.0
4,-5,9:18.0
5,-4,9:18.0
6,-2,9:18.0
-4,-7,9:18.0
1,-8,9:18.0
-3,-8,9:18.0
0,0,10:17.0
-1,-1,10:17.0
-1,1,10:17.0
1,1,10:17.0
1,-1,10:17.0
2,2,10:17.0
3,4,10:17.0
3,5,10:17.0
2,5,10:17.0
5,2,10:17.0
5,-1,10:17.0
3,-1,10:17.0
2,-2,10:17.0
2,-4,10:17.0
1,-3,10:17.0
0,-5,10:17.0
2,-6,10:17.0
-2,-2,10:17.0
-3,-1,10:17.0
-4,-2,10:17.0
-5,-1,10:17.0
-6,-1,10:17.0
-2,2,10:17.0
-3,3,10:17.0
-4,7,10:18.0
2,6,10:18.0
2,7,10:18.0
2,8,10:18.0
-4,2,10:17.0
-5,2,10:17.0
-4,5,10:18.0
-4,6,10:18.0
3,6,10:18.0
3,7,10:18.0
4,5,10:18.0
5,5,10:18.0
6,5,10:18.0
4,6,10:18.0
4,7,10:18.0
5,6,10:18.0
4,4,10:18.0
5,4,10:18.0
6,4,10:18.0
7,4,10:18.0
-3,8,10:18.0
-2,8,10:18.0
-1,8,10:18.0
0,8,10:18.0
1,8,10:18.0
1,6,10:18.0
0,6,10:18.0
-1,6,10:18.0
-2,6,10:18.0
-3,6,10:18.0
-3,7,10:18.0
-2,7,10:18.0
-1,7,10:18.0
0,7,10:18.0
1,7,10:18.0
-1,5,10:18.0
0,5,10:18.0
-5,6,10:18.0
-5,5,10:18.0
-3,5,10:17.0
-5,4,10:18.0
-5,3,10:18.0
-6,5,10:18.0
-6,4,10:18.0
-6,3,10:18.0
-6,2,10:18.0
-6,1,10:18.0
-6,0,10:18.0
-7,3,10:18.0
-8,3,10:18.0
-8,2,10:18.0
-7,2,10:18.0
-7,1,10:18.0
-8,1,10:18.0
-7,0,10:18.0
-8,0,10:18.0
-8,-1,10:18.0
-7,-1,10:18.0
-9,0,10:18.0
-9,-1,10:18.0
-9,-2,10:18.0
-8,-2,10:18.0
-7,-2,10:18.0
-6,-2,10:18.0
-5,-2,10:18.0
-1,-3,10:18.0
-2,-3,10:18.0
-3,-3,10:18.0
-4,-3,10:18.0
-5,-3,10:18.0
-6,-3,10:18.0
-7,-3,10:18.0
-8,-3,10:18.0
-7,-4,10:18.0
-6,-4,10:18.0
-5,-4,10:18.0
-4,-4,10:18.0
-3,-4,10:18.0
-2,-4,10:18.0
-7,-5,10:18.0
-6,-5,10:18.0
-5,-5,10:18.0
-4,-5,10:18.0
-3,-5,10:18.0
-2,-5,10:18.0
-6,-6,10:18.0
-5,-6,10:18.0
-4,-6,10:18.0
-3,-6,10:18.0
-2,-6,10:18.0
-1,-6,10:18.0
-1,-7,10:18.0
0,-7,10:18.0
0,-6,10:18.0
1,-6,10:18.0
-5,-7,10:18.0
-4,-7,10:18.0
-3,-7,10:18.0
-2,-7,10:18.0
1,-7,10:18.0
2,-7,10:18.0
-4,-8,10:18.0
0,-8,10:18.0
-1,-8,10:18.0
0,-9,10:18.0
1,-9,10:18.0
1,-8,10:18.0
2,-9,10:18.0
2,-8,10:18.0
3,-9,10:18.0
3,-8,10:18.0
3,-7,10:18.0
3,-6,10:18.0
4,-8,10:18.0
4,-7,10:18.0
4,-6,10:18.0
4,-5,10:18.0
4,-4,10:18.0
5,-7,10:18.0
5,-6,10:18.0
5,-5,10:18.0
5,-4,10:18.0
5,-3,10:18.0
6,-3,10:18.0
6,-4,10:18.0
6,-5,10:18.0
7,-4,10:18.0
7,-3,10:18.0
7,-2,10:18.0
8,-3,10:18.0
8,-2,10:18.0
8,-1,10:18.0
8,0,10:18.0
8,1,10:18.0
7,3,10:18.0
7,2,10:18.0
7,1,10:18.0
7,0,10:18.0
-3,-8,10:18.0
-2,-8,10:18.0
-5,-8,10:18.0
-4,-9,10:18.0
-3,-9,10:18.0
-2,-9,10:18.0
0,0,11:17.0
-1,2,11:17.0
0,6,11:18.0
1,6,11:18.0
-3,0,11:17.0
-4,-2,11:17.0
3,0,11:17.0
6,-1,11:17.0
6,2,11:17.0
3,-2,11:17.0
4,-3,11:17.0
2,-5,11:17.0
0,7,11:18.0
0,8,11:18.0
-1,8,11:18.0
-1,7,11:18.0
-1,6,11:18.0
-1,5,11:18.0
0,5,11:17.0
1,5,11:17.0
2,5,11:18.0
2,6,11:18.0
1,7,11:18.0
-3,7,11:18.0
-2,7,11:18.0
-1,4,11:18.0
0,4,11:18.0
1,4,11:18.0
2,4,11:18.0
-3,4,11:17.0
-3,6,11:18.0
-2,6,11:18.0
-2,5,11:18.0
-3,5,11:18.0
-4,5,11:18.0
-4,4,11:18.0
-5,4,11:18.0
-1,-1,11:18.0
-1,1,11:18.0
1,-1,11:18.0
1,1,11:18.0
-2,2,11:18.0
-3,3,11:18.0
-4,2,11:18.0
-5,2,11:18.0
-5,3,11:18.0
-5,1,11:18.0
-5,-1,11:18.0
-5,-2,11:18.0
-5,-3,11:18.0
-4,-3,11:18.0
-3,-3,11:18.0
-2,-3,11:18.0
-2,-2,11:18.0
-1,-2,11:18.0
-1,-3,11:18.0
0,-3,11:18.0
1,-3,11:18.0
1,-2,11:18.0
2,-1,11:18.0
3,-1,11:18.0
4,-1,11:18.0
5,-1,11:18.0
6,0,11:18.0
6,1,11:18.0
7,-3,11:18.0
7,-2,11:18.0
7,-1,11:18.0
7,0,11:18.0
7,1,11:18.0
7,2,11:18.0
7,3,11:18.0
6,3,11:18.0
5,4,11:18.0
4,5,11:18.0
3,6,11:18.0
2,2,11:18.0
2,3,11:18.0
3,2,11:18.0
4,1,11:18.0
4,2,11:18.0
5,3,11:18.0
4,3,11:18.0
3,3,11:18.0
3,4,11:18.0
4,4,11:18.0
3,5,11:18.0
-6,0,11:18.0
-7,0,11:18.0
-8,0,11:18.0
-8,-1,11:18.0
-8,-2,11:18.0
-7,1,11:18.0
-7,2,11:18.0
-6,3,11:18.0
-6,2,11:18.0
-6,1,11:18.0
-7,-1,11:18.0
-6,-1,11:18.0
-6,-2,11:18.0
-7,-2,11:18.0
-7,-3,11:18.0
-6,-4,11:18.0
-5,-5,11:18.0
-4,-6,11:18.0
2,-6,11:18.0
2,-7,11:18.0
2,-8,11:18.0
1,-8,11:18.0
1,-7,11:18.0
0,-7,11:18.0
-1,-7,11:18.0
-3,-6,11:18.0
-2,-6,11:18.0
-1,-6,11:18.0
0,-6,11:18.0
1,-5,11:17.0
3,-5,11:18.0
3,-6,11:18.0
1,-6,11:18.0
-6,-3,11:18.0
-5,-4,11:18.0
-4,-5,11:18.0
-3,-5,11:18.0
-2,-5,11:18.0
-1,-5,11:18.0
0,-5,11:18.0
0,-4,11:18.0
-1,-4,11:18.0
-2,-4,11:18.0
-3,-4,11:18.0
-4,-4,11:18.0
3,-7,11:18.0
3,-4,11:18.0
2,-4,11:18.0
1,-4,11:18.0
2,-3,11:18.0
2,-2,11:18.0
5,-2,11:18.0
5,-3,11:18.0
5,-4,11:18.0
5,-5,11:18.0
4,-6,11:18.0
4,-5,11:18.0
4,-4,11:18.0
6,-4,11:18.0
6,-3,11:18.0
6,-2,11:18.0
-4,-7,11:18.0
-3,-7,11:18.0
-1,0,12:18.0
-2,0,12:18.0
-3,0,12:18.0
-4,0,12:18.0
-5,0,12:18.0
-5,-1,12:18.0
0,1,12:18.0
0,2,12:18.0
0,3,12:18.0
0,4,12:18.0
0,5,12:18.0
0,-1,12:18.0
0,-2,12:18.0
0,-3,12:18.0
0,-4,12:18.0
1,0,12:18.0
2,0,12:18.0
3,0,12:18.0
4,0,12:18.0
5,0,12:18.0
6,0,12:18.0
6,-2,12:18.0
6,-1,12:18.0
6,1,12:18.0
6,2,12:18.0
5,3,12:18.0
4,3,12:18.0
3,4,12:18.0
2,4,12:18.0
1,5,12:18.0
0,6,12:18.0
-1,5,12:18.0
-1,6,12:18.0
-2,5,12:18.0
-4,1,12:18.0
-4,2,12:18.0
-4,3,12:18.0
-3,4,12:18.0
-4,-2,12:18.0
-3,-3,12:18.0
-2,-4,12:18.0
-1,-4,12:18.0
-1,-3,12:18.0
-2,-3,12:18.0
-2,-2,12:18.0
-3,-2,12:18.0
-3,-1,12:18.0
-1,-2,12:18.0
-2,-1,12:18.0
-4,-1,12:18.0
-1,-1,12:18.0
2,-5,12:18.0
2,-4,12:18.0
1,-4,12:18.0
3,-3,12:18.0
4,-3,12:18.0
3,-4,12:18.0
5,-3,12:18.0
5,-1,12:18.0
5,-2,12:18.0
4,-2,12:18.0
3,-2,12:18.0
2,-2,12:18.0
1,-2,12:18.0
2,-3,12:18.0
1,-1,12:18.0
2,-1,12:18.0
3,-1,12:18.0
1,-3,12:18.0
4,-1,12:18.0
2,1,12:18.0
1,1,12:18.0
3,1,12:18.0
0,0,12:18.0
4,1,12:18.0
5,1,12:18.0
3,2,12:18.0
2,2,12:18.0
1,2,12:18.0
4,2,12:18.0
5,2,12:18.0
3,3,12:18.0
2,3,12:18.0
1,3,12:18.0
1,4,12:18.0
-1,3,12:18.0
-2,3,12:18.0
-2,2,12:18.0
-1,2,12:18.0
-1,1,12:18.0
-2,1,12:18.0
-3,2,12:18.0
-3,3,12:18.0
-3,1,12:18.0
-1,4,12:18.0
-2,4,12:18.0
1,6,12:18.0
1,-5,12:18.0
0,-5,12:18.0
1,-6,12:18.0
-6,-1,12:18.0
-5,-2,12:18.0
-4,-3,12:18.0
-3,-4,12:18.0
-1,-5,12:18.0
0,0,13:18.0
-1,0,13:18.0
-1,-1,13:18.0
0,-1,13:18.0
0,-2,13:18.0
1,-2,13:18.0
1,-1,13:18.0
2,-1,13:18.0
2,-2,13:18.0
3,-1,13:18.0
3,0,13:18.0
3,1,13:18.0
2,2,13:18.0
2,1,13:18.0
2,0,13:18.0
1,2,13:18.0
1,1,13:18.0
1,0,13:18.0
0,3,13:18.0
0,2,13:18.0
0,1,13:18.0
-1,2,13:18.0
-1,1,13:18.0
-2,1,13:18.0
-2,0,13:18.0
-2,-1,13:18.0
-3,-1,13:18.0
-1,-2,13:18.0
1,-3,13:18.0
