[META]
version=2.0
spawnOnBlockType=1,2,3,12
spawnSunlight=True
spawnDarkness=True
spawnWater=False
spawnLava=False
underFill=True
randomRotation=True
dig=True
tree=False
branch=False
needsFoundation=True
rarity=40
collisionPercentage=0
spawnElevationMin=0
spawnElevationMax=240
spawnInBiome=Grassland
[DATA]
-4,-5,0:17.0
-3,-5,0:17.0
-3,-4,0:17.0
-2,-4,0:17.0
1,-4,0:17.0
-4,-3,0:17.0
-3,-3,0:17.0
-2,-3,0:17.0
-1,-3,0:17.0
0,-3,0:17.0
1,-3,0:17.0
-5,-2,0:17.0
-4,-2,0:17.0
-3,-2,0:17.0
-2,-2,0:17.0
-1,-2,0:17.0
0,-2,0:17.0
1,-2,0:17.0
2,-2,0:30
4,-2,0:17.0
-7,-1,0:17.0
-6,-1,0:17.0
-5,-1,0:17.0
-4,-1,0:17.0
-3,-1,0:17.0
-2,-1,0:17.0
-1,-1,0:53.1
1,-1,0:17.0
4,-1,0:17.0
-7,0,0:17.0
-6,0,0:17.0
-5,0,0:17.0
-4,0,0:17.0
1,0,0:17.0
2,0,0:17.0
3,0,0:17.0
-5,1,0:17.0
-4,1,0:17.0
-2,1,0:17.0
-1,1,0:17.0
0,1,0:17.0
1,1,0:17.0
2,1,0:17.0
-5,2,0:17.0
-4,2,0:17.0
-2,2,0:17.0
-1,2,0:17.0
0,2,0:17.0
1,2,0:17.0
2,2,0:17.0
-6,3,0:17.0
-5,3,0:17.0
-4,3,0:17.0
0,3,0:17.0
1,3,0:17.0
2,3,0:17.0
-6,4,0:17.0
1,4,0:17.0
2,4,0:17.0
-5,5,0:17.0
1,5,0:17.0
2,5,0:17.0
2,6,0:17.0
-1,-3,1:17.0
-3,-2,1:17.0
-2,-2,1:17.0
-1,-2,1:17.0
0,-2,1:17.0
2,-2,1:30
-4,-1,1:17.0
-3,-1,1:17.0
-2,-1,1:53.1
1,-1,1:17.0
-4,0,1:17.0
1,0,1:17.0
2,0,1:17.0
-4,1,1:17.0
-2,1,1:17.0
-1,1,1:17.0
0,1,1:17.0
1,1,1:17.0
-1,2,1:17.0
0,2,1:17.0
-1,-3,2:17.0
-3,-2,2:17.0
-2,-2,2:17.0
-1,-2,2:17.0
0,-2,2:17.0
2,-2,2:30
-4,-1,2:17.0
1,-1,2:17.0
-4,0,2:17.0
-3,0,2:53.2
-2,0,2:17.0
1,0,2:17.0
2,0,2:17.0
-2,1,2:17.0
0,1,2:17.0
1,1,2:17.0
-1,2,2:17.0
-1,-3,3:17.0
-4,-2,3:17.0
-3,-2,3:17.0
-2,-2,3:17.0
-1,-2,3:17.0
0,-2,3:17.0
1,-2,3:17.0
2,-2,3:30
-4,-1,3:17.0
1,-1,3:17.0
-4,0,3:17.0
-2,0,3:53.0
-1,0,3:17.0
1,0,3:17.0
2,0,3:17.0
-4,1,3:17.0
-3,1,3:17.0
-2,1,3:17.0
0,1,3:17.0
1,1,3:17.0
-1,2,3:17.0
1,2,3:17.0
-1,-3,4:17.0
-3,-2,4:17.0
-2,-2,4:17.0
-1,-2,4:17.0
0,-2,4:17.0
1,-2,4:17.0
2,-2,4:30
-4,-1,4:17.0
1,-1,4:17.0
-4,0,4:17.0
-1,0,4:53.0
0,0,4:17.0
1,0,4:17.0
2,0,4:17.0
-4,1,4:17.0
-3,1,4:17.0
-2,1,4:17.0
-1,1,4:17.0
0,1,4:17.0
1,1,4:17.0
-1,2,4:17.0
-2,-3,5:17.0
-1,-3,5:17.0
0,-3,5:17.0
-3,-2,5:17.0
-2,-2,5:17.0
0,-2,5:17.0
1,-2,5:17.0
2,-2,5:30
-5,-1,5:30
-4,-1,5:17.0
-1,-1,5:17.0
0,-1,5:53.3
1,-1,5:17.0
2,-1,5:17.0
-5,0,5:18
-4,0,5:17.0
1,0,5:17.0
2,0,5:17.0
-4,1,5:30
-3,1,5:17.0
-2,1,5:17.0
-1,1,5:17.0
0,1,5:17.0
1,1,5:17.0
2,1,5:17.0
-1,2,5:17.0
1,2,5:17.0
2,2,5:17.0
-1,-3,6:17.0
-5,-2,6:18
-3,-2,6:17.0
-2,-2,6:17.0
-1,-2,6:17.0
0,-2,6:17.0
2,-2,6:30
-5,-1,6:17.0
-4,-1,6:17.0
-2,-1,6:17.0
-1,-1,6:53.1
1,-1,6:17.0
-5,0,6:17.0
-4,0,6:17.0
1,0,6:17.0
-4,1,6:30
-3,1,6:17.0
-2,1,6:17.0
-1,1,6:17.0
0,1,6:17.0
1,1,6:18
-2,2,6:17.0
-1,2,6:17.0
1,2,6:18
-7,-5,7:18
-1,-3,7:17.0
-5,-2,7:18
-4,-2,7:17.0
-3,-2,7:17.0
-2,-2,7:17.0
-1,-2,7:17.0
0,-2,7:17.0
2,-2,7:30
-7,-1,7:18
-6,-1,7:17.0
-5,-1,7:17.0
-3,-1,7:17.0
-2,-1,7:53.1
1,-1,7:17.0
-6,0,7:17.0
-5,0,7:17.0
-4,0,7:17.0
-3,0,7:17.0
1,0,7:17.0
-4,1,7:18
-3,1,7:17.0
-2,1,7:17.0
-1,1,7:17.0
0,1,7:17.0
-3,2,7:18
-2,2,7:17.0
-2,3,7:18
-3,4,7:30
-4,7,7:18
-7,-6,8:18
-6,-6,8:18
-8,-5,8:18
-7,-5,8:17.0
-6,-5,8:18
-6,-4,8:18
-5,-4,8:18
-5,-3,8:18
-3,-3,8:17.0
-2,-3,8:17.0
-1,-3,8:17.0
-5,-2,8:17.0
-4,-2,8:17.0
-3,-2,8:17.0
-2,-2,8:17.0
-1,-2,8:17.0
0,-2,8:17.0
2,-2,8:30
-7,-1,8:18
-6,-1,8:17.0
-5,-1,8:17.0
-4,-1,8:17.0
-3,-1,8:53.1
1,-1,8:17.0
-7,0,8:18
-6,0,8:17.0
-5,0,8:17.0
-4,0,8:17.0
-3,0,8:17.0
1,0,8:17.0
2,0,8:18
-5,1,8:18
-4,1,8:18
-3,1,8:17.0
-2,1,8:17.0
-1,1,8:17.0
0,1,8:17.0
-4,2,8:18
-3,2,8:30
-2,2,8:17.0
0,2,8:18
-4,3,8:18
-4,4,8:30
-3,4,8:18
-7,5,8:18
-6,5,8:18
-3,5,8:30
-4,6,8:18
-4,7,8:17.0
-3,7,8:18
-4,8,8:18
-6,-6,9:18
-8,-5,9:18
-7,-5,9:17.0
-6,-5,9:17.0
-5,-5,9:18
-7,-4,9:18
-6,-4,9:17.0
-5,-4,9:17.0
-4,-4,9:18
-5,-3,9:17.0
-4,-3,9:18
-3,-3,9:18
-2,-3,9:18
-1,-3,9:18
-6,-2,9:18
-5,-2,9:17.0
-4,-2,9:17.0
-3,-2,9:17.0
-2,-2,9:17.0
-1,-2,9:17.0
0,-2,9:17.0
2,-2,9:30
-6,-1,9:18
-5,-1,9:17.0
0,-1,9:17.0
1,-1,9:18
-6,0,9:18
-5,0,9:17.0
-4,0,9:53.2
-3,0,9:30
0,0,9:17.0
-5,1,9:17.0
-4,1,9:17.0
-3,1,9:17.0
-2,1,9:17.0
-1,1,9:17.0
0,1,9:17.0
-5,2,9:17.0
-4,2,9:17.0
-3,2,9:17.0
-2,2,9:18
-6,3,9:18
-5,3,9:18
-4,3,9:17.0
-3,3,9:18
-4,4,9:17.0
-3,4,9:18
-8,5,9:18
-7,5,9:17.0
-6,5,9:17.0
-5,5,9:17.0
-4,5,9:17.0
-3,5,9:18
-7,6,9:18
-6,6,9:18
-5,6,9:18
-4,6,9:17.0
-5,7,9:18
-4,7,9:17.0
-3,7,9:18
-5,8,9:18
-4,8,9:17.0
-3,8,9:18
-4,9,9:18
-7,-5,10:18
-6,-5,10:18
-6,-4,10:18
-5,-4,10:18
-5,-3,10:17.0
-4,-3,10:18
-3,-2,10:30
-1,-2,10:17.0
0,-2,10:18
1,-2,10:18
2,-2,10:30
-1,-1,10:17.0
2,-1,10:30
-1,0,10:17.0
0,0,10:17.0
-4,1,10:53.2
-3,1,10:17.0
-2,1,10:17.0
-1,1,10:17.0
0,1,10:18
-5,2,10:17.0
-4,2,10:17.0
-3,2,10:17.0
-1,2,10:18
-4,3,10:17.0
-3,3,10:17.0
-4,4,10:18
-7,5,10:18
-6,5,10:17.0
-5,5,10:18
-4,5,10:18
-6,6,10:18
-5,6,10:30
-4,6,10:18
-6,7,10:30
-5,7,10:30
-4,7,10:17.0
-4,8,10:18
-5,-4,11:18
-5,-3,11:17.0
-3,-2,11:30
2,-2,11:30
-2,-1,11:30
-1,-1,11:17.0
2,-1,11:30
-2,0,11:30
-1,0,11:17.0
-3,1,11:53.0
-2,1,11:17.0
-1,1,11:18
-4,2,11:17.0
-3,2,11:17.0
3,2,11:18
5,2,11:18
-3,3,11:17.0
3,3,11:18
-6,5,11:18
-4,7,11:18
-7,-4,12:30
-6,-4,12:30
-5,-4,12:18
-7,-3,12:30
-6,-3,12:17.0
-5,-3,12:17.0
-4,-3,12:18
-2,-3,12:30
-1,-3,12:17.0
0,-3,12:30
1,-3,12:30
2,-3,12:30
-3,-2,12:30
-2,-2,12:30
-1,-2,12:17.0
0,-2,12:30
1,-2,12:30
2,-2,12:30
3,-2,12:30
-3,-1,12:30
-2,-1,12:30
-1,-1,12:17.0
0,-1,12:30
1,-1,12:30
2,-1,12:30
3,-1,12:30
-3,0,12:30
-2,0,12:30
-1,0,12:17.0
0,0,12:18
1,0,12:30
2,0,12:30
3,0,12:30
-2,1,12:53.0
-1,1,12:17.0
0,1,12:17.0
1,1,12:30
2,1,12:30
3,1,12:30
4,1,12:18
-4,2,12:30
-3,2,12:17.0
-2,2,12:17.0
-1,2,12:52
0,2,12:17.0
1,2,12:17.0
2,2,12:17.0
3,2,12:17.0
4,2,12:17.0
5,2,12:17.0
-3,3,12:30
-2,3,12:30
-1,3,12:30
0,3,12:30
1,3,12:18
2,3,12:18
3,3,12:18
5,3,12:17.0
6,3,12:18
-3,4,12:30
-2,4,12:30
-1,4,12:30
0,4,12:30
1,4,12:30
-7,-5,13:18
-8,-4,13:18
-7,-4,13:17.0
-7,-3,13:17.0
-6,-3,13:18
-5,-3,13:18
-3,-3,13:30
-2,-3,13:30
-1,-3,13:17.0
0,-3,13:30
1,-3,13:30
2,-3,13:30
-1,-2,13:30
3,-2,13:30
3,-1,13:30
3,0,13:30
4,1,13:18
-4,2,13:30
-3,2,13:17.0
0,2,13:18
1,2,13:18
2,2,13:18
3,2,13:18
4,2,13:17.0
5,2,13:17.0
6,2,13:17.0
7,2,13:18
8,2,13:18
-3,3,13:17.0
2,3,13:30
3,3,13:18
4,3,13:17.0
7,3,13:30
8,3,13:30
-3,4,13:30
-2,4,13:30
-1,4,13:30
0,4,13:30
1,4,13:30
4,4,13:18
-7,-4,14:18
-1,-4,14:17.0
-7,-3,14:18
-3,-3,14:30
-2,-3,14:30
-1,-3,14:17.0
-1,-2,14:30
10,-1,14:18
9,0,14:18
4,1,14:18
5,1,14:30
6,1,14:18
8,1,14:18
-3,2,14:18
4,2,14:52
5,2,14:18
6,2,14:17.0
7,2,14:17.0
-5,3,14:30
-4,3,14:17.0
-3,3,14:17.0
3,3,14:30
4,3,14:18
7,3,14:30
8,3,14:18
-6,4,14:30
-5,4,14:30
-4,4,14:17.0
8,4,14:30
9,4,14:18
11,4,14:18
-8,5,14:18
-7,5,14:18
-6,5,14:18
-5,5,14:18
-4,5,14:18
-3,5,14:30
9,5,14:30
-8,6,14:30
-5,6,14:30
-5,-9,15:18
-4,-9,15:18
-5,-8,15:18
-4,-8,15:18
-3,-8,15:18
-2,-8,15:18
-3,-7,15:18
-1,-7,15:18
1,-7,15:18
2,-7,15:18
-2,-6,15:18
-1,-6,15:17.0
-3,-5,15:18
-2,-5,15:18
-1,-5,15:17.0
0,-5,15:18
1,-5,15:18
-2,-4,15:18
-1,-4,15:17.0
0,-4,15:52
-1,-3,15:30
9,-2,15:18
10,-2,15:18
11,-2,15:18
8,-1,15:18
9,-1,15:18
10,-1,15:17.0
11,-1,15:18
7,0,15:18
8,0,15:17.0
9,0,15:17.0
10,0,15:17.0
4,1,15:30
5,1,15:30
6,1,15:18
7,1,15:17.0
8,1,15:17.0
10,1,15:18
5,2,15:30
6,2,15:17.0
7,2,15:17.0
8,2,15:17.0
9,2,15:30
-4,3,15:17.0
-3,3,15:18
4,3,15:18
6,3,15:18
7,3,15:17.0
8,3,15:17.0
9,3,15:17.0
10,3,15:18
-8,4,15:18
-7,4,15:18
-6,4,15:18
-5,4,15:18
-4,4,15:17.0
7,4,15:18
8,4,15:17.0
9,4,15:17.0
10,4,15:17.0
11,4,15:17.0
12,4,15:18
-9,5,15:18
-8,5,15:17.0
-7,5,15:17.0
-6,5,15:17.0
-5,5,15:17.0
-4,5,15:17.0
-3,5,15:18
9,5,15:18
10,5,15:18
11,5,15:18
-9,6,15:30
-8,6,15:18
-7,6,15:18
-6,6,15:30
-5,6,15:18
-4,6,15:17.0
-3,6,15:18
-4,7,15:17.0
-3,7,15:18
-4,8,15:18
-5,-10,16:18
-6,-9,16:18
-5,-9,16:17.0
-4,-9,16:17.0
-6,-8,16:18
-5,-8,16:17.0
-4,-8,16:17.0
-3,-8,16:17.0
-2,-8,16:18
1,-8,16:18
2,-8,16:18
-4,-7,16:18
-3,-7,16:17.0
-2,-7,16:17.0
-1,-7,16:17.0
1,-7,16:17.0
2,-7,16:17.0
-3,-6,16:18
-2,-6,16:17.0
-1,-6,16:17.0
0,-6,16:17.0
1,-6,16:17.0
2,-6,16:18
-3,-5,16:18
-2,-5,16:18
-1,-5,16:17.0
0,-5,16:18
1,-5,16:18
-1,-4,16:30
10,-2,16:18
8,-1,16:18
9,-1,16:18
10,-1,16:17.0
11,-1,16:18
7,0,16:30
8,0,16:17.0
9,0,16:30
10,0,16:18
11,0,16:18
6,1,16:30
7,1,16:18
8,1,16:18
5,2,16:30
6,2,16:18
7,2,16:18
8,2,16:18
7,3,16:18
8,3,16:18
9,3,16:18
-8,4,16:18
-7,4,16:18
-6,4,16:18
-4,4,16:18
7,4,16:18
8,4,16:18
9,4,16:18
10,4,16:18
11,4,16:18
-8,5,16:18
-7,5,16:17.0
-6,5,16:17.0
-5,5,16:18
-4,5,16:18
8,5,16:18
11,5,16:30
-8,6,16:30
-7,6,16:18
-6,6,16:18
-4,6,16:18
-4,7,16:17.0
-5,8,16:30
-4,8,16:17.0
-3,8,16:18
-4,9,16:18
-5,-10,17:18
-4,-10,17:18
2,-10,17:18
-6,-9,17:18
-5,-9,17:17.0
-4,-9,17:18
-3,-9,17:18
2,-9,17:18
-6,-8,17:30
-5,-8,17:17.0
-4,-8,17:17.0
-3,-8,17:18
0,-8,17:18
1,-8,17:18
2,-8,17:17.0
3,-8,17:18
-2,-7,17:18
-1,-7,17:18
0,-7,17:18
1,-7,17:17.0
2,-7,17:17.0
3,-7,17:18
-2,-6,17:18
-1,-6,17:18
0,-6,17:17.0
1,-6,17:18
2,-6,17:18
-1,-5,17:18
0,-5,17:18
8,0,17:30
8,1,17:30
8,2,17:30
8,3,17:18
9,3,17:30
8,4,17:18
-4,7,17:18
-4,8,17:18
-5,-10,18:18
-5,-9,18:18
2,-9,18:18
3,-9,18:18
-5,-8,18:30
-4,-8,18:18
1,-8,18:18
2,-8,18:17.0
3,-8,18:17.0
4,-8,18:18
0,-7,18:30
1,-7,18:18
2,-7,18:18
3,-7,18:18
1,-6,18:30
2,-8,19:30
3,-8,19:18
