[META]
version=2.0
spawnOnBlockType=1,2,3,12
spawnSunlight=True
spawnDarkness=True
spawnWater=False
spawnLava=False
underFill=True
randomRotation=True
dig=True
tree=False
branch=False
needsFoundation=True
rarity=30
collisionPercentage=0
spawnElevationMin=0
spawnElevationMax=240
spawnInBiome=Grassland
[DATA]
0,-2,0:17.3
-1,-1,0:17.3
0,-1,0:17.3
0,-1,1:17.3
0,-1,2:17.3
0,-1,3:17.3
0,-1,4:17.3
0,-2,5:91.2
-1,-1,5:18
0,-1,5:17.3
2,1,5:106.4
0,-3,6:18
-1,-2,6:18
0,-2,6:18
-1,-1,6:91.1
0,-1,6:17.3
1,-1,6:18
-2,0,6:18
-1,0,6:18
0,0,6:91.3
-1,1,6:18
0,1,6:18
2,1,6:106.4
1,-3,7:18
3,-3,7:18
4,-3,7:18
1,-2,7:18
2,-2,7:18
3,-2,7:18
-1,-1,7:18
0,-1,7:18
1,-1,7:17.3
2,-1,7:17.3
-1,0,7:18
0,0,7:18
1,0,7:18
2,0,7:18
3,0,7:18
1,1,7:18
2,1,7:106.4
3,1,7:18
1,-1,8:18
2,-1,8:18
