[META]
version=2.0
spawnOnBlockType=1,2,3,12
spawnSunlight=True
spawnDarkness=True
spawnWater=False
spawnLava=False
underFill=True
randomRotation=True
dig=True
tree=False
branch=False
needsFoundation=True
rarity=30
collisionPercentage=0
spawnElevationMin=0
spawnElevationMax=200
spawnInBiome=Grassland
[DATA]
-1,-1,0:17.0
-2,0,0:17.0
-1,0,0:17.0
0,0,0:17.0
-1,1,0:17.0
-1,0,1:86.0
-1,-2,2:30
-3,-1,2:30
-1,0,2:86.0
0,0,2:30
-1,2,2:30
-2,-2,3:18
-1,-2,3:18
0,-2,3:18
-3,-1,3:18
-2,-1,3:18
-1,-1,3:17.0
0,-1,3:18
1,-1,3:18
-3,0,3:18
-2,0,3:17.0
-1,0,3:17.0
0,0,3:17.0
1,0,3:18
-3,1,3:18
-2,1,3:18
-1,1,3:17.0
0,1,3:18
1,1,3:18
-2,2,3:18
-1,2,3:18
0,2,3:18
-1,-1,4:18
-2,0,4:18
-1,0,4:17.0
0,0,4:18
-1,1,4:18
-1,0,5:18
