[META]
version=2.0
spawnOnBlockType=35
spawnSunlight=True
spawnDarkness=True
spawnWater=False
spawnLava=False
underFill=False
randomRotation=True
dig=True
tree=False
branch=False
needsFoundation=True
rarity=750
collisionPercentage=0
spawnElevationMin=128
spawnElevationMax=245
spawnInBiome=Sky
[DATA]
-1,1,0:35.12
0,0,0:35.12
1,0,0:35.12
-1,-1,0:35.12
0,0,1:35.12
0,0,2:35.12
0,-1,2:35.12
0,0,3:35.12
-1,0,3:35.12
-1,1,3:35.12
0,-2,3:35.12
1,0,3:41
-2,0,3:41
-1,-2,3:41
-1,2,3:41
0,0,4:35.12
-2,0,4:35.12
-1,2,4:35.12
1,-2,4:35.12
0,0,5:35.12
1,0,5:35.12
-2,0,5:35.12
1,-2,5:35.12
-1,2,5:35.12
0,-2,5:41
1,1,5:41
-2,-1,5:41
-1,1,5:41
-3,0,6:35.12
-1,3,6:35.12
1,-3,6:35.12
2,0,6:35.12
0,0,6:35.12
-4,0,6:41
-1,4,6:41
3,0,6:41
1,-4,6:41
-2,3,6:41
2,-1,6:41
2,-3,6:41
-3,1,6:41
1,-3,7:41
-3,0,7:41
-1,3,7:41
0,0,7:41
2,0,7:41
