[META]
version=2.0
spawnOnBlockType=1,2,3,12
spawnSunlight=True
spawnDarkness=True
spawnWater=False
spawnLava=False
underFill=True
randomRotation=True
dig=True
tree=False
branch=False
needsFoundation=True
rarity=30
collisionPercentage=0
spawnElevationMin=0
spawnElevationMax=128
spawnInBiome=Grassland
[DATA]
-3,-17,0:86.0
-2,-17,0:86.0
-1,-17,0:86.0
0,-17,0:86.0
1,-17,0:86.0
-7,-16,0:86.0
-6,-16,0:86.0
-5,-16,0:86.0
-4,-16,0:86.0
-3,-16,0:5.0
-2,-16,0:5.0
-1,-16,0:5.0
0,-16,0:5.0
1,-16,0:5.0
2,-16,0:86.0
3,-16,0:86.0
4,-16,0:86.0
5,-16,0:86.0
-10,-15,0:86.0
-9,-15,0:86.0
-8,-15,0:86.0
-7,-15,0:5.0
-6,-15,0:5.0
-5,-15,0:5.0
-4,-15,0:5.0
-3,-15,0:5.0
-2,-15,0:5.0
-1,-15,0:5.0
0,-15,0:5.0
1,-15,0:5.0
2,-15,0:5.0
3,-15,0:5.0
4,-15,0:5.0
5,-15,0:5.0
6,-15,0:86.0
7,-15,0:86.0
8,-15,0:86.0
-12,-14,0:86.0
-11,-14,0:86.0
-10,-14,0:5.0
-9,-14,0:5.0
-8,-14,0:5.0
-7,-14,0:5.0
-6,-14,0:5.0
-5,-14,0:5.0
-4,-14,0:5.0
-3,-14,0:5.0
-2,-14,0:5.0
-1,-14,0:5.0
0,-14,0:5.0
1,-14,0:5.0
2,-14,0:5.0
3,-14,0:5.0
4,-14,0:5.0
5,-14,0:5.0
6,-14,0:5.0
7,-14,0:5.0
8,-14,0:5.0
9,-14,0:86.0
10,-14,0:86.0
-13,-13,0:86.0
-12,-13,0:5.0
-11,-13,0:5.0
-10,-13,0:5.0
-9,-13,0:5.0
-8,-13,0:5.0
-7,-13,0:5.0
-6,-13,0:5.0
-5,-13,0:5.0
-4,-13,0:5.0
-3,-13,0:5.0
-2,-13,0:5.0
-1,-13,0:5.0
0,-13,0:5.0
1,-13,0:5.0
2,-13,0:5.0
3,-13,0:5.0
4,-13,0:5.0
5,-13,0:5.0
6,-13,0:5.0
7,-13,0:5.0
8,-13,0:5.0
9,-13,0:5.0
10,-13,0:5.0
11,-13,0:86.0
-14,-12,0:86.3
-13,-12,0:5.0
-12,-12,0:5.0
-11,-12,0:5.0
-10,-12,0:5.0
-9,-12,0:5.0
-8,-12,0:5.0
-7,-12,0:5.0
-6,-12,0:5.0
-5,-12,0:5.0
-4,-12,0:5.0
-3,-12,0:5.0
-2,-12,0:5.0
-1,-12,0:5.0
0,-12,0:5.0
1,-12,0:5.0
2,-12,0:5.0
3,-12,0:5.0
4,-12,0:5.0
5,-12,0:5.0
6,-12,0:5.0
7,-12,0:5.0
8,-12,0:5.0
9,-12,0:5.0
10,-12,0:5.0
11,-12,0:5.0
12,-12,0:86.1
-15,-11,0:86.3
-14,-11,0:5.0
-13,-11,0:5.0
-12,-11,0:5.0
-11,-11,0:5.0
-10,-11,0:5.0
-9,-11,0:5.0
-8,-11,0:5.0
-7,-11,0:5.0
-6,-11,0:5.0
-5,-11,0:5.0
-4,-11,0:5.0
-3,-11,0:35.15
-2,-11,0:35.15
-1,-11,0:35.15
0,-11,0:35.15
1,-11,0:35.15
2,-11,0:35.15
3,-11,0:35.15
4,-11,0:35.15
5,-11,0:5.0
6,-11,0:5.0
7,-11,0:5.0
8,-11,0:5.0
9,-11,0:5.0
10,-11,0:5.0
11,-11,0:5.0
12,-11,0:5.0
13,-11,0:86.1
-15,-10,0:86.3
-14,-10,0:5.0
-13,-10,0:5.0
-12,-10,0:5.0
-11,-10,0:5.0
-10,-10,0:5.0
-9,-10,0:5.0
-8,-10,0:5.0
-7,-10,0:5.0
-6,-10,0:5.0
-5,-10,0:5.0
-4,-10,0:35.15
-3,-10,0:35.15
-2,-10,0:5.0
-1,-10,0:5.0
0,-10,0:5.0
1,-10,0:5.0
2,-10,0:5.0
3,-10,0:5.0
4,-10,0:35.15
5,-10,0:35.15
6,-10,0:5.0
7,-10,0:5.0
8,-10,0:5.0
9,-10,0:5.0
10,-10,0:5.0
11,-10,0:5.0
12,-10,0:5.0
13,-10,0:86.1
-16,-9,0:86.3
-15,-9,0:5.0
-14,-9,0:5.0
-13,-9,0:5.0
-12,-9,0:5.0
-11,-9,0:5.0
-10,-9,0:5.0
-9,-9,0:5.0
-8,-9,0:5.0
-7,-9,0:5.0
-6,-9,0:5.0
-5,-9,0:35.15
-4,-9,0:35.15
-3,-9,0:5.0
-2,-9,0:35.14
-1,-9,0:35.14
0,-9,0:35.14
1,-9,0:35.14
2,-9,0:35.14
3,-9,0:35.14
4,-9,0:5.0
5,-9,0:35.15
6,-9,0:35.15
7,-9,0:5.0
8,-9,0:5.0
9,-9,0:5.0
10,-9,0:5.0
11,-9,0:5.0
12,-9,0:5.0
13,-9,0:5.0
14,-9,0:86.1
-16,-8,0:86.3
-15,-8,0:5.0
-14,-8,0:5.0
-13,-8,0:5.0
-12,-8,0:5.0
-11,-8,0:5.0
-10,-8,0:5.0
-9,-8,0:5.0
-8,-8,0:5.0
-7,-8,0:5.0
-6,-8,0:35.15
-5,-8,0:35.15
-4,-8,0:5.0
-3,-8,0:35.14
-2,-8,0:35.14
-1,-8,0:5.0
0,-8,0:5.0
1,-8,0:5.0
2,-8,0:5.0
3,-8,0:35.14
4,-8,0:35.14
5,-8,0:5.0
6,-8,0:35.15
7,-8,0:35.15
8,-8,0:5.0
9,-8,0:5.0
10,-8,0:5.0
11,-8,0:5.0
12,-8,0:5.0
13,-8,0:5.0
14,-8,0:86.1
-16,-7,0:86.3
-15,-7,0:5.0
-14,-7,0:5.0
-13,-7,0:5.0
-12,-7,0:5.0
-11,-7,0:5.0
-10,-7,0:5.0
-9,-7,0:5.0
-8,-7,0:5.0
-7,-7,0:35.15
-6,-7,0:35.15
-5,-7,0:5.0
-4,-7,0:35.14
-3,-7,0:35.14
-2,-7,0:5.0
-1,-7,0:35.0
0,-7,0:35.0
1,-7,0:35.0
2,-7,0:35.0
3,-7,0:5.0
4,-7,0:35.14
5,-7,0:35.14
6,-7,0:5.0
7,-7,0:35.15
8,-7,0:35.15
9,-7,0:5.0
10,-7,0:5.0
11,-7,0:5.0
12,-7,0:5.0
13,-7,0:5.0
14,-7,0:86.1
-17,-6,0:86.3
-16,-6,0:5.0
-15,-6,0:5.0
-14,-6,0:5.0
-13,-6,0:5.0
-12,-6,0:5.0
-11,-6,0:5.0
-10,-6,0:5.0
-9,-6,0:5.0
-8,-6,0:35.15
-7,-6,0:35.15
-6,-6,0:5.0
-5,-6,0:35.14
-4,-6,0:35.14
-3,-6,0:5.0
-2,-6,0:35.0
-1,-6,0:35.0
0,-6,0:5.0
1,-6,0:5.0
2,-6,0:35.0
3,-6,0:35.0
4,-6,0:5.0
5,-6,0:35.14
6,-6,0:35.14
7,-6,0:5.0
8,-6,0:35.15
9,-6,0:35.15
10,-6,0:5.0
11,-6,0:5.0
12,-6,0:5.0
13,-6,0:5.0
14,-6,0:5.0
15,-6,0:86.1
-17,-5,0:86.3
-16,-5,0:5.0
-15,-5,0:5.0
-14,-5,0:5.0
-13,-5,0:5.0
-12,-5,0:5.0
-11,-5,0:5.0
-10,-5,0:5.0
-9,-5,0:35.15
-8,-5,0:35.15
-7,-5,0:5.0
-6,-5,0:35.14
-5,-5,0:35.14
-4,-5,0:5.0
-3,-5,0:35.0
-2,-5,0:35.0
-1,-5,0:5.0
0,-5,0:5.0
1,-5,0:5.0
2,-5,0:5.0
3,-5,0:35.0
4,-5,0:35.0
5,-5,0:5.0
6,-5,0:35.14
7,-5,0:35.14
8,-5,0:5.0
9,-5,0:35.15
10,-5,0:35.15
11,-5,0:5.0
12,-5,0:5.0
13,-5,0:5.0
14,-5,0:5.0
15,-5,0:86.1
-17,-4,0:86.3
-16,-4,0:5.0
-15,-4,0:5.0
-14,-4,0:5.0
-13,-4,0:5.0
-12,-4,0:5.0
-11,-4,0:5.0
-10,-4,0:35.15
-9,-4,0:35.15
-8,-4,0:5.0
-7,-4,0:35.14
-6,-4,0:35.14
-5,-4,0:5.0
-4,-4,0:35.0
-3,-4,0:35.0
-2,-4,0:5.0
-1,-4,0:5.0
0,-4,0:5.0
1,-4,0:5.0
2,-4,0:5.0
3,-4,0:5.0
4,-4,0:35.0
5,-4,0:35.0
6,-4,0:5.0
7,-4,0:35.14
8,-4,0:35.14
9,-4,0:5.0
10,-4,0:35.15
11,-4,0:35.15
12,-4,0:5.0
13,-4,0:5.0
14,-4,0:5.0
15,-4,0:86.1
-17,-3,0:86.3
-16,-3,0:5.0
-15,-3,0:5.0
-14,-3,0:5.0
-13,-3,0:5.0
-12,-3,0:5.0
-11,-3,0:35.15
-10,-3,0:35.15
-9,-3,0:5.0
-8,-3,0:35.14
-7,-3,0:35.14
-6,-3,0:5.0
-5,-3,0:35.0
-4,-3,0:35.0
-3,-3,0:5.0
-2,-3,0:5.0
-1,-3,0:5.0
0,-3,0:5.0
1,-3,0:5.0
2,-3,0:5.0
3,-3,0:5.0
4,-3,0:5.0
5,-3,0:35.0
6,-3,0:35.0
7,-3,0:5.0
8,-3,0:35.14
9,-3,0:35.14
10,-3,0:5.0
11,-3,0:35.15
12,-3,0:35.15
13,-3,0:5.0
14,-3,0:5.0
15,-3,0:86.1
-18,-2,0:86.3
-17,-2,0:44.2
-16,-2,0:44.2
-15,-2,0:44.2
-14,-2,0:5.0
-13,-2,0:5.0
-12,-2,0:35.15
-11,-2,0:35.15
-10,-2,0:5.0
-9,-2,0:35.14
-8,-2,0:35.14
-7,-2,0:5.0
-6,-2,0:35.0
-5,-2,0:35.0
-4,-2,0:5.0
-3,-2,0:5.0
-2,-2,0:5.0
-1,-2,0:5.0
0,-2,0:5.0
1,-2,0:5.0
2,-2,0:5.0
3,-2,0:5.0
4,-2,0:5.0
5,-2,0:5.0
6,-2,0:35.0
7,-2,0:35.0
8,-2,0:5.0
9,-2,0:35.14
10,-2,0:5.0
11,-2,0:5.0
12,-2,0:35.15
13,-2,0:5.0
14,-2,0:5.0
15,-2,0:5.0
16,-2,0:86.1
-19,-1,0:86.3
-18,-1,0:86.3
-17,-1,0:44.2
-16,-1,0:44.2
-15,-1,0:44.2
-14,-1,0:5.0
-13,-1,0:89
-12,-1,0:35.15
-11,-1,0:89
-10,-1,0:5.0
-9,-1,0:35.14
-8,-1,0:89
-7,-1,0:5.0
-6,-1,0:35.0
-5,-1,0:89
-4,-1,0:5.0
-3,-1,0:5.0
-2,-1,0:5.0
-1,-1,0:5.0
0,-1,0:5.0
1,-1,0:5.0
2,-1,0:5.0
3,-1,0:5.0
4,-1,0:5.0
5,-1,0:5.0
6,-1,0:89
7,-1,0:35.0
8,-1,0:89
9,-1,0:35.14
10,-1,0:5.0
11,-1,0:89
12,-1,0:35.15
13,-1,0:89
14,-1,0:5.0
15,-1,0:5.0
16,-1,0:86.1
-16,0,0:44.2
-15,0,0:44.2
-14,0,0:35.0
-13,0,0:35.0
-12,0,0:35.0
-11,0,0:35.0
-10,0,0:35.0
-9,0,0:35.0
-8,0,0:35.0
-7,0,0:35.0
-6,0,0:35.0
-5,0,0:35.0
-4,0,0:35.0
-3,0,0:35.0
-2,0,0:35.0
-1,0,0:35.0
0,0,0:35.0
1,0,0:35.0
2,0,0:35.0
3,0,0:35.0
4,0,0:35.0
5,0,0:35.0
6,0,0:35.0
7,0,0:35.0
8,0,0:35.0
9,0,0:35.0
10,0,0:35.0
11,0,0:35.0
12,0,0:35.0
13,0,0:35.0
14,0,0:35.0
15,0,0:35.0
16,0,0:86.1
-19,1,0:86.3
-18,1,0:86.3
-17,1,0:44.2
-16,1,0:44.2
-15,1,0:44.2
-14,1,0:5.0
-13,1,0:89
-12,1,0:35.15
-11,1,0:89
-10,1,0:5.0
-9,1,0:35.14
-8,1,0:89
-7,1,0:5.0
-6,1,0:35.0
-5,1,0:89
-4,1,0:5.0
-3,1,0:5.0
-2,1,0:5.0
-1,1,0:5.0
0,1,0:5.0
1,1,0:5.0
2,1,0:5.0
3,1,0:5.0
4,1,0:5.0
5,1,0:5.0
6,1,0:89
7,1,0:35.0
8,1,0:89
9,1,0:35.14
10,1,0:5.0
11,1,0:89
12,1,0:35.15
13,1,0:89
14,1,0:5.0
15,1,0:5.0
16,1,0:86.1
-18,2,0:86.3
-17,2,0:44.2
-16,2,0:44.2
-15,2,0:44.2
-14,2,0:5.0
-13,2,0:5.0
-12,2,0:35.15
-11,2,0:35.15
-10,2,0:5.0
-9,2,0:35.14
-8,2,0:35.14
-7,2,0:5.0
-6,2,0:35.0
-5,2,0:35.0
-4,2,0:5.0
-3,2,0:5.0
-2,2,0:5.0
-1,2,0:5.0
0,2,0:5.0
1,2,0:5.0
2,2,0:5.0
3,2,0:5.0
4,2,0:5.0
5,2,0:5.0
6,2,0:35.0
7,2,0:35.0
8,2,0:5.0
9,2,0:35.14
10,2,0:5.0
11,2,0:5.0
12,2,0:35.15
13,2,0:5.0
14,2,0:5.0
15,2,0:5.0
16,2,0:86.1
-17,3,0:86.3
-16,3,0:5.0
-15,3,0:5.0
-14,3,0:5.0
-13,3,0:5.0
-12,3,0:5.0
-11,3,0:35.15
-10,3,0:35.15
-9,3,0:5.0
-8,3,0:35.14
-7,3,0:35.14
-6,3,0:5.0
-5,3,0:35.0
-4,3,0:35.0
-3,3,0:5.0
-2,3,0:5.0
-1,3,0:5.0
0,3,0:5.0
1,3,0:5.0
2,3,0:5.0
3,3,0:5.0
4,3,0:5.0
5,3,0:35.0
6,3,0:35.0
7,3,0:5.0
8,3,0:35.14
9,3,0:35.14
10,3,0:5.0
11,3,0:35.15
12,3,0:35.15
13,3,0:5.0
14,3,0:5.0
15,3,0:86.1
-17,4,0:86.3
-16,4,0:5.0
-15,4,0:5.0
-14,4,0:5.0
-13,4,0:5.0
-12,4,0:5.0
-11,4,0:5.0
-10,4,0:35.15
-9,4,0:35.15
-8,4,0:5.0
-7,4,0:35.14
-6,4,0:35.14
-5,4,0:5.0
-4,4,0:35.0
-3,4,0:35.0
-2,4,0:5.0
-1,4,0:5.0
0,4,0:5.0
1,4,0:5.0
2,4,0:5.0
3,4,0:5.0
4,4,0:35.0
5,4,0:35.0
6,4,0:5.0
7,4,0:35.14
8,4,0:35.14
9,4,0:5.0
10,4,0:35.15
11,4,0:35.15
12,4,0:5.0
13,4,0:5.0
14,4,0:5.0
15,4,0:86.1
-17,5,0:86.3
-16,5,0:5.0
-15,5,0:5.0
-14,5,0:5.0
-13,5,0:5.0
-12,5,0:5.0
-11,5,0:5.0
-10,5,0:5.0
-9,5,0:35.15
-8,5,0:35.15
-7,5,0:5.0
-6,5,0:35.14
-5,5,0:35.14
-4,5,0:5.0
-3,5,0:35.0
-2,5,0:35.0
-1,5,0:5.0
0,5,0:5.0
1,5,0:5.0
2,5,0:5.0
3,5,0:35.0
4,5,0:35.0
5,5,0:5.0
6,5,0:35.14
7,5,0:35.14
8,5,0:5.0
9,5,0:35.15
10,5,0:35.15
11,5,0:5.0
12,5,0:5.0
13,5,0:5.0
14,5,0:5.0
15,5,0:86.1
-17,6,0:86.3
-16,6,0:5.0
-15,6,0:5.0
-14,6,0:5.0
-13,6,0:5.0
-12,6,0:5.0
-11,6,0:5.0
-10,6,0:5.0
-9,6,0:5.0
-8,6,0:35.15
-7,6,0:35.15
-6,6,0:5.0
-5,6,0:35.14
-4,6,0:35.14
-3,6,0:5.0
-2,6,0:35.0
-1,6,0:35.0
0,6,0:5.0
1,6,0:5.0
2,6,0:35.0
3,6,0:35.0
4,6,0:5.0
5,6,0:35.14
6,6,0:35.14
7,6,0:5.0
8,6,0:35.15
9,6,0:35.15
10,6,0:5.0
11,6,0:5.0
12,6,0:5.0
13,6,0:5.0
14,6,0:5.0
15,6,0:86.1
-16,7,0:86.3
-15,7,0:5.0
-14,7,0:5.0
-13,7,0:5.0
-12,7,0:5.0
-11,7,0:5.0
-10,7,0:5.0
-9,7,0:5.0
-8,7,0:5.0
-7,7,0:35.15
-6,7,0:35.15
-5,7,0:5.0
-4,7,0:35.14
-3,7,0:35.14
-2,7,0:5.0
-1,7,0:35.0
0,7,0:35.0
1,7,0:35.0
2,7,0:35.0
3,7,0:5.0
4,7,0:35.14
5,7,0:35.14
6,7,0:5.0
7,7,0:35.15
8,7,0:35.15
9,7,0:5.0
10,7,0:5.0
11,7,0:5.0
12,7,0:5.0
13,7,0:5.0
14,7,0:86.1
-16,8,0:86.3
-15,8,0:5.0
-14,8,0:5.0
-13,8,0:5.0
-12,8,0:5.0
-11,8,0:5.0
-10,8,0:5.0
-9,8,0:5.0
-8,8,0:5.0
-7,8,0:5.0
-6,8,0:35.15
-5,8,0:35.15
-4,8,0:5.0
-3,8,0:35.14
-2,8,0:35.14
-1,8,0:5.0
0,8,0:5.0
1,8,0:5.0
2,8,0:5.0
3,8,0:35.14
4,8,0:35.14
5,8,0:5.0
6,8,0:35.15
7,8,0:35.15
8,8,0:5.0
9,8,0:5.0
10,8,0:5.0
11,8,0:5.0
12,8,0:5.0
13,8,0:5.0
14,8,0:86.1
-16,9,0:86.3
-15,9,0:5.0
-14,9,0:5.0
-13,9,0:5.0
-12,9,0:5.0
-11,9,0:5.0
-10,9,0:5.0
-9,9,0:5.0
-8,9,0:5.0
-7,9,0:5.0
-6,9,0:5.0
-5,9,0:35.15
-4,9,0:35.15
-3,9,0:5.0
-2,9,0:35.14
-1,9,0:35.14
0,9,0:35.14
1,9,0:35.14
2,9,0:35.14
3,9,0:35.14
4,9,0:5.0
5,9,0:35.15
6,9,0:35.15
7,9,0:5.0
8,9,0:5.0
9,9,0:5.0
10,9,0:5.0
11,9,0:5.0
12,9,0:5.0
13,9,0:5.0
14,9,0:86.1
-15,10,0:86.3
-14,10,0:5.0
-13,10,0:5.0
-12,10,0:5.0
-11,10,0:5.0
-10,10,0:5.0
-9,10,0:5.0
-8,10,0:5.0
-7,10,0:5.0
-6,10,0:5.0
-5,10,0:5.0
-4,10,0:35.15
-3,10,0:35.15
-2,10,0:5.0
-1,10,0:5.0
0,10,0:5.0
1,10,0:5.0
2,10,0:5.0
3,10,0:5.0
4,10,0:35.15
5,10,0:35.15
6,10,0:5.0
7,10,0:5.0
8,10,0:5.0
9,10,0:5.0
10,10,0:5.0
11,10,0:5.0
12,10,0:5.0
13,10,0:86.1
-15,11,0:86.3
-14,11,0:5.0
-13,11,0:5.0
-12,11,0:5.0
-11,11,0:5.0
-10,11,0:5.0
-9,11,0:5.0
-8,11,0:5.0
-7,11,0:5.0
-6,11,0:5.0
-5,11,0:5.0
-4,11,0:5.0
-3,11,0:35.15
-2,11,0:35.15
-1,11,0:35.15
0,11,0:35.15
1,11,0:35.15
2,11,0:35.15
3,11,0:35.15
4,11,0:35.15
5,11,0:5.0
6,11,0:5.0
7,11,0:5.0
8,11,0:5.0
9,11,0:5.0
10,11,0:5.0
11,11,0:5.0
12,11,0:5.0
13,11,0:86.1
-14,12,0:86.3
-13,12,0:5.0
-12,12,0:5.0
-11,12,0:5.0
-10,12,0:5.0
-9,12,0:5.0
-8,12,0:5.0
-7,12,0:5.0
-6,12,0:5.0
-5,12,0:5.0
-4,12,0:5.0
-3,12,0:5.0
-2,12,0:5.0
-1,12,0:5.0
0,12,0:5.0
1,12,0:5.0
2,12,0:5.0
3,12,0:5.0
4,12,0:5.0
5,12,0:5.0
6,12,0:5.0
7,12,0:5.0
8,12,0:5.0
9,12,0:5.0
10,12,0:5.0
11,12,0:5.0
12,12,0:86.1
-13,13,0:86.3
-12,13,0:5.0
-11,13,0:5.0
-10,13,0:5.0
-9,13,0:5.0
-8,13,0:5.0
-7,13,0:5.0
-6,13,0:5.0
-5,13,0:5.0
-4,13,0:5.0
-3,13,0:5.0
-2,13,0:5.0
-1,13,0:5.0
0,13,0:5.0
1,13,0:5.0
2,13,0:5.0
3,13,0:5.0
4,13,0:5.0
5,13,0:5.0
6,13,0:5.0
7,13,0:5.0
8,13,0:5.0
9,13,0:5.0
10,13,0:5.0
11,13,0:86.2
-12,14,0:86.2
-11,14,0:86.2
-10,14,0:5.0
-9,14,0:5.0
-8,14,0:5.0
-7,14,0:5.0
-6,14,0:5.0
-5,14,0:5.0
-4,14,0:5.0
-3,14,0:5.0
-2,14,0:5.0
-1,14,0:5.0
0,14,0:5.0
1,14,0:5.0
2,14,0:5.0
3,14,0:5.0
4,14,0:5.0
5,14,0:5.0
6,14,0:5.0
7,14,0:5.0
8,14,0:5.0
9,14,0:86.2
10,14,0:86.2
-10,15,0:86.2
-9,15,0:86.2
-8,15,0:86.2
-7,15,0:5.0
-6,15,0:5.0
-5,15,0:5.0
-4,15,0:5.0
-3,15,0:5.0
-2,15,0:5.0
-1,15,0:5.0
0,15,0:5.0
1,15,0:5.0
2,15,0:5.0
3,15,0:5.0
4,15,0:5.0
5,15,0:5.0
6,15,0:86.2
7,15,0:86.2
8,15,0:86.2
-7,16,0:86.2
-6,16,0:86.2
-5,16,0:86.2
-4,16,0:86.2
-3,16,0:5.0
-2,16,0:5.0
-1,16,0:5.0
0,16,0:5.0
1,16,0:5.0
2,16,0:86.2
3,16,0:86.2
4,16,0:86.2
5,16,0:86.2
-3,17,0:86.2
-2,17,0:86.2
-1,17,0:86.2
0,17,0:86.2
1,17,0:86.2
-3,-18,1:86.0
-2,-18,1:86.0
-1,-18,1:86.0
0,-18,1:86.0
1,-18,1:86.0
-7,-17,1:86.0
-6,-17,1:86.0
-5,-17,1:86.0
-4,-17,1:86.0
2,-17,1:86.0
3,-17,1:86.0
4,-17,1:86.0
5,-17,1:86.0
-10,-16,1:86.0
-9,-16,1:86.0
-8,-16,1:86.0
-7,-16,1:5.0
-6,-16,1:5.0
6,-16,1:86.0
7,-16,1:86.0
8,-16,1:86.0
-12,-15,1:86.0
-11,-15,1:86.0
-8,-15,1:53.0
-7,-15,1:5.0
-6,-15,1:5.0
-5,-15,1:50.1
9,-15,1:86.0
10,-15,1:86.0
-13,-14,1:86.0
-8,-14,1:53.0
-7,-14,1:5.0
-6,-14,1:5.0
3,-14,1:50.5
11,-14,1:86.0
-14,-13,1:86.0
-8,-13,1:53.0
-7,-13,1:5.0
-6,-13,1:5.0
12,-13,1:86.1
-15,-12,1:86.3
-12,-12,1:50.5
-8,-12,1:53.0
-7,-12,1:5.0
-6,-12,1:5.0
13,-12,1:86.1
-16,-11,1:86.3
-8,-11,1:5.0
-7,-11,1:5.0
14,-11,1:86.1
-16,-10,1:86.3
3,-10,1:50.5
10,-10,1:50.5
14,-10,1:86.1
-17,-9,1:86.3
-3,-9,1:50.5
0,-9,1:85
1,-9,1:85
15,-9,1:86.1
-17,-8,1:86.3
0,-8,1:85
1,-8,1:85
15,-8,1:86.1
-17,-7,1:86.3
-1,-7,1:53.1
0,-7,1:85
1,-7,1:85
2,-7,1:53.0
12,-7,1:50.5
15,-7,1:86.1
-18,-6,1:86.3
-6,-6,1:50.5
0,-6,1:85
1,-6,1:85
16,-6,1:86.1
-18,-5,1:86.3
0,-5,1:85
1,-5,1:85
16,-5,1:86.1
-18,-4,1:86.3
-15,-4,1:50.5
-1,-4,1:53.1
0,-4,1:85
1,-4,1:85
2,-4,1:53.0
16,-4,1:86.1
-18,-3,1:86.3
0,-3,1:85
1,-3,1:85
16,-3,1:86.1
-19,-2,1:86.3
-2,-2,1:53.3
0,-2,1:85
1,-2,1:85
3,-2,1:53.3
10,-2,1:50.5
15,-2,1:50.5
17,-2,1:86.1
-19,-1,1:86.3
-6,-1,1:68.2
-3,-1,1:85
-2,-1,1:85
-1,-1,1:85
0,-1,1:85
1,-1,1:85
2,-1,1:85
3,-1,1:85
4,-1,1:85
7,-1,1:68.2
17,-1,1:86.1
-6,0,1:53.1
-5,0,1:85
-4,0,1:85
-3,0,1:85
-2,0,1:85
-1,0,1:85
0,0,1:3
1,0,1:3
2,0,1:85
3,0,1:85
4,0,1:85
5,0,1:85
6,0,1:85
7,0,1:53.0
17,0,1:86.1
-19,1,1:86.3
-6,1,1:68.3
-3,1,1:85
-2,1,1:85
-1,1,1:85
0,1,1:85
1,1,1:85
2,1,1:85
3,1,1:85
4,1,1:85
7,1,1:68.3
17,1,1:86.1
-19,2,1:86.3
-2,2,1:53.2
0,2,1:85
1,2,1:85
3,2,1:53.2
17,2,1:86.1
-18,3,1:86.3
0,3,1:85
1,3,1:85
16,3,1:86.1
-18,4,1:86.3
-1,4,1:53.1
0,4,1:85
1,4,1:85
2,4,1:53.0
16,4,1:86.1
-18,5,1:86.3
0,5,1:85
1,5,1:85
12,5,1:50.5
16,5,1:86.1
-18,6,1:86.3
-14,6,1:50.5
0,6,1:85
1,6,1:85
16,6,1:86.1
-17,7,1:86.3
-5,7,1:50.5
-1,7,1:53.1
0,7,1:85
1,7,1:85
2,7,1:53.0
15,7,1:86.1
-17,8,1:86.3
0,8,1:85
1,8,1:85
15,8,1:86.1
-17,9,1:86.3
0,9,1:85
1,9,1:85
15,9,1:86.1
-16,10,1:86.3
0,10,1:50.5
10,10,1:50.5
14,10,1:86.1
-16,11,1:86.3
-13,11,1:50.5
-8,11,1:5.0
-7,11,1:5.0
14,11,1:86.1
-15,12,1:86.2
-8,12,1:53.0
-7,12,1:5.0
-6,12,1:5.0
6,12,1:50.5
13,12,1:86.1
-14,13,1:86.2
-8,13,1:53.0
-7,13,1:5.0
-6,13,1:5.0
12,13,1:86.1
-13,14,1:86.2
-8,14,1:53.0
-7,14,1:5.0
-6,14,1:5.0
3,14,1:50.5
11,14,1:86.1
-12,15,1:86.2
-11,15,1:86.2
-8,15,1:53.0
-7,15,1:5.0
-6,15,1:5.0
-4,15,1:50.5
9,15,1:86.2
10,15,1:86.2
-10,16,1:86.2
-9,16,1:86.2
-8,16,1:86.2
-7,16,1:5.0
-6,16,1:5.0
6,16,1:86.2
7,16,1:86.2
8,16,1:86.2
-7,17,1:86.2
-6,17,1:86.2
-5,17,1:86.2
-4,17,1:86.2
2,17,1:86.2
3,17,1:86.2
4,17,1:86.2
5,17,1:86.2
-3,18,1:86.2
-2,18,1:86.2
-1,18,1:86.2
0,18,1:86.2
1,18,1:86.2
-3,-19,2:86.0
-2,-19,2:86.0
-1,-19,2:86.0
0,-19,2:86.0
1,-19,2:86.0
-7,-18,2:86.0
-6,-18,2:86.0
-5,-18,2:86.0
-4,-18,2:86.0
2,-18,2:86.0
3,-18,2:86.0
4,-18,2:86.0
5,-18,2:86.0
-10,-17,2:86.0
-9,-17,2:86.0
-8,-17,2:86.0
-6,-17,2:53.0
-5,-17,2:5.0
-4,-17,2:5.0
6,-17,2:86.0
7,-17,2:86.0
8,-17,2:86.0
-12,-16,2:86.0
-11,-16,2:86.0
-6,-16,2:53.0
-5,-16,2:5.0
-4,-16,2:5.0
9,-16,2:86.0
10,-16,2:86.0
-13,-15,2:86.0
-6,-15,2:53.0
-5,-15,2:5.0
-4,-15,2:5.0
11,-15,2:86.0
-14,-14,2:86.0
-6,-14,2:53.0
-5,-14,2:5.0
-4,-14,2:5.0
12,-14,2:86.0
-15,-13,2:86.0
-6,-13,2:53.0
-5,-13,2:5.0
-4,-13,2:5.0
13,-13,2:86.0
-16,-12,2:86.0
-7,-12,2:85
-6,-12,2:5.0
-5,-12,2:5.0
14,-12,2:86.1
-17,-11,2:86.3
-8,-11,2:85
-7,-11,2:85
15,-11,2:86.1
-17,-10,2:86.3
15,-10,2:86.1
-18,-9,2:86.3
0,-9,2:85
1,-9,2:85
16,-9,2:86.1
-18,-8,2:86.3
0,-8,2:72
1,-8,2:72
16,-8,2:86.1
-18,-7,2:86.3
0,-7,2:72
1,-7,2:72
16,-7,2:86.1
-19,-6,2:86.3
0,-6,2:72
1,-6,2:72
17,-6,2:86.1
-19,-5,2:86.3
0,-5,2:72
1,-5,2:72
17,-5,2:86.1
-19,-4,2:86.3
0,-4,2:72
1,-4,2:72
17,-4,2:86.1
-19,-3,2:86.3
0,-3,2:72
1,-3,2:72
17,-3,2:86.1
-20,-2,2:86.3
0,-2,2:72
1,-2,2:72
18,-2,2:86.1
-20,-1,2:86.3
-3,-1,2:72
-2,-1,2:72
-1,-1,2:72
0,-1,2:72
1,-1,2:72
2,-1,2:72
3,-1,2:72
4,-1,2:72
18,-1,2:86.1
-20,0,2:86.3
-5,0,2:72
-4,0,2:72
-3,0,2:85
-2,0,2:72
-1,0,2:72
0,0,2:37
1,0,2:37
2,0,2:72
3,0,2:72
4,0,2:85
5,0,2:72
6,0,2:72
18,0,2:86.1
-20,1,2:86.3
-3,1,2:72
-2,1,2:72
-1,1,2:72
0,1,2:72
1,1,2:72
2,1,2:72
3,1,2:72
4,1,2:72
18,1,2:86.1
-20,2,2:86.3
0,2,2:72
1,2,2:72
18,2,2:86.1
-19,3,2:86.3
0,3,2:72
1,3,2:72
17,3,2:86.1
-19,4,2:86.3
0,4,2:72
1,4,2:72
17,4,2:86.1
-19,5,2:86.3
0,5,2:72
1,5,2:72
17,5,2:86.1
-19,6,2:86.3
0,6,2:72
1,6,2:72
17,6,2:86.1
-18,7,2:86.3
0,7,2:72
1,7,2:72
16,7,2:86.1
-18,8,2:86.3
0,8,2:72
1,8,2:72
16,8,2:86.1
-18,9,2:86.3
0,9,2:85
1,9,2:85
16,9,2:86.1
-17,10,2:86.3
15,10,2:86.1
-17,11,2:86.3
-8,11,2:85
-7,11,2:85
15,11,2:86.1
-16,12,2:86.2
-7,12,2:85
-6,12,2:5.0
-5,12,2:5.0
14,12,2:86.1
-15,13,2:86.2
-6,13,2:53.0
-5,13,2:5.0
-4,13,2:5.0
13,13,2:86.1
-14,14,2:86.2
-6,14,2:53.0
-5,14,2:5.0
-4,14,2:5.0
12,14,2:86.2
-13,15,2:86.2
-6,15,2:53.0
-5,15,2:5.0
-4,15,2:5.0
11,15,2:86.2
-12,16,2:86.2
-11,16,2:86.2
-6,16,2:53.0
-5,16,2:5.0
-4,16,2:5.0
9,16,2:86.2
10,16,2:86.2
-10,17,2:86.2
-9,17,2:86.2
-8,17,2:86.2
-6,17,2:53.0
-5,17,2:5.0
-4,17,2:5.0
6,17,2:86.2
7,17,2:86.2
8,17,2:86.2
-7,18,2:86.2
-6,18,2:86.2
-5,18,2:86.2
-4,18,2:86.2
2,18,2:86.2
3,18,2:86.2
4,18,2:86.2
5,18,2:86.2
-3,19,2:86.2
-2,19,2:86.2
-1,19,2:86.2
0,19,2:86.2
1,19,2:86.2
-3,-19,3:86.0
-2,-19,3:86.0
-1,-19,3:86.0
0,-19,3:86.0
1,-19,3:86.0
-7,-18,3:86.0
-6,-18,3:86.0
-5,-18,3:86.0
-4,-18,3:86.0
-3,-18,3:5.0
-2,-18,3:5.0
2,-18,3:86.0
3,-18,3:86.0
4,-18,3:86.0
5,-18,3:86.0
-10,-17,3:86.0
-9,-17,3:86.0
-8,-17,3:86.0
-4,-17,3:53.0
-3,-17,3:5.0
-2,-17,3:5.0
5,-17,3:50.2
6,-17,3:86.0
7,-17,3:86.0
8,-17,3:86.0
-12,-16,3:86.0
-11,-16,3:86.0
-4,-16,3:53.0
-3,-16,3:5.0
-2,-16,3:5.0
9,-16,3:86.0
10,-16,3:86.1
-13,-15,3:86.0
-4,-15,3:53.0
-3,-15,3:5.0
-2,-15,3:5.0
11,-15,3:86.0
-14,-14,3:86.0
-4,-14,3:53.0
-3,-14,3:5.0
-2,-14,3:5.0
12,-14,3:86.0
-15,-13,3:86.0
-5,-13,3:85
-4,-13,3:5.0
-3,-13,3:5.0
13,-13,3:86.0
-16,-12,3:86.0
-7,-12,3:85
-6,-12,3:85
-5,-12,3:85
14,-12,3:86.1
-17,-11,3:86.3
-8,-11,3:50.5
15,-11,3:86.1
-17,-10,3:86.3
15,-10,3:86.1
-18,-9,3:86.3
0,-9,3:85
1,-9,3:85
16,-9,3:86.1
-18,-8,3:86.3
15,-8,3:50.2
16,-8,3:86.1
-18,-7,3:86.3
16,-7,3:86.1
-19,-6,3:86.3
17,-6,3:86.1
-19,-5,3:86.3
17,-5,3:86.1
-19,-4,3:86.3
17,-4,3:86.1
-19,-3,3:86.3
17,-3,3:86.1
-20,-2,3:86.3
18,-2,3:86.1
-20,-1,3:86.3
18,-1,3:86.1
-20,0,3:86.3
-3,0,3:85
4,0,3:85
18,0,3:86.1
-20,1,3:86.3
18,1,3:86.1
-20,2,3:86.3
18,2,3:86.1
-19,3,3:86.3
17,3,3:86.1
-19,4,3:86.3
17,4,3:86.1
-19,5,3:86.3
17,5,3:86.1
-19,6,3:86.2
17,6,3:86.1
-18,7,3:86.3
16,7,3:86.1
-18,8,3:86.3
16,8,3:86.1
-18,9,3:86.3
0,9,3:85
1,9,3:85
16,9,3:86.1
-17,10,3:86.3
15,10,3:86.1
-17,11,3:86.3
-7,11,3:50.5
15,11,3:86.1
-16,12,3:86.3
-7,12,3:85
-6,12,3:85
-5,12,3:85
14,12,3:86.1
-15,13,3:86.3
-5,13,3:85
-4,13,3:5.0
-3,13,3:5.0
13,13,3:86.1
-14,14,3:86.3
-4,14,3:53.0
-3,14,3:5.0
-2,14,3:5.0
12,14,3:86.2
-13,15,3:86.2
-4,15,3:53.0
-3,15,3:5.0
-2,15,3:5.0
11,15,3:86.2
-12,16,3:86.2
-11,16,3:86.3
-4,16,3:53.0
-3,16,3:5.0
-2,16,3:5.0
9,16,3:86.2
10,16,3:86.2
-10,17,3:86.2
-9,17,3:86.2
-8,17,3:86.2
-4,17,3:53.0
-3,17,3:5.0
-2,17,3:5.0
6,17,3:86.2
7,17,3:86.2
8,17,3:86.2
-7,18,3:86.2
-6,18,3:86.2
-5,18,3:86.2
-4,18,3:86.2
-3,18,3:5.0
-2,18,3:5.0
2,18,3:86.2
3,18,3:86.2
4,18,3:86.2
5,18,3:86.2
-3,19,3:86.2
-2,19,3:86.2
-1,19,3:86.2
0,19,3:86.2
1,19,3:86.2
-3,-20,4:86.0
-2,-20,4:86.0
-1,-20,4:86.0
0,-20,4:86.0
1,-20,4:86.0
-7,-19,4:86.0
-6,-19,4:86.0
-5,-19,4:86.0
-4,-19,4:86.0
-2,-19,4:53.0
-1,-19,4:5.0
0,-19,4:5.0
2,-19,4:86.0
3,-19,4:86.0
4,-19,4:86.0
5,-19,4:86.0
-10,-18,4:86.0
-9,-18,4:86.0
-8,-18,4:86.0
-2,-18,4:53.0
-1,-18,4:5.0
0,-18,4:5.0
6,-18,4:86.0
7,-18,4:86.0
8,-18,4:86.0
-12,-17,4:86.0
-11,-17,4:86.0
-2,-17,4:53.0
-1,-17,4:5.0
0,-17,4:5.0
9,-17,4:86.0
10,-17,4:86.0
-13,-16,4:86.0
-2,-16,4:53.0
-1,-16,4:5.0
0,-16,4:5.0
11,-16,4:86.0
-14,-15,4:86.0
-2,-15,4:53.0
-1,-15,4:5.0
0,-15,4:5.0
12,-15,4:86.0
-15,-14,4:86.0
-3,-14,4:85
-2,-14,4:5.0
-1,-14,4:5.0
13,-14,4:86.0
-16,-13,4:86.0
-5,-13,4:85
-4,-13,4:85
-3,-13,4:85
14,-13,4:86.0
-17,-12,4:86.3
-6,-12,4:50.5
15,-12,4:86.1
-18,-11,4:86.3
16,-11,4:86.1
-18,-10,4:86.3
16,-10,4:86.1
-19,-9,4:86.3
0,-9,4:50.5
17,-9,4:86.1
-19,-8,4:86.3
17,-8,4:86.1
-19,-7,4:86.3
17,-7,4:86.1
-20,-6,4:86.3
18,-6,4:86.1
-20,-5,4:86.3
18,-5,4:86.1
-20,-4,4:86.3
18,-4,4:86.1
-20,-3,4:86.3
18,-3,4:86.1
-21,-2,4:86.3
19,-2,4:86.1
-21,-1,4:86.3
19,-1,4:86.1
-21,0,4:86.3
-3,0,4:50.5
4,0,4:50.5
19,0,4:86.1
-21,1,4:86.3
19,1,4:86.1
-21,2,4:86.3
19,2,4:86.1
-20,3,4:86.3
18,3,4:86.1
-20,4,4:86.3
18,4,4:86.1
-20,5,4:86.3
18,5,4:86.1
-20,6,4:86.3
18,6,4:86.1
-19,7,4:86.3
17,7,4:86.1
-19,8,4:86.3
17,8,4:86.1
-19,9,4:86.3
0,9,4:50.5
16,9,4:50.2
17,9,4:86.1
-18,10,4:86.3
16,10,4:86.1
-18,11,4:86.3
16,11,4:86.1
-17,12,4:86.3
-6,12,4:50.5
15,12,4:86.2
-16,13,4:86.2
-5,13,4:85
-4,13,4:85
-3,13,4:85
14,13,4:86.2
-15,14,4:86.3
-3,14,4:85
-2,14,4:5.0
-1,14,4:5.0
13,14,4:86.2
-14,15,4:86.3
-2,15,4:53.0
-1,15,4:5.0
0,15,4:5.0
12,15,4:86.2
-13,16,4:86.3
-2,16,4:53.0
-1,16,4:5.0
0,16,4:5.0
9,16,4:50.4
11,16,4:86.2
-12,17,4:86.2
-11,17,4:86.2
-2,17,4:53.0
-1,17,4:5.0
0,17,4:5.0
9,17,4:86.2
10,17,4:86.2
-10,18,4:86.2
-9,18,4:86.2
-8,18,4:86.2
-2,18,4:53.0
-1,18,4:5.0
0,18,4:5.0
6,18,4:86.2
7,18,4:86.2
8,18,4:86.2
-7,19,4:86.2
-6,19,4:86.2
-5,19,4:86.2
-4,19,4:86.2
-2,19,4:53.0
-1,19,4:5.0
0,19,4:5.0
2,19,4:86.2
3,19,4:86.2
4,19,4:86.2
5,19,4:86.2
-3,20,4:86.2
-2,20,4:86.2
-1,20,4:86.2
0,20,4:86.2
1,20,4:86.2
-3,-20,5:86.0
-2,-20,5:86.0
-1,-20,5:86.0
0,-20,5:86.0
1,-20,5:86.0
-7,-19,5:86.0
-6,-19,5:86.0
-5,-19,5:86.0
-4,-19,5:86.0
-1,-19,5:50.3
0,-19,5:53.0
1,-19,5:5.0
2,-19,5:86.0
3,-19,5:86.0
4,-19,5:86.0
5,-19,5:86.0
-10,-18,5:86.0
-9,-18,5:86.0
-8,-18,5:86.0
0,-18,5:53.0
1,-18,5:5.0
2,-18,5:5.0
3,-18,5:5.0
4,-18,5:5.0
5,-18,5:5.0
6,-18,5:86.0
7,-18,5:86.0
8,-18,5:86.0
-12,-17,5:86.0
-11,-17,5:86.0
-10,-17,5:50.1
0,-17,5:53.0
1,-17,5:5.0
2,-17,5:5.0
3,-17,5:5.0
4,-17,5:5.0
5,-17,5:5.0
6,-17,5:5.0
7,-17,5:5.0
8,-17,5:5.0
9,-17,5:86.0
10,-17,5:86.0
-13,-16,5:86.0
0,-16,5:53.0
1,-16,5:5.0
2,-16,5:5.0
3,-16,5:5.0
4,-16,5:5.0
5,-16,5:5.0
6,-16,5:5.0
7,-16,5:5.0
8,-16,5:5.0
9,-16,5:5.0
10,-16,5:5.0
11,-16,5:86.0
-14,-15,5:86.0
-13,-15,5:50.1
-1,-15,5:85
0,-15,5:5.0
1,-15,5:5.0
2,-15,5:5.0
3,-15,5:5.0
4,-15,5:5.0
5,-15,5:5.0
6,-15,5:5.0
7,-15,5:5.0
8,-15,5:5.0
9,-15,5:5.0
10,-15,5:5.0
11,-15,5:5.0
12,-15,5:86.1
-15,-14,5:86.0
-3,-14,5:85
-2,-14,5:85
-1,-14,5:85
2,-14,5:5.0
3,-14,5:5.0
4,-14,5:5.0
5,-14,5:5.0
6,-14,5:5.0
7,-14,5:5.0
8,-14,5:5.0
9,-14,5:5.0
10,-14,5:5.0
11,-14,5:5.0
12,-14,5:5.0
13,-14,5:86.1
-16,-13,5:86.3
-4,-13,5:50.5
3,-13,5:5.0
4,-13,5:5.0
5,-13,5:5.0
6,-13,5:5.0
7,-13,5:5.0
8,-13,5:5.0
9,-13,5:5.0
10,-13,5:5.0
11,-13,5:5.0
12,-13,5:5.0
13,-13,5:5.0
14,-13,5:86.1
-17,-12,5:86.3
-16,-12,5:50.1
4,-12,5:5.0
5,-12,5:5.0
6,-12,5:5.0
7,-12,5:5.0
8,-12,5:5.0
9,-12,5:5.0
10,-12,5:5.0
11,-12,5:5.0
12,-12,5:5.0
13,-12,5:5.0
14,-12,5:5.0
15,-12,5:86.0
-18,-11,5:86.3
5,-11,5:5.0
6,-11,5:5.0
7,-11,5:5.0
8,-11,5:5.0
9,-11,5:5.0
10,-11,5:5.0
11,-11,5:5.0
12,-11,5:5.0
13,-11,5:5.0
14,-11,5:5.0
15,-11,5:5.0
16,-11,5:86.1
-18,-10,5:86.3
5,-10,5:5.0
6,-10,5:5.0
7,-10,5:5.0
8,-10,5:5.0
9,-10,5:5.0
10,-10,5:5.0
11,-10,5:5.0
12,-10,5:5.0
13,-10,5:5.0
14,-10,5:5.0
15,-10,5:5.0
16,-10,5:86.1
-19,-9,5:86.3
5,-9,5:5.0
6,-9,5:5.0
7,-9,5:5.0
8,-9,5:5.0
9,-9,5:5.0
10,-9,5:5.0
11,-9,5:5.0
12,-9,5:5.0
13,-9,5:5.0
14,-9,5:5.0
15,-9,5:5.0
16,-9,5:5.0
17,-9,5:86.1
-19,-8,5:86.3
-18,-8,5:50.1
5,-8,5:5.0
6,-8,5:5.0
7,-8,5:5.0
8,-8,5:5.0
9,-8,5:5.0
10,-8,5:5.0
11,-8,5:5.0
12,-8,5:5.0
13,-8,5:5.0
14,-8,5:5.0
15,-8,5:5.0
16,-8,5:5.0
17,-8,5:86.1
-19,-7,5:86.3
5,-7,5:5.0
6,-7,5:5.0
7,-7,5:5.0
8,-7,5:5.0
9,-7,5:5.0
10,-7,5:5.0
11,-7,5:5.0
12,-7,5:5.0
13,-7,5:5.0
14,-7,5:5.0
15,-7,5:5.0
16,-7,5:5.0
17,-7,5:86.1
-20,-6,5:86.3
5,-6,5:5.0
6,-6,5:5.0
7,-6,5:5.0
8,-6,5:5.0
9,-6,5:5.0
10,-6,5:5.0
11,-6,5:5.0
12,-6,5:5.0
13,-6,5:5.0
14,-6,5:5.0
15,-6,5:5.0
16,-6,5:5.0
17,-6,5:5.0
18,-6,5:86.1
-20,-5,5:86.3
5,-5,5:5.0
6,-5,5:5.0
7,-5,5:5.0
8,-5,5:5.0
9,-5,5:5.0
10,-5,5:5.0
11,-5,5:5.0
12,-5,5:5.0
13,-5,5:5.0
14,-5,5:5.0
15,-5,5:5.0
16,-5,5:5.0
17,-5,5:5.0
18,-5,5:86.1
-20,-4,5:86.3
5,-4,5:5.0
6,-4,5:5.0
7,-4,5:5.0
8,-4,5:5.0
9,-4,5:5.0
10,-4,5:5.0
11,-4,5:5.0
12,-4,5:5.0
13,-4,5:5.0
14,-4,5:5.0
15,-4,5:5.0
16,-4,5:5.0
17,-4,5:5.0
18,-4,5:86.1
-20,-3,5:86.3
5,-3,5:5.0
6,-3,5:5.0
7,-3,5:5.0
8,-3,5:5.0
9,-3,5:5.0
10,-3,5:5.0
11,-3,5:5.0
12,-3,5:5.0
13,-3,5:5.0
14,-3,5:5.0
15,-3,5:5.0
16,-3,5:5.0
17,-3,5:5.0
18,-3,5:86.1
-21,-2,5:86.3
-20,-2,5:50.1
5,-2,5:5.0
6,-2,5:5.0
7,-2,5:5.0
8,-2,5:5.0
9,-2,5:5.0
10,-2,5:5.0
11,-2,5:5.0
12,-2,5:5.0
13,-2,5:5.0
14,-2,5:5.0
15,-2,5:5.0
16,-2,5:5.0
17,-2,5:5.0
18,-2,5:5.0
19,-2,5:86.1
-21,-1,5:86.3
5,-1,5:5.0
6,-1,5:5.0
7,-1,5:5.0
8,-1,5:5.0
9,-1,5:5.0
10,-1,5:5.0
11,-1,5:5.0
12,-1,5:5.0
13,-1,5:5.0
14,-1,5:5.0
15,-1,5:5.0
16,-1,5:5.0
17,-1,5:5.0
18,-1,5:5.0
19,-1,5:86.1
-21,0,5:86.3
5,0,5:5.0
6,0,5:5.0
7,0,5:5.0
8,0,5:5.0
9,0,5:5.0
10,0,5:5.0
11,0,5:5.0
12,0,5:5.0
13,0,5:5.0
14,0,5:5.0
15,0,5:5.0
16,0,5:5.0
17,0,5:5.0
18,0,5:5.0
19,0,5:86.1
-21,1,5:86.3
5,1,5:5.0
6,1,5:5.0
7,1,5:5.0
8,1,5:5.0
9,1,5:5.0
10,1,5:5.0
11,1,5:5.0
12,1,5:5.0
13,1,5:5.0
14,1,5:5.0
15,1,5:5.0
16,1,5:5.0
17,1,5:5.0
18,1,5:5.0
19,1,5:86.1
-21,2,5:86.3
5,2,5:5.0
6,2,5:5.0
7,2,5:5.0
8,2,5:5.0
9,2,5:5.0
10,2,5:5.0
11,2,5:5.0
12,2,5:5.0
13,2,5:5.0
14,2,5:5.0
15,2,5:5.0
16,2,5:5.0
17,2,5:5.0
18,2,5:5.0
19,2,5:86.1
-20,3,5:86.3
-19,3,5:50.1
5,3,5:5.0
6,3,5:5.0
7,3,5:5.0
8,3,5:5.0
9,3,5:5.0
10,3,5:5.0
11,3,5:5.0
12,3,5:5.0
13,3,5:5.0
14,3,5:5.0
15,3,5:5.0
16,3,5:5.0
17,3,5:5.0
18,3,5:86.1
-20,4,5:86.3
5,4,5:5.0
6,4,5:5.0
7,4,5:5.0
8,4,5:5.0
9,4,5:5.0
10,4,5:5.0
11,4,5:5.0
12,4,5:5.0
13,4,5:5.0
14,4,5:5.0
15,4,5:5.0
16,4,5:5.0
17,4,5:5.0
18,4,5:86.1
-20,5,5:86.3
5,5,5:5.0
6,5,5:5.0
7,5,5:5.0
8,5,5:5.0
9,5,5:5.0
10,5,5:5.0
11,5,5:5.0
12,5,5:5.0
13,5,5:5.0
14,5,5:5.0
15,5,5:5.0
16,5,5:5.0
17,5,5:5.0
18,5,5:86.1
-20,6,5:86.3
5,6,5:5.0
6,6,5:5.0
7,6,5:5.0
8,6,5:5.0
9,6,5:5.0
10,6,5:5.0
11,6,5:5.0
12,6,5:5.0
13,6,5:5.0
14,6,5:5.0
15,6,5:5.0
16,6,5:5.0
17,6,5:5.0
18,6,5:86.1
-19,7,5:86.3
5,7,5:5.0
6,7,5:5.0
7,7,5:5.0
8,7,5:5.0
9,7,5:5.0
10,7,5:5.0
11,7,5:5.0
12,7,5:5.0
13,7,5:5.0
14,7,5:5.0
15,7,5:5.0
16,7,5:5.0
17,7,5:86.1
-19,8,5:86.3
-18,8,5:50.1
5,8,5:5.0
6,8,5:5.0
7,8,5:5.0
8,8,5:5.0
9,8,5:5.0
10,8,5:5.0
11,8,5:5.0
12,8,5:5.0
13,8,5:5.0
14,8,5:5.0
15,8,5:5.0
16,8,5:5.0
17,8,5:86.1
-19,9,5:86.3
5,9,5:5.0
6,9,5:5.0
7,9,5:5.0
8,9,5:5.0
9,9,5:5.0
10,9,5:5.0
11,9,5:5.0
12,9,5:5.0
13,9,5:5.0
14,9,5:5.0
15,9,5:5.0
16,9,5:5.0
17,9,5:86.1
-18,10,5:86.3
5,10,5:5.0
6,10,5:5.0
7,10,5:5.0
8,10,5:5.0
9,10,5:5.0
10,10,5:5.0
11,10,5:5.0
12,10,5:5.0
13,10,5:5.0
14,10,5:5.0
15,10,5:5.0
16,10,5:86.1
-18,11,5:86.3
4,11,5:5.0
5,11,5:5.0
6,11,5:5.0
7,11,5:5.0
8,11,5:5.0
9,11,5:5.0
10,11,5:5.0
11,11,5:5.0
12,11,5:5.0
13,11,5:5.0
14,11,5:5.0
15,11,5:5.0
16,11,5:86.1
-17,12,5:86.3
-16,12,5:50.1
3,12,5:5.0
4,12,5:5.0
5,12,5:5.0
6,12,5:5.0
7,12,5:5.0
8,12,5:5.0
9,12,5:5.0
10,12,5:5.0
11,12,5:5.0
12,12,5:5.0
13,12,5:5.0
14,12,5:5.0
15,12,5:86.1
-16,13,5:86.3
-4,13,5:50.5
2,13,5:5.0
3,13,5:5.0
4,13,5:5.0
5,13,5:5.0
6,13,5:5.0
7,13,5:5.0
8,13,5:5.0
9,13,5:5.0
10,13,5:5.0
11,13,5:5.0
12,13,5:5.0
13,13,5:5.0
14,13,5:86.2
-15,14,5:86.3
-3,14,5:85
-2,14,5:85
-1,14,5:85
1,14,5:5.0
2,14,5:5.0
3,14,5:5.0
4,14,5:5.0
5,14,5:5.0
6,14,5:5.0
7,14,5:5.0
8,14,5:5.0
9,14,5:5.0
10,14,5:5.0
11,14,5:5.0
12,14,5:5.0
13,14,5:86.2
-14,15,5:86.3
-13,15,5:50.1
-1,15,5:85
0,15,5:5.0
1,15,5:5.0
2,15,5:5.0
3,15,5:5.0
4,15,5:5.0
5,15,5:5.0
6,15,5:5.0
7,15,5:5.0
8,15,5:5.0
9,15,5:5.0
10,15,5:5.0
11,15,5:5.0
12,15,5:86.2
-13,16,5:86.3
0,16,5:53.0
1,16,5:5.0
2,16,5:5.0
3,16,5:5.0
4,16,5:5.0
5,16,5:5.0
6,16,5:5.0
7,16,5:5.0
8,16,5:5.0
9,16,5:5.0
10,16,5:5.0
11,16,5:86.2
-12,17,5:86.2
-11,17,5:86.3
-10,17,5:50.1
0,17,5:53.0
1,17,5:5.0
2,17,5:5.0
3,17,5:5.0
4,17,5:5.0
5,17,5:5.0
6,17,5:5.0
7,17,5:5.0
8,17,5:5.0
9,17,5:86.2
10,17,5:86.2
-10,18,5:86.2
-9,18,5:86.2
-8,18,5:86.2
-6,18,5:50.4
0,18,5:53.0
1,18,5:5.0
2,18,5:5.0
3,18,5:5.0
4,18,5:5.0
5,18,5:5.0
6,18,5:86.2
7,18,5:86.2
8,18,5:86.2
-7,19,5:86.2
-6,19,5:86.2
-5,19,5:86.2
-4,19,5:86.3
0,19,5:53.0
1,19,5:5.0
2,19,5:86.2
3,19,5:86.2
4,19,5:86.2
5,19,5:86.2
-3,20,5:86.2
-2,20,5:86.2
-1,20,5:86.2
0,20,5:86.2
1,20,5:86.2
-3,-20,6:86.0
-2,-20,6:86.0
-1,-20,6:86.0
0,-20,6:86.0
1,-20,6:86.0
-7,-19,6:86.0
-6,-19,6:86.0
-5,-19,6:86.0
-4,-19,6:86.0
2,-19,6:86.0
3,-19,6:86.0
4,-19,6:86.0
5,-19,6:86.0
-10,-18,6:86.0
-9,-18,6:86.0
-8,-18,6:86.0
6,-18,6:86.0
7,-18,6:86.0
8,-18,6:86.0
-12,-17,6:86.0
-11,-17,6:86.0
9,-17,6:86.0
10,-17,6:86.0
-13,-16,6:86.3
11,-16,6:86.0
-14,-15,6:86.3
-1,-15,6:85
0,-15,6:85
1,-15,6:85
2,-15,6:85
12,-15,6:86.0
-15,-14,6:86.3
-2,-14,6:50.5
2,-14,6:85
3,-14,6:85
13,-14,6:86.0
-16,-13,6:86.3
3,-13,6:85
4,-13,6:85
14,-13,6:86.0
-17,-12,6:86.3
4,-12,6:85
5,-12,6:85
15,-12,6:86.0
-18,-11,6:86.3
5,-11,6:85
16,-11,6:86.1
-18,-10,6:86.3
5,-10,6:85
7,-10,6:50.5
16,-10,6:86.1
-19,-9,6:86.3
5,-9,6:85
17,-9,6:86.1
-19,-8,6:86.3
5,-8,6:85
17,-8,6:86.1
-19,-7,6:86.3
5,-7,6:85
17,-7,6:86.1
-20,-6,6:86.3
5,-6,6:85
18,-6,6:86.1
-20,-5,6:86.3
5,-5,6:85
14,-5,6:50.2
15,-5,6:47
18,-5,6:86.1
-20,-4,6:86.3
5,-4,6:85
12,-4,6:118.3
15,-4,6:47
18,-4,6:86.1
-20,-3,6:86.3
5,-3,6:85
12,-3,6:5.0
15,-3,6:47
18,-3,6:86.1
-21,-2,6:86.3
-1,-2,6:85
5,-2,6:85
15,-2,6:47
19,-2,6:86.1
-21,-1,6:86.0
-2,-1,6:85
-1,-1,6:89
0,-1,6:85
5,-1,6:85
15,-1,6:47
19,-1,6:86.1
-21,0,6:86.0
-3,0,6:85
-2,0,6:89
-1,0,6:89
0,0,6:89
1,0,6:85
5,0,6:85
10,0,6:50.5
12,0,6:54.5
15,0,6:47
19,0,6:86.1
-21,1,6:86.3
-2,1,6:85
-1,1,6:89
0,1,6:85
5,1,6:85
12,1,6:54.5
15,1,6:47
16,1,6:50.1
19,1,6:86.1
-21,2,6:86.3
-1,2,6:85
5,2,6:85
15,2,6:47
19,2,6:86.1
-20,3,6:86.3
5,3,6:85
15,3,6:47
18,3,6:86.1
-20,4,6:86.3
5,4,6:85
12,4,6:5.0
15,4,6:47
18,4,6:86.1
-20,5,6:86.3
5,5,6:85
12,5,6:118.3
15,5,6:47
16,5,6:50.1
18,5,6:86.1
-20,6,6:86.3
5,6,6:85
15,6,6:47
18,6,6:86.1
-19,7,6:86.3
5,7,6:85
15,7,6:47
17,7,6:86.1
-19,8,6:86.3
5,8,6:85
10,8,6:50.5
15,8,6:47
17,8,6:86.1
-19,9,6:86.3
5,9,6:85
13,9,6:50.5
17,9,6:86.1
-18,10,6:86.3
5,10,6:85
16,10,6:86.1
-18,11,6:86.3
4,11,6:85
5,11,6:85
16,11,6:86.1
-17,12,6:86.3
3,12,6:85
4,12,6:85
15,12,6:86.1
-16,13,6:86.3
2,13,6:85
3,13,6:85
14,13,6:86.1
-15,14,6:86.3
-2,14,6:50.5
1,14,6:85
2,14,6:85
9,14,6:50.5
13,14,6:86.1
-14,15,6:86.3
-1,15,6:85
0,15,6:85
1,15,6:85
12,15,6:86.1
-13,16,6:86.3
11,16,6:86.1
-12,17,6:86.2
-11,17,6:86.2
4,17,6:50.5
9,17,6:86.2
10,17,6:86.2
-10,18,6:86.2
-9,18,6:86.2
-8,18,6:86.3
6,18,6:86.2
7,18,6:86.2
8,18,6:86.2
-7,19,6:86.3
-6,19,6:86.3
-5,19,6:86.2
-4,19,6:86.2
-1,19,6:50.4
2,19,6:86.2
3,19,6:86.2
4,19,6:86.2
5,19,6:86.2
-3,20,6:86.2
-2,20,6:86.2
-1,20,6:86.2
0,20,6:86.2
1,20,6:86.2
-3,-19,7:86.0
-2,-19,7:86.0
-1,-19,7:86.0
0,-19,7:86.0
1,-19,7:86.0
-7,-18,7:86.0
-6,-18,7:86.0
-5,-18,7:86.0
-4,-18,7:86.0
2,-18,7:86.0
3,-18,7:86.0
4,-18,7:86.0
5,-18,7:86.0
-10,-17,7:86.0
-9,-17,7:86.0
-8,-17,7:86.0
-5,-17,7:50.3
4,-17,7:50.3
6,-17,7:86.0
7,-17,7:86.0
8,-17,7:86.0
-12,-16,7:86.0
-11,-16,7:86.0
9,-16,7:86.0
10,-16,7:86.0
-13,-15,7:86.0
0,-15,7:50.5
2,-15,7:50.5
10,-15,7:50.2
11,-15,7:86.1
-14,-14,7:86.0
3,-14,7:50.5
12,-14,7:86.1
-15,-13,7:86.3
4,-13,7:50.5
13,-13,7:86.1
-16,-12,7:86.3
5,-12,7:50.5
13,-12,7:50.2
14,-12,7:86.1
-17,-11,7:86.3
15,-11,7:86.1
-17,-10,7:86.3
5,-10,7:50.5
15,-10,7:86.1
-18,-9,7:86.3
16,-9,7:86.1
-18,-8,7:86.3
16,-8,7:86.1
-18,-7,7:86.3
16,-7,7:86.1
-19,-6,7:86.3
5,-6,7:50.5
17,-6,7:86.1
-19,-5,7:86.3
17,-5,7:86.1
-19,-4,7:86.3
17,-4,7:86.1
-19,-3,7:86.3
12,-3,7:117
15,-3,7:47
17,-3,7:86.1
-20,-2,7:86.3
-1,-2,7:85
5,-2,7:50.5
15,-2,7:47
18,-2,7:86.1
-20,-1,7:86.3
-2,-1,7:85
-1,-1,7:85
0,-1,7:85
15,-1,7:47
18,-1,7:86.1
-20,0,7:86.3
-3,0,7:85
-2,0,7:85
-1,0,7:85
0,0,7:85
1,0,7:85
18,0,7:86.1
-20,1,7:86.3
-2,1,7:85
-1,1,7:85
0,1,7:85
15,1,7:47
18,1,7:86.1
-20,2,7:86.3
-1,2,7:85
5,2,7:50.5
18,2,7:86.1
-19,3,7:86.3
15,3,7:47
17,3,7:86.1
-19,4,7:86.3
12,4,7:117
17,4,7:86.1
-19,5,7:86.3
17,5,7:86.1
-19,6,7:86.3
5,6,7:50.5
15,6,7:47
17,6,7:86.1
-18,7,7:86.3
16,7,7:86.1
-18,8,7:86.3
16,8,7:86.1
-18,9,7:86.3
16,9,7:86.1
-17,10,7:86.3
5,10,7:50.5
15,10,7:86.1
-17,11,7:86.2
15,11,7:86.1
-16,12,7:86.2
4,12,7:50.5
14,12,7:86.1
-15,13,7:86.2
3,13,7:50.5
13,13,7:86.1
-14,14,7:86.2
2,14,7:50.5
12,14,7:86.2
-13,15,7:86.2
-1,15,7:50.5
1,15,7:50.5
11,15,7:86.2
-12,16,7:86.2
-11,16,7:86.2
9,16,7:86.2
10,16,7:86.2
-10,17,7:86.2
-9,17,7:86.2
-8,17,7:86.2
6,17,7:86.2
7,17,7:86.2
8,17,7:86.2
-7,18,7:86.2
-6,18,7:86.2
-5,18,7:86.2
-4,18,7:86.2
2,18,7:86.2
3,18,7:86.2
4,18,7:86.2
5,18,7:86.2
-3,19,7:86.2
-2,19,7:86.2
-1,19,7:86.2
0,19,7:86.2
1,19,7:86.2
-3,-19,8:86.0
-2,-19,8:86.0
-1,-19,8:86.0
0,-19,8:86.0
1,-19,8:86.0
-7,-18,8:86.0
-6,-18,8:86.0
-5,-18,8:86.0
-4,-18,8:86.0
2,-18,8:86.0
3,-18,8:86.0
4,-18,8:86.0
5,-18,8:86.0
-10,-17,8:86.0
-9,-17,8:86.0
-8,-17,8:86.0
6,-17,8:86.0
7,-17,8:86.0
8,-17,8:86.0
-12,-16,8:86.0
-11,-16,8:86.0
9,-16,8:86.0
10,-16,8:86.0
-13,-15,8:86.0
11,-15,8:86.0
-14,-14,8:86.3
12,-14,8:86.0
-15,-13,8:86.0
13,-13,8:86.1
-16,-12,8:86.3
14,-12,8:86.1
-17,-11,8:86.3
15,-11,8:86.1
-17,-10,8:86.3
-1,-10,8:85
15,-10,8:86.1
-18,-9,8:86.3
-2,-9,8:85
-1,-9,8:85
0,-9,8:85
16,-9,8:86.1
-18,-8,8:86.3
-1,-8,8:85
16,-8,8:86.1
-18,-7,8:86.3
16,-7,8:86.1
-19,-6,8:86.3
17,-6,8:86.1
-19,-5,8:86.3
17,-5,8:86.1
-19,-4,8:86.3
17,-4,8:86.1
-19,-3,8:86.3
15,-3,8:47
17,-3,8:86.1
-20,-2,8:86.3
18,-2,8:86.1
-20,-1,8:86.3
-10,-1,8:85
8,-1,8:85
18,-1,8:86.1
-20,0,8:86.3
-11,0,8:85
-10,0,8:85
-9,0,8:85
-1,0,8:85
7,0,8:85
8,0,8:85
9,0,8:85
18,0,8:86.1
-20,1,8:86.3
-10,1,8:85
8,1,8:85
15,1,8:47
18,1,8:86.1
-20,2,8:86.3
15,2,8:47
18,2,8:86.1
-19,3,8:86.3
15,3,8:47
17,3,8:86.1
-19,4,8:86.3
17,4,8:86.1
-19,5,8:86.3
17,5,8:86.1
-19,6,8:86.3
15,6,8:47
17,6,8:86.1
-18,7,8:86.3
16,7,8:86.1
-18,8,8:86.3
-1,8,8:85
16,8,8:86.1
-18,9,8:86.3
-2,9,8:85
-1,9,8:85
0,9,8:85
16,9,8:86.1
-17,10,8:86.3
-1,10,8:85
15,10,8:86.1
-17,11,8:86.3
15,11,8:86.1
-16,12,8:86.2
14,12,8:86.1
-15,13,8:86.2
13,13,8:86.2
-14,14,8:86.2
12,14,8:86.2
-13,15,8:86.2
11,15,8:86.2
-12,16,8:86.2
-11,16,8:86.2
9,16,8:86.2
10,16,8:86.2
-10,17,8:86.2
-9,17,8:86.2
-8,17,8:86.2
6,17,8:86.2
7,17,8:86.2
8,17,8:86.2
-7,18,8:86.2
-6,18,8:86.2
-5,18,8:86.2
-4,18,8:86.2
2,18,8:86.2
3,18,8:86.2
4,18,8:86.2
5,18,8:86.2
-3,19,8:86.2
-2,19,8:86.2
-1,19,8:86.2
0,19,8:86.2
1,19,8:86.2
-3,-18,9:86.0
-2,-18,9:86.0
-1,-18,9:86.0
0,-18,9:86.0
1,-18,9:86.0
-10,-17,9:50.4
-7,-17,9:86.0
-6,-17,9:86.0
-5,-17,9:86.0
-4,-17,9:86.0
2,-17,9:86.0
3,-17,9:86.0
4,-17,9:86.0
5,-17,9:86.0
-10,-16,9:86.0
-9,-16,9:86.0
-8,-16,9:86.0
6,-16,9:86.0
7,-16,9:86.0
8,-16,9:86.0
-12,-15,9:86.0
-11,-15,9:86.0
9,-15,9:86.0
10,-15,9:86.0
-13,-14,9:86.3
11,-14,9:86.1
-14,-13,9:86.3
12,-13,9:86.1
-15,-12,9:86.3
13,-12,9:86.1
14,-12,9:18
-16,-11,9:86.3
14,-11,9:86.1
-16,-10,9:86.3
-1,-10,9:85
14,-10,9:86.1
-17,-9,9:86.3
-2,-9,9:85
-1,-9,9:89
0,-9,9:85
15,-9,9:86.1
-17,-8,9:86.3
-1,-8,9:85
15,-8,9:86.1
-17,-7,9:86.3
15,-7,9:86.1
-18,-6,9:86.3
16,-6,9:86.1
-18,-5,9:86.3
16,-5,9:86.1
-18,-4,9:86.3
16,-4,9:86.1
-18,-3,9:86.3
16,-3,9:86.1
-19,-2,9:86.3
17,-2,9:86.1
-19,-1,9:86.3
-10,-1,9:85
8,-1,9:85
17,-1,9:86.1
-19,0,9:86.3
-11,0,9:85
-10,0,9:89
-9,0,9:85
-1,0,9:85
7,0,9:85
8,0,9:89
9,0,9:85
17,0,9:86.1
-19,1,9:86.3
-10,1,9:85
8,1,9:85
17,1,9:86.1
-19,2,9:86.3
17,2,9:86.1
-18,3,9:86.3
15,3,9:47
16,3,9:86.1
-18,4,9:86.3
16,4,9:86.1
-18,5,9:86.3
16,5,9:86.1
-18,6,9:86.3
15,6,9:47
16,6,9:86.1
-17,7,9:86.3
15,7,9:86.1
-17,8,9:86.3
-1,8,9:85
15,8,9:86.1
-17,9,9:86.3
-2,9,9:85
-1,9,9:89
0,9,9:85
15,9,9:86.1
-16,10,9:86.3
-1,10,9:85
14,10,9:86.1
-16,11,9:86.2
14,11,9:86.1
-15,12,9:86.2
13,12,9:86.1
-14,13,9:86.2
12,13,9:86.1
-13,14,9:86.2
11,14,9:86.1
-12,15,9:86.2
-11,15,9:86.2
9,15,9:86.2
10,15,9:86.1
-10,16,9:86.2
-9,16,9:86.2
-8,16,9:86.2
6,16,9:86.2
7,16,9:86.2
8,16,9:86.2
-7,17,9:86.2
-6,17,9:86.2
-5,17,9:86.2
-4,17,9:86.2
2,17,9:86.2
3,17,9:86.2
4,17,9:86.2
5,17,9:86.2
-7,18,9:18
-3,18,9:86.2
-2,18,9:86.2
-1,18,9:86.2
0,18,9:86.2
1,18,9:86.2
-1,-18,10:18
-7,-17,10:50.4
-3,-17,10:86.0
-2,-17,10:86.0
-1,-17,10:86.0
0,-17,10:86.0
1,-17,10:86.0
-7,-16,10:86.0
-6,-16,10:86.0
-5,-16,10:86.0
-4,-16,10:86.0
2,-16,10:86.0
3,-16,10:86.0
4,-16,10:86.0
5,-16,10:86.0
-10,-15,10:86.0
-9,-15,10:86.0
-8,-15,10:86.0
6,-15,10:86.0
7,-15,10:86.0
8,-15,10:86.0
-12,-14,10:86.0
-11,-14,10:86.0
9,-14,10:86.0
10,-14,10:86.0
-13,-13,10:86.3
11,-13,10:86.0
12,-13,10:18
-14,-12,10:86.3
12,-12,10:86.1
13,-12,10:18
-15,-11,10:86.3
13,-11,10:86.1
-15,-10,10:86.3
-1,-10,10:85
13,-10,10:86.1
-16,-9,10:86.3
-2,-9,10:85
-1,-9,10:85
0,-9,10:85
14,-9,10:86.1
-16,-8,10:86.3
-1,-8,10:85
14,-8,10:86.1
-16,-7,10:86.3
-1,-7,10:85
14,-7,10:86.1
-17,-6,10:86.3
-1,-6,10:85
15,-6,10:86.1
-17,-5,10:86.3
-1,-5,10:85
15,-5,10:86.1
-17,-4,10:86.3
-1,-4,10:85
15,-4,10:86.1
-17,-3,10:86.3
-1,-3,10:85
15,-3,10:86.1
-18,-2,10:86.3
-1,-2,10:85
16,-2,10:86.1
-18,-1,10:86.3
-10,-1,10:85
-1,-1,10:85
8,-1,10:85
16,-1,10:86.1
17,-1,10:18
-18,0,10:86.3
-11,0,10:85
-10,0,10:85
-9,0,10:85
-8,0,10:85
-7,0,10:85
-6,0,10:85
-5,0,10:85
-4,0,10:85
-3,0,10:85
-2,0,10:85
-1,0,10:85
0,0,10:85
1,0,10:85
2,0,10:85
3,0,10:85
4,0,10:85
5,0,10:85
6,0,10:85
7,0,10:85
8,0,10:85
9,0,10:85
16,0,10:86.1
-18,1,10:86.3
-10,1,10:85
-1,1,10:85
8,1,10:85
16,1,10:86.1
-18,2,10:86.3
-1,2,10:85
16,2,10:86.1
-17,3,10:86.3
-1,3,10:85
15,3,10:86.1
-17,4,10:86.3
-1,4,10:85
15,4,10:86.1
-17,5,10:86.3
-1,5,10:85
15,5,10:86.1
-17,6,10:86.3
-1,6,10:85
15,6,10:86.1
-16,7,10:86.3
-1,7,10:85
14,7,10:86.1
-16,8,10:86.3
-1,8,10:85
14,8,10:86.1
-16,9,10:86.3
-2,9,10:85
-1,9,10:85
0,9,10:85
14,9,10:86.1
-15,10,10:86.3
-1,10,10:85
13,10,10:86.1
-15,11,10:86.3
13,11,10:86.1
-14,12,10:86.3
12,12,10:86.1
-13,13,10:86.2
11,13,10:86.1
-12,14,10:86.2
-11,14,10:86.2
9,14,10:86.2
10,14,10:86.2
-10,15,10:86.2
-9,15,10:86.2
-8,15,10:86.2
6,15,10:86.2
7,15,10:86.2
8,15,10:86.2
-7,16,10:86.2
-6,16,10:86.2
-5,16,10:86.2
-4,16,10:86.2
2,16,10:86.2
3,16,10:86.2
4,16,10:86.2
5,16,10:86.2
-7,17,10:18
-6,17,10:18
-3,17,10:86.2
-2,17,10:86.2
-1,17,10:86.2
0,17,10:86.2
1,17,10:86.2
-1,-18,11:18
-2,-17,11:18
-1,-17,11:18
0,-17,11:18
-3,-16,11:86.0
-2,-16,11:86.0
-1,-16,11:86.0
0,-16,11:86.0
1,-16,11:86.0
-7,-15,11:86.0
-6,-15,11:86.0
-5,-15,11:86.0
-4,-15,11:86.0
-3,-15,11:86.0
-2,-15,11:86.0
-1,-15,11:86.0
0,-15,11:86.0
1,-15,11:86.0
2,-15,11:86.0
3,-15,11:86.0
4,-15,11:86.0
5,-15,11:86.0
-10,-14,11:86.0
-9,-14,11:86.0
-8,-14,11:86.0
-7,-14,11:86.0
5,-14,11:86.0
6,-14,11:86.0
7,-14,11:86.0
8,-14,11:86.0
-12,-13,11:86.0
-11,-13,11:86.0
-10,-13,11:86.0
-9,-13,11:86.0
7,-13,11:86.0
8,-13,11:86.0
9,-13,11:86.1
10,-13,11:86.1
11,-13,11:18
-13,-12,11:86.0
-12,-12,11:86.0
-11,-12,11:86.0
9,-12,11:86.1
10,-12,11:86.1
11,-12,11:86.1
12,-12,11:18
-14,-11,11:86.0
-13,-11,11:86.0
-12,-11,11:86.0
10,-11,11:86.1
11,-11,11:86.1
12,-11,11:86.1
13,-11,11:18
-14,-10,11:86.0
-13,-10,11:86.0
11,-10,11:86.1
12,-10,11:86.1
-15,-9,11:86.3
-14,-9,11:86.3
12,-9,11:86.1
13,-9,11:86.1
-15,-8,11:86.3
-14,-8,11:86.3
12,-8,11:86.1
13,-8,11:86.1
-15,-7,11:86.3
13,-7,11:86.1
-16,-6,11:86.3
-15,-6,11:86.3
13,-6,11:86.1
14,-6,11:86.1
-16,-5,11:86.3
14,-5,11:86.1
-16,-4,11:86.3
-4,-4,11:86.0
-3,-4,11:86.0
-2,-4,11:86.0
-1,-4,11:86.0
0,-4,11:86.0
1,-4,11:86.0
2,-4,11:86.0
14,-4,11:86.1
-17,-3,11:18
-16,-3,11:86.3
-5,-3,11:86.3
-4,-3,11:86.0
-3,-3,11:86.0
-2,-3,11:86.0
-1,-3,11:86.0
0,-3,11:86.0
1,-3,11:86.0
2,-3,11:86.1
3,-3,11:86.1
14,-3,11:86.1
15,-3,11:18
-17,-2,11:86.3
-16,-2,11:86.3
-5,-2,11:86.3
-4,-2,11:86.3
-3,-2,11:86.3
-2,-2,11:86.0
-1,-2,11:86.0
0,-2,11:86.0
1,-2,11:86.0
2,-2,11:86.1
3,-2,11:86.1
14,-2,11:86.1
15,-2,11:86.1
16,-2,11:18
-17,-1,11:86.3
-16,-1,11:86.3
-5,-1,11:86.3
-4,-1,11:86.3
-3,-1,11:86.3
-2,-1,11:86.0
-1,-1,11:86.3
0,-1,11:86.1
1,-1,11:86.1
2,-1,11:86.1
3,-1,11:86.1
14,-1,11:86.1
15,-1,11:86.1
16,-1,11:18
-17,0,11:86.3
-16,0,11:86.3
-5,0,11:86.3
-4,0,11:86.3
-3,0,11:86.3
-2,0,11:86.3
-1,0,11:3
0,0,11:86.1
1,0,11:86.1
2,0,11:86.1
3,0,11:86.1
14,0,11:86.1
15,0,11:86.1
16,0,11:18
-17,1,11:86.3
-16,1,11:86.3
-5,1,11:86.3
-4,1,11:86.3
-3,1,11:86.2
-2,1,11:86.2
-1,1,11:86.2
0,1,11:86.2
1,1,11:86.2
2,1,11:86.1
3,1,11:86.1
14,1,11:86.1
15,1,11:86.1
-17,2,11:86.3
-16,2,11:86.3
-5,2,11:86.3
-4,2,11:86.3
-3,2,11:86.2
-2,2,11:86.2
-1,2,11:86.2
0,2,11:86.2
1,2,11:86.2
2,2,11:86.1
3,2,11:86.1
14,2,11:86.1
15,2,11:86.1
-16,3,11:86.3
-5,3,11:86.3
-4,3,11:86.3
-3,3,11:86.2
-2,3,11:86.2
-1,3,11:86.2
0,3,11:86.2
1,3,11:86.2
2,3,11:86.1
3,3,11:86.1
14,3,11:86.1
-16,4,11:86.3
-4,4,11:86.2
-3,4,11:86.2
-2,4,11:86.2
-1,4,11:86.2
0,4,11:86.2
1,4,11:86.2
2,4,11:86.2
14,4,11:86.1
-17,5,11:18
-16,5,11:86.3
14,5,11:86.1
-16,6,11:86.3
-15,6,11:86.3
13,6,11:86.1
14,6,11:86.1
-15,7,11:86.3
13,7,11:86.1
-15,8,11:86.3
-14,8,11:86.3
12,8,11:86.1
13,8,11:86.1
-15,9,11:86.3
-14,9,11:86.3
12,9,11:86.1
13,9,11:86.1
-14,10,11:86.2
-13,10,11:86.2
11,10,11:86.1
12,10,11:86.1
13,10,11:18
-14,11,11:86.2
-13,11,11:86.2
-12,11,11:86.2
10,11,11:86.1
11,11,11:86.1
12,11,11:86.1
-13,12,11:86.2
-12,12,11:86.2
-11,12,11:86.2
9,12,11:86.2
10,12,11:86.2
11,12,11:86.1
-12,13,11:86.2
-11,13,11:86.2
-10,13,11:86.2
-9,13,11:86.2
7,13,11:86.1
8,13,11:86.2
9,13,11:86.2
10,13,11:86.2
-10,14,11:86.2
-9,14,11:86.2
-8,14,11:86.2
-7,14,11:86.2
5,14,11:86.2
6,14,11:86.2
7,14,11:86.2
8,14,11:86.2
-7,15,11:86.2
-6,15,11:86.2
-5,15,11:86.2
-4,15,11:86.2
-3,15,11:86.2
-2,15,11:86.2
-1,15,11:86.2
0,15,11:86.2
1,15,11:86.2
2,15,11:86.2
3,15,11:86.2
4,15,11:86.2
5,15,11:86.2
-7,16,11:18
-6,16,11:18
-5,16,11:18
-3,16,11:86.2
-2,16,11:86.2
-1,16,11:86.2
0,16,11:86.2
1,16,11:86.2
-2,-17,12:18
-1,-17,12:18
-3,-16,12:18
-2,-16,12:18
-1,-16,12:18
0,-16,12:18
-4,-15,12:18
-3,-15,12:18
-2,-15,12:18
-1,-15,12:18
0,-15,12:18
-6,-14,12:86.0
-5,-14,12:86.0
-4,-14,12:86.0
-3,-14,12:86.0
-2,-14,12:86.0
-1,-14,12:86.0
0,-14,12:86.0
1,-14,12:86.0
2,-14,12:86.0
3,-14,12:86.0
4,-14,12:86.0
-8,-13,12:86.0
-7,-13,12:86.0
-6,-13,12:86.0
-5,-13,12:86.0
-4,-13,12:86.0
-3,-13,12:86.0
-2,-13,12:86.0
-1,-13,12:86.0
0,-13,12:86.0
1,-13,12:86.0
2,-13,12:86.0
3,-13,12:86.0
4,-13,12:86.0
5,-13,12:86.0
6,-13,12:86.0
10,-13,12:18
-10,-12,12:86.0
-9,-12,12:86.0
-8,-12,12:86.0
-7,-12,12:86.0
-6,-12,12:86.0
-5,-12,12:86.0
-4,-12,12:86.0
-3,-12,12:86.0
-2,-12,12:86.0
-1,-12,12:86.0
0,-12,12:86.0
1,-12,12:86.0
2,-12,12:86.0
3,-12,12:86.0
4,-12,12:86.0
5,-12,12:86.0
6,-12,12:86.0
7,-12,12:86.0
8,-12,12:86.0
9,-12,12:18
10,-12,12:18
11,-12,12:18
-11,-11,12:86.0
-10,-11,12:86.0
-9,-11,12:86.0
-8,-11,12:86.0
-7,-11,12:86.0
5,-11,12:86.0
6,-11,12:86.0
7,-11,12:86.0
8,-11,12:86.0
9,-11,12:86.0
10,-11,12:18
11,-11,12:18
12,-11,12:18
-12,-10,12:86.3
-11,-10,12:86.0
-10,-10,12:86.0
-9,-10,12:86.0
7,-10,12:86.0
8,-10,12:86.0
9,-10,12:86.0
10,-10,12:86.0
11,-10,12:18
12,-10,12:18
-13,-9,12:86.3
-12,-9,12:86.3
-11,-9,12:86.0
-10,-9,12:86.0
8,-9,12:86.0
9,-9,12:86.1
10,-9,12:86.1
11,-9,12:86.1
-13,-8,12:86.3
-12,-8,12:86.3
-11,-8,12:86.3
9,-8,12:86.1
10,-8,12:86.1
11,-8,12:86.1
-14,-7,12:86.3
-13,-7,12:86.3
-12,-7,12:86.3
-6,-7,12:86.0
-5,-7,12:86.0
-4,-7,12:86.0
-3,-7,12:86.0
-2,-7,12:86.0
-1,-7,12:86.0
0,-7,12:86.0
1,-7,12:86.0
2,-7,12:86.0
3,-7,12:86.0
4,-7,12:86.0
10,-7,12:86.1
11,-7,12:86.1
12,-7,12:86.1
-14,-6,12:86.3
-13,-6,12:86.3
-12,-6,12:86.3
-7,-6,12:86.3
-6,-6,12:86.0
-5,-6,12:86.0
-4,-6,12:86.0
-3,-6,12:86.0
-2,-6,12:86.0
-1,-6,12:86.0
0,-6,12:86.0
1,-6,12:86.0
2,-6,12:86.0
3,-6,12:86.0
4,-6,12:86.0
5,-6,12:86.0
10,-6,12:86.1
11,-6,12:86.1
12,-6,12:86.1
-15,-5,12:86.3
-14,-5,12:86.3
-13,-5,12:86.3
-8,-5,12:86.3
-7,-5,12:86.3
-6,-5,12:86.0
-5,-5,12:86.0
-4,-5,12:86.0
-3,-5,12:86.0
-2,-5,12:86.0
-1,-5,12:86.0
0,-5,12:86.0
1,-5,12:86.0
2,-5,12:86.0
3,-5,12:86.0
4,-5,12:86.1
5,-5,12:86.1
6,-5,12:86.1
11,-5,12:86.1
12,-5,12:86.1
13,-5,12:86.1
-15,-4,12:86.3
-14,-4,12:86.3
-13,-4,12:86.3
-8,-4,12:86.3
-7,-4,12:86.3
-6,-4,12:86.0
-5,-4,12:86.0
-4,-4,12:17.0
-3,-4,12:18
-2,-4,12:18
-1,-4,12:17.0
0,-4,12:18
1,-4,12:18
2,-4,12:17.0
3,-4,12:86.1
4,-4,12:86.1
5,-4,12:86.1
6,-4,12:86.1
11,-4,12:86.1
12,-4,12:86.1
13,-4,12:86.1
14,-4,12:18
-16,-3,12:18
-15,-3,12:86.3
-14,-3,12:86.3
-13,-3,12:86.3
-8,-3,12:86.3
-7,-3,12:86.3
-6,-3,12:86.3
-5,-3,12:18
-4,-3,12:18
-3,-3,12:18
-2,-3,12:18
-1,-3,12:18
0,-3,12:18
1,-3,12:18
2,-3,12:18
3,-3,12:18
4,-3,12:86.1
5,-3,12:86.1
6,-3,12:86.1
11,-3,12:86.1
12,-3,12:86.1
13,-3,12:86.1
14,-3,12:18
15,-3,12:18
-17,-2,12:18
-16,-2,12:18
-15,-2,12:86.3
-14,-2,12:86.3
-13,-2,12:86.3
-8,-2,12:86.3
-7,-2,12:86.3
-6,-2,12:86.3
-5,-2,12:18
-4,-2,12:18
-3,-2,12:18
-2,-2,12:18
-1,-2,12:18
0,-2,12:18
1,-2,12:18
2,-2,12:18
3,-2,12:18
4,-2,12:86.1
5,-2,12:86.1
6,-2,12:86.1
11,-2,12:86.1
12,-2,12:86.1
13,-2,12:86.1
14,-2,12:18
15,-2,12:18
-16,-1,12:18
-15,-1,12:86.3
-14,-1,12:86.3
-13,-1,12:86.3
-8,-1,12:86.3
-7,-1,12:86.3
-6,-1,12:86.3
-5,-1,12:18
-4,-1,12:18
-3,-1,12:18
-2,-1,12:18
-1,-1,12:18
0,-1,12:18
1,-1,12:18
2,-1,12:18
3,-1,12:18
4,-1,12:86.1
5,-1,12:86.1
6,-1,12:86.1
11,-1,12:86.1
12,-1,12:86.1
13,-1,12:86.1
14,-1,12:18
15,-1,12:18
-15,0,12:86.3
-14,0,12:86.3
-13,0,12:86.3
-8,0,12:86.3
-7,0,12:86.3
-6,0,12:86.3
-5,0,12:18
-4,0,12:18
-3,0,12:18
-2,0,12:18
-1,0,12:17.0
0,0,12:18
1,0,12:18
2,0,12:18
3,0,12:18
4,0,12:86.1
5,0,12:86.1
6,0,12:86.1
11,0,12:86.1
12,0,12:86.1
13,0,12:86.1
14,0,12:18
15,0,12:18
-15,1,12:86.3
-14,1,12:86.3
-13,1,12:86.3
-8,1,12:86.3
-7,1,12:86.3
-6,1,12:86.3
-5,1,12:17.0
-4,1,12:18
-3,1,12:18
-2,1,12:18
-1,1,12:18
0,1,12:18
1,1,12:18
2,1,12:18
3,1,12:17.0
4,1,12:86.1
5,1,12:86.1
6,1,12:86.1
11,1,12:86.1
12,1,12:86.1
13,1,12:86.1
-15,2,12:86.3
-14,2,12:86.3
-13,2,12:86.2
-8,2,12:86.3
-7,2,12:86.3
-6,2,12:86.3
-5,2,12:18
-4,2,12:18
-3,2,12:18
-2,2,12:18
-1,2,12:18
0,2,12:18
1,2,12:18
2,2,12:18
3,2,12:18
4,2,12:86.1
5,2,12:86.1
6,2,12:86.1
11,2,12:86.1
12,2,12:86.1
13,2,12:86.1
-15,3,12:86.3
-14,3,12:86.3
-13,3,12:86.3
-8,3,12:86.3
-7,3,12:86.3
-6,3,12:86.3
-5,3,12:18
-4,3,12:18
-3,3,12:18
-2,3,12:18
-1,3,12:18
0,3,12:18
1,3,12:18
2,3,12:18
3,3,12:18
4,3,12:86.1
5,3,12:86.1
6,3,12:86.1
11,3,12:86.1
12,3,12:86.1
13,3,12:86.1
-15,4,12:86.3
-14,4,12:86.3
-13,4,12:86.3
-8,4,12:86.3
-7,4,12:86.3
-6,4,12:86.3
-5,4,12:86.2
-4,4,12:17.0
-3,4,12:18
-2,4,12:18
-1,4,12:18
0,4,12:18
1,4,12:18
2,4,12:17.0
3,4,12:86.1
4,4,12:86.1
5,4,12:86.1
6,4,12:86.1
11,4,12:86.1
12,4,12:86.1
13,4,12:86.1
-16,5,12:18
-15,5,12:86.3
-14,5,12:86.3
-13,5,12:86.3
-8,5,12:86.3
-7,5,12:86.3
-6,5,12:86.3
-5,5,12:86.2
-4,5,12:86.2
-3,5,12:86.2
-2,5,12:86.2
-1,5,12:86.2
0,5,12:86.2
1,5,12:86.2
2,5,12:86.2
3,5,12:86.2
4,5,12:86.2
5,5,12:86.1
6,5,12:86.1
11,5,12:86.1
12,5,12:86.1
13,5,12:86.1
-16,6,12:18
-15,6,12:18
-14,6,12:86.3
-13,6,12:86.3
-12,6,12:86.3
-7,6,12:86.2
-6,6,12:86.2
-5,6,12:86.2
-4,6,12:86.2
-3,6,12:86.2
-2,6,12:86.2
-1,6,12:86.2
0,6,12:86.2
1,6,12:86.2
2,6,12:86.2
3,6,12:86.2
4,6,12:86.2
5,6,12:86.1
10,6,12:86.1
11,6,12:86.1
12,6,12:86.1
-14,7,12:86.2
-13,7,12:86.3
-12,7,12:86.3
-6,7,12:86.2
-5,7,12:86.2
-4,7,12:86.2
-3,7,12:86.2
-2,7,12:86.2
-1,7,12:86.2
0,7,12:86.2
1,7,12:86.2
2,7,12:86.2
3,7,12:86.2
4,7,12:86.1
10,7,12:86.1
11,7,12:86.1
12,7,12:86.1
-13,8,12:86.2
-12,8,12:86.2
-11,8,12:86.2
9,8,12:86.1
10,8,12:86.1
11,8,12:86.1
-13,9,12:86.2
-12,9,12:86.2
-11,9,12:86.2
-10,9,12:86.2
8,9,12:86.1
9,9,12:86.1
10,9,12:86.1
11,9,12:86.1
12,9,12:18
-12,10,12:86.2
-11,10,12:86.2
-10,10,12:86.2
-9,10,12:86.2
7,10,12:86.2
8,10,12:86.1
9,10,12:86.1
10,10,12:86.1
11,10,12:18
12,10,12:18
-11,11,12:86.2
-10,11,12:86.2
-9,11,12:86.2
-8,11,12:86.2
-7,11,12:86.2
5,11,12:86.2
6,11,12:86.2
7,11,12:86.2
8,11,12:86.1
9,11,12:86.1
-10,12,12:86.2
-9,12,12:86.2
-8,12,12:86.2
-7,12,12:86.2
-6,12,12:86.2
-5,12,12:86.2
-4,12,12:86.2
-3,12,12:86.2
-2,12,12:86.2
-1,12,12:86.2
0,12,12:86.2
1,12,12:86.2
2,12,12:86.2
3,12,12:86.2
4,12,12:86.2
5,12,12:86.2
6,12,12:86.2
7,12,12:86.2
8,12,12:86.2
-8,13,12:86.2
-7,13,12:86.2
-6,13,12:86.2
-5,13,12:86.2
-4,13,12:86.2
-3,13,12:86.2
-2,13,12:86.2
-1,13,12:86.2
0,13,12:86.2
1,13,12:86.2
2,13,12:86.2
3,13,12:86.2
4,13,12:86.2
5,13,12:86.2
6,13,12:86.2
-6,14,12:86.2
-5,14,12:86.2
-4,14,12:86.2
-3,14,12:86.2
-2,14,12:86.2
-1,14,12:86.2
0,14,12:86.2
1,14,12:86.2
2,14,12:86.2
3,14,12:86.2
4,14,12:86.2
-7,15,12:18
-6,15,12:18
-5,15,12:18
-4,15,12:18
-3,15,12:18
-2,15,12:18
-6,16,12:18
-2,-15,13:18
-1,-15,13:18
-5,-14,13:18
-4,-14,13:18
-3,-14,13:18
-2,-14,13:18
-1,-14,13:18
0,-14,13:18
-5,-13,13:18
-4,-13,13:18
-3,-13,13:18
-2,-13,13:18
-1,-13,13:18
0,-13,13:18
-5,-12,13:18
-4,-12,13:18
-3,-12,13:18
-2,-12,13:18
-1,-12,13:18
0,-12,13:18
6,-12,13:18
7,-12,13:18
8,-12,13:18
-6,-11,13:86.0
-5,-11,13:86.0
-4,-11,13:86.0
-3,-11,13:86.0
-2,-11,13:86.0
-1,-11,13:86.0
0,-11,13:86.0
1,-11,13:86.0
2,-11,13:86.0
3,-11,13:86.0
4,-11,13:86.0
5,-11,13:18
6,-11,13:18
7,-11,13:18
8,-11,13:18
9,-11,13:18
-12,-10,13:18
-8,-10,13:86.3
-7,-10,13:86.3
-6,-10,13:86.3
-5,-10,13:86.3
-4,-10,13:86.0
-3,-10,13:86.0
-2,-10,13:86.0
-1,-10,13:86.0
0,-10,13:86.0
1,-10,13:86.0
2,-10,13:86.0
3,-10,13:86.0
4,-10,13:86.0
5,-10,13:86.0
6,-10,13:86.0
7,-10,13:18
8,-10,13:18
9,-10,13:18
10,-10,13:18
-13,-9,13:18
-12,-9,13:18
-11,-9,13:18
-9,-9,13:86.3
-8,-9,13:86.3
-7,-9,13:86.3
-6,-9,13:86.3
-5,-9,13:86.0
-4,-9,13:86.0
-3,-9,13:86.0
-2,-9,13:86.0
-1,-9,13:86.0
0,-9,13:86.0
1,-9,13:86.0
2,-9,13:86.0
3,-9,13:86.0
4,-9,13:86.0
5,-9,13:86.0
6,-9,13:86.0
7,-9,13:86.1
8,-9,13:18
9,-9,13:18
10,-9,13:18
-13,-8,13:18
-12,-8,13:18
-11,-8,13:18
-10,-8,13:86.3
-9,-8,13:86.3
-8,-8,13:86.3
-7,-8,13:86.0
-6,-8,13:86.0
-5,-8,13:86.0
-4,-8,13:86.1
-3,-8,13:86.0
-2,-8,13:86.0
-1,-8,13:86.0
0,-8,13:86.0
1,-8,13:86.0
2,-8,13:86.0
3,-8,13:86.0
4,-8,13:86.0
5,-8,13:86.0
6,-8,13:86.0
7,-8,13:86.1
8,-8,13:86.1
9,-8,13:18
10,-8,13:18
-12,-7,13:18
-11,-7,13:86.3
-10,-7,13:86.3
-9,-7,13:86.3
-8,-7,13:86.3
-7,-7,13:86.3
-6,-7,13:18
-5,-7,13:18
-4,-7,13:18
-3,-7,13:18
-2,-7,13:18
-1,-7,13:18
0,-7,13:18
1,-7,13:18
2,-7,13:18
3,-7,13:18
4,-7,13:18
5,-7,13:86.1
6,-7,13:86.1
7,-7,13:86.1
8,-7,13:86.1
9,-7,13:86.1
-11,-6,13:86.3
-10,-6,13:86.3
-9,-6,13:86.3
-8,-6,13:86.3
-7,-6,13:17.0
-6,-6,13:18
-5,-6,13:18
-4,-6,13:18
-3,-6,13:18
-2,-6,13:18
-1,-6,13:18
0,-6,13:18
1,-6,13:18
2,-6,13:18
3,-6,13:18
4,-6,13:18
5,-6,13:17.0
6,-6,13:86.1
7,-6,13:86.1
8,-6,13:86.1
9,-6,13:86.1
-12,-5,13:86.3
-11,-5,13:86.3
-10,-5,13:86.3
-9,-5,13:86.3
-8,-5,13:18
-7,-5,13:18
-6,-5,13:18
-5,-5,13:18
-4,-5,13:18
-3,-5,13:18
-2,-5,13:18
-1,-5,13:18
0,-5,13:18
1,-5,13:18
2,-5,13:18
3,-5,13:18
4,-5,13:18
5,-5,13:18
6,-5,13:18
7,-5,13:86.1
8,-5,13:86.1
9,-5,13:86.1
10,-5,13:86.1
11,-5,13:18
12,-5,13:18
-12,-4,13:86.3
-11,-4,13:86.3
-10,-4,13:86.3
-9,-4,13:86.3
-8,-4,13:18
-7,-4,13:18
-6,-4,13:18
-5,-4,13:18
-4,-4,13:18
-1,-4,13:18
2,-4,13:18
3,-4,13:18
4,-4,13:18
5,-4,13:18
6,-4,13:18
7,-4,13:86.1
8,-4,13:86.1
9,-4,13:86.1
10,-4,13:86.1
11,-4,13:18
12,-4,13:18
13,-4,13:18
14,-4,13:18
-12,-3,13:86.3
-11,-3,13:86.3
-10,-3,13:86.3
-9,-3,13:86.3
-8,-3,13:18
-7,-3,13:18
-6,-3,13:18
4,-3,13:18
5,-3,13:18
6,-3,13:18
7,-3,13:86.1
8,-3,13:86.1
9,-3,13:86.1
10,-3,13:86.1
11,-3,13:18
12,-3,13:18
13,-3,13:18
14,-3,13:18
-15,-2,13:18
-14,-2,13:18
-13,-2,13:18
-12,-2,13:86.3
-11,-2,13:86.3
-10,-2,13:86.3
-9,-2,13:86.3
-8,-2,13:18
-7,-2,13:18
-6,-2,13:18
-3,-2,13:18
-2,-2,13:18
-1,-2,13:18
0,-2,13:18
1,-2,13:18
4,-2,13:18
5,-2,13:18
6,-2,13:18
7,-2,13:86.1
8,-2,13:86.1
9,-2,13:86.1
10,-2,13:86.1
11,-2,13:18
12,-2,13:18
13,-2,13:18
14,-2,13:18
-15,-1,13:18
-14,-1,13:18
-13,-1,13:18
-12,-1,13:86.3
-11,-1,13:86.3
-10,-1,13:86.3
-9,-1,13:86.3
-8,-1,13:18
-7,-1,13:18
-6,-1,13:18
-3,-1,13:18
-2,-1,13:17.0
-1,-1,13:17.0
0,-1,13:17.0
1,-1,13:18
4,-1,13:18
5,-1,13:18
6,-1,13:18
7,-1,13:86.1
8,-1,13:86.1
9,-1,13:86.1
10,-1,13:86.1
11,-1,13:18
12,-1,13:18
13,-1,13:18
14,-1,13:18
-15,0,13:18
-14,0,13:18
-13,0,13:18
-12,0,13:86.3
-11,0,13:86.3
-10,0,13:86.3
-9,0,13:86.3
-8,0,13:18
-7,0,13:18
-6,0,13:18
-3,0,13:18
-2,0,13:17.0
-1,0,13:17.0
0,0,13:17.0
1,0,13:18
3,0,13:18
4,0,13:18
5,0,13:18
6,0,13:18
7,0,13:86.1
8,0,13:86.1
9,0,13:86.1
10,0,13:86.1
11,0,13:18
12,0,13:18
13,0,13:18
-14,1,13:18
-13,1,13:18
-12,1,13:86.3
-11,1,13:86.3
-10,1,13:86.3
-9,1,13:86.3
-8,1,13:18
-7,1,13:18
-6,1,13:18
-5,1,13:18
-3,1,13:18
-2,1,13:17.0
-1,1,13:17.0
0,1,13:17.0
1,1,13:18
3,1,13:18
4,1,13:18
5,1,13:18
6,1,13:18
7,1,13:86.1
8,1,13:86.1
9,1,13:86.1
10,1,13:86.1
11,1,13:18
12,1,13:18
-12,2,13:86.3
-11,2,13:86.3
-10,2,13:86.3
-9,2,13:86.3
-8,2,13:18
-7,2,13:18
-6,2,13:18
-3,2,13:18
-2,2,13:18
-1,2,13:18
0,2,13:18
1,2,13:18
3,2,13:18
4,2,13:18
5,2,13:18
6,2,13:18
7,2,13:86.1
8,2,13:86.1
9,2,13:86.1
10,2,13:86.1
-12,3,13:86.3
-11,3,13:86.2
-10,3,13:86.2
-9,3,13:86.2
-8,3,13:18
-7,3,13:18
-6,3,13:18
4,3,13:18
5,3,13:18
6,3,13:18
7,3,13:86.1
8,3,13:86.1
9,3,13:86.1
10,3,13:86.1
-12,4,13:86.3
-11,4,13:86.2
-10,4,13:86.2
-9,4,13:86.2
-8,4,13:18
-7,4,13:18
-6,4,13:18
-5,4,13:18
-4,4,13:18
2,4,13:18
3,4,13:18
4,4,13:18
5,4,13:18
6,4,13:18
7,4,13:86.1
8,4,13:86.1
9,4,13:86.1
10,4,13:86.1
-15,5,13:18
-14,5,13:18
-12,5,13:86.3
-11,5,13:86.2
-10,5,13:86.2
-9,5,13:86.2
-8,5,13:18
-7,5,13:18
-6,5,13:18
-5,5,13:18
-4,5,13:18
-3,5,13:18
-2,5,13:18
-1,5,13:18
0,5,13:18
1,5,13:18
2,5,13:18
3,5,13:18
4,5,13:18
5,5,13:18
6,5,13:18
7,5,13:86.1
8,5,13:86.1
9,5,13:86.1
10,5,13:86.1
-14,6,13:18
-13,6,13:18
-12,6,13:18
-11,6,13:86.2
-10,6,13:86.2
-9,6,13:86.2
-8,6,13:86.2
-7,6,13:17.0
-6,6,13:18
-5,6,13:18
-4,6,13:18
-3,6,13:18
-2,6,13:18
-1,6,13:18
0,6,13:18
1,6,13:18
2,6,13:18
3,6,13:18
4,6,13:18
5,6,13:17.0
6,6,13:86.1
7,6,13:86.1
8,6,13:86.1
9,6,13:86.1
-14,7,13:18
-13,7,13:18
-12,7,13:18
-11,7,13:86.2
-10,7,13:86.2
-9,7,13:86.2
-8,7,13:86.2
-7,7,13:86.2
-6,7,13:18
-5,7,13:18
-4,7,13:18
-3,7,13:18
-2,7,13:18
-1,7,13:18
0,7,13:18
1,7,13:18
2,7,13:18
3,7,13:18
4,7,13:18
5,7,13:86.2
6,7,13:86.1
7,7,13:86.1
8,7,13:86.1
9,7,13:86.1
-12,8,13:18
-11,8,13:18
-10,8,13:86.2
-9,8,13:86.2
-8,8,13:86.2
-7,8,13:86.2
-6,8,13:86.2
-5,8,13:86.2
-4,8,13:86.2
-3,8,13:86.2
-2,8,13:86.2
-1,8,13:86.2
0,8,13:86.2
1,8,13:86.2
2,8,13:86.2
3,8,13:86.2
4,8,13:86.2
5,8,13:86.2
6,8,13:86.1
7,8,13:86.1
8,8,13:86.1
9,8,13:18
10,8,13:18
11,8,13:18
-9,9,13:86.2
-8,9,13:86.2
-7,9,13:86.2
-6,9,13:86.2
-5,9,13:86.2
-4,9,13:86.2
-3,9,13:86.2
-2,9,13:86.2
-1,9,13:86.2
0,9,13:86.2
1,9,13:86.2
2,9,13:86.2
3,9,13:86.2
4,9,13:86.2
5,9,13:86.2
6,9,13:86.2
7,9,13:86.2
8,9,13:18
9,9,13:18
10,9,13:18
11,9,13:18
-8,10,13:86.2
-7,10,13:86.2
-6,10,13:86.2
-5,10,13:86.2
-4,10,13:86.2
-3,10,13:86.2
-2,10,13:86.2
-1,10,13:86.2
0,10,13:86.2
1,10,13:86.2
2,10,13:86.2
3,10,13:86.2
4,10,13:86.2
5,10,13:86.2
6,10,13:86.2
8,10,13:18
9,10,13:18
10,10,13:18
11,10,13:18
-6,11,13:86.2
-5,11,13:86.2
-4,11,13:86.2
-3,11,13:86.2
-2,11,13:86.2
-1,11,13:86.2
0,11,13:86.2
1,11,13:86.2
2,11,13:86.2
3,11,13:86.2
4,11,13:86.2
-5,12,13:18
-4,12,13:18
-3,12,13:18
-2,12,13:18
-1,12,13:18
0,12,13:18
1,12,13:18
2,12,13:18
3,12,13:18
-6,13,13:18
-5,13,13:18
-4,13,13:18
-3,13,13:18
-2,13,13:18
-1,13,13:18
0,13,13:18
1,13,13:18
2,13,13:18
-6,14,13:18
-5,14,13:18
-4,14,13:18
-3,14,13:18
-2,14,13:18
-1,14,13:18
0,14,13:18
-5,15,13:18
-4,15,13:18
-5,-12,14:18
-4,-12,14:18
-3,-12,14:18
-2,-12,14:18
-1,-12,14:18
0,-12,14:18
-5,-11,14:18
-4,-11,14:18
-3,-11,14:18
-2,-11,14:18
-1,-11,14:18
0,-11,14:18
1,-11,14:18
-4,-10,14:18
-3,-10,14:18
-2,-10,14:18
-1,-10,14:18
0,-10,14:18
1,-10,14:18
5,-10,14:18
6,-10,14:18
-4,-9,14:18
-3,-9,14:18
-2,-9,14:18
-1,-9,14:18
0,-9,14:18
1,-9,14:18
5,-9,14:18
6,-9,14:18
7,-9,14:18
-10,-8,14:18
-9,-8,14:18
-3,-8,14:18
-2,-8,14:18
-1,-8,14:17.0
0,-8,14:18
1,-8,14:18
5,-8,14:18
6,-8,14:18
7,-8,14:18
8,-8,14:18
-11,-7,14:18
-10,-7,14:18
-9,-7,14:18
-8,-7,14:18
-2,-7,14:18
-1,-7,14:18
0,-7,14:18
5,-7,14:18
6,-7,14:18
7,-7,14:18
8,-7,14:18
9,-7,14:18
-10,-6,14:18
-9,-6,14:18
-8,-6,14:18
6,-6,14:18
7,-6,14:18
-9,-5,14:18
10,-5,14:18
-9,-4,14:18
9,-4,14:18
10,-4,14:18
-12,-3,14:18
-11,-3,14:18
-10,-3,14:18
-9,-3,14:18
7,-3,14:18
8,-3,14:18
9,-3,14:18
10,-3,14:18
11,-3,14:18
-12,-2,14:18
-11,-2,14:18
-10,-2,14:18
-9,-2,14:18
6,-2,14:18
7,-2,14:18
8,-2,14:18
9,-2,14:18
10,-2,14:18
11,-2,14:18
-12,-1,14:18
-11,-1,14:18
-10,-1,14:18
-9,-1,14:18
-8,-1,14:18
-2,-1,14:17.0
-1,-1,14:17.0
0,-1,14:17.0
6,-1,14:18
7,-1,14:17.0
8,-1,14:18
9,-1,14:18
10,-1,14:18
11,-1,14:18
-12,0,14:18
-11,0,14:18
-10,0,14:18
-9,0,14:17.0
-8,0,14:18
-7,0,14:18
-2,0,14:17.0
-1,0,14:17.0
0,0,14:17.0
6,0,14:18
7,0,14:18
8,0,14:18
9,0,14:18
10,0,14:18
11,0,14:18
-12,1,14:18
-11,1,14:18
-10,1,14:18
-9,1,14:18
-8,1,14:18
-7,1,14:18
-2,1,14:17.0
-1,1,14:17.0
0,1,14:17.0
7,1,14:18
8,1,14:18
9,1,14:18
10,1,14:18
-11,2,14:18
-10,2,14:18
-9,2,14:18
-8,2,14:18
8,2,14:18
9,2,14:18
10,2,14:18
-9,3,14:18
-9,4,14:18
-11,6,14:18
-10,6,14:18
-9,6,14:18
-8,6,14:18
6,6,14:18
7,6,14:18
8,6,14:18
-11,7,14:18
-10,7,14:18
-9,7,14:18
-8,7,14:18
-7,7,14:18
5,7,14:18
6,7,14:18
7,7,14:18
8,7,14:18
9,7,14:18
-10,8,14:18
-9,8,14:18
-8,8,14:18
-7,8,14:18
-1,8,14:18
0,8,14:17.0
1,8,14:18
2,8,14:18
3,8,14:18
6,8,14:18
7,8,14:18
8,8,14:18
9,8,14:18
-9,9,14:18
-8,9,14:18
-2,9,14:18
-1,9,14:18
0,9,14:18
1,9,14:18
2,9,14:18
3,9,14:18
7,9,14:18
8,9,14:18
-4,10,14:18
-3,10,14:18
-2,10,14:18
-1,10,14:18
0,10,14:18
1,10,14:18
2,10,14:18
3,10,14:18
-4,11,14:18
-3,11,14:18
-2,11,14:18
-1,11,14:18
0,11,14:18
1,11,14:18
2,11,14:18
3,11,14:18
-4,12,14:18
-3,12,14:18
-2,12,14:18
-2,-1,15:17.0
-1,-1,15:17.0
0,-1,15:17.0
-2,0,15:17.0
-1,0,15:17.0
0,0,15:17.0
-2,1,15:17.0
-1,1,15:17.0
0,1,15:17.0
-2,-1,16:17.0
-1,-1,16:17.0
0,-1,16:17.0
-2,0,16:17.0
-1,0,16:17.0
0,0,16:17.0
-2,1,16:17.0
-1,1,16:17.0
0,1,16:17.0
-2,-1,17:17.0
-1,-1,17:17.0
0,-1,17:17.0
-2,0,17:17.0
-1,0,17:17.0
0,0,17:17.0
-2,1,17:17.0
-1,1,17:17.0
0,1,17:17.0
-2,-1,18:17.0
-1,-1,18:17.0
0,-1,18:17.0
-2,0,18:17.0
-1,0,18:17.0
0,0,18:17.0
-2,1,18:17.0
-1,1,18:17.0
0,1,18:17.0
-2,-2,19:17.0
-1,-2,19:17.0
0,-2,19:17.0
-2,-1,19:17.0
-1,-1,19:17.0
0,-1,19:17.0
-2,0,19:17.0
-1,0,19:17.0
0,0,19:17.0
-2,-2,20:17.0
-1,-2,20:17.0
0,-2,20:17.0
-2,-1,20:17.0
-1,-1,20:17.0
0,-1,20:17.0
-2,0,20:17.0
-1,0,20:17.0
0,0,20:17.0
-2,-4,21:17.0
-1,-4,21:17.0
0,-4,21:17.0
-2,-3,21:17.0
-1,-3,21:17.0
0,-3,21:17.0
-2,-2,21:17.0
-1,-2,21:17.0
0,-2,21:17.0
-2,-1,21:17.0
-1,-1,21:17.0
0,-1,21:17.0
-2,0,21:17.0
-1,0,21:17.0
0,0,21:17.0
-2,-4,22:17.0
-1,-4,22:17.0
0,-4,22:17.0
-2,-3,22:17.0
-1,-3,22:17.0
0,-3,22:17.0
-2,-2,22:17.0
-1,-2,22:17.0
0,-2,22:17.0
-2,-4,23:17.0
-1,-4,23:17.0
0,-4,23:17.0
-2,-3,23:17.0
-1,-3,23:17.0
0,-3,23:17.0
-2,-2,23:17.0
-1,-2,23:17.0
0,-2,23:17.0
-2,-7,24:17.0
-1,-7,24:17.0
0,-7,24:17.0
-2,-6,24:17.0
-1,-6,24:17.0
0,-6,24:17.0
-2,-5,24:17.0
-1,-5,24:17.0
0,-5,24:17.0
