[META]
version=2.0
spawnOnBlockType=87
spawnSunlight=True
spawnDarkness=True
spawnWater=False
spawnLava=True
underFill=True
randomRotation=True
dig=True
tree=False
branch=False
needsFoundation=True
rarity=250
collisionPercentage=0
spawnElevationMin=0
spawnElevationMax=120
spawnInBiome=Hell
[DATA]
0,0,0:49
1,-1,-1:49
0,0,-1:49
-1,-1,-1:49
-1,1,-1:49
1,1,-1:49
0,0,1:49
0,0,2:49
-1,0,2:49
1,0,2:49
2,0,3:49
-2,0,3:49
-2,-1,3:49
0,0,3:49
3,0,3:49
-3,-1,4:49
-2,-2,4:49
3,1,4:49
2,-1,4:49
0,0,4:49
0,1,4:49
0,2,4:49
0,-1,4:89
2,-2,4:89
4,1,4:89
-2,-3,4:89
-4,-1,4:89
-1,2,4:89
0,0,5:49
0,-1,5:49
0,-2,5:49
0,3,5:49
-2,-3,5:49
-2,-2,5:49
2,-1,5:49
2,-2,5:49
3,1,5:49
3,2,5:49
4,2,5:49
0,4,5:49
-3,0,5:49
-4,0,5:49
1,3,5:89
3,-2,5:89
-3,-3,5:89
-3,1,5:89
4,3,5:89
0,0,6:49
0,-3,6:49
0,-4,6:49
-2,-3,6:49
-2,-4,6:49
-4,0,6:49
-4,-1,6:49
2,-2,6:49
3,-2,6:49
4,2,6:49
4,3,6:49
0,4,6:49
-1,4,6:49
-1,5,6:49
-3,1,6:49
-3,2,6:49
5,3,6:89
-5,-1,6:89
3,-3,6:89
-2,5,6:89
-3,-4,6:89
-2,2,6:89
0,-5,6:89
4,1,6:89
4,4,6:89
4,-2,6:89
1,-4,6:89
-2,-5,6:89
-4,-2,6:89
-4,2,6:89
-3,3,6:89
-1,6,6:89
0,1,6:89
0,0,7:49
0,-1,7:49
-1,-1,7:49
0,1,7:49
1,1,7:49
1,2,7:49
-2,-4,7:89
-1,5,7:89
3,-2,7:89
-2,-1,7:89
2,2,7:89
-3,-1,8:49
-2,-1,8:49
-1,-2,8:49
1,2,8:49
1,3,8:49
0,3,8:49
-1,1,8:49
-2,1,8:49
-2,2,8:49
1,-1,8:49
2,-1,8:49
2,-2,8:49
3,-2,8:49
-1,-3,8:49
0,0,8:49
0,-3,8:89
-4,-1,8:89
-3,2,8:89
2,3,8:89
-1,3,8:89
4,-2,8:89
3,-3,8:89
2,0,8:89
-3,-2,8:89
1,4,8:89
-1,-3,9:49
-1,-4,9:49
0,-4,9:49
-3,-1,9:49
-4,-1,9:49
-4,0,9:49
-2,2,9:49
-3,2,9:49
-3,3,9:49
1,3,9:49
2,3,9:49
2,4,9:49
3,-2,9:49
3,-3,9:49
0,0,9:49
1,-1,9:49
1,0,9:49
0,-5,9:89
-5,0,9:89
-3,4,9:89
3,4,9:89
4,-3,9:89
-2,-4,9:89
3,-4,9:89
1,4,9:89
2,5,9:89
-4,3,9:89
-4,1,9:89
1,-4,9:89
3,-1,9:89
1,1,9:89
0,-1,9:89
-3,-2,9:89
0,0,10:49
-4,-1,10:89
2,4,10:89
3,-3,10:89
-1,0,10:89
0,0,11:49
0,-1,11:49
0,1,11:49
1,1,11:49
0,-2,11:49
1,-2,11:49
1,-3,11:49
-1,0,11:49
-2,0,11:49
-2,1,11:49
1,-4,11:89
2,1,11:89
-2,2,11:89
-1,-2,11:89
0,2,11:89
2,-2,11:89
0,0,12:49
1,-3,12:89
-2,1,12:89
0,-1,12:89
0,1,12:89
