[META]
version=2.0
spawnOnBlockType=2
spawnSunlight=True
spawnDarkness=True
spawnWater=False
spawnLava=False
underFill=False
randomRotation=True
dig=True
tree=False
branch=False
needsFoundation=True
rarity=10
collisionPercentage=10
spawnElevationMin=0
spawnElevationMax=102
groupId=Ruins
groupFrequencyMin=20
groupFrequencyMax=35
groupSeperationMin=5
groupSeperationMax=60
branchLimit=6
spawnInBiome=Jungle
[DATA]
-1,-5,-7:1.5
0,-5,-7:1.5
1,-5,-7:1.5
2,-5,-7:1.5
3,-5,-7:1.5
-2,-4,-7:1.5
-1,-4,-7:1.5
0,-4,-7:1.5
1,-4,-7:1.5
2,-4,-7:1.5
3,-4,-7:1.5
-3,-3,-7:1.5
-2,-3,-7:1.5
-1,-3,-7:1.5
0,-3,-7:1.5
1,-3,-7:1.5
2,-3,-7:1.5
3,-3,-7:1.5
4,-3,-7:1.5
-3,-2,-7:1.5
0,-2,-7:1.5
1,-2,-7:1.5
2,-2,-7:1.5
3,-2,-7:1.5
4,-2,-7:1.5
5,-2,-7:1.5
-3,-1,-7:1.5
-2,-1,-7:1.5
-1,-1,-7:1.5
0,-1,-7:1.5
1,-1,-7:1.5
2,-1,-7:1.5
3,-1,-7:1.5
4,-1,-7:1.5
-3,0,-7:1.5
-2,0,-7:1.5
-1,0,-7:1.5
0,0,-7:1.5
1,0,-7:1.5
2,0,-7:1.5
3,0,-7:1.5
4,0,-7:1.5
-2,1,-7:1.5
-1,1,-7:1.5
0,1,-7:1.5
1,1,-7:1.5
2,1,-7:1.5
3,1,-7:1.5
-1,2,-7:1.5
0,2,-7:1.5
1,2,-7:1.5
2,2,-7:1.5
-1,-6,-6:3.5
0,-6,-6:98.0
1,-6,-6:98.0
2,-6,-6:3.5
3,-6,-6:1.5
-3,-5,-6:3.5
-2,-5,-6:98.0
-1,-5,-6:98.0
0,-5,-6:98.0
1,-5,-6:98.0
2,-5,-6:98.0
3,-5,-6:98.0
4,-5,-6:3.5
-3,-4,-6:98.0
-2,-4,-6:98.2
-1,-4,-6:98.0
0,-4,-6:98.1
1,-4,-6:98.0
2,-4,-6:98.0
3,-4,-6:98.0
4,-4,-6:98.0
-4,-3,-6:3.5
-3,-3,-6:98.0
-2,-3,-6:98.0
-1,-3,-6:98.2
0,-3,-6:98.1
1,-3,-6:98.1
2,-3,-6:98.1
3,-3,-6:98.1
4,-3,-6:98.0
5,-3,-6:3.5
-5,-2,-6:3.5
-4,-2,-6:98.0
-3,-2,-6:98.0
-2,-2,-6:98.0
-1,-2,-6:98.1
0,-2,-6:98.2
1,-2,-6:98.0
2,-2,-6:98.1
3,-2,-6:98.2
4,-2,-6:98.2
5,-2,-6:98.0
6,-2,-6:1.5
-5,-1,-6:3.5
-4,-1,-6:98.0
-3,-1,-6:98.0
-2,-1,-6:98.0
-1,-1,-6:98.1
0,-1,-6:98.1
1,-1,-6:98.2
2,-1,-6:98.1
3,-1,-6:98.0
4,-1,-6:98.0
5,-1,-6:98.0
6,-1,-6:3.5
-4,0,-6:3.5
-3,0,-6:98.0
-2,0,-6:98.2
-1,0,-6:98.0
0,0,-6:98.1
1,0,-6:98.1
2,0,-6:98.0
3,0,-6:98.2
4,0,-6:98.1
5,0,-6:3.5
6,0,-6:2.0
-3,1,-6:98.0
-2,1,-6:98.2
-1,1,-6:98.0
0,1,-6:98.0
1,1,-6:98.0
2,1,-6:98.1
3,1,-6:98.0
4,1,-6:98.0
-2,2,-6:98.0
-1,2,-6:98.0
0,2,-6:98.0
1,2,-6:98.1
2,2,-6:98.0
3,2,-6:98.0
4,2,-6:3.5
-1,3,-6:3.5
0,3,-6:98.0
1,3,-6:98.0
-2,-6,-5:1.5
-1,-6,-5:3.5
0,-6,-5:98.1
1,-6,-5:98.0
2,-6,-5:3.5
3,-6,-5:1.5
-3,-5,-5:3.5
-2,-5,-5:98.0
-1,-5,-5:98.1
2,-5,-5:98.0
3,-5,-5:98.0
4,-5,-5:3.5
-4,-4,-5:3.5
-3,-4,-5:98.0
4,-4,-5:98.0
5,-4,-5:3.5
-4,-3,-5:3.5
-3,-3,-5:98.0
4,-3,-5:98.1
5,-3,-5:3.5
-5,-2,-5:3.5
-4,-2,-5:98.2
1,-2,-5:98.0
5,-2,-5:98.0
6,-2,-5:3.5
-5,-1,-5:3.5
-4,-1,-5:98.2
0,-1,-5:109.0
1,-1,-5:98.0
5,-1,-5:98.0
6,-1,-5:3.5
-4,0,-5:3.5
-3,0,-5:98.0
4,0,-5:98.0
5,0,-5:3.5
-4,1,-5:3.5
-3,1,-5:98.0
4,1,-5:98.0
5,1,-5:3.5
-3,2,-5:3.5
-2,2,-5:98.0
-1,2,-5:98.0
2,2,-5:98.1
3,2,-5:98.0
4,2,-5:3.5
-2,3,-5:3.5
-1,3,-5:3.5
0,3,-5:98.0
1,3,-5:98.0
2,3,-5:3.5
3,3,-5:3.5
-2,-6,-4:1.5
-1,-6,-4:3.5
0,-6,-4:44.13
1,-6,-4:44.13
2,-6,-4:3.0
3,-6,-4:1.5
-3,-5,-4:1.5
-2,-5,-4:98.0
-1,-5,-4:98.0
2,-5,-4:98.0
3,-5,-4:98.0
4,-5,-4:3.5
-4,-4,-4:1.5
-3,-4,-4:98.2
4,-4,-4:98.0
5,-4,-4:3.5
-5,-3,-4:2.0
-4,-3,-4:3.0
-3,-3,-4:98.2
4,-3,-4:98.1
5,-3,-4:3.0
-5,-2,-4:2.0
-4,-2,-4:44.13
1,-2,-4:98.0
5,-2,-4:44.13
6,-2,-4:3.0
-5,-1,-4:2.0
-4,-1,-4:44.13
1,-1,-4:109.0
5,-1,-4:44.13
6,-1,-4:3.0
-5,0,-4:2.0
-4,0,-4:3.0
-3,0,-4:98.2
4,0,-4:98.2
5,0,-4:3.0
6,0,-4:2.0
-4,1,-4:3.5
-3,1,-4:98.0
4,1,-4:98.0
5,1,-4:1.5
-3,2,-4:3.5
-2,2,-4:98.0
-1,2,-4:98.2
2,2,-4:98.0
3,2,-4:98.0
4,2,-4:1.5
-2,3,-4:1.5
-1,3,-4:3.0
0,3,-4:44.13
1,3,-4:44.13
2,3,-4:3.5
3,3,-4:2.0
-1,4,-4:2.0
0,4,-4:2.0
1,4,-4:2.0
-2,-6,-3:1.5
-1,-6,-3:3.0
0,-6,-3:3.0
1,-6,-3:3.5
2,-6,-3:3.5
3,-6,-3:1.5
-3,-5,-3:1.5
-1,-5,-3:3.5
0,-5,-3:98.0
1,-5,-3:98.0
2,-5,-3:3.5
4,-5,-3:1.5
-4,-4,-3:1.5
-3,-4,-3:2.0
-2,-4,-3:124.0
-1,-4,-3:98.0
0,-4,-3:98.2
1,-4,-3:98.0
2,-4,-3:98.0
3,-4,-3:124.0
4,-4,-3:3.5
5,-4,-3:3.0
-4,-3,-3:3.5
-3,-3,-3:3.5
-2,-3,-3:98.0
-1,-3,-3:98.0
2,-3,-3:98.0
3,-3,-3:98.0
4,-3,-3:3.5
5,-3,-3:3.5
-5,-2,-3:2.0
-4,-2,-3:3.0
-3,-2,-3:98.0
-2,-2,-3:98.2
0,-2,-3:98.0
1,-2,-3:109.3
3,-2,-3:98.0
4,-2,-3:98.0
5,-2,-3:3.0
6,-2,-3:13.5
-5,-1,-3:2.0
-4,-1,-3:3.5
-3,-1,-3:98.0
-2,-1,-3:98.0
3,-1,-3:98.0
4,-1,-3:98.0
5,-1,-3:3.0
6,-1,-3:13.5
-4,0,-3:3.5
-3,0,-3:3.5
-2,0,-3:98.0
-1,0,-3:98.0
2,0,-3:98.2
3,0,-3:98.0
4,0,-3:3.5
5,0,-3:3.5
6,0,-3:13.5
-4,1,-3:3.5
-3,1,-3:3.5
-2,1,-3:124.0
-1,1,-3:98.0
0,1,-3:98.0
1,1,-3:98.0
2,1,-3:98.0
3,1,-3:124.0
5,1,-3:1.5
-3,2,-3:1.5
-1,2,-3:3.5
0,2,-3:98.0
1,2,-3:98.0
2,2,-3:3.5
3,2,-3:3.5
4,2,-3:1.5
-2,3,-3:1.5
-1,3,-3:3.5
0,3,-3:3.0
1,3,-3:3.0
2,3,-3:3.5
0,4,-3:13.5
1,4,-3:13.5
-2,-6,-2:1.5
-1,-6,-2:3.5
0,-6,-2:3.5
1,-6,-2:3.5
2,-6,-2:3.5
3,-6,-2:1.5
-3,-5,-2:1.5
-1,-5,-2:3.5
0,-5,-2:3.5
1,-5,-2:3.5
2,-5,-2:3.5
3,-5,-2:3.5
4,-5,-2:1.5
-4,-4,-2:1.5
-3,-4,-2:1.5
-2,-4,-2:3.5
-1,-4,-2:3.5
0,-4,-2:3.5
1,-4,-2:3.5
2,-4,-2:3.5
3,-4,-2:3.5
4,-4,-2:3.5
5,-4,-2:1.5
-4,-3,-2:1.5
-3,-3,-2:3.5
-2,-3,-2:3.5
-1,-3,-2:98.0
0,-3,-2:98.0
1,-3,-2:98.2
2,-3,-2:98.0
3,-3,-2:3.5
4,-3,-2:3.5
5,-3,-2:3.5
-4,-2,-2:3.5
-3,-2,-2:3.5
-2,-2,-2:3.5
-1,-2,-2:98.0
0,-2,-2:109.1
2,-2,-2:98.0
3,-2,-2:3.5
4,-2,-2:3.5
5,-2,-2:3.5
6,-2,-2:2.0
-4,-1,-2:3.5
-3,-1,-2:3.5
-2,-1,-2:3.5
-1,-1,-2:98.0
2,-1,-2:98.0
3,-1,-2:3.5
4,-1,-2:3.5
5,-1,-2:3.5
6,-1,-2:2.0
-4,0,-2:3.5
-3,0,-2:3.5
-2,0,-2:3.5
-1,0,-2:98.0
0,0,-2:98.0
1,0,-2:98.2
2,0,-2:98.0
3,0,-2:3.5
4,0,-2:3.5
5,0,-2:3.5
-4,1,-2:3.0
-3,1,-2:3.5
-2,1,-2:3.5
-1,1,-2:3.5
0,1,-2:3.5
1,1,-2:3.5
2,1,-2:3.5
3,1,-2:3.5
4,1,-2:3.5
5,1,-2:3.5
-3,2,-2:3.0
-2,2,-2:3.5
-1,2,-2:3.5
0,2,-2:3.5
1,2,-2:3.5
2,2,-2:3.5
3,2,-2:3.5
4,2,-2:3.5
-2,3,-2:3.0
-1,3,-2:3.5
0,3,-2:3.5
1,3,-2:3.5
2,3,-2:3.5
-2,-6,-1:2.5
-1,-6,-1:2.5
0,-6,-1:2.5
1,-6,-1:2.5
2,-6,-1:2.5
3,-6,-1:2.5
-3,-5,-1:2.5
-2,-5,-1:98.0
-1,-5,-1:98.3
0,-5,-1:98.1
1,-5,-1:98.0
2,-5,-1:98.3
3,-5,-1:17.3
4,-5,-1:2.5
-4,-4,-1:2.5
-3,-4,-1:98.0
-2,-4,-1:98.0
-1,-4,-1:98.0
0,-4,-1:98.2
1,-4,-1:98.2
2,-4,-1:98.0
3,-4,-1:98.0
4,-4,-1:98.0
5,-4,-1:2.5
-4,-3,-1:2.5
-3,-3,-1:98.3
-2,-3,-1:98.0
-1,-3,-1:41.0
0,-3,-1:98.0
1,-3,-1:98.0
2,-3,-1:41.0
3,-3,-1:98.0
4,-3,-1:98.3
5,-3,-1:2.5
-4,-2,-1:2.5
-3,-2,-1:98.0
-2,-2,-1:98.0
-1,-2,-1:98.0
0,-2,-1:44.0
1,-2,-1:44.0
2,-2,-1:98.0
3,-2,-1:98.1
4,-2,-1:98.0
5,-2,-1:2.5
-4,-1,-1:2.5
-3,-1,-1:98.2
-2,-1,-1:98.0
-1,-1,-1:98.1
0,-1,-1:44.0
1,-1,-1:44.0
2,-1,-1:98.0
3,-1,-1:98.1
4,-1,-1:98.1
5,-1,-1:2.5
-4,0,-1:2.5
-3,0,-1:98.3
-2,0,-1:98.0
-1,0,-1:41.0
0,0,-1:98.1
1,0,-1:98.2
2,0,-1:41.0
3,0,-1:98.0
4,0,-1:98.3
5,0,-1:2.5
-4,1,-1:2.5
-3,1,-1:98.0
-2,1,-1:98.0
-1,1,-1:98.0
0,1,-1:98.0
1,1,-1:98.2
2,1,-1:98.0
3,1,-1:98.0
4,1,-1:98.0
5,1,-1:2.5
-3,2,-1:2.5
-2,2,-1:98.0
-1,2,-1:98.3
0,2,-1:98.0
1,2,-1:98.2
2,2,-1:98.3
3,2,-1:98.0
4,2,-1:2.5
-2,3,-1:2.5
-1,3,-1:2.5
0,3,-1:2.5
1,3,-1:2.5
2,3,-1:2.5
3,3,-1:2.5
-1,-4,0:98.3
2,-4,0:98.3
3,-4,0:17.3
-2,-3,0:98.3
-1,-3,0:44.0
2,-3,0:44.0
3,-3,0:98.3
0,-2,0:44.0
1,-2,0:44.0
0,-1,0:44.0
1,-1,0:44.0
-2,0,0:98.3
-1,0,0:44.0
2,0,0:44.0
3,0,0:98.3
-1,1,0:98.3
2,1,0:98.3
-1,-4,1:98.3
2,-4,1:98.3
3,-4,1:17.3
-2,-3,1:98.3
3,-3,1:98.3
-2,0,1:98.3
3,0,1:98.3
-1,1,1:98.3
2,1,1:98.3
-1,-4,2:109.2
2,-4,2:109.2
3,-4,2:17.3
-2,-3,2:109.0
-1,-3,2:44.13
2,-3,2:44.13
3,-3,2:109.1
-2,0,2:109.0
-1,0,2:44.13
2,0,2:44.13
3,0,2:109.1
-1,1,2:109.3
2,1,2:109.3
2,-4,3:17.3
-1,-3,3:98.0
0,-3,3:44.5
1,-3,3:44.5
2,-3,3:98.0
-1,-2,3:44.5
2,-2,3:44.5
-1,-1,3:44.5
2,-1,3:44.5
-1,0,3:98.0
0,0,3:44.5
1,0,3:44.5
2,0,3:98.0
2,-6,4:18.7
1,-5,4:18.15
2,-5,4:18.15
3,-5,4:18.15
2,-4,4:17.3
3,-4,4:18.15
-1,-3,4:98.3
0,-3,4:44.5
1,-3,4:44.5
2,-3,4:98.3
-1,-2,4:44.5
2,-2,4:44.5
-1,-1,4:44.5
2,-1,4:44.5
-1,0,4:98.3
0,0,4:44.5
1,0,4:44.5
2,0,4:98.3
2,-5,5:18.15
0,-4,5:109.2
1,-4,5:109.2
2,-4,5:17.3
3,-4,5:18.15
-1,-3,5:98.3
0,-3,5:109.7
1,-3,5:109.7
2,-3,5:98.3
-2,-2,5:109.0
-1,-2,5:109.5
2,-2,5:109.4
3,-2,5:109.1
-2,-1,5:109.0
-1,-1,5:109.5
2,-1,5:109.4
3,-1,5:109.1
-1,0,5:98.3
0,0,5:109.6
1,0,5:109.6
2,0,5:98.3
0,1,5:109.3
1,1,5:109.3
1,-4,6:17.3
0,-3,6:98.0
1,-3,6:98.0
-1,-2,6:98.0
2,-2,6:98.0
-1,-1,6:98.0
2,-1,6:98.0
0,0,6:98.0
1,0,6:98.0
1,-4,7:17.3
0,-3,7:109.2
1,-3,7:109.2
-1,-2,7:109.0
2,-2,7:109.1
-1,-1,7:109.0
2,-1,7:109.1
0,0,7:109.3
1,0,7:109.3
1,-3,8:17.3
1,-4,9:18.15
1,-3,9:17.3
2,-3,9:18.15
1,-3,10:17.3
1,-5,11:18.15
0,-4,11:18.15
1,-4,11:18.15
2,-4,11:18.15
-1,-3,11:18.15
0,-3,11:18.15
1,-3,11:17.3
2,-3,11:18.15
3,-3,11:18.15
-1,-2,11:18.15
0,-2,11:17.3
1,-2,11:17.3
2,-2,11:18.15
3,-2,11:18.15
0,-1,11:17.3
1,-1,11:18.15
0,0,11:17.3
-1,-3,12:18.15
0,-3,12:18.15
1,-3,12:18.15
-2,-2,12:18.15
-1,-2,12:17.3
0,-2,12:17.3
1,-2,12:18.15
2,-2,12:18.7
-1,0,12:18.15
0,0,12:18.15
1,0,12:18.15
-1,1,12:18.15
0,1,12:17.3
1,1,12:18.15
0,2,12:18.15
1,2,12:18.15
-2,-4,13:18.15
-3,-3,13:18.15
-2,-3,13:18.15
-1,-3,13:18.15
0,-3,13:18.15
-3,-2,13:18.15
-2,-2,13:17.3
-1,-2,13:18.15
0,-2,13:18.15
1,-2,13:18.15
-2,-1,13:18.15
0,-1,13:18.7
0,1,13:18.15
-2,-2,14:18.15
0,-2,14:18.15
1,-2,10:106.4
0,-2,10:106.0
0,-3,10:106.8
1,-2,9:106.4
0,-3,9:106.8
0,-3,8:106.8
1,-4,8:106.1
2,-4,7:106.2
1,-5,7:106.1
2,-4,6:106.2
1,-5,6:106.1
3,-5,2:106.1
4,-4,1:106.2
3,-5,1:106.1
2,-5,1:106.1
4,-4,0:106.2
3,-5,0:106.1
-2,2,-3:76.5
4,1,-3:76.5
3,-5,-3:76.5
-2,-5,-3:76.5
