[META]
version=2.0
spawnOnBlockType=2
spawnSunlight=True
spawnDarkness=True
spawnWater=False
spawnLava=False
underFill=False
randomRotation=True
dig=True
tree=False
branch=False
needsFoundation=True
rarity=10
collisionPercentage=10
spawnElevationMin=0
spawnElevationMax=102
groupId=Ruins
groupFrequencyMin=20
groupFrequencyMax=35
groupSeperationMin=5
groupSeperationMax=60
branchLimit=6
spawnInBiome=Jungle
[DATA]
0,-1,-5:1.5
0,0,-5:15.5
-1,-1,-4:1.5
0,-1,-4:3.5
1,-1,-4:3.5
-2,0,-4:1.5
-1,0,-4:15.5
0,0,-4:15.5
1,0,-4:1.5
0,1,-4:15.5
1,-2,-3:3.5
2,-2,-3:3.5
-1,-1,-3:1.5
0,-1,-3:3.5
1,-1,-3:1.5
-2,0,-3:1.5
-1,0,-3:3.5
0,0,-3:3.5
1,0,-3:1.5
2,0,-3:16.5
-2,1,-3:1.5
-1,1,-3:1.5
0,1,-3:3.5
1,1,-3:1.5
-1,2,-3:1.5
0,2,-3:1.5
-2,-3,-2:3.5
-1,-3,-2:3.5
0,-3,-2:3.5
2,-3,-2:1.5
-2,-2,-2:3.5
-1,-2,-2:1.5
0,-2,-2:3.5
1,-2,-2:1.5
2,-2,-2:1.5
3,-2,-2:1.5
-2,-1,-2:3.5
-1,-1,-2:1.5
0,-1,-2:3.5
1,-1,-2:3.5
2,-1,-2:1.5
3,-1,-2:16.5
4,-1,-2:1.5
-3,0,-2:1.5
-2,0,-2:3.5
-1,0,-2:3.5
0,0,-2:3.5
1,0,-2:3.5
2,0,-2:3.5
3,0,-2:16.5
-3,1,-2:1.5
-2,1,-2:1.5
-1,1,-2:1.5
0,1,-2:3.5
1,1,-2:3.5
2,1,-2:16.5
-2,2,-2:1.5
-1,2,-2:1.5
0,2,-2:3.5
1,2,-2:1.5
2,2,-2:1.5
0,3,-2:1.5
-3,-4,-1:2.5
-2,-4,-1:2.5
0,-4,-1:2.5
2,-4,-1:2.5
3,-4,-1:2.5
-4,-3,-1:2.5
-3,-3,-1:2.5
-2,-3,-1:2.5
-1,-3,-1:2.5
0,-3,-1:2.5
1,-3,-1:2.5
2,-3,-1:2.5
3,-3,-1:2.5
4,-3,-1:2.5
-3,-2,-1:2.5
-2,-2,-1:2.5
-1,-2,-1:2.5
0,-2,-1:2.5
1,-2,-1:2.5
2,-2,-1:2.5
3,-2,-1:2.5
-4,-1,-1:2.5
-3,-1,-1:2.5
-2,-1,-1:2.5
-1,-1,-1:2.5
0,-1,-1:2.5
1,-1,-1:2.5
2,-1,-1:2.5
3,-1,-1:2.5
4,-1,-1:2.5
-3,0,-1:2.5
-2,0,-1:2.5
-1,0,-1:2.5
0,0,-1:2.5
1,0,-1:2.5
2,0,-1:2.5
3,0,-1:2.5
4,0,-1:2.5
-4,1,-1:2.5
-3,1,-1:2.5
-2,1,-1:2.5
-1,1,-1:2.5
0,1,-1:2.5
1,1,-1:2.5
2,1,-1:2.5
3,1,-1:2.5
-3,2,-1:2.5
-2,2,-1:2.5
-1,2,-1:2.5
0,2,-1:2.5
1,2,-1:2.5
2,2,-1:2.5
3,2,-1:2.5
4,2,-1:2.5
-1,3,-1:2.5
2,3,-1:2.5
-3,-4,3:18.14
-2,-4,3:18.14
-1,-4,3:18.14
0,-4,3:18.14
3,-4,3:18.14
-4,-3,3:18.14
4,-3,3:18.14
-4,-2,3:18.14
4,-2,3:18.14
-4,-1,3:18.14
4,-1,3:18.14
-4,1,3:18.14
4,1,3:18.14
-4,2,3:18.14
4,2,3:18.14
-3,3,3:18.14
-2,3,3:18.14
-1,3,3:18.14
1,3,3:18.14
2,3,3:18.14
3,3,3:18.14
-3,-3,4:18.14
-2,-3,4:18.14
-1,-3,4:18.14
1,-3,4:18.14
2,-3,4:18.14
3,-3,4:18.14
-3,-2,4:18.14
3,-2,4:18.14
-3,0,4:18.14
3,0,4:18.14
-3,1,4:18.14
-3,2,4:18.14
-2,2,4:18.14
0,2,4:18.14
1,2,4:18.14
2,2,4:18.14
3,2,4:18.14
2,1,4:106.1
1,1,4:106.1
0,1,4:106.1
-2,1,4:106.1
2,0,4:106.8
-2,0,4:106.2
1,-2,4:106.4
-1,-2,4:106.4
-2,-2,4:106.4
3,2,3:85.0
2,2,3:85.0
1,2,3:85.0
0,2,3:85.0
-1,2,3:85.0
-2,2,3:85.0
-3,2,3:85.0
3,1,3:85.0
2,1,3:106.1
1,1,3:106.1
0,1,3:106.1
-2,1,3:106.1
-3,1,3:85.0
3,0,3:85.0
2,0,3:106.8
-2,0,3:106.2
-3,0,3:85.0
3,-1,3:85.0
-3,-1,3:85.0
3,-2,3:85.0
1,-2,3:106.4
-1,-2,3:106.4
-2,-2,3:106.4
-3,-2,3:85.0
3,-3,3:85.0
2,-3,3:85.0
1,-3,3:85.0
0,-3,3:85.0
-1,-3,3:85.0
-2,-3,3:85.0
-3,-3,3:85.0
3,2,2:85.0
-3,2,2:85.0
2,1,2:106.1
0,1,2:106.1
-2,1,2:106.1
2,0,2:106.8
-2,0,2:106.2
1,-2,2:106.4
-1,-2,2:106.4
-2,-2,2:106.4
3,-3,2:85.0
-3,-3,2:85.0
3,2,1:85.0
-3,2,1:85.0
2,1,1:106.1
2,0,1:106.8
-2,0,1:106.2
1,-2,1:106.4
-1,-2,1:106.4
-2,-2,1:106.4
3,-3,1:85.0
-3,-3,1:85.0
2,3,0:38.5
-1,3,0:38.5
4,2,0:37.5
3,2,0:85.0
2,2,0:31.1
1,2,0:31.2
0,2,0:31.1
-1,2,0:31.1
-2,2,0:31.1
-3,2,0:85.0
3,1,0:31.1
0,1,0:38.5
-2,1,0:31.2
-3,1,0:31.1
-4,1,0:38.5
3,0,0:31.2
2,0,0:31.2
1,0,0:37.5
-1,0,0:31.2
-3,0,0:31.1
4,-1,0:40.5
2,-1,0:40.5
0,-1,0:31.2
-2,-1,0:40.5
-3,-1,0:31.1
-4,-1,0:38.5
3,-2,0:31.1
2,-2,0:31.1
1,-2,0:106.4
-1,-2,0:106.4
-2,-2,0:31.2
-3,-2,0:31.1
3,-3,0:85.0
2,-3,0:31.1
1,-3,0:31.2
0,-3,0:31.2
-1,-3,0:31.1
-2,-3,0:31.1
-3,-3,0:85.0
-4,-3,0:38.5
2,-4,0:39.5
0,-4,0:37.5
-2,-4,0:37.5
-3,-4,0:37.5
0,3,-1:106.2
-2,3,-1:106.8
