[META]
version=2.0
spawnOnBlockType=2
spawnSunlight=True
spawnDarkness=True
spawnWater=False
spawnLava=False
underFill=False
randomRotation=True
dig=True
tree=False
branch=False
needsFoundation=True
rarity=10
collisionPercentage=70
spawnElevationMin=0
spawnElevationMax=102
groupId=Ruins
groupFrequencyMin=20
groupFrequencyMax=35
groupSeperationMin=5
groupSeperationMax=60
branchLimit=6
spawnInBiome=Jungle
[DATA]
-2,0,-3:3.5
-1,0,-3:3.5
-2,1,-3:3.5
-1,1,-3:3.5
0,1,-3:3.5
1,1,-3:3.5
-2,2,-3:3.5
-1,2,-3:3.5
0,2,-3:3.5
1,2,-3:3.5
-2,-2,-2:3.5
-1,-2,-2:3.5
-2,-1,-2:3.5
-1,-1,-2:3.5
-3,0,-2:3.5
-2,0,-2:3.5
-1,0,-2:3.5
0,0,-2:3.5
1,0,-2:3.5
-3,1,-2:3.5
-2,1,-2:3.5
-1,1,-2:3.5
0,1,-2:3.5
1,1,-2:3.5
-3,2,-2:3.5
-2,2,-2:3.5
-1,2,-2:3.5
0,2,-2:3.5
1,2,-2:3.5
2,2,-2:3.5
-3,3,-2:3.5
-2,3,-2:3.5
-1,3,-2:3.5
0,3,-2:3.5
1,3,-2:3.5
-1,4,-2:3.5
0,4,-2:3.5
-2,-3,-1:2.0
-3,-2,-1:2.5
-2,-2,-1:48.5
-1,-2,-1:2.5
-4,-1,-1:2.5
-3,-1,-1:2.5
-2,-1,-1:4.0
-1,-1,-1:2.5
0,-1,-1:2.5
1,-1,-1:2.5
2,-1,-1:2.5
-4,0,-1:2.5
-3,0,-1:3.0
-2,0,-1:2.5
-1,0,-1:2.5
0,0,-1:2.5
1,0,-1:48.5
2,0,-1:97.0
-4,1,-1:2.5
-3,1,-1:2.5
-2,1,-1:2.5
-1,1,-1:2.5
0,1,-1:2.5
1,1,-1:3.0
2,1,-1:2.5
-4,2,-1:2.5
-3,2,-1:2.5
-2,2,-1:2.5
-1,2,-1:2.5
0,2,-1:2.5
1,2,-1:2.5
2,2,-1:2.5
-4,3,-1:2.5
-3,3,-1:2.5
-2,3,-1:2.5
-1,3,-1:2.5
0,3,-1:2.5
1,3,-1:48.5
2,3,-1:2.5
-4,4,-1:2.5
-3,4,-1:2.5
-2,4,-1:3.0
-1,4,-1:3.0
0,4,-1:4.0
1,4,-1:2.5
-3,5,-1:2.5
-2,5,-1:2.5
-1,5,-1:2.5
0,5,-1:2.5
-3,0,0:48.5
1,1,0:1.5
-3,3,0:30.0
-2,3,0:67.2
-2,4,0:4.0
-1,4,0:48.5
-2,4,1:4.0
-2,5,1:106.4
0,5,0:31.1
-1,5,0:106.4
-2,5,0:106.4
-3,4,0:31.2
1,2,0:106.4
-3,2,0:31.1
2,1,0:106.2
0,1,0:106.8
1,0,0:106.1
0,0,0:31.1
-2,0,0:106.2
-3,-1,0:31.1
