[META]
version=2.0
spawnOnBlockType=2
spawnSunlight=True
spawnDarkness=True
spawnWater=False
spawnLava=False
underFill=False
randomRotation=True
dig=True
tree=False
branch=False
needsFoundation=True
rarity=100
collisionPercentage=10
spawnElevationMin=0
spawnElevationMax=102
groupId=Ruins
groupFrequencyMin=20
groupFrequencyMax=35
groupSeperationMin=5
groupSeperationMax=60
branchLimit=6
spawnInBiome=Jungle
[DATA]
2,-3,-5:1.5
0,-2,-5:1.5
1,-2,-5:1.5
2,-2,-5:1.5
3,-2,-5:1.5
0,-1,-5:1.5
1,-1,-5:1.5
2,-1,-5:1.5
1,0,-5:1.5
2,0,-5:1.5
2,-5,-4:2.0
0,-4,-4:1.5
1,-4,-4:1.5
2,-4,-4:3.5
3,-4,-4:1.5
-1,-3,-4:1.5
0,-3,-4:3.5
1,-3,-4:3.5
2,-3,-4:3.5
3,-3,-4:1.5
-2,-2,-4:1.5
-1,-2,-4:1.5
0,-2,-4:3.5
1,-2,-4:3.5
2,-2,-4:1.5
3,-2,-4:1.5
-2,-1,-4:1.5
-1,-1,-4:1.5
0,-1,-4:1.5
1,-1,-4:3.5
2,-1,-4:3.5
3,-1,-4:1.5
-1,0,-4:1.5
0,0,-4:1.5
1,0,-4:1.5
2,0,-4:1.5
3,0,-4:1.5
0,1,-4:1.5
1,1,-4:1.5
2,1,-4:1.5
-1,-6,-3:3.5
-3,-5,-3:3.5
-2,-5,-3:1.5
-1,-5,-3:1.5
0,-5,-3:1.5
1,-5,-3:1.5
-3,-4,-3:1.5
-2,-4,-3:1.5
-1,-4,-3:1.5
0,-4,-3:1.5
1,-4,-3:1.5
2,-4,-3:1.5
3,-4,-3:1.5
4,-4,-3:3.5
-3,-3,-3:1.5
-2,-3,-3:3.5
-1,-3,-3:3.5
0,-3,-3:3.5
1,-3,-3:3.5
2,-3,-3:1.5
3,-3,-3:1.5
4,-3,-3:1.5
5,-3,-3:3.5
-3,-2,-3:1.5
-2,-2,-3:1.5
-1,-2,-3:1.5
0,-2,-3:3.5
1,-2,-3:3.5
2,-2,-3:1.5
3,-2,-3:1.5
4,-2,-3:1.5
5,-2,-3:1.5
-3,-1,-3:1.5
-2,-1,-3:3.5
-1,-1,-3:1.5
0,-1,-3:1.5
1,-1,-3:1.5
2,-1,-3:1.5
3,-1,-3:1.5
4,-1,-3:1.5
5,-1,-3:3.5
-3,0,-3:1.5
-2,0,-3:1.5
-1,0,-3:1.5
0,0,-3:1.5
1,0,-3:1.5
2,0,-3:1.5
3,0,-3:1.5
4,0,-3:1.5
5,0,-3:3.5
-3,1,-3:3.5
-2,1,-3:1.5
-1,1,-3:1.5
0,1,-3:3.5
1,1,-3:3.5
2,1,-3:3.5
3,1,-3:1.5
4,1,-3:3.5
-2,2,-3:3.5
-1,2,-3:1.5
0,2,-3:1.5
1,2,-3:1.5
2,2,-3:1.5
3,2,-3:3.5
-1,-7,-2:3.5
-2,-6,-2:1.5
-1,-6,-2:3.5
0,-6,-2:3.5
1,-6,-2:3.5
2,-6,-2:3.5
4,-6,-2:3.5
-4,-5,-2:1.5
-3,-5,-2:3.5
-2,-5,-2:1.5
-1,-5,-2:1.5
0,-5,-2:1.5
1,-5,-2:1.5
2,-5,-2:1.5
3,-5,-2:1.5
4,-5,-2:3.5
6,-5,-2:3.5
-5,-4,-2:1.5
-4,-4,-2:1.5
-3,-4,-2:1.5
-2,-4,-2:1.5
-1,-4,-2:3.5
0,-4,-2:1.5
1,-4,-2:1.5
2,-4,-2:3.5
3,-4,-2:1.5
4,-4,-2:1.5
5,-4,-2:1.5
6,-4,-2:3.5
-4,-3,-2:1.5
-3,-3,-2:3.5
-2,-3,-2:1.5
-1,-3,-2:1.5
0,-3,-2:3.5
1,-3,-2:3.5
2,-3,-2:1.5
3,-3,-2:3.5
4,-3,-2:3.5
5,-3,-2:1.5
6,-3,-2:3.5
-5,-2,-2:1.5
-4,-2,-2:1.5
-3,-2,-2:1.5
-2,-2,-2:1.5
-1,-2,-2:1.5
0,-2,-2:3.5
1,-2,-2:3.5
2,-2,-2:3.5
3,-2,-2:1.5
4,-2,-2:1.5
5,-2,-2:1.5
6,-2,-2:1.5
-5,-1,-2:1.5
-4,-1,-2:1.5
-3,-1,-2:1.5
-2,-1,-2:3.5
-1,-1,-2:1.5
0,-1,-2:1.5
1,-1,-2:1.5
2,-1,-2:1.5
3,-1,-2:1.5
4,-1,-2:3.5
5,-1,-2:1.5
6,-1,-2:3.5
-4,0,-2:3.5
-3,0,-2:1.5
-2,0,-2:1.5
-1,0,-2:3.5
0,0,-2:3.5
1,0,-2:1.5
2,0,-2:1.5
3,0,-2:1.5
4,0,-2:1.5
5,0,-2:3.5
6,0,-2:3.5
-4,1,-2:1.5
-3,1,-2:1.5
-2,1,-2:1.5
-1,1,-2:3.5
0,1,-2:1.5
1,1,-2:1.5
2,1,-2:1.5
3,1,-2:1.5
4,1,-2:3.5
5,1,-2:3.5
6,1,-2:1.5
-3,2,-2:1.5
-2,2,-2:3.5
-1,2,-2:3.5
0,2,-2:3.5
1,2,-2:3.5
2,2,-2:3.5
3,2,-2:3.5
4,2,-2:3.5
5,2,-2:3.5
-3,3,-2:1.5
-2,3,-2:1.5
-1,3,-2:1.5
0,3,-2:3.5
1,3,-2:3.5
2,3,-2:1.5
3,3,-2:1.5
4,3,-2:1.5
0,4,-2:3.5
1,4,-2:3.5
2,4,-2:3.5
3,4,-2:1.5
4,4,-2:3.5
-3,-7,-1:2.0
-2,-7,-1:2.0
-1,-7,-1:2.0
0,-7,-1:2.0
1,-7,-1:2.0
2,-7,-1:2.0
3,-7,-1:2.0
4,-7,-1:2.0
-5,-6,-1:2.0
-4,-6,-1:2.0
-3,-6,-1:2.0
-2,-6,-1:2.0
-1,-6,-1:2.0
0,-6,-1:2.0
1,-6,-1:2.0
2,-6,-1:2.0
3,-6,-1:2.0
4,-6,-1:2.0
5,-6,-1:2.0
-6,-5,-1:2.0
-5,-5,-1:2.0
-4,-5,-1:2.0
-3,-5,-1:2.0
-2,-5,-1:3.0
-1,-5,-1:3.0
0,-5,-1:2.0
1,-5,-1:2.0
2,-5,-1:3.0
3,-5,-1:2.0
4,-5,-1:2.0
5,-5,-1:2.0
6,-5,-1:2.0
7,-5,-1:2.0
-6,-4,-1:2.0
-5,-4,-1:2.0
-4,-4,-1:2.0
-3,-4,-1:3.0
-2,-4,-1:3.0
-1,-4,-1:3.0
0,-4,-1:3.5
1,-4,-1:3.0
2,-4,-1:2.0
3,-4,-1:2.0
4,-4,-1:2.0
5,-4,-1:3.0
6,-4,-1:2.0
-5,-3,-1:2.0
-4,-3,-1:3.0
-3,-3,-1:3.0
-2,-3,-1:3.0
-1,-3,-1:3.0
0,-3,-1:3.0
1,-3,-1:2.0
2,-3,-1:3.0
3,-3,-1:2.0
4,-3,-1:2.0
5,-3,-1:2.0
6,-3,-1:2.0
7,-3,-1:2.0
-6,-2,-1:2.0
-5,-2,-1:2.0
-4,-2,-1:3.0
-3,-2,-1:3.0
-2,-2,-1:3.0
-1,-2,-1:3.0
0,-2,-1:2.0
1,-2,-1:2.0
2,-2,-1:2.0
3,-2,-1:3.0
4,-2,-1:2.0
5,-2,-1:2.0
6,-2,-1:2.0
-6,-1,-1:2.0
-5,-1,-1:2.0
-4,-1,-1:2.0
-3,-1,-1:3.0
-2,-1,-1:3.0
-1,-1,-1:2.0
0,-1,-1:2.0
1,-1,-1:3.0
2,-1,-1:3.0
3,-1,-1:2.0
4,-1,-1:3.0
5,-1,-1:2.0
6,-1,-1:2.0
7,-1,-1:2.0
-4,0,-1:2.0
-3,0,-1:2.0
-2,0,-1:2.0
-1,0,-1:3.0
0,0,-1:2.0
1,0,-1:3.0
2,0,-1:2.0
3,0,-1:3.0
4,0,-1:3.0
5,0,-1:2.0
6,0,-1:2.0
7,0,-1:2.0
-5,1,-1:2.0
-4,1,-1:2.0
-3,1,-1:2.0
-2,1,-1:2.0
-1,1,-1:2.0
0,1,-1:3.0
1,1,-1:2.0
2,1,-1:3.0
3,1,-1:2.0
4,1,-1:2.0
5,1,-1:3.0
6,1,-1:2.0
7,1,-1:2.0
-5,2,-1:2.0
-4,2,-1:2.0
-3,2,-1:2.0
-2,2,-1:2.0
-1,2,-1:2.0
0,2,-1:2.0
1,2,-1:3.0
2,2,-1:2.0
3,2,-1:2.0
4,2,-1:3.0
5,2,-1:3.0
6,2,-1:2.0
7,2,-1:2.0
-4,3,-1:2.0
-3,3,-1:2.0
-2,3,-1:2.0
-1,3,-1:2.0
0,3,-1:2.0
1,3,-1:2.0
2,3,-1:2.0
3,3,-1:3.0
4,3,-1:3.0
5,3,-1:3.0
6,3,-1:2.0
-4,4,-1:2.0
-2,4,-1:2.0
-1,4,-1:2.0
0,4,-1:2.0
1,4,-1:2.0
2,4,-1:2.0
3,4,-1:2.0
4,4,-1:2.0
5,4,-1:2.0
-2,5,-1:2.0
0,5,-1:2.0
1,5,-1:2.0
5,5,-1:2.0
-2,-6,0:44.5
-1,-6,0:44.5
3,-6,0:44.5
4,-6,0:44.5
-3,-5,0:44.5
-2,-5,0:98.0
-1,-5,0:98.1
0,-5,0:98.0
1,-5,0:98.0
2,-5,0:98.0
3,-5,0:98.0
4,-5,0:98.0
5,-5,0:44.5
-4,-4,0:44.5
-3,-4,0:98.0
-2,-4,0:98.0
-1,-4,0:98.1
0,-4,0:98.1
1,-4,0:98.0
2,-4,0:98.0
3,-4,0:98.0
4,-4,0:98.1
5,-4,0:98.0
6,-4,0:44.5
-4,-3,0:44.5
-3,-3,0:98.0
-2,-3,0:17.3
-1,-3,0:98.0
0,-3,0:98.0
1,-3,0:98.1
2,-3,0:98.0
3,-3,0:98.1
4,-3,0:98.1
5,-3,0:98.1
-4,-2,0:103.0
-3,-2,0:98.1
-2,-2,0:98.1
-1,-2,0:98.0
0,-2,0:9.0
1,-2,0:98.1
2,-2,0:98.2
3,-2,0:98.0
4,-2,0:98.2
-3,-1,0:98.0
-2,-1,0:98.0
-1,-1,0:98.1
0,-1,0:9.0
1,-1,0:98.0
2,-1,0:98.2
3,-1,0:98.1
4,-1,0:98.0
5,-1,0:98.1
-3,0,0:98.0
-2,0,0:98.1
-1,0,0:98.0
0,0,0:98.1
1,0,0:98.1
2,0,0:9.0
3,0,0:98.0
4,0,0:98.0
5,0,0:98.1
6,0,0:44.5
-4,1,0:44.5
-3,1,0:98.2
-2,1,0:98.2
-1,1,0:98.0
0,1,0:98.0
1,1,0:98.1
2,1,0:98.0
3,1,0:98.2
4,1,0:98.0
5,1,0:98.0
6,1,0:44.5
-4,2,0:44.5
-3,2,0:98.0
-2,2,0:98.0
-1,2,0:98.2
0,2,0:98.1
1,2,0:98.0
2,2,0:98.1
3,2,0:98.1
4,2,0:98.2
5,2,0:98.0
6,2,0:44.5
-2,3,0:98.0
-1,3,0:98.1
0,3,0:98.1
1,3,0:98.0
2,3,0:98.0
3,3,0:103.0
4,3,0:98.0
5,3,0:17.3
-2,4,0:44.5
-1,4,0:44.5
1,4,0:44.5
2,4,0:44.5
4,4,0:44.5
2,-5,1:30.0
1,-4,1:44.5
5,-4,1:30.0
-2,-3,1:17.3
0,-3,1:44.5
2,-3,1:44.5
-1,-2,1:44.5
3,-2,1:44.5
-2,-1,1:44.5
1,-1,1:98.2
2,-1,1:30.0
4,-1,1:44.5
-1,0,1:44.5
3,0,1:44.5
4,0,1:30.0
0,1,1:44.5
2,1,1:44.5
1,2,1:44.5
5,2,1:30.0
5,3,1:17.3
-2,-3,2:17.3
1,-1,2:98.2
1,0,2:30.0
5,3,2:17.3
-2,-3,3:17.3
1,-1,3:98.1
5,2,3:18.14
4,3,3:18.14
5,3,3:17.3
6,3,3:18.14
-3,-5,4:18.14
-2,-5,4:18.14
-1,-5,4:18.14
-4,-4,4:18.14
-3,-4,4:18.14
-2,-4,4:18.14
-1,-4,4:18.14
0,-4,4:18.14
-5,-3,4:18.14
-4,-3,4:18.14
-3,-3,4:18.14
-2,-3,4:17.3
-1,-3,4:18.14
0,-3,4:18.14
-4,-2,4:18.14
-3,-2,4:18.14
-2,-2,4:18.14
-1,-2,4:18.14
-3,-1,4:18.14
-2,-1,4:18.14
1,-1,4:98.0
5,1,4:18.14
4,2,4:18.14
5,2,4:18.14
6,2,4:18.14
3,3,4:18.14
4,3,4:18.14
5,3,4:17.3
6,3,4:18.14
7,3,4:18.14
4,4,4:18.14
5,4,4:18.14
6,4,4:18.14
5,5,4:18.14
-2,-4,5:18.14
-3,-3,5:18.14
-2,-3,5:17.3
-1,-3,5:18.14
-2,-2,5:18.14
1,-1,5:98.1
5,3,5:18.14
-2,-3,6:18.14
1,0,5:106.4
6,5,4:106.2
4,5,4:106.4
7,4,4:106.4
3,4,4:106.8
7,2,4:106.2
3,2,4:106.8
6,1,4:106.2
5,0,4:106.1
1,0,4:106.4
-2,0,4:106.4
-3,0,4:106.4
2,-1,4:106.2
0,-1,4:106.8
-4,-1,4:106.4
-5,-2,4:106.8
1,-3,4:106.2
1,-4,4:106.2
-5,-4,4:106.8
0,-5,4:106.2
-4,-5,4:106.8
-1,-6,4:106.1
-2,-6,4:106.1
-3,-6,4:106.1
6,5,3:106.2
4,5,3:106.4
7,4,3:106.4
3,4,3:106.8
7,2,3:106.2
3,2,3:106.8
6,1,3:106.2
5,0,3:106.1
1,0,3:106.4
-3,0,3:106.4
2,-1,3:106.2
0,-1,3:106.8
-4,-1,3:106.4
-2,-2,3:106.4
-5,-2,3:106.8
1,-3,3:106.2
1,-4,3:106.2
-5,-4,3:106.8
0,-5,3:106.2
-1,-6,3:106.1
-2,-6,3:106.1
-3,-6,3:106.1
6,5,2:106.2
4,5,2:106.4
7,4,2:106.4
3,4,2:106.8
3,2,2:106.8
6,1,2:106.2
5,0,2:106.1
-3,0,2:106.4
2,-1,2:106.2
0,-1,2:106.8
-4,-1,2:106.4
-2,-2,2:106.4
-5,-2,2:106.8
1,-3,2:106.2
1,-4,2:106.2
-5,-4,2:106.8
0,-5,2:106.2
-2,-6,2:106.1
-3,-6,2:106.1
6,5,1:106.2
4,5,1:106.4
3,4,1:106.8
2,3,1:40.5
3,2,1:106.8
-3,2,1:40.5
-1,1,1:40.5
5,0,1:106.1
-3,0,1:106.4
0,-1,1:111.0
-4,-1,1:106.4
4,-2,1:39.5
0,-2,1:111.0
-2,-2,1:106.4
-5,-2,1:106.8
1,-3,1:106.2
2,-4,1:40.5
-5,-4,1:106.8
0,-5,1:40.5
-2,-6,1:106.1
-3,-6,1:106.1
5,5,0:37.5
1,5,0:31.2
0,5,0:38.5
-2,5,0:31.1
5,4,0:31.2
3,4,0:37.5
0,4,0:31.1
-4,4,0:38.5
-3,3,0:31.1
-4,3,0:31.1
7,2,0:31.1
-5,2,0:31.1
7,1,0:37.5
-5,1,0:31.2
7,0,0:31.2
-4,0,0:38.5
7,-1,0:31.1
6,-1,0:31.2
-4,-1,0:38.5
-6,-1,0:31.1
6,-2,0:38.5
5,-2,0:37.5
-5,-2,0:31.2
-6,-2,0:37.5
7,-3,0:38.5
6,-3,0:31.2
-5,-3,0:38.5
-5,-4,0:31.1
-6,-4,0:37.5
7,-5,0:31.1
6,-5,0:39.5
-4,-5,0:31.1
-5,-5,0:31.2
5,-6,0:31.1
2,-6,0:106.1
1,-6,0:31.1
0,-6,0:31.1
-3,-6,0:31.1
-4,-6,0:31.2
-5,-6,0:31.1
4,-7,0:38.5
3,-7,0:31.1
2,-7,0:31.2
1,-7,0:31.1
0,-7,0:31.2
-1,-7,0:38.5
-2,-7,0:31.1
-3,-7,0:31.1
