[META]
version=2.0
spawnOnBlockType=2
spawnSunlight=True
spawnDarkness=True
spawnWater=False
spawnLava=False
underFill=False
randomRotation=True
dig=True
tree=False
branch=False
needsFoundation=True
rarity=40
collisionPercentage=10
spawnElevationMin=0
spawnElevationMax=102
groupId=Ruins
groupFrequencyMin=20
groupFrequencyMax=35
groupSeperationMin=5
groupSeperationMax=60
branchLimit=6
spawnInBiome=Jungle
[DATA]
0,-2,-5:1.5
1,-2,-5:15.5
2,-2,-5:15.5
-1,-1,-5:1.5
0,-1,-5:1.5
1,-1,-5:1.5
2,-1,-5:1.5
-1,0,-5:1.5
0,0,-5:1.5
1,0,-5:1.5
2,0,-5:1.5
-1,1,-5:1.5
0,1,-5:1.5
1,1,-5:1.5
2,1,-5:1.5
-1,-3,-4:1.5
0,-3,-4:1.5
1,-3,-4:1.5
2,-3,-4:1.5
-2,-2,-4:1.5
-1,-2,-4:1.5
0,-2,-4:1.5
1,-2,-4:15.5
2,-2,-4:15.5
3,-2,-4:1.5
4,-2,-4:1.5
-2,-1,-4:1.5
-1,-1,-4:1.5
0,-1,-4:1.5
1,-1,-4:1.5
2,-1,-4:1.5
3,-1,-4:1.5
4,-1,-4:1.5
-2,0,-4:1.5
-1,0,-4:1.5
0,0,-4:1.5
1,0,-4:16.5
2,0,-4:1.5
3,0,-4:1.5
4,0,-4:1.5
-2,1,-4:1.5
-1,1,-4:1.5
0,1,-4:1.5
1,1,-4:16.5
2,1,-4:1.5
3,1,-4:1.5
4,1,-4:1.5
-1,2,-4:1.5
0,2,-4:1.5
1,2,-4:1.5
2,2,-4:1.5
3,2,-4:1.5
-4,-5,-3:3.0
-3,-5,-3:3.0
-2,-5,-3:3.0
-1,-5,-3:3.0
0,-5,-3:3.0
1,-5,-3:3.0
2,-5,-3:3.0
3,-5,-3:3.0
4,-5,-3:3.0
5,-5,-3:3.0
6,-5,-3:3.0
-4,-4,-3:3.0
-3,-4,-3:3.0
-2,-4,-3:3.0
-1,-4,-3:3.0
0,-4,-3:3.0
1,-4,-3:3.0
2,-4,-3:3.0
3,-4,-3:3.0
4,-4,-3:3.0
5,-4,-3:3.0
6,-4,-3:3.0
-4,-3,-3:3.0
-3,-3,-3:3.0
-2,-3,-3:3.0
-1,-3,-3:3.0
0,-3,-3:3.0
1,-3,-3:3.0
2,-3,-3:3.0
3,-3,-3:3.0
4,-3,-3:3.0
5,-3,-3:3.0
6,-3,-3:3.0
-4,-2,-3:3.0
-3,-2,-3:3.0
-2,-2,-3:1.5
-1,-2,-3:1.5
0,-2,-3:1.5
1,-2,-3:1.5
2,-2,-3:1.5
3,-2,-3:1.5
4,-2,-3:3.0
5,-2,-3:3.0
6,-2,-3:3.0
-4,-1,-3:3.0
-3,-1,-3:3.0
-2,-1,-3:1.5
-1,-1,-3:1.5
0,-1,-3:1.5
1,-1,-3:16.5
2,-1,-3:1.5
3,-1,-3:1.5
4,-1,-3:3.0
5,-1,-3:3.0
6,-1,-3:3.0
-4,0,-3:3.0
-3,0,-3:3.0
-2,0,-3:1.5
-1,0,-3:1.5
0,0,-3:1.5
1,0,-3:16.5
2,0,-3:1.5
3,0,-3:1.5
4,0,-3:3.0
5,0,-3:3.0
6,0,-3:3.0
-4,1,-3:3.0
-3,1,-3:3.0
-2,1,-3:1.5
-1,1,-3:1.5
0,1,-3:1.5
1,1,-3:1.5
2,1,-3:1.5
3,1,-3:1.5
4,1,-3:3.0
5,1,-3:3.0
6,1,-3:3.0
-4,2,-3:3.0
-3,2,-3:3.0
-2,2,-3:3.0
-1,2,-3:3.0
0,2,-3:3.0
1,2,-3:3.0
2,2,-3:3.0
3,2,-3:3.0
4,2,-3:3.0
5,2,-3:3.0
6,2,-3:3.0
-4,3,-3:3.0
-3,3,-3:3.0
-2,3,-3:3.0
-1,3,-3:3.0
0,3,-3:3.0
1,3,-3:3.0
2,3,-3:3.0
3,3,-3:3.0
4,3,-3:3.0
5,3,-3:3.0
6,3,-3:3.0
-5,-6,-2:3.0
-4,-6,-2:3.0
-3,-6,-2:3.0
-2,-6,-2:3.0
-1,-6,-2:3.0
0,-6,-2:3.0
1,-6,-2:3.0
2,-6,-2:3.0
3,-6,-2:3.0
4,-6,-2:3.0
5,-6,-2:3.0
6,-6,-2:3.0
7,-6,-2:3.0
-5,-5,-2:3.0
-4,-5,-2:3.0
-3,-5,-2:3.0
-2,-5,-2:3.0
-1,-5,-2:3.0
0,-5,-2:3.0
1,-5,-2:3.0
2,-5,-2:3.0
3,-5,-2:3.0
4,-5,-2:3.0
5,-5,-2:3.0
6,-5,-2:3.0
7,-5,-2:3.0
-5,-4,-2:3.0
-4,-4,-2:3.0
-3,-4,-2:3.0
-2,-4,-2:3.0
-1,-4,-2:3.0
0,-4,-2:3.0
1,-4,-2:3.0
2,-4,-2:3.0
3,-4,-2:3.0
4,-4,-2:3.0
5,-4,-2:3.0
6,-4,-2:3.0
7,-4,-2:3.0
-5,-3,-2:3.0
-4,-3,-2:3.0
-3,-3,-2:3.0
-2,-3,-2:3.0
-1,-3,-2:3.0
0,-3,-2:3.0
1,-3,-2:3.0
2,-3,-2:3.0
3,-3,-2:3.0
4,-3,-2:3.0
5,-3,-2:3.0
6,-3,-2:3.0
7,-3,-2:3.0
-5,-2,-2:3.0
-4,-2,-2:3.0
-3,-2,-2:3.0
-2,-2,-2:3.0
-1,-2,-2:3.0
0,-2,-2:3.0
1,-2,-2:3.0
2,-2,-2:3.0
3,-2,-2:3.0
4,-2,-2:3.0
5,-2,-2:3.0
6,-2,-2:3.0
7,-2,-2:3.0
-5,-1,-2:3.0
-4,-1,-2:3.0
-3,-1,-2:3.0
-2,-1,-2:3.0
-1,-1,-2:3.0
0,-1,-2:3.0
1,-1,-2:3.0
2,-1,-2:3.0
3,-1,-2:3.0
4,-1,-2:3.0
5,-1,-2:3.0
6,-1,-2:3.0
7,-1,-2:3.0
-5,0,-2:3.0
-4,0,-2:3.0
-3,0,-2:3.0
-2,0,-2:3.0
-1,0,-2:3.0
0,0,-2:3.0
1,0,-2:3.0
2,0,-2:3.0
3,0,-2:3.0
4,0,-2:3.0
5,0,-2:3.0
6,0,-2:3.0
7,0,-2:3.0
-5,1,-2:3.0
-4,1,-2:3.0
-3,1,-2:3.0
-2,1,-2:3.0
-1,1,-2:3.0
0,1,-2:3.0
1,1,-2:3.0
2,1,-2:3.0
3,1,-2:3.0
4,1,-2:3.0
5,1,-2:3.0
6,1,-2:3.0
7,1,-2:3.0
-5,2,-2:3.0
-4,2,-2:3.0
-3,2,-2:3.0
-2,2,-2:3.0
-1,2,-2:3.0
0,2,-2:3.0
1,2,-2:3.0
2,2,-2:3.0
3,2,-2:3.0
4,2,-2:3.0
5,2,-2:3.0
6,2,-2:3.0
7,2,-2:3.0
-5,3,-2:3.0
-4,3,-2:3.0
-3,3,-2:3.0
-2,3,-2:3.0
-1,3,-2:3.0
0,3,-2:3.0
1,3,-2:3.0
2,3,-2:3.0
3,3,-2:3.0
4,3,-2:3.0
5,3,-2:3.0
6,3,-2:3.0
7,3,-2:3.0
-5,4,-2:3.0
-4,4,-2:3.0
-3,4,-2:3.0
-2,4,-2:3.0
-1,4,-2:3.0
0,4,-2:3.0
1,4,-2:3.0
2,4,-2:3.0
3,4,-2:3.0
4,4,-2:3.0
5,4,-2:3.0
6,4,-2:3.0
7,4,-2:3.0
-6,-7,-1:98.1
-5,-7,-1:98.1
-4,-7,-1:98.0
-3,-7,-1:98.0
-2,-7,-1:2.5
-1,-7,-1:2.5
0,-7,-1:98.0
1,-7,-1:98.0
2,-7,-1:98.0
3,-7,-1:98.0
4,-7,-1:98.0
5,-7,-1:2.5
6,-7,-1:98.0
7,-7,-1:98.0
8,-7,-1:98.0
-6,-6,-1:98.0
-5,-6,-1:48.5
-4,-6,-1:48.5
-3,-6,-1:43.0
-2,-6,-1:43.0
-1,-6,-1:2.5
0,-6,-1:2.5
1,-6,-1:43.0
2,-6,-1:43.0
3,-6,-1:43.0
4,-6,-1:43.0
5,-6,-1:2.5
6,-6,-1:43.0
7,-6,-1:48.5
8,-6,-1:98.0
-6,-5,-1:98.0
-5,-5,-1:48.5
-4,-5,-1:98.3
-3,-5,-1:98.1
-2,-5,-1:98.1
-1,-5,-1:2.5
0,-5,-1:3.0
1,-5,-1:98.0
2,-5,-1:98.0
3,-5,-1:98.0
4,-5,-1:2.5
5,-5,-1:98.0
6,-5,-1:98.3
7,-5,-1:43.0
8,-5,-1:98.0
-6,-4,-1:98.0
-5,-4,-1:2.5
-4,-4,-1:2.5
-3,-4,-1:43.0
-2,-4,-1:43.0
-1,-4,-1:43.0
0,-4,-1:2.5
1,-4,-1:43.0
2,-4,-1:43.0
3,-4,-1:43.0
4,-4,-1:2.5
5,-4,-1:43.0
6,-4,-1:98.0
7,-4,-1:2.5
8,-4,-1:2.5
-6,-3,-1:2.5
-5,-3,-1:2.5
-4,-3,-1:98.1
-3,-3,-1:43.0
-2,-3,-1:98.0
-1,-3,-1:98.3
0,-3,-1:49.5
1,-3,-1:49.5
2,-3,-1:49.5
3,-3,-1:98.3
4,-3,-1:98.0
5,-3,-1:43.0
6,-3,-1:98.1
7,-3,-1:43.0
8,-3,-1:98.0
-6,-2,-1:98.0
-5,-2,-1:43.0
-4,-2,-1:98.1
-3,-2,-1:43.0
-2,-2,-1:98.3
-1,-2,-1:49.5
0,-2,-1:48.5
1,-2,-1:4.0
2,-2,-1:4.0
3,-2,-1:49.5
4,-2,-1:2.5
5,-2,-1:43.0
6,-2,-1:98.1
7,-2,-1:43.0
8,-2,-1:98.0
-6,-1,-1:98.0
-5,-1,-1:43.0
-4,-1,-1:98.2
-3,-1,-1:43.0
-2,-1,-1:49.5
-1,-1,-1:48.5
0,-1,-1:48.5
1,-1,-1:42.0
2,-1,-1:48.5
3,-1,-1:4.0
4,-1,-1:49.5
5,-1,-1:43.0
6,-1,-1:98.1
7,-1,-1:43.0
8,-1,-1:98.0
-6,0,-1:98.0
-5,0,-1:43.0
-4,0,-1:98.2
-3,0,-1:43.0
-2,0,-1:98.3
-1,0,-1:49.5
0,0,-1:4.0
1,0,-1:48.5
2,0,-1:48.5
3,0,-1:49.5
4,0,-1:98.3
5,0,-1:43.0
6,0,-1:98.0
7,0,-1:43.0
8,0,-1:98.0
-6,1,-1:98.2
-5,1,-1:43.0
-4,1,-1:98.1
-3,1,-1:43.0
-2,1,-1:98.1
-1,1,-1:98.3
0,1,-1:49.5
1,1,-1:49.5
2,1,-1:49.5
3,1,-1:98.3
4,1,-1:98.1
5,1,-1:43.0
6,1,-1:2.5
7,1,-1:2.5
8,1,-1:98.0
-6,2,-1:98.2
-5,2,-1:43.0
-4,2,-1:98.1
-3,2,-1:43.0
-2,2,-1:43.0
-1,2,-1:43.0
0,2,-1:43.0
1,2,-1:43.0
2,2,-1:43.0
3,2,-1:43.0
4,2,-1:43.0
5,2,-1:3.0
6,2,-1:2.5
7,2,-1:43.0
8,2,-1:98.0
-6,3,-1:98.0
-5,3,-1:43.0
-4,3,-1:98.3
-3,3,-1:98.0
-2,3,-1:98.0
-1,3,-1:98.0
0,3,-1:2.5
1,3,-1:2.5
2,3,-1:98.0
3,3,-1:98.1
4,3,-1:98.1
5,3,-1:98.0
6,3,-1:98.0
7,3,-1:43.0
8,3,-1:98.0
-6,4,-1:2.5
-5,4,-1:48.5
-4,4,-1:43.0
-3,4,-1:43.0
-2,4,-1:43.0
-1,4,-1:43.0
0,4,-1:2.5
1,4,-1:43.0
2,4,-1:43.0
3,4,-1:43.0
4,4,-1:2.5
5,4,-1:43.0
6,4,-1:43.0
7,4,-1:48.5
8,4,-1:98.0
-6,5,-1:2.5
-5,5,-1:98.0
-4,5,-1:98.0
-3,5,-1:98.1
-2,5,-1:98.1
-1,5,-1:98.0
0,5,-1:98.1
1,5,-1:98.1
2,5,-1:98.0
3,5,-1:98.0
4,5,-1:98.0
5,5,-1:98.0
6,5,-1:98.0
7,5,-1:98.0
8,5,-1:98.0
-5,-6,0:4.0
-4,-6,0:48.5
6,-6,0:48.5
7,-6,0:48.5
8,-6,0:48.5
-5,-5,0:48.5
-4,-5,0:30.0
0,-5,0:17.3
7,-5,0:48.5
5,2,0:17.3
-5,3,0:48.5
-3,3,0:48.5
-2,3,0:48.5
6,3,0:30.0
7,3,0:48.5
-5,4,0:48.5
-4,4,0:48.5
5,4,0:48.5
6,4,0:48.5
7,4,0:48.5
-5,-6,1:4.0
-4,-6,1:48.5
6,-6,1:48.5
7,-6,1:48.5
-5,-5,1:48.5
0,-5,1:17.3
7,-5,1:48.5
5,2,1:17.3
-5,3,1:48.5
-4,3,1:30.0
7,3,1:48.5
-5,4,1:48.5
-4,4,1:48.5
7,4,1:48.5
-5,-6,2:48.5
7,-6,2:48.5
0,-5,2:17.3
7,-5,2:30.0
5,2,2:17.3
7,4,2:48.5
-5,-6,3:48.5
0,-5,3:17.3
5,2,3:17.3
7,4,3:48.5
-2,-7,4:18.3
-1,-7,4:18.3
0,-7,4:18.3
1,-7,4:18.3
-2,-6,4:18.3
-1,-6,4:18.3
0,-6,4:18.3
1,-6,4:18.3
2,-6,4:18.3
-2,-5,4:18.3
-1,-5,4:18.3
0,-5,4:17.3
1,-5,4:18.3
2,-5,4:18.3
-2,-4,4:18.3
-1,-4,4:18.3
0,-4,4:18.3
1,-4,4:18.3
2,-4,4:18.3
-2,-3,4:18.3
-1,-3,4:18.3
0,-3,4:18.3
1,-3,4:18.3
5,2,4:17.3
-2,-7,5:18.3
-1,-7,5:18.3
0,-7,5:18.3
1,-7,5:18.3
2,-7,5:18.3
-2,-6,5:18.3
-1,-6,5:18.3
0,-6,5:18.3
1,-6,5:18.3
2,-6,5:18.3
-2,-5,5:18.3
-1,-5,5:18.3
0,-5,5:17.3
1,-5,5:18.3
2,-5,5:18.3
-2,-4,5:18.3
-1,-4,5:18.3
0,-4,5:18.3
1,-4,5:18.3
2,-4,5:18.3
-1,-3,5:18.3
0,-3,5:18.3
1,-3,5:18.3
3,0,5:18.3
4,0,5:18.3
5,0,5:18.3
6,0,5:18.3
7,0,5:18.3
3,1,5:18.3
4,1,5:18.3
5,1,5:18.3
6,1,5:18.3
7,1,5:18.3
3,2,5:18.3
4,2,5:18.3
5,2,5:17.3
6,2,5:18.3
7,2,5:18.3
3,3,5:18.3
4,3,5:18.3
5,3,5:18.3
6,3,5:18.3
7,3,5:18.3
3,4,5:18.3
4,4,5:18.3
5,4,5:18.3
6,4,5:18.3
7,4,5:18.3
-1,-6,6:18.3
0,-6,6:18.3
-1,-5,6:18.3
0,-5,6:17.3
1,-5,6:18.3
-1,-4,6:18.3
0,-4,6:18.3
4,0,6:18.3
5,0,6:18.3
6,0,6:18.3
7,0,6:18.3
3,1,6:18.3
4,1,6:18.3
5,1,6:18.3
6,1,6:18.3
7,1,6:18.3
3,2,6:18.3
4,2,6:18.3
5,2,6:17.3
6,2,6:18.3
7,2,6:18.3
3,3,6:18.3
4,3,6:18.3
5,3,6:18.3
6,3,6:18.3
7,3,6:18.3
4,4,6:18.3
5,4,6:18.3
6,4,6:18.3
0,-6,7:18.3
-1,-5,7:18.3
0,-5,7:18.3
1,-5,7:18.3
0,-4,7:18.3
5,1,7:18.3
4,2,7:18.3
5,2,7:17.3
6,2,7:18.3
5,3,7:18.3
6,3,7:18.3
5,1,8:18.3
4,2,8:18.3
5,2,8:18.3
6,2,8:18.3
5,3,8:18.3
5,5,6:106.4
8,2,6:106.2
4,-1,6:106.1
5,5,5:106.4
3,5,5:106.4
8,3,5:106.2
2,3,5:106.8
8,2,5:106.2
2,1,5:106.8
8,0,5:106.2
6,-1,5:106.1
4,-1,5:106.1
0,-2,5:106.4
3,-4,5:106.2
-3,-6,5:106.8
-3,-7,5:106.8
5,5,4:106.4
3,5,4:106.4
2,3,4:106.8
8,2,4:106.2
2,1,4:106.8
8,0,4:106.2
6,-1,4:106.1
4,-1,4:106.1
0,-2,4:106.4
3,-4,4:106.2
-3,-4,4:106.8
3,-6,4:106.2
-3,-6,4:106.8
-3,-7,4:106.8
3,5,3:106.4
6,4,3:106.8
2,3,3:106.8
8,2,3:106.2
2,1,3:106.8
8,0,3:106.2
6,-1,3:106.1
4,-1,3:106.1
0,-2,3:106.4
3,-4,3:106.2
-3,-4,3:106.8
-5,-5,3:106.4
3,-6,3:106.2
-3,-6,3:106.8
-3,-7,3:106.8
7,5,2:106.4
3,5,2:106.4
6,4,2:106.8
2,3,2:106.8
8,2,2:106.2
2,1,2:106.8
8,0,2:106.2
6,-1,2:106.1
4,-1,2:106.1
0,-2,2:106.4
3,-4,2:106.2
-3,-4,2:106.8
-5,-5,2:106.4
6,-6,2:106.8
3,-6,2:106.2
-3,-6,2:106.8
-6,-6,2:106.8
7,-7,2:106.1
-3,-7,2:106.8
7,5,1:106.4
-4,5,1:106.4
6,4,1:106.8
-3,4,1:106.2
8,3,1:106.2
2,3,1:106.8
8,2,1:106.2
7,2,1:106.1
-5,2,1:106.1
2,1,1:106.8
8,0,1:106.2
6,-1,1:106.1
0,-2,1:106.4
7,-4,1:106.4
3,-4,1:106.2
-4,-5,1:106.4
5,-6,1:106.8
-3,-6,1:106.8
-6,-6,1:106.8
7,-7,1:106.1
-3,-7,1:106.8
-4,-7,1:106.1
-5,-7,1:106.1
7,5,0:106.4
-4,5,0:106.4
-6,5,0:31.1
4,4,0:31.1
0,4,0:31.1
-3,4,0:106.2
-6,4,0:31.1
8,3,0:106.2
2,3,0:106.8
1,3,0:31.1
0,3,0:31.1
-1,3,0:106.2
8,2,0:106.2
7,2,0:106.1
6,2,0:31.1
-3,2,0:106.1
-5,2,0:106.1
7,1,0:31.1
6,1,0:37.0
2,1,0:106.8
8,0,0:106.2
4,-2,0:31.1
0,-2,0:106.4
-5,-3,0:31.1
-6,-3,0:31.1
8,-4,0:31.1
7,-4,0:31.1
4,-4,0:31.1
3,-4,0:106.2
0,-4,0:31.1
-4,-4,0:31.1
-5,-4,0:31.1
8,-5,0:106.6
4,-5,0:31.1
-1,-5,0:31.1
5,-6,0:31.1
0,-6,0:31.1
-1,-6,0:31.1
-3,-6,0:106.8
-6,-6,0:106.8
7,-7,0:106.1
5,-7,0:31.1
-1,-7,0:31.1
-2,-7,0:38.0
-3,-7,0:106.8
-4,-7,0:106.1
-5,-7,0:106.1
