[META]
version=2.0
spawnOnBlockType=2
spawnSunlight=True
spawnDarkness=True
spawnWater=False
spawnLava=False
underFill=False
randomRotation=True
dig=True
tree=False
branch=False
needsFoundation=True
rarity=30
collisionPercentage=10
spawnElevationMin=0
spawnElevationMax=102
groupId=Ruins
groupFrequencyMin=20
groupFrequencyMax=35
groupSeperationMin=5
groupSeperationMax=60
branchLimit=6
spawnInBiome=Jungle
[DATA]
1,-1,-6:1.5
2,-1,-6:1.5
1,0,-6:1.5
2,0,-6:1.5
0,-2,-5:1.5
1,-2,-5:3.5
2,-2,-5:1.5
0,-1,-5:3.5
1,-1,-5:98.0
2,-1,-5:98.0
3,-1,-5:1.5
0,0,-5:3.5
1,0,-5:98.0
2,0,-5:98.0
3,0,-5:1.5
1,1,-5:1.5
2,1,-5:1.5
0,-3,-4:1.5
1,-3,-4:1.5
2,-3,-4:1.5
-1,-2,-4:1.5
0,-2,-4:1.5
1,-2,-4:98.0
2,-2,-4:98.0
3,-2,-4:3.5
-1,-1,-4:1.5
0,-1,-4:98.0
2,-1,-4:54.3
3,-1,-4:1.5
-1,0,-4:1.5
0,0,-4:98.0
3,0,-4:98.0
4,0,-4:1.5
-1,1,-4:1.5
0,1,-4:1.5
1,1,-4:98.0
2,1,-4:98.0
3,1,-4:1.5
-1,-3,-3:1.5
0,-3,-3:1.5
1,-3,-3:1.5
2,-3,-3:1.5
3,-3,-3:3.5
-2,-2,-3:3.5
-1,-2,-3:1.5
0,-2,-3:1.5
1,-2,-3:98.0
2,-2,-3:98.0
3,-2,-3:16.5
4,-2,-3:16.5
-2,-1,-3:3.5
-1,-1,-3:3.5
0,-1,-3:98.0
3,-1,-3:98.0
4,-1,-3:16.5
-2,0,-3:3.5
-1,0,-3:1.5
0,0,-3:98.0
1,0,-3:30.0
3,0,-3:98.0
4,0,-3:3.5
-1,1,-3:1.5
0,1,-3:3.5
1,1,-3:98.0
2,1,-3:98.0
3,1,-3:3.5
4,1,-3:1.5
0,2,-3:2.0
1,2,-3:1.5
2,2,-3:3.5
-2,-3,-2:1.5
-1,-3,-2:1.5
0,-3,-2:1.5
1,-3,-2:3.5
2,-3,-2:3.5
3,-3,-2:3.5
4,-3,-2:3.5
-2,-2,-2:3.5
-1,-2,-2:3.5
0,-2,-2:3.5
1,-2,-2:98.0
2,-2,-2:98.0
3,-2,-2:3.5
4,-2,-2:16.5
-2,-1,-2:3.5
-1,-1,-2:1.5
0,-1,-2:3.5
2,-1,-2:98.0
3,-1,-2:98.0
4,-1,-2:16.5
-2,0,-2:3.5
-1,0,-2:1.5
0,0,-2:1.5
1,0,-2:98.0
3,0,-2:98.0
4,0,-2:3.5
-2,1,-2:3.5
-1,1,-2:1.5
0,1,-2:1.5
1,1,-2:98.0
2,1,-2:98.0
3,1,-2:2.0
4,1,-2:3.5
1,2,-2:1.5
2,2,-2:3.5
3,2,-2:3.5
-2,-4,-1:2.5
-1,-4,-1:2.5
0,-4,-1:2.5
1,-4,-1:2.5
2,-4,-1:2.5
3,-4,-1:2.5
4,-4,-1:2.5
5,-4,-1:2.5
-3,-3,-1:2.5
-2,-3,-1:3.0
-1,-3,-1:3.0
0,-3,-1:3.0
1,-3,-1:3.0
2,-3,-1:3.0
3,-3,-1:3.0
4,-3,-1:2.5
5,-3,-1:2.5
-3,-2,-1:2.5
-2,-2,-1:3.0
-1,-2,-1:98.0
0,-2,-1:98.0
1,-2,-1:98.0
2,-2,-1:98.0
3,-2,-1:98.0
4,-2,-1:2.5
5,-2,-1:2.5
-3,-1,-1:2.5
-2,-1,-1:3.0
-1,-1,-1:98.0
0,-1,-1:17.0
1,-1,-1:98.0
2,-1,-1:98.0
3,-1,-1:98.0
4,-1,-1:2.5
5,-1,-1:2.5
-3,0,-1:2.5
-2,0,-1:3.0
-1,0,-1:98.0
0,0,-1:98.0
1,0,-1:98.0
3,0,-1:98.0
4,0,-1:2.5
5,0,-1:2.5
-3,1,-1:2.5
-2,1,-1:3.0
-1,1,-1:3.0
0,1,-1:3.0
1,1,-1:98.0
2,1,-1:98.0
4,1,-1:2.5
5,1,-1:2.5
-2,2,-1:2.5
-1,2,-1:2.5
0,2,-1:2.5
1,2,-1:2.5
2,2,-1:2.5
3,2,-1:2.5
4,2,-1:2.5
-2,-3,0:98.0
-1,-3,0:98.0
0,-3,0:98.0
1,-3,0:98.0
2,-3,0:98.0
3,-3,0:98.0
-2,-2,0:98.0
-1,-2,0:61.5
0,-2,0:67.5
1,-2,0:44.11
2,-2,0:67.4
3,-2,0:98.0
-2,-1,0:98.0
-1,-1,0:118.0
0,-1,0:17.0
3,-1,0:30.0
-2,0,0:98.0
-1,0,0:58.0
3,0,0:98.0
-2,1,0:98.0
-1,1,0:98.0
0,1,0:98.0
1,1,0:98.0
2,1,0:98.0
-2,-3,1:98.0
-1,-3,1:30.0
1,-3,1:98.0
3,-3,1:98.0
-2,-2,1:98.0
1,-2,1:117.0
-2,-1,1:98.0
0,-1,1:17.0
2,0,1:30.0
3,0,1:98.0
-2,1,1:98.0
-1,1,1:98.0
0,1,1:101.0
2,1,1:98.0
3,1,1:98.0
-1,-4,2:67.2
1,-4,2:67.2
2,-4,2:67.2
3,-4,2:67.2
4,-4,2:67.2
-2,-3,2:98.0
-1,-3,2:98.0
0,-3,2:98.0
1,-3,2:98.0
2,-3,2:98.0
3,-3,2:98.0
-2,-2,2:98.0
3,-2,2:98.0
-2,-1,2:98.0
0,-1,2:17.0
3,-1,2:98.0
-2,0,2:98.0
3,0,2:98.0
-2,1,2:98.0
-1,1,2:98.0
0,1,2:98.0
1,1,2:98.0
2,1,2:98.0
-3,2,2:67.3
-2,2,2:67.3
0,2,2:67.3
1,2,2:67.3
2,2,2:67.3
-2,-3,3:67.2
-1,-3,3:67.2
0,-3,3:67.2
1,-3,3:67.2
2,-3,3:18.13
3,-3,3:67.2
4,-3,3:67.2
2,-2,3:30.0
3,-2,3:98.0
-2,-1,3:101.0
0,-1,3:17.0
3,-1,3:101.0
-2,0,3:98.0
1,0,3:30.0
3,0,3:98.0
-3,1,3:67.3
-2,1,3:67.3
0,1,3:67.3
1,1,3:67.3
2,1,3:67.3
3,1,3:67.3
0,-3,4:18.13
1,-3,4:18.5
-3,-2,4:67.2
-2,-2,4:18.13
-1,-2,4:18.13
0,-2,4:18.13
1,-2,4:67.2
2,-2,4:18.13
3,-2,4:67.2
4,-2,4:67.2
-3,-1,4:4.0
-2,-1,4:98.0
-1,-1,4:18.13
0,-1,4:18.13
3,-1,4:98.0
4,-1,4:4.0
-3,0,4:67.3
-2,0,4:67.3
-1,0,4:67.3
0,0,4:18.13
1,0,4:67.3
2,0,4:18.13
3,0,4:67.3
4,0,4:67.3
0,1,4:18.13
1,1,4:18.5
0,-2,5:18.13
1,-2,5:18.13
-3,-1,5:44.3
-2,-1,5:44.3
-1,-1,5:18.5
0,-1,5:18.13
1,-1,5:18.13
2,-1,5:44.3
3,-1,5:44.3
4,-1,5:44.3
0,0,5:18.13
0,-1,6:18.13
0,-1,7:40.5
0,0,6:39.5
-1,-1,6:40.5
5,-1,4:106.2
-1,1,3:39.5
5,-1,3:106.2
4,0,2:106.2
-3,0,2:106.8
5,-1,2:106.2
4,-1,2:106.2
-3,-2,2:106.8
4,-3,2:106.2
0,-4,2:106.1
3,2,1:106.4
-1,2,1:106.4
4,1,1:106.2
1,1,1:39.5
-3,1,1:106.8
4,0,1:106.2
-3,0,1:106.8
5,-1,1:106.2
4,-1,1:106.2
3,-2,1:40.5
-3,-2,1:106.8
4,-3,1:106.2
2,-3,1:40.5
3,-4,1:106.1
1,-4,1:106.1
0,-4,1:106.1
-2,-4,1:106.1
4,2,0:37.5
3,2,0:31.2
2,2,0:31.1
1,2,0:31.2
0,2,0:31.1
-1,2,0:106.4
-2,2,0:31.2
5,1,0:31.2
4,1,0:39.5
-3,1,0:31.1
5,0,0:31.1
4,0,0:38.5
2,0,0:26.11
1,0,0:26.3
0,0,0:40.5
-3,0,0:106.8
5,-1,0:106.2
2,-1,0:39.5
1,-1,0:40.5
-3,-1,0:106.8
5,-2,0:31.1
4,-2,0:106.2
-3,-2,0:106.8
5,-3,0:31.1
4,-3,0:106.2
-3,-3,0:31.1
5,-4,0:31.2
4,-4,0:37.5
3,-4,0:31.1
2,-4,0:106.1
1,-4,0:38.5
0,-4,0:106.1
-1,-4,0:31.1
-2,-4,0:106.1
2,0,-1:65.2
2,0,-2:65.4
1,-1,-2:106.15
2,0,-3:65.2
2,-1,-3:106.0
1,-1,-3:106.15
2,0,-4:65.4
1,0,-4:106.2
1,-1,-4:106.15
