[META]
version=2.0
spawnOnBlockType=2
spawnSunlight=True
spawnDarkness=True
spawnWater=False
spawnLava=False
underFill=False
randomRotation=True
dig=True
tree=False
branch=False
needsFoundation=True
rarity=10
collisionPercentage=70
spawnElevationMin=0
spawnElevationMax=102
groupId=Ruins
groupFrequencyMin=20
groupFrequencyMax=35
groupSeperationMin=5
groupSeperationMax=60
branchLimit=6
spawnInBiome=Jungle
[DATA]
-1,-1,-3:3.5
-1,-2,-2:3.5
-2,-1,-2:3.5
-1,-1,-2:3.5
0,-1,-2:3.5
1,-1,-2:3.5
-2,0,-2:3.5
-1,0,-2:3.5
-2,-3,-1:2.5
-3,-2,-1:2.5
-2,-2,-1:3.0
-1,-2,-1:3.0
0,-2,-1:3.0
1,-2,-1:3.0
2,-2,-1:2.5
-3,-1,-1:2.5
-2,-1,-1:3.0
-1,-1,-1:97.2
0,-1,-1:97.0
1,-1,-1:98.0
2,-1,-1:2.5
-2,0,-1:3.0
-1,0,-1:97.0
0,0,-1:98.0
-2,1,-1:3.0
-1,1,-1:98.0
0,1,-1:2.5
-2,2,-1:2.5
-2,-2,0:98.0
-1,-2,0:98.0
0,-2,0:98.0
1,-2,0:98.0
2,-2,0:44.5
-2,-1,0:98.1
-2,0,0:98.0
-2,1,0:98.1
-2,2,0:44.5
-2,-2,1:98.1
-1,-2,1:98.0
0,-2,1:101.0
1,-2,1:101.0
-2,-1,1:98.0
-2,0,1:44.5
-2,-2,2:98.0
-1,-2,2:44.5
0,-2,2:44.5
-3,-2,2:106.8
-2,-3,2:106.1
-3,-1,1:106.8
-3,-2,1:106.8
-2,-3,1:106.1
-3,-1,0:106.8
-3,-2,0:106.8
-2,-3,0:106.1
