[META]
version=2.0
spawnOnBlockType=2
spawnSunlight=True
spawnDarkness=True
spawnWater=False
spawnLava=False
underFill=False
randomRotation=True
dig=True
tree=False
branch=False
needsFoundation=True
rarity=10
collisionPercentage=70
spawnElevationMin=0
spawnElevationMax=102
groupId=Ruins
groupFrequencyMin=20
groupFrequencyMax=35
groupSeperationMin=5
groupSeperationMax=60
branchLimit=6
spawnInBiome=Jungle
[DATA]
-1,-1,0:109.2
0,-1,0:109.2
1,-1,0:109.2
0,0,0:98.0
1,0,0:98.0
2,0,0:109.1
-1,1,0:109.3
0,1,0:109.3
1,1,0:109.3
-2,0,0:109.0
-1,0,0:98.0
-2,1,0:2
-1,2,0:2
0,2,0:2
1,2,0:2
2,1,0:2
2,-1,0:2
1,-2,0:2
0,-2,0:2
-1,-2,0:2
-2,-1,0:2
-1,0,1:98.0
1,0,1:98.0
0,0,1:98.0
-2,-1,1:40
2,1,1:40
0,2,1:40
-1,2,1:40
1,-2,1:31.0
2,-1,1:40
-2,1,1:31.0
-1,-2,1:39
0,-2,1:39
1,2,1:39
-1,0,2:109.0
1,0,2:109.1
0,0,2:22
0,0,3:44.5
-2,0,-1:3
-1,0,-1:3
0,0,-1:3
0,1,-1:3
1,1,-1:3
1,0,-1:3
2,0,-1:3
-1,-1,-1:3
0,-1,-1:3
1,-1,-1:3
-1,1,-1:3
-1,0,-2:3
0,0,-2:3
0,-1,-2:3
0,1,-2:3
1,0,-2:3
0,0,-3:3
