[META]
version=2.0
spawnOnBlockType=2
spawnSunlight=True
spawnDarkness=True
spawnWater=False
spawnLava=False
underFill=False
randomRotation=True
dig=True
tree=False
branch=False
needsFoundation=True
rarity=10
collisionPercentage=70
spawnElevationMin=0
spawnElevationMax=102
groupId=Ruins
groupFrequencyMin=20
groupFrequencyMax=35
groupSeperationMin=5
groupSeperationMax=60
branchLimit=6
spawnInBiome=Jungle
[DATA]
-5,-6,0:98.2
-4,-6,0:98.2
-3,-6,0:98.1
-2,-6,0:109.2
-1,-6,0:109.2
0,-6,0:109.2
1,-6,0:109.2
2,-6,0:98.2
3,-6,0:98.2
4,-6,0:98.2
5,-6,0:98.1
-6,-5,0:98.2
-5,-5,0:98.2
-4,-5,0:98.2
-3,-5,0:98.2
-2,-5,0:98.2
-1,-5,0:98.2
0,-5,0:98.2
1,-5,0:98.2
2,-5,0:98.2
3,-5,0:98.2
4,-5,0:98.2
5,-5,0:98.2
-6,-4,0:98.2
-5,-4,0:98.2
-4,-4,0:98.2
-3,-4,0:98.2
3,-4,0:98.2
4,-4,0:98.2
5,-4,0:98.2
-6,-3,0:98.2
-5,-3,0:98.2
-4,-3,0:98.2
4,-3,0:98.2
5,-3,0:98.2
-6,-2,0:109.0
-5,-2,0:98.2
-4,-2,0:98.2
4,-2,0:98.2
5,-2,0:109.1
-6,-1,0:109.0
-5,-1,0:98.2
-4,-1,0:97
5,-1,0:109.1
-6,0,0:109.0
-5,0,0:98.2
-4,0,0:97
4,0,0:98.2
5,0,0:109.1
-6,1,0:109.0
-5,1,0:98.2
-4,1,0:98.2
4,1,0:98.2
5,1,0:109.1
-6,2,0:98.1
-5,2,0:98.2
-4,2,0:98.2
4,2,0:98.2
5,2,0:98.1
-6,3,0:98.2
-5,3,0:98.2
-4,3,0:98.2
-3,3,0:98.2
3,3,0:98.2
4,3,0:98.2
5,3,0:98.2
-6,4,0:98.2
-5,4,0:98.1
-4,4,0:98.2
-3,4,0:98.2
-2,4,0:98.2
-1,4,0:98.2
0,4,0:98.2
1,4,0:98.2
2,4,0:98.2
3,4,0:98.2
4,4,0:98.2
5,4,0:98.2
-5,5,0:98.2
-4,5,0:98.2
-3,5,0:98.2
-2,5,0:109.3
-1,5,0:109.3
0,5,0:109.3
1,5,0:109.3
2,5,0:98.1
3,5,0:98.1
4,5,0:98.2
5,5,0:98.1
-1,-3,-6:3
0,-3,-6:3
-2,-2,-6:3
-1,-2,-6:98.2
0,-2,-6:98.2
1,-2,-6:3
-3,-1,-6:3
-2,-1,-6:98.2
-1,-1,-6:97
0,-1,-6:97
1,-1,-6:98.2
2,-1,-6:3
-3,0,-6:3
-2,0,-6:98.2
-1,0,-6:97
0,0,-6:97
1,0,-6:98.2
2,0,-6:3
-2,1,-6:3
-1,1,-6:98.2
0,1,-6:98.2
1,1,-6:3
-1,2,-6:3
0,2,-6:3
-4,-3,-5:3
-3,-3,-5:3
-2,-3,-5:3
-1,-3,-5:3
0,-3,-5:3
1,-3,-5:3
2,-3,-5:3
3,-3,-5:3
4,-3,-5:3
-4,-2,-5:3
-3,-2,-5:3
-2,-2,-5:3
-1,-2,-5:98.2
0,-2,-5:98.2
1,-2,-5:3
2,-2,-5:3
3,-2,-5:3
4,-2,-5:3
-4,-1,-5:3
-3,-1,-5:3
-2,-1,-5:98.2
-1,-1,-5:9
0,-1,-5:9
1,-1,-5:98.2
2,-1,-5:3
3,-1,-5:3
4,-1,-5:3
-4,0,-5:3
-3,0,-5:3
-2,0,-5:98.2
-1,0,-5:9
0,0,-5:9
1,0,-5:98.2
2,0,-5:3
3,0,-5:3
4,0,-5:3
-4,1,-5:3
-3,1,-5:3
-2,1,-5:3
-1,1,-5:98.2
0,1,-5:98.2
1,1,-5:3
2,1,-5:3
3,1,-5:3
4,1,-5:3
-4,2,-5:3
-3,2,-5:3
-2,2,-5:3
-1,2,-5:3
0,2,-5:3
1,2,-5:3
2,2,-5:3
3,2,-5:3
4,2,-5:3
-4,3,-5:3
-3,3,-5:3
-2,3,-5:3
-1,3,-5:3
0,3,-5:3
1,3,-5:3
2,3,-5:3
3,3,-5:3
4,3,-5:3
-4,4,-5:3
-3,4,-5:3
-2,4,-5:3
-1,4,-5:3
0,4,-5:3
1,4,-5:3
2,4,-5:3
3,4,-5:3
4,4,-5:3
-4,-6,-4:3
-3,-6,-4:3
-2,-6,-4:3
-1,-6,-4:3
0,-6,-4:3
1,-6,-4:3
2,-6,-4:3
3,-6,-4:3
4,-6,-4:3
-5,-5,-4:3
-4,-5,-4:98.2
-3,-5,-4:98.2
-2,-5,-4:98.2
-1,-5,-4:98.2
0,-5,-4:98.2
1,-5,-4:98.2
2,-5,-4:98.2
3,-5,-4:98.2
4,-5,-4:98.2
5,-5,-4:3
-5,-4,-4:3
-4,-4,-4:98.2
-3,-4,-4:98.2
-2,-4,-4:98.2
-1,-4,-4:98.2
0,-4,-4:98.2
1,-4,-4:98.2
2,-4,-4:98.2
3,-4,-4:98.2
4,-4,-4:98.2
5,-4,-4:3
-5,-3,-4:3
-4,-3,-4:98.2
-3,-3,-4:98.2
-2,-3,-4:98.2
-1,-3,-4:98.2
0,-3,-4:98.2
1,-3,-4:98.2
2,-3,-4:98.2
3,-3,-4:98.2
4,-3,-4:98.2
5,-3,-4:3
-5,-2,-4:3
-4,-2,-4:98.2
-3,-2,-4:98.2
-2,-2,-4:98.2
-1,-2,-4:98.2
0,-2,-4:98.2
1,-2,-4:98.2
2,-2,-4:98.2
3,-2,-4:98.2
4,-2,-4:98.2
5,-2,-4:3
-5,-1,-4:3
-4,-1,-4:98.2
-3,-1,-4:98.2
-2,-1,-4:98.2
-1,-1,-4:9
0,-1,-4:9
1,-1,-4:98.2
2,-1,-4:98.2
3,-1,-4:98.2
4,-1,-4:98.2
5,-1,-4:3
-5,0,-4:3
-4,0,-4:98.2
-3,0,-4:97
-2,0,-4:98.2
-1,0,-4:9
0,0,-4:9
1,0,-4:98.2
2,0,-4:98.2
3,0,-4:98.2
4,0,-4:98.2
5,0,-4:3
-5,1,-4:3
-4,1,-4:98.2
-3,1,-4:98.2
-2,1,-4:98.2
-1,1,-4:98.2
0,1,-4:98.2
1,1,-4:98.2
2,1,-4:98.2
3,1,-4:98.2
4,1,-4:98.2
5,1,-4:3
-5,2,-4:3
-4,2,-4:98.2
-3,2,-4:98.2
-2,2,-4:98.2
-1,2,-4:98.2
0,2,-4:98.2
1,2,-4:98.2
2,2,-4:98.2
3,2,-4:98.2
4,2,-4:98.2
5,2,-4:3
-5,3,-4:3
-4,3,-4:98.2
-3,3,-4:98.2
-2,3,-4:98.2
-1,3,-4:98.2
0,3,-4:98.2
1,3,-4:98.2
2,3,-4:98.2
3,3,-4:98.2
4,3,-4:98.2
5,3,-4:3
-5,4,-4:3
-4,4,-4:98.2
-3,4,-4:98.2
-2,4,-4:98.2
-1,4,-4:98.2
0,4,-4:98.2
1,4,-4:98.2
2,4,-4:98.2
3,4,-4:98.2
4,4,-4:98.2
5,4,-4:3
-4,5,-4:3
-3,5,-4:3
-2,5,-4:3
-1,5,-4:3
0,5,-4:3
1,5,-4:3
2,5,-4:3
3,5,-4:3
4,5,-4:3
-5,-7,-3:3
-4,-7,-3:3
-2,-7,-3:3
0,-7,-3:3
1,-7,-3:3
-5,-6,-3:98.2
-4,-6,-3:98.2
-3,-6,-3:98.1
-2,-6,-3:98.1
-1,-6,-3:98.1
0,-6,-3:98.2
1,-6,-3:97
2,-6,-3:98.2
3,-6,-3:98.2
4,-6,-3:98.2
5,-6,-3:98.2
-5,-5,-3:98.2
-3,-5,-3:98.2
-2,-5,-3:30
2,-5,-3:30
3,-5,-3:98.2
5,-5,-3:98.2
6,-5,-3:3
-5,-4,-3:98.2
-4,-4,-3:98.2
-3,-4,-3:98.2
3,-4,-3:98.2
4,-4,-3:98.2
5,-4,-3:98.2
-6,-3,-3:3
-5,-3,-3:98.2
-4,-3,-3:30
-1,-3,-3:30
1,-3,-3:30
4,-3,-3:30
5,-3,-3:98.2
-6,-2,-3:3
-5,-2,-3:98.2
5,-2,-3:98.1
6,-2,-3:3
-5,-1,-3:98.2
-2,-1,-3:30
2,-1,-3:30
5,-1,-3:98.2
6,-1,-3:3
-5,0,-3:98.2
5,0,-3:98.1
-6,1,-3:3
-5,1,-3:98.1
-4,1,-3:30
5,1,-3:98.2
-5,2,-3:98.2
0,2,-3:30
3,2,-3:30
4,2,-3:30
5,2,-3:98.2
6,2,-3:3
-5,3,-3:98.2
-4,3,-3:98.2
-3,3,-3:98.2
3,3,-3:98.2
4,3,-3:98.2
5,3,-3:98.2
6,3,-3:3
-6,4,-3:3
-5,4,-3:98.2
-4,4,-3:98.2
-3,4,-3:98.2
-1,4,-3:30
0,4,-3:30
1,4,-3:30
3,4,-3:98.2
5,4,-3:98.2
6,4,-3:3
-5,5,-3:98.2
-4,5,-3:98.2
-3,5,-3:98.2
-2,5,-3:98.2
-1,5,-3:98.2
0,5,-3:98.1
1,5,-3:98.1
2,5,-3:98.2
3,5,-3:98.2
4,5,-3:98.2
5,5,-3:98.2
6,5,-3:3
-5,6,-3:3
-3,6,-3:3
-1,6,-3:3
0,6,-3:3
1,6,-3:3
3,6,-3:3
4,6,-3:3
5,6,-3:3
-5,-7,-2:3
-4,-7,-2:3
-1,-7,-2:3
0,-7,-2:3
1,-7,-2:3
2,-7,-2:3
-6,-6,-2:3
-5,-6,-2:98.2
-4,-6,-2:98.2
-3,-6,-2:98.1
-2,-6,-2:98.2
-1,-6,-2:98.1
0,-6,-2:98.2
1,-6,-2:98.2
2,-6,-2:98.2
3,-6,-2:98.2
4,-6,-2:98.2
5,-6,-2:98.2
6,-6,-2:3
-5,-5,-2:98.2
-3,-5,-2:98.2
-1,-5,-2:30
0,-5,-2:30
1,-5,-2:30
3,-5,-2:98.2
5,-5,-2:98.2
6,-5,-2:3
-6,-4,-2:3
-5,-4,-2:98.2
-4,-4,-2:98.2
-3,-4,-2:98.2
-2,-4,-2:30
2,-4,-2:30
3,-4,-2:98.2
4,-4,-2:98.2
5,-4,-2:98.2
-6,-3,-2:3
-5,-3,-2:98.2
-3,-3,-2:30
3,-3,-2:30
5,-3,-2:98.2
-5,-2,-2:97
5,-2,-2:97
6,-2,-2:3
-6,-1,-2:3
-5,-1,-2:98.2
-4,-1,-2:30
4,-1,-2:30
5,-1,-2:97
6,-1,-2:3
-5,0,-2:98.1
-4,0,-2:30
4,0,-2:30
5,0,-2:98.1
6,0,-2:3
-6,1,-2:3
-5,1,-2:98.1
4,1,-2:30
5,1,-2:98.1
-5,2,-2:98.2
-3,2,-2:30
3,2,-2:30
5,2,-2:98.2
-6,3,-2:3
-5,3,-2:98.2
-4,3,-2:98.2
-3,3,-2:98.2
-2,3,-2:30
2,3,-2:30
3,3,-2:98.2
4,3,-2:98.2
5,3,-2:98.2
6,3,-2:3
-6,4,-2:3
-5,4,-2:98.2
-4,4,-2:98.2
-3,4,-2:98.2
0,4,-2:30
3,4,-2:98.2
5,4,-2:98.2
-5,5,-2:98.2
-4,5,-2:98.2
-3,5,-2:98.2
-2,5,-2:98.2
-1,5,-2:98.2
0,5,-2:98.1
1,5,-2:98.1
2,5,-2:98.2
3,5,-2:98.2
4,5,-2:98.2
5,5,-2:98.2
-3,6,-2:3
-2,6,-2:3
0,6,-2:3
2,6,-2:3
5,6,-2:3
4,-7,-2:3
5,-7,-2:3
6,5,-2:3
3,6,-2:3
-1,6,-2:3
-6,5,-2:3
-6,0,-2:3
-2,-7,-2:3
-5,6,-2:3
-5,-7,-1:2
-3,-7,-1:2
-2,-7,-1:2
-1,-7,-1:2
1,-7,-1:2
2,-7,-1:2
5,-7,-1:2
-6,-6,-1:2
-5,-6,-1:98.2
-4,-6,-1:98.2
-3,-6,-1:98.2
-2,-6,-1:98.2
-1,-6,-1:98.1
0,-6,-1:98.1
1,-6,-1:98.1
2,-6,-1:98.2
3,-6,-1:98.2
4,-6,-1:98.2
5,-6,-1:98.2
6,-6,-1:2
-7,-5,-1:2
-6,-5,-1:3
-5,-5,-1:98.2
-3,-5,-1:98.2
-2,-5,-1:30
2,-5,-1:30
3,-5,-1:98.2
5,-5,-1:98.2
6,-5,-1:2
-6,-4,-1:3
-5,-4,-1:98.2
-4,-4,-1:98.2
-3,-4,-1:98.2
3,-4,-1:98.2
4,-4,-1:98.2
5,-4,-1:98.2
-7,-3,-1:2
-6,-3,-1:3
-5,-3,-1:98.2
-4,-3,-1:30
4,-3,-1:30
5,-3,-1:98.2
-7,-2,-1:2
-6,-2,-1:3
-5,-2,-1:98.2
5,-2,-1:98.2
6,-2,-1:2
-7,-1,-1:2
-6,-1,-1:3
-5,-1,-1:98.2
5,-1,-1:97
6,-1,-1:2
-6,0,-1:3
-5,0,-1:98.2
5,0,-1:98.2
-6,1,-1:3
-5,1,-1:98.2
5,1,-1:98.1
6,1,-1:2
-7,2,-1:2
-6,2,-1:3
-5,2,-1:98.2
-4,2,-1:30
4,2,-1:30
5,2,-1:98.2
6,2,-1:2
-7,3,-1:2
-6,3,-1:3
-5,3,-1:98.2
-4,3,-1:98.2
-3,3,-1:98.2
3,3,-1:98.2
4,3,-1:98.2
5,3,-1:98.2
-6,4,-1:3
-5,4,-1:98.2
-4,4,-1:98.2
-3,4,-1:98.2
-2,4,-1:30
2,4,-1:30
3,4,-1:98.2
5,4,-1:98.2
6,4,-1:2
-6,5,-1:2
-5,5,-1:98.2
-4,5,-1:98.2
-3,5,-1:98.2
-2,5,-1:98.2
-1,5,-1:98.2
0,5,-1:98.1
1,5,-1:98.2
2,5,-1:98.2
3,5,-1:98.2
4,5,-1:98.2
5,5,-1:98.2
6,5,-1:2
-5,6,-1:2
-3,6,-1:2
-2,6,-1:2
-1,6,-1:2
2,6,-1:2
3,6,-1:2
4,6,-1:2
-4,-5,1:98.2
-3,-5,1:98.2
-2,-5,1:109.2
-1,-5,1:109.2
0,-5,1:109.2
1,-5,1:109.2
2,-5,1:98.2
3,-5,1:98.1
-5,-4,1:98.2
-4,-4,1:98.2
-3,-4,1:98.2
-2,-4,1:98.2
-1,-4,1:98.2
0,-4,1:98.2
1,-4,1:98.2
2,-4,1:98.2
3,-4,1:98.2
4,-4,1:98.2
-5,-3,1:98.1
-4,-3,1:98.2
3,-3,1:98.2
4,-3,1:98.2
-5,-2,1:109.0
-4,-2,1:98.2
3,-2,1:98.2
4,-2,1:109.1
-5,-1,1:109.0
-4,-1,1:98.2
3,-1,1:98.2
4,-1,1:109.1
-5,0,1:109.0
-4,0,1:98.2
3,0,1:98.2
4,0,1:109.1
-5,1,1:109.0
-4,1,1:98.2
3,1,1:98.2
4,1,1:109.1
-5,2,1:98.1
-4,2,1:98.2
3,2,1:98.2
4,2,1:98.2
-5,3,1:98.1
-4,3,1:98.2
-3,3,1:98.2
-2,3,1:98.2
-1,3,1:98.2
0,3,1:97
1,3,1:98.2
2,3,1:98.2
3,3,1:98.2
4,3,1:98.2
-4,4,1:98.1
-3,4,1:98.2
-2,4,1:109.3
-1,4,1:109.3
0,4,1:109.3
1,4,1:109.3
2,4,1:98.1
3,4,1:98.2
-4,-4,2:98.1
-3,-4,2:98.2
-2,-4,2:109.2
-1,-4,2:109.2
0,-4,2:109.2
1,-4,2:109.2
2,-4,2:98.2
3,-4,2:98.2
-4,-3,2:98.2
-3,-3,2:98.2
-2,-3,2:98.2
-1,-3,2:98.2
0,-3,2:98.2
1,-3,2:98.2
2,-3,2:98.2
3,-3,2:98.2
-4,-2,2:109.0
-3,-2,2:98.2
-2,-2,2:30
1,-2,2:30
2,-2,2:98.2
3,-2,2:109.1
-4,-1,2:109.0
-3,-1,2:98.2
2,-1,2:98.2
3,-1,2:109.1
-4,0,2:109.0
-3,0,2:98.2
2,0,2:98.2
3,0,2:109.1
-4,1,2:109.0
-3,1,2:98.2
-2,1,2:30
1,1,2:30
2,1,2:98.2
3,1,2:109.1
-4,2,2:98.2
-3,2,2:98.2
-2,2,2:98.2
-1,2,2:98.2
0,2,2:98.2
1,2,2:98.2
2,2,2:98.2
3,2,2:98.2
-4,3,2:98.2
-3,3,2:98.2
-2,3,2:109.3
-1,3,2:109.3
0,3,2:109.3
1,3,2:109.3
2,3,2:98.2
3,3,2:98.2
-3,-3,3:98.2
-2,-3,3:109.2
-1,-3,3:109.2
0,-3,3:109.2
1,-3,3:109.2
2,-3,3:98.2
-3,-2,3:109.0
-2,-2,3:98.2
-1,-2,3:98.2
0,-2,3:98.2
1,-2,3:98.2
2,-2,3:109.1
-3,-1,3:109.0
-2,-1,3:97
1,-1,3:98.2
2,-1,3:109.1
-3,0,3:109.0
-2,0,3:98.2
1,0,3:98.2
2,0,3:109.1
-3,1,3:109.0
-2,1,3:98.2
-1,1,3:98.2
0,1,3:98.2
1,1,3:98.2
2,1,3:109.1
-3,2,3:98.1
-2,2,3:109.3
-1,2,3:109.3
0,2,3:109.3
1,2,3:109.3
2,2,3:98.1
-3,-3,4:98.2
2,-3,4:98.2
-2,-2,4:98.2
1,-2,4:98.2
-2,1,4:98.2
1,1,4:98.2
-3,2,4:98.2
2,2,4:98.2
-3,-3,5:98.1
2,-3,5:98.1
-2,-2,5:98.2
1,-2,5:98.2
-2,1,5:98.2
1,1,5:98.2
-3,2,5:98.2
2,2,5:98.1
-3,-3,6:98.2
-2,-3,6:98.1
1,-3,6:98.2
2,-3,6:98.2
-3,-2,6:98.2
-2,-2,6:98.2
-1,-2,6:98.2
0,-2,6:98.2
1,-2,6:98.2
2,-2,6:98.2
-2,-1,6:98.2
-1,-1,6:98.2
0,-1,6:98.2
1,-1,6:98.2
-2,0,6:98.2
-1,0,6:98.2
0,0,6:98.2
1,0,6:98.2
-3,1,6:98.2
-2,1,6:98.2
-1,1,6:98.2
0,1,6:98.2
1,1,6:98.2
2,1,6:98.2
-3,2,6:98.2
-2,2,6:98.2
1,2,6:98.2
2,2,6:98.2
-1,-2,7:98.2
0,-2,7:98.1
-2,-1,7:98.2
-1,-1,7:98.2
0,-1,7:98.2
1,-1,7:98.2
-2,0,7:98.2
-1,0,7:98.2
0,0,7:98.2
1,0,7:98.1
-1,1,7:98.2
0,1,7:98.2
-1,-1,8:98.2
0,-1,8:98.1
-1,0,8:98.1
0,0,8:98.2
