[META]
version=2.0
spawnOnBlockType=2
spawnSunlight=True
spawnDarkness=True
spawnWater=False
spawnLava=False
underFill=False
randomRotation=True
dig=True
tree=False
branch=False
needsFoundation=True
rarity=1
collisionPercentage=50
spawnElevationMin=0
spawnElevationMax=102
groupId=Ruins
groupFrequencyMin=20
groupFrequencyMax=35
groupSeperationMin=5
groupSeperationMax=60
branchLimit=6
spawnInBiome=All
[DATA]
-1,-1,-4:1.5
0,-1,-4:1.5
1,-1,-4:1.5
-1,0,-4:1.5
0,0,-4:1.5
1,0,-4:1.5
-1,-2,-3:1.5
0,-2,-3:1.5
1,-2,-3:3.0
-2,-1,-3:1.5
-1,-1,-3:3.0
0,-1,-3:3.0
1,-1,-3:3.0
2,-1,-3:3.0
-2,0,-3:3.0
-1,0,-3:3.0
0,0,-3:3.0
1,0,-3:3.0
2,0,-3:3.0
-2,1,-3:3.0
-1,1,-3:3.0
0,1,-3:3.0
1,1,-3:3.0
2,1,-3:1.5
-1,2,-3:3.0
0,2,-3:3.0
1,2,-3:1.5
-2,-3,-2:3.0
-1,-3,-2:3.0
0,-3,-2:3.0
1,-3,-2:1.5
2,-3,-2:3.0
-3,-2,-2:3.0
-2,-2,-2:3.0
-1,-2,-2:3.0
0,-2,-2:3.0
1,-2,-2:3.0
2,-2,-2:3.0
3,-2,-2:3.0
-3,-1,-2:3.0
-2,-1,-2:3.0
-1,-1,-2:3.5
0,-1,-2:17.0
1,-1,-2:3.0
2,-1,-2:3.0
3,-1,-2:3.0
-3,0,-2:3.0
-2,0,-2:3.0
-1,0,-2:3.0
0,0,-2:3.0
1,0,-2:3.0
2,0,-2:3.0
3,0,-2:3.0
-2,1,-2:3.0
-1,1,-2:3.0
0,1,-2:3.0
1,1,-2:3.0
2,1,-2:3.0
-3,2,-2:3.0
-2,2,-2:3.0
-1,2,-2:3.0
0,2,-2:3.0
1,2,-2:3.0
2,2,-2:3.0
3,2,-2:3.0
-2,3,-2:3.0
-1,3,-2:3.0
0,3,-2:3.0
1,3,-2:3.0
2,3,-2:3.0
-3,-4,-1:2.0
-2,-4,-1:2.0
1,-4,-1:2.0
2,-4,-1:2.0
-4,-3,-1:2.0
-3,-3,-1:2.0
-2,-3,-1:2.0
-1,-3,-1:2.0
0,-3,-1:2.0
1,-3,-1:2.0
2,-3,-1:2.0
3,-3,-1:2.0
-4,-2,-1:2.0
-3,-2,-1:2.0
-2,-2,-1:2.0
-1,-2,-1:2.0
0,-2,-1:2.5
1,-2,-1:2.0
2,-2,-1:2.0
3,-2,-1:2.0
4,-2,-1:2.0
-4,-1,-1:2.0
-3,-1,-1:2.0
-2,-1,-1:2.0
-1,-1,-1:2.0
0,-1,-1:17.0
1,-1,-1:2.0
2,-1,-1:2.0
3,-1,-1:2.0
4,-1,-1:2.0
-4,0,-1:2.0
-3,0,-1:2.0
-2,0,-1:2.0
-1,0,-1:2.0
0,0,-1:2.0
1,0,-1:2.0
2,0,-1:2.0
3,0,-1:2.0
-3,1,-1:2.0
-2,1,-1:3.0
-1,1,-1:2.0
0,1,-1:3.0
1,1,-1:2.0
2,1,-1:2.0
3,1,-1:2.0
-4,2,-1:2.0
-3,2,-1:2.0
-2,2,-1:3.0
-1,2,-1:2.0
0,2,-1:3.0
1,2,-1:2.0
2,2,-1:2.0
3,2,-1:2.0
-4,3,-1:2.0
-3,3,-1:2.0
-2,3,-1:2.0
-1,3,-1:2.0
0,3,-1:2.0
1,3,-1:2.0
2,3,-1:2.0
3,3,-1:2.0
4,3,-1:2.0
-3,4,-1:2.0
-2,4,-1:2.0
-1,4,-1:2.0
0,4,-1:2.0
1,4,-1:2.0
2,4,-1:2.0
3,4,-1:2.0
0,-1,0:17.0
-2,1,0:98.0
0,1,0:98.0
-2,2,0:109.3
0,2,0:109.3
0,-1,1:17.0
-2,1,1:98.1
0,1,1:98.1
0,-1,2:17.0
-3,1,2:109.3
-2,1,2:98.1
0,1,2:98.0
1,1,2:109.3
0,-1,3:17.0
1,-1,3:17.0
-3,1,3:98.1
-2,1,3:109.0
-1,1,3:98.0
0,1,3:109.1
1,1,3:98.0
1,-1,4:17.0
-3,1,4:98.0
-2,1,4:109.0
-1,1,4:98.1
0,1,4:109.1
1,1,4:98.1
0,-3,5:18.4
1,-1,5:17.0
-3,1,5:44.5
-2,1,5:109.0
-1,1,5:98.1
0,1,5:109.1
1,1,5:44.5
0,-3,6:18.12
1,-1,6:17.0
-3,0,6:18.4
1,0,6:17.0
3,0,6:18.4
-2,1,6:98.2
-1,1,6:98.0
0,1,6:98.2
-1,2,6:98.1
0,3,6:18.4
0,-3,7:18.12
-2,-2,7:18.4
2,-2,7:18.4
-3,0,7:18.12
1,0,7:17.0
3,0,7:18.12
-2,1,7:98.1
-1,1,7:98.0
0,1,7:98.0
-1,2,7:109.3
2,2,7:18.4
0,3,7:18.12
0,-3,8:18.12
-2,-2,8:18.12
2,-2,8:18.12
-3,0,8:18.12
0,0,8:17.0
1,0,8:17.0
3,0,8:18.12
-2,1,8:109.3
-1,1,8:44.5
0,1,8:109.3
-2,2,8:18.4
2,2,8:18.12
0,3,8:18.12
0,-3,9:18.12
-2,-2,9:18.12
0,-2,9:18.12
2,-2,9:18.12
-1,-1,9:18.12
0,-1,9:18.12
1,-1,9:18.12
-3,0,9:18.12
-2,0,9:18.12
-1,0,9:18.12
0,0,9:17.0
1,0,9:18.12
2,0,9:18.12
3,0,9:18.12
-1,1,9:18.12
0,1,9:18.12
1,1,9:18.12
-2,2,9:18.12
0,2,9:18.12
2,2,9:18.12
0,3,9:18.12
0,-2,10:18.12
-1,-1,10:18.12
0,-1,10:18.12
1,-1,10:18.12
-2,0,10:18.12
-1,0,10:18.12
0,0,10:17.0
1,0,10:18.12
2,0,10:18.12
-1,1,10:18.12
0,1,10:18.12
1,1,10:18.12
0,2,10:18.12
0,-1,11:18.12
-1,0,11:18.12
0,0,11:18.12
1,0,11:18.12
0,1,11:18.12
0,0,12:18.4
2,0,11:106.2
1,-1,11:106.2
1,2,10:106.4
-1,2,10:106.4
2,1,10:106.4
-2,1,10:106.4
0,4,9:106.4
2,3,9:106.4
1,3,9:106.2
-2,3,9:106.4
3,2,9:106.2
1,2,9:106.4
-1,2,9:106.4
-3,2,9:106.8
3,1,9:106.4
2,1,9:106.4
-2,1,9:106.4
-3,1,9:106.4
4,0,9:106.2
-4,0,9:106.8
3,-1,9:106.1
-3,-1,9:106.1
3,-2,9:106.2
-3,-2,9:106.8
2,-3,9:106.1
1,-3,9:106.2
-1,-3,9:106.8
-2,-3,9:106.1
0,-4,9:106.1
0,4,8:106.4
2,3,8:106.4
1,3,8:106.2
-2,3,8:106.4
3,2,8:106.2
1,2,8:106.4
-1,2,8:106.4
-3,2,8:106.8
3,1,8:106.4
2,1,8:106.4
-3,1,8:106.4
4,0,8:106.2
2,0,8:106.2
-4,0,8:106.8
3,-1,8:106.1
1,-1,8:106.1
0,-1,8:106.1
-3,-1,8:106.1
3,-2,8:106.2
-3,-2,8:106.8
2,-3,8:106.1
1,-3,8:106.2
-1,-3,8:106.8
-2,-3,8:106.1
0,-4,8:106.1
0,4,7:106.4
2,3,7:106.4
1,3,7:106.2
-2,3,7:106.4
3,2,7:106.2
1,2,7:106.4
3,1,7:106.4
1,1,7:106.2
4,0,7:106.2
2,0,7:106.2
0,0,7:106.1
-1,0,7:106.1
-4,0,7:106.8
3,-1,7:106.1
1,-1,7:106.1
0,-1,7:106.1
-3,-1,7:106.1
3,-2,7:106.2
-3,-2,7:106.8
2,-3,7:106.1
1,-3,7:106.2
-1,-3,7:106.8
-2,-3,7:106.1
0,-4,7:106.1
0,4,6:106.4
2,3,6:106.4
1,3,6:106.2
-1,3,6:106.4
-2,3,6:106.4
3,2,6:106.2
-2,2,6:106.8
3,1,6:106.4
1,1,6:106.2
-3,1,6:106.4
4,0,6:106.2
2,0,6:106.2
0,0,6:106.1
-1,0,6:106.1
-4,0,6:106.8
3,-1,6:106.1
2,-1,6:106.2
0,-1,6:106.9
-3,-1,6:106.1
3,-2,6:106.2
1,-2,6:106.1
-3,-2,6:106.8
2,-3,6:106.1
1,-3,6:106.2
-1,-3,6:106.8
-2,-3,6:106.1
0,-4,6:106.1
0,4,5:106.4
2,3,5:106.4
1,3,5:106.2
-1,3,5:106.4
3,2,5:106.2
-1,2,5:106.4
-2,2,5:106.8
3,1,5:106.4
4,0,5:106.2
2,0,5:106.2
1,0,5:106.4
0,0,5:106.1
-1,0,5:106.1
-4,0,5:106.8
3,-1,5:106.1
2,-1,5:106.2
0,-1,5:106.8
-3,-1,5:106.1
3,-2,5:106.2
1,-2,5:106.1
-3,-2,5:106.8
2,-3,5:106.1
1,-3,5:106.2
-1,-3,5:106.8
0,-4,5:106.1
1,3,4:106.2
-1,3,4:106.4
3,2,4:106.2
1,2,4:106.4
-1,2,4:106.4
-2,2,4:106.8
2,1,4:106.2
-4,1,4:106.8
4,0,4:106.2
2,0,4:106.2
1,0,4:106.1
0,0,4:106.1
-1,0,4:106.1
-3,0,4:106.1
-4,0,4:106.8
3,-1,4:106.1
2,-1,4:106.2
0,-1,4:106.8
-3,-1,4:106.1
3,-2,4:106.2
1,-2,4:106.1
-3,-2,4:106.8
1,-3,4:106.2
0,-4,4:106.1
1,3,3:106.2
-1,3,3:106.4
1,2,3:106.4
-1,2,3:106.4
-2,2,3:106.8
2,1,3:106.2
-4,1,3:106.8
2,0,3:106.2
1,0,3:106.1
-1,0,3:106.1
-3,0,3:106.1
-4,0,3:106.8
3,-1,3:106.1
2,-1,3:106.2
-3,-1,3:106.1
1,-2,3:106.1
0,-2,3:106.1
-3,-2,3:106.8
0,-4,3:106.1
1,3,2:106.2
-1,3,2:106.4
1,2,2:106.4
-2,2,2:106.12
2,1,2:106.2
-4,1,2:106.8
2,0,2:106.2
1,0,2:106.1
0,0,2:106.1
-1,0,2:106.1
-2,0,2:106.1
-3,0,2:106.1
-4,0,2:106.8
3,-1,2:106.1
1,-2,2:106.1
0,-2,2:106.1
-3,-2,2:106.8
0,-4,2:106.1
-1,3,1:106.4
1,2,1:106.4
-2,2,1:106.12
2,1,1:106.2
-4,1,1:106.8
1,0,1:106.1
0,0,1:106.1
-1,0,1:106.1
-2,0,1:106.1
-3,0,1:106.1
1,-2,1:106.1
0,-2,1:106.1
-3,-2,1:106.8
0,-4,1:106.1
3,4,0:31.1
2,4,0:31.1
1,4,0:31.1
0,4,0:31.1
-1,4,0:31.1
-2,4,0:31.1
-3,4,0:31.1
4,3,0:31.1
3,3,0:31.1
2,3,0:38.0
1,3,0:31.1
0,3,0:31.1
-1,3,0:37.0
-2,3,0:31.1
-3,3,0:31.1
-4,3,0:31.1
2,2,0:31.1
1,2,0:37.0
-1,2,0:38.0
-3,2,0:31.1
-4,2,0:31.1
3,1,0:31.1
2,1,0:31.1
1,1,0:106.2
-1,1,0:31.1
-3,1,0:31.1
-4,1,0:106.8
3,0,0:31.1
2,0,0:37.0
1,0,0:31.1
0,0,0:106.1
-1,0,0:106.1
-2,0,0:31.1
-3,0,0:31.1
-4,0,0:31.1
4,-1,0:31.1
3,-1,0:31.1
2,-1,0:31.1
1,-1,0:31.1
-1,-1,0:37.0
-3,-1,0:37.0
-4,-1,0:31.1
4,-2,0:31.1
3,-2,0:31.1
1,-2,0:31.1
-1,-2,0:31.1
-2,-2,0:31.1
-3,-2,0:31.1
-4,-2,0:31.1
3,-3,0:31.1
2,-3,0:31.1
1,-3,0:37.0
0,-3,0:31.1
-1,-3,0:31.1
-2,-3,0:31.1
-3,-3,0:31.1
-4,-3,0:31.1
2,-4,0:38.0
1,-4,0:31.1
0,-4,0:106.1
-2,-4,0:31.1
