[META]
version=2.0
spawnOnBlockType=2
spawnSunlight=True
spawnDarkness=True
spawnWater=False
spawnLava=False
underFill=False
randomRotation=True
dig=True
tree=False
branch=False
needsFoundation=True
rarity=1
collisionPercentage=10
spawnElevationMin=0
spawnElevationMax=102
groupId=Ruins
groupFrequencyMin=20
groupFrequencyMax=35
groupSeperationMin=5
groupSeperationMax=60
branchLimit=6
spawnInBiome=All
[DATA]
-1,-3,0:3
1,-3,0:3
-2,-2,0:3
-1,-2,0:3
0,-2,0:3
1,-2,0:3
-2,-1,0:3
0,-1,0:3
2,-1,0:3
-3,0,0:3
-1,0,0:3
1,0,0:3
2,0,0:3
-2,1,0:3
-1,1,0:3
0,1,0:3
1,1,0:3
-1,2,0:3
1,2,0:3
0,-4,1:106.1
-2,-3,1:17.1
-1,-3,1:3
0,-3,1:2
1,-3,1:17.1
-3,-2,1:17.1
-2,-2,1:2
-1,-2,1:2
0,-2,1:3
1,-2,1:2
2,-2,1:17.1
-3,-1,1:2
-2,-1,1:3
-1,-1,1:2
0,-1,1:3
1,-1,1:3
2,-1,1:2
3,-1,1:17.1
-4,0,1:17.1
-3,0,1:2
-2,0,1:3
-1,0,1:3
0,0,1:3
1,0,1:3
2,0,1:3
3,0,1:17.1
-3,1,1:3
-2,1,1:3
-1,1,1:3
0,1,1:2
1,1,1:3
2,1,1:2
-2,2,1:2
-1,2,1:2
0,2,1:2
1,2,1:17.1
-1,3,1:17.1
1,3,1:17.1
-1,-3,2:17.1
0,-2,2:17.1
-2,-1,2:109.0
0,-1,2:17.1
1,-1,2:109.0
-2,0,2:17.1
-1,0,2:17.1
0,0,2:17.1
1,0,2:17.1
2,0,2:17.1
-3,1,2:17.1
-2,1,2:109.0
-1,1,2:17.1
1,1,2:109.0
-1,3,2:106.8
0,-4,2:106.1
-1,-1,3:98.1
0,-1,3:98.0
1,-1,3:98.0
-1,0,3:98.1
0,0,3:17.1
1,0,3:98.1
-1,1,3:98.1
0,1,3:98.1
1,1,3:98.1
-1,3,3:106.8
1,3,3:106.4
2,2,3:106.2
3,-1,3:106.2
0,-4,3:106.1
-2,-1,4:44.5
-1,-1,4:98.1
1,-1,4:98.0
0,0,4:17.1
-2,1,4:44.5
-1,1,4:98.1
1,1,4:98.1
0,-1,4:106.1
-1,3,4:106.8
1,3,4:106.4
2,2,4:106.2
3,-1,4:106.2
0,-4,4:106.1
-1,-1,5:109.2
1,-1,5:109.2
-1,0,5:23.4
0,0,5:17.1
-1,1,5:109.3
0,1,5:17.1
1,1,5:109.3
0,-1,5:106.1
-1,3,5:106.8
1,3,5:106.4
2,2,5:106.2
3,-1,5:106.2
0,-4,5:106.1
-1,0,6:44.5
0,0,6:44.5
1,0,6:44.5
0,1,6:17.1
1,1,6:106.2
-1,1,6:106.8
0,-1,6:106.1
-1,3,6:106.8
-3,1,6:106.8
1,3,6:106.4
2,2,6:106.2
2,-2,6:106.2
3,-1,6:106.2
0,-4,6:106.1
0,0,7:17.1
0,1,7:17.1
1,0,7:106.2
-1,0,7:106.8
0,-1,7:106.1
-1,3,7:106.8
-3,1,7:106.8
1,3,7:106.4
2,2,7:106.2
2,-2,7:106.2
3,-1,7:106.2
0,-4,7:106.1
0,0,8:17.1
1,0,8:106.2
-1,0,8:106.8
0,-1,8:106.1
-3,-1,8:106.1
-1,3,8:106.8
-3,1,8:106.8
1,3,8:106.4
2,2,8:106.2
2,-2,8:106.2
3,-1,8:106.2
0,-4,8:106.1
0,0,9:17.1
-1,3,9:106.8
0,1,9:106.4
1,0,9:106.2
0,-1,9:106.1
-3,-1,9:106.1
-3,1,9:106.8
1,3,9:106.4
2,2,9:106.2
2,-2,9:106.2
3,-1,9:106.2
0,-4,9:106.1
0,0,10:17.1
1,3,10:106.4
-1,3,10:106.8
-1,0,10:106.8
0,-1,10:106.1
-3,-1,10:106.1
0,-4,10:106.1
-3,1,10:106.8
2,2,10:106.2
2,-2,10:106.2
3,-1,10:106.2
0,-3,11:18
-1,-2,11:18
0,-2,11:18
1,-2,11:18
-2,-1,11:18
-1,-1,11:18
0,-1,11:18
1,-1,11:18
2,-1,11:18
-3,0,11:18
-2,0,11:18
-1,0,11:18
0,0,11:17.1
1,0,11:18
2,0,11:18
3,0,11:18
-2,1,11:18
-1,1,11:18
0,1,11:18
1,1,11:18
2,1,11:18
-1,2,11:18
0,2,11:18
1,2,11:18
0,3,11:18
1,3,11:106.4
-1,3,11:106.8
2,2,11:106.2
-2,2,11:106.8
3,1,11:106.4
-3,1,11:106.8
-4,0,11:106.8
3,-1,11:106.2
-3,-1,11:106.1
2,-2,11:106.2
-2,-2,11:106.1
1,-3,11:106.2
-1,-3,11:106.1
0,-4,11:106.1
0,-2,12:18
-1,-1,12:18
0,-1,12:18
1,-1,12:18
-2,0,12:18
-1,0,12:18
0,0,12:18
1,0,12:18
2,0,12:18
-1,1,12:18
0,1,12:18
1,1,12:18
0,2,12:18
