[META]
version=2.0
spawnOnBlockType=2
spawnSunlight=True
spawnDarkness=True
spawnWater=False
spawnLava=False
underFill=False
randomRotation=True
dig=True
tree=False
branch=False
needsFoundation=True
rarity=1
collisionPercentage=50
spawnElevationMin=0
spawnElevationMax=102
groupId=Ruins
groupFrequencyMin=20
groupFrequencyMax=35
groupSeperationMin=5
groupSeperationMax=60
branchLimit=6
spawnInBiome=All
[DATA]
-1,-4,0:98.1
1,-4,0:44.5
2,-4,0:44.5
3,-4,0:44.3
-2,-3,0:44.5
-1,-3,0:98.1
0,-3,0:98.0
1,-3,0:98.0
2,-3,0:98.0
3,-3,0:98.1
4,-3,0:44.5
-2,-2,0:98.1
-1,-2,0:98.2
0,-2,0:11
1,-2,0:11
2,-2,0:11
3,-2,0:98.0
4,-2,0:98.0
5,-2,0:44.5
-2,-1,0:44.5
-1,-1,0:98.1
0,-1,0:98.1
1,-1,0:98.0
2,-1,0:98.1
3,-1,0:98.1
4,-1,0:98.0
0,0,0:44.5
1,0,0:44.5
2,0,0:106.4
-1,0,0:106.4
0,-4,0:106.1
-1,-3,1:98.1
0,-3,1:98.2
1,-3,1:98.2
2,-3,1:98.2
3,-3,1:98.1
-1,-2,1:98.0
0,-2,1:11
1,-2,1:11
2,-2,1:11
3,-2,1:98.0
-1,-1,1:98.1
0,-1,1:98.0
1,-1,1:98.0
2,-1,1:98.0
3,-1,1:98.0
2,0,1:106.4
-1,0,1:106.4
4,-3,1:106.2
3,-4,1:106.1
0,-4,1:106.1
-1,-4,1:106.1
-1,-3,2:98.1
0,-3,2:98.0
1,-3,2:98.0
2,-3,2:98.0
3,-3,2:98.1
-1,-2,2:98.0
3,-2,2:98.1
-1,-1,2:98.0
3,-1,2:98.0
-1,0,2:106.4
4,-1,2:106.2
4,-2,2:106.2
4,-3,2:106.2
-2,-3,2:106.8
3,-4,2:106.1
-1,-4,2:106.1
-1,-3,3:98.1
1,-3,3:98.0
2,-3,3:30
3,-3,3:98.0
-1,-2,3:98.1
1,-2,3:98.0
3,-2,3:98.1
-1,-1,3:98.0
0,-1,3:98.0
1,-1,3:98.0
2,-1,3:98.0
3,-1,3:98.0
-1,0,3:106.4
4,-1,3:106.2
-2,-1,3:106.8
4,-2,3:106.2
-2,-2,3:106.8
-2,-3,3:106.8
3,-4,3:106.1
-1,-4,3:106.1
-1,-3,4:98.0
0,-3,4:98.0
1,-3,4:98.1
2,-3,4:98.0
3,-3,4:98.1
-1,-2,4:98.1
0,-2,4:30
1,-2,4:98.0
3,-2,4:98.1
-1,-1,4:98.1
1,-1,4:98.0
3,-1,4:98.1
-1,0,4:106.4
4,-1,4:106.2
-2,-1,4:106.8
4,-2,4:106.2
-2,-2,4:106.8
-2,-3,4:106.8
3,-4,4:106.1
-1,-4,4:106.1
-1,-3,5:44.5
0,-3,5:98.1
1,-3,5:98.1
2,-3,5:98.1
-1,-2,5:98.1
0,-2,5:98.1
1,-2,5:98.1
2,-2,5:98.1
3,-2,5:98.1
0,-1,5:98.1
1,-1,5:98.1
2,-1,5:98.1
4,-2,5:106.2
-2,-2,5:106.8
-2,-3,-1:3
-2,-2,-1:3
-2,-1,-1:3
-1,-1,-1:3
-1,-2,-1:3
-1,-3,-1:3
0,-3,-1:3
1,-3,-1:3
2,-3,-1:3
3,-3,-1:3
4,-3,-1:3
4,-2,-1:3
4,-1,-1:3
3,-1,-1:3
2,-1,-1:3
1,-1,-1:3
0,-1,-1:3
1,-2,-1:3
2,-2,-1:3
3,-2,-1:3
0,-2,-1:3
