[META]
version=2.0
spawnOnBlockType=2
spawnSunlight=True
spawnDarkness=True
spawnWater=False
spawnLava=False
underFill=False
randomRotation=True
dig=True
tree=False
branch=False
needsFoundation=True
rarity=1
collisionPercentage=10
spawnElevationMin=0
spawnElevationMax=102
groupId=Ruins
groupFrequencyMin=20
groupFrequencyMax=35
groupSeperationMin=5
groupSeperationMax=60
branchLimit=6
spawnInBiome=All
[DATA]
0,0,-3:3.0
0,-1,-2:3.0
-1,0,-2:3.0
0,0,-2:3.0
1,0,-2:3.0
0,1,-2:3.0
0,-2,-1:2.5
-1,-1,-1:2.5
0,-1,-1:3.0
1,-1,-1:2.5
-2,0,-1:2.5
-1,0,-1:3.0
0,0,-1:3.0
1,0,-1:3.0
2,0,-1:2.5
-1,1,-1:2.5
0,1,-1:3.0
1,1,-1:3.0
0,2,-1:2.5
-1,-1,0:44.5
0,-1,0:23.2
1,-1,0:44.5
-1,0,0:23.4
0,0,0:98.1
1,0,0:23.5
-1,1,0:44.5
0,1,0:23.3
1,1,0:44.5
0,-1,1:44.5
-1,0,1:44.5
0,0,1:98.2
1,0,1:44.5
0,1,1:44.5
0,0,2:98.1
0,0,3:98.2
0,0,4:98.1
0,-1,5:109.2
-1,0,5:109.0
0,0,5:98.2
1,0,5:109.1
0,1,5:109.3
0,-2,6:44.5
0,-1,6:109.2
-2,0,6:44.5
-1,0,6:109.0
0,0,6:98.1
1,0,6:109.1
2,0,6:44.5
0,1,6:109.3
0,2,6:44.5
-1,-1,7:44.5
0,-1,7:44.5
1,-1,7:44.5
-1,0,7:44.5
0,0,7:15.5
1,0,7:44.5
-1,1,7:44.5
0,1,7:44.5
1,1,7:44.5
0,1,4:106.4
1,0,4:106.2
-1,0,4:106.8
0,-1,4:106.1
0,1,3:106.4
1,0,3:106.2
-1,0,3:106.8
0,-1,3:106.1
0,1,2:106.4
1,0,2:106.2
-1,0,2:106.8
0,-1,2:106.1
0,2,0:37.0
2,0,0:31.1
-2,0,0:31.1
0,-2,0:31.1
