[META]
version=2.0
spawnOnBlockType=2
spawnSunlight=True
spawnDarkness=True
spawnWater=False
spawnLava=False
underFill=False
randomRotation=True
dig=True
tree=False
branch=False
needsFoundation=True
rarity=1
collisionPercentage=30
spawnElevationMin=0
spawnElevationMax=102
groupId=Ruins
groupFrequencyMin=20
groupFrequencyMax=35
groupSeperationMin=5
groupSeperationMax=60
branchLimit=6
spawnInBiome=All
[DATA]
-1,-2,0:1
0,-2,0:1
1,-2,0:1
-2,-1,0:1
2,-1,0:1
-2,0,0:1
2,0,0:1
-2,1,0:1
2,1,0:1
-1,2,0:1
0,2,0:1
1,2,0:1
1,3,0:106.4
2,2,0:31.2
0,-2,-3:3
-1,-1,-3:3
0,-1,-3:3
1,-1,-3:3
-2,0,-3:3
-1,0,-3:3
0,0,-3:3
1,0,-3:3
2,0,-3:3
-1,1,-3:3
0,1,-3:3
1,1,-3:3
0,2,-3:3
-1,-2,-2:3
0,-2,-2:3
1,-2,-2:3
-2,-1,-2:3
-1,-1,-2:3
0,-1,-2:3
1,-1,-2:3
2,-1,-2:3
-2,0,-2:3
-1,0,-2:3
0,0,-2:3
1,0,-2:3
2,0,-2:3
-2,1,-2:3
-1,1,-2:3
0,1,-2:3
1,1,-2:3
2,1,-2:3
-1,2,-2:3
0,2,-2:3
1,2,-2:3
-3,-3,-1:2
-2,-3,-1:2
-1,-3,-1:2
0,-3,-1:2
1,-3,-1:2
2,-3,-1:2
-3,-2,-1:2
-2,-2,-1:2
-1,-2,-1:3
0,-2,-1:3
1,-2,-1:3
2,-2,-1:2
-3,-1,-1:2
-2,-1,-1:2
-1,-1,-1:2
0,-1,-1:2
1,-1,-1:2
2,-1,-1:3
-3,0,-1:2
-2,0,-1:3
-1,0,-1:2
0,0,-1:2
1,0,-1:3
2,0,-1:3
-3,1,-1:2
-2,1,-1:2
-1,1,-1:2
0,1,-1:2
1,1,-1:2
2,1,-1:3
-3,2,-1:2
-2,2,-1:2
-1,2,-1:3
0,2,-1:3
1,2,-1:3
2,2,-1:2
-2,3,-1:2
-1,3,-1:2
0,3,-1:2
1,3,-1:2
2,3,-1:2
-1,-2,1:1
0,-2,1:1
1,-2,1:1
-2,-1,1:1
2,-1,1:1
-2,0,1:1
2,0,1:1
-1,1,1:98.0
1,1,1:98.0
-1,2,1:98.0
0,2,1:98.0
1,2,1:98.1
2,3,1:106.4
1,3,1:106.4
2,2,1:106.2
-1,-3,2:1
0,-3,2:1
1,-3,2:1
-2,-2,2:1
-1,-2,2:1
0,-2,2:1
1,-2,2:1
2,-2,2:1
-2,-1,2:1
2,-1,2:1
-2,0,2:1
0,0,2:1
2,0,2:1
-2,1,2:1
-1,1,2:1
1,1,2:1
2,1,2:1
-2,2,2:1
-1,2,2:1
1,2,2:1
2,2,2:1
2,3,2:106.4
1,3,2:106.4
-2,-3,3:1
-1,-3,3:1
0,-3,3:1
1,-3,3:1
2,-3,3:1
-2,-2,3:1
2,-2,3:1
-2,-1,3:1
2,-1,3:1
-2,0,3:1
0,0,3:1
2,0,3:1
-2,1,3:1
-1,1,3:56
0,1,3:1
1,1,3:56
2,1,3:1
0,2,3:1
2,3,3:106.4
-2,-3,4:1
-1,-3,4:1
0,-3,4:1
1,-3,4:1
2,-3,4:1
-2,-2,4:1
2,-2,4:1
-2,-1,4:1
2,-1,4:1
-2,0,4:1
0,0,4:89
2,0,4:1
-2,1,4:1
-1,1,4:1
0,1,4:1
1,1,4:1
2,1,4:1
-2,2,4:1
-1,2,4:1
0,2,4:1
1,2,4:1
2,2,4:1
2,3,4:106.4
1,3,4:106.4
0,3,4:106.4
-1,-3,5:1
0,-3,5:1
1,-3,5:1
-2,-2,5:1
-1,-2,5:1
0,-2,5:1
1,-2,5:1
2,-2,5:1
-2,-1,5:1
-1,-1,5:1
0,-1,5:1
1,-1,5:1
2,-1,5:1
-2,0,5:1
-1,0,5:1
0,0,5:1
1,0,5:1
2,0,5:1
-2,1,5:1
-1,1,5:1
0,1,5:1
1,1,5:1
2,1,5:1
-1,2,5:1
0,2,5:1
1,2,5:1
1,3,5:106.4
0,3,5:106.4
