[META]
version=2.0
spawnOnBlockType=2
spawnSunlight=True
spawnDarkness=True
spawnWater=False
spawnLava=False
underFill=False
randomRotation=True
dig=True
tree=False
branch=False
needsFoundation=True
rarity=1
collisionPercentage=10
spawnElevationMin=0
spawnElevationMax=102
groupId=Ruins
groupFrequencyMin=20
groupFrequencyMax=35
groupSeperationMin=5
groupSeperationMax=60
branchLimit=6
spawnInBiome=All
[DATA]
-1,-1,-2:3.0
0,-1,-2:3.0
1,-1,-2:3.0
-1,0,-2:3.0
0,0,-2:3.0
1,0,-2:3.0
-1,1,-2:3.0
0,1,-2:3.0
1,1,-2:3.0
-1,-2,-1:2.0
0,-2,-1:2.0
1,-2,-1:2.0
-2,-1,-1:2.0
-1,-1,-1:2.0
0,-1,-1:3.0
1,-1,-1:2.0
2,-1,-1:2.0
-2,0,-1:2.0
-1,0,-1:3.0
0,0,-1:3.0
1,0,-1:3.0
2,0,-1:2.0
-2,1,-1:2.0
-1,1,-1:2.0
0,1,-1:3.0
1,1,-1:3.0
2,1,-1:2.0
-1,2,-1:2.0
0,2,-1:2.0
1,2,-1:2.0
-1,-1,0:44.5
0,-1,0:109.2
1,-1,0:44.5
-1,0,0:109.0
0,0,0:89.0
1,0,0:109.1
-1,1,0:44.5
0,1,0:109.3
1,1,0:44.5
-1,-1,1:109.0
0,-1,1:44.5
1,-1,1:109.1
-1,0,1:44.5
1,0,1:44.5
-1,1,1:109.0
0,1,1:44.5
1,1,1:109.1
-1,-1,2:44.5
0,-1,2:109.2
1,-1,2:44.5
-1,0,2:109.0
0,0,2:98.0
1,0,2:109.1
-1,1,2:44.5
0,1,2:109.3
1,1,2:44.5
0,0,3:44.5
1,2,0:31.1
0,2,0:31.1
2,0,0:31.1
-2,0,0:31.1
2,-1,0:31.1
-2,-1,0:31.1
1,-2,0:31.1
0,-2,0:31.1
-1,-2,0:31.1
