[META]
version=2.0
spawnOnBlockType=3,2,12,1
spawnSunlight=True
spawnDarkness=True
spawnWater=False
spawnLava=False
underFill=False
randomRotation=True
dig=False
tree=True
branch=False
needsFoundation=False
rarity=10
collisionPercentage=2
spawnElevationMin=0
spawnElevationMax=128
spawnInBiome=Forest,Taiga,Tundra
[DATA]
1,-1,0:17.0
0,0,0:17.0
-1,1,0:17.0
1,1,0:17.0
-1,-1,0:17.0
1,0,0:18.2
0,0,1:17.0
-1,0,1:18.2
0,1,1:18.2
0,0,2:17.0
0,-1,2:18.2
0,0,3:17.0
0,1,3:18.2
0,0,4:17.0
-1,0,4:18.2
0,0,5:17.0
-1,-1,5:17.0
1,0,5:17.0
2,1,5:17.0
-2,-1,5:17.0
0,1,5:17.0
-1,2,5:17.0
1,-1,5:17.0
-2,-2,5:18.2
-2,0,5:18.2
-2,2,5:18.2
0,2,5:18.2
-1,3,5:18.2
-3,-1,5:18.2
0,-1,5:18.2
1,-2,5:18.2
2,-1,5:18.2
3,1,5:18.2
1,1,5:18.2
2,2,5:18.2
2,0,5:18.2
-1,1,5:18.2
-1,0,5:18.2
-1,-2,5:18.2
-2,-1,6:17.0
-2,2,6:17.0
1,-2,6:17.0
3,1,6:17.0
0,0,6:17.0
-2,-2,6:18.2
-3,-1,6:18.2
-2,0,6:18.2
-2,1,6:18.2
-3,2,6:18.2
-2,3,6:18.2
2,2,6:18.2
2,0,6:18.2
3,0,6:18.2
3,2,6:18.2
2,-2,6:18.2
1,-3,6:18.2
0,-2,6:18.2
-1,-1,6:18.2
1,-1,6:18.2
1,0,6:18.2
0,1,6:18.2
2,1,6:18.2
-1,2,6:18.2
2,-3,7:17.0
3,2,7:17.0
-3,2,7:17.0
-1,2,7:17.0
-2,-2,7:17.0
0,0,7:17.0
1,1,7:17.0
-1,0,7:17.0
-1,-3,7:18.2
-2,-3,7:18.2
-2,-1,7:18.2
-3,0,7:18.2
-2,2,7:18.2
-1,3,7:18.2
-1,1,7:18.2
1,2,7:18.2
1,0,7:18.2
2,1,7:18.2
3,1,7:18.2
2,3,7:18.2
1,-3,7:18.2
1,-2,7:18.2
2,-2,7:18.2
-3,-2,7:18.2
-3,3,7:18.2
0,-1,7:18.2
0,2,7:18.2
-2,-2,8:18.2
-1,-3,8:18.2
-2,-1,8:18.2
-1,0,8:18.2
0,0,8:18.2
0,-1,8:18.2
-1,2,8:18.2
-2,1,8:18.2
-3,2,8:18.2
-2,3,8:18.2
1,1,8:18.2
2,0,8:18.2
2,2,8:18.2
3,2,8:18.2
2,-3,8:18.2
1,-2,8:18.2
3,-2,8:18.2
-1,0,9:18.2
0,-1,9:18.2
0,1,9:18.2
1,0,9:18.2
0,-2,9:18.2
-2,-1,9:18.2
0,2,9:18.2
