[META]
version=2.0
spawnOnBlockType=2
spawnSunlight=True
spawnDarkness=True
spawnWater=False
spawnLava=False
underFill=False
randomRotation=True
dig=False
tree=False
branch=False
needsFoundation=True
rarity=1000
collisionPercentage=100
spawnElevationMin=0
spawnElevationMax=150
spawnInBiome=Forest2
[DATA]
0,-2,0:17.0
1,-2,0:17.0
-2,-1,0:17.0
-1,-1,0:17.0
0,-1,0:17.0
1,-1,0:17.0
-2,0,0:17.0
-1,0,0:17.0
0,0,0:17.0
1,0,0:17.0
-2,1,0:17.0
-1,1,0:17.0
0,1,0:17.0
1,1,0:17.0
0,2,0:17.0
2,0,0:31.1
2,-1,0:31.2
-1,-2,0:31.2
0,-1,-2:3
-1,0,-2:3
0,0,-2:3
1,0,-2:17.0
0,1,-2:3
0,2,-2:17.0
0,3,-2:17.0
0,4,-2:17.0
-1,4,-2:17.0
-1,1,-2:17.0
-2,1,-2:17.0
-3,1,-2:17.0
-3,2,-2:17.0
-3,3,-2:17.0
-4,3,-2:17.0
-1,-1,-2:17.0
-2,-1,-2:17.0
-2,-2,-2:17.0
-3,-2,-2:17.0
-3,-3,-2:17.0
-4,-3,-2:17.0
0,-3,-2:17.0
1,-3,-2:17.0
2,-3,-2:17.0
2,-4,-2:17.0
2,0,-2:17.0
3,0,-2:17.0
1,1,-2:17.0
1,2,-2:17.0
2,2,-2:17.0
2,3,-2:17.0
3,-1,-2:17.0
4,-1,-2:17.0
0,-2,-2:17.0
1,-1,-2:17.0
-2,0,-2:17.0
-1,-2,-2:3
1,-2,-2:3
2,-1,-2:3
2,1,-2:3
-1,2,-2:3
-3,0,-2:3
-1,-2,-1:2
0,-2,-1:3
1,-2,-1:17.0
-2,-1,-1:17.0
-1,-1,-1:17.0
0,-1,-1:3
1,-1,-1:3
2,-1,-1:2
-2,0,-1:3
-1,0,-1:17.0
0,0,-1:3
1,0,-1:17.0
2,0,-1:17.0
-2,1,-1:17.0
-1,1,-1:17.0
0,1,-1:3
1,1,-1:17.0
2,1,-1:2
-1,2,-1:2
0,2,-1:17.0
1,2,-1:2
0,-3,-1:17.0
1,-3,-1:17.0
0,-2,1:17.0
-1,-1,1:17.0
0,-1,1:17.0
1,-1,1:17.0
-2,0,1:17.0
-1,0,1:17.0
0,0,1:17.0
1,0,1:17.0
-2,1,1:17.0
-1,1,1:17.0
0,1,1:17.0
1,1,1:17.0
0,2,1:17.0
-1,-1,2:17.0
0,-1,2:17.0
1,-1,2:17.0
-2,0,2:17.0
-1,0,2:17.0
0,0,2:17.0
1,0,2:17.0
-2,1,2:17.0
-1,1,2:17.0
0,1,2:17.0
1,1,2:17.0
0,2,2:17.0
-1,-1,3:17.0
0,-1,3:17.0
1,-1,3:17.0
-2,0,3:17.0
-1,0,3:17.0
0,0,3:17.0
1,0,3:17.0
-2,1,3:17.0
-1,1,3:17.0
0,1,3:17.0
1,1,3:17.0
-1,-1,4:17.0
0,-1,4:17.0
1,-1,4:17.0
-2,0,4:17.0
-1,0,4:17.0
0,0,4:17.0
1,0,4:17.0
-2,1,4:17.0
-1,1,4:17.0
0,1,4:17.0
1,1,4:17.0
-1,-1,5:17.0
0,-1,5:17.0
1,-1,5:17.0
-2,0,5:17.0
-1,0,5:17.0
0,0,5:17.0
1,0,5:17.0
-1,1,5:17.0
0,1,5:17.0
1,1,5:17.0
-1,-1,6:17.0
0,-1,6:17.0
1,-1,6:17.0
-1,0,6:17.0
0,0,6:17.0
1,0,6:17.0
-1,1,6:17.0
0,1,6:17.0
-1,-1,7:17.0
0,-1,7:17.0
1,-1,7:17.0
-1,0,7:17.0
0,0,7:17.0
1,0,7:17.0
-1,1,7:17.0
0,1,7:17.0
-1,-1,8:17.0
0,-1,8:17.0
1,-1,8:17.0
-1,0,8:17.0
0,0,8:17.0
-1,1,8:17.0
0,1,8:17.0
-1,-1,9:17.0
0,-1,9:17.0
-1,0,9:17.0
0,0,9:17.0
-1,1,9:17.0
0,1,9:17.0
-1,-1,10:17.0
0,-1,10:17.0
-2,0,10:17.0
-1,0,10:17.0
0,0,10:17.0
-2,1,10:17.0
-1,1,10:17.0
0,1,10:17.0
-1,-1,11:17.0
-2,0,11:17.0
-1,0,11:17.0
0,0,11:17.0
-2,1,11:17.0
-1,1,11:17.0
0,1,11:17.0
-6,-1,12:18
-3,0,12:17.0
-2,0,12:17.0
-1,0,12:17.0
0,0,12:17.0
-2,1,12:17.0
-1,1,12:17.0
0,1,12:17.0
-6,2,12:18
-5,2,12:18
-6,-3,13:18
-6,-2,13:18
-5,-2,13:18
-4,-2,13:18
-6,-1,13:18
-5,-1,13:18
-4,-1,13:18
-3,-1,13:18
-6,0,13:18
-5,0,13:18
-4,0,13:17.0
-3,0,13:17.0
-1,0,13:17.0
0,0,13:17.0
-5,1,13:18
-4,1,13:17.0
-1,1,13:17.0
0,1,13:17.0
-5,2,13:18
-4,2,13:18
-4,0,14:18
-3,0,14:18
-1,0,14:17.0
0,0,14:17.0
-4,1,14:18
-1,1,14:17.0
0,1,14:17.0
-1,0,15:17.0
0,0,15:17.0
-1,1,15:17.0
0,1,15:17.0
2,-15,16:18
3,-15,16:18
0,-14,16:18
-5,-11,16:18
-6,-8,16:18
-1,0,16:17.0
0,0,16:17.0
-1,1,16:17.0
0,1,16:17.0
-5,17,16:18
0,-15,17:18
1,-15,17:18
2,-15,17:18
3,-15,17:18
-2,-14,17:18
-1,-14,17:18
0,-14,17:18
1,-14,17:18
2,-14,17:18
3,-14,17:18
4,-14,17:18
5,-14,17:18
6,-13,17:18
7,-13,17:18
16,-13,17:18
14,-12,17:18
15,-12,17:18
16,-12,17:18
18,-12,17:18
-5,-11,17:18
-7,-10,17:18
-6,-10,17:18
-5,-10,17:18
-7,-9,17:18
-6,-9,17:18
15,-9,17:18
-6,-8,17:18
-5,-8,17:18
-1,0,17:17.0
0,0,17:17.0
-1,1,17:17.0
0,1,17:17.0
-5,17,17:18
-4,17,17:18
-12,18,17:18
-6,19,17:18
2,-16,18:18
0,-15,18:18
1,-15,18:18
2,-15,18:18
4,-15,18:18
-1,-14,18:18
0,-14,18:17.0
1,-14,18:17.0
2,-14,18:17.0
3,-14,18:18
4,-14,18:18
5,-14,18:18
6,-14,18:18
7,-14,18:18
16,-14,18:18
-2,-13,18:18
-1,-13,18:18
0,-13,18:18
1,-13,18:18
2,-13,18:17.0
3,-13,18:18
4,-13,18:17.0
5,-13,18:17.0
6,-13,18:17.0
7,-13,18:18
8,-13,18:18
15,-13,18:18
16,-13,18:17.0
17,-13,18:18
-4,-12,18:18
0,-12,18:18
1,-12,18:18
2,-12,18:17.0
3,-12,18:17.0
4,-12,18:17.0
6,-12,18:18
7,-12,18:18
13,-12,18:18
14,-12,18:18
15,-12,18:18
16,-12,18:17.0
17,-12,18:18
18,-12,18:18
-5,-11,18:18
-4,-11,18:18
12,-11,18:18
13,-11,18:18
14,-11,18:18
15,-11,18:18
16,-11,18:17.0
17,-11,18:18
18,-11,18:18
19,-11,18:18
-6,-10,18:18
-5,-10,18:18
-4,-10,18:18
-1,-10,18:18
10,-10,18:18
11,-10,18:18
12,-10,18:18
13,-10,18:18
14,-10,18:17.0
15,-10,18:18
17,-10,18:18
-6,-9,18:18
-5,-9,18:18
11,-9,18:18
12,-9,18:18
14,-9,18:17.0
15,-9,18:18
17,-9,18:18
-5,-8,18:18
-2,-8,18:18
16,-7,18:18
-18,-2,18:18
-1,0,18:17.0
0,0,18:17.0
-1,1,18:17.0
0,1,18:17.0
15,1,18:18
14,2,18:18
15,2,18:18
15,3,18:18
15,5,18:18
15,6,18:18
-14,8,18:18
-13,8,18:18
-13,9,18:18
16,9,18:18
-13,11,18:18
-12,12,18:18
6,12,18:18
-14,13,18:18
-13,13,18:18
-15,14,18:18
-13,14,18:18
-15,15,18:18
-5,15,18:18
-4,15,18:18
-3,15,18:18
-2,15,18:18
-1,15,18:18
-14,16,18:18
-6,16,18:18
-3,16,18:18
-2,16,18:18
-15,17,18:18
-12,17,18:17.0
-10,17,18:18
-6,17,18:18
-5,17,18:18
-4,17,18:18
9,17,18:18
-13,18,18:18
-12,18,18:18
-11,18,18:18
-10,18,18:18
-9,18,18:18
-8,18,18:18
-7,18,18:18
12,18,18:18
-9,19,18:18
-7,19,18:18
-6,19,18:18
0,-14,19:18
1,-14,19:18
2,-14,19:18
2,-13,19:18
3,-13,19:18
4,-13,19:18
5,-13,19:18
6,-13,19:18
16,-13,19:18
17,-13,19:18
-4,-12,19:18
-3,-12,19:18
-2,-12,19:18
-1,-12,19:18
2,-12,19:18
3,-12,19:17.0
4,-12,19:18
5,-12,19:18
6,-12,19:18
16,-12,19:18
17,-12,19:18
18,-12,19:18
-4,-11,19:18
-3,-11,19:18
-2,-11,19:18
-1,-11,19:18
8,-11,19:18
15,-11,19:18
16,-11,19:17.0
17,-11,19:18
19,-11,19:18
-5,-10,19:18
-4,-10,19:17.0
-3,-10,19:18
-2,-10,19:18
-1,-10,19:18
8,-10,19:18
10,-10,19:18
11,-10,19:18
12,-10,19:18
14,-10,19:18
15,-10,19:18
16,-10,19:17.0
17,-10,19:18
18,-10,19:18
-6,-9,19:18
-5,-9,19:18
-4,-9,19:17.0
-3,-9,19:17.0
-2,-9,19:17.0
-1,-9,19:17.0
8,-9,19:18
9,-9,19:18
11,-9,19:18
12,-9,19:18
13,-9,19:18
14,-9,19:18
15,-9,19:18
16,-9,19:17.0
17,-9,19:18
18,-9,19:18
-5,-8,19:18
-4,-8,19:18
-3,-8,19:18
-2,-8,19:18
-1,-8,19:18
12,-8,19:18
13,-8,19:18
14,-8,19:17.0
15,-8,19:17.0
16,-8,19:17.0
-19,-7,19:18
-4,-7,19:18
-3,-7,19:18
-2,-7,19:18
13,-7,19:18
14,-7,19:17.0
15,-7,19:18
16,-7,19:18
17,-7,19:18
-19,-6,19:18
-18,-6,19:18
-3,-6,19:18
14,-6,19:17.0
15,-6,19:18
16,-6,19:18
-20,-5,19:18
-17,-3,19:18
18,-3,19:18
-18,-2,19:18
-17,-2,19:18
-18,-1,19:18
-17,-1,19:18
-17,0,19:18
-1,0,19:17.0
0,0,19:17.0
15,0,19:18
-1,1,19:17.0
0,1,19:17.0
14,1,19:17.0
15,1,19:17.0
16,1,19:18
17,1,19:18
12,2,19:18
14,2,19:18
15,2,19:18
16,2,19:18
15,3,19:18
-12,4,19:18
-12,5,19:18
13,5,19:18
14,5,19:18
15,5,19:18
-14,6,19:18
-13,6,19:18
14,6,19:18
15,6,19:18
-15,7,19:18
-14,7,19:18
14,7,19:18
15,7,19:18
16,7,19:18
-13,8,19:18
16,8,19:18
-13,9,19:18
-7,9,19:18
16,9,19:18
-13,10,19:18
-13,11,19:18
-12,11,19:18
-12,12,19:18
-6,12,19:18
-5,12,19:18
-4,12,19:18
-3,12,19:18
5,12,19:18
6,12,19:18
7,12,19:18
-15,13,19:18
-14,13,19:18
-13,13,19:18
-12,13,19:18
-11,13,19:18
-10,13,19:18
-9,13,19:18
-7,13,19:18
-6,13,19:18
-5,13,19:18
-4,13,19:18
-3,13,19:18
16,13,19:18
-16,14,19:18
-15,14,19:18
-14,14,19:18
-13,14,19:18
-12,14,19:18
-11,14,19:17.0
-10,14,19:17.0
-9,14,19:17.0
-8,14,19:17.0
-7,14,19:18
-6,14,19:17.0
-5,14,19:18
-4,14,19:18
-3,14,19:18
1,14,19:18
16,14,19:18
-16,15,19:18
-15,15,19:18
-14,15,19:17.0
-13,15,19:17.0
-12,15,19:17.0
-11,15,19:17.0
-10,15,19:18
-9,15,19:18
-8,15,19:17.0
-7,15,19:18
-6,15,19:17.0
-5,15,19:18
-4,15,19:18
16,15,19:18
-15,16,19:18
-14,16,19:18
-13,16,19:18
-12,16,19:17.0
-11,16,19:18
-10,16,19:18
-9,16,19:18
-8,16,19:17.0
-7,16,19:18
-6,16,19:17.0
-5,16,19:17.0
-4,16,19:17.0
-3,16,19:17.0
12,16,19:18
-15,17,19:18
-14,17,19:18
-13,17,19:18
-12,17,19:17.0
-11,17,19:18
-9,17,19:18
-8,17,19:17.0
-7,17,19:17.0
-6,17,19:17.0
-5,17,19:18
-4,17,19:18
-3,17,19:18
9,17,19:18
10,17,19:17.0
11,17,19:17.0
12,17,19:17.0
13,17,19:17.0
-15,18,19:18
-14,18,19:18
-13,18,19:18
-12,18,19:18
-11,18,19:18
-10,18,19:18
-8,18,19:18
-7,18,19:18
-6,18,19:18
-5,18,19:18
-2,18,19:18
9,18,19:18
10,18,19:18
11,18,19:18
12,18,19:18
13,18,19:18
-10,19,19:18
-8,19,19:18
-7,19,19:18
-6,19,19:18
-5,19,19:18
-3,19,19:18
9,19,19:18
-9,-17,20:18
-10,-16,20:18
-10,-15,20:18
2,-15,20:18
3,-15,20:18
2,-14,20:18
3,-14,20:18
4,-14,20:18
1,-13,20:18
2,-13,20:18
3,-13,20:18
4,-13,20:18
5,-13,20:18
-16,-12,20:18
-15,-12,20:18
-14,-12,20:18
-13,-12,20:18
-1,-12,20:18
0,-12,20:18
1,-12,20:18
2,-12,20:18
3,-12,20:17.0
4,-12,20:18
5,-12,20:18
6,-12,20:18
-19,-11,20:18
-18,-11,20:18
-17,-11,20:18
-1,-11,20:18
0,-11,20:18
1,-11,20:18
2,-11,20:18
3,-11,20:17.0
4,-11,20:18
5,-11,20:18
7,-11,20:18
16,-11,20:18
17,-11,20:18
18,-11,20:18
-19,-10,20:18
-18,-10,20:18
-17,-10,20:18
-5,-10,20:18
-4,-10,20:18
-2,-10,20:18
0,-10,20:17.0
1,-10,20:18
2,-10,20:18
3,-10,20:17.0
4,-10,20:18
5,-10,20:18
7,-10,20:18
10,-10,20:18
11,-10,20:18
12,-10,20:18
16,-10,20:18
17,-10,20:18
18,-10,20:18
-4,-9,20:18
-3,-9,20:18
-2,-9,20:18
-1,-9,20:17.0
0,-9,20:17.0
1,-9,20:17.0
2,-9,20:17.0
3,-9,20:17.0
5,-9,20:18
7,-9,20:18
8,-9,20:18
9,-9,20:18
10,-9,20:18
13,-9,20:18
15,-9,20:18
16,-9,20:18
17,-9,20:18
18,-9,20:18
-18,-8,20:18
-1,-8,20:18
0,-8,20:18
3,-8,20:18
8,-8,20:18
9,-8,20:17.0
14,-8,20:18
15,-8,20:18
16,-8,20:18
17,-8,20:18
-19,-7,20:18
-18,-7,20:18
0,-7,20:18
9,-7,20:17.0
14,-7,20:18
17,-7,20:18
-20,-6,20:18
-19,-6,20:18
-18,-6,20:17.0
-17,-6,20:18
9,-6,20:17.0
14,-6,20:17.0
16,-6,20:18
-21,-5,20:18
-20,-5,20:18
-19,-5,20:18
-18,-5,20:18
-17,-5,20:18
14,-5,20:17.0
15,-5,20:18
16,-5,20:18
-20,-4,20:18
-19,-4,20:18
13,-4,20:18
14,-4,20:17.0
15,-4,20:18
18,-4,20:18
-17,-3,20:18
14,-3,20:17.0
16,-3,20:18
17,-3,20:18
18,-3,20:18
-18,-2,20:18
-17,-2,20:17.0
16,-2,20:18
18,-2,20:18
-19,-1,20:18
-18,-1,20:18
-17,-1,20:18
-16,-1,20:18
16,-1,20:18
-18,0,20:18
-17,0,20:18
-1,0,20:17.0
0,0,20:17.0
12,0,20:18
13,0,20:18
14,0,20:18
15,0,20:18
16,0,20:18
-16,1,20:18
-15,1,20:18
-1,1,20:17.0
0,1,20:17.0
12,1,20:17.0
13,1,20:17.0
14,1,20:17.0
15,1,20:18
16,1,20:18
17,1,20:18
-1,2,20:17.0
0,2,20:17.0
11,2,20:18
12,2,20:17.0
13,2,20:18
14,2,20:18
17,2,20:18
-15,3,20:18
-12,3,20:18
-1,3,20:17.0
12,3,20:18
14,3,20:18
15,3,20:18
-15,4,20:18
-14,4,20:18
-13,4,20:18
-12,4,20:18
-11,4,20:18
14,4,20:18
-15,5,20:18
-14,5,20:18
-13,5,20:18
-12,5,20:17.0
-11,5,20:18
12,5,20:18
13,5,20:18
-14,6,20:18
-13,6,20:18
-12,6,20:17.0
-11,6,20:18
-10,6,20:18
-7,6,20:18
13,6,20:18
14,6,20:18
-15,7,20:18
-14,7,20:18
-13,7,20:17.0
-12,7,20:17.0
-11,7,20:17.0
-10,7,20:18
-9,7,20:18
-8,7,20:18
-7,7,20:18
-6,7,20:18
2,7,20:18
13,7,20:18
14,7,20:18
15,7,20:18
16,7,20:18
17,7,20:18
-15,8,20:18
-14,8,20:18
-13,8,20:18
-12,8,20:18
-11,8,20:17.0
-10,8,20:17.0
-9,8,20:17.0
-8,8,20:18
-7,8,20:18
-6,8,20:18
2,8,20:18
12,8,20:18
14,8,20:17.0
15,8,20:18
16,8,20:18
17,8,20:18
-14,9,20:18
-13,9,20:18
-12,9,20:18
-11,9,20:17.0
-10,9,20:18
-9,9,20:17.0
-8,9,20:17.0
-7,9,20:17.0
-6,9,20:17.0
-4,9,20:18
15,9,20:18
16,9,20:18
-14,10,20:18
-13,10,20:17.0
-12,10,20:17.0
-11,10,20:17.0
-10,10,20:18
-9,10,20:18
-7,10,20:18
-6,10,20:17.0
-5,10,20:18
-1,10,20:18
-13,11,20:18
-12,11,20:18
-11,11,20:18
-10,11,20:18
-9,11,20:18
-8,11,20:18
-7,11,20:18
-6,11,20:17.0
-5,11,20:18
-2,11,20:18
0,11,20:18
15,11,20:18
-11,12,20:18
-10,12,20:18
-9,12,20:18
-8,12,20:17.0
-7,12,20:17.0
-6,12,20:17.0
-5,12,20:18
4,12,20:18
5,12,20:18
6,12,20:18
7,12,20:18
8,12,20:18
15,12,20:18
-12,13,20:18
-11,13,20:18
-10,13,20:18
-9,13,20:18
-8,13,20:17.0
-7,13,20:18
-6,13,20:18
0,13,20:18
1,13,20:18
4,13,20:18
7,13,20:18
8,13,20:18
15,13,20:18
16,13,20:18
-14,14,20:18
-12,14,20:18
-11,14,20:18
-10,14,20:18
-9,14,20:18
-8,14,20:17.0
-6,14,20:18
-5,14,20:18
0,14,20:18
1,14,20:17.0
2,14,20:18
8,14,20:18
13,14,20:18
15,14,20:18
16,14,20:18
17,14,20:18
-14,15,20:18
-13,15,20:18
-12,15,20:18
-11,15,20:18
-10,15,20:18
-9,15,20:18
-8,15,20:18
-7,15,20:18
-6,15,20:18
-5,15,20:18
0,15,20:18
1,15,20:18
7,15,20:18
8,15,20:18
16,15,20:18
-13,16,20:18
-12,16,20:18
-11,16,20:18
-8,16,20:18
-7,16,20:18
-6,16,20:18
-5,16,20:18
-4,16,20:18
-3,16,20:18
-2,16,20:18
-1,16,20:18
11,16,20:18
12,16,20:18
13,16,20:18
-13,17,20:18
-12,17,20:18
-8,17,20:18
-7,17,20:18
-6,17,20:18
-5,17,20:18
-4,17,20:18
-2,17,20:18
-1,17,20:18
10,17,20:18
11,17,20:18
12,17,20:18
13,17,20:17.0
15,17,20:18
16,17,20:18
-13,18,20:18
-8,18,20:18
-6,18,20:18
-5,18,20:18
-3,18,20:18
-2,18,20:18
9,18,20:18
10,18,20:18
11,18,20:18
12,18,20:18
13,18,20:18
14,18,20:18
15,18,20:18
16,18,20:18
-6,19,20:18
8,19,20:18
10,19,20:18
11,19,20:18
12,19,20:18
-3,-21,21:18
-4,-20,21:18
-3,-20,21:18
-7,-18,21:18
-6,-18,21:18
-9,-17,21:18
-8,-17,21:18
-7,-17,21:18
-6,-17,21:18
-10,-16,21:18
-9,-16,21:18
-10,-15,21:18
-11,-14,21:18
3,-14,21:18
-15,-13,21:18
-14,-13,21:18
-12,-13,21:18
3,-13,21:18
-16,-12,21:18
-15,-12,21:18
-14,-12,21:18
-13,-12,21:18
2,-12,21:18
3,-12,21:18
4,-12,21:18
-18,-11,21:18
-17,-11,21:18
-16,-11,21:18
-9,-11,21:18
-1,-11,21:18
2,-11,21:18
3,-11,21:18
4,-11,21:18
6,-11,21:18
11,-11,21:18
-19,-10,21:18
-18,-10,21:18
-17,-10,21:17.0
-13,-10,21:18
-12,-10,21:18
-9,-10,21:18
-5,-10,21:18
-1,-10,21:18
0,-10,21:18
1,-10,21:18
2,-10,21:18
3,-10,21:18
4,-10,21:18
5,-10,21:18
6,-10,21:17.0
7,-10,21:18
10,-10,21:18
11,-10,21:18
-20,-9,21:18
-19,-9,21:18
-2,-9,21:18
-1,-9,21:18
0,-9,21:18
1,-9,21:18
2,-9,21:18
3,-9,21:17.0
4,-9,21:18
5,-9,21:18
6,-9,21:17.0
7,-9,21:18
8,-9,21:18
9,-9,21:18
10,-9,21:18
11,-9,21:18
12,-9,21:18
-20,-8,21:18
-19,-8,21:18
-1,-8,21:18
1,-8,21:18
2,-8,21:18
3,-8,21:17.0
4,-8,21:18
5,-8,21:18
6,-8,21:17.0
7,-8,21:18
8,-8,21:18
9,-8,21:18
10,-8,21:18
11,-8,21:18
12,-8,21:18
17,-8,21:18
-19,-7,21:18
-18,-7,21:18
1,-7,21:18
2,-7,21:18
3,-7,21:17.0
4,-7,21:18
5,-7,21:18
6,-7,21:17.0
7,-7,21:18
9,-7,21:18
10,-7,21:18
11,-7,21:18
12,-7,21:18
17,-7,21:18
-20,-6,21:18
-19,-6,21:18
-18,-6,21:17.0
2,-6,21:18
3,-6,21:17.0
4,-6,21:17.0
5,-6,21:17.0
6,-6,21:17.0
7,-6,21:17.0
8,-6,21:17.0
9,-6,21:17.0
10,-6,21:17.0
11,-6,21:17.0
12,-6,21:18
14,-6,21:18
17,-6,21:18
-20,-5,21:18
-19,-5,21:18
-18,-5,21:18
-4,-5,21:18
3,-5,21:18
4,-5,21:18
5,-5,21:18
8,-5,21:18
9,-5,21:18
10,-5,21:18
11,-5,21:17.0
12,-5,21:18
13,-5,21:18
14,-5,21:18
15,-5,21:18
16,-5,21:18
17,-5,21:18
18,-5,21:18
-20,-4,21:18
-19,-4,21:18
-18,-4,21:18
-17,-4,21:18
4,-4,21:18
9,-4,21:18
10,-4,21:18
11,-4,21:17.0
13,-4,21:18
14,-4,21:18
15,-4,21:18
16,-4,21:18
17,-4,21:18
-19,-3,21:18
-18,-3,21:18
-17,-3,21:18
9,-3,21:18
10,-3,21:18
11,-3,21:17.0
12,-3,21:17.0
13,-3,21:17.0
14,-3,21:17.0
15,-3,21:17.0
16,-3,21:17.0
17,-3,21:17.0
18,-3,21:18
-20,-2,21:18
-19,-2,21:18
-18,-2,21:18
-17,-2,21:17.0
10,-2,21:18
11,-2,21:18
12,-2,21:18
13,-2,21:18
15,-2,21:18
17,-2,21:18
-20,-1,21:18
-19,-1,21:18
-18,-1,21:18
-17,-1,21:18
-16,-1,21:18
0,-1,21:17.0
12,-1,21:18
13,-1,21:18
14,-1,21:18
15,-1,21:18
17,-1,21:18
-19,0,21:18
-18,0,21:18
-16,0,21:18
-1,0,21:17.0
0,0,21:17.0
12,0,21:18
14,0,21:18
-18,1,21:18
-16,1,21:18
-15,1,21:18
-1,1,21:17.0
0,1,21:17.0
12,1,21:18
13,1,21:18
14,1,21:18
-15,2,21:18
-14,2,21:18
-1,2,21:17.0
0,2,21:17.0
11,2,21:18
12,2,21:17.0
13,2,21:18
-15,3,21:18
-14,3,21:18
-1,3,21:17.0
12,3,21:18
13,3,21:18
14,3,21:18
-14,4,21:18
-1,4,21:17.0
12,4,21:18
13,4,21:18
14,4,21:18
-12,5,21:18
11,5,21:18
12,5,21:17.0
13,5,21:18
-13,6,21:18
-12,6,21:18
-11,6,21:18
11,6,21:18
12,6,21:17.0
13,6,21:18
14,6,21:18
-15,7,21:18
-14,7,21:18
-13,7,21:18
-12,7,21:18
-11,7,21:18
-5,7,21:18
2,7,21:18
12,7,21:17.0
13,7,21:18
14,7,21:18
15,7,21:18
16,7,21:18
-11,8,21:18
-10,8,21:18
-9,8,21:18
-8,8,21:18
-5,8,21:18
-4,8,21:18
-3,8,21:18
2,8,21:18
12,8,21:17.0
13,8,21:17.0
14,8,21:17.0
15,8,21:18
16,8,21:18
-13,9,21:18
-12,9,21:18
-11,9,21:18
-10,9,21:18
-9,9,21:18
-8,9,21:18
-7,9,21:18
-6,9,21:17.0
-5,9,21:17.0
-4,9,21:17.0
-3,9,21:17.0
-2,9,21:17.0
-1,9,21:17.0
1,9,21:18
14,9,21:18
15,9,21:18
16,9,21:18
17,9,21:18
-13,10,21:18
-12,10,21:18
-11,10,21:18
-8,10,21:18
-7,10,21:18
-6,10,21:17.0
-5,10,21:17.0
-4,10,21:17.0
-3,10,21:17.0
-2,10,21:17.0
-1,10,21:17.0
0,10,21:17.0
1,10,21:17.0
8,10,21:18
12,10,21:18
14,10,21:18
15,10,21:18
-8,11,21:18
-7,11,21:18
-6,11,21:18
-5,11,21:18
-4,11,21:18
-3,11,21:18
-2,11,21:18
-1,11,21:18
0,11,21:17.0
1,11,21:18
4,11,21:18
5,11,21:18
6,11,21:18
8,11,21:18
9,11,21:18
12,11,21:18
14,11,21:18
15,11,21:18
-8,12,21:18
-7,12,21:18
-6,12,21:18
-5,12,21:18
-2,12,21:18
-1,12,21:18
0,12,21:17.0
1,12,21:17.0
3,12,21:18
4,12,21:17.0
5,12,21:17.0
6,12,21:17.0
7,12,21:17.0
8,12,21:17.0
9,12,21:18
14,12,21:18
15,12,21:18
-9,13,21:18
-8,13,21:18
-6,13,21:18
0,13,21:18
1,13,21:17.0
4,13,21:17.0
5,13,21:18
6,13,21:18
7,13,21:18
8,13,21:17.0
9,13,21:18
13,13,21:18
14,13,21:18
15,13,21:18
-8,14,21:18
-1,14,21:18
0,14,21:18
1,14,21:17.0
2,14,21:18
4,14,21:18
6,14,21:18
7,14,21:18
8,14,21:17.0
9,14,21:18
13,14,21:17.0
14,14,21:17.0
15,14,21:17.0
16,14,21:18
17,14,21:18
-14,15,21:18
-1,15,21:18
0,15,21:18
1,15,21:18
7,15,21:18
8,15,21:17.0
9,15,21:18
12,15,21:18
13,15,21:17.0
14,15,21:18
16,15,21:18
17,15,21:18
-12,16,21:18
-2,16,21:18
-1,16,21:18
8,16,21:18
9,16,21:18
11,16,21:18
12,16,21:18
13,16,21:17.0
14,16,21:18
15,16,21:18
0,17,21:18
11,17,21:18
12,17,21:18
13,17,21:17.0
14,17,21:18
15,17,21:18
9,18,21:18
10,18,21:18
11,18,21:18
13,18,21:18
14,18,21:18
11,19,21:18
13,19,21:18
-4,-21,22:18
-5,-20,22:18
-4,-20,22:18
-3,-20,22:18
-2,-20,22:18
-6,-19,22:18
-5,-19,22:18
-4,-19,22:18
-1,-19,22:18
0,-19,22:18
-6,-18,22:18
-5,-18,22:18
-1,-18,22:18
1,-18,22:18
-8,-17,22:18
-7,-17,22:18
-6,-17,22:18
-10,-16,22:18
-9,-16,22:18
-8,-16,22:18
-7,-16,22:18
-6,-16,22:18
2,-16,22:18
-10,-15,22:18
-5,-15,22:18
-11,-14,22:18
-5,-14,22:18
1,-14,22:18
-15,-13,22:18
-12,-13,22:18
-11,-13,22:18
-8,-13,22:18
-7,-13,22:18
-1,-13,22:18
0,-13,22:18
3,-13,22:18
-15,-12,22:18
-12,-12,22:18
-11,-12,22:18
-10,-12,22:18
-6,-12,22:18
-1,-12,22:18
2,-12,22:18
3,-12,22:18
-17,-11,22:18
-16,-11,22:18
-15,-11,22:17.0
-14,-11,22:18
-13,-11,22:18
-12,-11,22:18
-10,-11,22:18
-9,-11,22:18
-8,-11,22:18
-7,-11,22:18
-5,-11,22:18
-2,-11,22:18
2,-11,22:18
3,-11,22:18
-19,-10,22:18
-18,-10,22:18
-17,-10,22:17.0
-16,-10,22:17.0
-15,-10,22:17.0
-14,-10,22:17.0
-13,-10,22:17.0
-12,-10,22:18
-9,-10,22:18
-8,-10,22:18
-5,-10,22:18
-3,-10,22:18
-2,-10,22:18
-1,-10,22:18
1,-10,22:18
2,-10,22:18
3,-10,22:18
4,-10,22:18
6,-10,22:18
-20,-9,22:18
-19,-9,22:18
-18,-9,22:18
-2,-9,22:18
2,-9,22:18
3,-9,22:18
4,-9,22:18
6,-9,22:18
8,-9,22:18
9,-9,22:18
-20,-8,22:18
-19,-8,22:18
-18,-8,22:18
2,-8,22:18
3,-8,22:18
4,-8,22:18
5,-8,22:18
6,-8,22:18
-19,-7,22:18
-18,-7,22:18
-3,-7,22:18
3,-7,22:18
4,-7,22:18
5,-7,22:18
6,-7,22:18
7,-7,22:18
8,-7,22:18
11,-7,22:18
-19,-6,22:18
-18,-6,22:17.0
-4,-6,22:18
-2,-6,22:18
0,-6,22:18
3,-6,22:18
4,-6,22:18
5,-6,22:18
6,-6,22:18
7,-6,22:17.0
8,-6,22:18
9,-6,22:18
10,-6,22:18
11,-6,22:18
12,-6,22:18
13,-6,22:18
-19,-5,22:18
-18,-5,22:18
-5,-5,22:18
-4,-5,22:17.0
-3,-5,22:18
-1,-5,22:18
0,-5,22:18
1,-5,22:18
7,-5,22:17.0
11,-5,22:18
12,-5,22:18
-18,-4,22:18
-17,-4,22:18
-4,-4,22:18
5,-4,22:18
6,-4,22:18
7,-4,22:17.0
8,-4,22:18
11,-4,22:18
12,-4,22:18
13,-4,22:18
14,-4,22:18
17,-4,22:18
-18,-3,22:18
-17,-3,22:18
-16,-3,22:18
-15,-3,22:18
5,-3,22:18
6,-3,22:18
7,-3,22:17.0
10,-3,22:18
11,-3,22:18
12,-3,22:18
13,-3,22:18
14,-3,22:18
15,-3,22:18
16,-3,22:18
17,-3,22:18
18,-3,22:18
-18,-2,22:18
-17,-2,22:17.0
-16,-2,22:17.0
-15,-2,22:17.0
5,-2,22:18
6,-2,22:18
7,-2,22:17.0
8,-2,22:18
14,-2,22:18
15,-2,22:18
-17,-1,22:18
-16,-1,22:18
-15,-1,22:17.0
0,-1,22:17.0
7,-1,22:17.0
8,-1,22:18
17,-1,22:18
-16,0,22:18
-15,0,22:17.0
-14,0,22:17.0
-13,0,22:17.0
-12,0,22:18
-1,0,22:17.0
0,0,22:17.0
7,0,22:17.0
9,0,22:18
10,0,22:18
11,0,22:18
12,0,22:18
13,0,22:18
14,0,22:18
15,0,22:18
-16,1,22:18
-15,1,22:18
-14,1,22:18
-13,1,22:17.0
-12,1,22:18
-1,1,22:17.0
0,1,22:17.0
6,1,22:18
7,1,22:17.0
8,1,22:18
9,1,22:18
10,1,22:18
11,1,22:18
12,1,22:18
13,1,22:18
14,1,22:18
-15,2,22:18
-14,2,22:18
-13,2,22:18
-12,2,22:18
-1,2,22:17.0
0,2,22:17.0
5,2,22:18
6,2,22:18
7,2,22:17.0
8,2,22:17.0
9,2,22:17.0
10,2,22:17.0
11,2,22:17.0
12,2,22:17.0
13,2,22:18
14,2,22:18
-14,3,22:18
-1,3,22:17.0
0,3,22:17.0
6,3,22:18
7,3,22:18
8,3,22:18
9,3,22:18
10,3,22:17.0
11,3,22:18
12,3,22:18
13,3,22:18
-1,4,22:17.0
0,4,22:17.0
6,4,22:18
7,4,22:18
8,4,22:18
9,4,22:18
10,4,22:18
11,4,22:18
-1,5,22:17.0
0,5,22:17.0
7,5,22:18
8,5,22:18
9,5,22:18
12,5,22:18
-11,6,22:18
-1,6,22:17.0
0,6,22:17.0
11,6,22:18
12,6,22:18
15,6,22:18
-12,7,22:18
-1,7,22:17.0
0,7,22:17.0
6,7,22:18
7,7,22:18
8,7,22:18
10,7,22:18
11,7,22:18
12,7,22:18
13,7,22:18
15,7,22:18
-6,8,22:18
-2,8,22:18
-1,8,22:17.0
0,8,22:17.0
2,8,22:18
3,8,22:18
6,8,22:18
7,8,22:18
8,8,22:18
9,8,22:18
10,8,22:18
11,8,22:18
12,8,22:17.0
13,8,22:18
14,8,22:18
15,8,22:18
16,8,22:18
-11,9,22:18
-6,9,22:18
-5,9,22:18
-4,9,22:18
-3,9,22:18
-2,9,22:18
-1,9,22:17.0
0,9,22:17.0
1,9,22:17.0
2,9,22:17.0
3,9,22:17.0
6,9,22:18
7,9,22:18
8,9,22:18
9,9,22:18
10,9,22:18
11,9,22:18
12,9,22:17.0
13,9,22:18
14,9,22:18
15,9,22:18
-6,10,22:18
-5,10,22:18
-4,10,22:18
-3,10,22:18
-2,10,22:18
-1,10,22:17.0
0,10,22:17.0
1,10,22:17.0
2,10,22:17.0
3,10,22:17.0
4,10,22:17.0
5,10,22:17.0
6,10,22:17.0
7,10,22:17.0
8,10,22:17.0
9,10,22:17.0
10,10,22:17.0
11,10,22:17.0
12,10,22:17.0
13,10,22:18
14,10,22:18
-5,11,22:18
-4,11,22:18
-3,11,22:18
-2,11,22:18
0,11,22:18
2,11,22:18
4,11,22:18
5,11,22:18
6,11,22:18
7,11,22:17.0
8,11,22:18
9,11,22:18
10,11,22:18
11,11,22:18
12,11,22:17.0
13,11,22:17.0
14,11,22:18
15,11,22:18
-8,12,22:18
-5,12,22:18
-1,12,22:18
0,12,22:18
1,12,22:18
2,12,22:18
3,12,22:18
4,12,22:18
5,12,22:18
6,12,22:18
7,12,22:17.0
8,12,22:17.0
10,12,22:18
11,12,22:18
12,12,22:18
13,12,22:17.0
14,12,22:18
15,12,22:18
-1,13,22:18
1,13,22:18
2,13,22:18
3,13,22:18
4,13,22:18
5,13,22:18
6,13,22:18
7,13,22:18
8,13,22:18
9,13,22:18
10,13,22:18
11,13,22:18
12,13,22:18
13,13,22:17.0
14,13,22:18
15,13,22:18
1,14,22:18
2,14,22:18
3,14,22:18
4,14,22:18
5,14,22:18
6,14,22:18
7,14,22:18
8,14,22:18
9,14,22:18
10,14,22:18
11,14,22:18
12,14,22:18
13,14,22:17.0
14,14,22:18
15,14,22:18
-1,15,22:18
0,15,22:18
1,15,22:18
3,15,22:18
4,15,22:18
5,15,22:18
6,15,22:18
7,15,22:18
8,15,22:18
9,15,22:18
10,15,22:18
11,15,22:18
12,15,22:18
13,15,22:18
14,15,22:18
15,15,22:18
16,15,22:18
-1,16,22:18
0,16,22:18
4,16,22:18
5,16,22:18
6,16,22:18
7,16,22:18
8,16,22:18
9,16,22:18
10,16,22:18
11,16,22:18
12,16,22:18
13,16,22:18
14,16,22:18
0,17,22:18
6,17,22:18
7,17,22:18
8,17,22:18
9,17,22:18
10,17,22:18
12,17,22:18
13,17,22:18
14,17,22:18
6,18,22:18
7,18,22:18
9,18,22:18
10,18,22:18
-5,-20,23:18
-4,-20,23:18
-3,-20,23:18
-2,-20,23:18
-5,-19,23:18
-4,-19,23:18
-3,-19,23:17.0
-2,-19,23:18
-1,-19,23:18
-6,-18,23:18
-5,-18,23:18
-4,-18,23:18
-3,-18,23:17.0
-2,-18,23:18
-1,-18,23:18
0,-18,23:18
1,-18,23:18
-6,-17,23:18
-5,-17,23:17.0
-4,-17,23:17.0
-3,-17,23:17.0
-2,-17,23:18
-1,-17,23:18
-9,-16,23:18
-8,-16,23:18
-6,-16,23:18
-5,-16,23:18
-2,-16,23:18
2,-16,23:18
-10,-15,23:18
-9,-15,23:18
-8,-15,23:18
-7,-15,23:18
-6,-15,23:18
-5,-15,23:18
0,-15,23:18
1,-15,23:18
-11,-14,23:18
-10,-14,23:18
-9,-14,23:18
-8,-14,23:18
-7,-14,23:18
-6,-14,23:18
-5,-14,23:18
1,-14,23:18
2,-14,23:18
-12,-13,23:18
-11,-13,23:18
-10,-13,23:17.0
-9,-13,23:17.0
-8,-13,23:18
-7,-13,23:18
-6,-13,23:18
-5,-13,23:18
-1,-13,23:18
0,-13,23:18
-15,-12,23:18
-12,-12,23:18
-11,-12,23:18
-10,-12,23:18
-9,-12,23:17.0
-8,-12,23:18
-7,-12,23:18
-6,-12,23:18
-5,-12,23:18
-2,-12,23:18
-1,-12,23:18
-16,-11,23:18
-15,-11,23:18
-14,-11,23:18
-11,-11,23:18
-10,-11,23:18
-9,-11,23:17.0
-8,-11,23:17.0
-7,-11,23:18
-6,-11,23:18
-5,-11,23:18
-2,-11,23:18
-1,-11,23:18
2,-11,23:18
-18,-10,23:18
-17,-10,23:18
-16,-10,23:18
-15,-10,23:17.0
-14,-10,23:18
-13,-10,23:18
-12,-10,23:18
-9,-10,23:18
-7,-10,23:18
-3,-10,23:18
-2,-10,23:18
-1,-10,23:18
3,-10,23:18
-17,-9,23:18
-16,-9,23:18
-15,-9,23:17.0
-14,-9,23:18
-13,-9,23:18
-8,-9,23:18
-5,-9,23:18
-4,-9,23:17.0
-3,-9,23:18
-2,-9,23:18
-1,-9,23:18
-16,-8,23:18
-15,-8,23:17.0
-14,-8,23:18
-13,-8,23:18
-12,-8,23:18
-4,-8,23:17.0
-2,-8,23:18
-1,-8,23:18
0,-8,23:18
1,-8,23:18
4,-8,23:18
-18,-7,23:18
-17,-7,23:18
-16,-7,23:18
-15,-7,23:17.0
-14,-7,23:18
-13,-7,23:18
-12,-7,23:18
-5,-7,23:18
-4,-7,23:17.0
-3,-7,23:18
5,-7,23:18
6,-7,23:18
8,-7,23:18
-19,-6,23:18
-18,-6,23:17.0
-17,-6,23:17.0
-16,-6,23:17.0
-15,-6,23:17.0
-14,-6,23:17.0
-13,-6,23:17.0
-5,-6,23:18
-4,-6,23:17.0
-2,-6,23:18
5,-6,23:18
6,-6,23:18
7,-6,23:18
8,-6,23:18
-18,-5,23:18
-17,-5,23:18
-16,-5,23:18
-15,-5,23:18
-13,-5,23:17.0
-5,-5,23:18
-4,-5,23:17.0
-2,-5,23:18
-1,-5,23:18
0,-5,23:18
1,-5,23:18
2,-5,23:18
5,-5,23:18
6,-5,23:18
7,-5,23:17.0
8,-5,23:18
-16,-4,23:18
-15,-4,23:18
-14,-4,23:18
-13,-4,23:17.0
-4,-4,23:18
-2,-4,23:18
-1,-4,23:18
1,-4,23:17.0
2,-4,23:18
5,-4,23:18
6,-4,23:18
7,-4,23:17.0
8,-4,23:18
12,-4,23:18
13,-4,23:18
16,-4,23:18
17,-4,23:18
-15,-3,23:18
-14,-3,23:18
-13,-3,23:17.0
0,-3,23:17.0
1,-3,23:17.0
3,-3,23:18
6,-3,23:18
7,-3,23:17.0
8,-3,23:18
12,-3,23:18
13,-3,23:18
14,-3,23:18
15,-3,23:18
16,-3,23:18
17,-3,23:18
-18,-2,23:18
-17,-2,23:18
-16,-2,23:18
-15,-2,23:17.0
-14,-2,23:17.0
-13,-2,23:17.0
-12,-2,23:18
1,-2,23:17.0
2,-2,23:18
3,-2,23:18
5,-2,23:18
6,-2,23:18
7,-2,23:17.0
8,-2,23:18
9,-2,23:18
13,-2,23:18
14,-2,23:18
15,-2,23:18
-15,-1,23:18
-14,-1,23:18
-13,-1,23:18
-12,-1,23:18
-1,-1,23:18
0,-1,23:17.0
1,-1,23:17.0
2,-1,23:17.0
3,-1,23:17.0
4,-1,23:17.0
5,-1,23:17.0
6,-1,23:17.0
7,-1,23:17.0
9,-1,23:18
10,-1,23:18
11,-1,23:18
12,-1,23:18
-15,0,23:18
-14,0,23:18
-13,0,23:18
-1,0,23:17.0
0,0,23:17.0
1,0,23:17.0
2,0,23:17.0
3,0,23:17.0
4,0,23:17.0
5,0,23:17.0
6,0,23:17.0
7,0,23:17.0
8,0,23:18
9,0,23:18
10,0,23:18
-16,1,23:18
-15,1,23:18
-14,1,23:18
-13,1,23:18
-12,1,23:18
-1,1,23:17.0
0,1,23:18
7,1,23:18
10,1,23:18
12,1,23:18
13,1,23:18
-13,2,23:18
-12,2,23:18
-1,2,23:18
0,2,23:18
5,2,23:18
6,2,23:18
7,2,23:18
8,2,23:18
9,2,23:18
10,2,23:18
11,2,23:18
12,2,23:18
-13,3,23:18
-12,3,23:18
-2,3,23:18
-1,3,23:17.0
0,3,23:17.0
1,3,23:18
8,3,23:18
9,3,23:18
10,3,23:18
11,3,23:18
-13,4,23:18
-12,4,23:18
-6,4,23:18
-5,4,23:18
-4,4,23:18
-3,4,23:18
-2,4,23:18
-1,4,23:17.0
0,4,23:17.0
1,4,23:18
-7,5,23:18
-6,5,23:18
-5,5,23:18
-4,5,23:17.0
-3,5,23:17.0
-2,5,23:17.0
-1,5,23:17.0
0,5,23:17.0
1,5,23:18
-9,6,23:18
-5,6,23:18
-4,6,23:18
-3,6,23:18
-2,6,23:18
-1,6,23:17.0
0,6,23:17.0
1,6,23:18
12,6,23:18
-4,7,23:18
-3,7,23:18
-2,7,23:18
-1,7,23:17.0
0,7,23:17.0
1,7,23:18
5,7,23:18
10,7,23:18
11,7,23:18
-2,8,23:18
-1,8,23:17.0
0,8,23:17.0
1,8,23:18
5,8,23:18
6,8,23:18
7,8,23:18
9,8,23:18
12,8,23:18
14,8,23:18
-8,9,23:18
-7,9,23:18
-4,9,23:18
-2,9,23:18
-1,9,23:17.0
0,9,23:17.0
1,9,23:17.0
2,9,23:17.0
3,9,23:18
4,9,23:18
5,9,23:18
6,9,23:18
7,9,23:18
8,9,23:18
9,9,23:18
11,9,23:18
12,9,23:18
13,9,23:18
-5,10,23:18
-4,10,23:18
-3,10,23:18
-2,10,23:18
-1,10,23:18
0,10,23:18
1,10,23:18
2,10,23:17.0
3,10,23:17.0
4,10,23:17.0
5,10,23:17.0
6,10,23:17.0
7,10,23:18
8,10,23:18
9,10,23:18
10,10,23:18
11,10,23:18
12,10,23:18
13,10,23:18
14,10,23:18
15,10,23:18
-3,11,23:18
-2,11,23:18
-1,11,23:18
2,11,23:18
3,11,23:18
4,11,23:18
5,11,23:18
6,11,23:18
7,11,23:18
8,11,23:18
9,11,23:18
11,11,23:18
12,11,23:18
13,11,23:18
14,11,23:18
15,11,23:18
-5,12,23:18
-2,12,23:18
-1,12,23:18
2,12,23:18
4,12,23:18
7,12,23:18
8,12,23:18
11,12,23:18
12,12,23:18
13,12,23:18
14,12,23:18
-2,13,23:18
-1,13,23:18
1,13,23:18
2,13,23:18
6,13,23:18
10,13,23:18
13,13,23:18
14,13,23:18
1,14,23:18
2,14,23:18
4,14,23:18
6,14,23:18
13,14,23:18
0,15,23:18
1,15,23:18
7,15,23:18
8,15,23:18
9,15,23:18
11,15,23:18
1,16,23:18
5,16,23:18
9,16,23:18
-3,-19,24:18
-3,-18,24:18
-6,-17,24:18
-5,-17,24:18
-4,-17,24:18
-3,-17,24:17.0
-2,-17,24:18
0,-17,24:18
-5,-16,24:18
-4,-16,24:18
-3,-16,24:17.0
-2,-16,24:18
-1,-16,24:18
0,-16,24:18
1,-16,24:18
2,-16,24:18
-5,-15,24:18
-4,-15,24:18
-3,-15,24:17.0
-2,-15,24:18
-1,-15,24:18
0,-15,24:18
1,-15,24:18
2,-15,24:18
-9,-14,24:18
-8,-14,24:18
-5,-14,24:18
-4,-14,24:17.0
-3,-14,24:17.0
-2,-14,24:17.0
-1,-14,24:17.0
0,-14,24:17.0
1,-14,24:18
2,-14,24:18
3,-14,24:18
-10,-13,24:18
-9,-13,24:18
-8,-13,24:17.0
-7,-13,24:18
-6,-13,24:18
-5,-13,24:18
-4,-13,24:17.0
-2,-13,24:18
-1,-13,24:18
0,-13,24:18
1,-13,24:18
-9,-12,24:18
-8,-12,24:17.0
-7,-12,24:18
-5,-12,24:18
-4,-12,24:17.0
-3,-12,24:18
-2,-12,24:18
-10,-11,24:18
-9,-11,24:18
-8,-11,24:17.0
-7,-11,24:18
-5,-11,24:18
-4,-11,24:17.0
-3,-11,24:18
-2,-11,24:18
-15,-10,24:18
-9,-10,24:18
-8,-10,24:17.0
-6,-10,24:18
-5,-10,24:18
-4,-10,24:17.0
-3,-10,24:17.0
-2,-10,24:18
-1,-10,24:18
-16,-9,24:18
-15,-9,24:18
-14,-9,24:18
-9,-9,24:18
-8,-9,24:17.0
-7,-9,24:17.0
-6,-9,24:17.0
-5,-9,24:17.0
-4,-9,24:17.0
-3,-9,24:18
-2,-9,24:18
-1,-9,24:18
-15,-8,24:18
-10,-8,24:18
-9,-8,24:18
-8,-8,24:18
-6,-8,24:18
-5,-8,24:18
-4,-8,24:18
-3,-8,24:18
-2,-8,24:18
-1,-8,24:18
-15,-7,24:18
-14,-7,24:18
-12,-7,24:18
-11,-7,24:18
-10,-7,24:18
-7,-7,24:18
-6,-7,24:18
-5,-7,24:18
-4,-7,24:18
-3,-7,24:18
-2,-7,24:18
-1,-7,24:18
-18,-6,24:18
-17,-6,24:18
-16,-6,24:18
-15,-6,24:18
-14,-6,24:18
-13,-6,24:18
-12,-6,24:18
-11,-6,24:18
-10,-6,24:17.0
-7,-6,24:18
-6,-6,24:18
-5,-6,24:18
-4,-6,24:18
-3,-6,24:18
-2,-6,24:18
-15,-5,24:18
-14,-5,24:18
-13,-5,24:17.0
-12,-5,24:17.0
-11,-5,24:17.0
-10,-5,24:17.0
-5,-5,24:18
-4,-5,24:18
-3,-5,24:18
0,-5,24:18
1,-5,24:18
2,-5,24:18
3,-5,24:18
7,-5,24:18
-14,-4,24:18
-13,-4,24:18
-12,-4,24:18
-11,-4,24:18
-4,-4,24:18
-3,-4,24:18
-2,-4,24:18
-1,-4,24:18
0,-4,24:18
1,-4,24:18
2,-4,24:18
3,-4,24:18
4,-4,24:18
7,-4,24:18
8,-4,24:18
12,-4,24:18
-14,-3,24:18
-13,-3,24:18
-12,-3,24:18
-4,-3,24:18
-3,-3,24:18
-2,-3,24:18
-1,-3,24:18
0,-3,24:18
1,-3,24:18
2,-3,24:18
3,-3,24:18
4,-3,24:18
7,-3,24:18
8,-3,24:18
12,-3,24:18
-15,-2,24:18
-14,-2,24:18
-13,-2,24:18
-2,-2,24:18
-1,-2,24:18
0,-2,24:18
1,-2,24:18
2,-2,24:18
3,-2,24:18
4,-2,24:18
5,-2,24:18
6,-2,24:18
7,-2,24:18
8,-2,24:18
13,-2,24:18
14,-2,24:18
-14,-1,24:18
-10,-1,24:18
-1,-1,24:18
0,-1,24:18
1,-1,24:17.0
2,-1,24:17.0
3,-1,24:17.0
4,-1,24:17.0
5,-1,24:17.0
6,-1,24:17.0
7,-1,24:18
-11,0,24:18
-10,0,24:17.0
-9,0,24:17.0
-8,0,24:17.0
-1,0,24:17.0
0,0,24:18
1,0,24:17.0
2,0,24:18
4,0,24:17.0
6,0,24:18
7,0,24:18
-11,1,24:18
-10,1,24:18
-1,1,24:17.0
0,1,24:18
1,1,24:18
6,1,24:18
-13,2,24:18
-10,2,24:18
-3,2,24:18
-2,2,24:18
-1,2,24:18
0,2,24:18
1,2,24:18
-10,3,24:18
-1,3,24:18
0,3,24:18
-2,4,24:18
-1,4,24:18
0,4,24:18
-8,5,24:18
-5,5,24:18
-4,5,24:18
-3,5,24:18
-2,5,24:18
-1,5,24:18
0,5,24:18
-9,6,24:18
-8,6,24:18
-5,6,24:18
-1,6,24:18
0,6,24:18
-9,7,24:18
-8,7,24:18
-1,7,24:18
0,7,24:18
1,7,24:18
-1,8,24:18
0,8,24:18
1,8,24:18
2,8,24:18
5,8,24:18
-9,9,24:18
-8,9,24:18
-7,9,24:18
-6,9,24:18
-2,9,24:18
-1,9,24:18
0,9,24:18
1,9,24:18
2,9,24:18
3,9,24:18
4,9,24:18
6,9,24:18
7,9,24:18
-9,10,24:18
-8,10,24:18
-7,10,24:18
-6,10,24:18
-5,10,24:18
-4,10,24:18
-3,10,24:18
-1,10,24:18
0,10,24:18
1,10,24:18
2,10,24:18
3,10,24:18
4,10,24:18
5,10,24:18
6,10,24:18
7,10,24:18
-8,11,24:18
-2,11,24:18
-1,11,24:18
0,11,24:18
1,11,24:18
2,11,24:18
3,11,24:18
4,11,24:18
9,11,24:18
-1,12,24:18
0,12,24:18
1,12,24:18
2,12,24:18
13,13,24:18
13,14,24:18
-4,-18,25:18
-4,-17,25:18
-3,-17,25:18
-4,-16,25:18
-3,-16,25:18
-3,-15,25:18
-2,-15,25:18
-4,-14,25:18
-3,-14,25:18
-2,-14,25:18
-1,-14,25:18
0,-14,25:18
1,-14,25:18
-8,-13,25:18
-5,-13,25:18
-4,-13,25:18
-2,-13,25:18
-8,-12,25:18
-4,-12,25:18
-8,-11,25:18
-4,-11,25:18
-10,-10,25:18
-9,-10,25:18
-8,-10,25:18
-7,-10,25:18
-6,-10,25:18
-5,-10,25:18
-4,-10,25:18
-3,-10,25:18
-10,-9,25:18
-9,-9,25:18
-8,-9,25:17.0
-7,-9,25:18
-6,-9,25:18
-5,-9,25:18
-4,-9,25:18
-9,-8,25:18
-8,-8,25:17.0
-4,-8,25:18
-3,-8,25:18
-14,-7,25:18
-12,-7,25:18
-9,-7,25:18
-8,-7,25:17.0
-7,-7,25:18
-14,-6,25:18
-10,-6,25:18
-9,-6,25:18
-8,-6,25:17.0
-7,-6,25:18
-13,-5,25:18
-12,-5,25:18
-11,-5,25:18
-10,-5,25:17.0
-9,-5,25:17.0
-8,-5,25:17.0
-7,-5,25:18
-6,-5,25:18
-12,-4,25:18
-10,-4,25:18
-9,-4,25:18
-8,-4,25:17.0
-7,-4,25:18
-6,-4,25:18
-5,-4,25:18
-10,-3,25:18
-9,-3,25:18
-8,-3,25:17.0
-7,-3,25:18
-6,-3,25:18
-5,-3,25:18
-1,-3,25:18
0,-3,25:18
4,-3,25:18
8,-3,25:18
-10,-2,25:18
-9,-2,25:18
-8,-2,25:17.0
-7,-2,25:18
-5,-2,25:18
1,-2,25:18
2,-2,25:18
4,-2,25:18
5,-2,25:18
6,-2,25:18
7,-2,25:18
8,-2,25:18
-11,-1,25:18
-10,-1,25:18
-9,-1,25:18
-8,-1,25:17.0
1,-1,25:18
2,-1,25:18
3,-1,25:18
4,-1,25:17.0
5,-1,25:18
6,-1,25:18
7,-1,25:18
8,-1,25:18
-11,0,25:18
-10,0,25:18
-9,0,25:18
-8,0,25:17.0
-1,0,25:17.0
1,0,25:18
3,0,25:18
4,0,25:17.0
5,0,25:18
-11,1,25:18
-10,1,25:18
-9,1,25:18
-8,1,25:18
-1,1,25:17.0
1,1,25:18
2,1,25:18
3,1,25:18
4,1,25:17.0
5,1,25:18
-11,2,25:18
-10,2,25:18
-9,2,25:18
-8,2,25:18
-1,2,25:18
2,2,25:18
3,2,25:17.0
4,2,25:17.0
5,2,25:18
6,2,25:18
-10,3,25:18
-9,3,25:18
-1,3,25:18
0,3,25:18
2,3,25:18
3,3,25:17.0
4,3,25:18
5,3,25:18
6,3,25:18
-10,4,25:18
-9,4,25:18
-7,4,25:18
-2,4,25:18
2,4,25:18
3,4,25:17.0
4,4,25:18
5,4,25:18
6,4,25:18
7,4,25:18
-9,5,25:18
-8,5,25:18
-7,5,25:18
-6,5,25:18
-5,5,25:18
2,5,25:18
3,5,25:17.0
4,5,25:17.0
5,5,25:17.0
6,5,25:18
7,5,25:18
8,5,25:18
-8,6,25:18
-7,6,25:18
0,6,25:18
2,6,25:18
3,6,25:18
4,6,25:18
5,6,25:17.0
6,6,25:18
7,6,25:18
8,6,25:18
-8,7,25:18
-2,7,25:18
2,7,25:18
3,7,25:18
4,7,25:18
5,7,25:18
6,7,25:18
7,7,25:18
-8,8,25:18
-2,8,25:18
5,8,25:18
-9,9,25:18
-8,9,25:18
-7,9,25:18
-6,9,25:18
-5,9,25:18
-2,9,25:18
-6,10,25:18
-5,10,25:18
-4,10,25:18
-3,10,25:18
-2,10,25:18
-1,10,25:18
4,10,25:18
7,10,25:18
-6,11,25:18
-5,11,25:18
0,11,25:18
1,11,25:18
-5,-10,26:18
-8,-9,26:18
-8,-8,26:18
-9,-7,26:18
-8,-7,26:18
-9,-6,26:18
-8,-6,26:18
-10,-5,26:18
-9,-5,26:18
-8,-5,26:18
-10,-4,26:18
-9,-4,26:18
-8,-4,26:17.0
-7,-4,26:18
-6,-4,26:18
-9,-3,26:18
-8,-3,26:17.0
-7,-3,26:18
-9,-2,26:18
-8,-2,26:17.0
-7,-2,26:18
-6,-2,26:18
-5,-2,26:18
-4,-2,26:18
-3,-2,26:18
7,-2,26:18
8,-2,26:18
-10,-1,26:18
-9,-1,26:18
-8,-1,26:17.0
-7,-1,26:18
-5,-1,26:18
-4,-1,26:18
-3,-1,26:18
-2,-1,26:18
-1,-1,26:18
4,-1,26:18
5,-1,26:18
6,-1,26:18
-9,0,26:18
-8,0,26:17.0
-7,0,26:17.0
-6,0,26:17.0
-5,0,26:17.0
-4,0,26:17.0
-3,0,26:17.0
-2,0,26:17.0
-1,0,26:17.0
0,0,26:18
3,0,26:18
4,0,26:18
-9,1,26:18
-8,1,26:18
-5,1,26:17.0
-4,1,26:17.0
-3,1,26:17.0
-2,1,26:17.0
-1,1,26:17.0
4,1,26:18
-9,2,26:18
-8,2,26:18
-4,2,26:18
-3,2,26:18
-2,2,26:18
-1,2,26:18
2,2,26:18
3,2,26:18
4,2,26:18
5,2,26:18
-4,3,26:18
-3,3,26:18
2,3,26:18
3,3,26:18
4,3,26:18
-8,4,26:18
-7,4,26:18
-4,4,26:18
-3,4,26:18
3,4,26:18
5,4,26:18
-8,5,26:18
-4,5,26:18
-3,5,26:18
-2,5,26:18
3,5,26:18
4,5,26:18
5,5,26:18
6,5,26:18
-8,6,26:18
-7,6,26:18
-5,6,26:18
-3,6,26:18
-2,6,26:18
3,6,26:18
5,6,26:18
6,6,26:18
7,6,26:18
-8,7,26:18
-7,7,26:17.0
-6,7,26:17.0
-5,7,26:17.0
-4,7,26:17.0
-3,7,26:17.0
-2,7,26:18
5,7,26:18
-8,8,26:18
-7,8,26:18
-6,8,26:17.0
-5,8,26:18
-4,8,26:18
-3,8,26:17.0
-2,8,26:18
-7,9,26:18
-6,9,26:17.0
-5,9,26:18
-4,9,26:18
-3,9,26:18
-2,9,26:18
-6,10,26:18
-5,10,26:18
-4,10,26:18
-3,10,26:18
-5,11,26:18
-9,-4,27:18
-8,-4,27:18
-9,-3,27:18
-8,-3,27:18
-9,-2,27:18
-8,-2,27:18
-7,-2,27:18
-4,-2,27:18
-8,-1,27:18
-7,-1,27:18
-6,-1,27:18
-5,-1,27:18
-4,-1,27:18
-3,-1,27:18
-2,-1,27:18
5,-1,27:18
-8,0,27:18
-7,0,27:17.0
-6,0,27:17.0
-5,0,27:17.0
-4,0,27:17.0
-3,0,27:17.0
-2,0,27:17.0
-1,0,27:18
-8,1,27:18
-7,1,27:18
-6,1,27:18
-5,1,27:17.0
-4,1,27:18
-3,1,27:18
-2,1,27:18
-1,1,27:18
-7,2,27:18
-6,2,27:18
-5,2,27:17.0
-4,2,27:18
-3,2,27:18
-2,2,27:18
-8,3,27:18
-7,3,27:18
-6,3,27:18
-5,3,27:17.0
-4,3,27:18
-6,4,27:18
-5,4,27:17.0
-4,4,27:18
-7,5,27:18
-6,5,27:18
-5,5,27:17.0
-4,5,27:18
-7,6,27:18
-6,6,27:18
-5,6,27:17.0
-4,6,27:18
3,6,27:18
-7,7,27:18
-6,7,27:18
-5,7,27:17.0
-4,7,27:18
-3,7,27:18
-6,8,27:18
-5,8,27:18
-4,8,27:18
-3,8,27:18
-6,9,27:18
-7,-1,28:18
-5,-1,28:18
-3,-1,28:18
-2,-1,28:18
-8,0,28:18
-7,0,28:18
-6,0,28:18
-5,0,28:18
-4,0,28:18
-3,0,28:18
-2,0,28:18
-5,1,28:18
-5,2,28:18
-5,3,28:18
-5,4,28:18
-5,5,28:18
-5,6,28:18
-5,7,28:18
-4,-3,-3:17.0
-5,-3,-3:17.0
-5,-4,-3:17.0
-4,3,-3:17.0
-4,4,-3:17.0
-5,4,-3:17.0
0,4,-3:17.0
1,4,-3:17.0
0,5,-3:17.0
2,2,-3:17.0
3,2,-3:17.0
3,3,-3:17.0
4,-1,-3:17.0
4,-2,-3:17.0
4,0,-3:17.0
2,-4,-3:17.0
3,-4,-3:17.0
2,-5,-3:17.0
-2,-1,-3:17.0
1,-1,-3:17.0
1,-2,-3:17.0
-1,1,-3:17.0
-1,2,-3:17.0
-3,1,-3:17.0
-3,0,-3:17.0
-3,-1,-3:3
-2,-2,-3:3
-1,-1,-3:3
-2,0,-3:3
0,-1,-3:3
0,-2,-3:3
1,-3,-3:3
2,-3,-3:3
2,-2,-3:3
2,-1,-3:3
3,-1,-3:3
2,1,-3:3
1,0,-3:3
0,0,-3:3
0,1,-3:3
2,0,-3:3
-1,0,-3:3
-2,1,-3:3
0,2,-3:3
1,1,-3:3
-2,2,-3:3
-1,-2,-3:3
-1,-3,-3:3
-4,0,-3:3
-1,3,-3:3
