[META]
version=2.0
spawnOnBlockType=2
spawnSunlight=True
spawnDarkness=True
spawnWater=False
spawnLava=False
underFill=False
randomRotation=True
dig=True
tree=False
branch=False
needsFoundation=True
rarity=100
collisionPercentage=30
spawnElevationMin=0
spawnElevationMax=102
spawnInBiome=Forest2,Jungle
[DATA]
0,-2,-6:1.5
1,-2,-6:1.5
0,-1,-6:1.5
1,-1,-6:1.5
0,-3,-5:1.5
1,-3,-5:1.5
-1,-2,-5:1.5
0,-2,-5:1.5
1,-2,-5:1.5
2,-2,-5:1.5
-1,-1,-5:1.5
0,-1,-5:1.5
1,-1,-5:1.5
2,-1,-5:1.5
0,0,-5:1.5
1,0,-5:1.5
0,-4,-4:1.5
1,-4,-4:1.5
-1,-3,-4:1.5
0,-3,-4:1.5
1,-3,-4:1.5
2,-3,-4:1.5
-2,-2,-4:1.5
-1,-2,-4:1.5
0,-2,-4:17.0
1,-2,-4:1.5
2,-2,-4:1.5
3,-2,-4:1.5
-2,-1,-4:1.5
-1,-1,-4:1.5
0,-1,-4:1.5
1,-1,-4:1.5
2,-1,-4:1.5
3,-1,-4:1.5
-1,0,-4:1.5
0,0,-4:1.5
1,0,-4:1.5
2,0,-4:1.5
0,1,-4:1.5
1,1,-4:1.5
-1,-5,-3:3.5
0,-5,-3:3.5
1,-5,-3:3.5
2,-5,-3:3.5
-2,-4,-3:3.5
-1,-4,-3:3.5
0,-4,-3:1.5
1,-4,-3:1.5
2,-4,-3:3.5
3,-4,-3:3.5
-3,-3,-3:3.5
-2,-3,-3:3.5
-1,-3,-3:1.5
0,-3,-3:17.0
1,-3,-3:17.0
2,-3,-3:1.5
3,-3,-3:3.5
4,-3,-3:3.5
-3,-2,-3:3.5
-2,-2,-3:1.5
-1,-2,-3:17.0
0,-2,-3:1.5
1,-2,-3:17.0
2,-2,-3:17.0
3,-2,-3:1.5
4,-2,-3:3.5
-3,-1,-3:3.5
-2,-1,-3:1.5
-1,-1,-3:17.0
0,-1,-3:1.5
1,-1,-3:17.0
2,-1,-3:17.0
3,-1,-3:1.5
4,-1,-3:3.5
-3,0,-3:3.5
-2,0,-3:3.5
-1,0,-3:1.5
0,0,-3:17.0
1,0,-3:17.0
2,0,-3:1.5
3,0,-3:3.5
4,0,-3:3.5
-2,1,-3:3.5
-1,1,-3:3.5
0,1,-3:1.5
1,1,-3:1.5
2,1,-3:3.5
3,1,-3:3.5
-1,2,-3:3.5
0,2,-3:3.5
1,2,-3:3.5
2,2,-3:3.5
-1,-6,-2:3.5
0,-6,-2:3.5
1,-6,-2:3.5
2,-6,-2:3.5
-2,-5,-2:3.5
-1,-5,-2:3.5
0,-5,-2:3.5
1,-5,-2:3.5
2,-5,-2:3.5
3,-5,-2:3.5
-3,-4,-2:3.5
-2,-4,-2:3.5
-1,-4,-2:1.5
0,-4,-2:17.0
1,-4,-2:17.0
2,-4,-2:1.5
3,-4,-2:3.5
4,-4,-2:3.5
-3,-3,-2:3.5
-2,-3,-2:1.5
-1,-3,-2:17.0
0,-3,-2:17.0
1,-3,-2:17.0
2,-3,-2:17.0
3,-3,-2:1.5
4,-3,-2:3.5
-3,-2,-2:3.5
-2,-2,-2:17.0
-1,-2,-2:1.5
0,-2,-2:17.0
1,-2,-2:17.0
2,-2,-2:17.0
3,-2,-2:17.0
4,-2,-2:3.5
-3,-1,-2:3.5
-2,-1,-2:17.0
-1,-1,-2:1.5
0,-1,-2:17.0
1,-1,-2:17.0
2,-1,-2:17.0
3,-1,-2:17.0
4,-1,-2:3.5
-3,0,-2:3.5
-2,0,-2:1.5
-1,0,-2:17.0
0,0,-2:17.0
1,0,-2:17.0
2,0,-2:17.0
3,0,-2:1.5
4,0,-2:3.5
-3,1,-2:3.5
-2,1,-2:3.5
-1,1,-2:1.5
0,1,-2:17.0
1,1,-2:17.0
2,1,-2:1.5
3,1,-2:3.5
4,1,-2:3.5
-2,2,-2:3.5
-1,2,-2:3.5
0,2,-2:3.5
1,2,-2:3.5
2,2,-2:3.5
3,2,-2:3.5
-1,3,-2:3.5
0,3,-2:3.5
1,3,-2:3.5
2,3,-2:3.5
-1,-7,-1:2.5
0,-7,-1:2.5
1,-7,-1:2.5
2,-7,-1:2.5
-2,-6,-1:2.5
-1,-6,-1:2.5
0,-6,-1:17.0
1,-6,-1:17.0
2,-6,-1:2.5
3,-6,-1:2.5
-3,-5,-1:2.5
-2,-5,-1:2.5
-1,-5,-1:17.0
0,-5,-1:17.0
1,-5,-1:17.0
2,-5,-1:17.0
3,-5,-1:2.5
4,-5,-1:2.5
-4,-4,-1:2.5
-3,-4,-1:2.5
-2,-4,-1:17.0
-1,-4,-1:17.0
0,-4,-1:17.0
1,-4,-1:17.0
2,-4,-1:17.0
3,-4,-1:17.0
4,-4,-1:2.5
5,-4,-1:2.5
-4,-3,-1:2.5
-3,-3,-1:17.0
-2,-3,-1:17.0
-1,-3,-1:17.0
0,-3,-1:17.0
1,-3,-1:17.0
2,-3,-1:17.0
3,-3,-1:17.0
4,-3,-1:17.0
5,-3,-1:2.5
-4,-2,-1:2.5
-3,-2,-1:17.0
-2,-2,-1:17.0
-1,-2,-1:17.0
0,-2,-1:17.0
1,-2,-1:17.0
2,-2,-1:17.0
3,-2,-1:17.0
4,-2,-1:17.0
5,-2,-1:2.5
-4,-1,-1:2.5
-3,-1,-1:17.0
-2,-1,-1:17.0
-1,-1,-1:17.0
0,-1,-1:17.0
1,-1,-1:17.0
2,-1,-1:17.0
3,-1,-1:17.0
4,-1,-1:17.0
5,-1,-1:2.5
-4,0,-1:2.5
-3,0,-1:17.0
-2,0,-1:17.0
-1,0,-1:17.0
0,0,-1:17.0
1,0,-1:17.0
2,0,-1:17.0
3,0,-1:17.0
4,0,-1:17.0
5,0,-1:2.5
-4,1,-1:2.5
-3,1,-1:2.5
-2,1,-1:17.0
-1,1,-1:17.0
0,1,-1:17.0
1,1,-1:17.0
2,1,-1:17.0
3,1,-1:17.0
4,1,-1:2.5
5,1,-1:2.5
-3,2,-1:2.5
-2,2,-1:2.5
-1,2,-1:17.0
0,2,-1:17.0
1,2,-1:17.0
2,2,-1:17.0
3,2,-1:2.5
4,2,-1:2.5
-2,3,-1:2.5
-1,3,-1:2.5
0,3,-1:17.0
1,3,-1:17.0
2,3,-1:2.5
3,3,-1:2.5
-1,4,-1:2.5
0,4,-1:2.5
1,4,-1:2.5
2,4,-1:2.5
0,-6,0:18.12
1,-6,0:18.12
-1,-5,0:18.12
0,-5,0:17.0
1,-5,0:17.0
2,-5,0:18.12
-2,-4,0:18.12
-1,-4,0:17.0
0,-4,0:17.0
1,-4,0:17.0
2,-4,0:17.0
3,-4,0:18.12
-3,-3,0:18.12
-2,-3,0:17.0
-1,-3,0:17.0
0,-3,0:17.0
1,-3,0:17.0
2,-3,0:17.0
3,-3,0:17.0
4,-3,0:18.12
-3,-2,0:18.12
-2,-2,0:17.0
-1,-2,0:17.0
0,-2,0:17.0
1,-2,0:17.0
2,-2,0:17.0
3,-2,0:17.0
4,-2,0:18.12
-3,-1,0:18.12
-2,-1,0:17.0
-1,-1,0:17.0
0,-1,0:17.0
1,-1,0:17.0
2,-1,0:17.0
3,-1,0:17.0
4,-1,0:18.12
-3,0,0:18.12
-2,0,0:17.0
-1,0,0:17.0
0,0,0:17.0
1,0,0:17.0
2,0,0:17.0
3,0,0:17.0
4,0,0:18.12
-2,1,0:18.12
-1,1,0:17.0
0,1,0:17.0
1,1,0:17.0
2,1,0:17.0
3,1,0:18.12
-1,2,0:18.12
0,2,0:17.0
1,2,0:17.0
2,2,0:18.12
0,3,0:18.12
1,3,0:18.12
0,-5,1:18.12
1,-5,1:18.12
-1,-4,1:18.12
0,-4,1:17.0
1,-4,1:17.0
2,-4,1:18.12
-2,-3,1:18.12
-1,-3,1:17.0
0,-3,1:17.0
1,-3,1:17.0
2,-3,1:17.0
3,-3,1:18.12
-2,-2,1:18.12
-1,-2,1:17.0
0,-2,1:17.0
1,-2,1:17.0
2,-2,1:17.0
3,-2,1:18.12
-2,-1,1:18.12
-1,-1,1:17.0
0,-1,1:17.0
1,-1,1:17.0
2,-1,1:17.0
3,-1,1:18.12
-2,0,1:18.12
-1,0,1:17.0
0,0,1:17.0
1,0,1:17.0
2,0,1:17.0
3,0,1:18.12
-1,1,1:18.12
0,1,1:17.0
1,1,1:17.0
2,1,1:18.12
0,2,1:18.12
1,2,1:18.12
0,-4,2:18.12
1,-4,2:18.12
-1,-3,2:18.12
0,-3,2:17.0
1,-3,2:17.0
2,-3,2:18.12
-1,-2,2:18.12
0,-2,2:17.0
1,-2,2:17.0
2,-2,2:18.12
-1,-1,2:18.12
0,-1,2:17.0
1,-1,2:17.0
2,-1,2:18.12
-1,0,2:18.12
0,0,2:17.0
1,0,2:17.0
2,0,2:18.12
0,1,2:18.12
1,1,2:18.12
1,-3,3:17.0
2,-3,3:17.0
0,-2,3:17.0
1,-2,3:17.0
0,-1,3:17.0
1,-1,3:17.0
-1,0,3:17.0
0,0,3:17.0
2,-3,4:17.0
0,-2,4:17.0
1,-2,4:17.0
2,-2,4:17.0
-1,-1,4:17.0
0,-1,4:17.0
1,-1,4:17.0
-1,0,4:17.0
-1,-2,5:17.0
0,-2,5:17.0
1,-2,5:17.0
2,-2,5:17.0
-1,-1,5:17.0
0,-1,5:17.0
1,-1,5:17.0
2,-1,5:17.0
-1,-3,6:17.0
-1,-2,6:17.0
0,-2,6:17.0
0,-1,6:17.0
1,-1,6:17.0
2,-1,6:17.0
2,0,6:17.0
-1,-3,7:17.0
0,-2,7:17.0
1,-2,7:17.0
0,-1,7:17.0
1,-1,7:17.0
1,0,7:17.0
2,0,7:17.0
0,-3,8:17.0
1,-3,8:17.0
0,-2,8:17.0
1,-2,8:17.0
0,-1,8:17.0
1,-1,8:17.0
0,0,8:17.0
1,0,8:17.0
1,-3,9:17.0
2,-3,9:17.0
0,-2,9:17.0
1,-2,9:17.0
0,-1,9:17.0
1,-1,9:17.0
-1,0,9:17.0
0,0,9:17.0
2,-3,10:17.0
0,-2,10:17.0
1,-2,10:17.0
2,-2,10:17.0
-1,-1,10:17.0
0,-1,10:17.0
1,-1,10:17.0
-1,0,10:17.0
-1,-2,11:17.0
0,-2,11:17.0
1,-2,11:17.0
2,-2,11:17.0
-1,-1,11:17.0
0,-1,11:17.0
1,-1,11:17.0
2,-1,11:17.0
-1,-6,12:18.2
0,-6,12:18.2
-2,-5,12:18.2
-1,-5,12:18.2
0,-5,12:18.2
1,-5,12:18.2
-3,-4,12:18.2
-2,-4,12:18.2
-1,-4,12:18.14
0,-4,12:18.14
1,-4,12:18.2
2,-4,12:18.2
-4,-3,12:18.2
-3,-3,12:18.2
-2,-3,12:18.14
-1,-3,12:17.0
0,-3,12:17.0
1,-3,12:18.14
2,-3,12:18.2
3,-3,12:18.2
-4,-2,12:18.2
-3,-2,12:18.2
-2,-2,12:18.14
-1,-2,12:17.0
0,-2,12:17.0
1,-2,12:17.0
2,-2,12:18.14
3,-2,12:18.2
4,-2,12:18.2
-3,-1,12:18.2
-2,-1,12:18.2
-1,-1,12:18.14
0,-1,12:17.0
1,-1,12:17.0
2,-1,12:17.0
3,-1,12:18.14
4,-1,12:18.2
5,-1,12:18.2
-2,0,12:18.2
-1,0,12:18.2
0,0,12:18.14
1,0,12:17.0
2,0,12:17.0
3,0,12:18.14
4,0,12:18.2
5,0,12:18.2
-1,1,12:18.2
0,1,12:18.2
1,1,12:18.14
2,1,12:18.14
3,1,12:18.2
4,1,12:18.2
0,2,12:18.2
1,2,12:18.2
2,2,12:18.2
3,2,12:18.2
1,3,12:18.2
2,3,12:18.2
-1,-7,13:18.2
-2,-6,13:18.2
-1,-6,13:18.2
0,-6,13:18.2
1,-6,13:18.2
-3,-5,13:18.2
-2,-5,13:18.2
-1,-5,13:18.14
0,-5,13:18.2
1,-5,13:18.2
2,-5,13:18.2
-4,-4,13:18.2
-3,-4,13:18.2
-2,-4,13:18.14
-1,-4,13:17.0
0,-4,13:18.14
1,-4,13:18.14
2,-4,13:18.2
3,-4,13:18.2
-4,-3,13:18.2
-3,-3,13:18.2
-2,-3,13:18.14
-1,-3,13:17.0
0,-3,13:17.0
1,-3,13:17.0
2,-3,13:18.14
3,-3,13:18.2
4,-3,13:18.2
-3,-2,13:18.2
-2,-2,13:18.2
-1,-2,13:18.14
0,-2,13:17.0
1,-2,13:17.0
2,-2,13:18.14
3,-2,13:18.2
4,-2,13:18.2
-3,-1,13:18.2
-2,-1,13:18.2
-1,-1,13:18.14
0,-1,13:17.0
1,-1,13:17.0
2,-1,13:18.14
3,-1,13:18.2
4,-1,13:18.2
-3,0,13:18.2
-2,0,13:18.2
-1,0,13:18.14
0,0,13:17.0
1,0,13:17.0
2,0,13:17.0
3,0,13:18.14
4,0,13:18.2
5,0,13:18.2
-2,1,13:18.2
-1,1,13:18.2
0,1,13:18.14
1,1,13:18.14
2,1,13:17.0
3,1,13:18.14
4,1,13:18.2
5,1,13:18.2
-1,2,13:18.2
0,2,13:18.2
1,2,13:18.2
2,2,13:18.14
3,2,13:18.2
4,2,13:18.2
0,3,13:18.2
1,3,13:18.2
2,3,13:18.2
3,3,13:18.2
2,4,13:18.2
-1,-8,14:18.2
-2,-7,14:18.2
-1,-7,14:18.2
0,-7,14:18.2
1,-7,14:18.2
-3,-6,14:18.2
-2,-6,14:18.2
-1,-6,14:18.14
0,-6,14:18.2
1,-6,14:18.2
2,-6,14:18.2
-4,-5,14:18.2
-3,-5,14:18.2
-2,-5,14:18.14
-1,-5,14:17.0
0,-5,14:18.14
1,-5,14:18.14
2,-5,14:18.2
3,-5,14:18.2
-4,-4,14:18.2
-3,-4,14:18.2
-2,-4,14:18.14
-1,-4,14:17.0
0,-4,14:17.0
1,-4,14:17.0
2,-4,14:18.14
3,-4,14:18.2
4,-4,14:18.2
-3,-3,14:18.2
-2,-3,14:18.2
-1,-3,14:18.14
0,-3,14:17.0
1,-3,14:17.0
2,-3,14:18.14
3,-3,14:18.2
4,-3,14:18.2
-3,-2,14:18.2
-2,-2,14:18.2
-1,-2,14:18.14
0,-2,14:17.0
1,-2,14:17.0
2,-2,14:18.14
3,-2,14:18.2
4,-2,14:18.2
-3,-1,14:18.2
-2,-1,14:18.2
-1,-1,14:18.14
0,-1,14:17.0
1,-1,14:17.0
2,-1,14:18.14
3,-1,14:18.2
4,-1,14:18.2
-3,0,14:18.2
-2,0,14:18.2
-1,0,14:18.14
0,0,14:17.0
1,0,14:17.0
2,0,14:18.14
3,0,14:18.2
4,0,14:18.2
-3,1,14:18.2
-2,1,14:18.2
-1,1,14:18.14
0,1,14:17.0
1,1,14:17.0
2,1,14:17.0
3,1,14:18.14
4,1,14:18.2
5,1,14:18.2
-2,2,14:18.2
-1,2,14:18.2
0,2,14:18.14
1,2,14:18.14
2,2,14:17.0
3,2,14:18.14
4,2,14:18.2
5,2,14:18.2
-1,3,14:18.2
0,3,14:18.2
1,3,14:18.2
2,3,14:18.14
3,3,14:18.2
4,3,14:18.2
0,4,14:18.2
1,4,14:18.2
2,4,14:18.2
3,4,14:18.6
2,5,14:18.2
-1,-8,15:18.2
0,-8,15:18.2
-2,-7,15:18.2
-1,-7,15:18.2
0,-7,15:18.2
1,-7,15:18.2
-3,-6,15:18.2
-2,-6,15:18.2
-1,-6,15:18.14
0,-6,15:18.14
1,-6,15:18.2
2,-6,15:18.2
-4,-5,15:18.2
-3,-5,15:18.2
-2,-5,15:18.14
-1,-5,15:17.0
0,-5,15:17.0
1,-5,15:18.14
2,-5,15:18.2
3,-5,15:18.2
-3,-4,15:18.2
-2,-4,15:18.2
-1,-4,15:18.14
0,-4,15:17.0
1,-4,15:17.0
2,-4,15:18.14
3,-4,15:18.2
4,-4,15:18.2
-3,-3,15:18.2
-2,-3,15:18.2
-1,-3,15:18.2
0,-3,15:18.14
1,-3,15:18.14
2,-3,15:18.14
3,-3,15:18.2
4,-3,15:18.2
-3,-2,15:18.2
-2,-2,15:18.2
-1,-2,15:18.14
0,-2,15:17.0
1,-2,15:17.0
2,-2,15:17.0
3,-2,15:18.14
4,-2,15:18.2
5,-2,15:18.2
-4,-1,15:18.2
-3,-1,15:18.2
-2,-1,15:18.14
-1,-1,15:17.0
0,-1,15:17.0
1,-1,15:17.0
2,-1,15:18.14
3,-1,15:18.2
4,-1,15:18.2
-3,0,15:18.2
-2,0,15:18.2
-1,0,15:18.14
0,0,15:18.14
1,0,15:18.14
2,0,15:18.2
3,0,15:18.2
4,0,15:18.2
-3,1,15:18.2
-2,1,15:18.2
-1,1,15:18.14
0,1,15:17.0
1,1,15:17.0
2,1,15:18.14
3,1,15:18.2
4,1,15:18.2
-2,2,15:18.2
-1,2,15:18.2
0,2,15:18.14
1,2,15:17.0
2,2,15:17.0
3,2,15:18.14
4,2,15:18.2
5,2,15:18.2
-1,3,15:18.2
0,3,15:18.2
1,3,15:18.14
2,3,15:18.14
3,3,15:18.2
4,3,15:18.2
0,4,15:18.2
1,4,15:18.2
2,4,15:18.2
3,4,15:18.2
1,5,15:18.2
2,5,15:18.2
0,-8,16:18.2
1,-8,16:18.2
-1,-7,16:18.2
0,-7,16:18.2
1,-7,16:18.2
2,-7,16:18.2
-2,-6,16:18.2
-1,-6,16:18.2
0,-6,16:18.14
1,-6,16:18.14
2,-6,16:18.2
3,-6,16:18.2
-3,-5,16:18.2
-2,-5,16:18.2
-1,-5,16:18.14
0,-5,16:17.0
1,-5,16:17.0
2,-5,16:18.14
3,-5,16:18.2
4,-5,16:18.2
-3,-4,16:18.2
-2,-4,16:18.2
-1,-4,16:18.2
0,-4,16:18.14
1,-4,16:18.14
2,-4,16:18.2
3,-4,16:18.2
4,-4,16:18.2
-3,-3,16:18.2
-2,-3,16:18.2
-1,-3,16:18.14
0,-3,16:18.14
1,-3,16:18.14
2,-3,16:18.14
3,-3,16:18.2
4,-3,16:18.2
-4,-2,16:18.2
-3,-2,16:18.2
-2,-2,16:18.14
-1,-2,16:17.0
0,-2,16:17.0
1,-2,16:17.0
2,-2,16:17.0
3,-2,16:18.14
4,-2,16:18.2
5,-2,16:18.2
-4,-1,16:18.2
-3,-1,16:18.2
-2,-1,16:18.14
-1,-1,16:17.0
0,-1,16:17.0
1,-1,16:17.0
2,-1,16:17.0
3,-1,16:18.14
4,-1,16:18.2
5,-1,16:18.2
-3,0,16:18.2
-2,0,16:18.2
-1,0,16:18.14
0,0,16:18.14
1,0,16:18.14
2,0,16:18.14
3,0,16:18.2
4,0,16:18.2
-3,1,16:18.2
-2,1,16:18.2
-1,1,16:18.2
0,1,16:18.14
1,1,16:18.14
2,1,16:18.2
3,1,16:18.2
4,1,16:18.2
-3,2,16:18.2
-2,2,16:18.2
-1,2,16:18.14
0,2,16:17.0
1,2,16:17.0
2,2,16:18.14
3,2,16:18.2
4,2,16:18.2
-2,3,16:18.2
-1,3,16:18.2
0,3,16:18.14
1,3,16:18.14
2,3,16:18.2
3,3,16:18.2
-1,4,16:18.2
0,4,16:18.2
1,4,16:18.2
2,4,16:18.2
0,5,16:18.2
1,5,16:18.2
1,-8,17:18.2
0,-7,17:18.2
1,-7,17:18.2
2,-7,17:18.2
-1,-6,17:18.2
0,-6,17:18.2
1,-6,17:18.14
2,-6,17:18.2
3,-6,17:18.2
-2,-5,17:18.2
-1,-5,17:18.2
0,-5,17:18.14
1,-5,17:17.0
2,-5,17:18.14
3,-5,17:18.2
4,-5,17:18.2
-3,-4,17:18.2
-2,-4,17:18.2
-1,-4,17:18.2
0,-4,17:18.2
1,-4,17:18.14
2,-4,17:18.2
3,-4,17:18.2
4,-4,17:18.2
-4,-3,17:18.2
-3,-3,17:18.2
-2,-3,17:18.14
-1,-3,17:18.14
0,-3,17:18.2
1,-3,17:18.2
2,-3,17:18.14
3,-3,17:18.14
4,-3,17:18.2
5,-3,17:18.2
-5,-2,17:18.2
-4,-2,17:18.2
-3,-2,17:18.14
-2,-2,17:17.0
-1,-2,17:17.0
0,-2,17:18.14
1,-2,17:18.14
2,-2,17:17.0
3,-2,17:17.0
4,-2,17:18.14
5,-2,17:18.2
6,-2,17:18.2
-5,-1,17:18.2
-4,-1,17:18.2
-3,-1,17:18.14
-2,-1,17:17.0
-1,-1,17:17.0
0,-1,17:18.14
1,-1,17:18.14
2,-1,17:17.0
3,-1,17:17.0
4,-1,17:18.14
5,-1,17:18.2
6,-1,17:18.2
-4,0,17:18.2
-3,0,17:18.6
-2,0,17:18.14
-1,0,17:18.14
0,0,17:18.2
1,0,17:18.2
2,0,17:18.14
3,0,17:18.14
4,0,17:18.2
5,0,17:18.2
-3,1,17:18.2
-2,1,17:18.2
-1,1,17:18.2
0,1,17:18.14
1,1,17:18.2
2,1,17:18.2
3,1,17:18.2
4,1,17:18.2
-3,2,17:18.2
-2,2,17:18.2
-1,2,17:18.14
0,2,17:17.0
1,2,17:18.14
2,2,17:18.2
3,2,17:18.2
-2,3,17:18.2
-1,3,17:18.2
0,3,17:18.14
1,3,17:18.2
2,3,17:18.2
-1,4,17:18.2
0,4,17:18.2
1,4,17:18.2
0,5,17:18.2
1,-7,18:18.2
0,-6,18:18.2
1,-6,18:18.2
2,-6,18:18.2
-3,-5,18:18.2
-2,-5,18:18.2
-1,-5,18:18.2
0,-5,18:18.2
1,-5,18:18.14
2,-5,18:18.2
3,-5,18:18.2
4,-5,18:18.2
-4,-4,18:18.2
-3,-4,18:18.2
-2,-4,18:18.2
-1,-4,18:18.2
0,-4,18:18.2
1,-4,18:18.2
2,-4,18:18.2
3,-4,18:18.2
4,-4,18:18.2
5,-4,18:18.2
-5,-3,18:18.2
-4,-3,18:18.2
-3,-3,18:18.14
-2,-3,18:18.14
-1,-3,18:18.2
0,-3,18:18.2
1,-3,18:18.2
2,-3,18:18.2
3,-3,18:18.14
4,-3,18:18.14
5,-3,18:18.2
6,-3,18:18.2
-6,-2,18:18.2
-5,-2,18:18.2
-4,-2,18:18.14
-3,-2,18:17.0
-2,-2,18:17.0
-1,-2,18:18.14
0,-2,18:18.2
1,-2,18:18.2
2,-2,18:18.14
3,-2,18:17.0
4,-2,18:17.0
5,-2,18:18.14
6,-2,18:18.2
7,-2,18:18.2
-6,-1,18:18.2
-5,-1,18:18.2
-4,-1,18:18.14
-3,-1,18:17.0
-2,-1,18:17.0
-1,-1,18:18.14
0,-1,18:18.2
1,-1,18:18.2
2,-1,18:18.14
3,-1,18:17.0
4,-1,18:17.0
5,-1,18:18.14
6,-1,18:18.2
7,-1,18:18.2
-5,0,18:18.2
-4,0,18:18.2
-3,0,18:18.14
-2,0,18:18.14
-1,0,18:18.2
0,0,18:18.2
1,0,18:18.2
2,0,18:18.2
3,0,18:18.14
4,0,18:18.14
5,0,18:18.2
6,0,18:18.2
-4,1,18:18.2
-3,1,18:18.2
-2,1,18:18.2
-1,1,18:18.2
0,1,18:18.2
1,1,18:18.2
2,1,18:18.2
3,1,18:18.2
4,1,18:18.2
5,1,18:18.2
-3,2,18:18.2
-2,2,18:18.2
-1,2,18:18.2
0,2,18:18.14
1,2,18:18.2
2,2,18:18.2
3,2,18:18.2
4,2,18:18.2
-1,3,18:18.2
0,3,18:18.2
1,3,18:18.2
0,4,18:18.2
1,-6,19:18.2
-4,-5,19:18.2
-3,-5,19:18.2
0,-5,19:18.2
1,-5,19:18.2
2,-5,19:18.2
4,-5,19:18.2
5,-5,19:18.2
-5,-4,19:18.2
-4,-4,19:18.2
-3,-4,19:18.2
-2,-4,19:18.2
1,-4,19:18.2
3,-4,19:18.2
4,-4,19:18.2
5,-4,19:18.2
6,-4,19:18.2
-6,-3,19:18.2
-5,-3,19:18.2
-4,-3,19:18.14
-3,-3,19:18.14
-2,-3,19:18.2
-1,-3,19:18.2
2,-3,19:18.2
3,-3,19:18.2
4,-3,19:18.14
5,-3,19:18.14
6,-3,19:18.2
7,-3,19:18.2
-7,-2,19:18.2
-6,-2,19:18.2
-5,-2,19:18.14
-4,-2,19:17.0
-3,-2,19:17.0
-2,-2,19:18.14
-1,-2,19:18.2
0,-2,19:18.2
1,-2,19:18.2
2,-2,19:18.2
3,-2,19:18.14
4,-2,19:17.0
5,-2,19:17.0
6,-2,19:18.14
7,-2,19:18.2
8,-2,19:18.6
-7,-1,19:18.2
-6,-1,19:18.2
-5,-1,19:18.14
-4,-1,19:17.0
-3,-1,19:17.0
-2,-1,19:18.14
-1,-1,19:18.2
0,-1,19:18.2
1,-1,19:18.2
2,-1,19:18.2
3,-1,19:18.14
4,-1,19:17.0
5,-1,19:17.0
6,-1,19:18.14
7,-1,19:18.2
8,-1,19:18.14
-6,0,19:18.2
-5,0,19:18.2
-4,0,19:18.14
-3,0,19:18.14
-2,0,19:18.2
-1,0,19:18.2
2,0,19:18.2
3,0,19:18.2
4,0,19:18.14
5,0,19:18.14
6,0,19:18.2
7,0,19:18.2
-5,1,19:18.2
-4,1,19:18.2
-3,1,19:18.2
-2,1,19:18.2
0,1,19:18.2
3,1,19:18.2
4,1,19:18.2
5,1,19:18.2
6,1,19:18.2
-4,2,19:18.2
-3,2,19:18.2
-1,2,19:18.2
0,2,19:18.2
1,2,19:18.2
4,2,19:18.2
5,2,19:18.2
0,3,19:18.2
1,-5,20:18.2
-4,-4,20:18.2
-3,-4,20:18.2
4,-4,20:18.2
5,-4,20:18.2
-5,-3,20:18.2
-4,-3,20:18.2
-3,-3,20:18.2
-2,-3,20:18.2
3,-3,20:18.2
4,-3,20:18.2
5,-3,20:18.2
6,-3,20:18.2
-6,-2,20:18.2
-5,-2,20:18.2
-4,-2,20:18.14
-3,-2,20:18.14
-2,-2,20:18.2
-1,-2,20:18.2
2,-2,20:18.2
3,-2,20:18.2
4,-2,20:18.14
5,-2,20:18.14
6,-2,20:18.2
7,-2,20:18.2
-6,-1,20:18.2
-5,-1,20:18.2
-4,-1,20:18.14
-3,-1,20:18.14
-2,-1,20:18.2
-1,-1,20:18.2
2,-1,20:18.2
3,-1,20:18.2
4,-1,20:18.14
5,-1,20:18.14
6,-1,20:18.2
7,-1,20:18.2
-5,0,20:18.2
-4,0,20:18.2
-3,0,20:18.2
-2,0,20:18.2
3,0,20:18.2
4,0,20:18.2
5,0,20:18.2
6,0,20:18.2
-4,1,20:18.2
-3,1,20:18.2
4,1,20:18.2
5,1,20:18.2
0,2,20:18.2
-4,-3,21:18.2
-3,-3,21:18.2
4,-3,21:18.2
5,-3,21:18.2
-5,-2,21:18.2
-4,-2,21:18.2
-3,-2,21:18.2
-2,-2,21:18.2
3,-2,21:18.2
4,-2,21:18.2
5,-2,21:18.2
6,-2,21:18.2
-5,-1,21:18.2
-4,-1,21:18.2
-3,-1,21:18.2
-2,-1,21:18.2
3,-1,21:18.2
4,-1,21:18.2
5,-1,21:18.2
6,-1,21:18.2
-4,0,21:18.2
-3,0,21:18.2
4,0,21:18.2
5,0,21:18.2
-4,-2,22:18.2
-3,-2,22:18.2
4,-2,22:18.2
5,-2,22:18.2
-4,-1,22:18.2
-3,-1,22:18.6
4,-1,22:18.2
5,-1,22:18.2
5,0,22:106.4
4,0,22:106.4
-3,0,22:106.4
-4,0,22:106.4
6,-1,22:106.2
3,-1,22:106.8
-2,-1,22:106.2
-5,-1,22:106.8
6,-2,22:106.2
3,-2,22:106.8
-2,-2,22:106.2
-5,-2,22:106.8
5,-3,22:106.1
4,-3,22:106.1
-3,-3,22:106.1
-4,-3,22:106.1
5,1,21:106.4
4,1,21:106.4
-3,1,21:106.4
-4,1,21:106.4
7,-1,21:106.2
-1,-1,21:106.2
-6,-1,21:106.8
7,-2,21:106.2
2,-2,21:106.8
-1,-2,21:106.2
-6,-2,21:106.8
5,-4,21:106.1
4,-4,21:106.1
-3,-4,21:106.1
-4,-4,21:106.1
5,2,20:106.4
4,2,20:106.4
-3,2,20:106.4
-4,2,20:106.4
6,1,20:106.4
3,1,20:106.4
-2,1,20:106.4
-5,1,20:106.8
7,0,20:106.2
2,0,20:106.8
-1,0,20:106.4
-6,0,20:106.8
8,-1,20:106.2
1,-1,20:106.8
0,-1,20:106.2
-7,-1,20:106.8
8,-2,20:106.2
1,-2,20:106.8
0,-2,20:106.2
-7,-2,20:106.8
7,-3,20:106.2
2,-3,20:106.8
-1,-3,20:106.1
-6,-3,20:106.8
6,-4,20:106.1
3,-4,20:106.1
1,-4,20:106.4
-2,-4,20:106.1
-5,-4,20:106.1
5,-5,20:106.1
4,-5,20:106.1
2,-5,20:106.2
0,-5,20:106.8
-3,-5,20:106.1
-4,-5,20:106.1
1,-6,20:106.1
0,4,19:106.4
5,3,19:106.4
4,3,19:106.4
1,3,19:106.2
-1,3,19:106.4
-3,3,19:106.4
-4,3,19:106.4
6,2,19:106.4
3,2,19:106.4
-2,2,19:106.4
-5,2,19:106.4
7,1,19:106.2
2,1,19:106.8
-6,1,19:106.8
8,0,19:106.2
-7,0,19:106.8
9,-1,19:106.2
-8,-1,19:106.8
9,-2,19:106.2
-8,-2,19:106.8
8,-3,19:106.2
1,-3,19:106.4
-7,-3,19:106.8
7,-4,19:106.2
2,-4,19:106.2
0,-4,19:106.8
-6,-4,19:106.1
6,-5,19:106.1
3,-5,19:106.1
-1,-5,19:106.8
-2,-5,19:106.1
-5,-5,19:106.1
5,-6,19:106.1
4,-6,19:106.1
2,-6,19:106.1
0,-6,19:106.1
-3,-6,19:106.1
-4,-6,19:106.1
1,-7,19:106.1
0,5,18:106.4
1,4,18:106.4
-1,4,18:106.4
5,3,18:106.4
4,3,18:106.4
3,3,18:106.4
2,3,18:106.2
-2,3,18:106.4
-3,3,18:106.4
-4,3,18:106.4
6,2,18:106.4
5,2,18:106.4
-4,2,18:106.4
-5,2,18:106.4
7,1,18:106.2
6,1,18:106.2
-5,1,18:106.4
-6,1,18:106.8
8,0,18:106.2
7,0,18:106.2
-6,0,18:106.4
-7,0,18:106.8
9,-1,18:106.2
8,-1,18:106.2
-7,-1,18:106.8
-8,-1,18:106.8
9,-2,18:106.2
8,-2,18:106.2
-7,-2,18:106.8
-8,-2,18:106.8
8,-3,18:106.2
7,-3,18:106.2
-6,-3,18:106.1
-7,-3,18:106.8
7,-4,18:106.2
6,-4,18:106.1
-5,-4,18:106.1
-6,-4,18:106.1
6,-5,18:106.1
5,-5,18:106.1
-4,-5,18:106.1
-5,-5,18:106.1
5,-6,18:106.1
4,-6,18:106.1
3,-6,18:106.1
-1,-6,18:106.1
-2,-6,18:106.1
-3,-6,18:106.1
-4,-6,18:106.1
2,-7,18:106.1
0,-7,18:106.1
1,-8,18:106.1
0,6,17:106.4
1,5,17:106.4
-1,5,17:106.4
2,4,17:106.4
-2,4,17:106.8
5,3,17:106.4
4,3,17:106.4
3,3,17:106.4
-3,3,17:106.4
-4,3,17:106.4
5,2,17:106.4
4,2,17:106.4
-4,2,17:106.12
-5,2,17:106.4
7,1,17:106.2
6,1,17:106.2
5,1,17:106.2
-4,1,17:106.8
-5,1,17:106.4
-6,1,17:106.8
8,0,17:106.2
7,0,17:106.2
6,0,17:106.2
-5,0,17:106.8
-6,0,17:106.4
9,-1,17:106.2
8,-1,17:106.2
7,-1,17:106.2
-6,-1,17:106.8
-7,-1,17:106.8
-8,-1,17:106.8
9,-2,17:106.2
8,-2,17:106.2
7,-2,17:106.2
-6,-2,17:106.8
-7,-2,17:106.8
-8,-2,17:106.8
8,-3,17:106.2
7,-3,17:106.2
6,-3,17:106.2
-5,-3,17:106.1
-6,-3,17:106.1
-7,-3,17:106.8
7,-4,17:106.2
6,-4,17:106.1
5,-4,17:106.2
-4,-4,17:106.1
-5,-4,17:106.1
-6,-4,17:106.1
6,-5,17:106.1
5,-5,17:106.3
-3,-5,17:106.1
-4,-5,17:106.1
-5,-5,17:106.1
5,-6,17:106.1
4,-6,17:106.3
-2,-6,17:106.1
-3,-6,17:106.1
-4,-6,17:106.1
3,-7,17:106.1
-1,-7,17:106.1
2,-8,17:106.1
0,-8,17:106.1
1,-9,17:106.1
1,6,16:106.4
0,6,16:106.4
2,5,16:106.2
-1,5,16:106.4
3,4,16:106.2
-2,4,16:106.12
4,3,16:106.6
-3,3,16:106.12
-4,3,16:106.4
5,2,16:106.6
-4,2,16:106.12
-5,2,16:106.4
7,1,16:106.2
6,1,16:106.2
5,1,16:106.2
-4,1,16:106.8
-5,1,16:106.4
-6,1,16:106.8
8,0,16:106.2
7,0,16:106.2
6,0,16:106.2
5,0,16:106.2
-4,0,16:106.8
-5,0,16:106.8
-6,0,16:106.4
9,-1,16:106.2
8,-1,16:106.2
7,-1,16:106.2
6,-1,16:106.2
-5,-1,16:106.8
-6,-1,16:106.8
-7,-1,16:106.8
-8,-1,16:106.8
9,-2,16:106.2
8,-2,16:106.2
7,-2,16:106.2
6,-2,16:106.2
-5,-2,16:106.8
-6,-2,16:106.8
-7,-2,16:106.8
-8,-2,16:106.8
8,-3,16:106.2
7,-3,16:106.2
6,-3,16:106.2
5,-3,16:106.2
-4,-3,16:106.8
-5,-3,16:106.1
-6,-3,16:106.1
7,-4,16:106.2
6,-4,16:106.1
5,-4,16:106.2
-4,-4,16:106.9
-5,-4,16:106.1
-6,-4,16:106.1
6,-5,16:106.1
5,-5,16:106.3
-4,-5,16:106.9
-5,-5,16:106.1
5,-6,16:106.1
4,-6,16:106.3
-3,-6,16:106.9
-4,-6,16:106.1
3,-7,16:106.1
-2,-7,16:106.8
2,-8,16:106.1
-1,-8,16:106.1
1,-9,16:106.1
0,-9,16:106.1
2,6,15:106.4
1,6,15:106.4
0,6,15:106.4
3,5,15:106.2
0,5,15:106.4
-1,5,15:106.4
4,4,15:106.2
-1,4,15:106.4
-2,4,15:106.12
5,3,15:106.4
-2,3,15:106.4
-3,3,15:106.12
-4,3,15:106.4
6,2,15:106.2
-3,2,15:106.4
-4,2,15:106.12
-5,2,15:106.4
7,1,15:106.2
5,1,15:106.2
-4,1,15:106.8
-5,1,15:106.4
-6,1,15:106.8
8,0,15:106.2
7,0,15:106.2
6,0,15:106.2
5,0,15:106.2
-4,0,15:106.8
-5,0,15:106.8
-6,0,15:106.4
9,-1,15:106.2
7,-1,15:106.2
6,-1,15:106.2
5,-1,15:106.2
-5,-1,15:106.8
-6,-1,15:106.8
-7,-1,15:106.8
-8,-1,15:106.8
9,-2,15:106.2
8,-2,15:106.2
7,-2,15:106.2
6,-2,15:106.2
-4,-2,15:106.8
-5,-2,15:106.8
-6,-2,15:106.8
-7,-2,15:106.8
-8,-2,15:106.8
8,-3,15:106.2
7,-3,15:106.2
6,-3,15:106.2
5,-3,15:106.2
-4,-3,15:106.8
-5,-3,15:106.1
-6,-3,15:106.1
7,-4,15:106.2
6,-4,15:106.1
5,-4,15:106.2
-4,-4,15:106.9
-5,-4,15:106.1
-6,-4,15:106.1
5,-5,15:106.3
4,-5,15:106.1
-5,-5,15:106.9
5,-6,15:106.1
4,-6,15:106.3
3,-6,15:106.1
-4,-6,15:106.9
3,-7,15:106.1
2,-7,15:106.1
-3,-7,15:106.8
2,-8,15:106.1
1,-8,15:106.1
-2,-8,15:106.8
1,-9,15:106.1
0,-9,15:106.1
-1,-9,15:106.1
2,6,14:106.4
1,6,14:106.4
0,6,14:106.4
3,5,14:106.2
1,5,14:106.4
0,5,14:106.4
-1,5,14:106.4
4,4,14:106.2
-1,4,14:106.4
-2,4,14:106.12
5,3,14:106.6
-2,3,14:106.12
-3,3,14:106.12
6,2,14:106.2
-3,2,14:106.4
-4,2,14:106.12
7,1,14:106.2
6,1,14:106.2
-4,1,14:106.8
-5,1,14:106.4
8,0,14:106.2
7,0,14:106.2
6,0,14:106.2
5,0,14:106.2
-4,0,14:106.8
-5,0,14:106.8
-6,0,14:106.4
9,-1,14:106.2
7,-1,14:106.2
6,-1,14:106.2
5,-1,14:106.2
-4,-1,14:106.8
-5,-1,14:106.8
-6,-1,14:106.8
-7,-1,14:106.8
-8,-1,14:106.8
9,-2,14:106.2
8,-2,14:106.2
7,-2,14:106.2
6,-2,14:106.2
5,-2,14:106.2
-4,-2,14:106.8
-5,-2,14:106.8
-6,-2,14:106.8
-7,-2,14:106.8
-8,-2,14:106.8
8,-3,14:106.2
7,-3,14:106.2
6,-3,14:106.2
5,-3,14:106.2
-4,-3,14:106.8
-5,-3,14:106.1
-6,-3,14:106.1
6,-4,14:106.1
5,-4,14:106.2
-5,-4,14:106.9
-6,-4,14:106.1
5,-5,14:106.3
4,-5,14:106.1
-5,-5,14:106.8
5,-6,14:106.1
4,-6,14:106.3
3,-6,14:106.1
-4,-6,14:106.9
3,-7,14:106.1
2,-7,14:106.1
-3,-7,14:106.8
2,-8,14:106.1
1,-8,14:106.1
0,-8,14:106.1
-2,-8,14:106.9
1,-9,14:106.1
0,-9,14:106.1
-1,-9,14:106.1
2,6,13:106.4
1,6,13:106.4
0,6,13:106.4
3,5,13:106.2
2,5,13:106.4
1,5,13:106.4
0,5,13:106.4
-1,5,13:106.4
4,4,13:106.2
3,4,13:106.2
1,4,13:106.4
0,4,13:106.4
-1,4,13:106.4
-2,4,13:106.12
5,3,13:106.6
4,3,13:106.2
-1,3,13:106.4
-2,3,13:106.12
-3,3,13:106.8
6,2,13:106.2
5,2,13:106.2
-2,2,13:106.4
-4,2,13:106.8
6,1,13:106.2
-3,1,13:106.4
-4,1,13:106.8
-5,1,13:106.4
7,0,13:106.2
6,0,13:106.2
-4,0,13:106.8
-5,0,13:106.8
-6,0,13:106.4
9,-1,13:106.2
7,-1,13:106.2
6,-1,13:106.2
5,-1,13:106.2
-4,-1,13:106.8
-5,-1,13:106.8
-6,-1,13:106.8
-7,-1,13:106.8
-8,-1,13:106.8
8,-2,13:106.2
7,-2,13:106.2
6,-2,13:106.2
5,-2,13:106.2
-4,-2,13:106.8
-5,-2,13:106.8
-6,-2,13:106.8
-7,-2,13:106.8
8,-3,13:106.2
6,-3,13:106.2
5,-3,13:106.2
-5,-3,13:106.9
-6,-3,13:106.1
5,-4,13:106.2
4,-4,13:106.2
-5,-4,13:106.9
-6,-4,13:106.1
5,-5,13:106.3
4,-5,13:106.1
3,-5,13:106.1
-4,-5,13:106.8
-5,-5,13:106.8
5,-6,13:106.1
4,-6,13:106.3
3,-6,13:106.1
2,-6,13:106.1
-3,-6,13:106.1
-4,-6,13:106.9
3,-7,13:106.1
2,-7,13:106.1
1,-7,13:106.1
0,-7,13:106.1
-2,-7,13:106.1
-3,-7,13:106.8
2,-8,13:106.1
1,-8,13:106.1
0,-8,13:106.1
-1,-8,13:106.1
-2,-8,13:106.9
1,-9,13:106.1
0,-9,13:106.1
-1,-9,13:106.1
2,6,12:106.4
1,6,12:106.4
0,6,12:106.4
3,5,12:106.2
2,5,12:106.4
1,5,12:106.4
0,5,12:106.4
-1,5,12:106.4
4,4,12:106.2
3,4,12:106.2
2,4,12:106.4
1,4,12:106.4
0,4,12:106.4
-1,4,12:106.4
-2,4,12:106.12
5,3,12:106.6
4,3,12:106.2
3,3,12:106.2
0,3,12:106.4
-1,3,12:106.4
-2,3,12:106.12
-3,3,12:106.8
6,2,12:106.2
5,2,12:106.2
4,2,12:106.2
-1,2,12:106.4
-2,2,12:106.4
-4,2,12:106.8
6,1,12:106.2
5,1,12:106.2
-2,1,12:106.4
-3,1,12:106.4
-4,1,12:106.8
-5,1,12:106.4
7,0,12:106.2
6,0,12:106.2
-3,0,12:106.4
-4,0,12:106.8
9,-1,12:106.2
7,-1,12:106.2
6,-1,12:106.2
-4,-1,12:106.12
-5,-1,12:106.8
-6,-1,12:106.8
-7,-1,12:106.8
8,-2,12:106.2
6,-2,12:106.2
5,-2,12:106.2
-5,-2,12:106.8
-6,-2,12:106.8
-7,-2,12:106.8
8,-3,12:106.2
6,-3,12:106.2
5,-3,12:106.2
4,-3,12:106.1
-5,-3,12:106.9
5,-4,12:106.2
4,-4,12:106.2
3,-4,12:106.1
-4,-4,12:106.8
-5,-4,12:106.8
-6,-4,12:106.1
5,-5,12:106.3
4,-5,12:106.1
3,-5,12:106.1
2,-5,12:106.1
-3,-5,12:106.1
-4,-5,12:106.8
-5,-5,12:106.8
5,-6,12:106.1
4,-6,12:106.3
3,-6,12:106.1
2,-6,12:106.1
1,-6,12:106.2
-2,-6,12:106.1
-3,-6,12:106.1
-4,-6,12:106.8
3,-7,12:106.1
2,-7,12:106.1
1,-7,12:106.1
0,-7,12:106.1
-1,-7,12:106.1
-2,-7,12:106.1
-3,-7,12:106.8
2,-8,12:106.1
1,-8,12:106.1
0,-8,12:106.1
-1,-8,12:106.1
-2,-8,12:106.9
1,-9,12:106.1
0,-9,12:106.1
-1,-9,12:106.1
2,6,11:106.4
1,6,11:106.4
0,6,11:106.4
3,5,11:106.2
2,5,11:106.4
1,5,11:106.4
0,5,11:106.4
-1,5,11:106.4
4,4,11:106.2
3,4,11:106.2
2,4,11:106.4
1,4,11:106.4
0,4,11:106.4
-1,4,11:106.4
-2,4,11:106.12
5,3,11:106.6
4,3,11:106.2
3,3,11:106.2
0,3,11:106.4
-1,3,11:106.4
-2,3,11:106.8
-3,3,11:106.8
6,2,11:106.2
5,2,11:106.2
4,2,11:106.2
-1,2,11:106.4
-2,2,11:106.4
-4,2,11:106.8
6,1,11:106.2
5,1,11:106.2
-2,1,11:106.4
-3,1,11:106.4
-4,1,11:106.8
7,0,11:106.2
6,0,11:106.2
-3,0,11:106.4
-4,0,11:106.8
9,-1,11:106.2
7,-1,11:106.2
3,-1,11:106.2
-2,-1,11:106.8
-4,-1,11:106.12
-6,-1,11:106.8
-7,-1,11:106.8
8,-2,11:106.2
6,-2,11:106.2
5,-2,11:106.2
3,-2,11:106.2
-2,-2,11:106.8
-5,-2,11:106.8
-6,-2,11:106.8
-7,-2,11:106.8
5,-3,11:106.2
4,-3,11:106.1
-5,-3,11:106.9
5,-4,11:106.2
4,-4,11:106.2
3,-4,11:106.1
-4,-4,11:106.8
-5,-4,11:106.8
5,-5,11:106.3
4,-5,11:106.1
3,-5,11:106.1
2,-5,11:106.1
-3,-5,11:106.1
-4,-5,11:106.8
-5,-5,11:106.8
5,-6,11:106.1
3,-6,11:106.1
2,-6,11:106.1
1,-6,11:106.2
-2,-6,11:106.1
-3,-6,11:106.1
-4,-6,11:106.8
3,-7,11:106.1
2,-7,11:106.1
1,-7,11:106.1
0,-7,11:106.1
-1,-7,11:106.1
-2,-7,11:106.1
2,-8,11:106.1
1,-8,11:106.1
0,-8,11:106.1
-1,-8,11:106.1
-2,-8,11:106.9
1,-9,11:106.1
-1,-9,11:106.1
2,6,10:106.4
1,6,10:106.4
0,6,10:106.4
3,5,10:106.2
2,5,10:106.4
1,5,10:106.4
-1,5,10:106.4
4,4,10:106.2
3,4,10:106.2
2,4,10:106.4
1,4,10:106.4
0,4,10:106.4
-1,4,10:106.4
4,3,10:106.2
3,3,10:106.2
0,3,10:106.4
6,2,10:106.2
5,2,10:106.2
4,2,10:106.2
-1,2,10:106.4
-2,2,10:106.4
-4,2,10:106.8
6,1,10:106.2
5,1,10:106.2
-1,1,10:106.4
-2,1,10:106.4
-3,1,10:106.4
-4,1,10:106.8
6,0,10:106.2
-2,0,10:106.8
-4,0,10:106.8
7,-1,10:106.2
3,-1,10:106.2
-2,-1,10:106.8
-4,-1,10:106.12
8,-2,10:106.2
5,-2,10:106.2
3,-2,10:106.2
-2,-2,10:106.8
-5,-2,10:106.8
-6,-2,10:106.8
-7,-2,10:106.8
5,-3,10:106.2
3,-3,10:106.2
-5,-3,10:106.9
4,-4,10:106.2
3,-4,10:106.1
2,-4,10:106.1
-4,-4,10:106.8
-5,-4,10:106.8
5,-5,10:106.1
4,-5,10:106.1
2,-5,10:106.1
-3,-5,10:106.1
-4,-5,10:106.8
-5,-5,10:106.8
5,-6,10:106.1
3,-6,10:106.1
2,-6,10:106.1
1,-6,10:106.2
-2,-6,10:106.1
-3,-6,10:106.1
-4,-6,10:106.8
3,-7,10:106.1
2,-7,10:106.1
1,-7,10:106.1
0,-7,10:106.1
-1,-7,10:106.1
-2,-7,10:106.1
2,-8,10:106.1
1,-8,10:106.1
0,-8,10:106.1
-1,-8,10:106.1
-2,-8,10:106.8
1,-9,10:106.1
-1,-9,10:106.1
2,6,9:106.4
1,6,9:106.4
0,6,9:106.4
3,5,9:106.2
2,5,9:106.4
1,5,9:106.4
-1,5,9:106.4
3,4,9:106.2
2,4,9:106.4
1,4,9:106.4
0,4,9:106.4
-1,4,9:106.4
4,3,9:106.2
3,3,9:106.2
6,2,9:106.2
5,2,9:106.2
4,2,9:106.2
-1,2,9:106.4
-2,2,9:106.4
6,1,9:106.2
5,1,9:106.2
0,1,9:106.4
-1,1,9:106.4
-2,1,9:106.4
-3,1,9:106.4
-4,1,9:106.8
6,0,9:106.2
-2,0,9:106.8
-4,0,9:106.8
7,-1,9:106.2
3,-1,9:106.2
-2,-1,9:106.8
-4,-1,9:106.12
5,-2,9:106.2
3,-2,9:106.2
-5,-2,9:106.8
-6,-2,9:106.8
-7,-2,9:106.8
5,-3,9:106.2
3,-3,9:106.2
-5,-3,9:106.9
3,-4,9:106.1
2,-4,9:106.1
1,-4,9:106.1
-4,-4,9:106.8
-5,-4,9:106.8
5,-5,9:106.1
2,-5,9:106.1
-3,-5,9:106.1
-4,-5,9:106.8
-5,-5,9:106.8
2,-6,9:106.1
1,-6,9:106.2
-2,-6,9:106.1
-3,-6,9:106.1
-4,-6,9:106.8
3,-7,9:106.1
2,-7,9:106.1
1,-7,9:106.1
0,-7,9:106.1
1,-9,9:106.1
2,6,8:106.4
1,6,8:106.4
0,6,8:106.4
3,5,8:106.2
2,5,8:106.4
3,4,8:106.2
2,4,8:106.4
0,4,8:106.4
-1,4,8:106.4
4,3,8:106.2
3,3,8:106.2
-1,2,8:106.4
-2,2,8:106.4
5,1,8:106.2
1,1,8:106.4
0,1,8:106.4
-1,1,8:106.4
-2,1,8:106.4
-3,1,8:106.4
6,0,8:106.2
-2,0,8:106.8
-4,0,8:106.8
7,-1,8:106.2
3,-1,8:106.2
-2,-1,8:106.8
-4,-1,8:106.12
5,-2,8:106.2
3,-2,8:106.2
-5,-2,8:106.8
-7,-2,8:106.8
3,-3,8:106.2
-5,-3,8:106.9
3,-4,8:106.1
2,-4,8:106.1
1,-4,8:106.1
-4,-4,8:106.8
-5,-4,8:106.8
5,-5,8:106.1
2,-5,8:106.1
-3,-5,8:106.1
-4,-5,8:106.8
-5,-5,8:106.8
2,-6,8:106.1
1,-6,8:106.2
-2,-6,8:106.1
-3,-6,8:106.1
-4,-6,8:106.8
3,-7,8:106.1
2,-7,8:106.1
1,-7,8:106.1
0,-7,8:106.1
1,-9,8:106.1
3,5,7:106.2
2,5,7:106.4
3,4,7:106.2
2,4,7:106.4
0,4,7:106.4
-1,4,7:106.4
4,3,7:106.2
3,3,7:106.2
5,1,7:106.2
2,1,7:106.4
1,1,7:106.4
0,1,7:106.4
-1,1,7:106.4
-2,1,7:106.4
6,0,7:106.2
3,0,7:106.2
-2,0,7:106.8
7,-1,7:106.2
3,-1,7:106.2
-2,-1,7:106.8
-4,-1,7:106.12
3,-2,7:106.2
-5,-2,7:106.8
3,-3,7:106.2
-2,-3,7:106.8
3,-4,7:106.1
2,-4,7:106.1
1,-4,7:106.1
-1,-4,7:106.1
-4,-4,7:106.8
2,-5,7:106.1
-3,-5,7:106.1
-5,-5,7:106.8
2,-6,7:106.1
-2,-6,7:106.1
-3,-6,7:106.1
-4,-6,7:106.8
1,-7,7:106.1
0,-7,7:106.1
3,4,6:106.2
2,4,6:106.4
0,4,6:106.4
4,3,6:106.2
2,1,6:106.4
1,1,6:106.4
0,1,6:106.4
-1,1,6:106.4
-2,1,6:106.4
6,0,6:106.2
3,0,6:106.2
-2,0,6:106.8
3,-1,6:106.2
-2,-1,6:106.8
-4,-1,6:106.12
3,-2,6:106.2
-2,-2,6:106.8
-5,-2,6:106.8
3,-3,6:106.2
-2,-3,6:106.8
-1,-4,6:106.1
-3,-5,6:106.1
-5,-5,6:106.8
2,-6,6:106.1
-4,-6,6:106.8
1,-7,6:106.1
3,4,5:106.2
2,4,5:106.4
2,1,5:106.4
1,1,5:106.4
0,1,5:106.4
-1,1,5:106.4
6,0,5:106.2
3,0,5:106.2
-2,0,5:106.8
3,-1,5:106.2
-2,-1,5:106.8
-4,-1,5:106.12
3,-2,5:106.2
-2,-2,5:106.8
-5,-2,5:106.8
3,-3,5:106.2
-2,-3,5:106.8
-1,-4,5:106.1
-3,-5,5:106.1
3,4,4:106.2
2,1,4:106.4
1,1,4:106.4
0,1,4:106.4
-1,1,4:106.4
6,0,4:106.2
3,0,4:106.2
-2,0,4:106.8
3,-1,4:106.2
-2,-1,4:106.8
-4,-1,4:106.12
3,-2,4:106.2
-2,-2,4:106.8
-5,-2,4:106.8
3,-3,4:106.2
-2,-3,4:106.8
2,-4,4:106.1
-1,-4,4:106.1
-3,-5,4:106.1
3,4,3:106.2
2,1,3:106.4
1,1,3:106.4
0,1,3:106.4
-1,1,3:106.4
6,0,3:106.2
3,0,3:106.2
-2,0,3:106.8
3,-1,3:106.2
-2,-1,3:106.8
-4,-1,3:106.12
3,-2,3:106.2
-2,-2,3:106.8
-5,-2,3:106.8
3,-3,3:106.2
-2,-3,3:106.8
2,-4,3:106.1
1,-4,3:106.1
-1,-4,3:106.1
-3,-5,3:106.1
1,2,2:106.4
0,2,2:106.4
2,1,2:106.4
-1,1,2:106.4
3,0,2:106.2
-2,0,2:106.8
3,-1,2:106.2
-2,-1,2:106.8
-4,-1,2:106.12
3,-2,2:106.2
-2,-2,2:106.8
-5,-2,2:106.8
3,-3,2:106.2
-2,-3,2:106.8
2,-4,2:106.1
-1,-4,2:106.1
1,-5,2:106.1
0,-5,2:106.1
1,3,1:106.4
0,3,1:106.4
2,2,1:106.4
-1,2,1:106.4
3,1,1:106.2
-2,1,1:106.8
4,0,1:106.2
-3,0,1:106.8
4,-1,1:106.2
-3,-1,1:106.8
4,-2,1:106.2
-3,-2,1:106.8
4,-3,1:106.2
-3,-3,1:106.8
3,-4,1:106.2
-2,-4,1:106.8
2,-5,1:106.1
-1,-5,1:106.1
1,-6,1:106.1
0,-6,1:106.1
1,4,0:106.4
0,4,0:106.4
2,3,0:106.4
-1,3,0:106.4
4,1,0:106.2
-3,1,0:106.8
5,0,0:106.2
-4,0,0:106.8
5,-1,0:106.2
-4,-1,0:106.8
5,-2,0:106.2
-4,-2,0:106.8
5,-3,0:106.2
-4,-3,0:106.8
4,-4,0:106.2
-3,-4,0:106.8
2,-6,0:106.1
-1,-6,0:106.1
1,-7,0:106.1
0,-7,0:106.1
