[META]
version=2.0
spawnOnBlockType=8,9
spawnSunlight=True
spawnDarkness=True
spawnWater=False
spawnLava=False
underFill=False
randomRotation=True
dig=True
tree=False
branch=False
needsFoundation=True
rarity=100
collisionPercentage=10
spawnElevationMin=0
spawnElevationMax=100
spawnInBiome=Forest3
[DATA]
-2,0,-6:17.0
-1,1,-6:17.0
-3,0,-5:17.0
-1,0,-5:17.0
-1,2,-5:17.0
-3,-1,-4:17.0
-1,-1,-4:17.0
0,0,-4:17.0
-1,2,-4:17.0
0,-1,-3:17.0
-3,0,-3:17.0
-1,2,-3:17.0
-3,0,-2:17.0
0,0,-2:17.0
-2,1,-2:17.0
-1,3,-2:17.0
-1,-1,-1:3.0
1,0,-1:17.0
-3,1,-1:17.0
-1,4,-1:17.0
-1,-2,0:17.0
-1,-1,0:17.0
1,0,0:17.0
-3,1,0:17.0
-1,3,0:17.0
-1,4,0:17.0
-1,-1,1:17.0
1,0,1:17.0
-2,1,1:17.0
-1,3,1:17.0
-1,-1,2:18.14
-1,0,2:17.0
0,0,2:17.0
-2,1,2:18.14
-1,1,2:17.0
0,1,2:18.14
-1,2,2:17.0
0,2,2:18.14
-1,0,3:18.14
-1,1,3:17.0
-1,2,3:18.14
-1,1,4:18.14
-1,2,4:17.0
-1,1,5:18.14
-2,2,5:18.14
-1,2,5:17.0
0,2,5:18.14
-1,3,5:18.14
-1,2,6:18.14
-1,4,5:106.4
-2,3,5:106.8
1,2,5:106.2
-3,2,5:106.8
-1,0,5:106.1
-1,4,4:106.4
-2,3,4:106.8
1,2,4:106.2
-3,2,4:106.8
-1,0,4:106.1
-1,4,3:106.4
-2,3,3:106.8
1,2,3:106.2
-3,2,3:106.8
-2,0,3:106.8
-1,4,2:106.4
0,3,2:106.4
-2,3,2:106.8
1,2,2:106.2
-2,2,2:106.8
-3,2,2:106.8
-2,0,2:106.8
0,-1,2:106.1
-1,4,1:106.4
0,3,1:106.4
-2,3,1:106.8
1,2,1:106.2
-2,2,1:106.8
-3,2,1:106.8
-2,0,1:106.8
0,-1,1:106.1
0,3,0:106.4
-2,3,0:106.8
1,2,0:106.2
-2,2,0:106.8
-3,2,0:106.8
-2,1,0:106.0
-2,0,0:106.8
0,-1,0:106.1
