[META]
version=2.0
spawnOnBlockType=2
spawnSunlight=True
spawnDarkness=True
spawnWater=False
spawnLava=False
underFill=False
randomRotation=True
dig=False
tree=False
branch=False
needsFoundation=True
rarity=30
collisionPercentage=50
spawnElevationMin=0
spawnElevationMax=88
spawnInBiome=Forest3
[DATA]
1,-3,-5:3.0
0,-2,-5:3.0
1,-2,-5:17.3
2,-2,-5:3.0
-1,-1,-5:17.3
0,-1,-5:3.0
1,-1,-5:3.0
2,-5,-4:3.0
2,-4,-4:3.0
-1,-3,-4:3.0
0,-3,-4:3.0
1,-3,-4:17.3
2,-3,-4:3.0
-1,-2,-4:3.0
0,-2,-4:17.3
1,-2,-4:17.3
2,-2,-4:3.0
-1,-1,-4:17.3
0,-1,-4:3.0
1,-1,-4:3.0
0,0,-4:3.0
1,0,-4:3.0
2,-6,-3:3.0
0,-5,-3:17.3
2,-5,-3:3.0
-1,-4,-3:3.0
0,-4,-3:3.0
1,-4,-3:3.0
2,-4,-3:3.0
-2,-3,-3:3.0
-1,-3,-3:3.0
0,-3,-3:17.3
1,-3,-3:17.3
2,-3,-3:3.0
3,-3,-3:3.0
-2,-2,-3:3.0
-1,-2,-3:3.0
0,-2,-3:3.0
1,-2,-3:3.0
2,-2,-3:17.3
-1,-1,-3:3.0
0,-1,-3:3.0
1,-1,-3:17.3
2,-1,-3:3.0
3,-1,-3:17.3
-2,0,-3:17.3
-1,0,-3:3.0
0,0,-3:3.0
1,0,-3:17.3
2,0,-3:3.0
-2,1,-3:3.0
1,1,-3:3.0
2,1,-3:3.0
0,-8,-2:3.0
-5,-7,-2:3.0
0,-7,-2:2.0
2,-7,-2:3.0
4,-7,-2:3.0
-3,-6,-2:3.0
1,-6,-2:3.0
2,-6,-2:3.0
4,-6,-2:3.0
-4,-5,-2:3.0
-2,-5,-2:17.3
-1,-5,-2:3.0
0,-5,-2:3.0
1,-5,-2:3.0
2,-5,-2:17.3
3,-5,-2:3.0
-5,-4,-2:3.0
-2,-4,-2:3.0
-1,-4,-2:3.0
0,-4,-2:17.3
1,-4,-2:17.3
2,-4,-2:3.0
3,-4,-2:3.0
-6,-3,-2:3.0
-4,-3,-2:3.0
-3,-3,-2:3.0
-2,-3,-2:3.0
-1,-3,-2:3.0
0,-3,-2:3.0
1,-3,-2:3.0
2,-3,-2:3.0
3,-3,-2:3.0
-5,-2,-2:3.0
-3,-2,-2:3.0
-2,-2,-2:3.0
-1,-2,-2:3.0
0,-2,-2:3.0
1,-2,-2:3.0
2,-2,-2:3.0
5,-2,-2:3.0
6,-2,-2:3.0
-6,-1,-2:3.0
-3,-1,-2:3.0
-2,-1,-2:3.0
-1,-1,-2:3.0
0,-1,-2:3.0
1,-1,-2:3.0
2,-1,-2:3.0
3,-1,-2:3.0
4,-1,-2:17.3
-4,0,-2:3.0
-3,0,-2:3.0
-2,0,-2:3.0
-1,0,-2:3.0
0,0,-2:3.0
1,0,-2:3.0
2,0,-2:3.0
3,0,-2:3.0
4,0,-2:3.0
-3,1,-2:17.3
-2,1,-2:3.0
-1,1,-2:3.0
0,1,-2:3.0
1,1,-2:3.0
2,1,-2:17.3
3,1,-2:3.0
4,1,-2:3.0
0,2,-2:3.0
1,2,-2:3.0
2,2,-2:17.3
3,2,-2:3.0
5,2,-2:3.0
-2,3,-2:3.0
4,3,-2:3.0
-3,4,-2:3.0
-2,4,-2:3.0
5,4,-2:3.0
-4,5,-2:3.0
-5,6,-2:3.0
-1,-9,-1:18.14
0,-9,-1:17.1
-6,-8,-1:17.1
-5,-8,-1:2.0
-1,-8,-1:2.0
0,-8,-1:2.0
1,-8,-1:2.0
4,-8,-1:2.0
5,-8,-1:17.1
-6,-7,-1:2.0
-5,-7,-1:2.0
-4,-7,-1:2.0
-2,-7,-1:2.0
-1,-7,-1:2.0
0,-7,-1:30.0
1,-7,-1:2.0
2,-7,-1:2.0
3,-7,-1:2.0
4,-7,-1:2.0
5,-7,-1:2.0
-4,-6,-1:17.1
-3,-6,-1:2.0
-2,-6,-1:2.0
-1,-6,-1:2.0
0,-6,-1:2.0
1,-6,-1:3.0
2,-6,-1:17.3
3,-6,-1:2.0
4,-6,-1:2.0
5,-6,-1:2.0
-5,-5,-1:2.0
-4,-5,-1:2.0
-3,-5,-1:2.0
-2,-5,-1:3.0
-1,-5,-1:17.3
0,-5,-1:17.3
1,-5,-1:17.3
2,-5,-1:3.0
3,-5,-1:2.0
4,-5,-1:2.0
-6,-4,-1:2.0
-5,-4,-1:2.0
-4,-4,-1:2.0
-3,-4,-1:3.0
-2,-4,-1:3.0
-1,-4,-1:17.3
0,-4,-1:2.0
1,-4,-1:2.0
2,-4,-1:17.3
3,-4,-1:2.0
4,-4,-1:2.0
-7,-3,-1:2.0
-6,-3,-1:2.0
-5,-3,-1:2.0
-4,-3,-1:2.0
-3,-3,-1:17.3
-2,-3,-1:17.3
-1,-3,-1:2.0
0,-3,-1:2.0
1,-3,-1:2.0
2,-3,-1:17.3
3,-3,-1:3.0
4,-3,-1:2.0
5,-3,-1:2.0
7,-3,-1:2.0
-8,-2,-1:2.0
-7,-2,-1:17.1
-6,-2,-1:2.0
-5,-2,-1:2.0
-4,-2,-1:2.0
-3,-2,-1:17.3
-2,-2,-1:2.0
-1,-2,-1:2.0
0,-2,-1:2.0
1,-2,-1:2.0
2,-2,-1:2.0
3,-2,-1:17.3
4,-2,-1:2.0
5,-2,-1:2.0
6,-2,-1:2.0
7,-2,-1:17.1
-7,-1,-1:2.0
-6,-1,-1:2.0
-5,-1,-1:2.0
-4,-1,-1:2.0
-3,-1,-1:17.3
-2,-1,-1:2.0
-1,-1,-1:2.0
0,-1,-1:3.0
1,-1,-1:2.0
2,-1,-1:2.0
3,-1,-1:17.3
4,-1,-1:17.3
5,-1,-1:2.0
6,-1,-1:2.0
7,-1,-1:18.12
-6,0,-1:2.0
-5,0,-1:2.0
-4,0,-1:3.0
-3,0,-1:3.0
-2,0,-1:17.3
0,0,-1:2.0
1,0,-1:2.0
2,0,-1:17.3
3,0,-1:2.0
4,0,-1:2.0
5,0,-1:2.0
-4,1,-1:2.0
-3,1,-1:17.3
-2,1,-1:2.0
-1,1,-1:17.3
0,1,-1:2.0
1,1,-1:3.0
2,1,-1:17.3
3,1,-1:3.0
4,1,-1:17.3
-3,2,-1:2.0
-2,2,-1:2.0
-1,2,-1:3.0
0,2,-1:17.3
1,2,-1:17.3
2,2,-1:3.0
3,2,-1:17.3
4,2,-1:2.0
5,2,-1:2.0
6,2,-1:2.0
-4,3,-1:2.0
-3,3,-1:2.0
-2,3,-1:2.0
-1,3,-1:2.0
0,3,-1:2.0
1,3,-1:3.0
2,3,-1:17.3
3,3,-1:2.0
4,3,-1:2.0
5,3,-1:2.0
-4,4,-1:2.0
-3,4,-1:2.0
-2,4,-1:2.0
-1,4,-1:2.0
4,4,-1:2.0
5,4,-1:2.0
6,4,-1:2.0
-5,5,-1:18.14
-4,5,-1:2.0
-3,5,-1:2.0
5,5,-1:2.0
6,5,-1:17.1
7,5,-1:18.13
-6,6,-1:18.14
-5,6,-1:17.1
-4,6,-1:18.14
6,6,-1:18.13
-5,7,-1:18.14
-6,-9,0:18.12
-1,-9,0:18.14
0,-9,0:18.14
1,-9,0:18.14
-7,-8,0:18.12
-6,-8,0:18.12
0,-8,0:18.14
4,-8,0:18.14
5,-8,0:18.14
6,-8,0:18.14
-6,-7,0:18.12
2,-7,0:18.14
6,-7,0:18.14
-4,-6,0:18.12
0,-6,0:18.12
1,-6,0:17.3
2,-6,0:17.2
3,-6,0:18.14
6,-6,0:18.14
-2,-5,0:17.3
-1,-5,0:18.12
0,-5,0:17.3
1,-5,0:17.3
2,-5,0:17.3
-3,-4,0:17.3
-2,-4,0:17.3
-1,-4,0:17.3
2,-4,0:17.3
3,-4,0:18.12
-7,-3,0:18.13
-2,-3,0:17.3
2,-3,0:17.3
3,-3,0:17.3
7,-3,0:18.12
-8,-2,0:18.13
-7,-2,0:18.13
-4,-2,0:18.12
-3,-2,0:17.3
3,-2,0:17.3
7,-2,0:18.12
-7,-1,0:18.13
-4,-1,0:18.12
-3,-1,0:17.3
3,-1,0:17.3
-4,0,0:17.3
-3,0,0:17.3
-2,0,0:17.3
-1,0,0:17.3
2,0,0:17.3
3,0,0:18.12
-3,1,0:17.3
-2,1,0:18.12
-1,1,0:17.3
2,1,0:17.3
3,1,0:17.3
-2,2,0:18.14
-1,2,0:17.2
0,2,0:17.3
1,2,0:17.3
2,2,0:17.3
-1,3,0:18.14
0,3,0:18.12
1,3,0:17.3
2,3,0:18.12
6,4,0:18.13
-5,5,0:18.14
5,5,0:18.13
6,5,0:18.13
7,5,0:18.13
-6,6,0:18.14
-5,6,0:18.14
6,6,0:18.13
0,-9,1:18.14
-6,-8,1:18.12
3,-8,1:18.14
4,-8,1:18.14
5,-8,1:18.14
6,-8,1:18.14
1,-7,1:18.14
2,-7,1:18.14
5,-7,1:30.0
6,-7,1:18.14
-4,-6,1:18.12
0,-6,1:18.12
1,-6,1:17.2
2,-6,1:17.2
3,-6,1:18.14
-1,-5,1:18.12
0,-5,1:17.3
1,-5,1:17.3
2,-5,1:17.3
-2,-4,1:17.3
-1,-4,1:17.3
2,-4,1:17.3
-2,-3,1:17.3
2,-3,1:17.3
-7,-2,1:18.13
-4,-2,1:18.12
-3,-2,1:17.3
2,-2,1:17.1
3,-2,1:17.1
4,-2,1:18.12
6,-2,1:30.0
7,-2,1:18.12
-7,-1,1:18.13
-3,-1,1:17.3
3,-1,1:17.3
-3,0,1:17.3
-2,0,1:17.3
-1,0,1:17.3
2,0,1:17.3
3,0,1:18.12
-2,1,1:18.14
-1,1,1:17.3
2,1,1:17.3
3,1,1:17.3
-2,2,1:18.14
-1,2,1:17.2
0,2,1:17.3
1,2,1:17.3
2,2,1:17.3
3,2,1:18.12
-1,3,1:18.14
6,5,1:18.13
-5,6,1:18.14
-6,-8,2:18.12
-5,-8,2:18.12
4,-8,2:18.14
5,-8,2:18.14
-6,-7,2:18.12
-4,-7,2:18.12
1,-7,2:18.14
5,-7,2:18.14
-4,-6,2:18.12
0,-6,2:18.14
1,-6,2:17.2
2,-6,2:18.14
-1,-5,2:18.12
0,-5,2:17.3
1,-5,2:17.3
-2,-4,2:17.3
-1,-4,2:17.3
2,-4,2:17.3
-7,-3,2:18.13
-2,-3,2:17.3
2,-3,2:17.3
-7,-2,2:18.13
-6,-2,2:18.13
-3,-2,2:17.3
3,-2,2:17.3
4,-2,2:18.12
5,-2,2:18.12
6,-2,2:18.12
7,-2,2:18.12
-7,-1,2:18.13
-3,-1,2:17.3
3,-1,2:17.3
-2,0,2:17.3
-1,0,2:17.3
2,0,2:17.3
3,0,2:18.12
-1,1,2:17.3
2,1,2:17.3
3,1,2:18.12
-2,2,2:18.14
-1,2,2:17.2
0,2,2:17.3
1,2,2:17.3
2,2,2:17.3
-1,3,2:18.14
0,3,2:17.2
0,4,2:18.14
6,4,2:18.13
-5,5,2:18.14
5,5,2:18.13
6,5,2:18.13
7,5,2:18.13
-5,6,2:18.14
-4,6,2:18.14
6,6,2:18.13
5,-8,3:18.14
0,-7,3:18.14
1,-7,3:18.14
-1,-6,3:18.14
0,-6,3:17.2
1,-6,3:17.2
2,-6,3:18.14
-2,-5,3:18.12
0,-5,3:17.3
1,-5,3:17.3
-2,-4,3:17.3
-1,-4,3:17.3
2,-4,3:17.3
-2,-3,3:17.3
2,-3,3:17.3
-3,-2,3:17.3
3,-2,3:17.3
-3,-1,3:17.3
3,-1,3:17.3
4,-1,3:18.12
-2,0,3:17.3
-1,0,3:17.3
2,0,3:17.3
-1,1,3:17.3
0,1,3:17.3
2,1,3:17.3
3,1,3:18.12
-1,2,3:18.14
0,2,3:17.3
1,2,3:17.3
-1,3,3:18.14
0,3,3:17.2
1,3,3:18.14
0,4,3:18.14
6,5,3:18.13
0,-7,4:18.14
-1,-6,4:18.14
0,-6,4:17.2
1,-6,4:18.14
0,-5,4:17.3
1,-5,4:17.3
-2,-4,4:18.12
-1,-4,4:17.3
2,-4,4:17.3
-2,-3,4:17.3
2,-3,4:17.3
3,-3,4:18.12
-3,-2,4:17.3
-2,-2,4:17.3
3,-2,4:17.3
4,-2,4:18.12
-3,-1,4:17.3
-2,-1,4:17.3
3,-1,4:17.3
-2,0,4:17.3
-1,0,4:17.3
2,0,4:17.3
-1,1,4:17.3
0,1,4:17.3
2,1,4:17.3
0,2,4:17.3
1,2,4:17.3
2,2,4:18.14
-1,3,4:18.14
0,3,4:17.2
1,3,4:17.2
2,3,4:18.14
0,4,4:18.14
1,4,4:18.14
-1,-7,5:18.14
0,-7,5:18.14
-2,-6,5:18.14
-1,-6,5:17.2
0,-6,5:17.2
1,-6,5:18.14
-2,-5,5:18.14
-1,-5,5:17.2
0,-5,5:17.3
1,-5,5:17.3
-2,-4,5:18.12
-1,-4,5:17.3
2,-4,5:17.3
-3,-3,5:18.12
-2,-3,5:17.3
1,-3,5:17.3
2,-3,5:17.3
3,-3,5:18.12
-3,-2,5:17.3
1,-2,5:17.3
2,-2,5:17.3
3,-2,5:17.3
4,-2,5:18.12
-2,-1,5:17.3
3,-1,5:17.3
-2,0,5:17.3
-1,0,5:17.3
1,0,5:17.3
2,0,5:17.3
3,0,5:17.3
0,1,5:17.3
2,1,5:17.3
0,2,5:17.3
1,2,5:17.3
0,3,5:18.14
1,3,5:17.2
2,3,5:18.14
1,4,5:18.14
-1,-6,6:18.14
0,-6,6:18.14
-2,-5,6:18.14
-1,-5,6:17.2
0,-5,6:17.3
1,-5,6:17.3
-2,-4,6:18.12
-1,-4,6:17.3
2,-4,6:17.3
3,-4,6:18.12
-3,-3,6:18.12
-2,-3,6:17.3
1,-3,6:17.3
2,-3,6:17.3
3,-3,6:18.12
-3,-2,6:17.3
-2,-2,6:17.3
0,-2,6:17.3
2,-2,6:17.3
3,-2,6:17.3
-2,-1,6:17.3
3,-1,6:17.3
-2,0,6:17.3
-1,0,6:17.3
1,0,6:17.3
3,0,6:17.3
0,1,6:17.3
2,1,6:17.3
0,2,6:17.3
1,2,6:17.3
2,2,6:17.2
3,2,6:18.14
0,3,6:18.14
1,3,6:17.2
2,3,6:18.14
1,4,6:18.14
-2,-6,7:18.14
-1,-6,7:18.14
-3,-5,7:18.14
-2,-5,7:17.2
-1,-5,7:17.2
0,-5,7:17.3
1,-5,7:17.3
2,-5,7:18.12
3,-5,7:18.12
-1,-4,7:17.3
1,-4,7:17.3
2,-4,7:17.3
3,-4,7:18.12
-2,-3,7:17.3
-1,-3,7:17.3
2,-3,7:17.3
-3,-2,7:18.12
-2,-2,7:17.3
3,-2,7:17.3
-2,-1,7:17.3
-1,-1,7:17.3
3,-1,7:17.3
-2,0,7:17.3
-1,0,7:17.3
3,0,7:17.3
0,1,7:17.3
1,1,7:17.3
2,1,7:17.3
0,2,7:17.3
1,2,7:17.3
2,2,7:17.2
3,2,7:18.14
1,3,7:18.14
2,3,7:18.14
-2,-6,8:18.14
-3,-5,8:18.14
-2,-5,8:17.2
-1,-5,8:18.12
0,-5,8:17.3
1,-5,8:17.3
2,-5,8:18.12
3,-5,8:18.12
-2,-4,8:17.3
-1,-4,8:17.3
2,-4,8:17.3
3,-4,8:18.12
-2,-3,8:17.3
2,-3,8:17.3
-2,-2,8:17.3
3,-2,8:17.3
-3,-1,8:18.12
-2,-1,8:17.3
3,-1,8:17.3
-2,0,8:17.3
-1,0,8:17.3
3,0,8:17.3
0,1,8:17.3
2,1,8:17.3
3,1,8:17.2
4,1,8:18.14
0,2,8:17.3
1,2,8:17.3
2,2,8:17.2
3,2,8:18.14
2,3,8:18.14
-2,-6,9:18.14
0,-6,9:18.12
-3,-5,9:18.14
-2,-5,9:17.2
-1,-5,9:18.12
0,-5,9:17.3
1,-5,9:18.12
-3,-4,9:18.14
-2,-4,9:17.2
-1,-4,9:17.3
0,-4,9:17.3
1,-4,9:18.12
2,-4,9:17.3
-2,-3,9:17.3
-1,-3,9:18.12
0,-3,9:17.3
1,-3,9:17.3
2,-3,9:17.3
-2,-2,9:17.3
-1,-2,9:17.3
0,-2,9:17.3
2,-2,9:17.3
-2,-1,9:18.12
-1,-1,9:17.3
0,-1,9:17.3
1,-1,9:17.3
2,-1,9:17.3
-2,0,9:17.3
-1,0,9:17.3
0,0,9:17.3
1,0,9:17.3
2,0,9:17.3
3,0,9:17.3
-1,1,9:18.12
0,1,9:17.3
1,1,9:17.3
2,1,9:17.3
3,1,9:17.2
4,1,9:18.14
-1,2,9:18.12
0,2,9:17.3
2,2,9:18.14
3,2,9:18.14
-2,-5,10:18.14
0,-5,10:18.12
-3,-4,10:18.14
-2,-4,10:17.2
-1,-4,10:18.12
0,-4,10:17.3
1,-4,10:18.12
-4,-3,10:18.14
-3,-3,10:17.2
-2,-3,10:17.2
-1,-3,10:18.12
0,-3,10:17.3
1,-3,10:17.3
2,-3,10:17.3
-3,-2,10:18.14
-2,-2,10:17.3
-1,-2,10:17.3
0,-2,10:17.3
2,-2,10:17.3
-1,-1,10:17.3
0,-1,10:17.3
1,-1,10:17.3
3,-1,10:18.14
-1,0,10:17.3
0,0,10:17.3
1,0,10:17.3
2,0,10:17.3
3,0,10:17.2
4,0,10:18.14
-1,1,10:18.12
0,1,10:17.3
3,1,10:18.14
-3,-4,11:18.14
-2,-4,11:18.14
0,-4,11:17.3
1,-4,11:18.12
-4,-3,11:18.14
-3,-3,11:17.2
-2,-3,11:18.14
-1,-3,11:18.12
0,-3,11:17.3
1,-3,11:17.3
2,-3,11:17.3
-3,-2,11:18.14
-2,-2,11:17.3
-1,-2,11:17.3
0,-2,11:17.3
2,-2,11:17.3
-1,-1,11:17.3
0,-1,11:17.3
1,-1,11:17.3
-1,0,11:17.3
0,0,11:17.3
1,0,11:17.3
2,0,11:17.2
3,0,11:18.14
0,1,11:18.12
1,1,11:18.12
2,1,11:18.14
-2,2,11:18.12
-3,-4,12:18.14
0,-4,12:17.3
-4,-3,12:18.14
-3,-3,12:17.2
-2,-3,12:18.12
0,-3,12:17.3
1,-3,12:17.3
2,-3,12:17.3
-4,-2,12:18.14
-3,-2,12:17.2
-2,-2,12:17.3
-1,-2,12:17.3
0,-2,12:17.3
2,-2,12:17.3
-3,-1,12:18.14
-1,-1,12:17.3
0,-1,12:17.3
1,-1,12:17.3
2,-1,12:17.2
3,-1,12:18.14
-2,0,12:18.12
-1,0,12:18.12
0,0,12:17.3
1,0,12:17.3
2,0,12:17.2
3,0,12:18.14
-2,1,12:18.12
-1,1,12:18.12
0,1,12:18.12
1,1,12:18.12
2,1,12:18.14
-2,2,12:18.12
-1,2,12:18.12
-3,-3,13:18.14
-2,-3,13:18.14
-1,-3,13:18.12
0,-3,13:17.3
1,-3,13:17.3
3,-3,13:18.14
-3,-2,13:18.14
-2,-2,13:17.2
-1,-2,13:17.3
0,-2,13:17.3
2,-2,13:17.3
3,-2,13:17.2
4,-2,13:18.14
-2,-1,13:18.12
-1,-1,13:17.3
0,-1,13:17.3
1,-1,13:17.3
2,-1,13:17.2
3,-1,13:18.14
-1,0,13:18.12
0,0,13:17.3
1,0,13:17.3
2,0,13:18.12
0,1,13:18.12
1,1,13:18.12
3,4,13:18.6
2,-4,14:18.14
-2,-3,14:18.14
-1,-3,14:18.12
0,-3,14:17.3
1,-3,14:17.3
2,-3,14:17.2
3,-3,14:18.14
-3,-2,14:18.14
-2,-2,14:17.2
-1,-2,14:17.3
0,-2,14:17.3
2,-2,14:17.3
3,-2,14:17.2
4,-2,14:18.14
-3,-1,14:18.14
-2,-1,14:17.2
-1,-1,14:17.3
0,-1,14:17.3
1,-1,14:17.3
2,-1,14:17.2
3,-1,14:18.12
-2,0,14:18.14
0,0,14:17.3
1,0,14:17.3
2,0,14:18.12
3,0,14:18.12
3,4,14:18.14
0,-4,15:18.12
1,-4,15:18.12
2,-4,15:18.14
0,-3,15:17.3
1,-3,15:17.3
2,-3,15:17.2
3,-3,15:18.14
-2,-2,15:18.14
-1,-2,15:17.3
0,-2,15:17.3
2,-2,15:17.3
3,-2,15:18.12
-3,-1,15:18.14
-2,-1,15:17.2
-1,-1,15:17.3
0,-1,15:17.3
1,-1,15:17.3
2,-1,15:17.2
3,-1,15:18.14
-2,0,15:18.14
0,0,15:17.3
1,0,15:17.3
3,4,15:18.14
0,-5,16:18.12
-1,-4,16:18.12
0,-4,16:18.12
1,-4,16:18.12
2,-4,16:18.14
-1,-3,16:18.12
0,-3,16:17.3
1,-3,16:17.3
2,-3,16:17.2
3,-3,16:18.14
-2,-2,16:18.14
-1,-2,16:17.3
0,-2,16:17.3
2,-2,16:17.3
3,-2,16:18.12
-3,-1,16:18.14
-2,-1,16:17.2
-1,-1,16:17.3
0,-1,16:17.3
1,-1,16:17.3
2,-1,16:17.2
3,-1,16:18.14
-3,0,16:18.14
-2,0,16:17.2
0,0,16:17.3
1,0,16:17.3
2,0,16:17.2
3,0,16:18.14
-2,1,16:18.14
2,1,16:18.14
2,2,16:18.14
3,2,16:18.14
3,3,16:18.14
4,3,16:18.14
3,4,16:18.14
1,-5,17:18.14
0,-4,17:18.12
1,-4,17:17.2
2,-4,17:18.14
0,-3,17:17.3
1,-3,17:17.3
2,-3,17:17.2
3,-3,17:18.14
-1,-2,17:17.3
0,-2,17:17.3
2,-2,17:17.3
-2,-1,17:18.14
-1,-1,17:17.3
0,-1,17:17.3
1,-1,17:17.3
-3,0,17:18.14
-2,0,17:17.2
-1,0,17:17.2
0,0,17:17.3
1,0,17:17.3
2,0,17:17.2
3,0,17:18.14
-2,1,17:18.14
-1,1,17:18.14
2,1,17:18.14
1,2,17:18.14
2,2,17:17.2
3,2,17:18.14
4,2,17:18.14
2,3,17:18.14
3,3,17:17.2
4,3,17:18.14
3,4,17:18.14
1,-5,18:18.14
0,-4,18:18.14
1,-4,18:17.2
2,-4,18:18.14
-1,-3,18:18.12
0,-3,18:17.3
1,-3,18:17.3
-1,-2,18:17.3
0,-2,18:17.3
2,-2,18:17.3
-1,-1,18:17.3
0,-1,18:17.3
1,-1,18:17.3
-2,0,18:18.14
-1,0,18:17.2
0,0,18:17.3
1,0,18:17.3
2,0,18:17.2
3,0,18:18.14
-1,1,18:18.14
0,1,18:17.2
1,1,18:17.2
2,1,18:18.14
1,2,18:18.14
2,2,18:18.14
3,3,18:18.14
0,-5,19:18.14
1,-5,19:18.14
0,-4,19:17.2
1,-4,19:17.2
2,-4,19:18.14
-1,-3,19:18.12
0,-3,19:17.3
1,-3,19:17.3
-1,-2,19:17.3
0,-2,19:17.3
2,-2,19:17.3
-1,-1,19:17.3
0,-1,19:17.3
1,-1,19:17.3
-2,0,19:18.14
-1,0,19:17.2
0,0,19:17.3
1,0,19:17.3
-2,1,19:18.14
-1,1,19:17.2
0,1,19:17.2
1,1,19:18.14
-1,2,19:18.14
0,-5,20:18.14
-1,-4,20:18.14
0,-4,20:17.2
1,-4,20:18.14
-2,-3,20:18.12
-1,-3,20:18.12
0,-3,20:17.3
1,-3,20:17.3
-1,-2,20:17.3
0,-2,20:17.3
2,-2,20:17.3
-1,-1,20:17.3
0,-1,20:17.3
1,-1,20:17.3
0,0,20:17.3
1,0,20:17.3
-1,1,20:18.14
0,1,20:17.2
1,1,20:18.14
-2,2,20:18.12
0,-5,21:18.14
-1,-4,21:18.14
0,-4,21:17.2
1,-4,21:18.14
-2,-3,21:18.14
-1,-3,21:17.2
0,-3,21:17.3
1,-3,21:17.3
-2,-2,21:18.12
-1,-2,21:17.3
0,-2,21:17.3
2,-2,21:17.3
-1,-1,21:17.3
0,-1,21:17.3
1,-1,21:17.3
0,0,21:17.3
1,0,21:17.3
-1,1,21:18.14
0,1,21:17.2
1,1,21:17.2
2,1,21:18.14
-2,2,21:18.12
1,2,21:18.14
-1,-4,22:18.14
0,-4,22:18.14
1,-4,22:18.12
-2,-3,22:18.14
-1,-3,22:17.2
0,-3,22:17.3
1,-3,22:17.3
-1,-2,22:17.3
0,-2,22:17.3
2,-2,22:17.3
-2,-1,22:18.12
-1,-1,22:17.3
0,-1,22:17.3
1,-1,22:17.3
0,0,22:17.3
1,0,22:17.3
0,1,22:18.14
1,1,22:17.2
2,1,22:18.14
-2,2,22:18.12
1,2,22:18.14
6,-6,23:18.12
-1,-4,23:18.14
-2,-3,23:18.14
-1,-3,23:17.2
0,-3,23:17.3
1,-3,23:17.3
2,-3,23:18.12
-3,-2,23:18.14
-2,-2,23:17.2
-1,-2,23:17.3
0,-2,23:17.3
2,-2,23:17.3
-1,-1,23:17.3
0,-1,23:17.3
1,-1,23:17.3
-1,0,23:18.12
0,0,23:17.3
1,0,23:17.3
-1,1,23:18.12
0,1,23:18.14
1,1,23:17.2
2,1,23:17.2
3,1,23:18.14
-2,2,23:18.12
-1,2,23:18.12
1,2,23:18.14
2,2,23:18.14
6,-6,24:18.12
-2,-3,24:18.14
-1,-3,24:18.14
0,-3,24:17.3
1,-3,24:17.3
-3,-2,24:18.14
-2,-2,24:17.2
-1,-2,24:17.3
0,-2,24:17.3
2,-2,24:17.3
3,-2,24:18.12
-2,-1,24:18.12
-1,-1,24:17.3
0,-1,24:17.3
1,-1,24:17.3
2,-1,24:17.2
3,-1,24:17.2
4,-1,24:18.14
-1,0,24:17.3
0,0,24:17.3
1,0,24:17.3
2,0,24:17.2
3,0,24:18.14
-3,1,24:18.12
-2,1,24:18.12
-1,1,24:17.3
0,1,24:18.12
1,1,24:18.12
2,1,24:17.2
3,1,24:18.14
-4,2,24:18.12
-3,2,24:18.12
-2,2,24:17.3
-1,2,24:18.12
2,2,24:18.14
-3,3,24:18.12
-2,3,24:18.12
-1,3,24:18.12
6,-6,25:18.12
-2,-3,25:18.14
0,-3,25:17.3
1,-3,25:17.3
3,-3,25:18.14
-3,-2,25:18.14
-2,-2,25:17.2
-1,-2,25:17.3
0,-2,25:17.3
2,-2,25:17.3
3,-2,25:17.2
4,-2,25:18.14
-3,-1,25:18.14
-2,-1,25:17.2
-1,-1,25:17.3
0,-1,25:17.3
1,-1,25:17.3
2,-1,25:18.12
3,-1,25:17.2
4,-1,25:18.14
-3,0,25:18.12
-2,0,25:18.14
-1,0,25:18.12
0,0,25:17.3
1,0,25:17.3
2,0,25:18.14
3,0,25:18.14
-4,1,25:18.12
-3,1,25:18.12
-1,1,25:18.12
1,1,25:18.12
2,1,25:18.14
-5,2,25:18.12
-4,2,25:18.12
-3,2,25:17.3
-2,2,25:18.12
-4,3,25:18.12
-3,3,25:18.12
-2,3,25:18.12
-3,4,25:18.12
6,-6,26:18.12
0,-3,26:17.3
1,-3,26:17.3
3,-3,26:18.14
-2,-2,26:18.14
-1,-2,26:17.3
0,-2,26:17.3
2,-2,26:17.3
3,-2,26:17.2
4,-2,26:18.14
-3,-1,26:18.14
-2,-1,26:17.2
-1,-1,26:17.3
0,-1,26:17.3
1,-1,26:17.3
2,-1,26:18.12
3,-1,26:18.12
4,-1,26:18.12
-2,0,26:18.14
0,0,26:17.3
1,0,26:17.3
2,0,26:18.12
3,0,26:18.12
-4,1,26:18.12
0,1,26:18.12
-4,2,26:18.12
-3,2,26:18.12
-2,2,26:18.12
-3,3,26:18.12
6,-6,27:18.12
3,-4,27:18.12
0,-3,27:17.3
1,-3,27:17.3
3,-3,27:18.12
-2,-2,27:18.14
-1,-2,27:17.3
0,-2,27:17.3
2,-2,27:17.3
3,-2,27:17.2
4,-2,27:18.14
-3,-1,27:18.14
-2,-1,27:17.2
-1,-1,27:17.3
0,-1,27:17.3
1,-1,27:17.3
2,-1,27:18.12
3,-1,27:18.12
-2,0,27:18.14
-1,0,27:17.2
0,0,27:17.3
1,0,27:17.3
2,0,27:18.12
3,0,27:18.12
-1,1,27:18.14
0,1,27:18.12
6,-7,28:18.12
7,-7,28:18.12
5,-6,28:18.12
6,-6,28:18.12
7,-6,28:18.12
3,-5,28:18.12
4,-5,28:18.12
5,-5,28:18.12
6,-5,28:18.12
7,-5,28:18.12
2,-4,28:18.12
3,-4,28:17.3
4,-4,28:18.12
5,-4,28:18.12
0,-3,28:17.3
1,-3,28:17.3
2,-3,28:17.3
3,-3,28:17.3
4,-3,28:18.12
-1,-2,28:17.3
2,-2,28:17.3
3,-2,28:17.2
4,-2,28:18.14
-2,-1,28:18.14
-1,-1,28:17.3
0,-1,28:17.3
1,-1,28:17.3
-2,0,28:18.14
-1,0,28:17.2
0,0,28:17.3
1,0,28:17.3
2,0,28:18.12
-1,1,28:18.14
1,1,28:18.12
6,-8,29:18.12
7,-8,29:18.12
5,-7,29:18.12
6,-7,29:18.12
7,-7,29:18.12
8,-7,29:18.12
4,-6,29:18.12
5,-6,29:17.3
6,-6,29:18.12
7,-6,29:17.3
8,-6,29:18.12
4,-5,29:18.12
5,-5,29:17.3
6,-5,29:17.3
7,-5,29:18.12
8,-5,29:18.12
2,-4,29:18.12
3,-4,29:18.12
4,-4,29:17.3
5,-4,29:18.12
6,-4,29:18.12
7,-4,29:18.12
0,-3,29:17.3
1,-3,29:17.3
2,-3,29:17.2
3,-3,29:17.2
4,-3,29:18.12
-1,-2,29:17.3
2,-2,29:17.3
3,-2,29:17.2
4,-2,29:18.14
-1,-1,29:17.3
0,-1,29:17.3
1,-1,29:17.3
2,-1,29:18.12
3,-1,29:18.12
-2,0,29:18.14
-1,0,29:17.2
0,0,29:17.3
1,0,29:17.3
2,0,29:18.12
-1,1,29:18.14
0,1,29:17.2
0,2,29:18.14
6,-7,30:18.12
-4,-6,30:18.12
5,-6,30:18.12
6,-6,30:18.12
7,-6,30:18.12
5,-5,30:18.12
6,-5,30:18.12
7,-5,30:18.12
0,-4,30:18.12
1,-4,30:18.12
2,-4,30:18.12
4,-4,30:18.12
0,-3,30:17.3
1,-3,30:17.3
2,-3,30:17.2
3,-3,30:18.12
0,-2,30:17.3
2,-2,30:18.12
3,-2,30:18.12
-1,-1,30:17.3
0,-1,30:17.3
1,-1,30:17.3
-1,0,30:18.14
0,0,30:17.3
1,0,30:17.3
-1,1,30:18.14
0,1,30:17.2
0,2,30:18.14
1,2,30:18.12
2,-7,31:18.12
-4,-6,31:18.12
6,-6,31:18.12
5,-5,31:18.12
6,-5,31:18.12
-1,-4,31:18.12
0,-4,31:18.12
1,-4,31:18.12
2,-4,31:18.12
-1,-3,31:18.12
0,-3,31:17.3
1,-3,31:17.3
2,-3,31:17.2
3,-3,31:18.12
0,-2,31:17.3
1,-2,31:17.3
2,-2,31:18.12
0,-1,31:17.3
1,-1,31:17.3
5,-1,31:18.12
-1,0,31:18.14
0,0,31:17.2
1,0,31:17.2
2,0,31:18.14
0,1,31:18.14
1,1,31:18.14
3,1,31:18.12
1,2,31:18.12
2,-7,32:18.12
-4,-6,32:18.12
5,-5,32:18.12
-1,-4,32:18.12
1,-4,32:18.12
2,-4,32:18.12
0,-3,32:17.3
1,-3,32:17.2
2,-3,32:17.2
3,-3,32:18.12
-6,-2,32:18.12
-1,-2,32:18.12
0,-2,32:17.3
1,-2,32:17.3
2,-2,32:18.12
0,-1,32:17.3
1,-1,32:17.3
5,-1,32:18.12
0,0,32:18.14
1,0,32:17.2
2,0,32:18.14
1,1,32:18.14
3,1,32:18.12
1,2,32:18.12
-3,3,32:18.12
6,3,32:18.12
2,-7,33:18.12
-4,-6,33:18.12
5,-5,33:18.12
-1,-4,33:18.12
0,-4,33:18.12
1,-4,33:18.12
-2,-3,33:18.12
-1,-3,33:17.2
0,-3,33:17.2
1,-3,33:17.2
2,-3,33:18.12
-6,-2,33:18.12
0,-2,33:17.3
1,-2,33:17.3
-1,-1,33:18.12
0,-1,33:17.3
1,-1,33:17.3
5,-1,33:18.12
0,0,33:17.3
1,0,33:17.2
2,0,33:18.14
1,1,33:18.14
3,1,33:18.12
1,2,33:18.12
-3,3,33:18.12
6,3,33:18.12
2,-7,34:18.12
-4,-6,34:18.12
5,-5,34:18.12
-3,-4,34:18.12
-2,-4,34:18.12
-1,-4,34:18.12
-2,-3,34:18.12
-1,-3,34:17.2
0,-3,34:17.3
1,-3,34:18.12
-6,-2,34:18.12
-2,-2,34:18.12
-1,-2,34:17.2
0,-2,34:17.2
1,-2,34:17.3
-2,-1,34:18.12
-1,-1,34:17.2
0,-1,34:18.12
1,-1,34:17.3
5,-1,34:18.12
-2,0,34:18.12
0,0,34:18.12
1,0,34:17.2
2,0,34:17.3
-1,1,34:17.3
1,1,34:18.14
3,1,34:18.12
4,1,34:18.12
1,2,34:18.12
3,2,34:18.12
-3,3,34:18.12
6,3,34:18.12
4,-8,35:18.12
2,-7,35:18.12
3,-7,35:18.12
4,-7,35:18.12
5,-7,35:18.12
-4,-6,35:18.12
2,-6,35:18.12
3,-6,35:18.12
4,-6,35:18.12
5,-6,35:18.12
6,-6,35:18.12
-5,-5,35:18.12
-4,-5,35:18.12
-3,-5,35:17.3
-2,-5,35:18.12
-1,-5,35:18.12
1,-5,35:18.12
2,-5,35:17.3
3,-5,35:18.12
4,-5,35:18.12
5,-5,35:18.12
-5,-4,35:18.12
-4,-4,35:18.12
-3,-4,35:18.12
-2,-4,35:17.3
-1,-4,35:17.3
0,-4,35:18.12
1,-4,35:18.12
2,-4,35:17.3
3,-4,35:18.12
-3,-3,35:18.12
-1,-3,35:18.12
0,-3,35:18.12
2,-3,35:17.3
3,-3,35:17.3
-6,-2,35:18.12
-1,-2,35:18.12
0,-2,35:18.12
1,-2,35:18.12
-2,-1,35:18.12
-1,-1,35:17.2
0,-1,35:18.12
1,-1,35:17.3
5,-1,35:18.12
-2,0,35:18.12
0,0,35:18.12
1,0,35:17.2
2,0,35:18.12
3,0,35:18.12
5,0,35:18.12
6,0,35:18.12
-3,1,35:18.12
-2,1,35:18.12
-1,1,35:18.12
0,1,35:18.12
1,1,35:17.2
2,1,35:18.12
3,1,35:17.3
4,1,35:17.3
5,1,35:18.12
6,1,35:18.12
7,1,35:18.12
-4,2,35:18.12
-3,2,35:18.12
-2,2,35:17.3
-1,2,35:18.12
0,2,35:18.12
1,2,35:17.3
3,2,35:18.12
4,2,35:18.12
5,2,35:18.12
6,2,35:18.12
-6,3,35:18.12
-5,3,35:18.12
-4,3,35:18.12
-3,3,35:17.3
-2,3,35:17.3
-1,3,35:18.12
0,3,35:18.12
4,3,35:18.12
5,3,35:17.3
6,3,35:18.12
-6,4,35:18.4
-5,4,35:18.12
-4,4,35:18.12
-2,4,35:18.12
-1,4,35:18.12
0,4,35:18.12
-4,5,35:18.12
-3,5,35:18.12
-1,5,35:18.12
0,5,35:18.12
-3,6,35:18.12
-2,6,35:18.12
-1,6,35:18.12
-4,7,35:18.12
-2,7,35:18.12
3,-9,36:18.12
4,-9,36:18.12
2,-8,36:18.12
3,-8,36:18.12
4,-8,36:18.12
5,-8,36:18.12
-4,-7,36:18.12
-3,-7,36:18.12
1,-7,36:18.12
2,-7,36:18.12
3,-7,36:18.12
4,-7,36:17.3
5,-7,36:18.12
6,-7,36:18.12
-5,-6,36:18.12
-4,-6,36:18.12
-3,-6,36:18.12
-2,-6,36:18.12
1,-6,36:18.12
2,-6,36:17.3
3,-6,36:18.12
4,-6,36:18.12
5,-6,36:18.12
6,-6,36:18.12
-6,-5,36:18.12
-5,-5,36:18.12
-4,-5,36:18.12
-3,-5,36:17.3
-2,-5,36:18.12
2,-5,36:18.12
3,-5,36:18.12
4,-5,36:18.12
5,-5,36:18.12
6,-5,36:18.12
7,-5,36:18.12
-7,-4,36:18.12
-6,-4,36:18.12
-5,-4,36:17.3
-4,-4,36:18.12
-3,-4,36:18.12
-2,-4,36:18.12
-1,-4,36:18.12
2,-4,36:18.12
3,-4,36:18.12
4,-4,36:18.12
5,-4,36:18.12
6,-4,36:18.12
-6,-3,36:18.12
-5,-3,36:18.12
-4,-3,36:18.12
-3,-3,36:18.12
-2,-3,36:18.12
2,-3,36:18.12
4,-3,36:17.3
5,-3,36:18.12
-8,-2,36:18.12
-7,-2,36:18.12
-6,-2,36:18.12
-5,-2,36:18.12
-2,-2,36:18.12
-1,-2,36:18.12
1,-2,36:18.12
2,-2,36:18.12
4,-2,36:18.12
5,-2,36:18.12
-8,-1,36:18.4
-7,-1,36:18.12
-6,-1,36:18.12
-2,-1,36:18.12
-1,-1,36:17.2
0,-1,36:18.12
1,-1,36:17.3
4,-1,36:18.12
5,-1,36:18.12
6,-1,36:18.12
-7,0,36:18.12
-6,0,36:18.12
-4,0,36:18.12
-3,0,36:18.12
-2,0,36:18.12
-1,0,36:18.12
0,0,36:18.4
1,0,36:18.12
3,0,36:18.12
4,0,36:18.12
5,0,36:18.12
6,0,36:18.12
-5,1,36:18.12
-4,1,36:18.12
-3,1,36:18.12
-2,1,36:18.12
-1,1,36:18.12
0,1,36:18.14
1,1,36:17.2
3,1,36:18.12
4,1,36:18.12
5,1,36:17.3
6,1,36:18.12
7,1,36:18.12
-6,2,36:18.12
-5,2,36:18.12
-4,2,36:18.12
-3,2,36:18.12
-2,2,36:18.12
-1,2,36:18.12
0,2,36:18.12
1,2,36:18.14
2,2,36:18.12
3,2,36:18.12
4,2,36:18.12
5,2,36:18.12
6,2,36:18.12
7,2,36:18.12
-7,3,36:18.12
-6,3,36:18.12
-5,3,36:18.12
-4,3,36:18.12
-3,3,36:17.3
-2,3,36:18.12
-1,3,36:18.12
0,3,36:18.12
1,3,36:18.12
2,3,36:18.12
3,3,36:18.12
4,3,36:18.12
5,3,36:18.12
6,3,36:18.12
-8,4,36:18.12
-7,4,36:18.12
-6,4,36:18.12
-5,4,36:18.12
-4,4,36:18.12
-3,4,36:18.12
-2,4,36:18.12
-1,4,36:18.12
0,4,36:18.12
1,4,36:18.12
2,4,36:18.12
4,4,36:18.12
-6,5,36:18.12
-5,5,36:18.12
-4,5,36:17.3
-3,5,36:18.12
-2,5,36:17.3
-1,5,36:18.12
0,5,36:18.12
1,5,36:18.12
-5,6,36:18.12
-4,6,36:18.12
-3,6,36:18.12
-2,6,36:18.12
-1,6,36:18.12
0,6,36:18.12
1,6,36:18.12
-4,7,36:18.12
-3,7,36:18.12
-2,7,36:17.3
-1,7,36:18.12
0,7,36:18.12
-3,8,36:18.12
-2,8,36:18.12
-1,8,36:18.12
4,-9,37:18.12
5,-9,37:18.12
-5,-8,37:18.12
-4,-8,37:18.12
-3,-8,37:18.12
1,-8,37:18.12
2,-8,37:18.12
3,-8,37:18.12
4,-8,37:18.12
5,-8,37:17.3
6,-8,37:18.12
-6,-7,37:18.12
-5,-7,37:17.3
-4,-7,37:18.12
-3,-7,37:18.12
-2,-7,37:18.12
0,-7,37:18.12
1,-7,37:17.3
2,-7,37:18.12
3,-7,37:18.12
4,-7,37:18.12
5,-7,37:18.12
6,-7,37:18.12
7,-7,37:18.12
-7,-6,37:18.12
-6,-6,37:18.12
-5,-6,37:18.12
-4,-6,37:18.12
-3,-6,37:18.12
-2,-6,37:17.3
-1,-6,37:18.12
0,-6,37:18.12
1,-6,37:18.12
2,-6,37:18.12
3,-6,37:18.12
4,-6,37:18.12
5,-6,37:18.12
6,-6,37:18.12
7,-6,37:18.12
8,-6,37:18.12
-7,-5,37:18.12
-6,-5,37:17.3
-5,-5,37:17.3
-4,-5,37:18.12
-3,-5,37:18.12
-2,-5,37:18.12
-1,-5,37:18.12
2,-5,37:18.12
3,-5,37:18.12
4,-5,37:18.12
5,-5,37:18.12
6,-5,37:18.12
7,-5,37:17.3
8,-5,37:18.12
-8,-4,37:18.12
-7,-4,37:18.12
-6,-4,37:18.12
-5,-4,37:18.12
-4,-4,37:18.12
-3,-4,37:18.12
-2,-4,37:18.12
-1,-4,37:18.12
2,-4,37:18.12
3,-4,37:18.12
4,-4,37:18.12
5,-4,37:18.12
6,-4,37:18.12
7,-4,37:18.12
8,-4,37:18.12
-8,-3,37:18.12
-7,-3,37:18.12
-6,-3,37:18.12
-5,-3,37:18.12
-4,-3,37:18.12
-3,-3,37:18.12
-2,-3,37:18.12
-1,-3,37:18.12
2,-3,37:18.12
4,-3,37:18.12
5,-3,37:18.12
6,-3,37:18.12
-9,-2,37:18.12
-8,-2,37:18.12
-7,-2,37:18.12
-6,-2,37:18.12
-5,-2,37:18.12
-4,-2,37:18.12
-3,-2,37:18.12
-2,-2,37:18.12
-1,-2,37:18.12
1,-2,37:18.12
-9,-1,37:18.12
-8,-1,37:18.12
-7,-1,37:17.3
-6,-1,37:18.12
-5,-1,37:18.12
-4,-1,37:18.12
-3,-1,37:18.12
-2,-1,37:18.12
-1,-1,37:17.2
0,-1,37:18.12
1,-1,37:17.3
2,-1,37:18.12
5,-1,37:18.12
-8,0,37:18.12
-7,0,37:18.12
-6,0,37:18.12
-5,0,37:18.12
-2,0,37:17.3
-1,0,37:18.12
1,0,37:18.12
3,0,37:18.12
4,0,37:18.12
5,0,37:18.12
6,0,37:18.12
7,0,37:18.12
-8,1,37:18.12
-7,1,37:18.12
-6,1,37:18.12
-2,1,37:18.12
0,1,37:18.14
1,1,37:17.2
2,1,37:18.12
3,1,37:18.12
4,1,37:18.12
5,1,37:18.12
6,1,37:18.12
7,1,37:17.3
8,1,37:18.12
-9,2,37:18.12
-8,2,37:18.12
-7,2,37:18.12
-6,2,37:18.12
-5,2,37:18.12
-3,2,37:18.12
-2,2,37:18.12
-1,2,37:18.12
0,2,37:18.12
1,2,37:18.14
3,2,37:18.12
4,2,37:17.3
5,2,37:18.12
6,2,37:18.12
7,2,37:18.12
8,2,37:18.12
-9,3,37:18.12
-8,3,37:18.12
-7,3,37:18.12
-6,3,37:18.12
-5,3,37:18.12
-4,3,37:17.3
-3,3,37:18.12
-2,3,37:18.12
-1,3,37:18.12
0,3,37:18.12
1,3,37:18.12
2,3,37:18.12
4,3,37:18.12
5,3,37:18.12
6,3,37:18.12
7,3,37:18.12
-9,4,37:18.12
-8,4,37:18.12
-7,4,37:17.3
-6,4,37:18.12
-5,4,37:18.12
-4,4,37:18.12
-3,4,37:18.12
-2,4,37:18.12
-1,4,37:18.12
0,4,37:18.12
1,4,37:17.3
2,4,37:18.12
4,4,37:18.12
5,4,37:17.3
6,4,37:18.12
-8,5,37:18.12
-7,5,37:18.12
-6,5,37:18.12
-4,5,37:18.12
-3,5,37:18.12
-2,5,37:18.12
-1,5,37:18.12
0,5,37:18.12
1,5,37:18.12
2,5,37:18.12
4,5,37:18.12
5,5,37:18.12
-7,6,37:18.12
-6,6,37:18.12
-4,6,37:18.12
-3,6,37:17.3
-2,6,37:18.12
-1,6,37:18.12
0,6,37:17.3
1,6,37:18.12
2,6,37:18.12
-3,7,37:18.12
-2,7,37:18.12
-1,7,37:18.12
0,7,37:18.12
1,7,37:18.12
-3,8,37:18.12
-2,8,37:17.3
-1,8,37:18.12
0,8,37:18.12
4,-8,38:18.12
5,-8,38:18.12
-5,-7,38:18.12
-4,-7,38:18.12
-3,-7,38:18.12
1,-7,38:18.12
3,-7,38:18.12
4,-7,38:18.12
5,-7,38:18.12
6,-7,38:18.12
-6,-6,38:18.12
-5,-6,38:18.12
-4,-6,38:18.12
-3,-6,38:18.12
-2,-6,38:18.12
2,-6,38:18.12
3,-6,38:18.12
4,-6,38:18.12
5,-6,38:18.12
6,-6,38:18.12
7,-6,38:18.12
-7,-5,38:18.12
-6,-5,38:18.12
-5,-5,38:18.12
-4,-5,38:18.12
-3,-5,38:18.12
-2,-5,38:18.12
-1,-5,38:18.12
2,-5,38:18.12
3,-5,38:18.12
4,-5,38:18.12
5,-5,38:18.12
6,-5,38:18.12
7,-5,38:18.12
-7,-4,38:18.12
-6,-4,38:18.12
-5,-4,38:18.12
-4,-4,38:18.12
-3,-4,38:18.12
-2,-4,38:18.12
-1,-4,38:18.12
3,-4,38:18.12
4,-4,38:18.12
5,-4,38:18.12
6,-4,38:18.12
7,-4,38:18.12
-6,-3,38:18.12
-5,-3,38:18.12
-4,-3,38:18.12
-3,-3,38:18.12
-2,-3,38:18.12
-1,-3,38:18.12
4,-3,38:18.12
5,-3,38:18.12
-6,-2,38:18.12
-5,-2,38:18.12
-4,-2,38:18.12
-3,-2,38:18.12
-2,-2,38:18.12
-1,-2,38:18.12
1,-2,38:18.12
-7,-1,38:18.12
-5,-1,38:18.12
-4,-1,38:18.12
-2,-1,38:18.12
-1,-1,38:17.2
0,-1,38:18.12
1,-1,38:17.3
2,-1,38:18.12
3,-1,38:18.12
-8,0,38:18.12
-7,0,38:18.12
-6,0,38:18.12
-1,0,38:18.12
1,0,38:18.12
3,0,38:18.12
4,0,38:18.12
5,0,38:18.12
-7,1,38:18.12
-2,1,38:18.12
-1,1,38:18.12
0,1,38:18.14
1,1,38:17.2
2,1,38:18.14
3,1,38:18.12
4,1,38:18.12
5,1,38:18.12
6,1,38:18.12
7,1,38:18.12
-6,2,38:18.12
-2,2,38:18.12
-1,2,38:18.12
0,2,38:18.12
1,2,38:18.14
4,2,38:18.12
5,2,38:18.12
6,2,38:18.12
7,2,38:18.12
-8,3,38:18.12
-7,3,38:18.12
-6,3,38:18.12
-5,3,38:18.12
-4,3,38:18.12
-3,3,38:18.12
-2,3,38:18.12
-1,3,38:18.12
4,3,38:18.12
5,3,38:18.12
6,3,38:18.12
-8,4,38:18.12
-7,4,38:18.12
-6,4,38:18.12
-5,4,38:18.12
-4,4,38:18.12
-3,4,38:18.12
-2,4,38:18.12
-1,4,38:18.12
0,4,38:18.12
1,4,38:18.12
5,4,38:18.12
-8,5,38:18.12
-7,5,38:18.12
-6,5,38:18.12
-3,5,38:18.12
-2,5,38:18.12
-1,5,38:18.12
0,5,38:18.12
1,5,38:18.12
-7,6,38:18.12
-6,6,38:18.12
-3,6,38:18.12
-2,6,38:18.12
-1,6,38:18.12
0,6,38:18.12
1,6,38:18.12
-1,7,38:18.12
0,7,38:18.12
-2,8,38:18.12
-4,-7,39:18.12
5,-7,39:18.12
-5,-6,39:18.12
-4,-6,39:18.12
-3,-6,39:18.12
4,-6,39:18.12
5,-6,39:18.12
6,-6,39:18.4
-6,-5,39:18.4
-5,-5,39:18.12
-4,-5,39:18.12
-3,-5,39:18.12
-2,-5,39:18.12
3,-5,39:18.12
4,-5,39:18.12
5,-5,39:18.12
6,-5,39:18.12
-5,-4,39:18.12
-4,-4,39:18.12
-3,-4,39:18.12
4,-4,39:18.12
5,-4,39:18.12
-4,-3,39:18.12
-2,-2,39:18.12
1,-1,39:18.12
2,-1,39:18.12
-7,0,39:18.12
5,1,39:18.12
4,2,39:18.12
5,2,39:18.12
-7,3,39:18.12
-6,3,39:18.4
-2,3,39:18.12
-8,4,39:18.12
-7,4,39:18.12
-6,4,39:18.12
-2,4,39:18.12
-1,4,39:18.12
-7,5,39:18.12
-6,5,39:18.12
-2,5,39:18.12
-1,5,39:18.12
0,5,39:18.12
4,-5,40:18.12
5,-5,40:18.12
5,-4,40:18.12
-1,4,40:18.12
-3,-6,35:106.2
-3,-7,35:106.0
-4,-7,35:106.1
7,3,34:106.2
-2,3,34:106.2
-4,3,34:106.8
-1,2,34:106.4
5,0,34:106.4
4,-5,34:106.8
3,-5,34:106.0
2,-5,34:106.0
3,-6,34:106.0
-3,-6,34:106.2
-4,-7,34:106.1
6,4,33:106.4
7,3,33:106.2
1,3,33:106.4
-2,3,33:106.2
-4,3,33:106.8
-1,2,33:106.4
5,0,33:106.4
4,-5,33:106.8
-3,-6,33:106.2
-4,-7,33:106.1
6,4,32:106.4
7,3,32:106.2
1,3,32:106.4
-2,3,32:106.2
-4,3,32:106.8
-1,2,32:106.4
5,0,32:106.4
5,-4,32:106.4
4,-5,32:106.8
-3,-6,32:106.2
-4,-7,32:106.1
6,4,31:106.4
7,3,31:106.2
1,3,31:106.4
-2,3,31:106.2
-4,3,31:106.8
-1,2,31:106.4
5,0,31:106.4
5,-4,31:106.4
4,-5,31:106.8
-3,-6,31:106.2
-5,-6,31:106.8
-4,-7,31:106.1
6,4,30:106.4
7,3,30:106.2
1,3,30:106.4
-2,3,30:106.2
-4,3,30:106.8
-1,2,30:106.4
5,0,30:106.4
-2,-1,30:106.8
-1,-2,30:106.1
6,-4,30:106.4
5,-4,30:106.4
4,-5,30:106.8
-3,-6,30:106.2
-5,-6,30:106.8
-4,-7,30:106.1
6,4,29:106.4
7,3,29:106.2
1,3,29:106.4
-2,3,29:106.2
-4,3,29:106.8
-1,2,29:106.4
5,0,29:106.4
-2,-1,29:106.8
-1,-3,29:106.8
0,-4,29:106.1
-3,-6,29:106.2
-5,-6,29:106.8
-4,-7,29:106.1
6,4,28:106.4
7,3,28:106.2
1,3,28:106.4
-2,3,28:106.2
-4,3,28:106.8
-1,2,28:106.4
5,0,28:106.4
-1,-3,28:106.8
0,-4,28:106.1
-3,-6,28:106.2
-5,-6,28:106.8
-4,-7,28:106.1
6,4,27:106.4
7,3,27:106.2
1,3,27:106.4
-2,3,27:106.2
-4,3,27:106.8
0,2,27:106.4
-1,2,27:106.4
5,0,27:106.4
-1,-3,27:106.8
0,-4,27:106.1
7,-6,27:106.2
5,-6,27:106.8
-3,-6,27:106.2
-5,-6,27:106.8
6,-7,27:106.1
-4,-7,27:106.1
6,4,26:106.4
7,3,26:106.2
1,3,26:106.4
-2,3,26:106.2
-4,3,26:106.8
0,2,26:106.4
-1,2,26:106.4
5,0,26:106.4
-1,-3,26:106.8
0,-4,26:106.1
7,-6,26:106.2
5,-6,26:106.8
-3,-6,26:106.2
-5,-6,26:106.8
6,-7,26:106.1
-4,-7,26:106.1
6,4,25:106.4
7,3,25:106.2
1,3,25:106.4
0,2,25:106.4
-1,2,25:106.4
5,0,25:106.4
-1,-3,25:106.8
0,-4,25:106.1
7,-6,25:106.2
5,-6,25:106.8
-3,-6,25:106.2
-5,-6,25:106.8
6,-7,25:106.1
-4,-7,25:106.1
6,4,24:106.4
7,3,24:106.2
1,3,24:106.4
0,2,24:106.4
5,0,24:106.4
0,-4,24:106.1
7,-6,24:106.2
5,-6,24:106.8
-3,-6,24:106.2
-5,-6,24:106.8
6,-7,24:106.1
-4,-7,24:106.1
6,4,23:106.4
7,3,23:106.2
1,3,23:106.4
0,2,23:106.4
5,0,23:106.4
2,0,23:106.2
0,-4,23:106.1
7,-6,23:106.2
5,-6,23:106.8
-3,-6,23:106.2
-5,-6,23:106.8
6,-7,23:106.1
-4,-7,23:106.1
6,4,22:106.4
7,3,22:106.2
1,3,22:106.4
0,2,22:106.4
5,0,22:106.4
2,0,22:106.2
2,-3,22:106.2
7,-6,22:106.2
5,-6,22:106.8
-3,-6,22:106.2
-5,-6,22:106.8
6,-7,22:106.1
-4,-7,22:106.1
6,4,21:106.4
7,3,21:106.2
1,3,21:106.4
0,2,21:106.4
-3,2,21:106.8
2,0,21:106.2
2,-1,21:106.4
2,-3,21:106.2
7,-6,21:106.2
5,-6,21:106.8
-3,-6,21:106.2
-5,-6,21:106.8
6,-7,21:106.1
-4,-7,21:106.1
7,3,20:106.2
1,3,20:106.4
0,2,20:106.4
-3,2,20:106.8
2,0,20:106.2
-1,0,20:106.8
2,-1,20:106.4
-2,-2,20:106.8
2,-3,20:106.2
7,-6,20:106.2
5,-6,20:106.8
-3,-6,20:106.2
-5,-6,20:106.8
6,-7,20:106.1
-4,-7,20:106.1
1,3,19:106.4
0,2,19:106.4
-3,2,19:106.8
2,0,19:106.2
2,-1,19:106.4
-2,-2,19:106.8
2,-3,19:106.2
-1,-4,19:106.1
7,-6,19:106.2
5,-6,19:106.8
-3,-6,19:106.2
-5,-6,19:106.8
6,-7,19:106.1
-4,-7,19:106.1
1,3,18:106.4
0,2,18:106.4
-3,2,18:106.8
2,-1,18:106.4
-2,-2,18:106.8
2,-3,18:106.2
-1,-4,18:106.1
7,-6,18:106.2
5,-6,18:106.8
-3,-6,18:106.2
-5,-6,18:106.8
6,-7,18:106.1
-4,-7,18:106.1
0,2,17:106.4
-3,2,17:106.8
0,1,17:106.4
2,-1,17:106.4
-2,-2,17:106.8
-1,-4,17:106.1
7,-6,17:106.2
-3,-6,17:106.2
-5,-6,17:106.8
6,-7,17:106.1
-4,-7,17:106.1
0,2,16:106.4
-3,2,16:106.8
0,1,16:106.4
-1,0,16:106.8
7,-6,16:106.2
-3,-6,16:106.2
-5,-6,16:106.8
6,-7,16:106.1
-4,-7,16:106.1
0,2,15:106.4
-3,2,15:106.8
0,1,15:106.4
2,0,15:106.2
-1,0,15:106.8
7,-6,15:106.2
-3,-6,15:106.2
-5,-6,15:106.8
-4,-7,15:106.1
3,5,14:106.4
0,2,14:106.4
-3,2,14:106.8
0,1,14:106.4
-1,0,14:106.8
-3,-6,14:106.2
-5,-6,14:106.8
-4,-7,14:106.1
3,5,13:106.4
0,2,13:106.4
-3,2,13:106.8
-3,-6,13:106.2
-5,-6,13:106.8
-4,-7,13:106.1
3,5,12:106.4
0,2,12:106.4
-3,2,12:106.8
-3,-6,12:106.2
-5,-6,12:106.8
-4,-7,12:106.1
3,5,11:106.4
0,2,11:106.4
-3,2,11:106.8
-1,1,11:106.4
-2,0,11:106.8
2,-1,11:106.2
3,-2,11:106.2
2,-4,11:106.1
1,-5,11:106.1
-3,-6,11:106.2
-5,-6,11:106.8
-4,-7,11:106.1
3,5,10:106.4
0,2,10:106.4
-3,2,10:106.8
2,1,10:106.4
-2,0,10:106.8
2,-1,10:106.2
3,-2,10:106.2
2,-4,10:106.1
1,-5,10:106.1
-3,-6,10:106.2
-4,-7,10:106.1
3,5,9:106.4
-3,2,9:106.8
3,-2,9:106.2
-3,-2,9:106.8
-3,-6,9:106.2
-4,-7,9:106.1
3,5,8:106.4
1,3,8:106.4
-3,2,8:106.8
-3,-2,8:106.8
-3,-6,8:106.2
-4,-7,8:106.1
3,3,7:106.4
4,2,7:106.2
-3,2,7:106.8
-3,-6,7:106.2
-4,-7,7:106.1
-3,2,6:106.8
-3,-6,6:106.2
-4,-7,6:106.1
-3,2,5:106.8
-3,-6,5:106.2
-3,2,4:106.8
-3,-6,4:106.2
-3,2,3:106.8
-3,-6,3:106.2
-4,7,2:106.4
-5,7,2:106.4
-3,6,2:106.2
-4,5,2:106.1
1,3,2:106.4
-3,2,2:106.8
6,-1,2:106.4
5,-1,2:106.4
-6,-1,2:106.4
-5,-2,2:106.2
6,-3,2:106.1
5,-3,2:106.1
-6,-3,2:106.1
5,-6,2:106.4
-3,-6,2:106.2
4,-7,2:106.4
-3,-7,2:106.2
-5,-7,2:106.8
-4,-8,2:106.1
-3,6,1:106.2
-4,5,1:106.1
-3,2,1:106.8
6,-1,1:106.4
-5,-2,1:106.2
6,-3,1:106.1
5,-3,1:106.1
-6,-3,1:106.1
4,-7,1:106.4
0,-7,1:106.1
-3,-7,1:106.2
-5,-7,1:106.8
-4,-8,1:106.1
-3,5,0:31.1
-4,5,0:31.1
5,4,0:31.1
4,4,0:31.2
-1,4,0:31.2
-2,4,0:31.1
-3,4,0:31.1
-4,4,0:31.1
5,3,0:31.1
4,3,0:31.1
3,3,0:31.1
-2,3,0:31.1
-3,3,0:31.1
-4,3,0:31.2
6,2,0:31.1
5,2,0:31.2
4,2,0:31.1
-3,2,0:31.1
-4,1,0:31.1
5,0,0:31.1
4,0,0:38.0
-5,0,0:31.1
-6,0,0:31.1
6,-1,0:31.2
5,-1,0:31.1
-6,-1,0:31.2
6,-2,0:31.1
5,-2,0:31.1
4,-2,0:31.1
-5,-2,0:31.1
-6,-2,0:31.1
6,-3,0:106.1
5,-3,0:31.1
4,-3,0:31.1
-4,-3,0:38.0
-5,-3,0:31.2
-6,-3,0:106.1
4,-4,0:31.1
-4,-4,0:31.1
-5,-4,0:31.2
-6,-4,0:31.1
4,-5,0:31.1
3,-5,0:38.0
-3,-5,0:31.1
-4,-5,0:31.1
-5,-5,0:31.1
5,-6,0:31.1
4,-6,0:31.2
-1,-6,0:31.1
-2,-6,0:31.1
-3,-6,0:31.1
4,-7,0:31.1
1,-7,0:31.1
0,-7,0:106.1
-1,-7,0:31.1
-2,-7,0:31.2
-3,-7,0:106.2
-4,-7,0:31.2
-5,-7,0:31.1
1,-8,0:31.2
-1,-8,0:31.1
-5,-8,0:31.1
