[META]
version=2.0
spawnOnBlockType=2,12
spawnSunlight=True
spawnDarkness=True
spawnWater=False
spawnLava=False
underFill=False
randomRotation=True
dig=True
tree=True
branch=False
needsFoundation=True
rarity=25
collisionPercentage=0
spawnElevationMin=0
spawnElevationMax=245
spawnInBiome=Plains
[DATA]
0,0,0:17.0
0,-1,0:31.1
-1,0,0:31.1
0,1,0:31.1
1,0,0:31.1
-1,-2,0:31.1
2,-1,0:31.1
-2,2,0:31.1
0,0,1:17.0
0,0,2:17.0
0,0,3:17.0
0,0,4:17.0
0,-1,4:17.0
0,0,5:17.0
0,-2,5:17.0
-1,1,5:17.0
1,1,5:17.0
0,0,6:17.0
-1,-1,6:17.0
1,-1,6:17.0
1,1,6:17.0
-2,1,6:17.0
-1,2,6:17.0
2,2,6:17.0
0,-3,6:17.0
-3,2,6:18.0
-3,3,6:18.0
-2,3,6:18.0
-1,3,6:18.0
0,4,6:18.0
1,4,6:18.0
2,3,6:18.0
3,3,6:18.0
3,2,6:18.0
4,1,6:18.0
4,0,6:18.0
4,-1,6:18.0
4,-2,6:18.0
3,-3,6:18.0
2,-4,6:18.0
1,-4,6:18.0
0,-4,6:18.0
-1,-3,6:18.0
-2,-3,6:18.0
-3,-2,6:18.0
-3,-1,6:18.0
-3,0,6:18.0
-4,-1,6:18.0
-4,0,6:18.0
-4,1,6:18.0
0,0,7:17.0
1,-1,7:17.0
2,0,7:17.0
3,0,7:17.0
2,-2,7:17.0
1,-3,7:17.0
3,2,7:17.0
2,3,7:17.0
1,3,7:17.0
0,2,7:17.0
-3,2,7:17.0
-3,1,7:17.0
-2,-1,7:17.0
-2,-2,7:17.0
-2,-3,7:17.0
-1,-3,7:17.0
-1,-1,7:18.0
-1,0,7:18.0
-2,0,7:18.0
-4,2,7:18.0
-4,1,7:18.0
-5,1,7:18.0
-5,2,7:18.0
-3,3,7:18.0
-4,3,7:18.0
-2,3,7:18.0
-1,2,7:18.0
0,3,7:18.0
-3,4,7:18.0
-2,4,7:18.0
-1,4,7:18.0
0,4,7:18.0
1,4,7:18.0
2,4,7:18.0
-1,5,7:18.0
0,5,7:18.0
1,5,7:18.0
3,4,7:18.0
3,3,7:18.0
4,2,7:18.0
5,2,7:18.0
4,0,7:18.0
5,0,7:18.0
5,1,7:18.0
4,1,7:18.0
4,-1,7:18.0
5,-1,7:18.0
4,-2,7:18.0
4,-3,7:18.0
3,-3,7:18.0
3,-2,7:18.0
3,-4,7:18.0
2,-4,7:18.0
1,-4,7:18.0
1,-5,7:18.0
0,-5,7:18.0
-1,-5,7:18.0
-1,-4,7:18.0
-2,-4,7:18.0
-3,-4,7:18.0
-3,0,7:18.0
-3,-1,7:18.0
-3,-2,7:18.0
-3,-3,7:18.0
-4,-2,7:18.0
-4,-1,7:18.0
-4,0,7:18.0
-5,-1,7:18.0
-5,0,7:18.0
0,0,8:17.0
0,-2,8:18.0
0,-3,8:18.0
0,-4,8:18.0
-1,0,8:18.0
-2,0,8:18.0
-4,0,8:18.0
-4,-1,8:18.0
-4,1,8:18.0
1,-3,8:18.0
2,-3,8:18.0
2,-2,8:18.0
3,-2,8:18.0
3,-1,8:18.0
1,-2,8:18.0
1,-1,8:18.0
2,-1,8:18.0
1,0,8:18.0
2,0,8:18.0
3,0,8:18.0
4,0,8:18.0
4,1,8:18.0
4,2,8:18.0
3,3,8:18.0
3,2,8:18.0
3,1,8:18.0
0,-1,8:17.0
-3,0,8:17.0
0,3,8:17.0
2,1,8:17.0
2,3,8:18.0
2,2,8:18.0
1,4,8:18.0
1,3,8:18.0
1,2,8:18.0
1,1,8:18.0
0,1,8:18.0
0,2,8:18.0
0,4,8:18.0
-1,4,8:18.0
-2,4,8:18.0
-3,3,8:18.0
-3,2,8:18.0
-2,2,8:18.0
-2,1,8:18.0
-3,1,8:18.0
-1,1,8:18.0
-1,2,8:18.0
-1,3,8:18.0
-2,3,8:18.0
-3,-1,8:18.0
-2,-1,8:18.0
-1,-1,8:18.0
-1,-3,8:18.0
-2,-3,8:18.0
-1,-2,8:18.0
-2,-2,8:18.0
-3,-2,8:18.0
0,0,9:18.0
1,0,9:18.0
1,-1,9:18.0
0,-1,9:18.0
0,-2,9:18.0
-1,-1,9:18.0
-1,0,9:18.0
-2,0,9:18.0
-3,0,9:18.0
-2,1,9:18.0
-1,1,9:18.0
0,1,9:18.0
1,1,9:18.0
2,1,9:18.0
1,2,9:18.0
0,2,9:18.0
-1,2,9:18.0
0,3,9:18.0
