[META]
version=2.0
spawnOnBlockType=1,2,3,12
spawnSunlight=True
spawnDarkness=True
spawnWater=False
spawnLava=False
underFill=True
randomRotation=True
dig=True
tree=False
branch=False
needsFoundation=True
rarity=40
collisionPercentage=0
spawnElevationMin=0
spawnElevationMax=128
spawnInBiome=Grassland
[DATA]
0,-3,0:17.0
-2,-2,0:17.0
-1,-2,0:17.0
0,-2,0:17.0
1,-2,0:17.0
-4,-1,0:17.0
-3,-1,0:17.0
-2,-1,0:17.0
-1,-1,0:17.0
0,-1,0:17.0
1,-1,0:17.0
-1,0,0:17.0
0,0,0:17.0
1,0,0:17.0
2,0,0:17.0
0,1,0:17.0
2,1,0:17.0
-1,-2,1:17.0
0,-2,1:17.0
-2,-1,1:17.0
-1,-1,1:17.0
0,-1,1:17.0
1,-1,1:17.0
-1,0,1:17.0
0,0,1:17.0
-1,-1,2:17.0
0,-1,2:17.0
-1,0,2:17.0
0,0,2:17.0
1,-7,3:18
0,-6,3:18
1,-6,3:18
2,-6,3:18
-2,-5,3:18
-1,-5,3:18
0,-5,3:17.0
1,-5,3:17.0
2,-5,3:17.0
3,-5,3:18
0,-4,3:17.0
1,-4,3:17.0
2,-4,3:18
-2,-3,3:30
-1,-3,3:17.0
0,-3,3:17.0
1,-3,3:18
-2,-2,3:18
-1,-2,3:17.0
0,-2,3:17.0
1,-2,3:18
-3,-1,3:18
-2,-1,3:18
-1,-1,3:17.0
0,-1,3:17.0
-1,0,3:17.0
0,0,3:17.0
1,-6,4:18
2,-6,4:18
-2,-5,4:18
0,-5,4:18
1,-5,4:18
2,-5,4:18
3,-5,4:18
-2,-4,4:18
-1,-4,4:18
0,-4,4:18
1,-4,4:18
-1,-3,4:18
0,-3,4:18
1,-3,4:18
0,-2,4:18
1,-2,4:18
-3,-1,4:30
-2,-1,4:18
-1,-1,4:17.0
0,-1,4:17.0
-3,0,4:18
-2,0,4:18
-1,0,4:17.0
0,0,4:17.0
-3,1,4:18
-2,1,4:18
-1,1,4:30
0,1,4:18
-5,2,4:18
-4,2,4:18
-3,2,4:18
0,2,4:18
-4,3,4:18
0,3,4:18
-5,4,4:18
-4,4,4:18
3,4,4:18
4,4,4:18
1,-6,5:18
1,-5,5:18
2,-5,5:30
1,-4,5:18
2,-4,5:18
3,-4,5:18
-5,-3,5:18
-4,-3,5:18
2,-3,5:18
3,-3,5:18
4,-3,5:18
-3,-2,5:18
-2,-2,5:18
1,-2,5:17.0
2,-2,5:17.0
3,-2,5:17.0
4,-2,5:17.0
5,-2,5:18
-4,-1,5:18
-3,-1,5:18
-2,-1,5:18
-1,-1,5:17.0
0,-1,5:17.0
1,-1,5:17.0
2,-1,5:17.0
3,-1,5:18
4,-1,5:18
-6,0,5:18
-4,0,5:18
-3,0,5:18
-2,0,5:17.0
-1,0,5:17.0
0,0,5:17.0
1,0,5:17.0
2,0,5:18
-6,1,5:18
-5,1,5:18
-4,1,5:17.0
-3,1,5:17.0
-2,1,5:17.0
-1,1,5:18
0,1,5:18
1,1,5:17.0
2,1,5:17.0
3,1,5:18
4,1,5:18
-6,2,5:18
-5,2,5:17.0
-4,2,5:17.0
-3,2,5:17.0
-2,2,5:18
-1,2,5:18
1,2,5:17.0
2,2,5:17.0
3,2,5:17.0
4,2,5:18
-5,3,5:18
-4,3,5:18
-3,3,5:18
-1,3,5:18
0,3,5:18
1,3,5:18
2,3,5:18
3,3,5:17.0
4,3,5:18
1,4,5:18
2,4,5:30
3,4,5:17.0
4,4,5:18
-4,-5,6:18
1,-5,6:18
-5,-4,6:18
-4,-4,6:17.0
-3,-4,6:18
-2,-4,6:18
0,-4,6:18
1,-4,6:18
2,-4,6:18
-5,-3,6:30
-4,-3,6:17.0
-3,-3,6:17.0
-2,-3,6:18
-1,-3,6:18
0,-3,6:17.0
3,-3,6:17.0
4,-3,6:18
-4,-2,6:18
-3,-2,6:17.0
-2,-2,6:17.0
-1,-2,6:17.0
0,-2,6:17.0
1,-2,6:17.0
2,-2,6:18
3,-2,6:18
4,-2,6:18
5,-2,6:18
-4,-1,6:18
-3,-1,6:17.0
-2,-1,6:18
-1,-1,6:17.0
0,-1,6:17.0
1,-1,6:17.0
2,-1,6:18
3,-1,6:18
-4,0,6:18
-3,0,6:18
-2,0,6:18
-1,0,6:17.0
0,0,6:17.0
1,0,6:30
2,0,6:18
-5,1,6:18
-4,1,6:18
-3,1,6:18
-2,1,6:18
-1,1,6:18
0,1,6:18
2,1,6:18
3,1,6:18
-5,2,6:18
-4,2,6:18
-3,2,6:18
-2,2,6:18
0,2,6:18
1,2,6:18
2,2,6:91.0
3,2,6:18
4,2,6:18
-2,3,6:18
1,3,6:18
3,3,6:18
3,4,6:18
0,-6,7:18
-1,-5,7:18
0,-5,7:18
2,-5,7:18
-4,-4,7:18
-1,-4,7:18
0,-4,7:17.0
1,-4,7:17.0
2,-4,7:18
-4,-3,7:18
-3,-3,7:18
-1,-3,7:18
0,-3,7:17.0
1,-3,7:18
2,-3,7:18
3,-3,7:91.3
4,-3,7:30
-3,-2,7:18
-2,-2,7:18
-1,-2,7:17.0
1,-2,7:18
2,-2,7:18
5,-2,7:18
-3,-1,7:91.1
-2,-1,7:18
-1,-1,7:17.0
0,-1,7:17.0
1,-1,7:91.0
-3,0,7:18
-2,0,7:18
-1,0,7:17.0
0,0,7:17.0
2,0,7:18
-3,1,7:18
-2,1,7:18
-1,1,7:18
-5,2,7:18
-4,2,7:18
-3,2,7:18
-1,2,7:18
0,2,7:18
4,2,7:18
-1,3,7:18
0,3,7:18
0,-5,8:18
1,-5,8:18
0,-4,8:18
1,-4,8:18
2,-4,8:18
3,-4,8:18
0,-3,8:91.2
2,-3,8:18
-2,-2,8:18
-1,-2,8:18
1,-2,8:18
2,-2,8:18
-3,-1,8:18
-2,-1,8:18
-1,-1,8:17.0
0,-1,8:17.0
1,-1,8:17.0
2,-1,8:17.0
3,-1,8:18
-3,0,8:18
-2,0,8:18
-1,0,8:17.0
0,0,8:17.0
1,0,8:17.0
2,0,8:17.0
3,0,8:17.0
4,0,8:18
5,0,8:18
-3,1,8:18
-2,1,8:18
-1,1,8:17.0
0,1,8:17.0
1,1,8:17.0
2,1,8:18
3,1,8:17.0
4,1,8:17.0
5,1,8:17.0
-3,2,8:18
-2,2,8:18
-1,2,8:17.0
0,2,8:17.0
3,2,8:18
4,2,8:17.0
5,2,8:18
-3,3,8:18
-2,3,8:17.0
-1,3,8:17.0
0,3,8:18
1,3,8:18
2,3,8:18
3,3,8:18
5,3,8:18
-3,4,8:18
-2,4,8:17.0
-1,4,8:18
0,4,8:18
5,4,8:18
-3,5,8:18
-2,5,8:18
0,-5,9:18
1,-5,9:18
-2,-4,9:18
-1,-4,9:18
0,-4,9:17.0
1,-4,9:18
-3,-3,9:18
-2,-3,9:17.0
-1,-3,9:17.0
0,-3,9:17.0
1,-3,9:18
-5,-2,9:18
-4,-2,9:18
-3,-2,9:18
-2,-2,9:18
-1,-2,9:17.0
0,-2,9:18
1,-2,9:18
2,-2,9:18
-6,-1,9:18
-5,-1,9:17.0
-4,-1,9:17.0
-3,-1,9:17.0
-2,-1,9:17.0
-1,-1,9:17.0
0,-1,9:17.0
1,-1,9:18
2,-1,9:18
3,-1,9:18
4,-1,9:18
-5,0,9:18
-4,0,9:18
-3,0,9:18
-2,0,9:17.0
0,0,9:17.0
1,0,9:18
2,0,9:18
3,0,9:18
4,0,9:30
0,1,9:18
1,1,9:91.3
3,1,9:18
4,1,9:18
5,1,9:18
-1,2,9:91.1
0,2,9:18
1,2,9:18
2,2,9:18
4,2,9:18
-1,3,9:18
0,3,9:18
-2,4,9:17.0
-1,4,9:18
0,4,9:18
-3,5,9:18
-2,5,9:18
-1,5,9:18
0,5,9:18
-1,6,9:18
0,-4,10:18
-2,-3,10:18
-1,-3,10:18
0,-3,10:18
-5,-2,10:18
-2,-2,10:18
0,-2,10:18
-6,-1,10:18
-5,-1,10:18
-4,-1,10:18
-3,-1,10:18
-2,-1,10:17.0
-1,-1,10:17.0
0,-1,10:18
-4,0,10:30
-3,0,10:18
-2,0,10:18
-1,0,10:17.0
0,0,10:17.0
-1,1,10:17.0
0,1,10:18
2,2,10:18
0,3,10:18
-1,-2,11:18
-2,-1,11:18
-1,-1,11:18
0,-1,11:18
-3,0,11:18
-2,0,11:18
-1,0,11:17.0
0,0,11:17.0
1,0,11:18
-4,1,11:18
-3,1,11:18
-2,1,11:17.0
-1,1,11:17.0
0,1,11:18
-5,2,11:18
-4,2,11:17.0
-3,2,11:17.0
-2,2,11:17.0
-1,2,11:17.0
-5,3,11:18
-3,3,11:18
-2,3,11:18
-1,3,11:17.0
-1,-2,12:18
-1,0,12:18
0,0,12:30
1,0,12:18
-2,1,12:18
-1,1,12:18
0,1,12:18
-4,2,12:18
-3,2,12:18
-2,2,12:18
-1,2,12:18
0,2,12:18
-4,3,12:18
-3,3,12:18
-1,3,12:18
-1,0,13:18
