[META]
version=2.0
spawnOnBlockType=1,2,3,12
spawnSunlight=True
spawnDarkness=True
spawnWater=False
spawnLava=False
underFill=True
randomRotation=True
dig=True
tree=False
branch=False
needsFoundation=True
rarity=40
collisionPercentage=0
spawnElevationMin=0
spawnElevationMax=128
spawnInBiome=Grassland,Extreme Hills Edge2
[DATA]
-2,-2,0:17.3
-1,-2,0:17.3
-2,-1,0:17.3
-2,-2,1:17.3
-2,-2,2:17.3
-2,-2,3:17.3
-2,-2,4:17.3
-1,-2,4:17.3
-1,-2,5:17.3
-1,-2,6:17.3
0,-2,6:17.3
0,-1,6:91.0
-1,-3,7:91.2
-1,-2,7:18
0,-2,7:17.3
1,-2,7:91.3
-1,-1,7:91.1
0,-1,7:18
1,-1,7:18
0,0,7:18
0,-4,8:106.1
1,-4,8:18
2,-4,8:18
-1,-3,8:106.8
0,-3,8:18
1,-3,8:18
2,-3,8:18
-1,-2,8:18
0,-2,8:17.3
1,-2,8:17.3
2,-2,8:18
3,-2,8:18
-2,-1,8:18
-1,-1,8:18
0,-1,8:18
1,-1,8:18
2,-1,8:18
-1,0,8:18
0,0,8:18
1,0,8:18
2,0,8:18
3,0,8:18
4,0,8:106.2
0,1,8:18
0,-2,9:18
1,-2,9:18
