[META]
version=2.0
spawnOnBlockType=1,2,3,12
spawnSunlight=True
spawnDarkness=True
spawnWater=False
spawnLava=False
underFill=True
randomRotation=True
dig=True
tree=False
branch=False
needsFoundation=True
rarity=30
collisionPercentage=0
spawnElevationMin=0
spawnElevationMax=128
spawnInBiome=Grassland
[DATA]
0,-1,0:39
-1,0,0:39
0,0,0:17.1
1,0,0:30
-1,1,0:40
0,1,0:17.1
0,0,1:17.1
1,0,1:17.1
0,1,1:17.1
-1,-3,2:18
0,-3,2:18
-2,-2,2:18
-1,-2,2:18
0,-2,2:18
1,-2,2:18
2,-2,2:18
-1,-1,2:18
0,-1,2:18
1,-1,2:18
-2,0,2:18
-1,0,2:18
0,0,2:17.1
1,0,2:18
2,0,2:18
3,0,2:18
-2,1,2:18
-1,1,2:18
0,1,2:18
1,1,2:18
2,1,2:18
-2,2,2:18
-1,2,2:18
0,2,2:18
1,2,2:18
2,2,2:18
-1,3,2:18
1,3,2:18
1,-3,3:18
-2,-2,3:18
0,-2,3:18
1,-2,3:18
2,-2,3:18
-1,-1,3:18
0,-1,3:18
-3,0,3:18
-2,0,3:18
0,0,3:17.1
2,0,3:18
3,0,3:30
-3,1,3:18
-2,1,3:18
-1,1,3:18
0,1,3:17.1
2,1,3:18
-2,2,3:30
0,2,3:18
0,0,4:17.1
0,1,4:91.0
0,-3,5:18
-1,-2,5:18
0,-2,5:18
1,-2,5:18
-2,-1,5:18
-1,-1,5:18
0,-1,5:17.1
1,-1,5:18
2,-1,5:18
-3,0,5:18
-2,0,5:18
-1,0,5:18
0,0,5:17.1
1,0,5:17.1
2,0,5:18
3,0,5:18
-2,1,5:18
-1,1,5:18
0,1,5:18
1,1,5:17.1
2,1,5:18
3,1,5:18
-1,2,5:18
0,2,5:18
1,2,5:18
2,2,5:18
0,3,5:18
-1,-2,6:18
0,-2,6:18
-2,-1,6:18
-1,-1,6:30
0,-1,6:91.2
0,0,6:17.1
1,0,6:17.1
1,1,6:30
0,0,7:17.1
1,0,7:18
0,-2,8:18
-2,-1,8:18
-1,-1,8:18
0,-1,8:18
1,-1,8:18
-2,0,8:18
-1,0,8:18
0,0,8:17.1
1,0,8:18
2,0,8:18
-1,1,8:18
0,1,8:17.1
1,1,8:18
0,2,8:18
0,-1,9:18
0,0,9:91.1
1,0,9:18
0,1,9:18
0,2,9:30
0,0,10:18
