[META]
version=2.0
spawnOnBlockType=1,2,3,12
spawnSunlight=True
spawnDarkness=True
spawnWater=False
spawnLava=False
underFill=True
randomRotation=True
dig=True
tree=False
branch=False
needsFoundation=True
rarity=30
collisionPercentage=0
spawnElevationMin=0
spawnElevationMax=240
spawnInBiome=Grassland
[DATA]
0,-1,0:17.0
-1,0,0:17.0
0,0,0:17.0
1,0,0:30
2,0,0:17.0
-2,1,0:17.0
-1,1,0:17.0
0,1,0:17.0
1,1,0:17.0
2,1,0:30
-1,2,0:17.0
0,2,0:17.0
1,2,0:17.0
-2,3,0:17.0
-1,3,0:17.0
0,3,0:30
1,3,0:17.0
-1,1,1:17.0
0,1,1:17.0
1,1,1:17.0
-1,2,1:17.0
-1,0,2:17.0
-1,1,2:17.0
0,1,2:17.0
-1,0,3:17.0
0,0,3:86.3
-1,1,3:18
0,1,3:17.0
-1,-1,4:18
-2,0,4:18
-1,0,4:17.0
0,0,4:18
-2,1,4:18
-1,1,4:18
0,1,4:18
-2,-1,5:18
-1,-1,5:18
-1,0,5:17.0
0,0,5:30
-1,1,5:17.0
0,1,5:17.0
-2,2,5:18
-1,2,5:18
0,-1,6:18
1,-1,6:18
-2,0,6:18
-1,0,6:18
1,0,6:18
-1,1,6:18
0,1,6:17.0
0,2,6:18
0,3,6:18
0,-2,7:18
1,-2,7:18
-1,-1,7:18
0,-1,7:17.0
1,-1,7:17.0
2,-1,7:18
1,0,7:17.0
2,0,7:18
-1,1,7:18
0,1,7:86.3
1,1,7:17.0
2,1,7:18
0,2,7:18
0,4,7:91.0
-2,-2,8:30
-1,-2,8:18
0,-2,8:30
-2,-1,8:18
-1,-1,8:17.0
0,-1,8:18
1,-1,8:18
2,-1,8:18
-2,0,8:18
2,0,8:18
1,1,8:18
0,4,8:30
-2,-2,9:18
-3,-1,9:18
-2,-1,9:17.0
-3,0,9:18
-2,0,9:17.0
0,4,9:30
-2,-1,10:18
-3,0,10:30
-2,0,10:18
0,0,10:17.0
1,0,10:18
-3,1,10:18
-2,1,10:17.0
-1,1,10:17.0
0,1,10:18
-2,2,10:18
-1,2,10:18
0,4,10:30
0,-3,11:30
0,-2,11:18
-2,-1,11:18
-1,-1,11:18
0,-1,11:17.0
1,-1,11:18
2,-1,11:18
-3,0,11:18
-2,0,11:17.0
-1,0,11:18
0,0,11:17.0
1,0,11:17.0
2,0,11:17.0
3,0,11:18
-2,1,11:18
-1,1,11:18
0,1,11:17.0
1,1,11:18
-1,2,11:18
0,2,11:17.0
1,2,11:18
0,3,11:18
1,3,11:18
0,4,11:18
0,-3,12:18
-1,-2,12:18
0,-2,12:17.0
1,-2,12:18
-2,0,12:18
0,0,12:18
1,0,12:18
2,0,12:18
-1,1,12:18
0,1,12:18
1,1,12:18
0,2,12:18
1,3,12:18
0,-2,13:18
0,1,13:18
