[META]
version=2.0
spawnOnBlockType=87
spawnSunlight=True
spawnDarkness=True
spawnWater=False
spawnLava=False
underFill=True
randomRotation=True
dig=True
tree=True
branch=False
needsFoundation=True
rarity=12
collisionPercentage=0
spawnElevationMin=0
spawnElevationMax=100
spawnInBiome=Hell
[DATA]
0,0,0:17.0
0,-1,0:17.0
0,1,0:17.0
-1,0,0:17.0
1,0,0:17.0
-1,-1,0:17.0
1,1,0:17.0
1,-1,0:17.0
-1,1,0:17.0
0,-2,0:17.0
-2,0,0:17.0
2,0,0:17.0
0,2,0:17.0
-1,0,1:17.0
0,-1,1:17.0
0,0,1:17.0
0,1,1:17.0
1,0,1:17.0
0,-2,1:17.0
-2,0,1:17.0
0,2,1:17.0
2,0,1:17.0
-1,0,2:17.0
0,-1,2:17.0
1,0,2:17.0
0,1,2:17.0
0,0,2:17.0
-1,0,3:17.0
0,0,3:17.0
0,-1,3:17.0
0,1,3:17.0
1,0,3:17.0
-1,0,4:17.0
0,0,4:17.0
0,-1,4:17.0
1,0,4:17.0
0,1,4:17.0
-1,0,5:17.0
0,0,5:17.0
0,1,5:17.0
1,0,5:17.0
0,-1,5:17.0
-1,0,6:17.0
0,0,6:17.0
1,0,6:17.0
0,-1,6:17.0
0,1,6:17.0
-1,0,7:17.0
0,-1,7:17.0
0,0,7:17.0
0,1,7:17.0
1,0,7:17.0
0,2,7:17.0
0,3,7:17.0
-1,4,7:17.0
0,-2,7:17.0
1,-3,7:17.0
-2,0,7:17.0
-1,0,8:17.0
0,0,8:17.0
0,-1,8:17.0
0,1,8:17.0
1,0,8:17.0
-1,0,9:17.0
0,-1,9:17.0
0,0,9:17.0
1,0,9:17.0
0,1,9:17.0
-1,0,10:17.0
0,0,10:17.0
0,-1,10:17.0
0,1,10:17.0
1,0,10:17.0
-1,0,11:17.0
0,0,11:17.0
0,-1,11:17.0
0,1,11:17.0
1,0,11:17.0
-1,0,12:17.0
0,0,12:17.0
0,-1,12:17.0
1,0,12:17.0
0,1,12:17.0
-1,0,13:17.0
-2,0,13:17.0
0,0,13:17.0
1,0,13:17.0
0,-1,13:17.0
0,1,13:17.0
0,2,13:17.0
0,3,13:17.0
-3,0,13:17.0
0,0,14:17.0
0,0,15:17.0
0,0,16:17.0
0,-1,16:17.0
1,-2,16:17.0
2,-3,16:17.0
-1,1,16:17.0
-2,2,16:17.0
-1,-1,16:17.0
-2,-2,16:17.0
1,1,16:17.0
0,0,17:17.0
0,0,18:17.0
0,0,19:17.0
-1,1,19:17.0
0,-1,19:17.0
0,-2,19:17.0
0,-3,19:17.0
1,1,19:17.0
2,2,19:17.0
3,3,19:17.0
4,4,19:17.0
-1,-3,19:17.0
-1,-4,19:17.0
-2,-5,19:17.0
1,-2,19:17.0
2,-3,19:17.0
3,-4,19:17.0
-2,2,19:17.0
-3,3,19:17.0
-4,2,19:17.0
-5,2,19:17.0
-2,-2,19:17.0
-3,-2,19:17.0
-4,-2,19:17.0
2,-1,19:17.0
3,-1,19:17.0
4,-4,19:17.0
4,-5,19:17.0
5,-6,19:17.0
5,-5,19:17.0
0,0,20:17.0
0,0,21:17.0
0,0,22:17.0
0,0,23:17.0
-1,-1,23:17.0
1,0,23:17.0
2,1,23:17.0
-1,1,23:17.0
-1,2,23:17.0
0,0,24:17.0
0,0,25:17.0
0,0,26:17.0
