[META]
version=2.0
spawnOnBlockType=1,2,3,12
spawnSunlight=True
spawnDarkness=True
spawnWater=False
spawnLava=False
underFill=True
randomRotation=True
dig=True
tree=False
branch=False
needsFoundation=True
rarity=30
collisionPercentage=0
spawnElevationMin=0
spawnElevationMax=128
spawnInBiome=Grassland
[DATA]
-4,-4,0:85
-3,-4,0:85
-2,-4,0:85
-1,-4,0:85
0,-4,0:85
1,-4,0:85
2,-4,0:85
3,-4,0:85
4,-4,0:85
-4,-3,0:85
4,-3,0:85
-4,-2,0:85
-2,-2,0:67.3
0,-2,0:67.3
2,-2,0:67.3
4,-2,0:85
-4,-1,0:85
-2,-1,0:44.3
0,-1,0:44.3
2,-1,0:44.3
4,-1,0:85
-4,0,0:17.0
4,0,0:17.0
-4,1,0:85
-2,1,0:67.3
0,1,0:67.3
2,1,0:67.3
4,1,0:85
-4,2,0:85
-2,2,0:44.3
0,2,0:44.3
2,2,0:44.3
4,2,0:85
-4,3,0:85
4,3,0:85
-4,4,0:85
-3,4,0:85
-2,4,0:85
-1,4,0:85
0,4,0:107.6
1,4,0:85
2,4,0:85
3,4,0:85
4,4,0:85
-4,0,1:17.0
-3,0,1:30
4,0,1:17.0
-4,-1,2:18
4,-1,2:18
-4,0,2:17.0
-3,0,2:30
-2,0,2:30
0,0,2:91.0
3,0,2:30
4,0,2:17.0
-4,1,2:18
4,1,2:18
-4,-1,3:30
-3,-1,3:18
-2,-1,3:18
-1,-1,3:18
0,-1,3:18
1,-1,3:18
2,-1,3:18
3,-1,3:18
-4,0,3:18
-3,0,3:17.0
-2,0,3:17.0
-1,0,3:17.0
0,0,3:17.0
1,0,3:17.0
2,0,3:17.0
3,0,3:17.0
4,0,3:18
-3,1,3:18
-2,1,3:18
-1,1,3:18
0,1,3:18
1,1,3:18
2,1,3:18
3,1,3:18
4,1,3:30
-2,-1,4:30
-3,0,4:18
-2,0,4:18
-1,0,4:18
0,0,4:18
1,0,4:18
2,0,4:18
3,0,4:18
0,1,4:30
