[META]
version=2.0
spawnOnBlockType=1,2,3,12
spawnSunlight=True
spawnDarkness=True
spawnWater=False
spawnLava=False
underFill=True
randomRotation=True
dig=True
tree=False
branch=False
needsFoundation=True
rarity=30
collisionPercentage=0
spawnElevationMin=0
spawnElevationMax=128
spawnInBiome=Grassland
[DATA]
-3,-3,0:45
-2,-3,0:92.0
-1,-3,0:92.0
0,-3,0:92.0
1,-3,0:92.0
2,-3,0:92.0
3,-3,0:45
-3,-2,0:92.0
-2,-2,0:61.3
-1,-2,0:54.3
0,-2,0:61.3
1,-2,0:58
2,-2,0:61.3
3,-2,0:13
-3,-1,0:92.0
3,-1,0:92.0
-3,0,0:64.0
3,0,0:92.0
-3,1,0:92.0
3,1,0:92.0
-3,2,0:92.0
-2,2,0:118.3
-1,2,0:5.0
0,2,0:116
1,2,0:5.0
2,2,0:5.0
3,2,0:92.0
-3,3,0:45
-2,3,0:92.0
-1,3,0:92.0
0,3,0:92.0
1,3,0:92.0
2,3,0:92.0
3,3,0:45
-3,-3,1:45
-2,-3,1:92.0
-1,-3,1:92.0
0,-3,1:92.0
1,-3,1:92.0
2,-3,1:92.0
3,-3,1:45
-3,-2,1:92.0
3,-2,1:13
-3,-1,1:92.0
3,-1,1:92.0
-3,0,1:64.8
3,0,1:92.0
-3,1,1:92.0
3,1,1:92.0
-3,2,1:92.0
2,2,1:117
3,2,1:92.0
-3,3,1:45
-2,3,1:92.0
-1,3,1:92.0
0,3,1:92.0
1,3,1:92.0
2,3,1:92.0
3,3,1:45
-3,-3,2:45
-2,-3,2:92.0
-1,-3,2:92.0
0,-3,2:92.0
1,-3,2:92.0
2,-3,2:92.0
3,-3,2:45
-3,-2,2:92.0
3,-2,2:13
-3,-1,2:92.0
3,-1,2:92.0
-3,0,2:13
3,0,2:92.0
-3,1,2:92.0
3,1,2:92.0
-3,2,2:92.0
3,2,2:92.0
-3,3,2:45
-2,3,2:92.0
-1,3,2:92.0
0,3,2:92.0
1,3,2:92.0
2,3,2:92.0
3,3,2:45
-3,-3,3:45
-2,-3,3:92.0
-1,-3,3:92.0
0,-3,3:92.0
1,-3,3:92.0
2,-3,3:92.0
3,-3,3:45
-3,-2,3:92.0
3,-2,3:13
-3,-1,3:92.0
3,-1,3:92.0
-3,0,3:13
3,0,3:92.0
-3,1,3:92.0
3,1,3:92.0
-3,2,3:92.0
3,2,3:92.0
-3,3,3:45
-2,3,3:92.0
-1,3,3:92.0
0,3,3:92.0
1,3,3:92.0
2,3,3:92.0
3,3,3:45
-3,-3,4:30
-2,-3,4:108.2
-1,-3,4:108.2
0,-3,4:108.2
1,-3,4:108.2
2,-3,4:108.2
3,-3,4:30
-3,-2,4:108.0
-2,-2,4:45
-1,-2,4:45
0,-2,4:45
1,-2,4:45
2,-2,4:45
3,-2,4:108.1
-3,-1,4:108.0
-2,-1,4:45
-1,-1,4:45
0,-1,4:45
1,-1,4:45
2,-1,4:45
3,-1,4:108.1
-3,0,4:108.0
-2,0,4:45
-1,0,4:45
0,0,4:45
1,0,4:45
2,0,4:45
3,0,4:108.1
-3,1,4:108.0
-2,1,4:45
-1,1,4:45
0,1,4:45
1,1,4:45
2,1,4:45
3,1,4:108.1
-3,2,4:108.0
-2,2,4:45
-1,2,4:45
0,2,4:45
1,2,4:45
2,2,4:45
3,2,4:108.1
-3,3,4:30
-2,3,4:108.3
-1,3,4:108.3
0,3,4:108.3
1,3,4:108.3
2,3,4:108.3
3,3,4:30
-2,-2,5:30
-1,-2,5:108.2
0,-2,5:108.2
1,-2,5:108.2
2,-2,5:30
-2,-1,5:108.0
-1,-1,5:45
0,-1,5:45
1,-1,5:45
2,-1,5:108.1
-2,0,5:108.0
-1,0,5:45
0,0,5:45
1,0,5:45
2,0,5:108.1
-2,1,5:108.0
-1,1,5:45
0,1,5:45
1,1,5:45
2,1,5:108.1
-2,2,5:30
-1,2,5:108.3
0,2,5:108.3
1,2,5:108.3
2,2,5:30
-1,-1,6:30
0,-1,6:108.2
1,-1,6:30
-1,0,6:108.0
0,0,6:45
1,0,6:108.1
-1,1,6:30
0,1,6:108.3
1,1,6:30
0,0,7:30
