[META]
version=2.0
spawnOnBlockType=2,3
spawnSunlight=True
spawnDarkness=True
spawnWater=False
spawnLava=False
underFill=True
randomRotation=True
dig=True
tree=True
branch=False
needsFoundation=True
rarity=850
collisionPercentage=2
spawnElevationMin=0
spawnElevationMax=100
spawnInBiome=Urwald,Urwald2,Jungle
[DATA]
-1,0,0:17.1
-1,1,0:17.1
0,1,0:17.1
0,0,0:17.1
-1,-1,0:17.1
-2,1,0:17.1
1,0,0:17.1
0,2,0:17.1
0,0,-1:17.1
-1,0,-1:17.1
-1,1,-1:17.1
0,1,-1:17.1
-2,1,-1:17.1
1,0,-1:17.1
-1,-1,-1:17.1
0,2,-1:17.1
-1,-2,-1:17.1
0,3,-1:17.1
-3,1,-1:17.1
2,0,-1:17.1
1,1,-1:17.1
0,-1,-1:17.1
-2,0,-1:17.1
-1,2,-1:17.1
-1,0,1:17.1
-1,1,1:17.1
0,1,1:17.1
0,0,1:17.1
-1,0,2:17.1
-1,1,2:17.1
0,1,2:17.1
0,0,2:17.1
-1,0,3:17.1
-1,1,3:17.1
0,1,3:17.1
0,0,3:17.1
-1,0,4:17.1
-1,1,4:17.1
0,1,4:17.1
0,0,4:17.1
-1,0,5:17.1
-1,1,5:17.1
0,1,5:17.1
0,0,5:17.1
-1,0,6:17.1
-1,1,6:17.1
0,1,6:17.1
0,0,6:17.1
-1,0,7:17.1
-1,1,7:17.1
0,1,7:17.1
0,0,7:17.1
-1,0,8:17.1
-1,1,8:17.1
0,1,8:17.1
0,0,8:17.1
-5,-4,8:18.0
-5,-3,8:18.0
-4,-3,8:18.0
-4,-4,8:18.0
-3,-4,8:18.0
-3,-5,8:18.0
-4,-5,8:18.0
-3,-8,8:18.0
-4,-8,8:18.0
-4,-7,8:18.0
-3,-7,8:18.0
-2,-7,8:18.0
-2,-8,8:18.0
1,-9,8:18.0
0,-9,8:18.0
0,-8,8:18.0
1,-8,8:18.0
1,-10,8:18.0
2,-8,8:18.0
1,-7,8:18.0
2,-5,8:18.0
2,-4,8:18.0
3,-4,8:18.0
3,-5,8:18.0
4,-4,8:18.0
3,-3,8:18.0
-1,0,9:17.1
-1,1,9:17.1
0,1,9:17.1
0,0,9:17.1
-1,-1,9:17.1
-1,-2,9:17.1
-1,-3,9:17.1
-1,-4,9:17.1
-1,-5,9:17.1
-1,-6,9:17.1
-2,-5,9:17.1
-3,-5,9:17.1
-4,-5,9:17.1
-4,-4,9:17.1
0,-4,9:17.1
1,-4,9:17.1
2,-4,9:17.1
2,-5,9:17.1
3,-5,9:17.1
-5,-4,9:17.1
-1,-7,9:17.1
-2,-7,9:17.1
0,-7,9:17.1
0,-8,9:17.1
0,-9,9:17.1
1,-9,9:17.1
-3,-7,9:17.1
-3,-8,9:17.1
-2,-8,9:18.0
-3,-9,9:18.0
-2,-9,9:18.0
-4,-9,9:18.0
-4,-8,9:18.0
-4,-7,9:18.0
-5,-5,9:18.0
-6,-5,9:18.0
-6,-4,9:18.0
-6,-3,9:18.0
-5,-3,9:18.0
-4,-3,9:18.0
-3,-3,9:18.0
-3,-4,9:18.0
-2,-1,9:18.0
-2,0,9:18.0
-2,1,9:18.0
-2,2,9:18.0
-1,2,9:18.0
0,2,9:18.0
1,2,9:18.0
1,1,9:18.0
1,0,9:18.0
1,-1,9:18.0
0,-1,9:18.0
1,-3,9:18.0
2,-3,9:18.0
3,-3,9:18.0
3,-4,9:18.0
4,-4,9:18.0
4,-5,9:18.0
4,-6,9:18.0
3,-6,9:18.0
2,-6,9:18.0
1,-6,9:18.0
1,-5,9:18.0
1,-8,9:18.0
2,-8,9:18.0
2,-9,9:18.0
2,-10,9:18.0
1,-10,9:18.0
0,-10,9:18.0
-1,-10,9:18.0
-1,-9,9:18.0
-4,-6,9:18.0
-1,0,10:17.1
-1,1,10:17.1
0,1,10:17.1
0,0,10:17.1
-3,-9,10:18.0
-3,-10,10:18.0
-4,-10,10:18.0
-5,-10,10:18.0
-5,-9,10:18.0
-5,-8,10:18.0
-5,-7,10:18.0
-4,-7,10:18.0
-3,-7,10:18.0
-3,-8,10:18.0
-4,-8,10:18.0
-4,-9,10:18.0
-1,-7,10:18.0
-1,-8,10:18.0
-1,-9,10:18.0
-1,-10,10:18.0
0,-10,10:18.0
0,-11,10:18.0
1,-11,10:18.0
1,-10,10:18.0
2,-10,10:18.0
3,-10,10:18.0
3,-9,10:18.0
2,-9,10:18.0
2,-8,10:18.0
1,-8,10:18.0
0,-8,10:18.0
0,-7,10:18.0
0,-9,10:18.0
1,-9,10:18.0
-3,-5,10:18.0
-4,-5,10:18.0
-5,-5,10:18.0
-5,-6,10:18.0
-6,-6,10:18.0
-7,-6,10:18.0
-7,-5,10:18.0
-7,-4,10:18.0
-7,-3,10:18.0
-6,-3,10:18.0
-6,-2,10:18.0
-5,-2,10:18.0
-4,-2,10:18.0
-4,-3,10:18.0
-5,-3,10:18.0
-5,-4,10:18.0
-6,-4,10:18.0
-4,-4,10:18.0
-6,-5,10:18.0
-3,-4,10:18.0
-3,-3,10:18.0
-2,-1,10:18.0
-2,0,10:18.0
-3,0,10:18.0
-3,1,10:18.0
-3,2,10:18.0
-2,2,10:18.0
-2,3,10:18.0
-1,3,10:18.0
0,3,10:18.0
0,2,10:18.0
-1,2,10:18.0
1,2,10:18.0
1,1,10:18.0
2,1,10:18.0
2,0,10:18.0
1,0,10:18.0
1,-1,10:18.0
0,-1,10:18.0
-1,-1,10:18.0
-1,-2,10:18.0
-2,1,10:18.0
1,-6,10:18.0
1,-5,10:18.0
1,-4,10:18.0
1,-3,10:18.0
2,-3,10:18.0
2,-4,10:18.0
2,-5,10:18.0
2,-6,10:18.0
3,-6,10:18.0
3,-5,10:18.0
3,-4,10:18.0
4,-4,10:18.0
4,-5,10:18.0
2,-7,10:18.0
-1,0,11:17.1
-1,1,11:17.1
0,1,11:17.1
0,0,11:17.1
-5,-9,11:18.0
-5,-8,11:18.0
-4,-8,11:18.0
-4,-9,11:18.0
-6,-5,11:18.0
-6,-4,11:18.0
-6,-3,11:18.0
-5,-3,11:18.0
-4,-3,11:18.0
-4,-4,11:18.0
-5,-4,11:18.0
-5,-5,11:18.0
0,-9,11:18.0
0,-8,11:18.0
0,-10,11:18.0
1,-10,11:18.0
1,-9,11:18.0
1,-8,11:18.0
2,-9,11:18.0
2,-10,11:18.0
2,-5,11:18.0
2,-4,11:18.0
1,-4,11:18.0
3,-4,11:18.0
3,-5,11:18.0
-1,0,12:17.1
-1,1,12:17.1
0,1,12:17.1
0,0,12:17.1
-1,0,13:17.1
-1,1,13:17.1
0,1,13:17.1
0,0,13:17.1
-1,0,14:17.1
-1,1,14:17.1
0,1,14:17.1
0,0,14:17.1
2,0,14:18.0
2,1,14:18.0
3,1,14:18.0
3,0,14:18.0
0,6,14:18.0
0,7,14:18.0
1,7,14:18.0
1,6,14:18.0
2,6,14:18.0
2,5,14:18.0
3,5,14:18.0
-6,6,14:18.0
-5,6,14:18.0
-5,5,14:18.0
-5,7,14:18.0
-4,7,14:18.0
-4,6,14:18.0
-4,5,14:18.0
-3,6,14:18.0
-5,2,14:18.0
-4,2,14:18.0
-3,2,14:18.0
-4,1,14:18.0
-4,3,14:18.0
-1,0,15:17.1
-1,1,15:17.1
0,1,15:17.1
0,0,15:17.1
-2,1,15:17.1
-2,2,15:17.1
-2,3,15:17.1
-2,4,15:17.1
-2,5,15:17.1
-3,5,15:17.1
-4,5,15:17.1
-4,6,15:17.1
-1,4,15:17.1
0,4,15:17.1
1,4,15:17.1
1,5,15:17.1
1,6,15:17.1
2,6,15:17.1
1,0,15:17.1
2,0,15:17.1
3,0,15:17.1
-3,2,15:17.1
-4,2,15:17.1
-5,6,15:17.1
-4,7,15:17.1
-6,6,15:17.1
1,7,15:17.1
0,7,15:17.1
-3,1,15:18.0
-4,1,15:18.0
-5,1,15:18.0
-5,2,15:18.0
-5,3,15:18.0
-4,3,15:18.0
-3,3,15:18.0
-5,5,15:18.0
-6,5,15:18.0
-7,5,15:18.0
-7,6,15:18.0
-7,7,15:18.0
-6,7,15:18.0
-5,7,15:18.0
-5,8,15:18.0
-4,8,15:18.0
-3,8,15:18.0
-3,7,15:18.0
0,6,15:18.0
-1,6,15:18.0
-1,7,15:18.0
-1,8,15:18.0
0,8,15:18.0
1,8,15:18.0
2,8,15:18.0
2,7,15:18.0
3,7,15:18.0
3,6,15:18.0
3,5,15:18.0
2,5,15:18.0
0,3,15:18.0
1,3,15:18.0
2,1,15:18.0
3,1,15:18.0
4,1,15:18.0
4,0,15:18.0
4,-1,15:18.0
3,-1,15:18.0
2,-1,15:18.0
1,-1,15:18.0
-1,0,16:17.1
-1,1,16:17.1
0,1,16:17.1
0,0,16:17.1
-3,0,16:18.0
-4,0,16:18.0
-5,0,16:18.0
-5,1,16:18.0
-6,1,16:18.0
-6,2,16:18.0
-6,3,16:18.0
-5,3,16:18.0
-4,3,16:18.0
-4,4,16:18.0
-3,3,16:18.0
-3,4,16:18.0
-5,2,16:18.0
-4,2,16:18.0
-3,2,16:18.0
-3,1,16:18.0
-2,2,16:18.0
-4,1,16:18.0
-7,2,16:18.0
-5,5,16:18.0
-6,5,16:18.0
-7,5,16:18.0
-8,5,16:18.0
-8,6,16:18.0
-8,7,16:18.0
-7,7,16:18.0
-7,6,16:18.0
-6,7,16:18.0
-6,8,16:18.0
-5,8,16:18.0
-4,8,16:18.0
-4,9,16:18.0
-9,6,16:18.0
-3,8,16:18.0
-3,7,16:18.0
-4,7,16:18.0
-5,7,16:18.0
-6,6,16:18.0
-5,6,16:18.0
-4,6,16:18.0
-4,5,16:18.0
-3,5,16:18.0
-2,4,16:18.0
-2,5,16:18.0
-1,6,16:18.0
-1,7,16:18.0
-2,7,16:18.0
-1,8,16:18.0
0,8,16:18.0
0,9,16:18.0
1,9,16:18.0
1,8,16:18.0
2,8,16:18.0
2,7,16:18.0
3,7,16:18.0
3,6,16:18.0
4,6,16:18.0
3,5,16:18.0
2,5,16:18.0
2,6,16:18.0
1,6,16:18.0
1,7,16:18.0
0,7,16:18.0
0,6,16:18.0
1,5,16:18.0
1,4,16:18.0
0,4,16:18.0
0,3,16:18.0
1,3,16:18.0
2,3,16:18.0
2,4,16:18.0
1,2,16:18.0
2,1,16:18.0
3,1,16:18.0
3,2,16:18.0
4,2,16:18.0
4,1,16:18.0
5,1,16:18.0
5,0,16:18.0
4,0,16:18.0
4,-1,16:18.0
3,-1,16:18.0
3,-2,16:18.0
2,-2,16:18.0
2,-1,16:18.0
1,-1,16:18.0
1,0,16:18.0
2,0,16:18.0
3,0,16:18.0
-1,0,17:17.1
-1,1,17:17.1
0,1,17:17.1
0,0,17:17.1
-1,0,18:17.1
-1,1,18:17.1
0,1,18:17.1
0,0,18:17.1
-1,0,19:17.1
-1,1,19:17.1
0,1,19:17.1
0,0,19:17.1
-9,5,19:18.0
-9,6,19:18.0
-9,7,19:18.0
-8,7,19:18.0
-7,7,19:18.0
-7,6,19:18.0
-8,6,19:18.0
-8,5,19:18.0
-3,8,19:18.0
-4,8,19:18.0
-4,9,19:18.0
-3,9,19:18.0
-3,10,19:18.0
-2,10,19:18.0
-2,9,19:18.0
-6,10,19:18.0
-7,10,19:18.0
-7,11,19:18.0
-6,11,19:18.0
1,8,19:18.0
1,9,19:18.0
1,10,19:18.0
2,10,19:18.0
2,9,19:18.0
4,7,19:18.0
5,8,19:18.0
5,9,19:18.0
4,9,19:18.0
4,8,19:18.0
6,1,19:18.0
6,2,19:18.0
5,2,19:18.0
6,3,19:18.0
7,3,19:18.0
7,2,19:18.0
7,1,19:18.0
-9,-4,19:18.0
-9,-3,19:18.0
-8,-3,19:18.0
-7,-10,19:18.0
-8,-10,19:18.0
-8,-9,19:18.0
-7,-9,19:18.0
-1,-11,19:18.0
-2,-11,19:18.0
-2,-10,19:18.0
-1,-10,19:18.0
-1,-12,19:18.0
4,-10,19:18.0
4,-9,19:18.0
3,-9,19:18.0
5,-9,19:18.0
5,-10,19:18.0
6,-10,19:18.0
7,-5,19:18.0
7,-4,19:18.0
8,-4,19:18.0
8,-3,19:18.0
9,-3,19:18.0
9,-4,19:18.0
9,-5,19:18.0
8,-5,19:18.0
-4,-4,19:18.0
-4,-3,19:18.0
-4,-2,19:18.0
-3,-3,19:18.0
-5,2,19:18.0
-5,3,19:18.0
-4,3,19:18.0
-1,0,20:17.1
-1,1,20:17.1
0,1,20:17.1
0,0,20:17.1
0,-1,20:17.1
0,-2,20:17.1
0,-3,20:17.1
0,-4,20:17.1
1,-4,20:17.1
2,-4,20:17.1
3,-4,20:17.1
3,-5,20:17.1
3,-6,20:17.1
4,-6,20:17.1
5,-6,20:17.1
5,-7,20:17.1
5,-8,20:17.1
5,-9,20:17.1
5,-10,20:17.1
3,-3,20:17.1
3,-2,20:17.1
4,-2,20:17.1
5,-2,20:17.1
6,-2,20:17.1
-1,-3,20:17.1
-2,-3,20:17.1
-3,-3,20:17.1
-3,-4,20:17.1
-3,-5,20:17.1
-3,-6,20:17.1
-3,-7,20:17.1
-4,-7,20:17.1
-5,-7,20:17.1
-6,-7,20:17.1
-7,-7,20:17.1
-7,-8,20:17.1
-7,-9,20:17.1
-5,-6,20:17.1
-5,-5,20:17.1
-6,-5,20:17.1
-6,-4,20:17.1
-3,-8,20:17.1
-2,-8,20:17.1
-2,-9,20:17.1
-2,-10,20:17.1
-2,-11,20:17.1
-1,-10,20:17.1
4,-9,20:17.1
3,-9,20:17.1
6,-8,20:17.1
7,-8,20:17.1
8,-8,20:17.1
5,-1,20:17.1
5,0,20:17.1
5,1,20:17.1
6,-3,20:17.1
7,-3,20:17.1
8,-3,20:17.1
9,-3,20:17.1
0,-6,20:17.1
0,-5,20:17.1
-1,2,20:17.1
-1,3,20:17.1
-1,4,20:17.1
-1,5,20:17.1
-2,5,20:17.1
-3,5,20:17.1
-4,5,20:17.1
-5,5,20:17.1
-6,5,20:17.1
-6,6,20:17.1
-6,7,20:17.1
-6,8,20:17.1
-6,9,20:17.1
-6,10,20:17.1
-5,8,20:17.1
-4,8,20:17.1
-3,8,20:17.1
-3,9,20:17.1
-7,6,20:17.1
-8,6,20:17.1
-9,6,20:17.1
-10,6,20:17.1
-9,5,20:17.1
-9,4,20:17.1
-9,3,20:17.1
-8,7,20:17.1
-8,8,20:17.1
-4,4,20:17.1
-4,3,20:17.1
-4,2,20:17.1
-5,2,20:17.1
-6,2,20:17.1
-1,6,20:17.1
0,6,20:17.1
1,6,20:17.1
2,6,20:17.1
2,7,20:17.1
2,8,20:17.1
2,9,20:17.1
2,10,20:17.1
1,9,20:17.1
3,8,20:17.1
4,8,20:17.1
5,8,20:17.1
5,9,20:17.1
0,3,20:17.1
1,3,20:17.1
2,3,20:17.1
2,4,20:17.1
3,4,20:17.1
4,4,20:17.1
6,0,20:17.1
7,0,20:17.1
7,1,20:17.1
7,2,20:17.1
7,3,20:17.1
8,-4,20:17.1
-6,-3,20:17.1
-7,-3,20:17.1
-8,-3,20:17.1
-9,-3,20:17.1
-8,-2,20:17.1
-8,-1,20:17.1
-8,-4,20:18.0
-9,-4,20:18.0
-10,-4,20:18.0
-10,-3,20:18.0
-10,-2,20:18.0
-9,-2,20:18.0
-9,-1,20:18.0
-9,0,20:18.0
-8,0,20:18.0
-7,0,20:18.0
-7,-1,20:18.0
-8,-8,20:18.0
-8,-9,20:18.0
-8,-10,20:18.0
-7,-10,20:18.0
-6,-10,20:18.0
-6,-9,20:18.0
-3,-10,20:18.0
-3,-11,20:18.0
-3,-12,20:18.0
-2,-12,20:18.0
-1,-12,20:18.0
-1,-11,20:18.0
0,-11,20:18.0
0,-10,20:18.0
0,-9,20:18.0
-1,-9,20:18.0
-1,-6,20:18.0
-1,-7,20:18.0
0,-7,20:18.0
1,-7,20:18.0
1,-6,20:18.0
3,-8,20:18.0
2,-8,20:18.0
2,-9,20:18.0
2,-10,20:18.0
3,-10,20:18.0
4,-10,20:18.0
4,-11,20:18.0
5,-11,20:18.0
6,-11,20:18.0
6,-10,20:18.0
7,-9,20:18.0
8,-9,20:18.0
9,-9,20:18.0
9,-8,20:18.0
9,-7,20:18.0
8,-7,20:18.0
7,-7,20:18.0
7,-4,20:18.0
7,-5,20:18.0
8,-5,20:18.0
9,-5,20:18.0
9,-4,20:18.0
10,-4,20:18.0
10,-3,20:18.0
10,-2,20:18.0
9,-2,20:18.0
8,-2,20:18.0
4,0,20:18.0
4,1,20:18.0
4,2,20:18.0
5,2,20:18.0
6,2,20:18.0
6,1,20:18.0
6,3,20:18.0
6,4,20:18.0
7,4,20:18.0
8,4,20:18.0
8,3,20:18.0
8,2,20:18.0
8,1,20:18.0
3,5,20:18.0
4,5,20:18.0
5,5,20:18.0
5,4,20:18.0
5,3,20:18.0
4,3,20:18.0
3,3,20:18.0
4,7,20:18.0
5,7,20:18.0
6,7,20:18.0
6,8,20:18.0
6,9,20:18.0
6,10,20:18.0
5,10,20:18.0
4,10,20:18.0
4,9,20:18.0
3,10,20:18.0
3,11,20:18.0
3,9,20:18.0
1,8,20:18.0
0,8,20:18.0
0,9,20:18.0
0,10,20:18.0
1,10,20:18.0
1,11,20:18.0
2,11,20:18.0
-8,4,20:18.0
-8,3,20:18.0
-8,2,20:18.0
-9,2,20:18.0
-10,2,20:18.0
-10,3,20:18.0
-10,4,20:18.0
-10,5,20:18.0
-11,5,20:18.0
-11,6,20:18.0
-11,7,20:18.0
-10,7,20:18.0
-9,7,20:18.0
-9,8,20:18.0
-9,9,20:18.0
-8,9,20:18.0
-7,9,20:18.0
-7,8,20:18.0
-7,7,20:18.0
-7,10,20:18.0
-7,11,20:18.0
-6,11,20:18.0
-5,11,20:18.0
-5,10,20:18.0
-5,9,20:18.0
-4,9,20:18.0
-4,10,20:18.0
-3,10,20:18.0
-2,10,20:18.0
-2,9,20:18.0
-2,8,20:18.0
-2,7,20:18.0
-3,7,20:18.0
-4,7,20:18.0
-5,3,20:18.0
-6,3,20:18.0
-7,3,20:18.0
-7,2,20:18.0
-7,1,20:18.0
-6,1,20:18.0
-5,1,20:18.0
-4,1,20:18.0
-3,1,20:18.0
-3,2,20:18.0
-4,-4,20:18.0
-4,-3,20:18.0
-4,-2,20:18.0
-3,-2,20:18.0
1,0,20:18.0
1,1,20:18.0
1,-1,20:18.0
1,4,20:18.0
2,2,20:18.0
4,-5,20:18.0
4,-4,20:18.0
-6,-6,20:18.0
-4,-8,20:18.0
-1,0,21:17.1
-1,1,21:17.1
0,1,21:17.1
0,0,21:17.1
-9,-3,21:17.1
-8,-1,21:17.1
-7,-9,21:17.1
-5,-7,21:17.1
-6,-3,21:17.1
-2,-11,21:17.1
-2,-9,21:17.1
-3,-6,21:17.1
0,-6,21:17.1
2,-4,21:17.1
3,-6,21:17.1
3,-9,21:17.1
5,-10,21:17.1
8,-8,21:17.1
5,-6,21:17.1
3,-2,21:17.1
6,-2,21:17.1
8,-4,21:17.1
5,1,21:17.1
7,3,21:17.1
-6,2,21:17.1
-9,3,21:17.1
-10,6,21:17.1
-8,8,21:17.1
-6,10,21:17.1
-3,9,21:17.1
-6,6,21:17.1
-4,5,21:17.1
-1,5,21:17.1
2,6,21:17.1
1,9,21:17.1
2,10,21:17.1
5,9,21:17.1
4,4,21:17.1
1,3,21:17.1
-9,2,21:18.0
-9,1,21:18.0
-10,1,21:18.0
-10,2,21:18.0
-10,3,21:18.0
-11,3,21:18.0
-11,4,21:18.0
-11,5,21:18.0
-12,5,21:18.0
-12,6,21:18.0
-12,7,21:18.0
-11,7,21:18.0
-11,8,21:18.0
-10,8,21:18.0
-10,9,21:18.0
-9,9,21:18.0
-9,10,21:18.0
-8,10,21:18.0
-8,11,21:18.0
-7,11,21:18.0
-7,12,21:18.0
-6,12,21:18.0
-5,12,21:18.0
-5,11,21:18.0
-5,10,21:18.0
-4,10,21:18.0
-4,11,21:18.0
-3,11,21:18.0
-2,11,21:18.0
-1,10,21:18.0
-1,9,21:18.0
-1,11,21:18.0
0,11,21:18.0
1,11,21:18.0
1,12,21:18.0
2,12,21:18.0
3,12,21:18.0
4,12,21:18.0
4,11,21:18.0
5,11,21:18.0
6,11,21:18.0
7,11,21:18.0
7,10,21:18.0
7,9,21:18.0
7,8,21:18.0
7,7,21:18.0
6,7,21:18.0
6,6,21:18.0
7,6,21:18.0
7,5,21:18.0
8,5,21:18.0
8,4,21:18.0
9,4,21:18.0
9,3,21:18.0
9,2,21:18.0
9,1,21:18.0
8,0,21:18.0
8,-1,21:18.0
7,-1,21:18.0
7,-2,21:18.0
8,-2,21:18.0
9,-2,21:18.0
9,-3,21:18.0
10,-3,21:18.0
10,-4,21:18.0
9,-4,21:18.0
9,-5,21:18.0
8,-5,21:18.0
8,-6,21:18.0
9,-6,21:18.0
9,-7,21:18.0
9,-8,21:18.0
10,-8,21:18.0
10,-9,21:18.0
9,-9,21:18.0
9,-10,21:18.0
8,-10,21:18.0
7,-10,21:18.0
7,-9,21:18.0
6,-10,21:18.0
6,-11,21:18.0
6,-12,21:18.0
5,-12,21:18.0
4,-12,21:18.0
4,-11,21:18.0
3,-11,21:18.0
3,-10,21:18.0
2,-10,21:18.0
2,-9,21:18.0
2,-8,21:18.0
1,-8,21:18.0
1,-7,21:18.0
0,-7,21:18.0
0,-8,21:18.0
0,-9,21:18.0
0,-10,21:18.0
1,-10,21:18.0
1,-11,21:18.0
0,-11,21:18.0
0,-12,21:18.0
-1,-12,21:18.0
-2,-12,21:18.0
-3,-12,21:18.0
-3,-11,21:18.0
-3,-10,21:18.0
-3,-13,21:18.0
-2,-13,21:18.0
-4,-10,21:18.0
-4,-9,21:18.0
-4,-8,21:18.0
-5,-8,21:18.0
-6,-8,21:18.0
-6,-9,21:18.0
-6,-10,21:18.0
-6,-11,21:18.0
-7,-11,21:18.0
-8,-11,21:18.0
-9,-11,21:18.0
-9,-10,21:18.0
-9,-9,21:18.0
-9,-8,21:18.0
-9,-7,21:18.0
-8,-7,21:18.0
-8,-8,21:18.0
-8,-9,21:18.0
-8,-10,21:18.0
-7,-10,21:18.0
-7,-8,21:18.0
-7,-7,21:18.0
-6,-7,21:18.0
-4,-7,21:18.0
-3,-7,21:18.0
-3,-8,21:18.0
-3,-9,21:18.0
-2,-7,21:18.0
-2,-8,21:18.0
-1,-8,21:18.0
-1,-9,21:18.0
-1,-10,21:18.0
-2,-10,21:18.0
-1,-11,21:18.0
1,-9,21:18.0
-1,-7,21:18.0
-1,-6,21:18.0
-3,-5,21:18.0
-3,-4,21:18.0
-3,-3,21:18.0
-4,-3,21:18.0
-4,-4,21:18.0
-4,-2,21:18.0
-3,-2,21:18.0
-2,-2,21:18.0
-2,-3,21:18.0
-2,-4,21:18.0
-5,-6,21:18.0
-4,-6,21:18.0
-4,-5,21:18.0
-5,-4,21:18.0
-5,-5,21:18.0
-6,-5,21:18.0
-6,-4,21:18.0
-7,-4,21:18.0
-7,-3,21:18.0
-7,-2,21:18.0
-8,-2,21:18.0
-8,-3,21:18.0
-8,-4,21:18.0
-8,-5,21:18.0
-9,-5,21:18.0
-10,-5,21:18.0
-11,-5,21:18.0
-11,-4,21:18.0
-11,-3,21:18.0
-11,-2,21:18.0
-11,-1,21:18.0
-10,-1,21:18.0
-10,-2,21:18.0
-12,-2,21:18.0
-12,-3,21:18.0
-10,-3,21:18.0
-10,-4,21:18.0
-9,-4,21:18.0
-9,-2,21:18.0
-9,-1,21:18.0
-9,0,21:18.0
-10,-10,21:18.0
-10,-9,21:18.0
-8,-12,21:18.0
-7,-12,21:18.0
-4,-12,21:18.0
8,-9,21:18.0
7,-8,21:18.0
6,-8,21:18.0
5,-8,21:18.0
5,-9,21:18.0
4,-9,21:18.0
4,-10,21:18.0
5,-11,21:18.0
6,-9,21:18.0
4,-8,21:18.0
5,-7,21:18.0
4,-7,21:18.0
4,-6,21:18.0
4,-5,21:18.0
5,-5,21:18.0
6,-5,21:18.0
6,-6,21:18.0
6,-7,21:18.0
7,-7,21:18.0
8,-7,21:18.0
7,-5,21:18.0
7,-4,21:18.0
7,-3,21:18.0
8,-3,21:18.0
6,-3,21:18.0
6,-4,21:18.0
5,-3,21:18.0
5,-2,21:18.0
4,-2,21:18.0
4,-3,21:18.0
3,-3,21:18.0
3,-4,21:18.0
4,-4,21:18.0
3,-5,21:18.0
2,-3,21:18.0
1,-3,21:18.0
1,-4,21:18.0
1,-5,21:18.0
1,-6,21:18.0
0,-5,21:18.0
-1,-5,21:18.0
-1,-4,21:18.0
0,-4,21:18.0
0,-3,21:18.0
-1,-3,21:18.0
-1,-2,21:18.0
0,-2,21:18.0
0,-1,21:18.0
1,-1,21:18.0
1,0,21:18.0
1,1,21:18.0
1,2,21:18.0
0,2,21:18.0
-1,2,21:18.0
-2,2,21:18.0
-2,1,21:18.0
-2,0,21:18.0
-2,-1,21:18.0
-1,-1,21:18.0
-3,2,21:18.0
-3,1,21:18.0
-4,1,21:18.0
-4,0,21:18.0
-5,0,21:18.0
-6,0,21:18.0
-6,1,21:18.0
-7,0,21:18.0
-7,-1,21:18.0
-8,0,21:18.0
-7,1,21:18.0
-7,2,21:18.0
-8,2,21:18.0
-8,3,21:18.0
-8,4,21:18.0
-9,4,21:18.0
-9,5,21:18.0
-10,5,21:18.0
-10,4,21:18.0
-11,6,21:18.0
-13,6,21:18.0
-6,13,21:18.0
-6,11,21:18.0
-7,10,21:18.0
-7,9,21:18.0
-7,8,21:18.0
-7,7,21:18.0
-7,6,21:18.0
-8,6,21:18.0
-9,6,21:18.0
-8,5,21:18.0
-7,5,21:18.0
-6,5,21:18.0
-5,5,21:18.0
-7,3,21:18.0
-6,3,21:18.0
-5,3,21:18.0
-4,4,21:18.0
-4,3,21:18.0
-4,2,21:18.0
-5,2,21:18.0
-2,4,21:18.0
-2,5,21:18.0
-3,5,21:18.0
-2,7,21:18.0
-3,7,21:18.0
-3,8,21:18.0
-4,8,21:18.0
-4,7,21:18.0
-5,8,21:18.0
-6,8,21:18.0
-6,9,21:18.0
-6,7,21:18.0
-8,7,21:18.0
-2,8,21:18.0
-2,9,21:18.0
-2,10,21:18.0
-3,10,21:18.0
-1,7,21:18.0
-1,6,21:18.0
-2,6,21:18.0
-1,4,21:18.0
-1,3,21:18.0
0,3,21:18.0
0,4,21:18.0
1,4,21:18.0
2,4,21:18.0
2,3,21:18.0
2,2,21:18.0
3,3,21:18.0
4,3,21:18.0
4,2,21:18.0
4,1,21:18.0
4,0,21:18.0
5,0,21:18.0
5,-1,21:18.0
6,-1,21:18.0
6,0,21:18.0
7,0,21:18.0
7,1,21:18.0
7,2,21:18.0
8,1,21:18.0
8,2,21:18.0
8,3,21:18.0
10,3,21:18.0
8,9,21:18.0
8,8,21:18.0
6,8,21:18.0
6,9,21:18.0
6,10,21:18.0
5,10,21:18.0
4,10,21:18.0
3,10,21:18.0
3,11,21:18.0
2,11,21:18.0
1,10,21:18.0
0,10,21:18.0
0,9,21:18.0
0,8,21:18.0
1,8,21:18.0
2,8,21:18.0
2,9,21:18.0
2,7,21:18.0
3,7,21:18.0
3,8,21:18.0
4,8,21:18.0
5,8,21:18.0
4,9,21:18.0
3,9,21:18.0
4,7,21:18.0
5,7,21:18.0
5,6,21:18.0
5,5,21:18.0
5,4,21:18.0
5,3,21:18.0
5,2,21:18.0
6,2,21:18.0
6,1,21:18.0
6,3,21:18.0
6,4,21:18.0
7,4,21:18.0
4,6,21:18.0
4,5,21:18.0
3,5,21:18.0
1,5,21:18.0
1,6,21:18.0
0,6,21:18.0
3,-1,21:18.0
-9,7,21:18.0
-10,7,21:18.0
-9,8,21:18.0
-8,9,21:18.0
3,4,21:18.0
-4,5,22:17.1
-6,6,22:17.1
-10,6,22:17.1
-8,8,22:17.1
-6,10,22:17.1
-3,9,22:17.1
1,9,22:17.1
2,10,22:17.1
2,6,22:17.1
5,9,22:17.1
4,4,22:17.1
1,3,22:17.1
-1,5,22:17.1
-1,0,22:17.1
-1,1,22:17.1
0,1,22:17.1
0,0,22:17.1
-6,2,22:17.1
-9,3,22:17.1
-8,-1,22:17.1
-2,0,22:17.1
-3,0,22:17.1
-4,0,22:17.1
1,1,22:17.1
2,1,22:17.1
3,1,22:17.1
-1,-1,22:17.1
-1,-2,22:17.1
-1,-3,22:17.1
-1,2,22:17.1
-2,2,22:17.1
-6,-3,22:17.1
-9,-3,22:17.1
-7,-9,22:17.1
-5,-7,22:17.1
-3,-6,22:17.1
-2,-9,22:17.1
-2,-11,22:17.1
0,-6,22:17.1
2,-4,22:17.1
3,-6,22:17.1
3,-9,22:17.1
5,-10,22:17.1
8,-8,22:17.1
5,-6,22:17.1
3,-2,22:17.1
6,-2,22:17.1
8,-4,22:17.1
5,1,22:17.1
7,3,22:17.1
-6,-8,22:18.0
-5,-8,22:18.0
-5,-9,22:18.0
-5,-10,22:18.0
-5,-11,22:18.0
-6,-11,22:18.0
-6,-12,22:18.0
-7,-12,22:18.0
-8,-12,22:18.0
-8,-13,22:18.0
-9,-13,22:18.0
-9,-12,22:18.0
-10,-12,22:18.0
-10,-11,22:18.0
-11,-11,22:18.0
-11,-10,22:18.0
-11,-9,22:18.0
-11,-8,22:18.0
-10,-8,22:18.0
-10,-7,22:18.0
-9,-7,22:18.0
-8,-7,22:18.0
-7,-7,22:18.0
-7,-6,22:18.0
-8,-6,22:18.0
-9,-6,22:18.0
-7,-8,22:18.0
-8,-8,22:18.0
-9,-8,22:18.0
-9,-9,22:18.0
-10,-9,22:18.0
-10,-10,22:18.0
-9,-10,22:18.0
-9,-11,22:18.0
-8,-11,22:18.0
-8,-10,22:18.0
-8,-9,22:18.0
-7,-11,22:18.0
-7,-10,22:18.0
-6,-10,22:18.0
-6,-9,22:18.0
-4,-9,22:18.0
-4,-10,22:18.0
-4,-11,22:18.0
-5,-12,22:18.0
-5,-13,22:18.0
-4,-13,22:18.0
-4,-14,22:18.0
-3,-14,22:18.0
-2,-14,22:18.0
-1,-14,22:18.0
0,-14,22:18.0
-2,-15,22:18.0
0,-13,22:18.0
0,-12,22:18.0
1,-12,22:18.0
1,-11,22:18.0
2,-11,22:18.0
3,-11,22:18.0
3,-12,22:18.0
4,-12,22:18.0
4,-13,22:18.0
5,-13,22:18.0
6,-13,22:18.0
7,-13,22:18.0
7,-12,22:18.0
8,-12,22:18.0
8,-11,22:18.0
9,-11,22:18.0
10,-11,22:18.0
10,-10,22:18.0
11,-10,22:18.0
11,-9,22:18.0
11,-8,22:18.0
12,-8,22:18.0
11,-7,22:18.0
10,-7,22:18.0
10,-6,22:18.0
10,-5,22:18.0
11,-5,22:18.0
11,-4,22:18.0
12,-4,22:18.0
12,-3,22:18.0
11,-3,22:18.0
11,-2,22:18.0
10,-2,22:18.0
9,-2,22:18.0
9,-1,22:18.0
10,-1,22:18.0
10,0,22:18.0
9,0,22:18.0
10,1,22:18.0
10,2,22:18.0
11,2,22:18.0
11,3,22:18.0
10,3,22:18.0
10,4,22:18.0
9,4,22:18.0
9,5,22:18.0
9,6,22:18.0
8,6,22:18.0
8,7,22:18.0
8,8,22:18.0
9,9,22:18.0
9,10,22:18.0
9,11,22:18.0
8,11,22:18.0
8,12,22:18.0
7,12,22:18.0
6,12,22:18.0
6,13,22:18.0
5,13,22:18.0
4,13,22:18.0
3,13,22:18.0
3,14,22:18.0
2,14,22:18.0
1,14,22:18.0
1,13,22:18.0
0,13,22:18.0
2,13,22:18.0
0,12,22:18.0
-1,12,22:18.0
-2,12,22:18.0
-3,12,22:18.0
-4,12,22:18.0
-4,13,22:18.0
-5,13,22:18.0
-6,13,22:18.0
-6,12,22:18.0
-7,12,22:18.0
-8,12,22:18.0
-8,13,22:18.0
-9,13,22:18.0
-9,12,22:18.0
-9,11,22:18.0
-9,10,22:18.0
-10,10,22:18.0
-11,10,22:18.0
-11,9,22:18.0
-11,8,22:18.0
-12,8,22:18.0
-12,7,22:18.0
-13,7,22:18.0
-13,6,22:18.0
-12,6,22:18.0
-12,5,22:18.0
-11,5,22:18.0
-11,4,22:18.0
-11,3,22:18.0
-12,3,22:18.0
-12,2,22:18.0
-11,2,22:18.0
-10,2,22:18.0
-10,1,22:18.0
-9,1,22:18.0
-9,0,22:18.0
-10,0,22:18.0
-10,-1,22:18.0
-11,-1,22:18.0
-12,-2,22:18.0
-12,-3,22:18.0
-11,-3,22:18.0
-13,-2,22:18.0
-13,-3,22:18.0
-11,-4,22:18.0
-11,-5,22:18.0
-10,-5,22:18.0
-9,-5,22:18.0
-10,-4,22:18.0
-10,-3,22:18.0
-10,-2,22:18.0
-11,-2,22:18.0
-9,-2,22:18.0
-8,-2,22:18.0
-8,-3,22:18.0
-8,-4,22:18.0
-9,-4,22:18.0
-7,-4,22:18.0
-7,-5,22:18.0
-6,-4,22:18.0
-6,-5,22:18.0
-6,-6,22:18.0
-6,-7,22:18.0
-5,-5,22:18.0
-5,-6,22:18.0
-5,-4,22:18.0
-4,-4,22:18.0
-4,-3,22:18.0
-5,-3,22:18.0
-5,-2,22:18.0
-5,-1,22:18.0
-6,-1,22:18.0
-6,-2,22:18.0
-7,-2,22:18.0
-7,-3,22:18.0
-8,-5,22:18.0
-4,-12,22:18.0
-4,-8,22:18.0
-4,-7,22:18.0
-4,-6,22:18.0
-4,-5,22:18.0
-4,-2,22:18.0
-4,-1,22:18.0
-3,-1,22:18.0
-2,-1,22:18.0
-2,-2,22:18.0
-2,-3,22:18.0
-3,-3,22:18.0
-3,-2,22:18.0
-3,-4,22:18.0
-3,-5,22:18.0
-2,-5,22:18.0
-2,-4,22:18.0
-2,-6,22:18.0
-2,-7,22:18.0
-3,-7,22:18.0
-3,-8,22:18.0
-3,-9,22:18.0
-3,-10,22:18.0
-3,-11,22:18.0
-3,-12,22:18.0
-3,-13,22:18.0
-2,-13,22:18.0
-1,-13,22:18.0
-1,-12,22:18.0
-2,-12,22:18.0
-1,-11,22:18.0
-1,-10,22:18.0
-2,-10,22:18.0
-1,-9,22:18.0
-1,-8,22:18.0
-2,-8,22:18.0
0,-11,22:18.0
0,-10,22:18.0
0,-9,22:18.0
0,-8,22:18.0
0,-7,22:18.0
-1,-7,22:18.0
-1,-6,22:18.0
-1,-5,22:18.0
-1,-4,22:18.0
0,-4,22:18.0
0,-5,22:18.0
0,-3,22:18.0
0,-2,22:18.0
0,-1,22:18.0
1,-1,22:18.0
1,-2,22:18.0
1,-3,22:18.0
1,-4,22:18.0
1,-5,22:18.0
1,-6,22:18.0
1,-7,22:18.0
1,-8,22:18.0
1,-9,22:18.0
1,-10,22:18.0
2,-10,22:18.0
2,-9,22:18.0
2,-8,22:18.0
2,-7,22:18.0
2,-6,22:18.0
2,-5,22:18.0
3,-5,22:18.0
4,-5,22:18.0
5,-5,22:18.0
6,-5,22:18.0
7,-5,22:18.0
8,-5,22:18.0
9,-5,22:18.0
9,-6,22:18.0
9,-7,22:18.0
9,-8,22:18.0
9,-9,22:18.0
9,-10,22:18.0
8,-10,22:18.0
7,-10,22:18.0
7,-9,22:18.0
6,-9,22:18.0
5,-9,22:18.0
4,-9,22:18.0
4,-10,22:18.0
3,-10,22:18.0
4,-11,22:18.0
5,-11,22:18.0
6,-11,22:18.0
7,-11,22:18.0
6,-10,22:18.0
6,-12,22:18.0
5,-12,22:18.0
5,-14,22:18.0
6,-14,22:18.0
4,-8,22:18.0
4,-7,22:18.0
4,-6,22:18.0
3,-7,22:18.0
3,-8,22:18.0
5,-7,22:18.0
5,-8,22:18.0
6,-8,22:18.0
7,-8,22:18.0
8,-9,22:18.0
10,-9,22:18.0
10,-8,22:18.0
8,-7,22:18.0
7,-7,22:18.0
6,-7,22:18.0
6,-6,22:18.0
7,-6,22:18.0
8,-6,22:18.0
9,-4,22:18.0
9,-3,22:18.0
10,-3,22:18.0
10,-4,22:18.0
8,-3,22:18.0
7,-3,22:18.0
6,-3,22:18.0
5,-3,22:18.0
4,-3,22:18.0
4,-4,22:18.0
3,-3,22:18.0
2,-3,22:18.0
3,-4,22:18.0
5,-4,22:18.0
6,-4,22:18.0
7,-4,22:18.0
7,-2,22:18.0
7,-1,22:18.0
7,0,22:18.0
7,1,22:18.0
7,2,22:18.0
6,0,22:18.0
5,0,22:18.0
4,0,22:18.0
3,0,22:18.0
2,0,22:18.0
1,0,22:18.0
2,-1,22:18.0
2,-2,22:18.0
3,-1,22:18.0
4,-1,22:18.0
5,-1,22:18.0
5,-2,22:18.0
4,-2,22:18.0
6,-1,22:18.0
8,-2,22:18.0
8,-1,22:18.0
8,0,22:18.0
8,1,22:18.0
8,2,22:18.0
8,3,22:18.0
8,4,22:18.0
8,5,22:18.0
9,3,22:18.0
9,2,22:18.0
9,1,22:18.0
6,1,22:18.0
6,2,22:18.0
5,2,22:18.0
4,2,22:18.0
4,1,22:18.0
0,2,22:18.0
1,2,22:18.0
2,2,22:18.0
3,2,22:18.0
3,3,22:18.0
3,4,22:18.0
3,5,22:18.0
3,6,22:18.0
3,7,22:18.0
3,8,22:18.0
3,9,22:18.0
3,10,22:18.0
3,11,22:18.0
3,12,22:18.0
4,12,22:18.0
4,11,22:18.0
4,10,22:18.0
4,9,22:18.0
4,8,22:18.0
4,7,22:18.0
4,6,22:18.0
5,6,22:18.0
5,5,22:18.0
6,5,22:18.0
6,4,22:18.0
5,4,22:18.0
5,3,22:18.0
4,3,22:18.0
6,3,22:18.0
4,5,22:18.0
7,5,22:18.0
7,4,22:18.0
7,6,22:18.0
7,7,22:18.0
7,8,22:18.0
7,9,22:18.0
7,10,22:18.0
7,11,22:18.0
8,10,22:18.0
8,9,22:18.0
6,7,22:18.0
5,7,22:18.0
5,8,22:18.0
6,8,22:18.0
6,6,22:18.0
6,9,22:18.0
6,10,22:18.0
6,11,22:18.0
5,12,22:18.0
5,11,22:18.0
5,10,22:18.0
10,10,22:18.0
-1,11,22:18.0
-1,10,22:18.0
-1,9,22:18.0
-1,8,22:18.0
-1,7,22:18.0
-1,6,22:18.0
0,6,22:18.0
0,5,22:18.0
0,4,22:18.0
0,3,22:18.0
-1,3,22:18.0
-2,3,22:18.0
-3,3,22:18.0
-3,2,22:18.0
-3,1,22:18.0
-2,1,22:18.0
-4,1,22:18.0
-5,1,22:18.0
-5,0,22:18.0
-6,0,22:18.0
-7,0,22:18.0
-7,-1,22:18.0
-7,1,22:18.0
-8,1,22:18.0
-8,0,22:18.0
-9,-1,22:18.0
-10,-6,22:18.0
-6,1,22:18.0
-7,2,22:18.0
-8,2,22:18.0
-9,2,22:18.0
-12,-9,22:18.0
2,15,22:18.0
-5,14,22:18.0
-10,12,22:18.0
-11,6,22:18.0
-11,7,22:18.0
-10,7,22:18.0
-10,8,22:18.0
-10,9,22:18.0
-9,9,22:18.0
-9,8,22:18.0
-9,7,22:18.0
-9,6,22:18.0
-9,5,22:18.0
-9,4,22:18.0
-10,4,22:18.0
-10,5,22:18.0
-10,3,22:18.0
-8,3,22:18.0
-8,4,22:18.0
-8,5,22:18.0
-8,6,22:18.0
-8,7,22:18.0
-8,9,22:18.0
-8,10,22:18.0
-8,11,22:18.0
-7,11,22:18.0
-7,10,22:18.0
-7,9,22:18.0
-7,8,22:18.0
-7,7,22:18.0
-7,6,22:18.0
-7,5,22:18.0
-7,4,22:18.0
-7,3,22:18.0
-6,3,22:18.0
-5,3,22:18.0
-5,2,22:18.0
-4,2,22:18.0
-4,3,22:18.0
-4,4,22:18.0
-5,4,22:18.0
-6,4,22:18.0
-6,5,22:18.0
-5,5,22:18.0
-5,6,22:18.0
-5,7,22:18.0
-6,7,22:18.0
-6,8,22:18.0
-6,9,22:18.0
-5,9,22:18.0
-5,8,22:18.0
-5,10,22:18.0
-5,11,22:18.0
-6,11,22:18.0
-5,12,22:18.0
-4,11,22:18.0
-4,10,22:18.0
-4,9,22:18.0
-4,8,22:18.0
-4,7,22:18.0
-4,6,22:18.0
-3,6,22:18.0
-3,5,22:18.0
-3,4,22:18.0
-3,7,22:18.0
-3,8,22:18.0
-2,8,22:18.0
-2,7,22:18.0
-2,6,22:18.0
-2,5,22:18.0
-2,4,22:18.0
-2,9,22:18.0
-2,10,22:18.0
-2,11,22:18.0
-3,11,22:18.0
-3,10,22:18.0
-1,4,22:18.0
1,4,22:18.0
1,5,22:18.0
1,6,22:18.0
1,7,22:18.0
1,8,22:18.0
0,8,22:18.0
0,7,22:18.0
0,9,22:18.0
0,10,22:18.0
0,11,22:18.0
1,11,22:18.0
1,12,22:18.0
2,12,22:18.0
2,11,22:18.0
1,10,22:18.0
2,9,22:18.0
2,8,22:18.0
2,7,22:18.0
2,5,22:18.0
2,4,22:18.0
2,3,22:18.0
7,3,23:17.1
8,3,23:17.1
8,4,23:17.1
4,4,23:17.1
4,5,23:17.1
5,5,23:17.1
5,9,23:17.1
6,9,23:17.1
6,10,23:17.1
2,10,23:17.1
2,11,23:17.1
1,9,23:17.1
0,9,23:17.1
0,10,23:17.1
-3,9,23:17.1
-3,10,23:17.1
-3,11,23:17.1
-6,10,23:17.1
-7,10,23:17.1
-7,11,23:17.1
-8,8,23:17.1
-9,8,23:17.1
-9,9,23:17.1
-10,6,23:17.1
-10,5,23:17.1
-11,5,23:17.1
-9,3,23:17.1
-9,2,23:17.1
-10,2,23:17.1
-9,-1,23:17.1
-10,-1,23:17.1
-9,-3,23:17.1
-9,-4,23:17.1
-9,-5,23:17.1
-10,-5,23:17.1
-7,-9,23:17.1
-8,-9,23:17.1
-8,-10,23:17.1
-5,-7,23:17.1
-6,-7,23:17.1
-6,-6,23:17.1
-5,-3,23:17.1
-4,-3,23:17.1
-4,-4,23:17.1
-3,-6,23:17.1
-3,-7,23:17.1
-2,-9,23:17.1
-1,-9,23:17.1
0,-9,23:17.1
0,-10,23:17.1
-2,-11,23:17.1
-2,-12,23:17.1
-3,-12,23:17.1
0,-6,23:17.1
0,-5,23:17.1
3,-6,23:17.1
2,-6,23:17.1
2,-7,23:17.1
3,-9,23:17.1
3,-10,23:17.1
3,-11,23:17.1
2,-11,23:17.1
5,-10,23:17.1
6,-10,23:17.1
6,-11,23:17.1
6,-12,23:17.1
8,-8,23:17.1
8,-9,23:17.1
9,-9,23:17.1
5,-6,23:17.1
6,-6,23:17.1
6,-5,23:17.1
8,-4,23:17.1
8,-3,23:17.1
9,-3,23:17.1
6,-2,23:17.1
6,-1,23:17.1
7,-1,23:17.1
7,0,23:17.1
3,-2,23:17.1
2,-2,23:17.1
2,-1,23:17.1
2,-4,23:17.1
3,-4,23:17.1
3,1,23:17.1
3,2,23:17.1
-1,-3,23:17.1
-2,-3,23:17.1
-4,0,23:17.1
-4,1,23:17.1
-6,2,23:17.1
-6,1,23:17.1
-7,1,23:17.1
-6,6,23:17.1
-6,5,23:17.1
-7,5,23:17.1
-4,5,23:17.1
-4,6,23:17.1
-4,7,23:17.1
-3,7,23:17.1
-1,5,23:17.1
-2,5,23:17.1
-2,4,23:17.1
-2,2,23:17.1
-1,0,23:17.1
-1,1,23:17.1
0,1,23:17.1
0,0,23:17.1
1,3,23:17.1
1,4,23:17.1
2,6,23:17.1
1,6,23:17.1
1,7,23:17.1
5,1,23:17.1
5,2,23:17.1
-7,-11,23:18.0
-7,-10,23:18.0
-8,-11,23:18.0
-9,-11,23:18.0
-9,-10,23:18.0
-9,-9,23:18.0
-9,-8,23:18.0
-8,-8,23:18.0
-7,-8,23:18.0
-6,-8,23:18.0
-6,-9,23:18.0
-6,-10,23:18.0
-6,-11,23:18.0
-5,-11,23:18.0
-5,-12,23:18.0
-4,-12,23:18.0
-4,-13,23:18.0
-3,-13,23:18.0
-2,-13,23:18.0
-1,-13,23:18.0
-1,-12,23:18.0
-1,-11,23:18.0
-1,-10,23:18.0
-2,-10,23:18.0
-3,-10,23:18.0
-3,-11,23:18.0
-3,-9,23:18.0
-3,-8,23:18.0
-2,-8,23:18.0
-1,-8,23:18.0
-2,-7,23:18.0
-2,-6,23:18.0
-2,-5,23:18.0
-2,-4,23:18.0
-3,-4,23:18.0
-3,-5,23:18.0
-4,-5,23:18.0
-4,-6,23:18.0
-4,-7,23:18.0
-4,-8,23:18.0
-4,-9,23:18.0
-4,-10,23:18.0
-4,-11,23:18.0
-5,-10,23:18.0
-5,-9,23:18.0
-5,-8,23:18.0
-5,-6,23:18.0
-5,-5,23:18.0
-5,-4,23:18.0
-6,-4,23:18.0
-7,-4,23:18.0
-6,-3,23:18.0
-7,-5,23:18.0
-7,-6,23:18.0
-7,-7,23:18.0
-8,-7,23:18.0
-9,-7,23:18.0
-9,-6,23:18.0
-8,-6,23:18.0
-10,-7,23:18.0
-10,-8,23:18.0
-10,-9,23:18.0
-11,-9,23:18.0
-10,-10,23:18.0
-10,-11,23:18.0
-8,-12,23:18.0
-9,-12,23:18.0
-2,-14,23:18.0
0,-13,23:18.0
0,-12,23:18.0
0,-11,23:18.0
1,-11,23:18.0
1,-10,23:18.0
1,-9,23:18.0
1,-8,23:18.0
1,-7,23:18.0
0,-8,23:18.0
0,-7,23:18.0
-1,-7,23:18.0
-1,-6,23:18.0
-1,-5,23:18.0
-1,-4,23:18.0
0,-4,23:18.0
0,-3,23:18.0
0,-2,23:18.0
0,-1,23:18.0
-1,-2,23:18.0
-1,-1,23:18.0
-2,-1,23:18.0
-3,-1,23:18.0
-4,-1,23:18.0
-5,-1,23:18.0
-6,-1,23:18.0
-7,-1,23:18.0
-8,-1,23:18.0
-8,-2,23:18.0
-8,-3,23:18.0
-8,-4,23:18.0
-8,-5,23:18.0
-6,-5,23:18.0
-7,-3,23:18.0
-7,-2,23:18.0
-6,-2,23:18.0
-5,-2,23:18.0
-4,-2,23:18.0
-3,-2,23:18.0
-3,-3,23:18.0
-2,-2,23:18.0
-3,0,23:18.0
-3,1,23:18.0
-3,2,23:18.0
-3,3,23:18.0
-3,4,23:18.0
-3,5,23:18.0
-3,6,23:18.0
-5,0,23:18.0
-5,1,23:18.0
-5,2,23:18.0
-5,3,23:18.0
-5,4,23:18.0
-5,5,23:18.0
-5,6,23:18.0
-5,7,23:18.0
-5,8,23:18.0
-5,9,23:18.0
-5,10,23:18.0
-5,11,23:18.0
-5,12,23:18.0
-5,13,23:18.0
-6,12,23:18.0
-7,12,23:18.0
-6,11,23:18.0
-8,12,23:18.0
-8,11,23:18.0
-8,10,23:18.0
-8,9,23:18.0
-7,9,23:18.0
-6,9,23:18.0
-6,8,23:18.0
-6,7,23:18.0
-7,8,23:18.0
-7,7,23:18.0
-7,6,23:18.0
-8,6,23:18.0
-8,7,23:18.0
-9,7,23:18.0
-9,6,23:18.0
-9,5,23:18.0
-6,0,23:18.0
-7,0,23:18.0
-8,0,23:18.0
-9,0,23:18.0
-10,0,23:18.0
-11,0,23:18.0
-11,-1,23:18.0
-11,-2,23:18.0
-12,-2,23:18.0
-12,-3,23:18.0
-11,-3,23:18.0
-11,-4,23:18.0
-11,-5,23:18.0
-11,-6,23:18.0
-10,-6,23:18.0
-10,-4,23:18.0
-10,-3,23:18.0
-10,-2,23:18.0
-9,-2,23:18.0
-10,1,23:18.0
-9,1,23:18.0
-11,1,23:18.0
-11,2,23:18.0
-11,3,23:18.0
-12,2,23:18.0
-12,3,23:18.0
-11,4,23:18.0
-12,4,23:18.0
-12,5,23:18.0
-12,6,23:18.0
-13,6,23:18.0
-13,7,23:18.0
-12,7,23:18.0
-11,6,23:18.0
-11,7,23:18.0
-11,8,23:18.0
-10,7,23:18.0
-10,8,23:18.0
-10,9,23:18.0
-10,10,23:18.0
-9,10,23:18.0
-9,11,23:18.0
-10,4,23:18.0
-9,4,23:18.0
-10,3,23:18.0
-8,1,23:18.0
-8,2,23:18.0
-8,3,23:18.0
-8,4,23:18.0
-8,5,23:18.0
-7,2,23:18.0
-7,3,23:18.0
-7,4,23:18.0
-6,4,23:18.0
-6,3,23:18.0
-2,0,23:18.0
-2,1,23:18.0
-4,2,23:18.0
-4,3,23:18.0
-4,4,23:18.0
-4,8,23:18.0
-4,9,23:18.0
-4,10,23:18.0
-4,11,23:18.0
-4,12,23:18.0
-3,12,23:18.0
-2,12,23:18.0
-2,11,23:18.0
-2,10,23:18.0
-2,9,23:18.0
-2,8,23:18.0
-3,8,23:18.0
-2,7,23:18.0
-2,6,23:18.0
-1,6,23:18.0
-1,7,23:18.0
-1,8,23:18.0
-1,9,23:18.0
-1,10,23:18.0
-1,11,23:18.0
-1,12,23:18.0
0,12,23:18.0
0,11,23:18.0
1,12,23:18.0
1,11,23:18.0
1,10,23:18.0
2,12,23:18.0
2,13,23:18.0
3,13,23:18.0
3,12,23:18.0
3,11,23:18.0
4,12,23:18.0
5,12,23:18.0
6,12,23:18.0
6,11,23:18.0
5,11,23:18.0
4,11,23:18.0
5,10,23:18.0
4,10,23:18.0
3,10,23:18.0
3,9,23:18.0
3,8,23:18.0
3,7,23:18.0
2,8,23:18.0
1,8,23:18.0
0,8,23:18.0
2,9,23:18.0
2,7,23:18.0
0,7,23:18.0
0,6,23:18.0
0,5,23:18.0
0,4,23:18.0
0,3,23:18.0
0,2,23:18.0
-1,2,23:18.0
-1,3,23:18.0
-1,4,23:18.0
-2,3,23:18.0
1,-12,23:18.0
2,-12,23:18.0
3,-12,23:18.0
4,-12,23:18.0
5,-12,23:18.0
5,-13,23:18.0
6,-13,23:18.0
7,-13,23:18.0
7,-12,23:18.0
7,-11,23:18.0
8,-11,23:18.0
8,-10,23:18.0
9,-10,23:18.0
10,-10,23:18.0
10,-9,23:18.0
10,-8,23:18.0
9,-8,23:18.0
9,-7,23:18.0
9,-6,23:18.0
8,-6,23:18.0
8,-7,23:18.0
7,-7,23:18.0
7,-8,23:18.0
7,-9,23:18.0
7,-10,23:18.0
5,-11,23:18.0
4,-11,23:18.0
4,-10,23:18.0
4,-9,23:18.0
4,-8,23:18.0
3,-8,23:18.0
2,-8,23:18.0
2,-9,23:18.0
2,-10,23:18.0
1,-6,23:18.0
1,-5,23:18.0
1,-4,23:18.0
1,-3,23:18.0
1,-2,23:18.0
1,-1,23:18.0
1,0,23:18.0
1,1,23:18.0
1,2,23:18.0
2,2,23:18.0
2,1,23:18.0
2,0,23:18.0
3,0,23:18.0
3,-1,23:18.0
2,-3,23:18.0
3,-3,23:18.0
4,-3,23:18.0
5,-3,23:18.0
6,-3,23:18.0
7,-3,23:18.0
4,-4,23:18.0
5,-4,23:18.0
6,-4,23:18.0
7,-4,23:18.0
2,-5,23:18.0
3,-5,23:18.0
4,-5,23:18.0
5,-5,23:18.0
4,-7,23:18.0
4,-6,23:18.0
3,-7,23:18.0
5,-7,23:18.0
5,-8,23:18.0
5,-9,23:18.0
6,-9,23:18.0
6,-8,23:18.0
6,-7,23:18.0
7,-6,23:18.0
7,-5,23:18.0
8,-5,23:18.0
9,-5,23:18.0
9,-4,23:18.0
10,-4,23:18.0
10,-3,23:18.0
10,-2,23:18.0
9,-2,23:18.0
8,-2,23:18.0
7,-2,23:18.0
5,-2,23:18.0
5,-1,23:18.0
5,0,23:18.0
4,-2,23:18.0
4,-1,23:18.0
4,0,23:18.0
4,1,23:18.0
4,2,23:18.0
4,3,23:18.0
2,3,23:18.0
2,4,23:18.0
2,5,23:18.0
1,5,23:18.0
3,3,23:18.0
3,4,23:18.0
3,5,23:18.0
3,6,23:18.0
4,6,23:18.0
4,7,23:18.0
4,8,23:18.0
4,9,23:18.0
5,6,23:18.0
5,7,23:18.0
5,8,23:18.0
5,3,23:18.0
5,4,23:18.0
6,0,23:18.0
6,1,23:18.0
6,2,23:18.0
6,3,23:18.0
6,4,23:18.0
6,5,23:18.0
6,6,23:18.0
6,7,23:18.0
6,8,23:18.0
7,4,23:18.0
7,5,23:18.0
7,6,23:18.0
7,7,23:18.0
7,8,23:18.0
7,9,23:18.0
7,10,23:18.0
7,11,23:18.0
8,5,23:18.0
9,5,23:18.0
9,4,23:18.0
9,3,23:18.0
10,3,23:18.0
10,2,23:18.0
9,2,23:18.0
8,2,23:18.0
7,2,23:18.0
7,1,23:18.0
8,1,23:18.0
8,0,23:18.0
8,-1,23:18.0
9,-1,23:18.0
8,9,23:18.0
8,10,23:18.0
8,11,23:18.0
8,7,23:18.0
11,-3,23:18.0
10,-6,23:18.0
11,-8,23:18.0
2,14,23:18.0
5,13,23:18.0
9,10,23:18.0
-9,12,23:18.0
-7,-10,24:18.0
-8,-10,24:18.0
-8,-9,24:18.0
-8,-8,24:18.0
-9,-8,24:18.0
-9,-7,24:18.0
-9,-6,24:18.0
-9,-5,24:18.0
-10,-5,24:18.0
-10,-4,24:18.0
-10,-3,24:18.0
-9,-3,24:18.0
-9,-2,24:18.0
-9,-1,24:18.0
-10,-1,24:18.0
-10,0,24:18.0
-10,1,24:18.0
-10,2,24:18.0
-10,3,24:18.0
-11,3,24:18.0
-11,4,24:18.0
-11,5,24:18.0
-11,6,24:18.0
-10,6,24:18.0
-10,7,24:18.0
-9,7,24:18.0
-9,8,24:18.0
-9,9,24:18.0
-8,9,24:18.0
-8,10,24:18.0
-7,10,24:18.0
-7,11,24:18.0
-6,11,24:18.0
-5,11,24:18.0
-4,11,24:18.0
-3,11,24:18.0
-2,11,24:18.0
-1,11,24:18.0
0,11,24:18.0
1,11,24:18.0
2,11,24:18.0
3,11,24:18.0
3,12,24:18.0
4,12,24:18.0
4,11,24:18.0
5,11,24:18.0
6,11,24:18.0
6,10,24:18.0
6,9,24:18.0
6,8,24:18.0
6,7,24:18.0
6,6,24:18.0
7,6,24:18.0
7,5,24:18.0
8,5,24:18.0
8,4,24:18.0
8,3,24:18.0
8,2,24:18.0
7,2,24:18.0
7,1,24:18.0
8,1,24:18.0
8,0,24:18.0
8,-1,24:18.0
7,-1,24:18.0
7,-2,24:18.0
8,-2,24:18.0
8,-3,24:18.0
9,-3,24:18.0
9,-4,24:18.0
8,-4,24:18.0
8,-5,24:18.0
8,-6,24:18.0
8,-7,24:18.0
9,-7,24:18.0
9,-8,24:18.0
9,-9,24:18.0
8,-9,24:18.0
7,-9,24:18.0
7,-10,24:18.0
7,-11,24:18.0
7,-12,24:18.0
6,-12,24:18.0
5,-12,24:18.0
4,-12,24:18.0
4,-11,24:18.0
3,-11,24:18.0
2,-11,24:18.0
2,-10,24:18.0
1,-10,24:18.0
1,-11,24:18.0
0,-11,24:18.0
-1,-11,24:18.0
-1,-12,24:18.0
-2,-12,24:18.0
-2,-13,24:18.0
-3,-13,24:18.0
-3,-12,24:18.0
-3,-11,24:18.0
-4,-11,24:18.0
-4,-10,24:18.0
-5,-10,24:18.0
-5,-9,24:18.0
-6,-9,24:18.0
-7,-9,24:18.0
-7,-8,24:18.0
-7,-7,24:18.0
-7,-6,24:18.0
-8,-6,24:18.0
-8,-5,24:18.0
-8,-4,24:18.0
-9,-4,24:18.0
-9,0,24:18.0
-9,1,24:18.0
-9,2,24:18.0
-9,3,24:18.0
-9,4,24:18.0
-9,5,24:18.0
-10,5,24:18.0
-10,4,24:18.0
-9,6,24:18.0
-8,6,24:18.0
-8,7,24:18.0
-8,8,24:18.0
-8,5,24:18.0
-8,4,24:18.0
-8,3,24:18.0
-8,2,24:18.0
-8,1,24:18.0
-8,0,24:18.0
-8,-1,24:18.0
-8,-2,24:18.0
-8,-3,24:18.0
-8,-7,24:18.0
-6,-8,24:18.0
-6,-7,24:18.0
-6,-6,24:18.0
-6,-5,24:18.0
-6,-4,24:18.0
-6,-3,24:18.0
-6,-2,24:18.0
-6,-1,24:18.0
-6,0,24:18.0
-7,1,24:18.0
-7,2,24:18.0
-7,3,24:18.0
-7,4,24:18.0
-7,5,24:18.0
-6,5,24:18.0
-6,6,24:18.0
-6,7,24:18.0
-6,8,24:18.0
-7,8,24:18.0
-7,7,24:18.0
-7,6,24:18.0
-7,0,24:18.0
-7,-1,24:18.0
-7,-2,24:18.0
-7,-3,24:18.0
-7,-4,24:18.0
-7,-5,24:18.0
-7,9,24:18.0
-6,9,24:18.0
-6,10,24:18.0
-6,4,24:18.0
-6,3,24:18.0
-5,2,24:18.0
-5,1,24:18.0
-5,0,24:18.0
-5,-1,24:18.0
-5,-2,24:18.0
-5,-3,24:18.0
-5,-4,24:18.0
-5,-5,24:18.0
-5,-6,24:18.0
-5,-7,24:18.0
-5,-8,24:18.0
-6,1,24:18.0
-6,2,24:18.0
-5,8,24:18.0
-5,9,24:18.0
-5,10,24:18.0
-5,7,24:18.0
-5,6,24:18.0
-5,5,24:18.0
-5,4,24:18.0
-5,3,24:18.0
-4,0,24:18.0
-4,-1,24:18.0
-4,-2,24:18.0
-4,-3,24:18.0
-4,-4,24:18.0
-4,-5,24:18.0
-4,-6,24:18.0
-4,-7,24:18.0
-4,-8,24:18.0
-4,-9,24:18.0
-4,1,24:18.0
-4,2,24:18.0
-4,3,24:18.0
-4,4,24:18.0
-4,5,24:18.0
-4,6,24:18.0
-4,7,24:18.0
-4,8,24:18.0
-4,9,24:18.0
-4,10,24:18.0
-3,9,24:18.0
-3,8,24:18.0
-3,7,24:18.0
-3,6,24:18.0
-3,5,24:18.0
-3,4,24:18.0
-3,3,24:18.0
-3,2,24:18.0
-3,1,24:18.0
-3,0,24:18.0
-3,-1,24:18.0
-3,-2,24:18.0
-3,-3,24:18.0
-3,-4,24:18.0
-3,-5,24:18.0
-3,-6,24:18.0
-3,-7,24:18.0
-3,-8,24:18.0
-3,-9,24:18.0
-3,-10,24:18.0
-2,-9,24:18.0
-2,-8,24:18.0
-2,-7,24:18.0
-2,-6,24:18.0
-2,-5,24:18.0
-2,-4,24:18.0
-2,-3,24:18.0
-2,-2,24:18.0
-2,-1,24:18.0
-2,0,24:18.0
-2,1,24:18.0
-2,2,24:18.0
-2,3,24:18.0
-2,4,24:18.0
-2,5,24:18.0
-2,6,24:18.0
-2,7,24:18.0
-2,8,24:18.0
-2,9,24:18.0
-2,10,24:18.0
-3,10,24:18.0
-1,9,24:18.0
-1,8,24:18.0
-1,7,24:18.0
-1,6,24:18.0
-1,5,24:18.0
-1,4,24:18.0
-1,3,24:18.0
-1,2,24:18.0
-1,1,24:18.0
0,0,24:18.0
0,-1,24:18.0
0,-2,24:18.0
0,-3,24:18.0
0,-4,24:18.0
0,-5,24:18.0
0,-6,24:18.0
0,-7,24:18.0
0,-8,24:18.0
-1,-8,24:18.0
-1,-9,24:18.0
-1,-10,24:18.0
-2,-10,24:18.0
-2,-11,24:18.0
-1,-7,24:18.0
-1,-6,24:18.0
-1,-5,24:18.0
-1,-4,24:18.0
-1,-3,24:18.0
-1,-2,24:18.0
-1,-1,24:18.0
-1,0,24:18.0
-1,10,24:18.0
0,10,24:18.0
0,9,24:18.0
0,8,24:18.0
0,7,24:18.0
0,6,24:18.0
0,5,24:18.0
0,4,24:18.0
0,3,24:18.0
0,2,24:18.0
1,2,24:18.0
1,1,24:18.0
1,0,24:18.0
1,-1,24:18.0
1,-2,24:18.0
1,-3,24:18.0
1,-4,24:18.0
1,-5,24:18.0
1,-6,24:18.0
1,-7,24:18.0
0,-9,24:18.0
0,-10,24:18.0
0,1,24:18.0
1,8,24:18.0
1,9,24:18.0
1,10,24:18.0
2,9,24:18.0
2,8,24:18.0
2,7,24:18.0
2,6,24:18.0
2,5,24:18.0
1,5,24:18.0
1,4,24:18.0
1,3,24:18.0
1,6,24:18.0
1,7,24:18.0
2,4,24:18.0
2,3,24:18.0
2,2,24:18.0
2,1,24:18.0
2,0,24:18.0
2,-1,24:18.0
2,-2,24:18.0
2,-3,24:18.0
2,-4,24:18.0
2,-5,24:18.0
2,-6,24:18.0
2,-7,24:18.0
2,-8,24:18.0
2,-9,24:18.0
1,-9,24:18.0
1,-8,24:18.0
3,-9,24:18.0
3,-10,24:18.0
3,-8,24:18.0
3,-7,24:18.0
3,-6,24:18.0
3,-5,24:18.0
3,-4,24:18.0
3,-3,24:18.0
3,-2,24:18.0
3,-1,24:18.0
3,0,24:18.0
3,1,24:18.0
3,2,24:18.0
3,3,24:18.0
3,4,24:18.0
3,5,24:18.0
3,6,24:18.0
3,7,24:18.0
3,8,24:18.0
2,10,24:18.0
3,10,24:18.0
3,9,24:18.0
4,3,24:18.0
4,2,24:18.0
5,1,24:18.0
5,0,24:18.0
5,-1,24:18.0
5,-2,24:18.0
5,-3,24:18.0
5,-4,24:18.0
5,-5,24:18.0
5,-6,24:18.0
5,-7,24:18.0
5,-8,24:18.0
5,-9,24:18.0
5,-10,24:18.0
4,-10,24:18.0
4,-9,24:18.0
4,-8,24:18.0
4,-7,24:18.0
4,-6,24:18.0
4,-5,24:18.0
5,2,24:18.0
5,3,24:18.0
4,4,24:18.0
4,5,24:18.0
4,6,24:18.0
4,7,24:18.0
4,8,24:18.0
4,9,24:18.0
4,10,24:18.0
5,10,24:18.0
5,9,24:18.0
5,8,24:18.0
5,7,24:18.0
5,6,24:18.0
5,5,24:18.0
5,4,24:18.0
6,4,24:18.0
6,3,24:18.0
7,4,24:18.0
7,3,24:18.0
6,5,24:18.0
6,2,24:18.0
6,1,24:18.0
6,0,24:18.0
6,-1,24:18.0
6,-2,24:18.0
6,-3,24:18.0
6,-4,24:18.0
6,-5,24:18.0
6,-6,24:18.0
6,-7,24:18.0
6,-8,24:18.0
6,-9,24:18.0
6,-10,24:18.0
6,-11,24:18.0
5,-11,24:18.0
4,-3,24:18.0
4,-2,24:18.0
4,-1,24:18.0
4,0,24:18.0
4,1,24:18.0
4,-4,24:18.0
7,-6,24:18.0
7,-7,24:18.0
7,-8,24:18.0
7,-5,24:18.0
7,-4,24:18.0
7,-3,24:18.0
7,0,24:18.0
8,-8,24:18.0
7,9,24:18.0
7,10,24:18.0
-2,12,24:18.0
-1,12,24:18.0
-5,-7,25:18.0
-6,-7,25:18.0
-6,-6,25:18.0
-6,-5,25:18.0
-5,-4,25:18.0
-5,-5,25:18.0
-5,-6,25:18.0
-4,-6,25:18.0
-4,-5,25:18.0
-4,0,25:18.0
-4,1,25:18.0
-4,2,25:18.0
-4,3,25:18.0
-3,4,25:18.0
-2,4,25:18.0
-2,5,25:18.0
-7,2,25:18.0
-8,2,25:18.0
-8,3,25:18.0
-7,3,25:18.0
-7,4,25:18.0
-6,4,25:18.0
-6,5,25:18.0
-1,-9,25:18.0
-1,-8,25:18.0
0,-8,25:18.0
0,-9,25:18.0
1,-9,25:18.0
1,-8,25:18.0
2,-8,25:18.0
5,-9,25:18.0
5,-8,25:18.0
6,-8,25:18.0
6,-7,25:18.0
6,-6,25:18.0
6,-5,25:18.0
7,-5,25:18.0
6,0,25:18.0
6,1,25:18.0
5,1,25:18.0
5,2,25:18.0
6,2,25:18.0
6,3,25:18.0
6,4,25:18.0
4,6,25:18.0
3,7,25:18.0
3,8,25:18.0
4,8,25:18.0
5,8,25:18.0
5,9,25:18.0
-3,9,25:18.0
-4,9,25:18.0
-5,9,25:18.0
-6,9,25:18.0
-6,10,25:18.0
-3,0,25:18.0
-4,-1,25:18.0
-5,-1,25:18.0
-5,0,25:18.0
-1,5,25:18.0
-1,6,25:18.0
-2,6,25:18.0
-3,6,25:18.0
-8,1,25:18.0
-9,1,25:18.0
-9,2,25:18.0
-7,-6,25:18.0
-6,6,25:18.0
-5,6,25:18.0
-5,5,25:18.0
2,-4,25:18.0
3,-4,25:18.0
3,-3,25:18.0
3,-2,25:18.0
2,-2,25:18.0
2,-3,25:18.0
1,-3,25:18.0
7,-4,25:18.0
4,-9,25:18.0
4,-10,25:18.0
5,-10,25:18.0
6,-10,25:18.0
6,-9,25:18.0
6,-4,25:18.0
6,-3,25:18.0
7,-3,25:18.0
8,-3,25:18.0
7,2,25:18.0
0,0,25:18.0
-1,0,25:18.0
-1,1,25:18.0
0,1,25:18.0
-4,-1,26:18.0
-5,-1,26:18.0
-5,0,26:18.0
-9,1,26:18.0
-9,2,26:18.0
-8,2,26:18.0
-6,9,26:18.0
-6,10,26:18.0
-5,9,26:18.0
-2,6,26:18.0
-1,6,26:18.0
-1,5,26:18.0
-5,-6,26:18.0
-6,-6,26:18.0
0,-9,26:18.0
0,-8,26:18.0
3,-3,26:18.0
2,-3,26:18.0
2,-2,26:18.0
3,-2,26:18.0
5,-9,26:18.0
6,-9,26:18.0
5,-10,26:18.0
7,-3,26:18.0
7,-4,26:18.0
6,-4,26:18.0
6,-3,26:18.0
6,1,26:18.0
6,2,26:18.0
6,3,26:18.0
3,7,26:18.0
3,6,26:18.0
5,9,26:18.0
-6,5,26:18.0
-6,6,26:18.0
-5,6,26:18.0
-4,3,26:18.0
-6,-6,27:18.0
-9,2,27:18.0
-6,10,27:18.0
5,9,27:18.0
6,2,27:18.0
7,-4,27:18.0
5,-10,27:18.0
0,-9,27:18.0
-1,6,27:18.0
-5,-1,27:18.0
3,-3,27:18.0
