[META]
version=2.0
spawnOnBlockType=1,2,3,12
spawnSunlight=True
spawnDarkness=True
spawnWater=False
spawnLava=False
underFill=True
randomRotation=True
dig=True
tree=False
branch=False
needsFoundation=True
rarity=50
collisionPercentage=0
spawnElevationMin=0
spawnElevationMax=128
spawnInBiome=Grassland
[DATA]
-1,-8,0:86.0
0,-8,0:86.0
1,-8,0:86.0
-3,-7,0:86.0
-2,-7,0:86.0
-1,-7,0:3
0,-7,0:3
1,-7,0:3
2,-7,0:86.0
3,-7,0:86.0
-5,-6,0:86.0
-4,-6,0:86.0
-3,-6,0:3
-2,-6,0:3
-1,-6,0:3
0,-6,0:2
1,-6,0:3
2,-6,0:3
3,-6,0:3
4,-6,0:86.0
5,-6,0:86.0
-6,-5,0:86.0
-5,-5,0:3
-4,-5,0:2
-3,-5,0:2
-2,-5,0:2
-1,-5,0:2
0,-5,0:2
1,-5,0:2
2,-5,0:2
3,-5,0:2
4,-5,0:2
5,-5,0:2
6,-5,0:86.0
-6,-4,0:86.0
-5,-4,0:2
-4,-4,0:2
-3,-4,0:2
-2,-4,0:2
-1,-4,0:2
0,-4,0:2
1,-4,0:2
2,-4,0:2
3,-4,0:2
4,-4,0:2
5,-4,0:2
6,-4,0:86.0
-7,-3,0:86.0
-6,-3,0:3
-5,-3,0:3
-4,-3,0:2
-3,-3,0:2
-2,-3,0:2
-1,-3,0:2
0,-3,0:2
1,-3,0:2
2,-3,0:2
4,-3,0:2
5,-3,0:2
6,-3,0:2
7,-3,0:86.0
-7,-2,0:86.0
-6,-2,0:3
-5,-2,0:2
-4,-2,0:2
-3,-2,0:2
-2,-2,0:2
-1,-2,0:2
0,-2,0:2
1,-2,0:2
2,-2,0:2
3,-2,0:2
4,-2,0:2
5,-2,0:2
6,-2,0:3
7,-2,0:86.0
-8,-1,0:86.0
-7,-1,0:3
-6,-1,0:3
-5,-1,0:2
-4,-1,0:2
-3,-1,0:2
-2,-1,0:2
-1,-1,0:2
0,-1,0:2
1,-1,0:2
2,-1,0:2
3,-1,0:2
4,-1,0:2
5,-1,0:3
6,-1,0:3
7,-1,0:3
8,-1,0:86.0
-8,0,0:86.0
-7,0,0:3
-6,0,0:3
-5,0,0:3
-4,0,0:3
-3,0,0:3
-2,0,0:3
-1,0,0:2
0,0,0:2
1,0,0:2
2,0,0:2
3,0,0:2
4,0,0:3
5,0,0:3
6,0,0:3
7,0,0:3
8,0,0:86.0
-8,1,0:86.3
-7,1,0:3
-6,1,0:3
-5,1,0:3
-4,1,0:3
-3,1,0:3
-2,1,0:3
-1,1,0:3
0,1,0:3
2,1,0:3
3,1,0:3
4,1,0:3
5,1,0:3
6,1,0:3
7,1,0:3
8,1,0:86.1
-7,2,0:86.0
-6,2,0:3
-5,2,0:3
-4,2,0:3
-3,2,0:3
-2,2,0:3
-1,2,0:3
0,2,0:3
1,2,0:3
2,2,0:3
3,2,0:3
4,2,0:3
5,2,0:3
6,2,0:3
7,2,0:86.0
-7,3,0:86.3
-6,3,0:3
-5,3,0:3
-4,3,0:3
-3,3,0:3
-2,3,0:3
-1,3,0:3
0,3,0:3
1,3,0:3
2,3,0:3
3,3,0:3
4,3,0:3
5,3,0:3
6,3,0:3
7,3,0:86.1
-6,4,0:86.0
-5,4,0:3
-4,4,0:3
-3,4,0:3
-2,4,0:3
-1,4,0:3
0,4,0:3
1,4,0:3
2,4,0:3
3,4,0:3
4,4,0:3
5,4,0:3
6,4,0:86.0
-6,5,0:86.3
-5,5,0:3
-4,5,0:3
-3,5,0:3
-2,5,0:3
-1,5,0:3
0,5,0:3
1,5,0:3
2,5,0:3
3,5,0:3
4,5,0:3
5,5,0:3
6,5,0:86.1
-5,6,0:86.3
-4,6,0:86.3
-3,6,0:3
-2,6,0:3
-1,6,0:3
0,6,0:3
1,6,0:3
2,6,0:3
3,6,0:3
4,6,0:86.1
5,6,0:86.1
-3,7,0:86.3
-2,7,0:86.3
-1,7,0:3
0,7,0:3
1,7,0:3
2,7,0:86.1
3,7,0:86.1
-1,8,0:86.3
0,8,0:86.3
1,8,0:86.1
-1,-9,1:86.0
0,-9,1:86.0
1,-9,1:86.0
-3,-8,1:86.0
-2,-8,1:86.0
-1,-8,1:3
0,-8,1:3
1,-8,1:3
2,-8,1:86.0
3,-8,1:86.0
-5,-7,1:86.0
-4,-7,1:86.0
-3,-7,1:3
-2,-7,1:3
-1,-7,1:3
0,-7,1:3
1,-7,1:3
2,-7,1:3
3,-7,1:3
4,-7,1:86.0
5,-7,1:86.0
-6,-6,1:86.0
-5,-6,1:3
-4,-6,1:3
-3,-6,1:3
-2,-6,1:3
-1,-6,1:2
1,-6,1:3
2,-6,1:3
3,-6,1:2
4,-6,1:3
5,-6,1:3
6,-6,1:86.0
-7,-5,1:86.0
-6,-5,1:3
-5,-5,1:3
6,-5,1:2
7,-5,1:86.0
-7,-4,1:86.0
-6,-4,1:3
6,-4,1:2
7,-4,1:86.0
-8,-3,1:86.0
-7,-3,1:3
-6,-3,1:3
-5,-3,1:86.3
7,-3,1:3
8,-3,1:86.0
-8,-2,1:86.0
-7,-2,1:3
-6,-2,1:3
6,-2,1:3
7,-2,1:3
8,-2,1:86.0
-9,-1,1:86.0
-8,-1,1:3
-7,-1,1:3
-6,-1,1:3
6,-1,1:3
7,-1,1:56
8,-1,1:3
9,-1,1:86.0
-9,0,1:86.0
-8,0,1:3
-7,0,1:3
-6,0,1:86.3
1,0,1:52
2,0,1:52
6,0,1:3
7,0,1:56
8,0,1:3
9,0,1:86.0
-9,1,1:86.3
-8,1,1:3
-7,1,1:3
-6,1,1:3
1,1,1:52
2,1,1:52
7,1,1:3
8,1,1:3
9,1,1:86.1
-8,2,1:86.0
-7,2,1:3
-6,2,1:56
-5,2,1:3
7,2,1:3
8,2,1:86.0
-8,3,1:86.3
-7,3,1:3
-6,3,1:3
5,3,1:3
6,3,1:3
8,3,1:86.1
-7,4,1:86.0
-6,4,1:3
-5,4,1:3
-4,4,1:3
-3,4,1:3
5,4,1:3
6,4,1:3
7,4,1:86.0
-7,5,1:86.3
-6,5,1:3
-5,5,1:3
-4,5,1:3
-3,5,1:56
-2,5,1:3
-1,5,1:3
0,5,1:3
5,5,1:3
6,5,1:3
7,5,1:86.1
-6,6,1:86.3
-5,6,1:3
-4,6,1:3
-3,6,1:3
-2,6,1:3
-1,6,1:3
0,6,1:3
1,6,1:86.2
2,6,1:3
3,6,1:3
4,6,1:3
5,6,1:3
6,6,1:86.1
-5,7,1:86.3
-4,7,1:86.3
-3,7,1:3
-2,7,1:3
-1,7,1:3
0,7,1:3
1,7,1:3
2,7,1:3
3,7,1:3
4,7,1:86.1
5,7,1:86.1
-3,8,1:86.3
-2,8,1:86.3
-1,8,1:3
0,8,1:3
1,8,1:3
2,8,1:86.1
3,8,1:86.1
-1,9,1:86.3
0,9,1:86.3
1,9,1:86.1
-1,-10,2:86.0
0,-10,2:86.0
1,-10,2:86.0
-3,-9,2:86.0
-2,-9,2:86.0
-1,-9,2:3
0,-9,2:3
1,-9,2:3
2,-9,2:86.0
3,-9,2:86.0
-5,-8,2:86.0
-4,-8,2:86.0
-3,-8,2:3
-2,-8,2:3
-1,-8,2:3
0,-8,2:3
1,-8,2:3
2,-8,2:3
3,-8,2:3
4,-8,2:86.0
5,-8,2:86.0
-6,-7,2:86.0
-5,-7,2:3
-4,-7,2:3
-2,-7,2:3
-1,-7,2:3
0,-7,2:3
1,-7,2:3
2,-7,2:3
3,-7,2:3
4,-7,2:3
5,-7,2:3
6,-7,2:86.0
-7,-6,2:86.0
-6,-6,2:3
-5,-6,2:3
-4,-6,2:86.0
-3,-6,2:3
-2,-6,2:3
0,-6,2:2
1,-6,2:3
2,-6,2:3
4,-6,2:3
5,-6,2:3
6,-6,2:3
7,-6,2:86.0
-8,-5,2:86.0
-7,-5,2:3
-6,-5,2:3
6,-5,2:86.0
7,-5,2:3
8,-5,2:86.0
-8,-4,2:86.0
-7,-4,2:3
-6,-4,2:3
7,-4,2:3
8,-4,2:86.0
-9,-3,2:86.0
-8,-3,2:3
6,-3,2:2
7,-3,2:3
8,-3,2:3
9,-3,2:86.0
-9,-2,2:86.0
-8,-2,2:3
-7,-2,2:3
-6,-2,2:86.3
6,-2,2:3
7,-2,2:56
8,-2,2:3
9,-2,2:86.0
-10,-1,2:86.0
-8,-1,2:3
-7,-1,2:3
7,-1,2:3
8,-1,2:3
9,-1,2:3
10,-1,2:86.0
-10,0,2:86.0
-9,0,2:3
-8,0,2:56
-7,0,2:3
7,0,2:3
8,0,2:3
9,0,2:3
10,0,2:86.0
-10,1,2:86.3
-9,1,2:3
-8,1,2:3
-7,1,2:3
7,1,2:3
8,1,2:3
9,1,2:3
10,1,2:86.1
-9,2,2:86.0
-8,2,2:3
-7,2,2:56
-6,2,2:3
7,2,2:3
8,2,2:3
9,2,2:86.0
-9,3,2:86.3
-8,3,2:3
-7,3,2:56
-6,3,2:56
-5,3,2:3
6,3,2:86.1
7,3,2:3
8,3,2:3
9,3,2:86.0
-8,4,2:86.0
-7,4,2:3
-6,4,2:3
-5,4,2:3
-4,4,2:86.2
-3,4,2:3
6,4,2:3
7,4,2:3
8,4,2:86.0
9,4,2:86.1
-8,5,2:86.3
-7,5,2:56
-6,5,2:56
-5,5,2:56
-4,5,2:3
-3,5,2:56
-2,5,2:3
-1,5,2:3
6,5,2:86.1
7,5,2:3
8,5,2:86.1
-7,6,2:86.3
-6,6,2:3
-5,6,2:3
-4,6,2:3
-3,6,2:3
-2,6,2:3
-1,6,2:3
0,6,2:3
2,6,2:86.2
3,6,2:3
4,6,2:3
5,6,2:3
6,6,2:3
7,6,2:86.1
-6,7,2:86.3
-5,7,2:3
-4,7,2:3
-3,7,2:3
-2,7,2:56
-1,7,2:3
0,7,2:3
1,7,2:3
2,7,2:3
3,7,2:56
4,7,2:3
6,7,2:86.1
-5,8,2:86.3
-4,8,2:86.3
-3,8,2:3
-2,8,2:3
-1,8,2:3
0,8,2:3
1,8,2:3
2,8,2:3
3,8,2:3
4,8,2:86.1
5,8,2:86.1
-3,9,2:86.3
-2,9,2:86.3
-1,9,2:3
0,9,2:3
1,9,2:3
2,9,2:86.1
3,9,2:86.1
-1,10,2:86.3
0,10,2:86.2
1,10,2:86.2
-1,-10,3:86.0
0,-10,3:86.0
1,-10,3:86.0
-3,-9,3:86.0
-2,-9,3:86.0
-1,-9,3:3
0,-9,3:3
1,-9,3:3
2,-9,3:86.0
3,-9,3:86.0
-5,-8,3:86.0
-4,-8,3:86.0
-3,-8,3:3
-2,-8,3:3
-1,-8,3:3
0,-8,3:3
1,-8,3:3
2,-8,3:3
3,-8,3:3
4,-8,3:86.0
5,-8,3:86.0
-6,-7,3:86.0
-5,-7,3:3
-4,-7,3:3
-2,-7,3:3
-1,-7,3:3
0,-7,3:3
1,-7,3:3
2,-7,3:3
3,-7,3:3
4,-7,3:3
5,-7,3:3
6,-7,3:86.0
-7,-6,3:86.0
-6,-6,3:3
-5,-6,3:3
-2,-6,3:3
1,-6,3:86.0
4,-6,3:3
5,-6,3:86.0
6,-6,3:3
7,-6,3:86.0
-8,-5,3:86.0
-7,-5,3:3
-5,-5,3:3
7,-5,3:3
8,-5,3:86.0
-8,-4,3:86.0
-7,-4,3:3
-6,-4,3:3
-5,-4,3:3
7,-4,3:3
8,-4,3:86.0
-9,-3,3:86.0
-8,-3,3:3
-7,-3,3:3
7,-3,3:3
8,-3,3:3
9,-3,3:86.0
-9,-2,3:86.0
-8,-2,3:3
-7,-2,3:3
6,-2,3:86.1
7,-2,3:3
8,-2,3:3
9,-2,3:86.0
-10,-1,3:86.0
-9,-1,3:3
-8,-1,3:3
-7,-1,3:3
9,-1,3:3
10,-1,3:86.0
-10,0,3:86.0
-9,0,3:3
-8,0,3:3
-7,0,3:3
8,0,3:86.1
9,0,3:3
10,0,3:86.0
-10,1,3:86.3
-9,1,3:3
-8,1,3:3
-7,1,3:86.3
8,1,3:3
9,1,3:3
10,1,3:86.1
-9,2,3:86.0
-8,2,3:3
-7,2,3:3
-6,2,3:86.3
7,2,3:86.1
8,2,3:3
9,2,3:86.0
-9,3,3:86.3
-8,3,3:3
-7,3,3:3
-6,3,3:3
7,3,3:3
8,3,3:3
9,3,3:86.0
-8,4,3:86.0
-7,4,3:3
-6,4,3:3
-5,4,3:86.2
6,4,3:3
7,4,3:3
8,4,3:86.0
9,4,3:86.1
-8,5,3:86.3
-7,5,3:3
-6,5,3:3
-5,5,3:3
-4,5,3:3
-3,5,3:3
5,5,3:3
6,5,3:3
7,5,3:3
8,5,3:86.1
-7,6,3:86.3
-6,6,3:3
-5,6,3:3
-4,6,3:3
-3,6,3:56
-2,6,3:3
0,6,3:3
2,6,3:3
3,6,3:3
4,6,3:3
5,6,3:3
6,6,3:3
7,6,3:86.1
-6,7,3:86.3
-5,7,3:3
-4,7,3:3
-3,7,3:3
-2,7,3:3
-1,7,3:3
0,7,3:3
1,7,3:3
2,7,3:56
3,7,3:56
4,7,3:3
6,7,3:86.1
-5,8,3:86.3
-4,8,3:86.3
-2,8,3:3
-1,8,3:3
0,8,3:3
1,8,3:3
2,8,3:3
3,8,3:3
4,8,3:86.1
5,8,3:86.1
-3,9,3:86.3
-2,9,3:86.3
-1,9,3:3
0,9,3:3
1,9,3:3
2,9,3:86.1
3,9,3:86.2
-1,10,3:86.3
0,10,3:86.3
1,10,3:86.2
-1,-9,4:86.0
0,-9,4:86.0
1,-9,4:86.0
-3,-8,4:86.0
-2,-8,4:86.0
-1,-8,4:3
0,-8,4:3
1,-8,4:3
2,-8,4:86.0
3,-8,4:86.0
4,-8,4:18
-5,-7,4:86.0
-4,-7,4:86.0
-3,-7,4:3
-2,-7,4:3
-1,-7,4:3
0,-7,4:3
1,-7,4:3
2,-7,4:3
3,-7,4:3
4,-7,4:86.0
5,-7,4:86.0
-6,-6,4:86.0
-5,-6,4:3
-4,-6,4:3
-2,-6,4:86.0
0,-6,4:3
2,-6,4:3
3,-6,4:3
4,-6,4:3
5,-6,4:3
6,-6,4:86.0
-7,-5,4:86.0
-6,-5,4:3
4,-5,4:3
5,-5,4:3
6,-5,4:3
7,-5,4:86.0
-7,-4,4:86.0
-6,-4,4:3
6,-4,4:3
7,-4,4:86.0
-8,-3,4:86.0
-7,-3,4:3
7,-3,4:3
8,-3,4:86.0
-8,-2,4:86.0
-7,-2,4:3
7,-2,4:3
8,-2,4:86.0
-9,-1,4:86.0
-8,-1,4:3
-7,-1,4:3
8,-1,4:3
9,-1,4:86.0
-9,0,4:86.0
-8,0,4:3
8,0,4:3
9,0,4:86.0
-9,1,4:86.3
-8,1,4:3
8,1,4:3
9,1,4:86.1
-8,2,4:86.0
-7,2,4:3
-6,2,4:3
7,2,4:3
8,2,4:86.0
-8,3,4:86.3
-7,3,4:3
6,3,4:3
8,3,4:86.1
-7,4,4:86.0
-6,4,4:3
-5,4,4:3
6,4,4:3
7,4,4:86.0
-7,5,4:86.3
-5,5,4:3
5,5,4:3
6,5,4:3
7,5,4:86.1
-6,6,4:86.3
-5,6,4:3
-4,6,4:3
-3,6,4:3
-2,6,4:86.2
0,6,4:86.2
3,6,4:86.2
4,6,4:3
6,6,4:86.1
-6,7,4:18
-5,7,4:86.3
-4,7,4:86.3
-3,7,4:3
-2,7,4:3
-1,7,4:3
0,7,4:3
1,7,4:3
2,7,4:3
3,7,4:3
4,7,4:86.1
5,7,4:86.1
-3,8,4:86.3
-2,8,4:86.3
-1,8,4:3
0,8,4:3
1,8,4:3
2,8,4:86.1
3,8,4:86.1
-1,9,4:86.3
0,9,4:86.3
1,9,4:86.1
-1,-9,5:18
-2,-8,5:18
-1,-8,5:86.0
0,-8,5:86.0
1,-8,5:86.0
3,-8,5:18
-3,-7,5:86.0
-2,-7,5:86.0
-1,-7,5:3
0,-7,5:3
1,-7,5:3
2,-7,5:86.0
3,-7,5:86.0
4,-7,5:18
5,-7,5:18
-5,-6,5:86.0
-4,-6,5:86.0
-3,-6,5:3
-2,-6,5:3
-1,-6,5:3
0,-6,5:3
1,-6,5:3
2,-6,5:3
3,-6,5:3
4,-6,5:86.0
5,-6,5:86.0
-7,-5,5:18
-6,-5,5:86.0
-5,-5,5:3
-4,-5,5:3
-2,-5,5:3
-1,-5,5:3
1,-5,5:3
2,-5,5:3
3,-5,5:3
4,-5,5:3
5,-5,5:3
6,-5,5:86.0
-7,-4,5:18
-6,-4,5:86.0
-5,-4,5:3
-3,-4,5:3
-1,-4,5:3
0,-4,5:3
1,-4,5:3
3,-4,5:3
4,-4,5:3
5,-4,5:3
6,-4,5:86.0
-7,-3,5:86.0
-6,-3,5:3
-5,-3,5:3
-4,-3,5:3
-3,-3,5:3
-2,-3,5:3
-1,-3,5:3
1,-3,5:3
2,-3,5:3
3,-3,5:3
4,-3,5:3
5,-3,5:3
6,-3,5:3
7,-3,5:86.0
-7,-2,5:86.0
-6,-2,5:3
-5,-2,5:3
-4,-2,5:3
-3,-2,5:3
-1,-2,5:3
0,-2,5:3
3,-2,5:3
4,-2,5:3
5,-2,5:3
6,-2,5:3
7,-2,5:86.0
-8,-1,5:86.0
-6,-1,5:3
-3,-1,5:3
-2,-1,5:3
-1,-1,5:3
1,-1,5:3
2,-1,5:3
3,-1,5:3
4,-1,5:3
5,-1,5:3
7,-1,5:3
8,-1,5:86.0
-8,0,5:86.0
-7,0,5:3
-5,0,5:3
-4,0,5:3
-2,0,5:3
-1,0,5:3
0,0,5:3
1,0,5:3
3,0,5:3
5,0,5:3
6,0,5:3
7,0,5:3
8,0,5:86.0
-8,1,5:86.3
-7,1,5:3
-6,1,5:3
-2,1,5:3
-1,1,5:3
1,1,5:3
2,1,5:3
3,1,5:3
4,1,5:3
5,1,5:3
7,1,5:3
8,1,5:86.1
-8,2,5:18
-7,2,5:86.0
-6,2,5:3
-5,2,5:3
-4,2,5:3
-3,2,5:3
-2,2,5:3
0,2,5:3
1,2,5:3
2,2,5:3
4,2,5:3
6,2,5:3
7,2,5:86.0
8,2,5:18
-7,3,5:86.3
-6,3,5:3
-4,3,5:3
-3,3,5:3
-2,3,5:3
-1,3,5:3
0,3,5:3
3,3,5:3
6,3,5:3
7,3,5:86.1
8,3,5:18
-6,4,5:86.0
-5,4,5:3
-4,4,5:3
-3,4,5:3
-2,4,5:3
2,4,5:3
3,4,5:3
4,4,5:3
5,4,5:3
6,4,5:86.0
7,4,5:18
-6,5,5:86.3
-5,5,5:3
-4,5,5:3
-1,5,5:3
0,5,5:3
1,5,5:3
2,5,5:3
4,5,5:3
5,5,5:3
6,5,5:86.1
-6,6,5:18
-5,6,5:86.3
-4,6,5:86.2
-3,6,5:3
-2,6,5:3
2,6,5:3
3,6,5:3
4,6,5:86.1
5,6,5:86.1
-5,7,5:18
-3,7,5:86.3
-2,7,5:86.3
-1,7,5:3
0,7,5:3
1,7,5:3
2,7,5:86.1
3,7,5:86.1
4,7,5:18
-1,8,5:86.3
0,8,5:86.2
1,8,5:86.1
-1,-8,6:18
-1,-7,6:86.0
0,-7,6:86.0
1,-7,6:86.0
3,-7,6:18
-3,-6,6:86.0
-2,-6,6:86.0
-1,-6,6:86.0
0,-6,6:86.0
1,-6,6:86.0
2,-6,6:86.0
3,-6,6:86.0
4,-6,6:18
5,-6,6:18
-5,-5,6:86.0
-4,-5,6:86.0
-3,-5,6:86.0
-2,-5,6:86.0
-1,-5,6:86.0
0,-5,6:86.0
1,-5,6:18
2,-5,6:86.0
3,-5,6:86.0
4,-5,6:86.0
5,-5,6:86.0
-6,-4,6:18
-5,-4,6:86.0
-4,-4,6:86.0
-3,-4,6:86.0
-2,-4,6:18
-1,-4,6:18
0,-4,6:18
1,-4,6:18
2,-4,6:18
3,-4,6:18
4,-4,6:86.0
5,-4,6:86.0
-6,-3,6:86.0
-5,-3,6:86.0
-4,-3,6:86.0
-3,-3,6:86.0
-2,-3,6:18
-1,-3,6:18
0,-3,6:18
1,-3,6:18
2,-3,6:18
3,-3,6:18
4,-3,6:86.0
5,-3,6:86.0
6,-3,6:86.0
7,-3,6:18
-6,-2,6:86.0
-5,-2,6:86.0
-4,-2,6:18
-3,-2,6:18
-2,-2,6:18
-1,-2,6:18
0,-2,6:86.0
1,-2,6:18
2,-2,6:18
3,-2,6:18
4,-2,6:86.0
5,-2,6:86.0
6,-2,6:86.0
-7,-1,6:86.0
-6,-1,6:86.0
-5,-1,6:86.0
-4,-1,6:86.0
-3,-1,6:18
-2,-1,6:18
-1,-1,6:86.0
0,-1,6:86.0
1,-1,6:86.0
2,-1,6:18
3,-1,6:18
4,-1,6:86.0
5,-1,6:86.0
6,-1,6:86.0
7,-1,6:86.0
-7,0,6:86.0
-6,0,6:86.0
-5,0,6:86.0
-4,0,6:86.0
-3,0,6:86.0
-2,0,6:18
-1,0,6:18
0,0,6:86.0
1,0,6:18
2,0,6:18
3,0,6:18
4,0,6:18
5,0,6:86.0
6,0,6:86.0
7,0,6:86.0
-8,1,6:18
-7,1,6:86.3
-6,1,6:86.0
-5,1,6:86.0
-4,1,6:86.0
-3,1,6:18
-2,1,6:18
-1,1,6:18
0,1,6:18
1,1,6:18
2,1,6:18
3,1,6:18
4,1,6:86.0
5,1,6:86.0
6,1,6:86.0
7,1,6:86.1
-7,2,6:18
-6,2,6:86.0
-5,2,6:86.0
-4,2,6:86.0
-3,2,6:86.0
-2,2,6:18
-1,2,6:18
0,2,6:18
1,2,6:18
2,2,6:18
3,2,6:18
4,2,6:18
5,2,6:86.0
6,2,6:86.0
7,2,6:18
-6,3,6:86.3
-5,3,6:86.0
-4,3,6:86.0
-3,3,6:86.0
-2,3,6:86.0
-1,3,6:18
0,3,6:18
1,3,6:18
2,3,6:18
3,3,6:18
4,3,6:18
5,3,6:86.0
6,3,6:86.2
7,3,6:18
-5,4,6:86.0
-4,4,6:86.0
-3,4,6:86.0
-2,4,6:86.0
-1,4,6:86.0
0,4,6:18
1,4,6:18
2,4,6:18
3,4,6:18
4,4,6:86.0
5,4,6:86.0
-5,5,6:86.3
-4,5,6:86.3
-3,5,6:86.0
-2,5,6:86.0
-1,5,6:86.0
0,5,6:86.0
1,5,6:86.0
2,5,6:86.0
3,5,6:86.0
4,5,6:86.3
5,5,6:86.2
-5,6,6:18
-4,6,6:18
-3,6,6:86.3
-2,6,6:86.3
-1,6,6:86.0
0,6,6:86.0
1,6,6:86.0
2,6,6:86.3
3,6,6:86.2
4,6,6:18
-1,7,6:86.3
0,7,6:86.3
1,7,6:86.2
3,7,6:18
-1,-7,7:18
0,-7,7:18
0,-6,7:18
0,-5,7:18
2,-5,7:18
3,-5,7:18
4,-5,7:18
-5,-4,7:18
-4,-4,7:18
-3,-4,7:18
-4,-3,7:18
-3,-3,7:18
6,-3,7:18
0,-2,7:17.0
5,-2,7:18
-5,-1,7:18
-4,-1,7:18
-1,-1,7:17.0
0,-1,7:17.0
1,-1,7:17.0
4,-1,7:18
-5,0,7:18
-4,0,7:18
-3,0,7:18
0,0,7:17.0
-7,1,7:18
-6,1,7:18
-5,1,7:18
-4,1,7:18
4,1,7:18
5,1,7:18
6,1,7:18
6,2,7:18
-3,3,7:18
-2,3,7:18
-4,4,7:18
-3,4,7:18
-2,4,7:18
-4,5,7:18
-3,5,7:18
1,5,7:18
2,5,7:18
3,6,7:18
0,-2,8:17.0
-1,-1,8:17.0
0,-1,8:17.0
1,-1,8:17.0
0,0,8:17.0
0,-2,9:17.0
-1,-1,9:17.0
0,-1,9:17.0
1,-1,9:17.0
0,0,9:17.0
0,-3,10:17.0
-1,-2,10:17.0
0,-2,10:17.0
1,-2,10:17.0
0,-1,10:17.0
0,-3,11:17.0
-1,-2,11:17.0
0,-2,11:17.0
1,-2,11:17.0
0,-1,11:17.0
0,-4,12:17.0
-1,-3,12:17.0
0,-3,12:17.0
1,-3,12:17.0
0,-2,12:17.0
0,-5,13:17.0
-1,-4,13:17.0
0,-4,13:17.0
1,-4,13:17.0
0,-3,13:17.0
