[META]
version=2.0
spawnOnBlockType=3,2
spawnSunlight=True
spawnDarkness=True
spawnWater=False
spawnLava=False
underFill=True
randomRotation=True
dig=True
tree=False
branch=False
needsFoundation=True
rarity=550
collisionPercentage=2
spawnElevationMin=0
spawnElevationMax=105
spawnInBiome=Urwald
[DATA]
0,0,0:17.2
-1,0,0:17.2
-1,1,0:17.2
0,1,0:17.2
-2,0,0:106.4
1,1,0:106.2
1,-1,-1:17.2
0,0,-1:17.2
-1,0,-1:17.2
-1,1,-1:17.2
0,1,-1:17.2
0,2,-1:17.2
-2,1,-1:17.2
-2,2,-1:17.2
-1,-1,-1:17.2
-2,-1,-1:17.2
1,2,-1:17.2
-1,0,1:17.2
0,1,1:17.2
-1,1,1:17.2
0,0,1:17.2
-5,1,1:106.8
3,0,1:106.2
-2,0,1:106.4
1,1,1:106.2
-1,-2,2:17.2
-3,1,2:17.2
0,3,2:17.2
2,0,2:17.2
-1,-1,2:17.2
-1,0,2:17.2
-2,1,2:17.2
-1,1,2:17.2
0,0,2:17.2
1,0,2:17.2
0,1,2:17.2
0,2,2:17.2
3,3,2:106.4
-5,1,2:106.8
3,0,2:106.2
-2,0,2:106.4
1,1,2:106.2
-1,-2,3:17.2
-3,1,3:17.2
0,3,3:17.2
2,0,3:17.2
-2,-4,3:106.1
3,3,3:106.4
-5,1,3:106.8
-8,3,3:106.8
3,0,3:106.2
4,-3,3:106.2
-2,0,3:106.4
1,1,3:106.2
-1,-2,4:17.2
-3,1,4:17.2
0,3,4:17.2
2,0,4:17.2
0,-2,4:17.2
3,0,4:17.2
-1,3,4:17.2
-4,1,4:17.2
-5,1,4:18.0
0,-3,4:18.0
4,0,4:18.0
-1,4,4:18.0
-1,-3,4:18.0
1,-2,4:18.0
1,-3,4:18.0
-2,3,4:18.0
0,4,4:18.0
-4,0,4:18.0
3,1,4:18.0
-2,-4,4:106.1
3,3,4:106.4
-8,3,4:106.8
4,-3,4:106.2
-2,0,4:106.4
1,1,4:106.2
-1,-2,5:17.2
-2,-2,5:17.2
-3,1,5:17.2
-3,2,5:17.2
0,3,5:17.2
1,3,5:17.2
2,0,5:17.2
3,0,5:17.2
-2,-4,5:106.1
-3,6,5:106.4
3,3,5:106.4
-8,3,5:106.8
4,-3,5:106.2
-2,0,5:106.4
1,1,5:106.2
3,0,6:17.2
1,3,6:17.2
-3,2,6:17.2
-2,-2,6:17.2
-1,-2,6:18.0
-1,-3,6:18.0
-2,-3,6:18.0
-3,-3,6:18.0
-3,-2,6:18.0
-3,-1,6:18.0
-2,-1,6:18.0
-1,-1,6:18.0
-3,1,6:18.0
-4,1,6:18.0
-4,2,6:18.0
-4,3,6:18.0
-3,3,6:18.0
-2,3,6:18.0
-2,2,6:18.0
-2,1,6:18.0
0,2,6:18.0
0,3,6:18.0
0,4,6:18.0
1,4,6:18.0
2,4,6:18.0
2,3,6:18.0
2,2,6:18.0
1,2,6:18.0
2,1,6:18.0
2,0,6:18.0
2,-1,6:18.0
3,-1,6:18.0
4,0,6:18.0
3,1,6:18.0
4,-1,6:18.0
4,1,6:18.0
-2,-4,6:106.1
-3,6,6:106.4
3,3,6:106.4
-8,3,6:106.8
4,-3,6:106.2
-2,0,6:106.4
1,1,6:106.2
-2,-2,7:17.2
-2,-3,7:17.2
-3,2,7:17.2
-4,2,7:17.2
1,3,7:17.2
1,4,7:17.2
3,0,7:17.2
3,-1,7:17.2
-2,-4,7:106.1
-3,6,7:106.4
3,3,7:106.4
-8,3,7:106.8
4,-3,7:106.2
-2,0,7:106.4
1,1,7:106.2
-2,-3,8:17.2
-4,2,8:17.2
1,4,8:17.2
3,-1,8:17.2
4,-1,8:17.2
2,-1,8:17.2
1,5,8:17.2
2,4,8:17.2
-5,2,8:17.2
-4,3,8:17.2
-3,-3,8:17.2
-1,-3,8:17.2
-2,-4,8:106.1
4,-3,8:106.2
-3,6,8:106.4
3,3,8:106.4
-8,3,8:106.8
-2,0,8:106.4
1,1,8:106.2
-3,-3,9:17.2
-1,-3,9:17.2
-5,2,9:17.2
-6,2,9:17.2
-4,3,9:17.2
-4,4,9:17.2
1,5,9:17.2
0,5,9:17.2
2,4,9:17.2
3,4,9:17.2
4,-1,9:17.2
4,0,9:17.2
2,-1,9:17.2
2,-2,9:17.2
-2,-4,9:106.1
4,-3,9:106.2
3,3,9:106.4
-3,6,9:106.4
-8,3,9:106.8
-2,0,9:106.4
1,1,9:106.2
-3,-3,10:17.2
-1,-3,10:17.2
-6,2,10:17.2
-4,4,10:17.2
0,5,10:17.2
3,4,10:17.2
4,0,10:17.2
2,-2,10:17.2
-3,4,10:18.0
-4,5,10:18.0
-5,4,10:18.0
-6,1,10:18.0
-7,1,10:18.0
-7,2,10:18.0
-3,-4,10:18.0
-4,-3,10:18.0
-1,-4,10:18.0
0,-3,10:18.0
2,-3,10:18.0
3,-2,10:18.0
4,1,10:18.0
5,0,10:18.0
4,4,10:18.0
3,5,10:18.0
0,6,10:18.0
-1,5,10:18.0
-2,-4,10:106.1
4,-3,10:106.2
3,3,10:106.4
-3,6,10:106.4
-8,3,10:106.8
-2,0,10:106.4
1,1,10:106.2
0,0,10:18.0
0,1,10:18.0
-6,2,11:17.2
-3,-3,11:17.2
-1,-3,11:17.2
2,-2,11:17.2
4,0,11:17.2
3,4,11:17.2
0,5,11:17.2
-3,4,11:17.2
-4,4,11:17.2
0,6,11:17.2
-6,1,11:17.2
-4,-3,11:17.2
-1,-4,11:17.2
2,-3,11:17.2
5,0,11:17.2
3,5,11:17.2
4,5,11:17.2
-1,6,11:17.2
-4,5,11:17.2
-7,1,11:17.2
-4,-4,11:17.2
-1,-5,11:17.2
3,-3,11:17.2
5,1,11:17.2
-4,6,11:17.2
-8,1,11:17.2
-5,-4,11:17.2
-1,-6,11:17.2
3,-4,11:17.2
6,1,11:17.2
4,6,11:17.2
-1,7,11:17.2
-8,0,11:18.0
-9,0,11:18.0
-9,1,11:18.0
-9,2,11:18.0
-8,2,11:18.0
-5,-5,11:18.0
-6,-5,11:18.0
-6,-4,11:18.0
-6,-3,11:18.0
-5,-3,11:18.0
-2,-6,11:18.0
-2,-7,11:18.0
-1,-7,11:18.0
0,-7,11:18.0
0,-6,11:18.0
-3,-2,11:18.0
-1,-2,11:18.0
2,-4,11:18.0
2,-5,11:18.0
3,-5,11:18.0
4,-5,11:18.0
4,-4,11:18.0
6,0,11:18.0
7,0,11:18.0
7,1,11:18.0
7,2,11:18.0
6,2,11:18.0
2,-1,11:18.0
3,0,11:18.0
3,3,11:18.0
0,4,11:18.0
-2,4,11:18.0
-3,3,11:18.0
-5,2,11:18.0
-5,5,11:18.0
-5,6,11:18.0
-5,7,11:18.0
-4,7,11:18.0
-3,7,11:18.0
-3,6,11:18.0
-2,8,11:18.0
-1,8,11:18.0
0,8,11:18.0
0,7,11:18.0
3,6,11:18.0
3,7,11:18.0
4,7,11:18.0
5,7,11:18.0
5,6,11:18.0
-2,-4,11:106.1
-8,3,11:106.8
4,-3,11:106.2
-2,0,11:106.4
1,1,11:106.2
1,-1,11:18.0
1,0,11:18.0
0,0,11:18.0
-3,5,11:35.4
1,-2,11:35.4
-2,-3,11:35.4
2,4,11:35.4
-6,0,11:35.4
-4,6,12:17.2
-8,1,12:17.2
-5,-4,12:17.2
-3,-3,12:17.2
-1,-6,12:17.2
-1,-3,12:17.2
2,-2,12:17.2
3,-4,12:17.2
4,0,12:17.2
6,1,12:17.2
3,4,12:17.2
4,6,12:17.2
-8,0,12:18.0
-9,0,12:18.0
-9,1,12:18.0
-8,2,12:18.0
-9,2,12:18.0
-7,2,12:18.0
-7,1,12:18.0
-7,0,12:35.4
-4,5,12:18.0
-3,5,12:18.0
-3,6,12:35.4
-3,7,12:18.0
-4,7,12:18.0
-5,7,12:18.0
-5,6,12:18.0
-5,5,12:18.0
-1,7,12:18.0
-1,6,12:18.0
0,7,12:18.0
-1,8,12:18.0
-2,7,12:18.0
3,6,12:35.4
3,5,12:18.0
4,5,12:18.0
5,5,12:18.0
5,6,12:18.0
5,7,12:18.0
4,7,12:18.0
3,7,12:18.0
2,5,12:18.0
2,4,12:18.0
2,3,12:18.0
3,3,12:18.0
4,3,12:18.0
4,4,12:18.0
5,-1,12:18.0
5,0,12:18.0
5,1,12:18.0
5,2,12:18.0
6,2,12:18.0
7,2,12:18.0
7,1,12:18.0
7,0,12:18.0
6,0,12:18.0
4,-1,12:18.0
3,-1,12:18.0
3,0,12:18.0
3,1,12:18.0
4,1,12:35.4
3,-2,12:35.4
3,-3,12:18.0
2,-3,12:18.0
1,-3,12:18.0
1,-2,12:18.0
1,-1,12:18.0
2,-1,12:18.0
2,-4,12:18.0
2,-5,12:18.0
3,-5,12:18.0
4,-5,12:18.0
4,-4,12:18.0
4,-3,12:18.0
-1,-5,12:18.0
0,-5,12:18.0
0,-6,12:18.0
0,-7,12:18.0
-1,-7,12:18.0
-2,-7,12:18.0
-2,-6,12:35.4
-2,-5,12:18.0
-2,-4,12:18.0
-2,-3,12:18.0
-2,-2,12:18.0
-1,-2,12:18.0
0,-2,12:18.0
0,-3,12:18.0
0,-4,12:18.0
-1,-4,12:18.0
-3,-4,12:18.0
-4,-4,12:18.0
-4,-3,12:35.4
-4,-2,12:18.0
-3,-2,12:18.0
-4,-5,12:18.0
-5,-5,12:18.0
-6,-5,12:18.0
-6,-4,12:18.0
-6,-3,12:18.0
-5,-3,12:18.0
-3,-1,12:18.0
-2,-1,12:18.0
-1,-1,12:18.0
-6,1,12:18.0
-6,2,12:18.0
-4,4,12:18.0
-3,4,12:18.0
-6,6,12:18.0
-4,8,12:18.0
4,8,12:18.0
1,4,12:18.0
-2,0,12:18.0
-7,-4,12:18.0
-1,-8,12:18.0
-5,-6,12:18.0
3,-6,12:18.0
5,-4,12:18.0
8,1,12:18.0
6,3,12:18.0
6,6,12:18.0
-8,3,12:18.0
-10,1,12:18.0
-8,-1,12:18.0
-2,5,12:18.0
3,2,12:18.0
2,7,12:18.0
1,-6,12:18.0
-6,-2,12:18.0
-6,3,12:18.0
1,1,12:106.2
1,0,12:18.0
0,0,12:18.0
-8,0,13:18.0
-9,0,13:18.0
-9,1,13:18.0
-9,2,13:18.0
-8,2,13:18.0
-8,1,13:18.0
-7,1,13:18.0
-4,5,13:18.0
-4,6,13:18.0
-4,7,13:18.0
-3,6,13:18.0
-5,6,13:18.0
-6,-4,13:18.0
-5,-4,13:18.0
-5,-5,13:18.0
-4,-4,13:18.0
-4,-3,13:18.0
-3,-3,13:18.0
-2,-3,13:18.0
-2,-2,13:18.0
-1,-3,13:18.0
-1,-4,13:18.0
-1,-5,13:18.0
-1,-6,13:18.0
0,-3,13:18.0
2,-3,13:18.0
2,-2,13:18.0
3,-5,13:18.0
3,-4,13:18.0
3,-3,13:18.0
4,-4,13:18.0
0,-6,13:18.0
-1,-7,13:18.0
-2,-5,13:18.0
-6,-3,13:18.0
1,-1,13:18.0
4,-1,13:18.0
4,0,13:18.0
4,1,13:18.0
3,0,13:18.0
5,0,13:18.0
5,1,13:18.0
6,1,13:18.0
7,1,13:18.0
6,2,13:18.0
2,4,13:18.0
3,4,13:18.0
3,3,13:18.0
3,5,13:18.0
4,5,13:18.0
4,6,13:18.0
5,6,13:18.0
4,7,13:18.0
3,7,13:18.0
-1,7,13:18.0
-2,0,13:18.0
-6,3,13:18.0
1,1,13:18.0
1,0,13:18.0
0,0,13:18.0
-5,-4,14:18.0
-2,-3,14:18.0
-1,-6,14:18.0
3,-4,14:18.0
2,-2,14:18.0
4,0,14:18.0
6,1,14:18.0
3,4,14:18.0
4,6,14:18.0
-4,6,14:18.0
-8,1,14:18.0
-8,2,14:18.0
-4,-3,14:18.0
-2,-5,14:18.0
1,-1,14:18.0
4,1,14:18.0
