[META]
version=2.0
spawnOnBlockType=3,2,1
spawnSunlight=True
spawnDarkness=False
spawnWater=False
spawnLava=False
underFill=False
randomRotation=True
dig=False
tree=False
branch=False
needsFoundation=False
rarity=30
collisionPercentage=10
spawnElevationMin=0
spawnElevationMax=110
spawnInBiome=Urwald,Ocean,Tropical
[DATA]
-2,15,0:17.0
-2,16,0:17.0
-5,16,0:17.0
-5,17,0:17.0
-4,15,0:17.0
-4,16,0:17.0
-2,14,0:17.0
0,17,0:17.0
0,18,0:17.0
0,19,0:17.0
1,19,0:17.0
0,16,0:17.0
-2,-7,0:17.0
-2,7,0:17.0
-4,17,0:3
-3,17,0:3
-1,17,0:3
-1,18,0:3
0,20,0:3
2,20,0:3
-6,19,0:3
-5,18,0:72
-5,19,0:72
-2,18,0:72
-2,17,0:72
1,20,0:72
1,21,0:72
-1,7,0:72
-3,-7,0:72
-5,19,-1:17.0
-5,18,-1:17.0
-5,17,-1:17.0
-2,18,-1:17.0
-2,17,-1:17.0
-2,16,-1:17.0
1,21,-1:17.0
1,20,-1:17.0
1,19,-1:17.0
-2,-7,-1:17.0
-2,7,-1:17.0
-1,7,-1:17.0
-3,-7,-1:17.0
-5,19,-2:17.0
-2,18,-2:17.0
1,21,-2:17.0
-5,20,-2:72
-2,19,-2:72
1,22,-2:72
-5,20,-3:17.0
-2,19,-3:17.0
-2,18,-3:17.0
-5,19,-3:17.0
1,22,-3:17.0
1,21,-3:17.0
-5,20,-4:17.0
-2,19,-4:17.0
1,22,-4:17.0
-4,15,1:17.0
-4,14,1:17.0
-2,15,1:17.0
-2,14,1:17.0
-2,13,1:17.0
0,17,1:17.0
0,16,1:17.0
0,15,1:17.0
-2,12,1:17.0
-2,11,1:17.0
-2,10,1:17.0
-2,9,1:17.0
-2,8,1:17.0
-2,7,1:17.0
-2,6,1:17.0
-2,5,1:17.0
-2,4,1:17.0
-2,3,1:17.0
-2,2,1:17.0
-3,11,1:17.0
-3,12,1:17.0
-3,13,1:17.0
-3,14,1:17.0
-1,12,1:17.0
-1,13,1:17.0
-1,14,1:17.0
-1,15,1:17.0
-2,-3,1:17.0
-2,-4,1:17.0
-1,-17,1:17.0
-1,-18,1:17.0
-1,-19,1:17.0
-1,-20,1:17.0
-2,-7,1:17.0
1,-10,1:17.0
3,-9,1:17.0
-6,14,1:17.0
-7,14,1:17.0
-6,18,1:3
-4,17,1:3
-4,18,1:3
-5,18,1:3
-3,17,1:3
-3,18,1:3
-2,17,1:3
-1,17,1:3
-1,16,1:3
-3,16,1:3
-1,18,1:3
2,19,1:3
2,20,1:3
-1,20,1:3
0,20,1:3
-7,19,1:3
4,-9,1:18.1
-3,-4,1:18.1
-1,7,1:18.1
-2,-19,1:18.1
0,-10,1:18.1
1,-9,1:18.1
-3,-7,1:18.1
-3,5,1:18.1
-1,-21,1:18.1
0,-20,1:18.1
0,-19,1:18.1
1,-20,1:18.1
-1,-22,1:18.1
-3,-20,1:18.1
-3,-19,1:18.1
-4,-8,1:18.1
-3,-8,1:18.1
1,-11,1:18.1
2,-11,1:18.1
2,-12,1:18.1
4,-10,1:18.1
5,-9,1:18.1
-4,-4,1:18.1
-4,-3,1:18.1
-5,-4,1:18.1
-4,4,1:18.1
-4,5,1:18.1
0,7,1:18.1
1,7,1:18.1
0,6,1:18.1
-5,17,1:72
-5,16,1:72
-4,16,1:72
0,18,1:72
0,19,1:72
1,19,1:72
-2,16,1:72
-2,14,2:17.0
-2,13,2:17.0
-2,12,2:17.0
-2,11,2:17.0
-2,10,2:17.0
-2,9,2:17.0
-2,8,2:17.0
-2,7,2:17.0
-2,6,2:17.0
-2,5,2:17.0
-1,5,2:17.0
-1,4,2:17.0
-2,4,2:17.0
-2,3,2:17.0
-2,2,2:17.0
-3,3,2:17.0
-3,4,2:17.0
-3,5,2:17.0
-3,6,2:17.0
-3,7,2:17.0
-3,8,2:17.0
-3,9,2:17.0
-3,10,2:17.0
-3,11,2:17.0
-3,12,2:17.0
-3,13,2:17.0
-4,14,2:17.0
-3,14,2:17.0
0,15,2:17.0
0,14,2:17.0
-1,14,2:17.0
-1,13,2:17.0
-1,12,2:17.0
-1,11,2:17.0
-1,10,2:17.0
-1,9,2:17.0
-1,8,2:17.0
-1,7,2:17.0
-1,6,2:17.0
-2,-14,2:17.0
-2,-13,2:17.0
-2,-12,2:17.0
-2,-11,2:17.0
-2,-10,2:17.0
-2,-9,2:17.0
-2,-8,2:17.0
-2,-7,2:17.0
-2,-6,2:17.0
-2,-5,2:17.0
-2,-4,2:17.0
-2,-3,2:17.0
-1,-21,2:17.0
-1,-20,2:17.0
-1,-19,2:17.0
-1,-18,2:17.0
-1,-17,2:17.0
-1,-16,2:17.0
-1,-15,2:17.0
-1,-14,2:17.0
-1,-13,2:17.0
-1,-12,2:17.0
-1,-22,2:17.0
-3,-10,2:17.0
-3,-9,2:17.0
-3,-8,2:17.0
-3,-7,2:17.0
-3,-6,2:17.0
-3,-5,2:17.0
-3,-4,2:17.0
-3,-3,2:17.0
-1,-4,2:17.0
-1,-3,2:17.0
-3,-2,2:17.0
-1,-2,2:17.0
-1,-7,2:17.0
0,-7,2:17.0
1,-8,2:17.0
0,-8,2:17.0
2,-9,2:17.0
1,-9,2:17.0
3,-9,2:17.0
1,-10,2:17.0
-2,-17,2:17.0
-3,-17,2:17.0
-3,-18,2:17.0
-4,-18,2:17.0
-4,-9,2:17.0
-5,-10,2:17.0
-5,-9,2:17.0
-4,4,2:17.0
-5,4,2:17.0
0,7,2:17.0
1,7,2:17.0
-5,14,2:17.0
-6,14,2:17.0
-1,15,2:17.0
-5,15,2:3
-3,15,2:72
1,16,2:3
1,17,2:3
-2,18,2:3
-4,17,2:3
-3,17,2:3
-4,-19,2:18.1
-4,-17,2:18.1
-5,-18,2:18.1
-5,-11,2:18.1
-6,-10,2:18.1
0,-10,2:18.1
1,-11,2:18.1
2,-10,2:18.1
3,-8,2:18.1
4,-9,2:18.1
1,-7,2:18.1
0,-6,2:18.1
1,6,2:18.1
2,7,2:18.1
1,8,2:18.1
-5,3,2:18.1
-6,4,2:18.1
-5,5,2:18.1
-5,-8,2:18.1
-2,-21,2:18.1
0,-19,2:18.1
-3,-14,2:18.1
-4,9,2:18.1
0,11,2:18.1
-2,-23,2:18.1
-2,-22,2:18.1
-3,-22,2:18.1
-1,-23,2:18.1
0,-23,2:18.1
0,-22,2:18.1
1,-20,2:18.1
1,-21,2:18.1
-3,-20,2:18.1
-2,-18,2:18.1
0,-17,2:18.1
-3,-16,2:18.1
0,-14,2:18.1
-7,14,2:72
-2,15,2:72
0,16,2:72
0,17,2:72
0,15,3:17.0
0,16,3:17.0
1,16,3:17.0
1,17,3:17.0
-4,14,3:17.0
-4,15,3:17.0
-5,15,3:17.0
-5,16,3:17.0
-2,2,3:17.0
-2,3,3:17.0
-2,4,3:17.0
-2,5,3:17.0
-2,6,3:17.0
-2,7,3:17.0
-2,8,3:17.0
-2,9,3:17.0
-2,10,3:17.0
-2,11,3:17.0
-2,12,3:17.0
-2,13,3:17.0
-2,14,3:17.0
-3,6,3:17.0
-3,7,3:17.0
-3,8,3:17.0
-3,9,3:17.0
-3,10,3:17.0
-3,11,3:17.0
-3,12,3:17.0
-3,13,3:17.0
-3,14,3:17.0
-1,7,3:17.0
-1,8,3:17.0
-1,9,3:17.0
-1,10,3:17.0
-1,11,3:17.0
-1,12,3:17.0
-1,13,3:17.0
-1,14,3:17.0
-3,15,3:17.0
-1,15,3:17.0
-3,-1,3:17.0
-3,-2,3:17.0
-3,-3,3:17.0
-3,-4,3:17.0
-3,-5,3:17.0
-3,-6,3:17.0
-1,-1,3:17.0
-1,-2,3:17.0
-1,-3,3:17.0
-1,-4,3:17.0
-1,-5,3:17.0
-1,-6,3:17.0
-1,-7,3:17.0
-2,-4,3:17.0
-2,-5,3:17.0
-2,-6,3:17.0
-2,-7,3:17.0
-2,-8,3:17.0
-2,-9,3:17.0
-2,-10,3:17.0
-2,-11,3:17.0
-2,-12,3:17.0
-2,-13,3:17.0
-3,-8,3:17.0
-3,-7,3:17.0
-1,-11,3:17.0
-1,-12,3:17.0
-1,-13,3:17.0
-1,-14,3:17.0
-1,-15,3:17.0
-1,-16,3:17.0
-1,-17,3:17.0
-1,-18,3:17.0
-1,-19,3:17.0
-5,-10,3:17.0
-6,-10,3:17.0
-4,-18,3:17.0
-5,-18,3:17.0
-5,-19,3:17.0
-3,-17,3:17.0
-3,-16,3:17.0
-5,4,3:17.0
-6,4,3:17.0
-6,3,3:17.0
-5,5,3:17.0
1,7,3:17.0
1,6,3:17.0
2,6,3:17.0
3,-9,3:17.0
3,-8,3:17.0
1,-10,3:17.0
1,-11,3:17.0
2,-11,3:17.0
0,-7,3:17.0
1,-7,3:17.0
-2,15,3:17.0
-2,16,3:17.0
-1,-20,3:18.1
-1,-21,3:18.1
-3,-20,3:18.1
-2,-21,3:18.1
-2,-20,3:18.1
0,-22,3:18.1
-1,-22,3:18.1
-1,-23,3:18.1
-4,-17,3:18.1
-6,-18,3:18.1
-5,-20,3:18.1
-6,-19,3:18.1
1,-20,3:18.1
-3,-13,3:18.1
-4,-13,3:18.1
-2,-14,3:18.1
0,-14,3:18.1
1,-14,3:18.1
1,-15,3:18.1
0,-17,3:18.1
1,-17,3:18.1
1,-18,3:18.1
2,-20,3:18.1
2,-12,3:18.1
3,-11,3:18.1
1,-8,3:18.1
0,-8,3:18.1
-4,-9,3:18.1
-5,-8,3:18.1
-6,-8,3:18.1
-5,-7,3:18.1
-7,-9,3:18.1
-7,-10,3:18.1
-8,-10,3:18.1
-7,-11,3:18.1
-4,-10,3:18.1
2,-9,3:18.1
1,-6,3:18.1
0,-5,3:18.1
3,-7,3:18.1
4,-9,3:18.1
0,-12,3:18.1
4,-11,3:18.1
4,-12,3:18.1
-5,-15,3:18.1
-5,-14,3:18.1
-5,-13,3:18.1
-6,-13,3:18.1
-7,-18,3:18.1
-2,-22,3:18.1
-6,14,3:72
-5,14,3:72
-4,4,3:72
-3,4,3:72
-3,3,3:72
-3,5,3:72
-1,4,3:72
-1,5,3:72
-1,6,3:72
0,7,3:72
0,14,3:72
-2,-3,3:72
1,-9,3:72
-5,-9,3:72
-3,-9,3:72
-3,-10,3:72
-2,-17,3:72
-3,-18,3:72
-2,6,4:17.0
-2,7,4:17.0
-2,8,4:17.0
-2,9,4:17.0
-2,10,4:17.0
-2,11,4:17.0
-2,12,4:17.0
-2,13,4:17.0
-2,14,4:17.0
-3,14,4:17.0
-5,16,4:17.0
-5,17,4:17.0
-6,17,4:17.0
-3,15,4:17.0
-3,16,4:17.0
1,17,4:17.0
-1,-16,4:17.0
-1,-15,4:17.0
-1,-14,4:17.0
-1,-13,4:17.0
-1,-12,4:17.0
-1,-11,4:17.0
-2,-12,4:17.0
-2,-11,4:17.0
-2,-10,4:17.0
-2,-9,4:17.0
-2,-8,4:17.0
-2,-7,4:17.0
-2,-6,4:17.0
-2,-5,4:17.0
-2,-4,4:17.0
-2,-3,4:17.0
-2,16,4:17.0
-2,15,4:17.0
-2,17,4:17.0
0,-16,4:17.0
1,-16,4:17.0
1,-17,4:17.0
2,-17,4:17.0
2,-18,4:17.0
2,-19,4:17.0
3,-19,4:17.0
3,-20,4:17.0
-4,16,4:3
-4,17,4:3
-1,16,4:3
-1,17,4:3
0,17,4:3
-5,18,4:3
-6,18,4:3
-7,17,4:3
1,18,4:3
2,-20,4:18.1
3,-21,4:18.1
4,-20,4:18.1
3,-17,4:18.1
1,-15,4:18.1
0,-19,4:18.1
-1,-19,4:18.1
-6,3,4:18.1
-6,-10,4:18.1
-6,-11,4:18.1
-5,-19,4:18.1
-6,-18,4:18.1
-5,-18,4:18.1
-6,4,4:18.1
-7,3,4:18.1
2,-11,4:18.1
3,-11,4:18.1
3,-8,4:18.1
4,-8,4:18.1
3,-7,4:18.1
-1,-4,4:18.1
0,-4,4:18.1
2,6,4:18.1
2,5,4:18.1
3,6,4:18.1
1,7,4:18.1
0,7,4:18.1
-3,9,4:18.1
-4,9,4:18.1
-5,15,4:72
-4,15,4:72
-4,14,4:72
-3,13,4:72
-3,12,4:72
-3,11,4:72
-3,10,4:72
-3,8,4:72
-3,7,4:72
-3,6,4:72
-5,4,4:72
-5,5,4:72
-2,2,4:72
-2,3,4:72
-2,4,4:72
-2,5,4:72
1,6,4:72
-1,7,4:72
-1,8,4:72
-1,9,4:72
-1,10,4:72
-1,11,4:72
-1,12,4:72
-1,13,4:72
-1,14,4:72
-1,15,4:72
0,15,4:72
0,16,4:72
1,16,4:72
-3,-1,4:72
-1,-1,4:72
-1,-2,4:72
-1,-3,4:72
-1,-5,4:72
-1,-6,4:72
-1,-7,4:72
0,-7,4:72
1,-7,4:72
1,-11,4:72
1,-10,4:72
3,-9,4:72
-3,-8,4:72
-3,-7,4:72
-3,-6,4:72
-3,-5,4:72
-3,-4,4:72
-3,-3,4:72
-3,-2,4:72
-5,-10,4:72
-3,-16,4:72
-3,-17,4:72
-4,-18,4:72
-2,-13,4:72
-1,-17,4:72
-1,-18,4:72
-5,17,5:17.0
-6,17,5:17.0
-3,16,5:17.0
-3,17,5:17.0
1,17,5:17.0
-7,17,5:17.0
-8,17,5:17.0
-8,18,5:17.0
-9,18,5:17.0
1,18,5:17.0
2,18,5:17.0
3,18,5:17.0
3,19,5:17.0
4,19,5:17.0
4,20,5:17.0
-2,17,5:17.0
-1,17,5:17.0
-2,18,5:17.0
-2,-12,5:17.0
2,-18,5:17.0
-1,-14,5:17.0
0,-14,5:18.1
-7,18,5:3
-7,16,5:3
-6,16,5:3
-1,18,5:3
2,19,5:3
3,20,5:3
4,18,5:3
4,21,5:3
-9,19,5:3
5,20,5:3
-10,18,5:3
-1,-15,5:18.1
-2,-15,5:18.1
-2,-14,5:18.1
-3,-12,5:18.1
-3,-11,5:18.1
-2,-11,5:18.1
-1,-13,5:18.1
1,-18,5:18.1
2,-19,5:18.1
2,-17,5:18.1
3,-18,5:18.1
1,-14,5:18.1
0,-13,5:18.1
-2,16,5:72
-4,16,5:72
-4,17,5:72
-5,18,5:72
-6,18,5:72
-5,16,5:72
-3,15,5:72
-2,15,5:72
-3,14,5:72
-2,14,5:72
-2,13,5:72
-2,12,5:72
-1,16,5:72
0,17,5:72
-2,11,5:72
-2,10,5:72
-2,9,5:72
-2,8,5:72
-2,7,5:72
-2,6,5:72
-1,-16,5:72
0,-16,5:72
1,-16,5:72
1,-17,5:72
3,-19,5:72
3,-20,5:72
-1,-12,5:72
-1,-11,5:72
-2,-10,5:72
-2,-9,5:72
-2,-8,5:72
-2,-7,5:72
-2,-6,5:72
-2,-5,5:72
-2,-4,5:72
-2,-3,5:72
-6,17,6:17.0
-6,18,6:17.0
-6,19,6:17.0
-3,17,6:17.0
1,17,6:17.0
2,17,6:17.0
2,18,6:17.0
-5,19,6:17.0
-5,20,6:17.0
-4,20,6:17.0
-4,21,6:17.0
-2,-12,6:17.0
2,-18,6:17.0
0,-14,6:17.0
1,-14,6:17.0
1,-15,6:17.0
-3,21,6:3
2,-19,6:18.1
2,-17,6:18.1
1,-18,6:18.1
2,-14,6:18.1
-3,-13,6:18.1
-2,-11,6:18.1
-5,17,6:72
-7,17,6:72
-3,16,6:72
-2,17,6:72
-2,18,6:72
-1,17,6:72
1,18,6:72
3,19,6:72
3,18,6:72
4,19,6:72
4,20,6:72
-1,-14,6:72
-6,19,7:17.0
-3,17,7:17.0
2,18,7:17.0
-4,21,7:17.0
-2,-12,7:17.0
-2,-13,7:17.0
2,-18,7:17.0
1,-18,7:17.0
0,-18,7:17.0
0,-19,7:17.0
1,-15,7:18.1
-5,21,7:3
1,18,7:3
2,19,7:3
-7,18,7:3
0,-20,7:18.1
-1,-20,7:18.1
-1,-19,7:18.1
-1,-18,7:18.1
1,-19,7:18.1
3,-18,7:18.1
2,-15,7:18.1
1,-16,7:18.1
0,-15,7:18.1
1,-14,7:18.1
-1,-12,7:18.1
-3,-12,7:18.1
-2,-14,7:18.1
0,-14,7:72
-5,20,7:72
-4,20,7:72
-5,19,7:72
-6,18,7:72
-6,17,7:72
1,17,7:72
2,17,7:72
-6,20,8:17.0
-6,19,8:17.0
-3,17,8:17.0
-3,18,8:17.0
-2,-14,8:17.0
-2,-13,8:17.0
2,-18,8:18.1
1,-15,8:18.1
-2,-12,8:18.1
-3,-14,8:18.1
-2,-15,8:18.1
-1,-14,8:18.1
0,-19,8:72
0,-18,8:72
1,-18,8:72
-4,21,8:72
2,18,8:72
-6,20,9:17.0
-3,18,9:17.0
-2,-14,9:17.0
-2,-15,9:18.1
-3,17,9:72
-6,19,9:72
-2,-13,9:72
-3,18,10:17.0
-2,18,10:17.0
-2,-14,10:17.0
-3,-14,10:17.0
-2,-15,10:18.1
-2,-13,10:18.1
-4,-14,10:18.1
-1,-14,10:18.1
-6,20,10:72
-2,18,11:17.0
-2,-14,11:17.0
-1,-14,11:17.0
-1,-15,11:17.0
0,-15,11:17.0
-3,-14,11:18.1
0,-16,11:18.1
1,-15,11:18.1
0,-14,11:18.1
-3,18,11:72
-2,-14,12:17.0
-3,-15,12:18.1
-2,-13,12:18.1
-2,-15,12:18.1
-1,-15,12:18.1
0,-15,12:18.1
-3,-14,12:18.1
-3,-13,12:18.1
-1,-14,12:18.1
-2,18,12:72
-2,-14,13:18.1
