[META]
version=2.0
spawnOnBlockType=2,3
spawnSunlight=True
spawnDarkness=True
spawnWater=False
spawnLava=False
underFill=True
randomRotation=True
dig=True
tree=False
branch=False
needsFoundation=True
rarity=3
collisionPercentage=0
spawnElevationMin=60
spawnElevationMax=75
spawnInBiome=Ice Plains
[DATA]
-5,-2,0:80
-5,-1,0:80
-5,0,0:80
-5,1,0:80
-5,2,0:80
-4,3,0:80
-3,4,0:80
-2,4,0:80
-1,4,0:80
0,4,0:80
1,4,0:80
2,3,0:80
3,2,0:80
3,1,0:80
3,-1,0:80
3,-2,0:80
2,-3,0:80
-3,-4,0:80
-2,-4,0:80
-1,-4,0:80
0,-4,0:80
1,-4,0:80
-4,-3,0:80
0,-4,-1:80
-1,-4,-1:80
1,-4,-1:80
2,-3,-1:80
3,-2,-1:80
3,-1,-1:80
3,2,-1:80
2,3,-1:80
3,0,-1:80
3,1,-1:80
-2,-4,-1:80
1,4,-1:80
0,4,-1:80
-1,4,-1:80
-2,4,-1:80
-3,4,-1:80
-3,-4,-1:80
-4,-3,-1:80
-4,3,-1:80
-5,-2,-1:80
-5,-1,-1:80
-5,0,-1:80
-5,1,-1:80
-5,2,-1:80
-4,-2,1:80
-4,-1,1:80
-4,0,1:80
-4,1,1:80
-4,2,1:80
-3,3,1:80
-2,3,1:80
-1,3,1:80
0,3,1:80
1,3,1:80
2,2,1:80
2,1,1:80
2,-1,1:80
2,-2,1:80
-3,-3,1:80
-2,-3,1:80
-1,-3,1:80
0,-3,1:80
1,-3,1:80
-1,-4,1:80
-5,0,1:80
-1,4,1:80
-3,-4,1:80
-2,-4,1:80
0,-4,1:80
1,-4,1:80
2,-3,1:80
3,-2,1:80
3,-1,1:80
3,1,1:80
3,2,1:80
2,3,1:80
1,4,1:80
0,4,1:80
-2,4,1:80
-3,4,1:80
-4,3,1:80
-5,2,1:80
-5,1,1:80
-5,-1,1:80
-5,-2,1:80
-4,-3,1:80
2,-2,2:80
2,-1,2:80
2,1,2:80
2,2,2:80
1,3,2:80
0,3,2:80
-2,3,2:80
-3,3,2:80
-4,2,2:80
-4,1,2:80
-4,-1,2:80
-4,-2,2:80
-3,-3,2:80
-2,-3,2:80
0,-3,2:80
1,-3,2:80
-1,-4,2:80
-5,0,2:80
-1,4,2:80
3,-1,2:80
3,1,2:80
-3,-2,3:80
1,-2,3:80
1,2,3:80
0,3,3:80
-1,3,3:80
-2,3,3:80
-3,2,3:80
-2,-3,3:80
-1,-3,3:80
0,-3,3:80
-4,-1,3:80
-4,0,3:80
-4,1,3:80
2,-1,3:80
3,-1,3:80
2,1,3:80
3,1,3:80
3,0,3:80
2,0,3:80
-3,-1,4:80
-3,0,4:80
-3,1,4:80
1,1,4:80
1,0,4:80
1,-1,4:80
-2,-2,4:80
-1,-2,4:80
0,-2,4:80
-2,2,4:80
-1,2,4:80
0,2,4:80
2,0,4:80
-2,-1,4:80
-2,0,4:80
-2,1,4:80
-1,1,4:80
-1,0,4:80
0,0,4:80
0,-1,4:80
0,1,4:80
-1,-1,4:80
