[META]
version=2.0
spawnOnBlockType=3,2,12
spawnSunlight=True
spawnDarkness=True
spawnWater=False
spawnLava=False
underFill=False
randomRotation=True
dig=False
tree=False
branch=True
needsFoundation=False
diggingBranch=True
rarity=550
collisionPercentage=5
spawnElevationMin=0
spawnElevationMax=128
spawnInBiome=Urwald,Urwald2,Plain
[DATA]
-5,-5,0:17.1
-4,-5,0:17.1
-3,-5,0:17.1
-3,-4,0:17.1
-2,-4,0:17.1
-2,-3,0:17.1
-1,-3,0:17.1
-1,-2,0:17.1
-1,-7,0:17.1
-1,-6,0:17.1
-1,-5,0:17.1
-1,-4,0:17.1
-4,1,0:17.1
-4,0,0:17.1
-3,0,0:17.1
-3,-1,0:17.1
-2,-1,0:17.1
-1,-1,0:17.1
-1,0,0:17.1
-1,1,0:17.1
-1,2,0:17.1
-4,4,0:17.1
-4,3,0:17.1
-3,3,0:17.1
-2,3,0:17.1
-1,3,0:17.1
0,2,0:17.1
1,2,0:17.1
1,3,0:17.1
1,4,0:17.1
1,5,0:17.1
2,5,0:17.1
2,6,0:17.1
0,0,0:17.1
1,0,0:17.1
2,0,0:17.1
2,2,0:17.1
3,2,0:17.1
3,3,0:17.1
4,3,0:17.1
5,3,0:17.1
0,-2,0:17.1
1,-2,0:17.1
2,-2,0:17.1
3,-2,0:17.1
4,-2,0:17.1
4,-3,0:17.1
1,-3,0:17.1
1,-4,0:17.1
2,-4,0:17.1
2,-5,0:17.1
-5,1,0:17.1
-5,4,0:17.1
-5,5,0:17.1
0,-1,0:17.1
0,1,0:17.1
-7,7,0:31.1
-6,4,0:31.1
-7,1,0:31.1
-6,0,0:31.1
-5,3,0:31.1
-2,1,0:31.1
-2,0,0:31.1
-4,-4,0:31.1
-5,-6,0:31.1
-7,-5,0:31.1
-2,-6,0:31.1
-2,-5,0:31.1
-1,-9,0:31.1
0,-4,0:31.1
0,-3,0:31.1
4,-7,0:31.1
2,-3,0:31.1
2,-1,0:31.1
1,-1,0:31.1
3,0,0:31.1
6,-2,0:31.1
6,2,0:31.1
5,4,0:31.1
0,3,0:31.1
0,4,0:31.1
-1,4,0:31.1
3,6,0:31.1
3,-7,-1:17.1
3,-6,-1:17.1
3,-5,-1:17.1
2,-5,-1:17.1
2,-4,-1:17.1
1,-4,-1:17.1
1,-3,-1:17.1
1,-2,-1:17.1
-2,-9,-1:17.1
-2,-8,-1:17.1
-1,-8,-1:17.1
-1,-7,-1:17.1
-1,-6,-1:17.1
-1,-5,-1:17.1
-1,-4,-1:17.1
-1,-3,-1:17.1
-1,-2,-1:17.1
0,-2,-1:17.1
-2,-3,-1:17.1
-2,-4,-1:17.1
-3,-4,-1:17.1
-3,-5,-1:17.1
-4,-5,-1:17.1
-5,-5,-1:17.1
-6,-6,-1:17.1
-6,-5,-1:17.1
-1,-1,-1:17.1
-2,-1,-1:17.1
-3,-1,-1:17.1
-3,0,-1:17.1
-4,0,-1:17.1
-4,1,-1:17.1
-1,0,-1:17.1
-1,1,-1:17.1
-1,2,-1:17.1
-1,3,-1:17.1
-2,3,-1:17.1
-3,3,-1:17.1
-4,3,-1:17.1
-4,4,-1:17.1
-5,4,-1:17.1
-5,5,-1:17.1
-6,5,-1:17.1
-6,6,-1:17.1
-6,7,-1:17.1
0,1,-1:17.1
0,2,-1:17.1
1,2,-1:17.1
1,3,-1:17.1
1,4,-1:17.1
1,5,-1:17.1
2,5,-1:17.1
2,6,-1:17.1
0,0,-1:17.1
1,0,-1:17.1
2,0,-1:17.1
2,1,-1:17.1
2,2,-1:17.1
3,2,-1:17.1
3,3,-1:17.1
4,3,-1:17.1
5,3,-1:17.1
6,3,-1:17.1
2,-2,-1:17.1
3,-2,-1:17.1
4,-2,-1:17.1
5,-2,-1:17.1
-5,1,-1:17.1
-6,1,-1:17.1
4,-3,-1:17.1
5,-1,-1:17.1
6,-1,-1:17.1
6,4,-1:17.1
-5,3,-1:3
-4,-4,-1:3
-2,-5,-1:3
-2,-6,-1:3
0,-3,-1:3
0,-4,-1:3
0,-1,-1:3
1,-1,-1:3
0,3,-1:3
0,4,-1:3
-1,4,-1:3
-2,0,-1:3
-2,1,-1:3
2,-1,-1:3
3,0,-1:3
2,-3,-1:3
-6,4,-1:3
-5,-6,-1:3
-1,-9,-1:3
3,6,-1:3
6,2,-1:3
6,-2,-1:3
4,-7,-1:3
-7,7,-1:3
-6,0,-1:3
-7,-5,-1:3
-7,1,-1:3
5,4,-1:3
-1,-5,1:17.1
-1,-4,1:17.1
-4,0,1:17.1
-3,0,1:17.1
-1,2,1:17.1
-1,3,1:17.1
1,5,1:17.1
2,5,1:17.1
1,4,1:17.1
2,2,1:17.1
3,2,1:17.1
1,-3,1:17.1
1,-2,1:17.1
1,0,1:17.1
2,0,1:17.1
-3,-4,1:17.1
-1,-1,1:17.1
-1,0,1:17.1
-3,-4,2:17.1
-1,-4,2:17.1
-1,0,2:17.1
1,0,2:17.1
1,-2,2:17.1
-1,2,2:17.1
1,4,2:17.1
2,2,2:17.1
-3,0,2:17.1
-3,-4,3:17.1
-1,-4,3:17.1
-3,0,3:17.1
-1,0,3:17.1
-1,2,3:17.1
2,2,3:17.1
1,4,3:17.1
1,0,3:17.1
1,-2,3:17.1
-1,-4,4:17.1
-1,-3,4:17.1
-3,-4,4:17.1
-3,-3,4:17.1
-3,0,4:17.1
-2,0,4:17.1
-1,0,4:17.1
1,0,4:17.1
1,-2,4:17.1
0,-2,4:17.1
0,0,4:17.1
-1,2,4:17.1
-1,1,4:17.1
2,2,4:17.1
1,2,4:17.1
1,4,4:17.1
1,3,4:17.1
-3,-3,5:17.1
-3,-2,5:17.1
-2,0,5:17.1
-1,0,5:17.1
-1,1,5:17.1
-1,-3,5:17.1
-1,-2,5:17.1
0,-2,5:17.1
0,0,5:17.1
1,1,5:17.1
1,2,5:17.1
-3,-2,6:17.1
-1,-2,6:17.1
-2,0,6:17.1
0,0,6:17.1
1,1,6:17.1
0,1,6:17.1
-3,-2,7:17.1
-2,-1,7:17.1
-2,0,7:17.1
-1,-1,7:17.1
-1,0,7:17.1
0,0,7:17.1
-1,-2,7:17.1
1,1,7:17.1
0,1,7:17.1
-2,-1,8:17.1
-2,0,8:17.1
-1,0,8:17.1
-1,-1,8:17.1
-5,-8,8:106.1
0,5,8:106.4
4,0,8:106.2
-8,1,8:106.8
-2,-1,9:17.1
-2,0,9:17.1
-1,0,9:17.1
-1,-1,9:17.1
-5,-8,9:106.1
-2,-4,9:106.1
0,5,9:106.4
4,0,9:106.2
-8,1,9:106.8
-2,-1,10:17.1
-2,0,10:17.1
-1,0,10:17.1
-1,-1,10:17.1
0,-8,10:106.1
-5,-8,10:106.1
-2,-4,10:106.1
0,5,10:106.4
-4,6,10:106.4
4,0,10:106.2
-8,1,10:106.8
-3,0,11:17.1
-4,0,11:17.1
-4,1,11:17.1
-2,-2,11:17.1
-3,-2,11:17.1
-3,-3,11:17.1
0,-1,11:17.1
0,-2,11:17.1
0,-3,11:17.1
1,-3,11:17.1
-1,1,11:17.1
0,1,11:17.1
0,2,11:17.1
0,3,11:17.1
-2,1,11:17.1
-2,2,11:17.1
-2,3,11:17.1
-5,1,11:17.1
-4,-3,11:17.1
-4,-4,11:17.1
0,-4,11:17.1
-1,-4,11:17.1
-1,-5,11:17.1
1,3,11:17.1
-3,3,11:17.1
-2,-1,11:17.1
-2,0,11:17.1
-1,0,11:17.1
-1,-1,11:17.1
0,-8,11:106.1
-5,-8,11:106.1
-2,-4,11:106.1
0,5,11:106.4
-4,6,11:106.4
4,0,11:106.2
-8,1,11:106.8
-4,-4,12:17.1
-4,-3,12:17.1
-5,1,12:17.1
-4,1,12:17.1
-3,3,12:17.1
-2,3,12:17.1
0,3,12:17.1
1,3,12:17.1
0,-3,12:17.1
1,-3,12:17.1
-1,-5,12:17.1
0,-1,12:17.1
0,1,12:17.1
-2,-2,12:17.1
-2,1,12:17.1
0,-8,12:106.1
-5,-8,12:106.1
-2,-4,12:106.1
0,5,12:106.4
-4,6,12:106.4
4,0,12:106.2
-8,1,12:106.8
-5,1,13:17.1
-4,-4,13:17.1
-1,-5,13:17.1
1,-3,13:17.1
-2,-2,13:17.1
0,-1,13:17.1
0,1,13:17.1
-2,1,13:17.1
-3,4,13:17.1
-3,3,13:17.1
1,3,13:17.1
0,-8,13:106.1
-5,-8,13:106.1
-2,-4,13:106.1
0,5,13:106.4
-4,6,13:106.4
4,0,13:106.2
-8,1,13:106.8
-3,4,14:17.1
-5,1,14:17.1
-4,-4,14:17.1
-4,-5,14:17.1
-6,1,14:17.1
-1,-5,14:17.1
-1,-6,14:17.1
1,-3,14:17.1
2,-3,14:17.1
0,-1,14:17.1
1,-1,14:17.1
0,1,14:17.1
1,1,14:17.1
1,3,14:17.1
1,4,14:17.1
-2,-2,14:17.1
-3,-2,14:17.1
-2,1,14:17.1
-2,2,14:17.1
0,-8,14:106.1
-5,-8,14:106.1
-2,-4,14:106.1
0,5,14:106.4
-4,6,14:106.4
4,0,14:106.2
-8,1,14:106.8
-4,-5,15:17.1
-1,-6,15:17.1
2,-3,15:17.1
1,-1,15:17.1
1,1,15:17.1
1,4,15:17.1
-2,2,15:17.1
-3,-2,15:17.1
-6,1,15:17.1
-3,4,15:17.1
0,-8,15:106.1
-5,-8,15:106.1
-2,-4,15:106.1
0,5,15:106.4
-4,6,15:106.4
4,0,15:106.2
-8,1,15:106.8
-6,1,16:17.1
-3,-2,16:17.1
-4,-5,16:17.1
-1,-6,16:17.1
2,-3,16:17.1
1,-1,16:17.1
1,1,16:17.1
1,4,16:17.1
1,5,16:17.1
2,5,16:17.1
-2,2,16:17.1
-3,2,16:17.1
-3,4,16:17.1
-3,5,16:17.1
-6,2,16:17.1
-4,-2,16:17.1
-4,-1,16:17.1
-4,-6,16:17.1
-5,-6,16:17.1
0,-6,16:17.1
0,-7,16:17.1
3,-3,16:17.1
3,-4,16:17.1
2,-1,16:17.1
2,1,16:17.1
2,2,16:17.1
3,2,16:17.1
0,-1,16:17.1
0,-2,16:17.1
-2,-3,16:17.1
-2,-2,16:17.1
-2,1,16:17.1
-4,4,16:17.1
-7,1,16:17.1
-5,-7,16:17.1
0,-5,16:17.1
4,-3,16:17.1
2,6,16:17.1
3,6,16:17.1
0,-8,16:106.1
-5,-8,16:106.1
-2,-4,16:106.1
0,5,16:106.4
-4,6,16:106.4
4,0,16:106.2
-8,1,16:106.8
-5,-7,17:17.1
-4,-1,17:17.1
-7,1,17:17.1
-3,5,17:17.1
-3,2,17:17.1
-2,1,17:17.1
0,-7,17:17.1
0,-5,17:17.1
3,-4,17:17.1
4,-3,17:17.1
2,-1,17:17.1
0,-2,17:17.1
-2,-3,17:17.1
1,1,17:17.1
3,2,17:17.1
1,4,17:17.1
3,6,17:17.1
0,-8,17:106.1
-5,-8,17:106.1
-2,-4,17:106.1
0,5,17:106.4
-4,6,17:106.4
4,0,17:106.2
-8,1,17:106.8
-5,-7,18:17.1
-7,1,18:17.1
-4,-1,18:17.1
-2,-3,18:17.1
0,-5,18:17.1
0,-7,18:17.1
4,-3,18:17.1
2,-1,18:17.1
1,1,18:17.1
0,-2,18:17.1
-2,1,18:17.1
-3,2,18:17.1
-3,5,18:17.1
1,4,18:17.1
3,2,18:17.1
3,6,18:17.1
-5,-8,18:106.1
0,-8,18:106.1
-2,-4,18:106.1
0,5,18:106.4
-4,6,18:106.4
4,0,18:106.2
-8,1,18:106.8
-5,-7,19:17.1
-7,1,19:17.1
-4,-1,19:17.1
-2,1,19:17.1
-3,2,19:17.1
-3,5,19:17.1
-2,-3,19:17.1
0,-5,19:17.1
0,-7,19:17.1
4,-3,19:17.1
2,-1,19:17.1
0,-2,19:17.1
1,1,19:17.1
3,2,19:17.1
1,4,19:17.1
3,6,19:17.1
-4,-7,19:18.2
-6,-7,19:18.2
-5,-8,19:18.2
-5,-6,19:18.2
-7,0,19:18.2
-8,1,19:18.2
-7,2,19:18.2
-6,1,19:18.2
-5,-1,19:18.2
-4,0,19:18.2
-4,-2,19:18.2
-3,-1,19:18.2
-3,-3,19:18.2
-2,-2,19:18.2
-1,-3,19:18.2
-2,-4,19:18.2
-1,-5,19:18.2
0,-4,19:18.2
1,-5,19:18.2
0,-6,19:18.2
-1,-7,19:18.2
1,-7,19:18.2
0,-8,19:18.2
0,-3,19:18.2
1,-2,19:18.2
-1,-2,19:18.2
0,-1,19:18.2
1,-1,19:18.2
2,-2,19:18.2
2,0,19:18.2
3,-1,19:18.2
3,-3,19:18.2
4,-2,19:18.2
4,-4,19:18.2
5,-3,19:18.2
2,1,19:18.2
1,0,19:18.2
0,1,19:18.2
1,2,19:18.2
2,2,19:18.2
3,1,19:18.2
4,2,19:18.2
3,3,19:18.2
1,3,19:18.2
2,4,19:18.2
0,4,19:18.2
1,5,19:18.2
3,5,19:18.2
2,6,19:18.2
3,7,19:18.2
4,6,19:18.2
-2,5,19:18.2
-3,4,19:18.2
-3,6,19:18.2
-4,5,19:18.2
-4,2,19:18.2
-3,1,19:18.2
-2,0,19:18.2
-1,1,19:18.2
-2,2,19:18.2
-3,3,19:18.2
0,5,19:106.4
-4,6,19:106.4
4,0,19:106.2
-5,-7,20:17.1
-5,-8,20:17.1
-6,-7,20:17.1
-7,0,20:17.1
-6,2,20:17.1
-7,1,20:17.1
-4,-2,20:17.1
-5,-1,20:17.1
-4,-1,20:17.1
-2,-3,20:17.1
-2,-4,20:17.1
-2,-5,20:17.1
-3,-5,20:17.1
0,-5,20:17.1
0,-4,20:17.1
1,-5,20:17.1
0,-7,20:17.1
-1,-7,20:17.1
0,-8,20:17.1
1,-7,20:17.1
4,-3,20:17.1
3,-3,20:17.1
4,-4,20:17.1
2,-1,20:17.1
3,-1,20:17.1
3,0,20:17.1
0,-2,20:17.1
0,-1,20:17.1
-1,-1,20:17.1
-2,1,20:17.1
-1,1,20:17.1
-1,2,20:17.1
-3,2,20:17.1
-4,2,20:17.1
-4,3,20:17.1
-3,5,20:17.1
-2,5,20:17.1
-4,5,20:17.1
-4,6,20:17.1
-2,6,20:17.1
1,4,20:17.1
0,4,20:17.1
0,5,20:17.1
2,4,20:17.1
2,3,20:17.1
3,2,20:17.1
4,2,20:17.1
5,2,20:17.1
3,6,20:17.1
2,6,20:17.1
3,7,20:17.1
4,6,20:17.1
-8,0,20:17.1
-6,-6,20:17.1
-5,-2,20:18.2
-4,-3,20:18.2
-3,-2,20:18.2
-3,-1,20:18.2
-4,0,20:18.2
-5,0,20:18.2
-6,-1,20:18.2
-6,0,20:18.2
-6,1,20:18.2
-5,1,20:18.2
-5,2,20:18.2
-5,3,20:18.2
-6,3,20:18.2
-7,3,20:18.2
-7,2,20:18.2
-8,2,20:18.2
-8,1,20:18.2
-9,0,20:18.2
-8,-1,20:18.2
-7,-1,20:18.2
-5,-6,20:18.2
-6,-5,20:18.2
-7,-6,20:18.2
-7,-7,20:18.2
-6,-8,20:18.2
-5,-9,20:18.2
-4,-8,20:18.2
-4,-7,20:18.2
-3,-6,20:18.2
-4,-5,20:18.2
-3,-4,20:18.2
-2,-2,20:18.2
-3,-3,20:18.2
-1,-3,20:18.2
-1,-4,20:18.2
-1,-5,20:18.2
-2,-6,20:18.2
-1,-6,20:18.2
0,-6,20:18.2
1,-6,20:18.2
1,-8,20:18.2
0,-9,20:18.2
-1,-8,20:18.2
-2,-7,20:18.2
2,-7,20:18.2
2,-5,20:18.2
1,-4,20:18.2
0,-3,20:18.2
1,-2,20:18.2
1,-1,20:18.2
1,0,20:18.2
2,-2,20:18.2
3,-2,20:18.2
4,-2,20:18.2
5,-4,20:18.2
5,-3,20:18.2
4,-5,20:18.2
3,-4,20:18.2
2,-3,20:18.2
4,-1,20:18.2
4,0,20:18.2
3,1,20:18.2
4,1,20:18.2
5,1,20:18.2
6,2,20:18.2
5,3,20:18.2
4,3,20:18.2
3,3,20:18.2
2,2,20:18.2
-1,0,20:18.2
0,0,20:18.2
-2,-1,20:18.2
-2,0,20:18.2
-3,1,20:18.2
-4,1,20:18.2
-4,4,20:18.2
-5,5,20:18.2
-5,6,20:18.2
-4,7,20:18.2
-3,6,20:18.2
-2,7,20:18.2
-1,6,20:18.2
-1,5,20:18.2
-2,4,20:18.2
-3,4,20:18.2
-3,3,20:18.2
-2,2,20:18.2
-1,3,20:18.2
0,2,20:18.2
0,1,20:18.2
1,3,20:18.2
0,3,20:18.2
-1,4,20:18.2
0,6,20:18.2
1,5,20:18.2
2,5,20:18.2
1,6,20:18.2
2,7,20:18.2
3,8,20:18.2
4,7,20:18.2
5,6,20:18.2
4,5,20:18.2
3,5,20:18.2
3,4,20:18.2
2,0,20:18.2
-6,-6,21:17.1
-5,-8,21:17.1
-8,0,21:17.1
-6,2,21:17.1
-5,-1,21:17.1
-3,-5,21:17.1
-2,-3,21:17.1
-1,-7,21:17.1
0,-8,21:17.1
1,-7,21:17.1
1,-5,21:17.1
0,-4,21:17.1
0,-2,21:17.1
-1,-1,21:17.1
-2,1,21:17.1
-1,2,21:17.1
-4,3,21:17.1
-4,6,21:17.1
-2,6,21:17.1
0,5,21:17.1
2,3,21:17.1
4,2,21:17.1
5,2,21:17.1
2,-1,21:17.1
3,0,21:17.1
3,-3,21:17.1
4,-4,21:17.1
2,6,21:17.1
3,7,21:17.1
4,6,21:17.1
-6,-7,21:18.2
-5,-7,21:18.2
-6,-8,21:18.2
-5,-9,21:18.2
-4,-8,21:18.2
-5,-6,21:18.2
-6,-5,21:18.2
-7,-6,21:18.2
-5,-2,21:18.2
-4,-1,21:18.2
-5,0,21:18.2
-6,-1,21:18.2
-8,-1,21:18.2
-7,0,21:18.2
-8,1,21:18.2
-9,0,21:18.2
-7,2,21:18.2
-6,1,21:18.2
-6,3,21:18.2
-5,2,21:18.2
-5,3,21:18.2
-4,4,21:18.2
-4,2,21:18.2
-3,3,21:18.2
-4,5,21:18.2
-5,6,21:18.2
-4,7,21:18.2
-3,6,21:18.2
-2,5,21:18.2
-1,6,21:18.2
-2,7,21:18.2
-1,5,21:18.2
0,4,21:18.2
0,6,21:18.2
1,5,21:18.2
1,6,21:18.2
2,7,21:18.2
3,8,21:18.2
4,7,21:18.2
5,6,21:18.2
4,5,21:18.2
3,5,21:18.2
3,6,21:18.2
2,5,21:18.2
2,4,21:18.2
1,3,21:18.2
2,2,21:18.2
3,3,21:18.2
3,2,21:18.2
4,1,21:18.2
4,3,21:18.2
5,3,21:18.2
5,1,21:18.2
6,2,21:18.2
4,0,21:18.2
3,1,21:18.2
2,0,21:18.2
3,-1,21:18.2
2,-2,21:18.2
1,-1,21:18.2
2,-3,21:18.2
3,-2,21:18.2
3,-4,21:18.2
4,-5,21:18.2
5,-4,21:18.2
4,-3,21:18.2
1,-6,21:18.2
2,-7,21:18.2
2,-5,21:18.2
1,-4,21:18.2
0,-3,21:18.2
-1,-4,21:18.2
0,-5,21:18.2
0,-7,21:18.2
1,-8,21:18.2
0,-9,21:18.2
-1,-8,21:18.2
-2,-7,21:18.2
-1,-6,21:18.2
-2,-6,21:18.2
-2,-5,21:18.2
-3,-6,21:18.2
-4,-5,21:18.2
-3,-4,21:18.2
-2,-4,21:18.2
-2,-2,21:18.2
-3,-3,21:18.2
-1,-3,21:18.2
-1,-2,21:18.2
-2,-1,21:18.2
-1,0,21:18.2
0,-1,21:18.2
-1,1,21:18.2
-2,0,21:18.2
-3,1,21:18.2
-2,2,21:18.2
-1,3,21:18.2
0,2,21:18.2
-8,0,22:18.2
-5,-1,22:18.2
-6,-6,22:18.2
-5,-8,22:18.2
-3,-5,22:18.2
-2,-3,22:18.2
-1,-1,22:18.2
-2,1,22:18.2
-1,2,22:18.2
-4,3,22:18.2
-6,2,22:18.2
-4,6,22:18.2
-2,6,22:18.2
0,5,22:18.2
2,3,22:18.2
2,6,22:18.2
3,7,22:18.2
4,6,22:18.2
4,2,22:18.2
5,2,22:18.2
3,0,22:18.2
2,-1,22:18.2
3,-3,22:18.2
4,-4,22:18.2
1,-5,22:18.2
0,-4,22:18.2
0,-2,22:18.2
-1,-7,22:18.2
0,-8,22:18.2
1,-7,22:18.2
