[META]
version=2.0
spawnOnBlockType=3,2,12
spawnSunlight=True
spawnDarkness=True
spawnWater=False
spawnLava=False
underFill=False
randomRotation=True
dig=False
tree=False
branch=False
needsFoundation=False
rarity=450
collisionPercentage=2
spawnElevationMin=0
spawnElevationMax=200
spawnInBiome=Urwald,DesertOasis,Urwald2
[DATA]
1,-1,0:17.0
0,0,0:17.0
-1,1,0:17.0
1,1,0:17.0
-1,-1,0:17.0
-1,0,0:31.1
0,-1,0:31.1
1,0,0:31.1
0,1,0:31.1
-2,2,0:31.1
-2,-2,0:31.1
2,-2,0:31.1
2,2,0:31.1
1,-1,-1:17.0
2,-2,-1:17.0
0,-1,-1:17.0
0,0,-1:17.0
-1,-1,-1:17.0
-2,-2,-1:17.0
-1,1,-1:17.0
-2,2,-1:17.0
1,1,-1:17.0
2,2,-1:17.0
-1,0,-1:17.0
0,1,-1:17.0
1,0,-1:17.0
0,0,1:17.0
0,0,2:17.0
0,0,3:17.0
0,-1,4:17.0
0,0,4:17.0
0,1,4:17.0
-1,1,4:17.0
1,0,4:17.0
2,0,4:17.0
0,0,5:17.0
-1,1,5:17.0
-1,2,5:17.0
2,0,5:17.0
0,-1,5:17.0
0,-2,5:17.0
0,-2,6:17.0
0,0,6:17.0
-1,2,6:17.0
2,0,6:17.0
-1,3,6:17.0
0,-3,6:17.0
3,0,6:17.0
-1,-3,6:17.0
-2,3,6:17.0
3,1,6:17.0
-2,3,7:17.0
-1,-3,7:17.0
3,1,7:17.0
0,0,7:17.0
-1,2,7:31.1
0,-2,7:31.1
2,0,7:31.1
-1,-3,8:17.0
-2,3,8:17.0
0,0,8:17.0
3,1,8:17.0
-1,-6,8:18.0
-4,-3,8:18.0
2,-3,8:18.0
-1,0,8:18.0
-5,3,8:18.0
-2,0,8:18.0
-2,6,8:18.0
1,3,8:18.0
0,1,8:18.0
3,-2,8:18.0
3,4,8:18.0
6,1,8:18.0
-3,-5,8:18.0
-3,-1,8:18.0
1,-5,8:18.0
1,-2,8:18.0
1,-1,8:18.0
5,-1,8:18.0
5,3,8:18.0
-4,1,8:18.0
0,5,8:18.0
-4,6,8:18.0
0,2,8:18.0
-1,-3,9:17.0
-2,3,9:17.0
3,1,9:17.0
0,0,9:17.0
-1,-6,9:18.0
-4,-3,9:18.0
2,-3,9:18.0
-1,0,9:18.0
0,1,9:18.0
3,-2,9:18.0
6,1,9:18.0
3,4,9:18.0
1,3,9:18.0
-5,3,9:18.0
-2,0,9:18.0
-2,6,9:18.0
-3,-5,9:18.0
1,-5,9:18.0
-3,-1,9:18.0
-4,1,9:18.0
-4,6,9:18.0
0,5,9:18.0
0,2,9:18.0
1,-1,9:18.0
5,-1,9:18.0
5,3,9:18.0
-3,2,9:35.1
-1,4,9:35.1
0,-4,9:35.1
-2,-3,9:35.1
4,0,9:35.1
3,2,9:35.1
1,1,9:35.1
0,0,10:17.0
-1,-3,10:18.0
-2,3,10:18.0
3,1,10:18.0
3,0,10:18.0
3,-1,10:18.0
3,2,10:18.0
3,3,10:18.0
2,1,10:18.0
1,1,10:18.0
0,1,10:18.0
4,1,10:18.0
5,1,10:18.0
6,1,10:18.0
3,-2,10:18.0
3,4,10:18.0
2,-3,10:18.0
1,-3,10:18.0
0,-3,10:18.0
-2,-3,10:18.0
-3,-3,10:18.0
-4,-3,10:18.0
-1,-6,10:18.0
-1,-5,10:18.0
-1,-4,10:18.0
-1,-2,10:18.0
-1,-1,10:18.0
-1,0,10:18.0
1,3,10:18.0
0,3,10:18.0
-1,3,10:18.0
-3,3,10:18.0
-4,3,10:18.0
-5,3,10:18.0
-2,0,10:18.0
-2,1,10:18.0
-2,2,10:18.0
-2,4,10:18.0
-2,5,10:18.0
-2,6,10:18.0
-3,-5,10:18.0
-2,-4,10:18.0
-2,-2,10:18.0
-3,-1,10:18.0
-4,1,10:18.0
-3,2,10:18.0
-3,4,10:18.0
-4,5,10:18.0
-4,6,10:18.0
5,3,10:18.0
4,2,10:18.0
4,0,10:18.0
5,-1,10:18.0
1,-1,10:18.0
2,0,10:18.0
1,-5,10:18.0
0,-4,10:18.0
0,5,10:18.0
-1,4,10:18.0
0,2,10:18.0
0,0,11:17.0
0,2,11:18.0
2,0,11:18.0
-1,-5,11:18.0
-3,-3,11:18.0
-1,-3,11:18.0
-1,-1,11:18.0
1,-3,11:18.0
-2,3,11:18.0
-4,3,11:18.0
-2,5,11:18.0
0,3,11:18.0
-2,1,11:18.0
0,-2,11:18.0
5,1,11:18.0
3,-1,11:18.0
3,1,11:18.0
3,3,11:18.0
1,1,11:18.0
-2,-4,11:18.0
-2,-2,11:18.0
0,-4,11:18.0
4,0,11:18.0
2,2,11:18.0
4,2,11:18.0
-3,4,11:18.0
-3,2,11:18.0
-1,4,11:18.0
-1,2,11:18.0
-4,5,11:18.0
0,0,12:17.0
0,-2,12:18.0
-2,0,12:18.0
2,0,12:18.0
0,2,12:18.0
2,-2,12:18.0
1,-1,12:18.0
-1,1,12:18.0
-1,-1,12:18.0
1,1,12:18.0
-2,-2,12:18.0
2,2,12:18.0
0,0,13:18.0
0,-1,13:18.0
-1,0,13:18.0
1,0,13:18.0
0,2,13:18.0
0,1,13:18.0
0,-2,13:18.0
-2,0,13:18.0
2,0,13:18.0
-2,2,13:18.0
-2,-2,13:18.0
-1,-1,13:18.0
-1,1,13:18.0
1,-1,13:18.0
2,-2,13:18.0
1,1,13:18.0
2,2,13:18.0
0,3,13:18.0
0,-3,13:18.0
-3,0,13:18.0
3,0,13:18.0
0,-1,14:18.0
0,1,14:18.0
-1,0,14:18.0
1,0,14:18.0
-2,-2,14:18.0
-1,-1,14:18.0
-1,1,14:18.0
-2,2,14:18.0
1,1,14:18.0
2,2,14:18.0
1,-1,14:18.0
2,-2,14:18.0
2,0,14:18.0
3,0,14:18.0
0,2,14:18.0
0,3,14:18.0
0,-3,14:18.0
0,-2,14:18.0
-3,0,14:18.0
-2,0,14:18.0
0,-2,15:18.0
-2,0,15:18.0
2,0,15:18.0
0,2,15:18.0
-1,-1,15:18.0
-1,1,15:18.0
1,1,15:18.0
1,-1,15:18.0
