[META]
version=2.0
spawnOnBlockType=1,2,3
spawnSunlight=True
spawnDarkness=True
spawnWater=False
spawnLava=False
underFill=True
randomRotation=True
dig=True
tree=True
branch=False
needsFoundation=True
rarity=70
collisionPercentage=2
spawnElevationMin=64
spawnElevationMax=140
spawnInBiome=Mystic,MysticHills,ForestCave
[DATA]
-1,-1,0:17.3
0,0,0:17.3
-1,1,0:17.3
1,1,0:17.3
1,-1,0:17.3
-1,-1,-1:3
-1,1,-1:3
1,1,-1:3
1,-1,-1:3
0,0,-1:3
0,0,1:17.3
0,0,2:17.3
0,0,3:17.3
0,0,4:17.3
0,0,5:17.3
-4,0,5:18.3
-3,0,5:18.3
-2,0,5:18.3
-1,0,5:18.3
-2,-1,5:18.3
-2,-2,5:18.3
-3,-2,5:18.3
-1,1,5:18.3
-1,2,5:18.3
-2,3,5:18.3
-1,3,5:18.3
0,3,5:18.3
1,3,5:18.3
-2,4,5:18.3
1,4,5:18.3
1,5,5:18.3
1,1,5:18.3
2,1,5:18.3
3,1,5:18.3
1,0,5:18.3
1,-1,5:18.3
2,-1,5:18.3
2,-2,5:18.3
3,-2,5:18.3
3,-3,5:18.3
0,-1,5:18.3
0,-2,5:18.3
0,-3,5:18.3
0,-4,5:18.3
0,-5,5:18.3
2,0,5:30
-2,1,5:30
-3,-1,5:30
0,4,5:30
1,-2,5:30
0,0,6:17.3
0,-1,6:17.3
-1,0,6:17.3
-1,1,6:17.3
1,0,6:17.3
1,1,6:17.3
2,1,6:17.3
0,-2,6:17.3
0,-3,6:17.3
3,1,6:17.3
-1,2,6:17.3
-1,3,6:17.3
-2,0,6:17.3
-3,0,6:17.3
1,-1,6:17.3
2,-2,6:17.3
3,-3,6:17.3
3,-2,6:17.3
2,-1,6:17.3
-2,-1,6:17.3
-2,-2,6:17.3
-3,-2,6:17.3
-4,0,6:17.3
0,-4,6:17.3
-2,3,6:17.3
-2,4,6:17.3
0,3,6:17.3
1,3,6:17.3
1,4,6:17.3
1,5,6:17.3
0,-5,6:17.3
-5,0,6:18.3
-4,-2,6:18.3
0,-6,6:18.3
3,-4,6:18.3
4,1,6:18.3
1,6,6:18.3
-2,5,6:18.3
-4,1,6:106.2
-3,1,6:106.2
-2,1,6:106.2
-1,4,6:106.2
0,4,6:106.2
0,1,6:106.2
1,2,6:106.8
2,2,6:106.2
3,2,6:106.2
2,0,6:106.2
3,-1,6:106.2
-3,-1,6:106.2
-3,-3,6:106.8
-2,-3,6:106.8
-1,-1,6:106.8
-2,2,6:106.8
0,2,6:106.8
1,-2,6:106.8
2,-3,6:106.8
-1,-2,6:106.1
1,-5,6:106.4
1,-4,6:106.4
1,-3,6:106.4
2,3,6:106.4
2,4,6:106.4
2,5,6:106.4
4,-3,6:106.4
4,-2,6:106.4
-1,-5,6:106.1
-1,-4,6:106.1
-1,-3,6:106.1
-3,3,6:106.1
-3,4,6:106.1
0,5,6:106.1
0,0,7:17.3
-2,1,7:18.3
-3,1,7:18.3
-4,1,7:18.3
-4,2,7:18.3
-5,2,7:18.3
0,1,7:18.3
0,2,7:18.3
1,2,7:18.3
1,3,7:18.3
1,4,7:18.3
-1,-1,7:18.3
-1,-2,7:18.3
-2,-2,7:18.3
-2,-3,7:18.3
-2,-4,7:18.3
1,0,7:18.3
2,0,7:18.3
3,0,7:18.3
3,-1,7:18.3
4,-1,7:18.3
-2,0,7:18.3
-1,0,7:18.3
-2,-1,7:30
-1,1,7:30
1,1,7:30
0,-1,7:30
0,3,7:30
-4,0,7:30
3,-2,7:30
-1,-3,7:30
-3,0,7:18.1
-3,-2,7:18.1
-2,3,7:18.1
-2,4,7:18.1
-1,3,7:18.1
-1,2,7:18.1
1,5,7:18.1
0,-2,7:18.1
0,-3,7:18.1
0,-4,7:18.1
0,-5,7:18.1
2,-2,7:18.1
3,-3,7:18.1
2,-1,7:18.1
1,-1,7:18.1
2,1,7:18.1
3,1,7:18.1
0,0,8:17.3
-1,0,8:17.3
-1,-1,8:17.3
-1,-2,8:17.3
-2,-2,8:17.3
-2,-3,8:17.3
0,1,8:17.3
0,2,8:17.3
1,3,8:17.3
1,2,8:17.3
1,4,8:17.3
1,0,8:17.3
2,0,8:17.3
3,0,8:17.3
3,-1,8:17.3
4,-1,8:17.3
-2,0,8:17.3
-2,1,8:17.3
-3,1,8:17.3
-4,1,8:17.3
-4,2,8:17.3
-5,2,8:17.3
-2,-4,8:17.3
-6,2,8:18.3
-2,-5,8:18.3
5,-1,8:18.3
1,5,8:18.3
-1,2,8:106.1
-1,1,8:106.4
-2,-1,8:106.1
-3,-2,8:106.1
-3,-3,8:106.1
-3,-4,8:106.1
-3,0,8:106.1
-5,1,8:106.1
0,3,8:106.1
0,4,8:106.1
2,-1,8:106.1
1,1,8:106.4
0,-1,8:106.4
0,-2,8:106.4
-1,-3,8:106.4
-1,-4,8:106.4
-3,2,8:106.4
4,0,8:106.4
2,2,8:106.4
2,3,8:106.4
2,4,8:106.4
1,-1,8:106.8
3,-2,8:106.8
4,-2,8:106.8
-4,0,8:106.8
-2,2,8:106.2
2,1,8:106.2
3,1,8:106.2
-5,3,8:106.2
-4,3,8:106.2
0,0,9:17.3
0,1,9:18.3
0,2,9:18.3
0,-1,9:18.3
0,-2,9:18.3
0,-3,9:18.3
-1,0,9:18.3
-2,0,9:18.3
-3,0,9:18.3
1,-1,9:18.3
2,-1,9:18.3
3,-1,9:18.3
-1,-1,9:30
1,2,9:30
-3,1,9:30
-5,2,9:18.1
-4,2,9:18.1
-4,1,9:18.1
-2,1,9:18.1
-2,-2,9:18.1
-1,-2,9:18.1
-2,-3,9:18.1
-2,-4,9:18.1
1,0,9:18.1
2,0,9:18.1
3,0,9:18.1
4,-1,9:18.1
1,3,9:18.1
1,4,9:18.1
0,0,10:17.3
0,-1,10:17.3
0,-2,10:17.3
0,-3,10:17.3
0,1,10:17.3
0,2,10:17.3
-1,0,10:17.3
-2,0,10:17.3
1,-1,10:17.3
2,-1,10:17.3
3,-1,10:17.3
-3,0,10:17.3
-4,0,10:18.3
0,-4,10:18.3
4,-1,10:18.3
0,3,10:18.3
-3,-1,10:106.8
-2,-1,10:106.8
-1,-1,10:106.8
1,-2,10:106.8
2,-2,10:106.8
3,-2,10:106.8
1,0,10:106.4
1,1,10:106.4
1,2,10:106.4
1,-3,10:106.4
-1,-2,10:106.1
-1,-3,10:106.1
-1,1,10:106.1
-1,2,10:106.1
-2,1,10:106.2
-3,1,10:106.2
3,0,10:106.2
2,0,10:106.2
0,0,11:17.3
0,-1,11:30
-3,0,11:18.1
-2,0,11:18.1
-1,0,11:18.1
0,1,11:18.1
0,2,11:18.1
0,-2,11:18.1
0,-3,11:18.1
1,-1,11:18.1
2,-1,11:18.1
3,-1,11:18.1
0,0,12:17.3
0,-1,12:18.3
0,-2,12:18.3
0,-3,12:18.3
0,1,12:18.3
0,2,12:18.3
0,3,12:18.3
-1,0,12:18.3
-2,0,12:18.3
-3,0,12:18.3
1,0,12:18.3
2,0,12:18.3
3,0,12:18.3
0,0,13:17.3
-1,0,13:17.3
-2,0,13:17.3
1,0,13:17.3
2,0,13:17.3
0,1,13:17.3
0,2,13:17.3
0,-1,13:17.3
0,-2,13:17.3
0,-3,13:17.3
0,3,13:17.3
-3,0,13:17.3
3,0,13:17.3
-4,0,13:18.3
0,-4,13:18.3
0,4,13:18.3
4,0,13:18.3
-1,1,13:106.2
-1,2,13:106.1
-1,3,13:106.1
-1,-1,13:106.1
-1,-2,13:106.1
-1,-3,13:106.1
1,1,13:106.2
2,1,13:106.2
3,1,13:106.2
-2,1,13:106.2
-3,1,13:106.2
1,-1,13:106.8
2,-1,13:106.8
3,-1,13:106.8
1,2,13:106.4
1,3,13:106.4
1,-2,13:106.4
1,-3,13:106.4
-3,-1,13:106.8
-2,-1,13:106.8
0,0,14:17.3
0,1,14:30
-3,0,14:18.1
-2,0,14:18.1
-1,0,14:18.1
0,-1,14:18.1
0,-2,14:18.1
0,-3,14:18.1
1,0,14:18.1
2,0,14:18.1
3,0,14:18.1
0,2,14:18.1
0,3,14:18.1
0,0,15:17.3
0,0,16:18.3
