[META]
version=2.0
spawnOnBlockType=3,2
spawnSunlight=True
spawnDarkness=True
spawnWater=False
spawnLava=False
underFill=True
randomRotation=True
dig=True
tree=True
branch=False
needsFoundation=True
rarity=100
collisionPercentage=2
spawnElevationMin=0
spawnElevationMax=125
spawnInBiome=Urwald
[DATA]
0,0,0:17.0
0,-1,0:17.0
0,-2,0:17.0
0,-3,0:17.0
0,1,0:17.0
0,2,0:17.0
0,3,0:17.0
-1,0,0:17.0
-2,0,0:17.0
-3,0,0:17.0
1,0,0:17.0
2,0,0:17.0
3,0,0:17.0
1,-1,0:17.0
1,1,0:17.0
-1,1,0:17.0
-1,-1,0:17.0
-2,0,1:17.0
-1,0,1:17.0
0,-1,1:17.0
0,-2,1:17.0
1,0,1:17.0
2,0,1:17.0
0,1,1:17.0
0,2,1:17.0
0,0,1:17.0
-1,0,2:17.0
0,-1,2:17.0
1,0,2:17.0
0,0,2:17.0
0,1,2:17.0
-1,0,3:17.0
0,0,3:17.0
0,-1,3:17.0
0,1,3:17.0
1,0,3:17.0
-1,0,4:17.0
0,0,4:17.0
1,0,4:17.0
0,1,4:17.0
0,-1,4:17.0
-1,0,5:17.0
0,0,5:17.0
1,0,5:17.0
0,1,5:17.0
0,-1,5:17.0
0,3,5:18.2
-2,0,5:18.2
0,-2,5:18.2
-1,0,6:17.0
0,0,6:17.0
1,0,6:17.0
0,1,6:17.0
0,2,6:17.0
0,-1,6:17.0
0,3,6:17.0
-1,3,6:18.2
0,4,6:18.2
1,3,6:18.2
-1,0,7:17.0
0,0,7:17.0
0,1,7:17.0
1,0,7:17.0
0,-1,7:17.0
0,3,7:18.2
-1,0,8:17.0
1,0,8:17.0
0,-1,8:17.0
0,1,8:17.0
0,0,8:17.0
0,-3,8:18.2
-2,0,8:18.2
0,-1,9:17.0
0,-2,9:17.0
0,-3,9:17.0
1,0,9:17.0
-1,0,9:17.0
0,1,9:17.0
0,0,9:17.0
-1,-3,9:18.2
0,-4,9:18.2
1,-3,9:18.2
-1,0,10:17.0
0,0,10:17.0
0,-1,10:17.0
0,1,10:17.0
1,0,10:17.0
0,-3,10:18.2
0,2,10:18.2
-1,3,10:18.2
-1,0,11:17.0
0,0,11:17.0
0,-1,11:17.0
1,0,11:17.0
0,1,11:17.0
-1,0,12:17.0
0,0,12:17.0
0,-1,12:17.0
1,0,12:17.0
0,1,12:17.0
-2,0,12:18.2
-2,-1,12:18.2
2,0,12:18.2
-1,0,13:17.0
0,0,13:17.0
0,-1,13:17.0
1,0,13:17.0
0,1,13:17.0
3,0,13:18.2
2,0,14:17.0
3,0,14:17.0
1,0,14:17.0
0,0,14:17.0
-1,0,14:17.0
0,-1,14:17.0
0,1,14:17.0
3,-1,14:18.2
4,0,14:18.2
3,1,14:18.2
-1,0,15:17.0
0,0,15:17.0
0,-1,15:17.0
0,1,15:17.0
1,0,15:17.0
3,0,15:18.2
0,-1,16:17.0
0,-2,16:17.0
0,-3,16:17.0
-1,-3,16:17.0
1,0,16:17.0
2,0,16:17.0
3,0,16:17.0
4,0,16:17.0
0,1,16:17.0
0,2,16:17.0
0,3,16:17.0
-1,4,16:17.0
-1,0,16:17.0
-2,0,16:17.0
-3,1,16:17.0
-4,1,16:17.0
-1,-4,16:17.0
4,1,16:17.0
5,1,16:17.0
-5,2,16:17.0
2,-1,16:18.2
-1,2,16:18.2
-3,-1,16:18.2
4,2,16:18.2
1,-4,16:18.2
-5,2,17:17.0
-6,2,17:17.0
-1,4,17:17.0
-1,5,17:17.0
5,1,17:17.0
6,1,17:17.0
-1,-4,17:17.0
-1,-5,17:17.0
0,-1,17:17.0
0,1,17:17.0
-1,0,17:17.0
1,0,17:17.0
-6,1,17:18.2
-7,2,17:18.2
-6,3,17:18.2
-3,1,17:18.2
-2,2,17:18.2
-4,0,17:18.2
-3,-1,17:18.2
-2,-3,17:18.2
-3,-4,17:18.2
-2,-5,17:18.2
-2,-6,17:18.2
0,-6,17:18.2
1,-7,17:18.2
1,-4,17:18.2
0,-4,17:18.2
0,-3,17:18.2
2,-1,17:18.2
3,0,17:18.2
2,1,17:18.2
4,-1,17:18.2
4,1,17:18.2
6,2,17:18.2
7,1,17:18.2
6,0,17:18.2
0,5,17:18.2
-1,6,17:18.2
-2,6,17:18.2
-2,5,17:18.2
0,3,17:18.2
-3,3,17:18.2
0,7,17:18.2
5,-2,17:18.2
-5,4,17:18.2
-4,-5,17:18.2
5,3,17:18.2
5,4,17:18.2
0,0,17:18.2
-1,-5,18:17.0
-1,-6,18:17.0
-6,2,18:17.0
-7,2,18:17.0
-1,5,18:17.0
-1,6,18:17.0
0,5,18:17.0
1,5,18:17.0
-6,1,18:17.0
-6,0,18:17.0
-6,-1,18:17.0
0,-5,18:17.0
1,-4,18:17.0
2,-4,18:17.0
6,1,18:17.0
6,0,18:17.0
7,-1,18:17.0
0,-1,18:17.0
-1,0,18:17.0
0,1,18:17.0
1,0,18:17.0
-5,-1,18:18.2
-7,-1,18:18.2
-6,-2,18:18.2
-7,1,18:18.2
-7,3,18:18.2
-5,2,18:18.2
-5,3,18:18.2
-4,4,18:18.2
-2,3,18:18.2
-1,2,18:18.2
-1,4,18:18.2
1,6,18:18.2
2,5,18:18.2
3,6,18:18.2
3,4,18:18.2
1,4,18:18.2
2,3,18:18.2
-1,7,18:18.2
-2,7,18:18.2
-2,6,18:18.2
-3,6,18:18.2
-1,-1,18:18.2
-2,-2,18:18.2
0,0,18:18.2
1,1,18:18.2
2,2,18:18.2
2,0,18:18.2
2,-1,18:18.2
5,1,18:18.2
5,2,18:18.2
4,2,18:18.2
4,0,18:18.2
7,1,18:18.2
7,2,18:18.2
6,-1,18:18.2
5,-2,18:18.2
7,-2,18:18.2
2,-5,18:18.2
3,-5,18:18.2
4,-6,18:18.2
3,-3,18:18.2
0,-6,18:18.2
1,-7,18:18.2
-1,-7,18:18.2
-2,-7,18:18.2
-3,-5,18:18.2
-2,-5,18:18.2
-1,-4,18:18.2
-5,-3,18:18.2
-8,2,18:18.2
-1,-8,18:18.2
8,1,18:18.2
-1,8,18:18.2
4,7,18:18.2
-6,-4,18:18.2
6,4,18:18.2
-5,5,18:18.2
-1,-6,19:17.0
2,-4,19:17.0
-7,2,19:17.0
-6,-1,19:17.0
-1,6,19:17.0
1,5,19:17.0
6,1,19:17.0
7,-1,19:17.0
0,1,19:17.0
0,-1,19:17.0
1,0,19:17.0
-1,0,19:17.0
-2,0,19:17.0
-3,0,19:17.0
1,2,19:17.0
2,-1,19:17.0
3,-1,19:17.0
-1,-2,19:17.0
-2,-3,19:17.0
-5,-1,19:18.2
-5,-2,19:18.2
-6,-2,19:18.2
-7,-2,19:18.2
-7,-1,19:18.2
-7,1,19:18.2
-7,3,19:18.2
-6,3,19:18.2
-3,1,19:18.2
-4,1,19:18.2
-4,0,19:18.2
-3,-1,19:18.2
-1,1,19:18.2
0,2,19:18.2
1,3,19:18.2
2,3,19:18.2
3,4,19:18.2
2,2,19:18.2
1,1,19:18.2
2,0,19:18.2
1,-1,19:18.2
2,-2,19:18.2
3,-2,19:18.2
4,-1,19:18.2
6,0,19:18.2
6,-1,19:18.2
7,-2,19:18.2
7,0,19:18.2
7,2,19:18.2
5,2,19:18.2
5,-2,19:18.2
3,-4,19:18.2
4,-4,19:18.2
4,-5,19:18.2
2,-5,19:18.2
0,-5,19:18.2
1,-3,19:18.2
-2,-4,19:18.2
-2,-5,19:18.2
-2,-6,19:18.2
-2,-7,19:18.2
0,-7,19:18.2
1,-7,19:18.2
-3,-6,19:18.2
-6,-3,19:18.2
-5,4,19:18.2
-6,1,19:18.2
-4,3,19:18.2
-3,5,19:18.2
-2,5,19:18.2
-2,4,19:18.2
-1,5,19:18.2
0,6,19:18.2
-1,7,19:18.2
-2,7,19:18.2
1,6,19:18.2
2,7,19:18.2
0,4,19:18.2
0,0,19:18.2
-8,1,19:18.2
0,-8,19:18.2
8,0,19:18.2
-1,8,19:18.2
-5,-4,19:18.2
5,4,19:18.2
4,3,19:18.2
-4,-3,19:18.2
-2,-3,20:17.0
-3,0,20:17.0
3,-1,20:17.0
1,2,20:17.0
-1,6,20:17.0
1,5,20:17.0
-7,2,20:17.0
-6,-1,20:17.0
-1,-6,20:17.0
2,-4,20:17.0
7,-1,20:17.0
6,1,20:17.0
0,-1,20:17.0
0,1,20:17.0
-6,-2,20:18.2
-5,-2,20:18.2
-5,-1,20:18.2
-7,-1,20:18.2
-6,2,20:18.2
-6,3,20:18.2
-7,3,20:18.2
0,5,20:18.2
0,6,20:18.2
0,7,20:18.2
-2,7,20:18.2
-2,5,20:18.2
0,3,20:18.2
0,2,20:18.2
-1,2,20:18.2
-3,-1,20:18.2
-2,0,20:18.2
-1,0,20:18.2
-1,-2,20:18.2
1,0,20:18.2
0,0,20:18.2
2,-1,20:18.2
4,-2,20:18.2
4,0,20:18.2
3,-4,20:18.2
3,-5,20:18.2
2,-5,20:18.2
1,-4,20:18.2
0,-6,20:18.2
0,-7,20:18.2
-1,-7,20:18.2
-2,-7,20:18.2
-1,-5,20:18.2
-3,-4,20:18.2
6,2,20:18.2
7,2,20:18.2
6,0,20:18.2
7,-2,20:18.2
7,0,20:18.2
5,1,20:18.2
2,3,20:18.2
2,1,20:18.2
2,5,20:18.2
2,6,20:18.2
-7,1,20:18.2
-7,-3,20:18.2
-3,-6,20:18.2
1,-6,20:18.2
2,-7,20:18.2
4,-4,20:18.2
5,-5,20:18.2
6,-3,20:18.2
6,3,20:18.2
5,3,20:18.2
3,5,20:18.2
4,6,20:18.2
-3,6,20:18.2
-4,7,20:18.2
-4,5,20:18.2
-3,2,20:18.2
-4,1,20:18.2
-5,-3,20:18.2
0,8,20:18.2
8,2,20:18.2
8,0,20:18.2
9,0,20:18.2
6,-6,20:18.2
1,-8,20:18.2
0,-9,20:18.2
-2,-8,20:18.2
-5,-4,20:18.2
-6,-5,20:18.2
-8,-1,20:18.2
-9,0,20:18.2
-2,8,20:18.2
0,1,21:17.0
0,-1,21:17.0
1,5,21:17.0
-1,6,21:17.0
-3,0,21:17.0
-2,-3,21:17.0
2,-4,21:17.0
6,1,21:17.0
-2,6,21:18.2
0,6,21:18.2
-1,8,21:18.2
-1,7,21:18.2
-1,5,21:18.2
1,4,21:18.2
2,4,21:18.2
2,6,21:18.2
2,5,21:18.2
1,6,21:18.2
0,5,21:18.2
1,2,21:18.2
-1,-6,21:18.2
-6,-1,21:18.2
-7,2,21:18.2
3,-1,21:18.2
7,-1,21:18.2
6,2,21:18.2
5,1,21:18.2
6,0,21:18.2
7,2,21:18.2
7,1,21:18.2
3,-5,21:18.2
2,-5,21:18.2
1,-4,21:18.2
3,-3,21:18.2
-1,-3,21:18.2
-2,-4,21:18.2
-3,-3,21:18.2
-2,-2,21:18.2
0,-2,21:18.2
-1,2,21:18.2
-3,1,21:18.2
-4,1,21:18.2
-4,0,21:18.2
-2,-1,21:18.2
0,0,21:17.0
8,-1,21:18.2
4,7,21:18.2
-1,9,21:18.2
0,9,21:18.2
-8,2,21:18.2
-1,-8,21:18.2
0,-9,21:18.2
-5,-4,21:18.2
-6,-5,21:18.2
6,-6,21:18.2
-5,7,21:18.2
-2,-3,22:18.2
-3,0,22:18.2
0,0,22:17.0
0,-1,22:18.2
0,1,22:18.2
1,5,22:18.2
-1,6,22:18.2
-5,1,22:18.2
-5,-2,22:18.2
-2,-5,22:18.2
-2,-7,22:18.2
2,-4,22:18.2
2,-5,22:18.2
2,-6,22:18.2
6,1,22:18.2
6,0,22:18.2
5,0,22:18.2
0,0,23:17.0
-1,-1,23:17.0
-1,-2,23:17.0
1,1,23:17.0
2,1,23:17.0
2,2,23:17.0
2,3,23:17.0
0,-3,23:18.2
-1,0,23:18.2
1,3,23:18.2
0,3,23:18.2
3,3,23:18.2
3,4,23:18.2
2,0,23:18.2
3,-1,23:18.2
-2,-2,23:18.2
4,4,23:18.2
-1,4,23:18.2
-2,1,23:18.2
0,0,24:17.0
-1,-2,24:18.2
-1,-3,24:18.2
0,-3,24:18.2
-2,-1,24:18.2
2,0,24:18.2
3,0,24:18.2
3,2,24:18.2
2,2,24:18.2
1,3,24:18.2
2,4,24:18.2
-1,1,24:18.2
-3,-1,24:18.2
1,-4,24:18.2
4,0,24:18.2
5,-1,24:18.2
1,5,24:18.2
-2,2,24:18.2
0,0,25:17.0
-1,1,25:17.0
-2,1,25:17.0
0,-1,25:17.0
0,-2,25:17.0
1,-2,25:17.0
2,-2,25:17.0
0,0,26:17.0
-2,1,26:18.2
-3,1,26:18.2
-2,2,26:18.2
1,-2,26:18.2
2,-2,26:18.2
2,-3,26:18.2
-1,-3,26:18.2
0,2,26:18.2
3,-1,26:18.2
-4,0,26:18.2
1,3,26:18.2
-2,-4,26:18.2
0,-1,26:18.2
-1,-1,26:18.2
1,1,26:18.2
0,0,27:17.0
-1,-1,27:18.2
1,0,27:18.2
2,1,27:18.2
-1,3,27:18.2
1,-4,27:18.2
-4,-1,27:18.2
3,2,27:18.2
0,0,28:18.2
-1,-1,28:18.2
1,1,28:18.2
0,2,28:18.2
0,0,29:18.2
