[META]
version=2.0
spawnOnBlockType=3,2,12,88,1
spawnSunlight=True
spawnDarkness=True
spawnWater=False
spawnLava=False
underFill=False
randomRotation=True
dig=False
tree=True
branch=True
needsFoundation=True
diggingBranch=True
rarity=320
collisionPercentage=5
spawnElevationMin=0
spawnElevationMax=112
spawnInBiome=Urwald,Extreme Hills
[DATA]
0,3,0:17.1
0,2,0:17.1
3,3,0:17.1
4,-4,0:17.1
4,0,0:17.1
-2,-6,0:17.1
-3,2,0:17.1
-4,1,0:17.1
4,4,0:17.1
-3,1,0:17.1
-2,-5,0:17.1
5,-5,0:17.1
-2,3,0:17.1
-3,4,0:17.1
3,0,1:17.1
-3,0,1:17.1
-2,-5,1:17.1
4,4,1:17.1
0,2,1:17.1
0,1,1:17.1
5,-5,1:17.1
-3,1,1:17.1
2,0,1:17.1
3,3,1:17.1
-2,0,1:17.1
-1,-4,1:17.1
4,-4,1:17.1
-2,3,1:17.1
3,-3,1:17.1
2,-2,1:17.1
-1,-3,1:17.1
0,-2,1:17.1
-1,2,1:17.1
2,2,1:17.1
2,0,2:17.1
-1,-4,2:17.1
4,-4,2:17.1
-2,0,2:17.1
3,3,2:17.1
-3,0,2:17.1
-2,-5,2:17.1
0,1,2:17.1
-1,2,2:17.1
3,-3,2:17.1
-1,-3,2:17.1
0,-2,2:17.1
2,-2,2:17.1
2,2,2:17.1
1,-1,3:17.1
0,-1,3:17.1
-1,0,3:17.1
0,1,3:17.1
1,1,3:17.1
1,0,3:17.1
0,0,3:17.1
2,0,3:17.1
-1,-3,3:17.1
3,-3,3:17.1
3,3,3:17.1
-2,0,3:17.1
2,2,3:17.1
-1,2,3:17.1
2,-2,3:17.1
0,-2,3:17.1
-1,0,4:17.1
0,0,4:17.1
1,0,4:17.1
2,0,4:17.1
1,-1,4:17.1
1,1,4:17.1
0,-1,4:17.1
0,1,4:17.1
-1,2,4:17.1
2,2,4:17.1
2,-2,4:17.1
-1,-2,4:17.1
-2,0,4:17.1
1,-2,4:18.2
3,1,4:18.2
0,2,4:18.2
-2,-1,4:18.2
2,1,4:18.2
-2,-3,4:18.2
3,-2,4:18.2
-2,2,4:18.2
0,0,5:17.1
1,0,5:17.1
1,-1,5:17.1
1,1,5:17.1
0,1,5:17.1
0,-1,5:17.1
-1,-2,5:17.1
2,-2,5:17.1
-1,2,5:17.1
2,2,5:17.1
-1,0,5:18.2
2,0,5:18.2
0,-1,6:17.1
1,-1,6:17.1
0,1,6:17.1
1,1,6:17.1
0,0,6:17.1
1,0,6:17.1
0,-2,6:18.2
0,2,6:18.2
0,-1,7:17.1
0,0,7:17.1
0,1,7:17.1
1,1,7:17.1
1,0,7:17.1
1,-1,7:17.1
-1,0,8:17.1
0,0,8:17.1
1,0,8:17.1
2,0,8:17.1
1,-1,8:17.1
1,1,8:17.1
0,1,8:17.1
0,-1,8:17.1
-2,0,9:17.1
-1,-2,9:17.1
2,-2,9:17.1
2,2,9:17.1
-1,2,9:17.1
3,0,9:17.1
-2,-2,10:17.1
0,-3,10:17.1
2,-3,10:17.1
3,-2,10:17.1
4,0,10:17.1
3,1,10:17.1
2,3,10:17.1
0,3,10:17.1
-2,3,10:17.1
-3,1,10:17.1
-2,-3,10:18.2
-3,-2,10:18.2
-3,2,10:18.2
-4,0,10:18.2
-3,4,10:18.2
0,4,10:18.2
3,4,10:18.2
5,-1,10:18.2
5,1,10:18.2
4,-3,10:18.2
1,-4,10:18.2
0,-2,10:18.2
0,2,10:18.2
2,0,10:18.2
2,-2,10:18.2
-2,0,10:18.2
-1,2,10:18.2
2,2,10:18.2
-14,-11,10:18.2
-4,0,11:17.1
-4,2,11:17.1
-2,4,11:17.1
1,4,11:17.1
3,4,11:17.1
4,2,11:17.1
5,-1,11:17.1
4,-3,11:17.1
2,-4,11:17.1
0,-5,11:17.1
0,-4,11:17.1
-2,-3,11:17.1
-3,-2,11:17.1
-4,-2,11:17.1
-4,3,11:17.1
-3,2,12:17.1
-5,3,12:17.1
-5,0,12:17.1
-4,-3,12:17.1
-2,-4,12:17.1
-1,-6,12:17.1
1,-6,12:17.1
3,-5,12:17.1
5,-3,12:17.1
6,-1,12:17.1
6,0,12:17.1
5,2,12:17.1
4,3,12:17.1
4,5,12:17.1
1,5,12:17.1
-1,5,12:17.1
-3,5,12:17.1
-1,3,12:17.1
-2,-1,12:17.1
0,-3,12:17.1
2,-3,12:17.1
4,-1,12:17.1
3,1,12:17.1
1,3,12:17.1
0,2,13:17.1
-2,1,13:17.1
-1,-1,13:17.1
1,-2,13:17.1
3,-1,13:17.1
2,1,13:17.1
3,3,13:17.1
5,5,13:17.1
3,6,13:17.1
1,6,13:17.1
-1,6,13:17.1
-3,6,13:17.1
-4,5,13:17.1
-6,4,13:17.1
-6,2,13:17.1
-6,0,13:17.1
-5,-1,13:17.1
-5,-3,13:17.1
-4,-4,13:17.1
-2,-5,13:17.1
-1,-7,13:17.1
1,-7,13:17.1
2,-6,13:17.1
4,-6,13:17.1
6,-4,13:17.1
4,-4,13:17.1
6,-2,13:17.1
7,-1,13:17.1
7,1,13:17.1
6,3,13:17.1
4,1,13:17.1
5,-1,13:17.1
3,-3,13:17.1
2,-4,13:17.1
1,-5,13:17.1
-1,-4,13:17.1
-2,-3,13:17.1
-3,-2,13:17.1
-4,1,13:17.1
-2,3,13:17.1
-4,3,13:17.1
0,4,13:17.1
2,5,13:17.1
-4,-3,13:18.2
-2,-4,13:18.2
-1,-6,13:18.2
1,-6,13:18.2
3,-5,13:18.2
4,-7,13:18.2
5,-6,13:18.2
2,-8,13:18.2
0,-8,13:18.2
-2,-8,13:18.2
-3,-6,13:18.2
-5,-5,13:18.2
-6,-4,13:18.2
-6,-2,13:18.2
-7,-1,13:18.2
-7,1,13:18.2
-7,3,13:18.2
-6,5,13:18.2
-5,5,13:18.2
-4,6,13:18.2
-3,7,13:18.2
-2,7,13:18.2
0,6,13:18.2
0,7,13:18.2
2,7,13:18.2
2,6,13:18.2
4,6,13:18.2
6,5,13:18.2
5,6,13:18.2
6,4,13:18.2
7,3,13:18.2
7,2,13:18.2
8,0,13:18.2
7,0,13:18.2
8,-2,13:18.2
7,-3,13:18.2
7,-5,13:18.2
6,-5,13:18.2
5,-3,13:18.2
2,-3,13:18.2
0,-3,13:18.2
-2,-1,13:18.2
-5,0,13:18.2
-3,2,13:18.2
-5,3,13:18.2
0,0,13:18.2
-1,3,13:18.2
-1,5,13:18.2
-2,5,13:18.2
-3,5,13:18.2
1,5,13:18.2
1,3,13:18.2
1,1,13:18.2
2,-1,13:18.2
3,0,13:18.2
4,-2,13:18.2
6,0,13:18.2
4,-1,13:18.2
6,-1,13:18.2
5,2,13:18.2
4,3,13:18.2
4,5,13:18.2
3,1,13:18.2
4,7,13:18.2
8,2,13:18.2
-6,6,13:18.2
-5,-1,14:17.1
-4,-4,14:17.1
-3,-2,14:17.1
-1,-4,14:17.1
1,-7,14:17.1
2,-4,14:17.1
4,-4,14:17.1
6,-2,14:17.1
3,-1,14:17.1
-1,-1,14:17.1
1,3,14:17.1
-2,3,14:17.1
-2,1,14:17.1
-4,1,14:17.1
-6,2,14:17.1
-4,5,14:17.1
1,6,14:17.1
3,3,14:17.1
4,1,14:17.1
5,5,14:17.1
7,1,14:17.1
-3,2,14:18.2
-4,0,14:18.2
-5,1,14:18.2
-6,0,14:18.2
-5,-3,14:18.2
-4,-5,14:18.2
-3,-4,14:18.2
-2,-3,14:18.2
-2,-4,14:18.2
1,-2,14:18.2
1,-5,14:18.2
0,-7,14:18.2
-2,-6,14:18.2
-1,-7,14:18.2
-2,-5,14:18.2
1,-8,14:18.2
2,-7,14:18.2
4,-6,14:18.2
3,-6,14:18.2
3,-5,14:18.2
3,-4,14:18.2
5,-4,14:18.2
6,-4,14:18.2
6,-3,14:18.2
7,-2,14:18.2
7,0,14:18.2
8,1,14:18.2
7,3,14:18.2
6,4,14:18.2
5,3,14:18.2
6,2,14:18.2
6,-1,14:18.2
8,-1,14:18.2
1,-6,14:18.2
2,-5,14:18.2
0,-4,14:18.2
-1,-3,14:18.2
0,0,14:18.2
-3,-1,14:18.2
-4,-2,14:18.2
-6,-2,14:18.2
-7,1,14:18.2
-7,3,14:18.2
-6,4,14:18.2
-5,4,14:18.2
-5,5,14:18.2
-3,6,14:18.2
-1,6,14:18.2
0,6,14:18.2
1,7,14:18.2
2,6,14:18.2
3,6,14:18.2
2,5,14:18.2
0,4,14:18.2
1,5,14:18.2
-2,5,14:18.2
-1,3,14:18.2
0,2,14:18.2
2,1,14:18.2
2,2,14:18.2
4,2,14:18.2
4,0,14:18.2
5,-1,14:18.2
3,-3,14:18.2
3,-2,14:18.2
2,-6,14:18.2
7,-1,14:18.2
6,0,14:18.2
4,4,14:18.2
6,6,14:18.2
5,6,14:18.2
-4,3,14:18.2
2,-1,14:18.2
4,-2,14:18.2
-2,0,14:18.2
2,4,14:18.2
-2,7,14:18.2
3,7,14:18.2
-6,2,15:18.2
-4,1,15:18.2
-5,-1,15:18.2
-3,-2,15:18.2
-4,-4,15:18.2
-1,-4,15:18.2
-1,-1,15:18.2
-2,1,15:18.2
-2,3,15:18.2
-4,5,15:18.2
1,6,15:18.2
1,3,15:18.2
3,3,15:18.2
5,5,15:18.2
4,1,15:18.2
3,-1,15:18.2
2,-4,15:18.2
1,-7,15:18.2
4,-4,15:18.2
6,-2,15:18.2
7,1,15:18.2
