[META]
version=2.0
spawnOnBlockType=3,2,12,1
spawnSunlight=True
spawnDarkness=True
spawnWater=False
spawnLava=False
underFill=True
randomRotation=True
dig=True
tree=False
branch=False
needsFoundation=True
rarity=40
collisionPercentage=2
spawnElevationMin=0
spawnElevationMax=256
spawnInBiome=Grassland
[DATA]
0,0,0:17.2
0,1,0:17.2
0,-1,0:17.2
1,0,0:17.2
-1,0,0:17.2
0,0,1:17.2
0,0,2:17.2
-1,0,2:17.2
0,-1,2:17.2
0,1,2:17.2
0,2,2:86.0
-2,0,2:86.1
0,-2,2:86.2
-1,-1,2:18.2
1,0,2:18.2
-1,1,2:30
1,-1,2:30
0,-2,3:17.2
-2,0,3:17.2
1,0,3:17.2
-1,-2,3:18.2
0,-3,3:18.2
1,-2,3:18.2
-2,1,3:18.2
-3,0,3:18.2
2,0,3:18.2
1,1,3:18.2
2,0,4:17.2
0,-3,4:17.2
-3,0,4:17.2
0,0,4:17.2
3,0,4:17.2
3,1,4:17.2
0,-4,4:86.2
0,1,4:86.0
3,2,4:86.0
-4,0,4:86.1
4,0,4:86.3
2,-1,4:86.2
-3,1,4:18.2
0,-1,4:18.2
1,-1,4:30
-2,0,4:30
2,1,4:30
0,0,5:17.2
0,1,5:17.2
0,2,5:17.2
0,-3,5:17.2
-3,0,5:17.2
3,1,5:17.2
0,-1,5:18.2
-1,0,5:18.2
1,2,5:18.2
-1,2,5:18.2
-3,-1,5:18.2
-3,1,5:18.2
1,-3,5:18.2
-1,-3,5:18.2
1,0,5:18.2
0,3,5:18.2
1,-1,5:30
-1,1,5:30
0,-2,5:30
-2,0,5:30
3,0,5:30
-1,2,6:17.2
0,2,6:17.2
0,-3,6:17.2
2,-3,6:17.2
1,-3,6:17.2
-3,0,6:17.2
-3,-1,6:17.2
-4,-1,6:17.2
3,1,6:17.2
3,0,6:17.2
4,0,6:17.2
0,0,6:17.2
0,-4,6:86.2
4,-1,6:86.2
-4,-2,6:86.2
-1,3,6:86.0
3,2,6:86.0
2,-2,6:86.0
-3,1,6:86.0
-5,-1,6:86.1
-1,0,6:86.1
2,0,6:86.1
1,2,6:86.3
-2,-1,6:18.2
-2,2,6:18.2
5,0,6:18.2
2,-4,6:18.2
3,-3,6:18.2
-4,0,6:18.2
0,-1,6:18.2
0,3,6:18.2
3,-4,6:30
4,1,6:30
-3,2,6:30
-1,-1,6:30
2,1,6:30
1,-4,6:30
5,-1,6:30
0,0,7:17.2
0,-1,7:17.2
0,-2,7:86.2
-4,-1,7:18.2
0,-3,7:18.2
4,0,7:18.2
3,1,7:18.2
-1,2,7:18.2
-3,0,7:18.2
2,-3,7:18.2
3,0,7:30
1,-3,7:30
0,2,7:30
-3,-1,7:30
0,0,8:17.2
0,1,8:86.0
-1,0,8:18.2
0,-1,8:18.2
-1,1,8:30
-1,-1,8:30
0,0,9:86.3
