[META]
version=2.0
spawnOnBlockType=3,2,12,1
spawnSunlight=True
spawnDarkness=True
spawnWater=False
spawnLava=False
underFill=True
randomRotation=True
dig=True
tree=False
branch=False
needsFoundation=True
rarity=50
collisionPercentage=2
spawnElevationMin=0
spawnElevationMax=256
spawnInBiome=Grassland
[DATA]
0,1,0:86.0
-1,0,0:86.1
0,-1,0:86.2
1,0,0:86.3
0,0,0:86.3
1,-1,1:86.3
2,0,1:86.3
1,1,1:86.3
0,2,1:86.0
-1,1,1:86.1
-2,0,1:86.1
-1,-1,1:86.1
0,-2,1:86.2
0,-1,1:86.1
0,0,1:86.1
0,1,1:86.1
-1,0,1:86.1
1,0,1:86.1
0,-3,2:86.2
-1,-2,2:86.2
1,-2,2:86.2
2,-1,2:86.3
3,0,2:86.3
2,1,2:86.3
1,2,2:86.0
0,3,2:86.0
-1,2,2:86.0
-2,1,2:86.1
-3,0,2:86.1
-2,-1,2:86.1
0,-2,2:86.1
0,-1,2:86.1
0,0,2:86.1
0,1,2:86.1
0,2,2:86.1
-1,-1,2:86.1
-1,0,2:86.1
-1,1,2:86.1
-2,0,2:86.1
1,-1,2:86.1
1,0,2:86.1
1,1,2:86.1
2,0,2:86.1
-3,1,3:86.1
-2,2,3:86.1
-1,3,3:86.1
1,3,3:86.3
2,2,3:86.3
3,1,3:86.3
3,-1,3:86.2
2,-2,3:86.2
1,-3,3:86.2
-1,-3,3:86.2
-2,-2,3:86.2
-3,-1,3:86.2
-2,-1,4:86.2
-1,-2,4:86.2
0,-3,4:86.2
1,-2,4:86.2
2,-1,4:86.2
3,0,4:86.3
2,1,4:86.0
1,2,4:86.0
0,3,4:86.0
-1,2,4:86.0
-2,1,4:86.0
-3,0,4:86.1
-2,0,5:86.1
-1,1,5:86.1
-1,-1,5:86.1
1,-1,5:86.3
2,0,5:86.3
1,1,5:86.3
0,-2,5:86.2
0,2,5:86.0
0,-1,5:18.0
0,0,5:18.0
0,1,5:18.0
-1,0,5:18.0
1,0,5:18.0
0,0,6:18.0
-1,0,7:18.0
