[META]
version=2.0
spawnOnBlockType=2
spawnSunlight=True
spawnDarkness=True
spawnWater=False
spawnLava=False
underFill=False
randomRotation=True
dig=True
tree=False
branch=False
needsFoundation=True
rarity=10
collisionPercentage=70
spawnElevationMin=0
spawnElevationMax=102
groupId=Ruins
groupFrequencyMin=20
groupFrequencyMax=35
groupSeperationMin=5
groupSeperationMax=60
branchLimit=6
spawnInBiome=Jungle
[DATA]
-1,-2,-4:3.5
-2,-1,-4:1.5
-1,-1,-4:1.5
0,-1,-4:3.5
-2,0,-4:1.5
-1,0,-4:3.5
-2,-2,-3:3.5
-1,-2,-3:3.5
0,-2,-3:97.0
1,-2,-3:3.5
-2,-1,-3:1.5
-1,-1,-3:1.5
0,-1,-3:3.5
1,-1,-3:1.5
-2,0,-3:3.5
-1,0,-3:3.5
0,0,-3:3.5
1,0,-3:1.5
-2,1,-3:3.5
0,1,-3:3.5
-3,-4,-2:3.5
-1,-4,-2:3.5
0,-4,-2:97.0
-3,-3,-2:3.5
-2,-3,-2:3.5
-1,-3,-2:3.5
0,-3,-2:97.0
1,-3,-2:97.0
2,-3,-2:97.0
-2,-2,-2:3.5
-1,-2,-2:3.5
0,-2,-2:3.5
1,-2,-2:3.5
2,-2,-2:3.5
-3,-1,-2:3.5
-2,-1,-2:3.5
-1,-1,-2:3.5
0,-1,-2:3.5
1,-1,-2:3.5
2,-1,-2:3.5
3,-1,-2:3.5
-4,0,-2:3.5
-3,0,-2:3.5
-2,0,-2:3.5
-1,0,-2:3.5
0,0,-2:3.5
1,0,-2:3.5
2,0,-2:97.0
-3,1,-2:3.5
-2,1,-2:3.5
-1,1,-2:3.5
0,1,-2:3.5
1,1,-2:3.5
2,1,-2:3.5
-3,2,-2:3.5
1,2,-2:97.0
-2,3,-2:3.5
-1,3,-2:3.5
0,3,-2:3.5
-4,-4,-1:3.0
-3,-4,-1:3.0
-2,-4,-1:2.0
-1,-4,-1:2.0
0,-4,-1:2.0
1,-4,-1:2.0
2,-4,-1:2.0
3,-4,-1:3.5
-5,-3,-1:2.0
-4,-3,-1:2.0
-3,-3,-1:3.0
-2,-3,-1:3.0
-1,-3,-1:3.0
0,-3,-1:3.0
1,-3,-1:3.0
2,-3,-1:3.0
3,-3,-1:2.0
-5,-2,-1:97.0
-4,-2,-1:97.0
-3,-2,-1:3.0
-2,-2,-1:3.0
-1,-2,-1:3.0
0,-2,-1:3.0
1,-2,-1:3.0
2,-2,-1:3.0
3,-2,-1:2.0
4,-2,-1:2.0
-5,-1,-1:97.0
-4,-1,-1:2.0
-3,-1,-1:3.0
-2,-1,-1:3.0
-1,-1,-1:3.0
0,-1,-1:3.0
1,-1,-1:3.0
2,-1,-1:3.0
3,-1,-1:2.0
4,-1,-1:2.0
-5,0,-1:2.0
-4,0,-1:2.0
-3,0,-1:3.0
-2,0,-1:3.0
-1,0,-1:2.0
0,0,-1:3.0
1,0,-1:3.0
2,0,-1:3.0
3,0,-1:2.0
4,0,-1:2.0
-5,1,-1:2.0
-4,1,-1:2.0
-3,1,-1:3.0
-2,1,-1:3.0
-1,1,-1:3.0
0,1,-1:3.0
1,1,-1:3.0
2,1,-1:3.0
3,1,-1:2.0
-3,2,-1:3.0
-2,2,-1:3.0
-1,2,-1:3.0
0,2,-1:3.0
1,2,-1:3.0
2,2,-1:3.0
3,2,-1:2.0
-3,3,-1:2.0
-2,3,-1:2.0
-1,3,-1:2.0
0,3,-1:97.0
1,3,-1:3.5
2,3,-1:3.5
3,3,-1:3.0
-2,4,-1:2.0
-1,4,-1:2.0
0,4,-1:97.0
1,4,-1:2.0
-4,-4,0:98.0
-3,-4,0:44.5
-2,-4,0:44.5
-1,-4,0:44.5
0,-4,0:44.5
1,-4,0:44.5
2,-4,0:44.5
3,-4,0:98.1
-4,-3,0:44.5
-3,-3,0:98.0
-2,-3,0:98.0
-1,-3,0:98.0
0,-3,0:44.5
1,-3,0:98.1
2,-3,0:98.1
3,-3,0:44.5
-3,-2,0:44.5
-2,-2,0:98.0
-1,-2,0:98.0
0,-2,0:98.0
1,-2,0:98.0
2,-2,0:98.1
3,-2,0:44.5
-4,-1,0:44.5
-3,-1,0:98.1
-2,-1,0:98.0
-1,-1,0:98.2
0,-1,0:98.0
1,-1,0:98.0
2,-1,0:97.2
3,-1,0:44.5
-4,0,0:44.5
-3,0,0:98.0
-2,0,0:98.0
0,0,0:98.2
1,0,0:98.0
2,0,0:44.5
3,0,0:44.5
-4,1,0:44.5
-3,1,0:98.2
-2,1,0:98.0
-1,1,0:98.0
0,1,0:98.0
1,1,0:98.0
2,1,0:98.0
3,1,0:44.5
-4,2,0:44.5
-3,2,0:98.0
-2,2,0:98.1
-1,2,0:98.0
0,2,0:98.0
1,2,0:98.0
2,2,0:98.0
3,2,0:44.5
-4,3,0:98.0
-3,3,0:44.5
-2,3,0:44.5
-1,3,0:44.5
1,3,0:44.5
2,3,0:44.5
3,3,0:98.1
-3,-3,1:98.0
2,-3,1:98.1
-2,-2,1:44.5
-1,-2,1:44.5
0,-2,1:44.5
1,-2,1:44.5
-2,-1,1:44.5
-1,-1,1:98.2
0,-1,1:98.0
1,-1,1:44.5
-2,0,1:44.5
-1,0,1:98.0
0,0,1:98.2
1,0,1:44.5
-2,1,1:44.5
-1,1,1:44.5
0,1,1:44.5
1,1,1:44.5
-3,2,1:98.1
2,2,1:98.0
-1,-1,2:98.2
0,-1,2:98.1
-1,0,2:98.1
0,0,2:98.2
-1,-1,3:98.2
0,-1,3:98.0
-1,0,3:98.0
0,0,3:98.2
-1,-1,4:98.2
-1,0,4:98.1
0,0,4:98.2
-1,-1,5:98.2
-1,0,5:98.0
0,0,5:98.2
-1,-1,6:98.2
-1,0,6:98.1
0,0,6:98.2
-1,0,7:98.0
0,0,7:98.2
-1,0,8:98.0
-1,1,8:106.4
0,0,8:106.2
-2,0,8:106.8
-1,1,7:106.4
-2,0,7:106.8
0,-1,7:106.1
-1,1,6:106.4
0,-1,6:106.1
-2,-1,6:106.8
-1,1,5:106.4
-2,0,5:106.8
0,-1,5:106.1
-2,-1,5:106.8
-1,1,4:106.4
-2,0,4:106.8
0,-1,4:106.1
-2,-1,4:106.8
-1,-2,4:106.1
-1,1,3:106.4
-2,0,3:106.8
-2,-1,3:106.8
-1,-2,3:106.1
-1,1,2:106.4
-2,0,2:106.8
-2,-1,2:106.8
0,-2,2:106.1
-1,-2,2:106.1
