[META]
version=2.0
spawnOnBlockType=2
spawnSunlight=True
spawnDarkness=True
spawnWater=False
spawnLava=False
underFill=False
randomRotation=True
dig=True
tree=False
branch=False
needsFoundation=True
rarity=10
collisionPercentage=70
spawnElevationMin=0
spawnElevationMax=102
groupId=Ruins
groupFrequencyMin=20
groupFrequencyMax=35
groupSeperationMin=5
groupSeperationMax=60
branchLimit=6
spawnInBiome=Jungle
[DATA]
0,-1,0:109.2
0,0,0:98.0
1,0,0:109.1
0,1,0:44.5
-1,-1,-2:3
0,-1,-2:3
1,-1,-2:3
-1,0,-2:3
0,0,-2:3
1,0,-2:3
0,1,-2:3
1,1,-2:3
-1,-1,-1:43.0
0,-1,-1:98.0
1,-1,-1:43.0
-1,0,-1:2
0,0,-1:3
1,0,-1:98.0
0,1,-1:98.0
1,1,-1:43.0
0,0,1:98.0
0,1,1:106.4
-1,0,1:106.8
0,-1,1:106.1
0,0,2:98.2
0,1,2:106.4
-1,0,2:106.8
0,-1,2:106.1
0,0,3:98.0
0,1,3:106.4
1,0,3:106.2
0,-1,3:106.1
0,0,4:98.0
1,0,4:106.2
-1,0,4:106.8
0,-1,4:106.1
0,-1,5:98.0
-1,0,5:98.0
0,0,5:98.0
1,0,5:98.0
0,1,5:98.0
