[META]
version=2.0
spawnOnBlockType=8,9
spawnSunlight=True
spawnDarkness=True
spawnWater=False
spawnLava=False
underFill=False
randomRotation=True
dig=True
tree=False
branch=False
needsFoundation=True
rarity=10
collisionPercentage=10
spawnElevationMin=0
spawnElevationMax=100
spawnInBiome=Jungle
[DATA]
-2,-2,0:18
-1,-2,0:17.0
1,-2,0:98.1
2,-2,0:18
1,-1,0:98.0
0,0,0:18
1,0,0:98.1
1,1,0:98.0
2,1,0:106.2
0,1,0:106.4
-1,0,0:106.4
2,-1,0:106.2
3,-2,0:106.2
-3,-2,0:106.8
0,-3,-6:17.0
-3,-2,-6:17.0
1,-1,-6:98.1
2,-1,-6:98.1
-1,1,-6:17.0
1,1,-6:98.1
2,1,-6:98.1
0,-3,-5:17.0
-3,-2,-5:17.0
0,-2,-5:17.0
1,-1,-5:98.1
-1,1,-5:17.0
1,1,-5:98.1
-3,-2,-4:17.0
-1,-2,-4:17.0
0,-2,-4:17.0
-3,-1,-4:17.0
1,-1,-4:98.1
-1,0,-4:17.0
-1,1,-4:17.0
1,1,-4:98.1
-1,-2,-3:17.0
-3,-1,-3:17.0
-2,-1,-3:17.0
-1,-1,-3:17.0
1,-1,-3:98.1
-1,0,-3:17.0
1,1,-3:98.1
-2,-1,-2:17.0
-1,-1,-2:17.0
1,-1,-2:98.1
1,0,-2:98.1
1,1,-2:98.1
-1,-3,-1:9
0,-3,-1:9
1,-3,-1:9
2,-3,-1:9
-2,-2,-1:9
-1,-2,-1:17.0
0,-2,-1:9
1,-2,-1:109.3
2,-2,-1:9
-2,-1,-1:9
-1,-1,-1:17.0
0,-1,-1:9
1,-1,-1:98.1
2,-1,-1:9
-2,0,-1:9
-1,0,-1:9
0,0,-1:9
1,0,-1:98.1
2,0,-1:9
0,1,-1:9
1,1,-1:98.1
2,1,-1:9
0,2,-1:9
1,2,-1:9
2,2,-1:9
1,3,-1:9
0,-4,1:18
-2,-2,1:18
-1,-2,1:17.0
0,-2,1:17.0
1,-2,1:109.2
2,-2,1:18
-1,-1,1:18
1,-1,1:98.0
0,0,1:18
1,0,1:98.0
1,1,1:98.1
1,2,1:98.0
2,2,1:98.1
3,2,1:98.0
2,3,1:106.4
1,3,1:106.4
0,2,1:106.8
2,1,1:106.2
0,1,1:106.4
-1,0,1:106.4
2,-1,1:106.2
-2,-1,1:106.8
3,-2,1:106.2
-3,-2,1:106.8
-2,-3,1:106.8
0,-4,2:18
-1,-3,2:18
1,-3,2:18
-2,-2,2:18
0,-2,2:17.0
2,-2,2:18
-1,-1,2:18
1,-1,2:44
0,0,2:18
1,0,2:98.0
2,0,2:109.1
1,1,2:44
0,1,2:106.4
-1,0,2:106.4
-2,-1,2:106.8
3,-2,2:106.2
-3,-2,2:106.8
2,-3,2:106.2
-2,-3,2:106.8
1,-4,2:106.1
-1,-4,2:106.1
0,-4,3:18
-1,-3,3:18
0,-3,3:18
1,-3,3:18
-2,-2,3:18
-1,-2,3:18
0,-2,3:17.0
1,-2,3:18
2,-2,3:18
-1,-1,3:18
0,-1,3:18
1,-1,3:98.2
0,0,3:18
1,0,3:98.1
2,0,3:44.5
1,1,3:98.2
1,2,3:106.4
2,1,3:106.2
0,1,3:106.4
-1,0,3:106.4
2,-1,3:106.2
-2,-1,3:106.8
3,-2,3:106.2
-3,-2,3:106.8
2,-3,3:106.2
-2,-3,3:106.8
1,-4,3:106.1
-1,-4,3:106.1
0,-3,4:18
-1,-2,4:18
0,-2,4:18
1,-2,4:18
0,-1,4:18
1,-1,4:109.3
1,1,4:109.2
0,0,4:106.4
2,-2,4:106.2
-2,-2,4:106.8
0,-4,4:106.1
0,-2,5:18
