[META]
version=2.0
spawnOnBlockType=2
spawnSunlight=True
spawnDarkness=True
spawnWater=False
spawnLava=False
underFill=False
randomRotation=True
dig=True
tree=False
branch=False
needsFoundation=True
rarity=10
collisionPercentage=70
spawnElevationMin=0
spawnElevationMax=102
groupId=Ruins
groupFrequencyMin=20
groupFrequencyMax=35
groupSeperationMin=5
groupSeperationMax=60
branchLimit=6
spawnInBiome=Jungle
[DATA]
-1,-1,0:109.2
0,-1,0:109.2
1,-1,0:109.2
0,0,0:98.1
1,0,0:98.1
2,0,0:109.1
-1,1,0:109.3
0,1,0:109.3
1,1,0:109.3
-2,0,0:109.0
-1,0,0:98.1
-2,1,0:31.1
0,2,0:38
1,2,0:31.1
2,-1,0:38
0,-2,0:38
-2,-1,0:37
-1,2,0:31.1
2,1,0:37
-1,-2,0:37
1,-2,0:31.1
-1,0,1:98.1
1,0,1:98.1
0,0,1:98.1
-1,0,2:109.0
1,0,2:109.1
0,0,2:41
0,0,3:44.5
-2,0,-1:3
-1,0,-1:3
0,0,-1:3
0,1,-1:3
1,1,-1:3
1,0,-1:3
2,0,-1:3
-1,-1,-1:3
0,-1,-1:3
1,-1,-1:3
-1,1,-1:3
-2,1,-1:2
-2,-1,-1:2
-1,-2,-1:2
0,-2,-1:2
1,-2,-1:2
-1,2,-1:2
0,2,-1:2
1,2,-1:2
2,1,-1:2
2,-1,-1:2
0,-1,-2:3
1,-1,-2:3
1,0,-2:3
0,1,-2:3
-1,1,-2:3
-1,0,-2:3
0,0,-2:3
