[META]
version=2.0
spawnOnBlockType=2
spawnSunlight=True
spawnDarkness=True
spawnWater=False
spawnLava=False
underFill=False
randomRotation=True
dig=True
tree=False
branch=False
needsFoundation=True
rarity=10
collisionPercentage=10
spawnElevationMin=0
spawnElevationMax=102
groupId=Ruins
groupFrequencyMin=20
groupFrequencyMax=35
groupSeperationMin=5
groupSeperationMax=60
branchLimit=6
spawnInBiome=Jungle
[DATA]
-1,-2,-9:1.0
-2,-3,-8:1.0
0,-3,-8:1.0
1,-3,-8:1.0
-1,-2,-8:1.0
2,-2,-8:1.0
-1,-1,-8:1.0
0,-1,-8:1.0
1,-1,-8:1.0
2,-1,-8:1.0
-2,-4,-7:1.0
-1,-4,-7:1.0
1,-4,-7:1.0
2,-4,-7:1.0
-2,-3,-7:48.0
-1,-3,-7:48.0
0,-3,-7:48.0
1,-3,-7:48.0
2,-3,-7:48.0
-3,-2,-7:1.0
-2,-2,-7:1.0
-1,-2,-7:48.0
0,-2,-7:48.0
1,-2,-7:48.0
2,-2,-7:48.0
-3,-1,-7:1.0
-2,-1,-7:48.0
-1,-1,-7:48.0
0,-1,-7:48.0
1,-1,-7:48.0
2,-1,-7:48.0
-2,0,-7:1.0
-1,0,-7:1.0
0,0,-7:1.0
2,0,-7:1.0
-1,-5,-6:1.0
0,-5,-6:1.0
1,-5,-6:1.0
-3,-4,-6:1.0
-2,-4,-6:98.0
-1,-4,-6:98.0
0,-4,-6:98.0
1,-4,-6:98.0
2,-4,-6:98.0
-3,-3,-6:98.0
-2,-3,-6:43.0
2,-3,-6:43.0
3,-3,-6:98.0
-4,-2,-6:1.0
-3,-2,-6:98.0
3,-2,-6:98.0
4,-2,-6:1.0
-3,-1,-6:98.0
3,-1,-6:98.0
-3,0,-6:1.0
-2,0,-6:98.0
-1,0,-6:98.0
0,0,-6:98.0
1,0,-6:98.0
2,0,-6:98.0
3,0,-6:1.0
-1,1,-6:1.0
1,1,-6:1.0
-2,-5,-5:1.0
-1,-5,-5:1.0
1,-5,-5:1.0
2,-5,-5:1.0
-3,-4,-5:1.0
-2,-4,-5:98.0
-1,-4,-5:98.0
0,-4,-5:98.0
1,-4,-5:98.0
2,-4,-5:98.0
3,-4,-5:1.0
-4,-3,-5:1.0
-3,-3,-5:98.0
3,-3,-5:98.0
4,-3,-5:1.0
-4,-2,-5:1.0
-3,-2,-5:98.0
3,-2,-5:98.0
4,-2,-5:1.0
-4,-1,-5:1.0
-3,-1,-5:98.0
3,-1,-5:98.0
4,-1,-5:1.0
-3,0,-5:1.0
-2,0,-5:98.0
-1,0,-5:98.0
0,0,-5:98.0
1,0,-5:98.0
2,0,-5:98.0
3,0,-5:1.0
-2,1,-5:1.0
-1,1,-5:1.0
0,1,-5:1.0
1,1,-5:1.0
2,1,-5:1.0
-2,-4,-4:1.0
-1,-4,-4:2.0
0,-4,-4:1.0
1,-4,-4:1.0
2,-4,-4:1.0
-3,-3,-4:3.0
-2,-3,-4:98.1
-1,-3,-4:98.1
0,-3,-4:98.1
1,-3,-4:98.0
2,-3,-4:98.1
3,-3,-4:1.0
-3,-2,-4:1.0
-2,-2,-4:98.1
-1,-2,-4:98.1
0,-2,-4:98.0
1,-2,-4:98.1
2,-2,-4:98.0
3,-2,-4:1.0
4,-2,-4:3.0
-3,-1,-4:3.0
-2,-1,-4:98.1
-1,-1,-4:98.0
1,-1,-4:98.0
2,-1,-4:98.0
3,-1,-4:1.0
-3,0,-4:2.0
-2,0,-4:1.0
-1,0,-4:1.0
0,0,-4:98.0
1,0,-4:1.0
2,0,-4:1.0
3,0,-4:3.0
-2,1,-4:2.0
-1,1,-4:3.0
0,1,-4:3.0
1,1,-4:3.0
2,1,-4:2.0
-2,-4,-3:3.0
0,-4,-3:3.0
1,-4,-3:3.0
2,-4,-3:3.0
-3,-3,-3:3.0
-2,-3,-3:3.0
-1,-3,-3:3.0
0,-3,-3:1.0
1,-3,-3:1.0
2,-3,-3:1.0
3,-3,-3:3.0
-3,-2,-3:3.0
-2,-2,-3:1.0
-1,-2,-3:1.0
0,-2,-3:98.0
1,-2,-3:1.0
2,-2,-3:1.0
3,-2,-3:3.0
4,-2,-3:2.0
-3,-1,-3:3.0
-2,-1,-3:1.0
-1,-1,-3:98.0
1,-1,-3:98.0
2,-1,-3:1.0
3,-1,-3:3.0
-2,0,-3:3.0
-1,0,-3:3.0
0,0,-3:98.0
1,0,-3:3.0
2,0,-3:3.0
3,0,-3:2.0
-1,1,-3:3.0
0,1,-3:3.0
1,1,-3:3.0
0,2,-3:3.0
-3,-4,-2:3.0
-2,-4,-2:3.0
-1,-4,-2:3.0
0,-4,-2:3.0
1,-4,-2:3.0
2,-4,-2:3.0
-3,-3,-2:3.0
-2,-3,-2:3.0
-1,-3,-2:3.0
0,-3,-2:3.0
1,-3,-2:3.0
2,-3,-2:3.0
3,-3,-2:3.0
-3,-2,-2:3.0
-2,-2,-2:3.0
-1,-2,-2:3.0
0,-2,-2:98.2
1,-2,-2:3.0
2,-2,-2:3.0
3,-2,-2:3.0
-3,-1,-2:3.0
-2,-1,-2:3.0
-1,-1,-2:98.2
1,-1,-2:98.0
2,-1,-2:3.0
3,-1,-2:3.0
-3,0,-2:3.0
-2,0,-2:3.0
-1,0,-2:3.0
0,0,-2:98.0
1,0,-2:3.0
2,0,-2:3.0
-3,1,-2:3.0
-2,1,-2:3.0
-1,1,-2:3.0
0,1,-2:3.0
1,1,-2:3.0
-2,2,-2:3.0
-1,2,-2:3.0
0,2,-2:3.0
1,2,-2:3.0
-3,-5,-1:3.0
-2,-5,-1:2.5
-1,-5,-1:2.5
0,-5,-1:2.5
1,-5,-1:2.5
2,-5,-1:2.5
-4,-4,-1:2.5
-3,-4,-1:2.0
-2,-4,-1:98.0
-1,-4,-1:2.0
0,-4,-1:2.0
1,-4,-1:2.0
2,-4,-1:98.0
3,-4,-1:2.0
-3,-3,-1:98.0
-2,-3,-1:3.0
-1,-3,-1:3.0
0,-3,-1:3.0
1,-3,-1:3.0
2,-3,-1:3.0
3,-3,-1:98.0
-4,-2,-1:2.0
-3,-2,-1:2.0
-2,-2,-1:3.0
-1,-2,-1:98.1
0,-2,-1:98.2
1,-2,-1:98.2
2,-2,-1:3.0
3,-2,-1:2.0
4,-2,-1:2.0
-4,-1,-1:2.0
-3,-1,-1:2.0
-2,-1,-1:3.0
-1,-1,-1:98.1
1,-1,-1:98.2
2,-1,-1:3.0
3,-1,-1:2.0
-3,0,-1:2.0
-2,0,-1:3.0
-1,0,-1:98.1
0,0,-1:98.0
1,0,-1:98.1
2,0,-1:3.0
3,0,-1:2.0
4,0,-1:2.0
-3,1,-1:98.0
-2,1,-1:3.0
-1,1,-1:3.0
0,1,-1:3.0
1,1,-1:3.0
2,1,-1:3.0
3,1,-1:98.0
4,1,-1:3.0
5,1,-1:2.0
6,1,-1:3.0
-3,2,-1:2.0
-2,2,-1:98.0
-1,2,-1:2.0
0,2,-1:2.0
1,2,-1:2.0
2,2,-1:98.0
3,2,-1:2.0
4,2,-1:2.0
-3,-5,0:98.0
-4,-4,0:44.5
-1,-4,0:44.5
0,-4,0:44.5
1,-4,0:44.5
-2,-3,0:98.0
-1,-3,0:98.0
0,-3,0:98.0
1,-3,0:98.0
2,-3,0:98.0
-3,-2,0:44.5
-2,-2,0:98.0
2,-2,0:98.0
3,-2,0:44.5
-3,-1,0:44.5
-2,-1,0:98.0
1,-1,0:98.2
2,-1,0:98.0
3,-1,0:44.5
-3,0,0:44.5
-2,0,0:98.0
0,0,0:98.1
2,0,0:98.0
3,0,0:44.5
-2,1,0:98.0
-1,1,0:98.2
0,1,0:98.0
1,1,0:98.0
2,1,0:98.0
3,1,0:98.1
4,1,0:98.1
6,1,0:98.1
-1,2,0:44.5
0,2,0:44.5
1,2,0:44.5
-2,-3,1:98.1
2,-3,1:98.1
-2,1,1:98.1
-2,-3,2:98.1
2,-3,2:98.0
-2,1,2:98.1
2,-3,3:98.1
-2,1,3:98.1
-1,-3,4:98.0
0,-3,4:23.2
1,-3,4:98.0
2,-3,4:44.5
-2,-2,4:98.0
-1,-2,4:43.5
0,-2,4:98.0
1,-2,4:43.5
2,-2,4:98.0
-2,-1,4:23.4
-1,-1,4:98.0
1,-1,4:98.0
2,-1,4:23.5
-2,0,4:98.0
-1,0,4:43.5
0,0,4:98.0
1,0,4:43.5
2,0,4:98.0
-2,1,4:44.5
-1,1,4:98.0
0,1,4:23.3
1,1,4:98.0
2,1,4:44.5
0,-3,5:44.5
0,-2,5:44.5
-2,-1,5:44.5
-1,-1,5:44.5
0,-1,5:43.5
1,-1,5:44.5
2,-1,5:44.5
0,0,5:44.5
0,1,5:44.5
4,2,0:38.0
3,2,0:31.1
-3,2,0:31.1
5,1,0:31.1
4,0,0:31.2
4,-2,0:31.1
-4,-2,0:31.1
3,-4,0:31.2
2,-5,0:38.0
1,-5,0:31.1
0,-5,0:31.2
-1,-5,0:31.2
2,-3,-5:85.0
-2,-3,-5:85.0
