[META]
version=2.0
spawnOnBlockType=2
spawnSunlight=True
spawnDarkness=True
spawnWater=False
spawnLava=False
underFill=False
randomRotation=True
dig=True
tree=False
branch=False
needsFoundation=True
rarity=1
collisionPercentage=10
spawnElevationMin=0
spawnElevationMax=102
groupId=Ruins
groupFrequencyMin=20
groupFrequencyMax=35
groupSeperationMin=5
groupSeperationMax=60
branchLimit=6
spawnInBiome=All
[DATA]
-2,-3,0:44.5
0,-3,0:44.5
-2,-2,0:98.2
0,-2,0:43.5
-2,0,0:109.2
-4,1,0:98.1
-2,1,0:98.2
-1,1,0:98.1
0,1,0:98.0
-2,2,0:98.0
-1,2,0:98.1
0,2,0:98.1
1,2,0:98.0
2,2,0:44.5
-3,3,0:98.0
-1,3,0:98.0
-1,5,0:98.1
1,5,0:98.1
0,6,0:98.0
-2,4,0:31.1
1,3,0:38
1,1,0:106.2
0,0,0:106.1
1,-1,0:31.1
-1,-1,0:31.1
-5,-1,0:38
1,-2,0:106.2
-3,-1,-3:1
-2,-1,-3:1
-1,-1,-3:1
0,-1,-3:1
-4,0,-3:1
-3,0,-3:1
-2,0,-3:1
-1,0,-3:1
0,0,-3:1
-4,1,-3:3
-3,1,-3:1
-2,1,-3:1
-1,1,-3:1
0,1,-3:1
-4,2,-3:2
-3,2,-3:1
-2,2,-3:1
-1,2,-3:1
0,2,-3:1
-3,3,-3:1
-2,3,-3:1
-1,3,-3:1
0,3,-3:1
-3,4,-3:1
-2,4,-3:1
-1,4,-3:1
0,4,-3:1
-2,5,-3:3
-1,5,-3:1
0,5,-3:3
1,5,-3:1
-1,6,-3:2
0,6,-3:2
0,-2,-2:3
-4,-1,-2:3
-3,-1,-2:3
-2,-1,-2:1
-1,-1,-2:1
0,-1,-2:3
-4,0,-2:3
-3,0,-2:3
-2,0,-2:1
-1,0,-2:3
0,0,-2:3
1,0,-2:3
-4,1,-2:3
-3,1,-2:3
-2,1,-2:3
-1,1,-2:3
0,1,-2:3
1,1,-2:3
-3,2,-2:3
-2,2,-2:3
-1,2,-2:3
0,2,-2:3
1,2,-2:3
-5,3,-2:3
-4,3,-2:3
-3,3,-2:3
-2,3,-2:3
-1,3,-2:3
0,3,-2:3
1,3,-2:3
2,3,-2:1
-4,4,-2:3
-3,4,-2:3
-2,4,-2:3
-1,4,-2:3
0,4,-2:3
1,4,-2:3
2,4,-2:1
-4,5,-2:3
-3,5,-2:3
-2,5,-2:3
-1,5,-2:1
0,5,-2:1
1,5,-2:3
2,5,-2:1
-2,-2,-2:3
-1,-2,-2:3
-1,-3,-2:3
0,-3,-2:3
-3,-2,-2:3
-1,-4,-1:2
0,-4,-1:2
-3,-3,-1:2
-2,-3,-1:2
-1,-3,-1:2
0,-3,-1:2
1,-3,-1:2
-4,-2,-1:2
-3,-2,-1:2
-2,-2,-1:3
-1,-2,-1:2
0,-2,-1:3
1,-2,-1:2
-5,-1,-1:2
-4,-1,-1:2
-3,-1,-1:2
-2,-1,-1:2
-1,-1,-1:2
0,-1,-1:2
1,-1,-1:2
-5,0,-1:2
-4,0,-1:2
-3,0,-1:98.2
-2,0,-1:98.0
-1,0,-1:2
0,0,-1:2
1,0,-1:2
-5,1,-1:2
-4,1,-1:3
-3,1,-1:2
-2,1,-1:3
-1,1,-1:3
0,1,-1:3
1,1,-1:2
2,1,-1:2
-5,2,-1:2
-4,2,-1:2
-3,2,-1:98.1
-2,2,-1:3
-1,2,-1:3
0,2,-1:3
2,2,-1:2
-5,3,-1:98.2
-4,3,-1:2
-3,3,-1:3
-2,3,-1:2
-1,3,-1:3
0,3,-1:2
1,3,-1:2
2,3,-1:2
-5,4,-1:2
-4,4,-1:2
-3,4,-1:2
-2,4,-1:2
-1,4,-1:2
0,4,-1:98.1
1,4,-1:2
2,4,-1:2
-4,5,-1:98.2
-3,5,-1:2
-2,5,-1:2
-1,5,-1:3
0,5,-1:2
1,5,-1:3
2,5,-1:2
-2,6,-1:2
-1,6,-1:2
0,6,-1:3
1,6,-1:2
-2,-2,1:109.3
0,-2,1:98.2
1,-2,1:106.2
0,-3,1:106.1
