[META]
version=2.0
spawnOnBlockType=3,2,1
spawnSunlight=True
spawnDarkness=False
spawnWater=False
spawnLava=False
underFill=True
randomRotation=True
dig=True
tree=False
branch=False
needsFoundation=True
rarity=450
collisionPercentage=2
spawnElevationMin=65
spawnElevationMax=100
spawnInBiome=Forest
[DATA]
-1,-1,0:17.1
-1,0,0:17.1
-1,1,0:17.1
0,1,0:17.1
1,1,0:17.1
1,0,0:17.1
1,-1,0:17.1
0,-1,0:17.1
0,-2,0:17.1
1,-2,0:17.1
-2,-1,0:17.1
-1,2,0:17.1
2,1,0:17.1
0,0,0:17.1
-2,2,0:17.1
-2,3,0:17.1
-2,-2,0:17.1
-3,-2,0:17.1
1,-3,0:17.1
2,-3,0:17.1
3,1,0:17.1
4,1,0:17.1
-3,2,0:17.1
1,-4,0:17.1
4,0,0:17.1
2,2,0:17.1
2,-4,-1:17.1
3,-4,-1:17.1
2,-3,-1:17.1
1,-2,-1:17.1
1,-3,-1:17.1
0,-2,-1:17.1
0,-1,-1:17.1
0,0,-1:17.1
-1,-1,-1:17.1
-1,0,-1:17.1
-1,1,-1:17.1
0,1,-1:17.1
1,1,-1:17.1
1,0,-1:17.1
1,-1,-1:17.1
-1,2,-1:17.1
-2,3,-1:17.1
-2,4,-1:17.1
-2,5,-1:17.1
2,1,-1:17.1
3,1,-1:17.1
4,2,-1:17.1
-2,-1,-1:17.1
-3,-2,-1:17.1
-4,-2,-1:17.1
-4,-3,-1:17.1
-2,2,-1:17.1
4,1,-1:17.1
-2,-2,-1:17.1
-3,5,-1:17.1
-4,-4,-1:17.1
-5,-4,-1:17.1
4,3,-1:17.1
5,3,-1:17.1
3,-5,-1:17.1
-1,-1,1:17.1
-1,0,1:17.1
-1,1,1:17.1
0,1,1:17.1
1,1,1:17.1
1,0,1:17.1
1,-1,1:17.1
0,-1,1:17.1
0,0,1:17.1
-2,-1,1:17.1
1,-2,1:17.1
2,1,1:17.1
-1,2,1:17.1
-1,-1,2:17.1
-1,0,2:17.1
-1,1,2:17.1
0,1,2:17.1
0,0,2:17.1
1,0,2:17.1
0,-1,2:17.1
1,-1,2:17.1
1,1,2:17.1
2,0,2:18.1
-1,-1,3:17.1
-1,0,3:17.1
0,0,3:17.1
0,1,3:17.1
1,1,3:17.1
1,0,3:17.1
1,-1,3:17.1
0,-1,3:17.1
-1,1,3:17.1
-1,2,3:18.1
0,-2,3:18.1
-1,-1,4:17.1
-1,0,4:17.1
-1,1,4:17.1
0,1,4:17.1
1,1,4:17.1
1,0,4:17.1
1,-1,4:17.1
0,-1,4:17.1
0,0,4:17.1
-1,-1,5:17.1
-1,0,5:17.1
-1,1,5:17.1
0,1,5:17.1
1,1,5:17.1
1,0,5:17.1
1,-1,5:17.1
0,-1,5:17.1
0,0,5:17.1
-1,-2,5:17.1
-1,-3,5:17.1
-1,-4,5:17.1
1,2,5:17.1
1,3,5:17.1
2,3,5:17.1
2,4,5:17.1
2,5,5:17.1
-2,0,5:17.1
-3,0,5:17.1
-3,1,5:17.1
-4,1,5:17.1
2,0,5:17.1
3,0,5:17.1
4,0,5:17.1
4,-1,5:17.1
0,-4,5:17.1
-3,2,5:18.1
-2,-4,5:18.1
4,1,5:18.1
3,5,5:18.1
0,3,5:18.1
-2,-2,5:18.1
0,-5,5:18.1
-5,1,5:18.1
1,5,5:18.1
4,-2,5:18.1
1,-2,5:18.1
5,0,5:18.1
-4,0,5:18.1
0,-5,6:17.1
0,-4,6:17.1
-4,1,6:17.1
-4,2,6:17.1
-3,-1,6:17.1
-3,0,6:17.1
-1,-3,6:17.1
-2,-3,6:17.1
1,3,6:17.1
0,3,6:17.1
2,5,6:17.1
3,5,6:17.1
4,-2,6:17.1
4,-1,6:17.1
3,0,6:17.1
3,1,6:17.1
1,-2,6:17.1
1,-1,6:17.1
-1,1,6:18.1
-1,-2,6:18.1
0,-1,6:18.1
2,0,6:18.1
1,2,6:18.1
2,4,6:18.1
-2,0,6:18.1
-3,1,6:18.1
-1,-4,6:18.1
4,0,6:18.1
0,0,6:18.1
1,1,6:18.1
2,3,6:18.1
-1,-1,6:18.1
-1,0,6:18.1
0,1,6:18.1
1,0,6:18.1
3,6,6:18.1
-4,3,6:18.1
0,-6,6:18.1
-3,-3,6:18.1
1,-3,6:18.1
4,-3,6:18.1
3,-2,6:18.1
5,-2,6:18.1
3,2,6:18.1
-1,3,6:18.1
0,4,6:18.1
-4,-1,6:18.1
4,5,6:18.1
-4,2,7:17.1
-5,2,7:17.1
0,-5,7:17.1
-1,-5,7:17.1
4,-2,7:17.1
5,-2,7:17.1
3,5,7:17.1
3,6,7:17.1
0,3,7:17.1
-1,3,7:17.1
-1,-3,7:17.1
-1,-2,7:17.1
3,1,7:17.1
2,1,7:17.1
-3,-1,7:17.1
-4,-1,7:17.1
-1,-1,7:18.1
-2,-5,7:18.1
-5,-1,7:18.1
-6,2,7:18.1
-2,3,7:18.1
3,7,7:18.1
4,1,7:18.1
6,-2,7:18.1
3,-2,7:18.1
1,1,7:18.1
0,4,7:18.1
4,5,7:18.1
0,-6,7:18.1
1,-5,7:18.1
-2,-3,7:18.1
0,-2,7:18.1
-4,-2,7:18.1
-4,3,7:18.1
5,-3,7:18.1
2,4,7:18.1
2,5,7:18.1
1,-1,7:18.1
-1,2,7:18.1
-1,-6,7:18.1
4,-1,7:18.1
4,6,7:18.1
-5,3,7:18.1
-4,0,7:18.1
-1,-4,7:18.1
3,-3,7:18.1
-4,1,7:18.1
-3,0,7:18.1
0,-4,7:18.1
1,-2,7:18.1
3,0,7:18.1
1,3,7:18.1
-5,2,8:17.1
-4,-1,8:17.1
-1,-2,8:17.1
-1,-5,8:17.1
5,-2,8:17.1
3,1,8:17.1
-1,3,8:17.1
3,6,8:17.1
-4,0,8:18.1
-1,2,8:18.1
3,2,8:18.1
-1,-6,8:18.1
5,-1,8:18.1
2,6,8:18.1
-3,-1,8:17.1
-3,0,8:17.1
-3,1,8:17.1
-5,-1,8:17.1
-5,-2,8:17.1
-5,-3,8:17.1
-6,-3,8:17.1
0,3,8:17.1
1,3,8:17.1
1,4,8:17.1
1,5,8:17.1
3,5,8:17.1
3,4,8:17.1
4,4,8:17.1
5,4,8:17.1
2,1,8:17.1
2,0,8:17.1
4,-2,8:17.1
4,-3,8:17.1
4,-4,8:17.1
4,-5,8:17.1
3,-5,8:17.1
5,-4,8:17.1
6,-4,8:17.1
0,-5,8:17.1
0,-6,8:17.1
0,-7,8:17.1
-1,-7,8:17.1
-1,-8,8:17.1
-5,-4,8:17.1
-6,-4,8:18.1
-7,-3,8:18.1
-6,-2,8:18.1
-5,-5,8:18.1
-4,-4,8:18.1
-2,-8,8:18.1
-2,-9,8:18.1
-1,-9,8:18.1
0,-8,8:18.1
1,-7,8:18.1
2,-5,8:18.1
3,-6,8:18.1
5,-5,8:18.1
6,-5,8:18.1
7,-4,8:18.1
6,-3,8:18.1
3,-4,8:18.1
2,-1,8:18.1
1,0,8:18.1
3,0,8:18.1
-2,-2,8:18.1
-1,-3,8:18.1
-2,0,8:18.1
-5,1,8:18.1
-6,2,8:18.1
5,3,8:18.1
6,4,8:18.1
5,5,8:18.1
0,5,8:18.1
-4,2,8:18.1
-5,2,9:18.1
-5,1,9:18.1
-6,2,9:18.1
-5,3,9:18.1
-4,2,9:18.1
-2,3,9:18.1
-1,2,9:18.1
-1,3,9:18.1
-1,4,9:18.1
0,3,9:18.1
2,1,9:18.1
3,1,9:18.1
3,0,9:18.1
4,1,9:18.1
3,2,9:18.1
3,5,9:18.1
3,6,9:18.1
2,6,9:18.1
3,7,9:18.1
4,6,9:18.1
5,-2,9:18.1
4,-2,9:18.1
5,-3,9:18.1
5,-1,9:18.1
6,-2,9:18.1
-1,-2,9:18.1
-1,-3,9:18.1
0,-2,9:18.1
-2,-2,9:18.1
-1,-1,9:18.1
0,-5,9:18.1
-1,-5,9:18.1
-2,-5,9:18.1
-1,-6,9:18.1
-4,-2,9:18.1
-4,0,9:18.1
-5,-1,9:18.1
-4,-1,9:18.1
-3,-1,9:18.1
-1,-4,9:18.1
1,5,9:18.1
5,4,9:18.1
6,-4,9:18.1
3,-5,9:18.1
-1,-8,9:18.1
0,-7,9:18.1
-5,-4,9:18.1
-6,-3,9:18.1
-5,-2,9:18.1
-1,-7,9:18.1
-3,1,9:18.1
4,-5,9:18.1
5,-4,9:18.1
1,4,9:18.1
4,4,9:18.1
1,3,9:18.1
3,4,9:18.1
2,0,9:18.1
4,-4,9:18.1
0,-6,9:18.1
-5,-3,9:18.1
-3,0,9:18.1
4,-3,9:18.1
-1,-5,10:18.1
-1,-2,10:18.1
-4,-1,10:18.1
2,1,10:18.1
-1,3,10:18.1
-4,2,10:18.1
4,-2,10:18.1
3,6,10:18.1
-6,-3,10:18.1
-1,-7,10:18.1
5,-4,10:18.1
-6,2,10:18.1
1,5,10:18.1
3,-5,10:18.1
