[META]
version=2.0
spawnOnBlockType=2
spawnSunlight=True
spawnDarkness=True
spawnWater=False
spawnLava=False
underFill=False
randomRotation=True
dig=True
tree=False
branch=False
needsFoundation=True
rarity=30
collisionPercentage=5
spawnElevationMin=0
spawnElevationMax=102
groupId=Ruins
groupFrequencyMin=20
groupFrequencyMax=35
groupSeperationMin=5
groupSeperationMax=60
branchLimit=6
spawnInBiome=All
[DATA]
-6,-15,0:109.0
-4,-15,0:18
1,-15,0:2
2,-15,0:2
13,-15,0:44.5
-11,-14,0:18
-5,-14,0:18
-4,-14,0:17.1
-3,-14,0:18
0,-14,0:2
1,-14,0:2
2,-14,0:2
3,-14,0:2
4,-14,0:2
-12,-13,0:18
-11,-13,0:17.1
-10,-13,0:18
-5,-13,0:18
-4,-13,0:18
-3,-13,0:98.1
-2,-13,0:109.2
-1,-13,0:109.2
0,-13,0:2
1,-13,0:3
2,-13,0:3
3,-13,0:2
4,-13,0:98.0
7,-13,0:2
8,-13,0:17.0
9,-13,0:2
-14,-12,0:44.5
-12,-12,0:18
-11,-12,0:44.5
-10,-12,0:98.0
-9,-12,0:44.5
-4,-12,0:44.5
-3,-12,0:98.0
-2,-12,0:98.0
-1,-12,0:98.0
0,-12,0:98.0
1,-12,0:98.0
2,-12,0:98.0
3,-12,0:98.0
4,-12,0:98.0
5,-12,0:44.5
6,-12,0:2
7,-12,0:3
8,-12,0:3
9,-12,0:2
10,-12,0:44.5
11,-12,0:98.1
12,-12,0:44.5
-12,-11,0:2
-11,-11,0:98.0
-10,-11,0:98.0
-9,-11,0:98.0
-8,-11,0:98.0
-7,-11,0:98.0
-6,-11,0:98.0
-5,-11,0:98.0
-4,-11,0:98.0
-3,-11,0:98.0
-2,-11,0:98.0
-1,-11,0:98.0
0,-11,0:98.0
1,-11,0:98.0
2,-11,0:98.0
3,-11,0:98.0
4,-11,0:98.0
5,-11,0:98.0
6,-11,0:98.0
7,-11,0:98.0
8,-11,0:98.0
9,-11,0:98.0
10,-11,0:98.0
11,-11,0:98.0
12,-11,0:98.0
-13,-10,0:2
-12,-10,0:2
-11,-10,0:2
-10,-10,0:98.0
-9,-10,0:98.0
-8,-10,0:98.0
-7,-10,0:98.0
-6,-10,0:98.0
-5,-10,0:98.0
-4,-10,0:98.0
-3,-10,0:98.0
-2,-10,0:98.0
-1,-10,0:98.0
0,-10,0:98.1
1,-10,0:98.0
2,-10,0:98.0
3,-10,0:98.0
4,-10,0:98.0
5,-10,0:98.0
6,-10,0:98.0
7,-10,0:98.0
8,-10,0:98.0
9,-10,0:98.0
10,-10,0:98.0
11,-10,0:98.0
12,-10,0:2
13,-10,0:2
-12,-9,0:2
-11,-9,0:3
-10,-9,0:98.0
-9,-9,0:98.0
-8,-9,0:98.0
-7,-9,0:98.1
-6,-9,0:98.0
-5,-9,0:98.1
-4,-9,0:98.1
-3,-9,0:98.0
-2,-9,0:98.0
-1,-9,0:98.0
0,-9,0:98.0
1,-9,0:98.1
2,-9,0:98.0
3,-9,0:98.0
4,-9,0:98.0
5,-9,0:98.0
6,-9,0:98.0
7,-9,0:98.0
8,-9,0:98.0
9,-9,0:98.0
10,-9,0:98.0
11,-9,0:98.1
12,-9,0:3
13,-9,0:2
14,-9,0:2
-12,-8,0:44.5
-11,-8,0:2
-10,-8,0:98.0
-9,-8,0:98.0
-8,-8,0:98.1
-7,-8,0:98.0
-6,-8,0:98.0
-5,-8,0:98.0
-4,-8,0:98.0
-3,-8,0:98.0
-2,-8,0:98.0
-1,-8,0:98.0
0,-8,0:98.0
1,-8,0:98.0
2,-8,0:98.0
3,-8,0:98.1
4,-8,0:98.0
5,-8,0:98.1
6,-8,0:98.0
7,-8,0:98.0
8,-8,0:98.0
9,-8,0:98.0
10,-8,0:98.0
11,-8,0:98.1
12,-8,0:3
13,-8,0:3
14,-8,0:2
-12,-7,0:18
-11,-7,0:18
-10,-7,0:98.0
-9,-7,0:98.1
-8,-7,0:98.1
-7,-7,0:98.0
-6,-7,0:98.0
-5,-7,0:98.1
-4,-7,0:98.0
-3,-7,0:98.0
-2,-7,0:98.1
-1,-7,0:98.0
0,-7,0:98.0
1,-7,0:98.0
2,-7,0:98.1
3,-7,0:98.0
4,-7,0:98.0
5,-7,0:98.0
6,-7,0:98.1
7,-7,0:98.0
8,-7,0:98.0
9,-7,0:98.0
10,-7,0:98.0
11,-7,0:98.1
12,-7,0:3
13,-7,0:3
14,-7,0:2
15,-7,0:2
-13,-6,0:18
-12,-6,0:17.1
-11,-6,0:44.5
-10,-6,0:98.0
-9,-6,0:98.0
-8,-6,0:98.0
-7,-6,0:98.1
-6,-6,0:98.1
-5,-6,0:98.0
-4,-6,0:98.0
-3,-6,0:98.0
-2,-6,0:98.0
-1,-6,0:98.0
0,-6,0:98.0
1,-6,0:98.0
2,-6,0:98.0
3,-6,0:98.1
4,-6,0:98.0
5,-6,0:98.0
6,-6,0:98.0
7,-6,0:98.1
8,-6,0:98.1
9,-6,0:98.0
10,-6,0:98.0
11,-6,0:98.1
12,-6,0:3
13,-6,0:3
14,-6,0:2
-13,-5,0:18
-12,-5,0:98.0
-11,-5,0:98.0
-10,-5,0:98.1
-9,-5,0:98.1
-8,-5,0:98.1
-7,-5,0:98.0
-6,-5,0:98.0
-5,-5,0:98.1
-4,-5,0:98.0
-3,-5,0:98.0
-2,-5,0:98.0
-1,-5,0:98.0
0,-5,0:98.0
1,-5,0:98.0
2,-5,0:98.0
3,-5,0:98.0
4,-5,0:98.1
5,-5,0:98.0
6,-5,0:98.0
7,-5,0:98.0
8,-5,0:98.0
9,-5,0:98.0
10,-5,0:98.0
11,-5,0:98.0
12,-5,0:98.1
13,-5,0:98.1
14,-5,0:98.1
15,-5,0:109.1
-13,-4,0:18
-12,-4,0:109.0
-11,-4,0:98.0
-10,-4,0:98.0
-9,-4,0:98.0
-8,-4,0:98.1
-7,-4,0:98.1
-6,-4,0:98.0
-5,-4,0:98.0
-4,-4,0:98.1
-3,-4,0:98.0
-2,-4,0:98.0
-1,-4,0:98.0
0,-4,0:98.0
1,-4,0:98.0
2,-4,0:98.0
3,-4,0:98.0
4,-4,0:98.0
5,-4,0:98.0
6,-4,0:98.1
7,-4,0:98.0
8,-4,0:98.0
9,-4,0:98.1
10,-4,0:98.0
11,-4,0:98.0
12,-4,0:98.0
13,-4,0:109.1
-12,-3,0:109.0
-11,-3,0:98.0
-10,-3,0:98.0
-9,-3,0:98.0
-8,-3,0:98.2
-7,-3,0:98.0
-6,-3,0:98.2
-5,-3,0:98.0
-4,-3,0:98.2
-3,-3,0:98.0
-2,-3,0:98.1
-1,-3,0:98.0
0,-3,0:98.2
1,-3,0:98.0
2,-3,0:98.2
3,-3,0:98.0
4,-3,0:98.2
5,-3,0:43.0
6,-3,0:43.0
7,-3,0:43.0
8,-3,0:43.0
9,-3,0:43.0
10,-3,0:43.0
11,-3,0:43.0
12,-3,0:43.0
13,-3,0:109.1
15,-3,0:44.5
-12,-2,0:109.0
-11,-2,0:98.0
-10,-2,0:98.0
-9,-2,0:98.0
-8,-2,0:98.0
-7,-2,0:98.0
-6,-2,0:109.1
-1,-2,0:98.0
0,-2,0:98.0
1,-2,0:98.0
2,-2,0:98.0
3,-2,0:98.0
4,-2,0:98.0
5,-2,0:98.0
6,-2,0:98.0
7,-2,0:98.0
8,-2,0:98.0
9,-2,0:98.0
10,-2,0:98.0
11,-2,0:98.1
12,-2,0:98.1
13,-2,0:109.1
-12,-1,0:109.0
-11,-1,0:98.0
-10,-1,0:98.0
-9,-1,0:98.1
-8,-1,0:98.0
-7,-1,0:98.0
-6,-1,0:109.1
-1,-1,0:98.0
0,-1,0:98.0
1,-1,0:98.0
2,-1,0:98.0
3,-1,0:98.0
4,-1,0:98.0
5,-1,0:98.0
6,-1,0:98.0
7,-1,0:98.0
8,-1,0:98.0
9,-1,0:98.0
10,-1,0:98.0
11,-1,0:98.0
12,-1,0:98.0
13,-1,0:109.1
-12,0,0:109.0
-11,0,0:98.0
-10,0,0:98.0
-9,0,0:98.1
-8,0,0:98.2
-7,0,0:98.1
-6,0,0:98.2
-5,0,0:98.0
-4,0,0:98.2
-3,0,0:98.0
-2,0,0:98.2
-1,0,0:98.0
0,0,0:98.2
1,0,0:98.0
2,0,0:98.2
3,0,0:98.0
4,0,0:98.2
5,0,0:43.0
6,0,0:43.0
7,0,0:43.0
8,0,0:43.0
9,0,0:43.0
10,0,0:43.0
11,0,0:43.0
12,0,0:43.0
13,0,0:109.1
-12,1,0:109.0
-11,1,0:98.0
-10,1,0:98.0
-9,1,0:98.0
-8,1,0:98.0
-7,1,0:98.0
-6,1,0:98.0
-5,1,0:98.0
-4,1,0:98.0
-3,1,0:98.0
-2,1,0:98.0
-1,1,0:98.0
0,1,0:98.0
1,1,0:98.0
2,1,0:98.0
3,1,0:98.0
4,1,0:98.0
5,1,0:98.0
6,1,0:98.0
7,1,0:98.0
8,1,0:98.0
9,1,0:98.0
10,1,0:98.0
11,1,0:98.0
12,1,0:98.0
13,1,0:109.1
16,1,0:44.5
-13,2,0:18
-12,2,0:98.0
-11,2,0:98.0
-10,2,0:98.1
-9,2,0:98.1
-8,2,0:98.1
-7,2,0:98.1
-6,2,0:17
-5,2,0:98.0
-4,2,0:98.0
-3,2,0:98.0
-2,2,0:98.0
-1,2,0:98.0
0,2,0:98.0
1,2,0:98.0
2,2,0:98.1
3,2,0:98.0
4,2,0:98.0
5,2,0:98.0
6,2,0:98.0
7,2,0:98.1
8,2,0:98.0
9,2,0:98.1
10,2,0:98.0
11,2,0:98.0
12,2,0:98.0
13,2,0:98.0
14,2,0:98.1
15,2,0:109.1
-13,3,0:18
-12,3,0:17.1
-11,3,0:44.5
-10,3,0:98.0
-9,3,0:98.0
-8,3,0:98.1
-7,3,0:98.0
-6,3,0:98.1
-5,3,0:98.0
-4,3,0:98.0
-3,3,0:98.0
-2,3,0:98.0
-1,3,0:98.0
0,3,0:98.0
1,3,0:98.0
2,3,0:98.0
3,3,0:98.0
4,3,0:98.1
5,3,0:98.0
6,3,0:98.1
7,3,0:98.0
8,3,0:98.0
9,3,0:98.0
10,3,0:98.1
11,3,0:98.0
12,3,0:44.5
-12,4,0:18
-11,4,0:18
-10,4,0:98.0
-9,4,0:98.1
-8,4,0:98.0
-7,4,0:98.0
-6,4,0:98.1
-5,4,0:98.1
-4,4,0:98.0
-3,4,0:98.1
-2,4,0:98.0
-1,4,0:98.0
0,4,0:98.0
1,4,0:98.0
2,4,0:98.0
3,4,0:98.0
4,4,0:98.0
5,4,0:98.0
6,4,0:98.1
7,4,0:98.0
8,4,0:98.0
9,4,0:98.0
10,4,0:98.0
11,4,0:98.0
15,4,0:44.5
-11,5,0:2
-10,5,0:98.0
-9,5,0:98.0
-8,5,0:98.0
-7,5,0:98.0
-6,5,0:98.0
-5,5,0:98.0
-4,5,0:98.0
-3,5,0:98.0
-2,5,0:98.0
-1,5,0:98.0
0,5,0:98.0
1,5,0:98.0
2,5,0:98.0
3,5,0:98.1
4,5,0:98.0
5,5,0:98.0
6,5,0:98.0
7,5,0:98.0
8,5,0:98.1
9,5,0:98.0
10,5,0:98.0
11,5,0:98.1
12,5,0:18
-13,6,0:44.5
-12,6,0:2
-11,6,0:3
-10,6,0:98.1
-9,6,0:98.0
-8,6,0:98.0
-7,6,0:98.0
-6,6,0:98.1
-5,6,0:98.0
-4,6,0:98.0
-3,6,0:98.0
-2,6,0:98.0
-1,6,0:98.0
0,6,0:98.0
1,6,0:98.0
2,6,0:98.0
3,6,0:98.0
4,6,0:98.0
5,6,0:98.0
6,6,0:98.0
7,6,0:98.0
8,6,0:98.0
9,6,0:98.0
10,6,0:98.0
11,6,0:98.0
12,6,0:18
13,6,0:18
-13,7,0:2
-12,7,0:3
-11,7,0:3
-10,7,0:98.0
-9,7,0:98.0
-8,7,0:98.0
-7,7,0:98.0
-6,7,0:98.0
-5,7,0:98.0
-4,7,0:98.0
-3,7,0:98.0
-2,7,0:98.0
-1,7,0:98.0
0,7,0:98.0
1,7,0:98.0
2,7,0:98.0
3,7,0:98.0
4,7,0:98.0
5,7,0:98.0
6,7,0:98.0
7,7,0:98.0
8,7,0:98.0
9,7,0:98.0
10,7,0:98.0
11,7,0:98.0
12,7,0:44.5
13,7,0:18
-12,8,0:2
-11,8,0:98.0
-10,8,0:98.0
-9,8,0:98.0
-8,8,0:98.0
-7,8,0:98.0
-6,8,0:98.0
-5,8,0:98.0
-4,8,0:98.0
-3,8,0:98.1
-2,8,0:98.0
-1,8,0:98.0
0,8,0:98.0
1,8,0:98.0
2,8,0:98.0
3,8,0:98.1
4,8,0:98.0
5,8,0:98.0
6,8,0:98.0
7,8,0:98.0
8,8,0:98.0
9,8,0:98.0
10,8,0:98.0
11,8,0:98.0
12,8,0:98.1
14,8,0:44.5
-11,9,0:44.5
-10,9,0:98.0
-9,9,0:44.5
-8,9,0:17.0
-7,9,0:18
-5,9,0:2
-4,9,0:2
-3,9,0:98.0
-2,9,0:98.0
-1,9,0:98.0
0,9,0:98.0
1,9,0:98.0
2,9,0:98.0
3,9,0:98.0
4,9,0:98.0
5,9,0:44.5
6,9,0:18
10,9,0:44.5
11,9,0:98.0
12,9,0:44.5
-14,10,0:44.5
-8,10,0:18
-7,10,0:18
-5,10,0:2
-4,10,0:2
-3,10,0:98.0
-2,10,0:2
-1,10,0:109.3
0,10,0:109.3
1,10,0:44.5
2,10,0:109.3
3,10,0:109.3
4,10,0:98.1
5,10,0:17.1
6,10,0:18
11,10,0:18
12,10,0:17.1
13,10,0:18
-4,11,0:2
-3,11,0:3
-2,11,0:2
-1,11,0:2
4,11,0:18
5,11,0:18
6,11,0:18
11,11,0:18
12,11,0:18
13,11,0:18
-11,12,0:44.5
-7,12,0:44.5
-4,12,0:2
-3,12,0:2
-2,12,0:2
1,12,0:44.5
4,12,0:44.5
10,12,0:44.5
11,13,0:44.5
10,14,0:31.1
5,14,0:31.1
4,14,0:31.1
3,14,0:31.1
2,14,0:31.1
1,14,0:31.1
0,14,0:31.1
-1,14,0:31.1
-2,14,0:31.1
-3,14,0:31.1
-4,14,0:31.1
-5,14,0:31.1
-7,14,0:31.1
13,13,0:31.1
12,13,0:31.1
9,13,0:37
8,13,0:31.1
7,13,0:31.1
6,13,0:31.1
5,13,0:31.1
4,13,0:31.1
2,13,0:31.1
1,13,0:31.1
0,13,0:31.1
-1,13,0:37
-2,13,0:31.1
-3,13,0:31.1
-4,13,0:31.1
-7,13,0:31.1
-8,13,0:31.1
14,12,0:31.1
13,12,0:31.1
12,12,0:31.1
11,12,0:31.1
8,12,0:31.1
7,12,0:31.1
6,12,0:31.1
5,12,0:37
2,12,0:31.1
0,12,0:31.1
-1,12,0:31.1
-5,12,0:31.1
-9,12,0:31.1
-10,12,0:31.1
-12,12,0:37
15,11,0:31.1
14,11,0:31.1
10,11,0:31.1
9,11,0:31.1
7,11,0:37
2,11,0:31.1
-7,11,0:31.1
-8,11,0:106.4
-9,11,0:31.1
-10,11,0:31.1
-11,11,0:31.1
-12,11,0:31.1
16,10,0:31.1
15,10,0:31.1
14,10,0:31.1
10,10,0:31.1
9,10,0:31.1
8,10,0:31.1
-6,10,0:31.1
-9,10,0:31.1
-10,10,0:31.1
-11,10,0:31.1
-12,10,0:31.1
16,9,0:38
15,9,0:31.1
14,9,0:31.1
13,9,0:31.1
9,9,0:31.1
8,9,0:106.4
-6,9,0:106.4
-12,9,0:106.8
-13,9,0:31.1
-14,9,0:31.1
-15,9,0:31.1
15,8,0:31.1
13,8,0:31.1
-13,8,0:31.1
-14,8,0:31.1
-15,8,0:31.1
16,7,0:31.1
15,7,0:31.1
-14,7,0:31.1
-15,7,0:31.1
15,6,0:37
14,6,0:31.1
-14,6,0:31.1
-15,6,0:31.1
-12,5,0:31.1
-13,5,0:31.1
-14,5,0:31.1
-15,5,0:31.1
12,4,0:106.2
-13,4,0:37
-14,4,0:37
-15,4,0:31.1
-14,3,0:31.1
-15,3,0:31.1
-14,2,0:38
-15,2,0:31.1
-13,1,0:31.1
-14,1,0:31.1
-15,1,0:31.1
16,0,0:31.1
-13,0,0:31.1
-15,0,0:37
16,-1,0:31.1
15,-1,0:31.1
-2,-1,0:106.8
-15,-1,0:31.1
16,-2,0:37
15,-2,0:31.1
-2,-2,0:106.8
-15,-2,0:31.1
-13,-3,0:31.1
-14,-4,0:37
-15,-4,0:31.1
-14,-5,0:31.1
-15,-5,0:31.1
16,-6,0:31.1
-14,-6,0:31.1
-15,-6,0:31.1
-13,-7,0:31.1
-14,-7,0:31.1
-15,-7,0:31.1
16,-8,0:37
-13,-8,0:37
15,-9,0:38
-14,-9,0:31.1
15,-10,0:31.1
14,-10,0:31.1
-15,-10,0:31.1
16,-11,0:31.1
14,-11,0:31.1
13,-11,0:31.1
-14,-11,0:31.1
-15,-11,0:31.1
15,-12,0:31.1
13,-12,0:31.1
-5,-12,0:106.1
-6,-12,0:106.1
-7,-12,0:31.1
-8,-12,0:31.1
-13,-12,0:31.1
14,-13,0:31.1
13,-13,0:31.1
12,-13,0:31.1
11,-13,0:31.1
6,-13,0:31.1
-6,-13,0:31.1
-7,-13,0:31.1
-8,-13,0:31.1
-9,-13,0:37
-13,-13,0:31.1
13,-14,0:31.1
12,-14,0:31.1
11,-14,0:38
10,-14,0:31.1
9,-14,0:31.1
8,-14,0:31.1
7,-14,0:31.1
6,-14,0:31.1
5,-14,0:31.1
-1,-14,0:31.1
-2,-14,0:31.1
-6,-14,0:31.1
-7,-14,0:31.1
-9,-14,0:31.1
-10,-14,0:31.1
12,-15,0:31.1
10,-15,0:31.1
9,-15,0:31.1
8,-15,0:31.1
7,-15,0:31.1
6,-15,0:31.1
5,-15,0:31.1
4,-15,0:31.1
3,-15,0:31.1
0,-15,0:31.1
-1,-15,0:37
-3,-15,0:31.1
-8,-15,0:31.1
-9,-15,0:31.1
-10,-15,0:31.1
7,-16,0:31.1
6,-16,0:31.1
5,-16,0:31.1
4,-16,0:31.1
3,-16,0:31.1
2,-16,0:31.1
1,-16,0:31.1
0,-16,0:38
-1,-16,0:31.1
-2,-16,0:31.1
-3,-16,0:31.1
-4,-16,0:31.1
-6,-16,0:31.1
-7,-16,0:31.1
-8,-16,0:31.1
-3,-2,0:0
-4,-1,0:0
-4,-2,0:0
-3,-1,0:0
-5,-1,0:0
-5,-2,0:0
0,-2,-16:1
1,-2,-16:3
-1,-1,-16:3
0,-1,-16:1
1,-1,-16:3
-1,-3,-15:3
-1,-2,-15:3
0,-2,-15:3
1,-2,-15:3
2,-2,-15:1
-1,-1,-15:1
0,-1,-15:1
1,-1,-15:1
2,-1,-15:1
0,0,-15:1
1,0,-15:3
2,0,-15:1
-1,-4,-14:3
4,-4,-14:3
-2,-3,-14:3
-1,-3,-14:3
0,-3,-14:1
1,-3,-14:3
2,-3,-14:3
3,-3,-14:1
-2,-2,-14:3
-1,-2,-14:1
0,-2,-14:1
1,-2,-14:1
2,-2,-14:3
3,-2,-14:1
-2,-1,-14:3
-1,-1,-14:1
0,-1,-14:1
1,-1,-14:1
2,-1,-14:3
3,-1,-14:1
-3,0,-14:3
-2,0,-14:3
-1,0,-14:1
0,0,-14:1
1,0,-14:1
2,0,-14:3
3,0,-14:1
-3,1,-14:3
-2,1,-14:3
-1,1,-14:3
0,1,-14:1
1,1,-14:1
2,1,-14:3
3,1,-14:1
4,-5,-13:3
-2,-4,-13:1
-1,-4,-13:1
0,-4,-13:1
1,-4,-13:1
2,-4,-13:1
3,-4,-13:1
4,-4,-13:1
-3,-3,-13:3
-2,-3,-13:1
-1,-3,-13:1
0,-3,-13:1
1,-3,-13:1
2,-3,-13:1
3,-3,-13:1
4,-3,-13:1
-3,-2,-13:3
-2,-2,-13:1
-1,-2,-13:1
0,-2,-13:1
1,-2,-13:1
2,-2,-13:1
3,-2,-13:16
4,-2,-13:1
-3,-1,-13:3
-2,-1,-13:1
-1,-1,-13:1
0,-1,-13:1
1,-1,-13:1
2,-1,-13:1
3,-1,-13:16
4,-1,-13:1
-3,0,-13:3
-2,0,-13:1
-1,0,-13:1
0,0,-13:1
1,0,-13:1
2,0,-13:1
3,0,-13:1
4,0,-13:1
-3,1,-13:3
-2,1,-13:1
-1,1,-13:1
0,1,-13:1
1,1,-13:1
2,1,-13:1
3,1,-13:1
4,1,-13:1
-3,2,-13:3
-2,2,-13:1
-1,2,-13:1
0,2,-13:1
1,2,-13:1
2,2,-13:1
3,2,-13:1
4,2,-13:1
-3,-6,-12:1
-2,-6,-12:1
-4,-5,-12:1
-3,-5,-12:1
-2,-5,-12:1
-1,-5,-12:1
0,-5,-12:1
1,-5,-12:1
2,-5,-12:1
3,-5,-12:3
4,-5,-12:3
5,-5,-12:1
-4,-4,-12:1
-3,-4,-12:1
-2,-4,-12:1
-1,-4,-12:1
0,-4,-12:1
1,-4,-12:1
2,-4,-12:1
3,-4,-12:1
4,-4,-12:1
5,-4,-12:1
-4,-3,-12:1
-3,-3,-12:1
-2,-3,-12:1
-1,-3,-12:1
0,-3,-12:1
1,-3,-12:1
2,-3,-12:1
3,-3,-12:1
4,-3,-12:1
5,-3,-12:1
-4,-2,-12:1
-3,-2,-12:1
-2,-2,-12:1
-1,-2,-12:1
0,-2,-12:1
1,-2,-12:1
2,-2,-12:1
3,-2,-12:1
4,-2,-12:1
5,-2,-12:1
-4,-1,-12:1
-3,-1,-12:1
-2,-1,-12:1
-1,-1,-12:1
0,-1,-12:1
1,-1,-12:1
2,-1,-12:1
3,-1,-12:1
4,-1,-12:1
5,-1,-12:1
-4,0,-12:1
-3,0,-12:1
-2,0,-12:1
-1,0,-12:1
0,0,-12:1
1,0,-12:1
2,0,-12:1
3,0,-12:1
4,0,-12:1
5,0,-12:1
-4,1,-12:1
-3,1,-12:1
-2,1,-12:1
-1,1,-12:1
0,1,-12:1
1,1,-12:1
2,1,-12:1
3,1,-12:1
4,1,-12:1
5,1,-12:1
-4,2,-12:1
-3,2,-12:1
-2,2,-12:1
-1,2,-12:1
0,2,-12:1
1,2,-12:1
2,2,-12:1
3,2,-12:1
4,2,-12:1
5,2,-12:1
-4,3,-12:3
-3,3,-12:3
-2,3,-12:3
-1,3,-12:1
0,3,-12:1
1,3,-12:1
2,3,-12:3
3,3,-12:3
4,3,-12:3
5,3,-12:1
-2,4,-12:1
-5,-6,-11:3
-4,-6,-11:3
-3,-6,-11:3
-2,-6,-11:3
-1,-6,-11:1
0,-6,-11:1
1,-6,-11:1
2,-6,-11:3
3,-6,-11:1
4,-6,-11:3
5,-6,-11:3
6,-6,-11:1
-5,-5,-11:3
-4,-5,-11:1
-3,-5,-11:1
-2,-5,-11:1
-1,-5,-11:1
0,-5,-11:1
1,-5,-11:1
2,-5,-11:1
3,-5,-11:1
4,-5,-11:1
5,-5,-11:1
6,-5,-11:1
-5,-4,-11:3
-4,-4,-11:1
-3,-4,-11:1
-2,-4,-11:1
-1,-4,-11:1
0,-4,-11:1
1,-4,-11:1
2,-4,-11:1
3,-4,-11:1
4,-4,-11:1
5,-4,-11:1
6,-4,-11:1
-5,-3,-11:3
-4,-3,-11:1
-3,-3,-11:1
-2,-3,-11:1
-1,-3,-11:1
0,-3,-11:1
1,-3,-11:1
2,-3,-11:1
3,-3,-11:1
4,-3,-11:1
5,-3,-11:1
6,-3,-11:1
-5,-2,-11:1
-4,-2,-11:1
-3,-2,-11:1
-2,-2,-11:1
-1,-2,-11:1
0,-2,-11:1
1,-2,-11:1
2,-2,-11:1
3,-2,-11:1
4,-2,-11:1
5,-2,-11:1
6,-2,-11:1
-5,-1,-11:1
-4,-1,-11:1
-3,-1,-11:1
-2,-1,-11:1
-1,-1,-11:1
0,-1,-11:1
1,-1,-11:1
2,-1,-11:1
3,-1,-11:1
4,-1,-11:1
5,-1,-11:1
6,-1,-11:1
-5,0,-11:1
-4,0,-11:1
-3,0,-11:1
-2,0,-11:1
-1,0,-11:1
0,0,-11:1
1,0,-11:1
2,0,-11:1
3,0,-11:1
4,0,-11:1
5,0,-11:1
6,0,-11:1
-5,1,-11:3
-4,1,-11:1
-3,1,-11:1
-2,1,-11:1
-1,1,-11:1
0,1,-11:1
1,1,-11:1
2,1,-11:1
3,1,-11:1
4,1,-11:1
5,1,-11:1
6,1,-11:1
-5,2,-11:3
-4,2,-11:1
-3,2,-11:1
-2,2,-11:1
-1,2,-11:1
0,2,-11:1
1,2,-11:1
2,2,-11:16
3,2,-11:1
4,2,-11:1
5,2,-11:1
6,2,-11:1
-5,3,-11:3
-4,3,-11:1
-3,3,-11:1
-2,3,-11:1
-1,3,-11:1
0,3,-11:1
1,3,-11:1
2,3,-11:1
3,3,-11:1
4,3,-11:1
5,3,-11:1
6,3,-11:1
-5,4,-11:3
-4,4,-11:1
-3,4,-11:1
-2,4,-11:1
-1,4,-11:1
0,4,-11:1
1,4,-11:1
2,4,-11:1
3,4,-11:1
4,4,-11:1
5,4,-11:1
6,4,-11:1
-2,5,-11:3
4,5,-11:3
-6,-7,-10:3
-5,-7,-10:1
-4,-7,-10:1
-3,-7,-10:1
-2,-7,-10:1
-1,-7,-10:1
0,-7,-10:1
1,-7,-10:1
2,-7,-10:1
3,-7,-10:1
4,-7,-10:3
5,-7,-10:3
6,-7,-10:3
7,-7,-10:3
-6,-6,-10:3
-5,-6,-10:1
-4,-6,-10:1
-3,-6,-10:1
-2,-6,-10:1
-1,-6,-10:1
0,-6,-10:1
1,-6,-10:1
2,-6,-10:1
3,-6,-10:1
4,-6,-10:1
5,-6,-10:1
6,-6,-10:1
7,-6,-10:1
-6,-5,-10:3
-5,-5,-10:1
-4,-5,-10:1
-3,-5,-10:1
-2,-5,-10:1
-1,-5,-10:1
0,-5,-10:1
1,-5,-10:1
2,-5,-10:1
3,-5,-10:1
4,-5,-10:1
5,-5,-10:1
6,-5,-10:1
7,-5,-10:1
-6,-4,-10:1
-5,-4,-10:1
-4,-4,-10:1
-3,-4,-10:1
-2,-4,-10:1
-1,-4,-10:1
0,-4,-10:1
1,-4,-10:1
2,-4,-10:1
3,-4,-10:1
4,-4,-10:1
5,-4,-10:1
6,-4,-10:1
7,-4,-10:1
-6,-3,-10:1
-5,-3,-10:1
-4,-3,-10:1
-3,-3,-10:1
-2,-3,-10:1
-1,-3,-10:1
0,-3,-10:1
1,-3,-10:1
2,-3,-10:1
3,-3,-10:1
4,-3,-10:1
5,-3,-10:1
6,-3,-10:1
7,-3,-10:1
-6,-2,-10:1
-5,-2,-10:1
-4,-2,-10:1
-3,-2,-10:1
-2,-2,-10:1
-1,-2,-10:1
0,-2,-10:1
1,-2,-10:1
2,-2,-10:1
3,-2,-10:1
4,-2,-10:1
5,-2,-10:1
6,-2,-10:1
7,-2,-10:1
-6,-1,-10:3
-5,-1,-10:1
-4,-1,-10:1
-3,-1,-10:1
-2,-1,-10:1
-1,-1,-10:1
0,-1,-10:1
1,-1,-10:1
2,-1,-10:1
3,-1,-10:1
4,-1,-10:1
5,-1,-10:1
6,-1,-10:1
7,-1,-10:1
-6,0,-10:3
-5,0,-10:1
-4,0,-10:1
-3,0,-10:1
-2,0,-10:1
-1,0,-10:1
0,0,-10:1
1,0,-10:1
2,0,-10:1
3,0,-10:1
4,0,-10:1
5,0,-10:1
6,0,-10:1
7,0,-10:1
-6,1,-10:3
-5,1,-10:1
-4,1,-10:1
-3,1,-10:1
-2,1,-10:1
-1,1,-10:1
0,1,-10:1
1,1,-10:1
2,1,-10:16
3,1,-10:16
4,1,-10:1
5,1,-10:1
6,1,-10:1
7,1,-10:1
-6,2,-10:3
-5,2,-10:1
-4,2,-10:1
-3,2,-10:1
-2,2,-10:1
-1,2,-10:1
0,2,-10:1
1,2,-10:1
2,2,-10:16
3,2,-10:1
4,2,-10:1
5,2,-10:1
6,2,-10:1
7,2,-10:1
-6,3,-10:3
-5,3,-10:1
-4,3,-10:1
-3,3,-10:1
-2,3,-10:1
-1,3,-10:1
0,3,-10:1
1,3,-10:1
2,3,-10:1
3,3,-10:1
4,3,-10:1
5,3,-10:1
6,3,-10:1
7,3,-10:1
-6,4,-10:3
-5,4,-10:1
-4,4,-10:1
-3,4,-10:1
-2,4,-10:1
-1,4,-10:1
0,4,-10:1
1,4,-10:1
2,4,-10:1
3,4,-10:1
4,4,-10:1
5,4,-10:1
6,4,-10:1
7,4,-10:1
-6,5,-10:1
-5,5,-10:1
-4,5,-10:1
-3,5,-10:1
-2,5,-10:1
-1,5,-10:1
0,5,-10:1
1,5,-10:1
2,5,-10:1
3,5,-10:1
4,5,-10:1
5,5,-10:1
6,5,-10:1
7,5,-10:1
-7,-8,-9:1
-6,-8,-9:1
-5,-8,-9:1
-4,-8,-9:1
-3,-8,-9:1
-2,-8,-9:1
-1,-8,-9:1
0,-8,-9:1
1,-8,-9:1
2,-8,-9:1
3,-8,-9:1
4,-8,-9:1
5,-8,-9:1
6,-8,-9:1
7,-8,-9:1
8,-8,-9:1
-7,-7,-9:3
-6,-7,-9:1
-5,-7,-9:1
-4,-7,-9:1
-3,-7,-9:1
-2,-7,-9:1
-1,-7,-9:1
0,-7,-9:1
1,-7,-9:1
2,-7,-9:1
3,-7,-9:1
4,-7,-9:1
5,-7,-9:1
6,-7,-9:1
7,-7,-9:1
8,-7,-9:1
-7,-6,-9:3
-6,-6,-9:1
-5,-6,-9:1
-4,-6,-9:1
-3,-6,-9:1
-2,-6,-9:1
-1,-6,-9:1
0,-6,-9:1
1,-6,-9:1
2,-6,-9:1
3,-6,-9:1
4,-6,-9:1
5,-6,-9:1
6,-6,-9:1
7,-6,-9:1
8,-6,-9:1
-7,-5,-9:1
-6,-5,-9:1
-5,-5,-9:1
-4,-5,-9:1
-3,-5,-9:1
-2,-5,-9:1
-1,-5,-9:1
0,-5,-9:1
1,-5,-9:1
2,-5,-9:1
3,-5,-9:1
4,-5,-9:1
5,-5,-9:1
6,-5,-9:1
7,-5,-9:1
8,-5,-9:1
-7,-4,-9:1
-6,-4,-9:1
-5,-4,-9:1
-4,-4,-9:1
-3,-4,-9:1
-2,-4,-9:1
-1,-4,-9:1
0,-4,-9:1
1,-4,-9:1
2,-4,-9:1
3,-4,-9:1
4,-4,-9:1
5,-4,-9:1
6,-4,-9:1
7,-4,-9:1
8,-4,-9:1
-7,-3,-9:1
-6,-3,-9:1
-5,-3,-9:1
-4,-3,-9:1
-3,-3,-9:1
-2,-3,-9:1
-1,-3,-9:1
0,-3,-9:1
1,-3,-9:1
2,-3,-9:1
3,-3,-9:1
4,-3,-9:1
5,-3,-9:1
6,-3,-9:1
7,-3,-9:1
8,-3,-9:1
-7,-2,-9:3
-6,-2,-9:1
-5,-2,-9:1
-4,-2,-9:1
-3,-2,-9:1
-2,-2,-9:1
-1,-2,-9:1
0,-2,-9:1
1,-2,-9:1
2,-2,-9:1
3,-2,-9:1
4,-2,-9:1
5,-2,-9:1
6,-2,-9:1
7,-2,-9:1
8,-2,-9:16
-7,-1,-9:3
-6,-1,-9:1
-5,-1,-9:1
-4,-1,-9:1
-3,-1,-9:1
-2,-1,-9:1
-1,-1,-9:1
0,-1,-9:1
1,-1,-9:1
2,-1,-9:1
3,-1,-9:1
4,-1,-9:1
5,-1,-9:1
6,-1,-9:1
7,-1,-9:1
8,-1,-9:1
-7,0,-9:3
-6,0,-9:1
-5,0,-9:1
-4,0,-9:1
-3,0,-9:1
-2,0,-9:1
-1,0,-9:1
0,0,-9:1
1,0,-9:1
2,0,-9:1
3,0,-9:1
4,0,-9:1
5,0,-9:1
6,0,-9:1
7,0,-9:1
8,0,-9:16
-7,1,-9:3
-6,1,-9:1
-5,1,-9:1
-4,1,-9:1
-3,1,-9:1
-2,1,-9:1
-1,1,-9:1
0,1,-9:1
1,1,-9:1
2,1,-9:1
3,1,-9:1
4,1,-9:1
5,1,-9:1
6,1,-9:1
7,1,-9:1
8,1,-9:1
-7,2,-9:3
-6,2,-9:1
-5,2,-9:1
-4,2,-9:1
-3,2,-9:1
-2,2,-9:1
-1,2,-9:1
0,2,-9:1
1,2,-9:1
2,2,-9:1
3,2,-9:1
4,2,-9:1
5,2,-9:1
6,2,-9:1
7,2,-9:1
8,2,-9:1
-7,3,-9:3
-6,3,-9:1
-5,3,-9:1
-4,3,-9:1
-3,3,-9:1
-2,3,-9:1
-1,3,-9:1
0,3,-9:1
1,3,-9:1
2,3,-9:1
3,3,-9:1
4,3,-9:1
5,3,-9:1
6,3,-9:1
7,3,-9:1
8,3,-9:1
-7,4,-9:3
-6,4,-9:1
-5,4,-9:1
-4,4,-9:1
-3,4,-9:1
-2,4,-9:1
-1,4,-9:1
0,4,-9:1
1,4,-9:1
2,4,-9:1
3,4,-9:1
4,4,-9:1
5,4,-9:1
6,4,-9:1
7,4,-9:1
8,4,-9:1
-7,5,-9:3
-6,5,-9:1
-5,5,-9:1
-4,5,-9:1
-3,5,-9:1
-2,5,-9:1
-1,5,-9:1
0,5,-9:1
1,5,-9:1
2,5,-9:1
3,5,-9:1
4,5,-9:1
5,5,-9:1
6,5,-9:1
7,5,-9:1
8,5,-9:1
-7,6,-9:1
-6,6,-9:3
-5,6,-9:3
-4,6,-9:3
-3,6,-9:3
-2,6,-9:3
-1,6,-9:1
0,6,-9:3
1,6,-9:3
2,6,-9:1
3,6,-9:1
4,6,-9:1
5,6,-9:1
6,6,-9:16
7,6,-9:1
8,6,-9:1
-8,-9,-8:3
-7,-9,-8:3
-6,-9,-8:1
-5,-9,-8:3
-4,-9,-8:3
-3,-9,-8:3
-2,-9,-8:1
-1,-9,-8:1
0,-9,-8:1
1,-9,-8:1
2,-9,-8:1
3,-9,-8:1
4,-9,-8:1
5,-9,-8:1
6,-9,-8:1
7,-9,-8:3
8,-9,-8:3
9,-9,-8:3
-8,-8,-8:1
-7,-8,-8:1
-6,-8,-8:1
-5,-8,-8:1
-4,-8,-8:1
-3,-8,-8:1
-2,-8,-8:1
-1,-8,-8:1
0,-8,-8:1
1,-8,-8:1
2,-8,-8:1
3,-8,-8:1
4,-8,-8:1
5,-8,-8:1
6,-8,-8:1
7,-8,-8:1
8,-8,-8:1
9,-8,-8:3
-8,-7,-8:1
-7,-7,-8:1
-6,-7,-8:1
-5,-7,-8:1
-4,-7,-8:1
-3,-7,-8:1
-2,-7,-8:1
-1,-7,-8:1
0,-7,-8:1
1,-7,-8:1
2,-7,-8:1
3,-7,-8:1
4,-7,-8:1
5,-7,-8:1
6,-7,-8:1
7,-7,-8:1
8,-7,-8:1
9,-7,-8:3
-8,-6,-8:1
-7,-6,-8:1
-6,-6,-8:1
-5,-6,-8:1
-4,-6,-8:1
-3,-6,-8:1
-2,-6,-8:1
-1,-6,-8:1
0,-6,-8:1
1,-6,-8:1
2,-6,-8:1
3,-6,-8:1
4,-6,-8:1
5,-6,-8:1
6,-6,-8:1
7,-6,-8:1
8,-6,-8:1
9,-6,-8:1
-8,-5,-8:1
-7,-5,-8:1
-6,-5,-8:1
-5,-5,-8:1
-4,-5,-8:1
-3,-5,-8:1
-2,-5,-8:1
-1,-5,-8:1
0,-5,-8:1
1,-5,-8:1
2,-5,-8:1
3,-5,-8:1
4,-5,-8:1
5,-5,-8:1
6,-5,-8:1
7,-5,-8:1
8,-5,-8:1
9,-5,-8:1
-8,-4,-8:1
-7,-4,-8:1
-6,-4,-8:1
-5,-4,-8:1
-4,-4,-8:1
-3,-4,-8:1
-2,-4,-8:1
-1,-4,-8:1
0,-4,-8:1
1,-4,-8:1
2,-4,-8:1
3,-4,-8:1
4,-4,-8:1
5,-4,-8:1
6,-4,-8:1
7,-4,-8:1
8,-4,-8:1
9,-4,-8:1
-8,-3,-8:1
-7,-3,-8:1
-6,-3,-8:1
-5,-3,-8:1
-4,-3,-8:1
-3,-3,-8:1
-2,-3,-8:1
-1,-3,-8:1
0,-3,-8:1
1,-3,-8:1
2,-3,-8:1
3,-3,-8:1
4,-3,-8:1
5,-3,-8:1
6,-3,-8:1
7,-3,-8:1
8,-3,-8:1
9,-3,-8:1
-8,-2,-8:1
-7,-2,-8:1
-6,-2,-8:1
-5,-2,-8:1
-4,-2,-8:1
-3,-2,-8:1
-2,-2,-8:1
-1,-2,-8:1
0,-2,-8:1
1,-2,-8:1
2,-2,-8:1
3,-2,-8:1
4,-2,-8:1
5,-2,-8:1
6,-2,-8:1
7,-2,-8:1
8,-2,-8:1
9,-2,-8:1
-8,-1,-8:1
-7,-1,-8:1
-6,-1,-8:1
-5,-1,-8:1
-4,-1,-8:1
-3,-1,-8:1
-2,-1,-8:1
-1,-1,-8:1
0,-1,-8:1
1,-1,-8:1
2,-1,-8:1
3,-1,-8:1
4,-1,-8:1
5,-1,-8:1
6,-1,-8:1
7,-1,-8:1
8,-1,-8:1
9,-1,-8:1
-8,0,-8:1
-7,0,-8:1
-6,0,-8:1
-5,0,-8:1
-4,0,-8:1
-3,0,-8:1
-2,0,-8:1
-1,0,-8:1
0,0,-8:1
1,0,-8:1
2,0,-8:1
3,0,-8:1
4,0,-8:1
5,0,-8:1
6,0,-8:1
7,0,-8:1
8,0,-8:1
9,0,-8:1
-9,1,-8:16
-8,1,-8:1
-7,1,-8:1
-6,1,-8:1
-5,1,-8:1
-4,1,-8:1
-3,1,-8:1
-2,1,-8:1
-1,1,-8:1
0,1,-8:1
1,1,-8:1
2,1,-8:1
3,1,-8:1
4,1,-8:1
5,1,-8:1
6,1,-8:1
7,1,-8:1
8,1,-8:1
9,1,-8:1
-9,2,-8:16
-8,2,-8:1
-7,2,-8:1
-6,2,-8:1
-5,2,-8:1
-4,2,-8:1
-3,2,-8:1
-2,2,-8:1
-1,2,-8:1
0,2,-8:1
1,2,-8:1
2,2,-8:1
3,2,-8:1
4,2,-8:1
5,2,-8:1
6,2,-8:1
7,2,-8:1
8,2,-8:1
9,2,-8:1
-8,3,-8:1
-7,3,-8:1
-6,3,-8:1
-5,3,-8:1
-4,3,-8:1
-3,3,-8:1
-2,3,-8:1
-1,3,-8:1
0,3,-8:1
1,3,-8:1
2,3,-8:1
3,3,-8:1
4,3,-8:1
5,3,-8:1
6,3,-8:1
7,3,-8:1
8,3,-8:1
9,3,-8:1
-8,4,-8:1
-7,4,-8:1
-6,4,-8:1
-5,4,-8:1
-4,4,-8:1
-3,4,-8:1
-2,4,-8:1
-1,4,-8:1
0,4,-8:1
1,4,-8:1
2,4,-8:1
3,4,-8:1
4,4,-8:1
5,4,-8:1
6,4,-8:1
7,4,-8:1
8,4,-8:1
9,4,-8:1
-8,5,-8:1
-7,5,-8:1
-6,5,-8:1
-5,5,-8:1
-4,5,-8:1
-3,5,-8:1
-2,5,-8:1
-1,5,-8:1
0,5,-8:1
1,5,-8:1
2,5,-8:1
3,5,-8:1
4,5,-8:1
5,5,-8:1
6,5,-8:1
7,5,-8:1
8,5,-8:1
9,5,-8:1
-8,6,-8:1
-7,6,-8:1
-6,6,-8:1
-5,6,-8:1
-4,6,-8:1
-3,6,-8:1
-2,6,-8:1
-1,6,-8:1
0,6,-8:1
1,6,-8:1
2,6,-8:1
3,6,-8:1
4,6,-8:1
5,6,-8:1
6,6,-8:1
7,6,-8:1
8,6,-8:1
9,6,-8:1
-8,7,-8:1
-7,7,-8:1
-6,7,-8:3
-5,7,-8:3
-4,7,-8:3
-3,7,-8:3
-2,7,-8:3
-1,7,-8:3
0,7,-8:1
1,7,-8:1
2,7,-8:1
3,7,-8:1
4,7,-8:1
5,7,-8:1
6,7,-8:16
7,7,-8:16
8,7,-8:1
9,7,-8:1
3,-11,-7:16
-9,-10,-7:3
-8,-10,-7:3
-7,-10,-7:1
-6,-10,-7:1
-5,-10,-7:3
-4,-10,-7:3
-3,-10,-7:1
-2,-10,-7:1
-1,-10,-7:3
0,-10,-7:1
1,-10,-7:1
2,-10,-7:16
3,-10,-7:1
4,-10,-7:1
5,-10,-7:1
6,-10,-7:1
7,-10,-7:1
8,-10,-7:1
9,-10,-7:3
10,-10,-7:1
-9,-9,-7:1
-8,-9,-7:1
-7,-9,-7:1
-6,-9,-7:1
-5,-9,-7:1
-4,-9,-7:1
-3,-9,-7:98.0
-2,-9,-7:98.1
-1,-9,-7:98.1
0,-9,-7:98.0
1,-9,-7:98.0
2,-9,-7:98.0
3,-9,-7:98.0
4,-9,-7:98.0
5,-9,-7:98.0
6,-9,-7:98.0
7,-9,-7:98.0
8,-9,-7:98.0
9,-9,-7:98.0
10,-9,-7:1
-9,-8,-7:1
-8,-8,-7:1
-7,-8,-7:1
-6,-8,-7:1
-5,-8,-7:1
-4,-8,-7:1
-3,-8,-7:98.0
-2,-8,-7:98.1
-1,-8,-7:98.0
0,-8,-7:98.0
1,-8,-7:98.0
2,-8,-7:98.1
3,-8,-7:98.1
4,-8,-7:98.1
5,-8,-7:98.0
6,-8,-7:98.1
7,-8,-7:98.1
8,-8,-7:98.1
9,-8,-7:98.0
10,-8,-7:1
-9,-7,-7:3
-8,-7,-7:1
-7,-7,-7:1
-6,-7,-7:1
-5,-7,-7:1
-4,-7,-7:1
-3,-7,-7:98.0
-2,-7,-7:98.1
-1,-7,-7:98.1
0,-7,-7:98.1
1,-7,-7:98.1
2,-7,-7:98.1
3,-7,-7:98.0
4,-7,-7:98.0
5,-7,-7:98.0
6,-7,-7:98.0
7,-7,-7:98.0
8,-7,-7:98.0
9,-7,-7:98.0
10,-7,-7:1
-9,-6,-7:3
-8,-6,-7:1
-7,-6,-7:98.1
-6,-6,-7:98.0
-5,-6,-7:98.0
-4,-6,-7:98.0
-3,-6,-7:98.0
-2,-6,-7:98.1
-1,-6,-7:98.0
0,-6,-7:98.1
1,-6,-7:98.0
2,-6,-7:98.0
3,-6,-7:98.1
4,-6,-7:98.1
5,-6,-7:98.0
6,-6,-7:98.0
7,-6,-7:98.0
8,-6,-7:98.0
9,-6,-7:98.1
10,-6,-7:1
-9,-5,-7:3
-8,-5,-7:1
-7,-5,-7:98.0
-6,-5,-7:17.0
-5,-5,-7:98.0
-4,-5,-7:98.0
-3,-5,-7:98.1
-2,-5,-7:98.0
-1,-5,-7:98.0
0,-5,-7:98.1
1,-5,-7:98.0
2,-5,-7:98.0
3,-5,-7:98.1
4,-5,-7:98.0
5,-5,-7:98.0
6,-5,-7:98.0
7,-5,-7:98.0
8,-5,-7:98.0
9,-5,-7:98.0
10,-5,-7:1
-9,-4,-7:1
-8,-4,-7:1
-7,-4,-7:98.0
-6,-4,-7:98.0
-5,-4,-7:98.0
-4,-4,-7:98.0
-3,-4,-7:98.1
-2,-4,-7:98.1
-1,-4,-7:98.1
0,-4,-7:98.0
1,-4,-7:98.1
2,-4,-7:98.1
3,-4,-7:98.1
4,-4,-7:98.0
5,-4,-7:98.1
6,-4,-7:98.0
7,-4,-7:98.1
8,-4,-7:98.0
9,-4,-7:98.0
10,-4,-7:1
-9,-3,-7:1
-8,-3,-7:98.0
-7,-3,-7:98.0
-6,-3,-7:98.0
-5,-3,-7:98.0
-4,-3,-7:98.0
-3,-3,-7:98.1
-2,-3,-7:98.0
-1,-3,-7:98.0
0,-3,-7:98.0
1,-3,-7:98.1
2,-3,-7:98.1
3,-3,-7:98.0
4,-3,-7:98.1
5,-3,-7:98.0
6,-3,-7:98.1
7,-3,-7:98.1
8,-3,-7:98.0
9,-3,-7:98.0
10,-3,-7:1
-10,-2,-7:1
-9,-2,-7:98.0
-8,-2,-7:98.0
-7,-2,-7:98.1
-6,-2,-7:98.0
-5,-2,-7:98.0
-4,-2,-7:98.0
-3,-2,-7:98.1
-2,-2,-7:98.0
-1,-2,-7:98.0
0,-2,-7:98.1
1,-2,-7:98.0
2,-2,-7:98.0
3,-2,-7:98.0
4,-2,-7:98.1
5,-2,-7:98.0
6,-2,-7:98.0
7,-2,-7:98.0
8,-2,-7:98.0
9,-2,-7:98.0
10,-2,-7:1
-10,-1,-7:1
-9,-1,-7:98.0
-8,-1,-7:98.0
-7,-1,-7:98.1
-6,-1,-7:98.1
-5,-1,-7:98.0
-4,-1,-7:98.0
-3,-1,-7:98.1
-2,-1,-7:98.0
-1,-1,-7:98.1
0,-1,-7:98.0
1,-1,-7:98.1
2,-1,-7:98.1
3,-1,-7:98.0
4,-1,-7:98.1
5,-1,-7:98.0
6,-1,-7:98.1
7,-1,-7:98.1
8,-1,-7:98.0
9,-1,-7:98.0
10,-1,-7:1
-10,0,-7:1
-9,0,-7:98.0
-8,0,-7:98.0
-7,0,-7:98.0
-6,0,-7:98.1
-5,0,-7:98.0
-4,0,-7:98.0
-3,0,-7:98.1
-2,0,-7:98.0
-1,0,-7:98.0
0,0,-7:98.0
1,0,-7:98.1
2,0,-7:98.0
3,0,-7:98.0
4,0,-7:98.0
5,0,-7:98.0
6,0,-7:98.1
7,0,-7:98.1
8,0,-7:98.0
9,0,-7:98.0
10,0,-7:1
-10,1,-7:1
-9,1,-7:3
-8,1,-7:3
-7,1,-7:98.0
-6,1,-7:98.0
-5,1,-7:98.0
-4,1,-7:98.0
-3,1,-7:98.1
-2,1,-7:98.0
-1,1,-7:98.0
0,1,-7:98.1
1,1,-7:98.1
2,1,-7:98.0
3,1,-7:98.0
4,1,-7:98.1
5,1,-7:98.0
6,1,-7:98.0
7,1,-7:98.1
8,1,-7:98.0
9,1,-7:98.1
10,1,-7:1
-10,2,-7:1
-9,2,-7:3
-8,2,-7:3
-7,2,-7:98.1
-6,2,-7:98.0
-5,2,-7:98.0
-4,2,-7:98.0
-3,2,-7:98.0
-2,2,-7:98.0
-1,2,-7:98.1
0,2,-7:98.0
1,2,-7:98.0
2,2,-7:98.0
3,2,-7:98.0
4,2,-7:98.0
5,2,-7:98.0
6,2,-7:98.0
7,2,-7:98.0
8,2,-7:98.0
9,2,-7:98.0
10,2,-7:1
-9,3,-7:3
-8,3,-7:3
-7,3,-7:98.1
-6,3,-7:17.0
-5,3,-7:98.0
-4,3,-7:98.0
-3,3,-7:98.1
-2,3,-7:98.0
-1,3,-7:98.0
0,3,-7:98.0
1,3,-7:98.0
2,3,-7:98.0
3,3,-7:98.0
4,3,-7:98.0
5,3,-7:98.0
6,3,-7:98.0
7,3,-7:98.0
8,3,-7:98.0
9,3,-7:98.1
10,3,-7:1
-9,4,-7:3
-8,4,-7:3
-7,4,-7:98.1
-6,4,-7:98.0
-5,4,-7:98.0
-4,4,-7:98.0
-3,4,-7:98.1
-2,4,-7:98.0
-1,4,-7:98.0
0,4,-7:98.0
1,4,-7:98.0
2,4,-7:98.1
3,4,-7:98.0
4,4,-7:98.0
5,4,-7:98.1
6,4,-7:98.1
7,4,-7:98.0
8,4,-7:98.0
9,4,-7:1
10,4,-7:1
-9,5,-7:1
-8,5,-7:3
-7,5,-7:98.1
-6,5,-7:98.1
-5,5,-7:98.1
-4,5,-7:98.1
-3,5,-7:98.0
-2,5,-7:98.0
-1,5,-7:98.0
0,5,-7:98.1
1,5,-7:98.1
2,5,-7:98.0
3,5,-7:98.0
4,5,-7:98.0
5,5,-7:98.0
6,5,-7:98.0
7,5,-7:98.1
8,5,-7:98.1
9,5,-7:98.0
10,5,-7:1
-9,6,-7:1
-8,6,-7:3
-7,6,-7:98.1
-6,6,-7:98.0
-5,6,-7:98.0
-4,6,-7:98.0
-3,6,-7:98.0
-2,6,-7:98.1
-1,6,-7:98.1
0,6,-7:98.0
1,6,-7:98.0
2,6,-7:98.0
3,6,-7:98.0
4,6,-7:98.0
5,6,-7:98.0
6,6,-7:98.0
7,6,-7:98.0
8,6,-7:98.0
9,6,-7:98.0
10,6,-7:1
-9,7,-7:1
-8,7,-7:3
-7,7,-7:98.0
-6,7,-7:98.0
-5,7,-7:98.0
-4,7,-7:98.0
-3,7,-7:98.0
-2,7,-7:98.0
-1,7,-7:98.0
0,7,-7:98.0
1,7,-7:98.0
2,7,-7:98.0
3,7,-7:98.0
4,7,-7:98.0
5,7,-7:98.0
6,7,-7:98.0
7,7,-7:98.0
8,7,-7:98.0
9,7,-7:98.0
10,7,-7:1
-9,8,-7:1
-8,8,-7:1
-7,8,-7:1
-6,8,-7:1
-5,8,-7:3
-4,8,-7:3
-3,8,-7:3
-2,8,-7:1
-1,8,-7:1
0,8,-7:1
1,8,-7:1
2,8,-7:1
3,8,-7:1
4,8,-7:1
5,8,-7:1
6,8,-7:1
7,8,-7:1
8,8,-7:16
9,8,-7:1
10,8,-7:1
-3,9,-7:3
-10,-11,-6:3
-9,-11,-6:3
-8,-11,-6:3
-7,-11,-6:3
-6,-11,-6:3
-5,-11,-6:3
-4,-11,-6:3
-3,-11,-6:3
-2,-11,-6:3
-1,-11,-6:1
0,-11,-6:1
1,-11,-6:1
2,-11,-6:1
3,-11,-6:16
4,-11,-6:16
5,-11,-6:1
6,-11,-6:1
7,-11,-6:1
8,-11,-6:1
9,-11,-6:1
10,-11,-6:1
11,-11,-6:3
-10,-10,-6:1
-9,-10,-6:3
-8,-10,-6:1
-7,-10,-6:1
-6,-10,-6:3
-5,-10,-6:3
-4,-10,-6:3
-3,-10,-6:3
-2,-10,-6:1
-1,-10,-6:3
0,-10,-6:3
1,-10,-6:3
2,-10,-6:1
3,-10,-6:1
4,-10,-6:1
5,-10,-6:1
6,-10,-6:1
7,-10,-6:3
8,-10,-6:1
9,-10,-6:1
10,-10,-6:3
11,-10,-6:1
-10,-9,-6:1
-9,-9,-6:3
-8,-9,-6:1
-7,-9,-6:3
-6,-9,-6:3
-5,-9,-6:3
-4,-9,-6:3
-3,-9,-6:98.0
-2,-9,-6:98.0
-1,-9,-6:98.0
0,-9,-6:98.1
1,-9,-6:98.0
2,-9,-6:98.1
3,-9,-6:98.0
4,-9,-6:98.0
5,-9,-6:98.1
6,-9,-6:98.1
7,-9,-6:98.0
8,-9,-6:98.1
9,-9,-6:98.1
10,-9,-6:1
11,-9,-6:1
-10,-8,-6:1
-9,-8,-6:3
-8,-8,-6:3
-7,-8,-6:3
-6,-8,-6:3
-5,-8,-6:1
-4,-8,-6:1
-3,-8,-6:98.0
-2,-8,-6:44.5
8,-8,-6:109.0
9,-8,-6:98.1
10,-8,-6:1
11,-8,-6:1
-10,-7,-6:3
-9,-7,-6:3
-8,-7,-6:3
-7,-7,-6:1
-6,-7,-6:1
-5,-7,-6:1
-4,-7,-6:1
-3,-7,-6:98.0
4,-7,-6:98.0
9,-7,-6:98.0
10,-7,-6:1
11,-7,-6:1
-10,-6,-6:3
-9,-6,-6:3
-8,-6,-6:1
-7,-6,-6:98.0
-6,-6,-6:98.0
-5,-6,-6:98.0
-4,-6,-6:98.0
-3,-6,-6:98.0
-2,-6,-6:98.2
0,-6,-6:98.2
1,-6,-6:98.0
2,-6,-6:98.1
3,-6,-6:98.0
4,-6,-6:98.0
5,-6,-6:98.0
7,-6,-6:98.2
8,-6,-6:98.1
9,-6,-6:98.0
10,-6,-6:1
11,-6,-6:1
-10,-5,-6:1
-9,-5,-6:3
-8,-5,-6:1
-7,-5,-6:98.0
-6,-5,-6:17.0
-5,-5,-6:18
7,-5,-6:17
8,-5,-6:98.0
9,-5,-6:98.1
10,-5,-6:1
11,-5,-6:1
-10,-4,-6:1
-9,-4,-6:3
-8,-4,-6:1
-7,-4,-6:98.0
-6,-4,-6:18
8,-4,-6:44.5
9,-4,-6:98.0
10,-4,-6:3
11,-4,-6:1
-10,-3,-6:1
-9,-3,-6:98.0
-8,-3,-6:98.0
-7,-3,-6:98.2
-4,-3,-6:98.1
-3,-3,-6:98.0
-2,-3,-6:98.0
-1,-3,-6:98.0
0,-3,-6:98.0
1,-3,-6:98.0
2,-3,-6:98.1
9,-3,-6:98.0
10,-3,-6:3
11,-3,-6:1
-10,-2,-6:1
-9,-2,-6:3
-8,-2,-6:3
-4,-2,-6:44.5
-3,-2,-6:98.0
-1,-2,-6:98.0
0,-2,-6:109.1
9,-2,-6:98.0
10,-2,-6:3
11,-2,-6:1
-10,-1,-6:3
-9,-1,-6:3
-8,-1,-6:3
-4,-1,-6:44.5
-3,-1,-6:98.0
-2,-1,-6:98.0
-1,-1,-6:98.0
0,-1,-6:109.1
9,-1,-6:98.0
10,-1,-6:3
11,-1,-6:1
-10,0,-6:3
-9,0,-6:3
-8,0,-6:98.0
-7,0,-6:98.2
-4,0,-6:98.0
-3,0,-6:98.0
-2,0,-6:98.0
-1,0,-6:98.0
0,0,-6:98.0
1,0,-6:98.0
2,0,-6:98.1
9,0,-6:98.0
10,0,-6:1
11,0,-6:1
-10,1,-6:3
-9,1,-6:3
-8,1,-6:3
-7,1,-6:98.0
9,1,-6:98.1
10,1,-6:1
11,1,-6:1
-10,2,-6:3
-9,2,-6:3
-8,2,-6:3
-7,2,-6:98.1
-6,2,-6:18
-5,2,-6:18
8,2,-6:109.0
9,2,-6:98.0
10,2,-6:1
11,2,-6:1
-10,3,-6:3
-9,3,-6:3
-8,3,-6:3
-7,3,-6:98.1
-6,3,-6:17
-5,3,-6:98.0
-4,3,-6:98.1
-3,3,-6:98.0
-2,3,-6:98.2
0,3,-6:98.2
1,3,-6:98.0
2,3,-6:109.2
3,3,-6:98.0
4,3,-6:98.1
5,3,-6:98.2
7,3,-6:98.2
8,3,-6:98.0
9,3,-6:98.1
10,3,-6:3
11,3,-6:1
-10,4,-6:3
-9,4,-6:3
-8,4,-6:3
-7,4,-6:98.0
-6,4,-6:18
-3,4,-6:109.3
2,4,-6:98.0
3,4,-6:98.0
9,4,-6:98.0
10,4,-6:1
11,4,-6:1
-10,5,-6:3
-9,5,-6:3
-8,5,-6:3
-7,5,-6:98.0
2,5,-6:109.0
3,5,-6:98.0
9,5,-6:98.0
10,5,-6:1
11,5,-6:1
-10,6,-6:3
-9,6,-6:3
-8,6,-6:3
-7,6,-6:98.1
-6,6,-6:98.0
1,6,-6:44.5
2,6,-6:98.0
3,6,-6:98.0
5,6,-6:98.1
9,6,-6:98.0
10,6,-6:1
11,6,-6:1
-10,7,-6:3
-9,7,-6:3
-8,7,-6:3
-7,7,-6:98.0
-6,7,-6:98.0
-5,7,-6:98.1
-4,7,-6:98.1
-3,7,-6:98.0
-2,7,-6:98.0
-1,7,-6:98.0
0,7,-6:98.0
1,7,-6:98.1
2,7,-6:98.0
3,7,-6:98.0
4,7,-6:98.0
5,7,-6:98.0
6,7,-6:98.0
7,7,-6:98.0
8,7,-6:98.0
9,7,-6:98.0
10,7,-6:3
11,7,-6:1
-10,8,-6:3
-9,8,-6:3
-8,8,-6:3
-7,8,-6:3
-6,8,-6:3
-5,8,-6:3
-4,8,-6:3
-3,8,-6:3
-2,8,-6:3
-1,8,-6:3
0,8,-6:3
1,8,-6:3
2,8,-6:3
3,8,-6:3
4,8,-6:3
5,8,-6:3
6,8,-6:3
7,8,-6:3
8,8,-6:3
9,8,-6:3
10,8,-6:3
11,8,-6:1
-10,9,-6:3
-9,9,-6:1
-8,9,-6:1
-7,9,-6:1
-6,9,-6:1
-5,9,-6:1
-4,9,-6:1
-3,9,-6:1
-2,9,-6:1
-1,9,-6:16
0,9,-6:1
1,9,-6:1
2,9,-6:1
3,9,-6:1
4,9,-6:1
5,9,-6:1
6,9,-6:1
7,9,-6:1
8,9,-6:1
9,9,-6:1
10,9,-6:1
11,9,-6:1
4,6,-6:106.2
4,5,-6:106.2
6,2,-6:106.1
4,2,-6:106.1
3,0,-6:106.2
8,-1,-6:106.8
3,-1,-6:106.2
2,-1,-6:106.1
8,-2,-6:106.8
3,-2,-6:106.2
1,-2,-6:106.8
3,-3,-6:106.2
-2,-7,-6:0
-1,-7,-6:0
0,-7,-6:0
0,-8,-6:0
-1,-8,-6:0
-1,-6,-6:0
1,-7,-6:0
2,-7,-6:0
3,-7,-6:0
2,-8,-6:0
1,-8,-6:0
3,-8,-6:0
4,-8,-6:0
5,-8,-6:0
6,-8,-6:0
6,-7,-6:0
5,-7,-6:0
7,-7,-6:0
7,-8,-6:0
8,-7,-6:0
6,-6,-6:0
6,-5,-6:0
5,-5,-6:0
7,-4,-6:0
7,-3,-6:0
8,-3,-6:0
6,-3,-6:0
6,-4,-6:0
5,-4,-6:0
5,-3,-6:0
5,-2,-6:0
6,-2,-6:0
7,-2,-6:0
6,-1,-6:0
6,0,-6:0
7,0,-6:0
7,-1,-6:0
8,0,-6:0
8,1,-6:0
7,1,-6:0
7,2,-6:0
6,1,-6:0
5,1,-6:0
5,2,-6:0
5,0,-6:0
5,-1,-6:0
4,0,-6:0
4,1,-6:0
4,-1,-6:0
4,-2,-6:0
4,-3,-6:0
4,-4,-6:0
4,-5,-6:0
3,-5,-6:0
2,-5,-6:0
1,-5,-6:0
0,-5,-6:0
-1,-5,-6:0
-2,-5,-6:0
-3,-5,-6:0
-3,-4,-6:0
-4,-4,-6:0
-4,-5,-6:0
-5,-4,-6:0
-2,-4,-6:0
-1,-4,-6:0
0,-4,-6:0
1,-4,-6:0
2,-4,-6:0
3,-4,-6:0
2,-2,-6:0
1,-1,-6:0
3,1,-6:0
2,1,-6:0
1,1,-6:0
0,1,-6:0
-1,1,-6:0
-2,1,-6:0
-3,1,-6:0
3,2,-6:0
2,2,-6:0
1,2,-6:0
0,2,-6:0
-4,1,-6:0
-4,2,-6:0
-3,2,-6:0
-2,2,-6:0
-1,2,-6:0
-1,3,-6:0
-1,4,-6:0
1,4,-6:0
1,5,-6:0
0,5,-6:0
0,4,-6:0
0,6,-6:0
-1,6,-6:0
-1,5,-6:0
-2,5,-6:0
-2,6,-6:0
-2,4,-6:0
-3,5,-6:0
-3,6,-6:0
-4,6,-6:0
-4,5,-6:0
-5,5,-6:0
-4,4,-6:0
-5,4,-6:0
-5,6,-6:0
-6,5,-6:0
-5,1,-6:0
-6,1,-6:0
-5,0,-6:0
-5,-1,-6:0
-5,-2,-6:0
-5,-3,-6:0
-6,-2,-6:0
-6,-1,-6:0
-6,0,-6:0
-6,-3,-6:0
-7,-2,-6:0
-7,-1,-6:0
6,4,-6:0
5,4,-6:0
4,4,-6:0
6,3,-6:0
5,5,-6:0
6,5,-6:0
7,5,-6:0
7,4,-6:0
8,4,-6:0
8,5,-6:0
7,6,-6:0
6,6,-6:0
8,6,-6:0
-2,-2,-6:0
-11,-12,-5:3
-10,-12,-5:3
-9,-12,-5:3
-8,-12,-5:1
-7,-12,-5:1
-6,-12,-5:1
-5,-12,-5:1
-4,-12,-5:1
-3,-12,-5:1
-2,-12,-5:1
-1,-12,-5:1
0,-12,-5:1
1,-12,-5:1
2,-12,-5:1
3,-12,-5:1
4,-12,-5:1
5,-12,-5:1
6,-12,-5:1
7,-12,-5:1
8,-12,-5:1
9,-12,-5:1
10,-12,-5:1
11,-12,-5:1
12,-12,-5:3
-11,-11,-5:1
-10,-11,-5:3
-9,-11,-5:3
-8,-11,-5:3
-7,-11,-5:3
-6,-11,-5:3
-5,-11,-5:3
-4,-11,-5:3
-3,-11,-5:3
-2,-11,-5:3
-1,-11,-5:3
0,-11,-5:3
1,-11,-5:3
2,-11,-5:3
3,-11,-5:3
4,-11,-5:3
5,-11,-5:3
6,-11,-5:3
7,-11,-5:3
8,-11,-5:3
9,-11,-5:3
10,-11,-5:3
11,-11,-5:3
12,-11,-5:1
-11,-10,-5:1
-10,-10,-5:3
-9,-10,-5:3
-8,-10,-5:3
-7,-10,-5:3
-6,-10,-5:3
-5,-10,-5:3
-4,-10,-5:3
-3,-10,-5:3
-2,-10,-5:3
-1,-10,-5:3
0,-10,-5:3
1,-10,-5:3
2,-10,-5:3
3,-10,-5:1
4,-10,-5:3
5,-10,-5:3
6,-10,-5:3
7,-10,-5:3
8,-10,-5:3
9,-10,-5:3
10,-10,-5:3
11,-10,-5:1
12,-10,-5:1
-11,-9,-5:1
-10,-9,-5:3
-9,-9,-5:3
-8,-9,-5:3
-7,-9,-5:3
-6,-9,-5:3
-5,-9,-5:3
-4,-9,-5:3
-3,-9,-5:98.0
-2,-9,-5:98.0
-1,-9,-5:98.0
0,-9,-5:98.0
1,-9,-5:98.0
2,-9,-5:98.1
3,-9,-5:98.1
4,-9,-5:98.0
5,-9,-5:98.0
6,-9,-5:98.1
7,-9,-5:98.0
8,-9,-5:98.0
9,-9,-5:98.1
10,-9,-5:1
11,-9,-5:1
12,-9,-5:1
-11,-8,-5:1
-10,-8,-5:3
-9,-8,-5:3
-8,-8,-5:3
-7,-8,-5:3
-6,-8,-5:3
-5,-8,-5:3
-4,-8,-5:3
-3,-8,-5:98.0
9,-8,-5:98.0
10,-8,-5:3
11,-8,-5:3
12,-8,-5:1
-11,-7,-5:3
-10,-7,-5:3
-9,-7,-5:3
-8,-7,-5:3
-7,-7,-5:3
-6,-7,-5:3
-5,-7,-5:3
-4,-7,-5:1
-3,-7,-5:98.0
9,-7,-5:98.0
10,-7,-5:1
11,-7,-5:3
12,-7,-5:1
-11,-6,-5:1
-10,-6,-5:3
-9,-6,-5:3
-8,-6,-5:3
-7,-6,-5:98.0
-6,-6,-5:98.0
-5,-6,-5:98.1
-4,-6,-5:98.0
-3,-6,-5:98.0
-2,-6,-5:98.2
0,-6,-5:98.2
1,-6,-5:98.0
2,-6,-5:109.3
3,-6,-5:98.0
4,-6,-5:98.1
5,-6,-5:98.2
7,-6,-5:98.2
8,-6,-5:98.1
9,-6,-5:98.0
10,-6,-5:1
11,-6,-5:3
12,-6,-5:1
-11,-5,-5:3
-10,-5,-5:3
-9,-5,-5:3
-8,-5,-5:3
-7,-5,-5:98.0
-6,-5,-5:17.0
-5,-5,-5:18
7,-5,-5:17
8,-5,-5:17
9,-5,-5:98.1
10,-5,-5:3
11,-5,-5:1
12,-5,-5:1
-11,-4,-5:1
-10,-4,-5:3
-9,-4,-5:3
-8,-4,-5:3
-7,-4,-5:98.1
-6,-4,-5:18
9,-4,-5:98.1
10,-4,-5:3
11,-4,-5:3
12,-4,-5:1
-11,-3,-5:1
-10,-3,-5:98.0
-9,-3,-5:98.1
-8,-3,-5:98.0
-7,-3,-5:98.2
-4,-3,-5:98.0
-3,-3,-5:98.0
-2,-3,-5:98.0
-1,-3,-5:98.0
0,-3,-5:98.0
1,-3,-5:98.0
2,-3,-5:98.2
9,-3,-5:98.0
10,-3,-5:3
11,-3,-5:1
12,-3,-5:1
-12,-2,-5:1
-11,-2,-5:1
-10,-2,-5:3
-9,-2,-5:3
-8,-2,-5:3
-4,-2,-5:44.5
-3,-2,-5:98.0
-2,-2,-5:98.0
-1,-2,-5:109.1
9,-2,-5:98.0
10,-2,-5:3
11,-2,-5:3
12,-2,-5:1
-12,-1,-5:1
-11,-1,-5:3
-10,-1,-5:3
-9,-1,-5:3
-8,-1,-5:3
-4,-1,-5:44.5
-3,-1,-5:98.0
-2,-1,-5:98.0
-1,-1,-5:109.1
9,-1,-5:98.1
10,-1,-5:3
11,-1,-5:1
12,-1,-5:1
-11,0,-5:3
-10,0,-5:98.0
-9,0,-5:3
-8,0,-5:98.0
-7,0,-5:98.2
-4,0,-5:98.1
-3,0,-5:98.0
-2,0,-5:98.0
-1,0,-5:98.0
0,0,-5:98.0
1,0,-5:98.0
2,0,-5:98.2
9,0,-5:98.1
10,0,-5:3
11,0,-5:3
12,0,-5:1
-11,1,-5:3
-10,1,-5:3
-9,1,-5:3
-8,1,-5:3
-7,1,-5:98.0
-6,1,-5:18
9,1,-5:98.0
10,1,-5:3
11,1,-5:1
12,1,-5:1
-11,2,-5:3
-10,2,-5:3
-9,2,-5:3
-8,2,-5:3
-7,2,-5:98.0
-6,2,-5:18
-5,2,-5:18
9,2,-5:98.0
10,2,-5:1
11,2,-5:3
12,2,-5:1
-11,3,-5:3
-10,3,-5:3
-9,3,-5:3
-8,3,-5:3
-7,3,-5:98.0
-6,3,-5:17
-5,3,-5:98.1
-4,3,-5:98.1
-3,3,-5:30
-2,3,-5:98.2
0,3,-5:98.2
1,3,-5:98.1
2,3,-5:109
3,3,-5:98.0
4,3,-5:98.0
5,3,-5:98.2
7,3,-5:98.2
8,3,-5:98.0
9,3,-5:98.0
10,3,-5:3
11,3,-5:3
12,3,-5:1
-11,4,-5:3
-10,4,-5:3
-9,4,-5:3
-8,4,-5:3
-7,4,-5:98.0
-6,4,-5:18
2,4,-5:98.0
3,4,-5:98.0
9,4,-5:98.0
10,4,-5:3
11,4,-5:3
12,4,-5:1
-11,5,-5:3
-10,5,-5:3
-9,5,-5:3
-8,5,-5:3
-7,5,-5:98.1
3,5,-5:44.5
9,5,-5:98.0
10,5,-5:3
11,5,-5:3
12,5,-5:1
-11,6,-5:3
-10,6,-5:3
-9,6,-5:3
-8,6,-5:3
-7,6,-5:98.0
2,6,-5:44
3,6,-5:98.0
9,6,-5:98.0
10,6,-5:1
11,6,-5:3
12,6,-5:1
-11,7,-5:3
-10,7,-5:3
-9,7,-5:3
-8,7,-5:3
-7,7,-5:98.0
-6,7,-5:98.1
-5,7,-5:98.0
-4,7,-5:98.0
-3,7,-5:98.0
-2,7,-5:98.0
-1,7,-5:98.0
0,7,-5:98.0
1,7,-5:98.0
2,7,-5:98.0
3,7,-5:98.1
4,7,-5:98.1
5,7,-5:98.0
6,7,-5:98.1
7,7,-5:98.0
8,7,-5:98.0
9,7,-5:98.0
10,7,-5:3
11,7,-5:3
12,7,-5:1
-11,8,-5:3
-10,8,-5:3
-9,8,-5:3
-8,8,-5:3
-7,8,-5:3
-5,8,-5:3
-4,8,-5:3
-3,8,-5:3
-2,8,-5:3
-1,8,-5:3
0,8,-5:3
1,8,-5:3
2,8,-5:3
3,8,-5:3
4,8,-5:3
5,8,-5:3
6,8,-5:3
7,8,-5:3
8,8,-5:3
9,8,-5:3
10,8,-5:3
11,8,-5:3
12,8,-5:1
-11,9,-5:3
-10,9,-5:3
-9,9,-5:3
-8,9,-5:3
-7,9,-5:3
-6,9,-5:3
-5,9,-5:3
-3,9,-5:3
-2,9,-5:3
-1,9,-5:3
0,9,-5:3
1,9,-5:3
2,9,-5:3
3,9,-5:3
4,9,-5:3
5,9,-5:3
6,9,-5:3
7,9,-5:3
8,9,-5:3
9,9,-5:3
10,9,-5:3
11,9,-5:3
12,9,-5:1
-11,10,-5:3
-10,10,-5:1
-9,10,-5:1
-8,10,-5:1
-7,10,-5:1
-6,10,-5:1
-5,10,-5:1
-4,10,-5:1
-3,10,-5:1
-2,10,-5:16
-1,10,-5:16
0,10,-5:16
1,10,-5:1
2,10,-5:1
3,10,-5:1
4,10,-5:1
5,10,-5:1
6,10,-5:1
7,10,-5:1
8,10,-5:1
9,10,-5:1
10,10,-5:1
11,10,-5:1
12,10,-5:1
4,5,-5:106.2
6,2,-5:106.1
4,2,-5:106.1
3,0,-5:106.2
8,-1,-5:106.8
3,-1,-5:106.2
2,-1,-5:106.1
1,-1,-5:106.8
8,-2,-5:106.8
3,-2,-5:106.2
1,-2,-5:106.8
3,-3,-5:106.2
-6,5,-5:0
-5,5,-5:0
-4,5,-5:0
-5,4,-5:0
-4,4,-5:0
-3,5,-5:0
-4,6,-5:0
-5,6,-5:0
-6,6,-5:0
-3,6,-5:0
-2,6,-5:0
-2,5,-5:0
-3,4,-5:0
-2,4,-5:0
-1,4,-5:0
0,4,-5:0
1,4,-5:0
0,5,-5:0
-1,5,-5:0
1,5,-5:0
2,5,-5:0
1,6,-5:0
0,6,-5:0
-1,6,-5:0
-1,3,-5:0
-4,2,-5:0
-3,2,-5:0
-2,2,-5:0
-1,2,-5:0
0,2,-5:0
1,2,-5:0
2,2,-5:0
3,1,-5:0
2,1,-5:0
1,1,-5:0
0,1,-5:0
-1,1,-5:0
-2,1,-5:0
-3,1,-5:0
-4,1,-5:0
-5,1,-5:0
-5,0,-5:0
-5,-1,-5:0
-6,-1,-5:0
-6,0,-5:0
-7,-1,-5:0
-6,-2,-5:0
-7,-2,-5:0
-5,-2,-5:0
-5,-3,-5:0
-6,-3,-5:0
-5,-4,-5:0
-4,-4,-5:0
-3,-4,-5:0
-3,-5,-5:0
-2,-5,-5:0
-4,-5,-5:0
4,4,-5:0
5,4,-5:0
6,4,-5:0
6,3,-5:0
7,4,-5:0
8,4,-5:0
8,5,-5:0
7,5,-5:0
6,5,-5:0
7,6,-5:0
8,6,-5:0
6,6,-5:0
5,6,-5:0
5,5,-5:0
4,6,-5:0
3,2,-5:0
4,1,-5:0
5,1,-5:0
5,2,-5:0
6,1,-5:0
7,1,-5:0
8,1,-5:0
8,2,-5:0
7,2,-5:0
8,0,-5:0
7,0,-5:0
5,0,-5:0
4,0,-5:0
5,-1,-5:0
6,-1,-5:0
6,0,-5:0
7,-1,-5:0
7,-2,-5:0
7,-3,-5:0
7,-4,-5:0
8,-4,-5:0
8,-3,-5:0
6,-3,-5:0
5,-3,-5:0
5,-2,-5:0
6,-2,-5:0
4,-1,-5:0
4,-2,-5:0
4,-3,-5:0
6,-4,-5:0
6,-5,-5:0
5,-5,-5:0
4,-5,-5:0
3,-5,-5:0
2,-5,-5:0
1,-5,-5:0
0,-5,-5:0
-1,-5,-5:0
-2,-4,-5:0
-1,-4,-5:0
0,-4,-5:0
1,-4,-5:0
2,-4,-5:0
3,-4,-5:0
4,-4,-5:0
5,-4,-5:0
2,-2,-5:0
0,-2,-5:0
0,-1,-5:0
-1,-6,-5:0
-1,-7,-5:0
-2,-7,-5:0
-2,-8,-5:0
-1,-8,-5:0
0,-8,-5:0
1,-8,-5:0
2,-8,-5:0
3,-8,-5:0
2,-7,-5:0
1,-7,-5:0
0,-7,-5:0
3,-7,-5:0
4,-7,-5:0
5,-7,-5:0
6,-7,-5:0
7,-8,-5:0
8,-8,-5:0
6,-8,-5:0
5,-8,-5:0
4,-8,-5:0
7,-7,-5:0
8,-7,-5:0
6,-6,-5:0
-11,-13,-4:3
-10,-13,-4:3
-9,-13,-4:1
-8,-13,-4:1
-7,-13,-4:1
-6,-13,-4:1
-5,-13,-4:1
-4,-13,-4:1
-3,-13,-4:1
-2,-13,-4:1
-1,-13,-4:1
0,-13,-4:1
1,-13,-4:1
2,-13,-4:1
3,-13,-4:1
4,-13,-4:1
5,-13,-4:1
6,-13,-4:1
7,-13,-4:1
8,-13,-4:1
9,-13,-4:1
10,-13,-4:1
11,-13,-4:1
12,-13,-4:3
-12,-12,-4:1
-11,-12,-4:3
-10,-12,-4:3
-9,-12,-4:3
-8,-12,-4:3
-7,-12,-4:3
-6,-12,-4:3
-5,-12,-4:3
-4,-12,-4:3
-3,-12,-4:3
-2,-12,-4:3
-1,-12,-4:3
0,-12,-4:3
1,-12,-4:3
2,-12,-4:3
3,-12,-4:3
4,-12,-4:3
5,-12,-4:3
6,-12,-4:3
7,-12,-4:3
8,-12,-4:3
9,-12,-4:3
10,-12,-4:3
11,-12,-4:3
12,-12,-4:3
13,-12,-4:3
-12,-11,-4:16
-11,-11,-4:3
-10,-11,-4:3
-9,-11,-4:3
-8,-11,-4:3
-7,-11,-4:3
-6,-11,-4:3
-5,-11,-4:3
-4,-11,-4:3
-3,-11,-4:3
-2,-11,-4:3
-1,-11,-4:3
0,-11,-4:3
1,-11,-4:3
2,-11,-4:3
3,-11,-4:3
4,-11,-4:3
5,-11,-4:3
6,-11,-4:3
7,-11,-4:3
8,-11,-4:3
9,-11,-4:3
10,-11,-4:3
11,-11,-4:3
12,-11,-4:3
13,-11,-4:3
-12,-10,-4:16
-11,-10,-4:3
-10,-10,-4:3
-9,-10,-4:3
-8,-10,-4:3
-7,-10,-4:3
-6,-10,-4:3
-5,-10,-4:3
-4,-10,-4:3
-3,-10,-4:3
-2,-10,-4:3
-1,-10,-4:3
0,-10,-4:3
1,-10,-4:3
2,-10,-4:3
3,-10,-4:3
4,-10,-4:3
5,-10,-4:3
6,-10,-4:3
7,-10,-4:3
8,-10,-4:3
9,-10,-4:3
10,-10,-4:3
11,-10,-4:3
12,-10,-4:3
13,-10,-4:3
-12,-9,-4:3
-11,-9,-4:3
-10,-9,-4:3
-9,-9,-4:3
-8,-9,-4:3
-7,-9,-4:3
-6,-9,-4:3
-5,-9,-4:3
-4,-9,-4:3
-3,-9,-4:98.0
-2,-9,-4:98.0
-1,-9,-4:98.1
0,-9,-4:98.0
1,-9,-4:98.0
2,-9,-4:98.1
3,-9,-4:98.1
4,-9,-4:98.0
5,-9,-4:98.1
6,-9,-4:98.0
7,-9,-4:98.0
8,-9,-4:98.0
9,-9,-4:98.0
10,-9,-4:3
11,-9,-4:3
12,-9,-4:3
13,-9,-4:3
-12,-8,-4:3
-11,-8,-4:3
-10,-8,-4:3
-9,-8,-4:3
-8,-8,-4:3
-7,-8,-4:3
-6,-8,-4:3
-5,-8,-4:3
-4,-8,-4:3
-3,-8,-4:98.0
9,-8,-4:98.0
10,-8,-4:3
11,-8,-4:3
12,-8,-4:3
13,-8,-4:3
-12,-7,-4:3
-11,-7,-4:3
-10,-7,-4:3
-9,-7,-4:3
-8,-7,-4:3
-7,-7,-4:3
-6,-7,-4:3
-5,-7,-4:3
-4,-7,-4:3
-3,-7,-4:98.0
-2,-7,-4:30
9,-7,-4:98.0
10,-7,-4:3
11,-7,-4:3
12,-7,-4:3
13,-7,-4:3
-12,-6,-4:1
-11,-6,-4:3
-10,-6,-4:3
-9,-6,-4:3
-8,-6,-4:3
-7,-6,-4:98.0
-6,-6,-4:98.0
-5,-6,-4:98.0
-4,-6,-4:98.1
-3,-6,-4:98.0
-2,-6,-4:98.2
-1,-6,-4:98.2
0,-6,-4:98.2
1,-6,-4:98.0
2,-6,-4:98.0
3,-6,-4:98.0
4,-6,-4:98.1
5,-6,-4:98.2
6,-6,-4:98.2
7,-6,-4:98.2
8,-6,-4:98.0
9,-6,-4:98.0
10,-6,-4:3
11,-6,-4:3
12,-6,-4:3
13,-6,-4:3
-12,-5,-4:1
-11,-5,-4:3
-10,-5,-4:3
-9,-5,-4:3
-8,-5,-4:3
-7,-5,-4:98.1
-6,-5,-4:18
-5,-5,-4:18
8,-5,-4:17
9,-5,-4:98.0
10,-5,-4:3
11,-5,-4:3
12,-5,-4:3
13,-5,-4:3
-12,-4,-4:1
-11,-4,-4:3
-10,-4,-4:3
-9,-4,-4:3
-8,-4,-4:3
-7,-4,-4:98.0
-6,-4,-4:18
9,-4,-4:98.0
10,-4,-4:3
11,-4,-4:3
12,-4,-4:1
13,-4,-4:3
-12,-3,-4:1
-11,-3,-4:3
-10,-3,-4:3
-9,-3,-4:98.1
-8,-3,-4:98.0
-7,-3,-4:98.2
-4,-3,-4:98.0
-3,-3,-4:98.0
-2,-3,-4:98.0
-1,-3,-4:98.0
0,-3,-4:98.0
1,-3,-4:98.0
2,-3,-4:98.1
9,-3,-4:23.4
10,-3,-4:3
11,-3,-4:3
12,-3,-4:1
13,-3,-4:3
-13,-2,-4:1
-12,-2,-4:98.0
-11,-2,-4:3
-10,-2,-4:3
-9,-2,-4:3
-8,-2,-4:3
-7,-2,-4:98.2
-4,-2,-4:44.5
-3,-2,-4:98.0
-2,-2,-4:109.1
9,-2,-4:98.0
10,-2,-4:3
11,-2,-4:3
12,-2,-4:1
13,-2,-4:3
-13,-1,-4:1
-12,-1,-4:3
-11,-1,-4:3
-10,-1,-4:3
-9,-1,-4:3
-8,-1,-4:98.1
-7,-1,-4:98.2
-4,-1,-4:44.5
-3,-1,-4:98.0
-2,-1,-4:109.1
9,-1,-4:98.0
10,-1,-4:3
11,-1,-4:3
12,-1,-4:1
13,-1,-4:3
-12,0,-4:3
-11,0,-4:3
-10,0,-4:3
-9,0,-4:98.1
-8,0,-4:98.0
-7,0,-4:98.2
-4,0,-4:98.0
-3,0,-4:98.0
-2,0,-4:98.0
-1,0,-4:98.0
0,0,-4:98.1
1,0,-4:98.0
2,0,-4:98.1
9,0,-4:23.4
10,0,-4:3
11,0,-4:3
12,0,-4:3
13,0,-4:3
-12,1,-4:3
-11,1,-4:3
-10,1,-4:3
-9,1,-4:3
-8,1,-4:3
-7,1,-4:98.0
-6,1,-4:18
-5,1,-4:18
9,1,-4:98.0
10,1,-4:3
11,1,-4:3
12,1,-4:3
13,1,-4:3
-12,2,-4:3
-11,2,-4:3
-10,2,-4:3
-9,2,-4:3
-8,2,-4:3
-7,2,-4:98.0
-6,2,-4:17
-5,2,-4:18
9,2,-4:98.0
10,2,-4:3
11,2,-4:3
12,2,-4:3
13,2,-4:3
-12,3,-4:3
-11,3,-4:3
-10,3,-4:3
-9,3,-4:3
-8,3,-4:3
-7,3,-4:98.0
-6,3,-4:98.0
-5,3,-4:98.1
-4,3,-4:98.0
-3,3,-4:98.0
-2,3,-4:98.2
-1,3,-4:98.2
0,3,-4:98.2
1,3,-4:98.1
2,3,-4:98.0
3,3,-4:98.0
4,3,-4:98.1
5,3,-4:98.2
6,3,-4:98.2
7,3,-4:98.2
8,3,-4:98.0
9,3,-4:98.1
10,3,-4:3
11,3,-4:3
12,3,-4:3
13,3,-4:3
-12,4,-4:3
-11,4,-4:3
-10,4,-4:3
-9,4,-4:3
-8,4,-4:3
-7,4,-4:98.1
2,4,-4:98.0
3,4,-4:98.0
9,4,-4:3
10,4,-4:3
11,4,-4:3
12,4,-4:3
13,4,-4:3
-12,5,-4:3
-11,5,-4:3
-10,5,-4:3
-9,5,-4:3
-8,5,-4:3
-7,5,-4:98.0
2,5,-4:109
3,5,-4:98.1
9,5,-4:3
10,5,-4:3
11,5,-4:3
12,5,-4:3
13,5,-4:3
-12,6,-4:3
-11,6,-4:3
-10,6,-4:3
-9,6,-4:3
-8,6,-4:3
-7,6,-4:98.0
-6,6,-4:30
-1,6,-4:30
2,6,-4:98.0
3,6,-4:98.0
8,6,-4:30
9,6,-4:98.0
10,6,-4:3
11,6,-4:3
12,6,-4:3
13,6,-4:3
-12,7,-4:3
-11,7,-4:3
-10,7,-4:3
-9,7,-4:3
-8,7,-4:3
-7,7,-4:98.1
-6,7,-4:98.1
-5,7,-4:98.0
-4,7,-4:98.1
-3,7,-4:98.1
-2,7,-4:98.0
-1,7,-4:98.1
0,7,-4:98.1
1,7,-4:98.0
2,7,-4:98.1
3,7,-4:98.0
4,7,-4:98.1
5,7,-4:98.0
6,7,-4:98.0
7,7,-4:3
8,7,-4:98.0
9,7,-4:98.0
10,7,-4:3
11,7,-4:3
12,7,-4:3
13,7,-4:3
-12,8,-4:3
-11,8,-4:3
-10,8,-4:3
-9,8,-4:3
-8,8,-4:3
-7,8,-4:3
-6,8,-4:3
-5,8,-4:3
-4,8,-4:3
-3,8,-4:3
-2,8,-4:3
-1,8,-4:3
0,8,-4:3
1,8,-4:3
2,8,-4:3
3,8,-4:3
4,8,-4:3
5,8,-4:3
6,8,-4:3
7,8,-4:3
8,8,-4:3
9,8,-4:3
10,8,-4:3
11,8,-4:3
12,8,-4:3
13,8,-4:3
-12,9,-4:3
-11,9,-4:3
-10,9,-4:3
-9,9,-4:3
-8,9,-4:3
-7,9,-4:3
-6,9,-4:3
-5,9,-4:3
-4,9,-4:3
-3,9,-4:3
-2,9,-4:3
-1,9,-4:3
0,9,-4:3
1,9,-4:3
2,9,-4:3
3,9,-4:3
4,9,-4:3
5,9,-4:3
6,9,-4:3
7,9,-4:3
8,9,-4:3
9,9,-4:3
10,9,-4:3
11,9,-4:3
12,9,-4:3
13,9,-4:3
-12,10,-4:3
-11,10,-4:3
-10,10,-4:3
-9,10,-4:3
-8,10,-4:3
-7,10,-4:3
-6,10,-4:3
-5,10,-4:3
-4,10,-4:3
-3,10,-4:3
-2,10,-4:3
-1,10,-4:3
0,10,-4:3
1,10,-4:3
2,10,-4:3
3,10,-4:3
4,10,-4:3
5,10,-4:3
6,10,-4:3
7,10,-4:3
8,10,-4:3
9,10,-4:3
10,10,-4:3
11,10,-4:3
12,10,-4:3
13,10,-4:3
-11,11,-4:1
-10,11,-4:3
-9,11,-4:1
-8,11,-4:2
-7,11,-4:1
-6,11,-4:1
-5,11,-4:1
-4,11,-4:3
-3,11,-4:3
-2,11,-4:3
-1,11,-4:3
0,11,-4:3
1,11,-4:3
2,11,-4:3
3,11,-4:3
4,11,-4:3
5,11,-4:3
6,11,-4:3
7,11,-4:3
8,11,-4:3
9,11,-4:3
10,11,-4:3
11,11,-4:3
12,11,-4:3
13,11,-4:3
4,5,-4:106.2
6,2,-4:106.1
4,2,-4:106.1
3,0,-4:106.2
8,-1,-4:106.8
3,-1,-4:106.2
2,-1,-4:106.1
1,-1,-4:106.8
8,-2,-4:106.8
3,-2,-4:106.2
1,-2,-4:106.8
3,-3,-4:106.2
0,-1,-4:0
0,-2,-4:0
-1,-2,-4:0
-1,-1,-4:0
2,-2,-4:0
4,-5,-4:0
4,-4,-4:0
3,-4,-4:0
2,-4,-4:0
1,-4,-4:0
0,-4,-4:0
-1,-4,-4:0
-2,-4,-4:0
-3,-4,-4:0
-4,-5,-4:0
-3,-5,-4:0
-2,-5,-4:0
-1,-5,-4:0
0,-5,-4:0
1,-5,-4:0
2,-5,-4:0
5,-4,-4:0
6,-5,-4:0
3,-5,-4:0
5,-5,-4:0
7,-5,-4:0
8,-4,-4:0
7,-4,-4:0
6,-4,-4:0
5,-3,-4:0
4,-3,-4:0
8,-3,-4:0
7,-3,-4:0
6,-3,-4:0
7,-2,-4:0
6,-2,-4:0
5,-2,-4:0
4,-2,-4:0
4,-1,-4:0
5,-1,-4:0
6,-1,-4:0
7,-1,-4:0
6,0,-4:0
5,0,-4:0
4,0,-4:0
5,1,-4:0
6,1,-4:0
7,1,-4:0
8,0,-4:0
7,0,-4:0
8,1,-4:0
8,2,-4:0
7,2,-4:0
5,2,-4:0
4,1,-4:0
3,1,-4:0
2,1,-4:0
1,1,-4:0
0,1,-4:0
3,2,-4:0
2,2,-4:0
1,2,-4:0
0,2,-4:0
-1,2,-4:0
-2,2,-4:0
-3,2,-4:0
-1,1,-4:0
-2,1,-4:0
-3,1,-4:0
-4,2,-4:0
-4,1,-4:0
-5,0,-4:0
-5,-1,-4:0
-5,-2,-4:0
-5,-3,-4:0
-4,-4,-4:0
-5,-4,-4:0
-6,-3,-4:0
-6,-2,-4:0
-6,-1,-4:0
-6,0,-4:0
-2,-8,-4:0
-1,-8,-4:0
0,-8,-4:0
0,-7,-4:0
-1,-7,-4:0
1,-7,-4:0
2,-7,-4:0
3,-7,-4:0
3,-8,-4:0
4,-8,-4:0
2,-8,-4:0
1,-8,-4:0
5,-7,-4:0
6,-7,-4:0
6,-8,-4:0
7,-8,-4:0
8,-8,-4:0
7,-7,-4:0
5,-8,-4:0
8,-7,-4:0
4,-7,-4:0
4,4,-4:0
5,4,-4:0
5,5,-4:0
5,6,-4:0
4,6,-4:0
6,6,-4:0
6,5,-4:0
7,6,-4:0
7,5,-4:0
8,5,-4:0
7,4,-4:0
6,4,-4:0
8,4,-4:0
1,6,-4:0
1,5,-4:0
1,4,-4:0
0,4,-4:0
0,5,-4:0
0,6,-4:0
-1,5,-4:0
-2,5,-4:0
-2,6,-4:0
-3,6,-4:0
-4,6,-4:0
-5,6,-4:0
-5,5,-4:0
-6,5,-4:0
-6,4,-4:0
-5,4,-4:0
-4,4,-4:0
-3,4,-4:0
-2,4,-4:0
-1,4,-4:0
-3,5,-4:0
-4,5,-4:0
-8,-15,-3:3
-11,-14,-3:3
-10,-14,-3:3
-9,-14,-3:3
-8,-14,-3:3
-7,-14,-3:3
-6,-14,-3:3
-5,-14,-3:3
-4,-14,-3:3
-3,-14,-3:3
-2,-14,-3:3
-1,-14,-3:3
0,-14,-3:3
1,-14,-3:3
2,-14,-3:3
3,-14,-3:3
4,-14,-3:3
5,-14,-3:3
6,-14,-3:3
7,-14,-3:3
8,-14,-3:3
9,-14,-3:3
10,-14,-3:3
11,-14,-3:3
12,-14,-3:3
-12,-13,-3:3
-11,-13,-3:3
-10,-13,-3:3
-9,-13,-3:3
-8,-13,-3:3
-7,-13,-3:3
-6,-13,-3:3
-5,-13,-3:3
-4,-13,-3:3
-3,-13,-3:3
-2,-13,-3:3
-1,-13,-3:3
0,-13,-3:3
1,-13,-3:3
2,-13,-3:3
3,-13,-3:3
4,-13,-3:3
5,-13,-3:3
6,-13,-3:3
7,-13,-3:3
8,-13,-3:3
9,-13,-3:3
10,-13,-3:3
11,-13,-3:3
12,-13,-3:3
13,-13,-3:3
-13,-12,-3:3
-12,-12,-3:3
-11,-12,-3:3
-10,-12,-3:3
-9,-12,-3:3
-8,-12,-3:3
-7,-12,-3:3
-6,-12,-3:3
-5,-12,-3:3
-4,-12,-3:3
-3,-12,-3:3
-2,-12,-3:3
-1,-12,-3:3
0,-12,-3:3
1,-12,-3:3
2,-12,-3:3
3,-12,-3:3
4,-12,-3:3
5,-12,-3:3
6,-12,-3:3
7,-12,-3:3
8,-12,-3:3
9,-12,-3:3
10,-12,-3:3
11,-12,-3:3
12,-12,-3:3
13,-12,-3:3
14,-12,-3:3
-13,-11,-3:3
-12,-11,-3:3
-11,-11,-3:3
-10,-11,-3:3
-9,-11,-3:3
-8,-11,-3:3
-7,-11,-3:3
-6,-11,-3:3
-5,-11,-3:3
-4,-11,-3:3
-3,-11,-3:3
-2,-11,-3:3
-1,-11,-3:3
0,-11,-3:3
1,-11,-3:3
2,-11,-3:3
3,-11,-3:3
4,-11,-3:3
5,-11,-3:3
6,-11,-3:3
7,-11,-3:3
8,-11,-3:3
9,-11,-3:3
10,-11,-3:3
11,-11,-3:3
12,-11,-3:3
13,-11,-3:3
14,-11,-3:3
-13,-10,-3:1
-12,-10,-3:3
-11,-10,-3:3
-10,-10,-3:3
-9,-10,-3:3
-8,-10,-3:3
-7,-10,-3:3
-6,-10,-3:3
-5,-10,-3:3
-4,-10,-3:3
-3,-10,-3:3
-2,-10,-3:3
-1,-10,-3:3
0,-10,-3:3
1,-10,-3:3
2,-10,-3:3
3,-10,-3:3
4,-10,-3:3
5,-10,-3:3
6,-10,-3:3
7,-10,-3:3
8,-10,-3:3
9,-10,-3:3
10,-10,-3:3
11,-10,-3:3
12,-10,-3:3
13,-10,-3:3
14,-10,-3:3
-13,-9,-3:1
-12,-9,-3:3
-11,-9,-3:3
-10,-9,-3:3
-9,-9,-3:3
-8,-9,-3:3
-7,-9,-3:3
-6,-9,-3:3
-5,-9,-3:3
-4,-9,-3:3
-3,-9,-3:98.0
-2,-9,-3:98.0
-1,-9,-3:98.0
0,-9,-3:98.0
1,-9,-3:98.0
2,-9,-3:98.0
3,-9,-3:98.1
4,-9,-3:98.0
5,-9,-3:98.1
6,-9,-3:98.1
7,-9,-3:98.1
8,-9,-3:98.1
9,-9,-3:98.1
10,-9,-3:3
11,-9,-3:3
12,-9,-3:3
13,-9,-3:3
14,-9,-3:3
-13,-8,-3:1
-12,-8,-3:3
-11,-8,-3:3
-10,-8,-3:3
-9,-8,-3:3
-8,-8,-3:3
-7,-8,-3:3
-6,-8,-3:3
-5,-8,-3:3
-4,-8,-3:3
-3,-8,-3:98.0
-2,-8,-3:98.0
-1,-8,-3:98.1
0,-8,-3:98.0
1,-8,-3:98.0
2,-8,-3:98.0
3,-8,-3:98.0
4,-8,-3:98.1
5,-8,-3:98.1
6,-8,-3:98.1
7,-8,-3:98.0
8,-8,-3:30
9,-8,-3:98.0
10,-8,-3:3
11,-8,-3:3
12,-8,-3:3
13,-8,-3:3
14,-8,-3:3
-13,-7,-3:1
-12,-7,-3:3
-11,-7,-3:3
-10,-7,-3:3
-9,-7,-3:3
-8,-7,-3:3
-7,-7,-3:3
-6,-7,-3:3
-5,-7,-3:3
-4,-7,-3:3
-3,-7,-3:98.0
-2,-7,-3:98.1
-1,-7,-3:98.0
0,-7,-3:98.0
1,-7,-3:98.0
2,-7,-3:98.1
3,-7,-3:98.0
5,-7,-3:98.1
6,-7,-3:98.0
7,-7,-3:98.0
8,-7,-3:98.0
9,-7,-3:98.0
10,-7,-3:3
11,-7,-3:3
12,-7,-3:3
13,-7,-3:3
14,-7,-3:3
-13,-6,-3:3
-12,-6,-3:3
-11,-6,-3:3
-10,-6,-3:3
-9,-6,-3:3
-8,-6,-3:3
-7,-6,-3:98.0
-6,-6,-3:98.0
-5,-6,-3:98.0
-4,-6,-3:98.1
-3,-6,-3:98.0
-2,-6,-3:98.0
-1,-6,-3:98.0
0,-6,-3:98.0
1,-6,-3:98.0
2,-6,-3:98.1
3,-6,-3:98.1
4,-6,-3:98.0
5,-6,-3:98.0
6,-6,-3:98.0
7,-6,-3:98.0
8,-6,-3:98.0
9,-6,-3:98.0
10,-6,-3:3
11,-6,-3:3
12,-6,-3:3
13,-6,-3:3
14,-6,-3:3
-13,-5,-3:3
-12,-5,-3:3
-11,-5,-3:3
-10,-5,-3:3
-9,-5,-3:3
-8,-5,-3:3
-7,-5,-3:98.1
-6,-5,-3:18
7,-5,-3:30
8,-5,-3:17
9,-5,-3:98.1
10,-5,-3:3
11,-5,-3:3
12,-5,-3:3
13,-5,-3:3
14,-5,-3:3
-13,-4,-3:3
-12,-4,-3:3
-11,-4,-3:3
-10,-4,-3:3
-9,-4,-3:3
-8,-4,-3:3
-7,-4,-3:98.0
9,-4,-3:98.0
10,-4,-3:3
11,-4,-3:3
12,-4,-3:3
13,-4,-3:3
14,-4,-3:3
-13,-3,-3:1
-12,-3,-3:3
-11,-3,-3:3
-10,-3,-3:3
-9,-3,-3:3
-8,-3,-3:3
-7,-3,-3:98.0
-4,-3,-3:98.0
-3,-3,-3:98.0
-2,-3,-3:98.0
-1,-3,-3:98.1
0,-3,-3:98.0
1,-3,-3:98.0
2,-3,-3:98.2
8,-3,-3:109
9,-3,-3:98.0
10,-3,-3:3
11,-3,-3:3
12,-3,-3:3
13,-3,-3:3
14,-3,-3:3
-13,-2,-3:1
-12,-2,-3:3
-11,-2,-3:3
-10,-2,-3:3
-9,-2,-3:3
-8,-2,-3:3
-7,-2,-3:98.0
-4,-2,-3:44.5
-3,-2,-3:109.1
2,-2,-3:98.1
9,-2,-3:98.1
10,-2,-3:3
11,-2,-3:3
12,-2,-3:3
13,-2,-3:3
14,-2,-3:3
-13,-1,-3:1
-12,-1,-3:3
-11,-1,-3:3
-10,-1,-3:3
-9,-1,-3:3
-8,-1,-3:3
-7,-1,-3:98.0
-4,-1,-3:44.5
-3,-1,-3:109.1
2,-1,-3:98.1
9,-1,-3:98.0
10,-1,-3:3
11,-1,-3:3
12,-1,-3:3
13,-1,-3:3
14,-1,-3:3
15,-1,-3:3
-13,0,-3:1
-12,0,-3:3
-11,0,-3:3
-10,0,-3:3
-9,0,-3:3
-8,0,-3:3
-7,0,-3:98.0
-4,0,-3:98.1
-3,0,-3:98.0
-2,0,-3:98.0
-1,0,-3:98.0
0,0,-3:98.1
1,0,-3:98.0
2,0,-3:98.2
8,0,-3:109
9,0,-3:98.0
10,0,-3:3
11,0,-3:3
12,0,-3:3
13,0,-3:3
14,0,-3:3
-13,1,-3:1
-12,1,-3:3
-11,1,-3:3
-10,1,-3:3
-9,1,-3:3
-8,1,-3:3
-7,1,-3:98.1
-6,1,-3:18
-5,1,-3:18
8,1,-3:109
9,1,-3:98.0
10,1,-3:3
11,1,-3:3
12,1,-3:3
13,1,-3:3
14,1,-3:3
15,1,-3:3
-13,2,-3:1
-12,2,-3:3
-11,2,-3:3
-10,2,-3:3
-9,2,-3:3
-8,2,-3:3
-7,2,-3:98.0
-6,2,-3:17
-5,2,-3:18
9,2,-3:98.0
10,2,-3:3
11,2,-3:3
12,2,-3:3
13,2,-3:3
14,2,-3:3
-13,3,-3:1
-12,3,-3:3
-11,3,-3:3
-10,3,-3:3
-9,3,-3:3
-8,3,-3:3
-7,3,-3:98.0
-6,3,-3:98.1
-5,3,-3:98.0
-4,3,-3:98.0
-3,3,-3:98.1
-2,3,-3:98.0
-1,3,-3:98.0
0,3,-3:98.0
1,3,-3:98.0
2,3,-3:98.1
3,3,-3:98.1
4,3,-3:98.1
5,3,-3:98.0
6,3,-3:98.1
7,3,-3:98.0
8,3,-3:98.0
9,3,-3:98.0
10,3,-3:3
11,3,-3:3
12,3,-3:3
13,3,-3:3
14,3,-3:3
-13,4,-3:1
-12,4,-3:3
-11,4,-3:3
-10,4,-3:3
-9,4,-3:3
-8,4,-3:3
-7,4,-3:98.0
-6,4,-3:98.1
-5,4,-3:98.1
-4,4,-3:98.1
-3,4,-3:98.1
-2,4,-3:98.1
-1,4,-3:98.0
0,4,-3:98.0
1,4,-3:98.1
2,4,-3:98.0
3,4,-3:98.0
4,4,-3:98.0
5,4,-3:98.0
6,4,-3:98.1
7,4,-3:98.1
8,4,-3:98.1
9,4,-3:98.0
10,4,-3:3
11,4,-3:3
12,4,-3:3
13,4,-3:3
14,4,-3:3
-13,5,-3:1
-12,5,-3:3
-11,5,-3:3
-10,5,-3:3
-9,5,-3:3
-8,5,-3:3
-7,5,-3:98.0
-6,5,-3:98.1
-5,5,-3:98.0
-4,5,-3:98.1
-3,5,-3:98.1
-2,5,-3:98.0
-1,5,-3:98.0
0,5,-3:98.0
1,5,-3:98.1
2,5,-3:98.1
3,5,-3:98.0
4,5,-3:98.1
5,5,-3:98.0
6,5,-3:98.1
7,5,-3:98.1
8,5,-3:98.1
9,5,-3:3
10,5,-3:3
11,5,-3:3
12,5,-3:3
13,5,-3:3
14,5,-3:3
-13,6,-3:1
-12,6,-3:3
-11,6,-3:3
-10,6,-3:3
-9,6,-3:3
-8,6,-3:3
-7,6,-3:98.0
-6,6,-3:98.0
-5,6,-3:98.1
-4,6,-3:98.1
-3,6,-3:98.1
-2,6,-3:98.0
-1,6,-3:98.0
0,6,-3:98.0
1,6,-3:30
2,6,-3:98.0
3,6,-3:98.0
4,6,-3:98.0
5,6,-3:30
6,6,-3:98.1
7,6,-3:98.1
8,6,-3:98.1
9,6,-3:98.0
10,6,-3:3
11,6,-3:3
12,6,-3:3
13,6,-3:3
14,6,-3:3
-13,7,-3:1
-12,7,-3:3
-11,7,-3:3
-10,7,-3:3
-9,7,-3:3
-8,7,-3:3
-7,7,-3:98.0
-6,7,-3:98.0
-5,7,-3:98.0
-4,7,-3:98.0
-3,7,-3:98.0
-2,7,-3:98.0
-1,7,-3:98.0
0,7,-3:98.0
1,7,-3:98.0
2,7,-3:98.0
3,7,-3:98.0
4,7,-3:98.0
5,7,-3:98.0
6,7,-3:3
7,7,-3:3
8,7,-3:98.0
9,7,-3:98.0
10,7,-3:3
11,7,-3:3
12,7,-3:3
13,7,-3:3
14,7,-3:3
-13,8,-3:3
-12,8,-3:3
-11,8,-3:3
-10,8,-3:3
-9,8,-3:3
-8,8,-3:3
-7,8,-3:3
-6,8,-3:3
-5,8,-3:3
-4,8,-3:3
-3,8,-3:3
-2,8,-3:3
-1,8,-3:3
0,8,-3:3
1,8,-3:3
2,8,-3:3
3,8,-3:3
4,8,-3:3
5,8,-3:3
6,8,-3:3
7,8,-3:3
8,8,-3:3
9,8,-3:3
10,8,-3:3
11,8,-3:3
12,8,-3:3
13,8,-3:3
14,8,-3:3
15,8,-3:3
-13,9,-3:3
-12,9,-3:3
-11,9,-3:3
-10,9,-3:3
-9,9,-3:3
-8,9,-3:3
-7,9,-3:3
-5,9,-3:3
-4,9,-3:3
-3,9,-3:3
-2,9,-3:3
0,9,-3:3
1,9,-3:3
2,9,-3:3
3,9,-3:3
4,9,-3:3
5,9,-3:3
6,9,-3:3
7,9,-3:3
8,9,-3:3
9,9,-3:3
10,9,-3:3
11,9,-3:3
12,9,-3:3
13,9,-3:3
14,9,-3:3
-13,10,-3:3
-12,10,-3:3
-11,10,-3:3
-10,10,-3:3
-9,10,-3:3
-8,10,-3:3
-7,10,-3:3
-6,10,-3:3
-5,10,-3:3
-4,10,-3:3
-3,10,-3:3
-2,10,-3:3
-1,10,-3:3
0,10,-3:3
1,10,-3:3
2,10,-3:3
3,10,-3:3
4,10,-3:3
5,10,-3:3
6,10,-3:3
7,10,-3:3
8,10,-3:3
9,10,-3:3
10,10,-3:3
11,10,-3:3
12,10,-3:3
13,10,-3:3
14,10,-3:3
-12,11,-3:1
-11,11,-3:3
-10,11,-3:3
-9,11,-3:3
-7,11,-3:3
-6,11,-3:3
-5,11,-3:3
-4,11,-3:3
-3,11,-3:3
-2,11,-3:3
-1,11,-3:3
0,11,-3:3
1,11,-3:3
2,11,-3:3
3,11,-3:3
4,11,-3:3
5,11,-3:3
6,11,-3:3
7,11,-3:3
8,11,-3:3
9,11,-3:3
10,11,-3:3
11,11,-3:3
12,11,-3:3
13,11,-3:3
14,11,-3:3
-11,12,-3:1
-10,12,-3:1
-9,12,-3:3
-8,12,-3:3
-7,12,-3:3
-6,12,-3:3
-5,12,-3:3
-4,12,-3:3
-3,12,-3:3
-2,12,-3:3
-1,12,-3:3
0,12,-3:3
1,12,-3:3
2,12,-3:3
3,12,-3:3
4,12,-3:3
5,12,-3:3
6,12,-3:3
7,12,-3:3
8,12,-3:3
9,12,-3:3
10,12,-3:3
11,12,-3:3
12,12,-3:3
13,12,-3:3
6,2,-3:106.1
4,2,-3:106.1
3,0,-3:106.2
8,-1,-3:106.8
3,-1,-3:106.2
1,-1,-3:106.8
-2,-1,-3:106
8,-2,-3:106.8
3,-2,-3:106.2
1,-2,-3:106.8
3,-3,-3:106.2
-2,-2,-3:0
-1,-2,-3:0
0,-2,-3:0
-1,-1,-3:0
-5,-1,-3:0
-5,-2,-3:0
-6,-2,-3:0
-6,-1,-3:0
-6,0,-3:0
-5,0,-3:0
-6,-3,-3:0
-5,-3,-3:0
-6,-4,-3:0
-5,-4,-3:0
-5,-5,-3:0
-4,-5,-3:0
-3,-5,-3:0
-2,-5,-3:0
-1,-5,-3:0
0,-5,-3:0
1,-5,-3:0
2,-5,-3:0
2,-4,-3:0
3,-4,-3:0
4,-4,-3:0
1,-4,-3:0
0,-4,-3:0
-1,-4,-3:0
-2,-4,-3:0
-3,-4,-3:0
-4,-4,-3:0
5,-4,-3:0
5,-5,-3:0
6,-5,-3:0
4,-5,-3:0
3,-5,-3:0
8,-4,-3:0
7,-4,-3:0
6,-4,-3:0
4,-7,-3:0
7,-3,-3:0
7,-2,-3:0
7,-1,-3:0
7,0,-3:0
7,1,-3:0
8,2,-3:0
7,2,-3:0
5,2,-3:0
5,1,-3:0
6,1,-3:0
6,0,-3:0
6,-1,-3:0
6,-2,-3:0
6,-3,-3:0
5,-3,-3:0
4,-3,-3:0
4,-2,-3:0
4,-1,-3:0
4,0,-3:0
5,0,-3:0
5,-1,-3:0
5,-2,-3:0
4,1,-3:0
3,1,-3:0
3,2,-3:0
2,1,-3:0
1,1,-3:0
0,1,-3:0
-1,1,-3:0
-2,1,-3:0
-3,1,-3:0
-4,1,-3:0
-4,2,-3:0
-3,2,-3:0
-2,2,-3:0
-1,2,-3:0
0,2,-3:0
1,2,-3:0
2,2,-3:0
-10,-15,-2:3
-9,-15,-2:3
-8,-15,-2:3
-7,-15,-2:3
-6,-15,-2:3
-5,-15,-2:3
-4,-15,-2:3
-3,-15,-2:3
-2,-15,-2:3
-1,-15,-2:3
0,-15,-2:3
1,-15,-2:3
2,-15,-2:3
3,-15,-2:3
4,-15,-2:3
5,-15,-2:3
6,-15,-2:3
7,-15,-2:3
8,-15,-2:3
9,-15,-2:3
10,-15,-2:3
11,-15,-2:3
12,-15,-2:3
-11,-14,-2:3
-10,-14,-2:3
-9,-14,-2:3
-8,-14,-2:3
-7,-14,-2:3
-6,-14,-2:3
-5,-14,-2:3
-4,-14,-2:3
-3,-14,-2:3
-2,-14,-2:3
-1,-14,-2:3
0,-14,-2:3
1,-14,-2:3
2,-14,-2:3
3,-14,-2:3
4,-14,-2:3
5,-14,-2:3
6,-14,-2:3
7,-14,-2:3
8,-14,-2:3
9,-14,-2:3
10,-14,-2:3
11,-14,-2:3
12,-14,-2:3
13,-14,-2:3
-12,-13,-2:3
-11,-13,-2:3
-10,-13,-2:3
-9,-13,-2:3
-8,-13,-2:3
-7,-13,-2:3
-6,-13,-2:3
-5,-13,-2:3
-4,-13,-2:3
-3,-13,-2:3
-2,-13,-2:3
-1,-13,-2:3
0,-13,-2:3
1,-13,-2:3
2,-13,-2:3
3,-13,-2:3
4,-13,-2:3
5,-13,-2:3
6,-13,-2:3
7,-13,-2:3
8,-13,-2:3
9,-13,-2:3
10,-13,-2:3
11,-13,-2:3
12,-13,-2:3
13,-13,-2:3
14,-13,-2:3
-13,-12,-2:3
-12,-12,-2:3
-11,-12,-2:3
-10,-12,-2:3
-9,-12,-2:3
-8,-12,-2:3
-7,-12,-2:3
-6,-12,-2:3
-5,-12,-2:3
-4,-12,-2:3
-3,-12,-2:3
-2,-12,-2:3
-1,-12,-2:3
0,-12,-2:3
1,-12,-2:3
2,-12,-2:3
3,-12,-2:3
4,-12,-2:3
5,-12,-2:3
6,-12,-2:3
7,-12,-2:3
8,-12,-2:3
9,-12,-2:3
10,-12,-2:3
11,-12,-2:3
12,-12,-2:3
13,-12,-2:3
14,-12,-2:3
15,-12,-2:3
-14,-11,-2:3
-13,-11,-2:3
-12,-11,-2:3
-11,-11,-2:3
-10,-11,-2:3
-9,-11,-2:3
-8,-11,-2:3
-7,-11,-2:3
-6,-11,-2:3
-5,-11,-2:3
-4,-11,-2:3
-3,-11,-2:3
-2,-11,-2:3
-1,-11,-2:3
0,-11,-2:3
1,-11,-2:3
2,-11,-2:3
3,-11,-2:3
4,-11,-2:3
5,-11,-2:3
6,-11,-2:3
7,-11,-2:3
8,-11,-2:3
9,-11,-2:3
10,-11,-2:3
11,-11,-2:3
12,-11,-2:3
13,-11,-2:3
14,-11,-2:3
15,-11,-2:3
-14,-10,-2:1
-13,-10,-2:3
-12,-10,-2:3
-11,-10,-2:3
-10,-10,-2:3
-9,-10,-2:3
-8,-10,-2:3
-7,-10,-2:3
-6,-10,-2:3
-5,-10,-2:3
-4,-10,-2:3
-3,-10,-2:3
-2,-10,-2:3
-1,-10,-2:3
0,-10,-2:3
1,-10,-2:3
2,-10,-2:3
3,-10,-2:3
4,-10,-2:3
5,-10,-2:3
6,-10,-2:3
7,-10,-2:3
8,-10,-2:3
9,-10,-2:3
10,-10,-2:3
11,-10,-2:3
12,-10,-2:3
13,-10,-2:3
14,-10,-2:3
15,-10,-2:3
-14,-9,-2:3
-13,-9,-2:3
-12,-9,-2:3
-11,-9,-2:3
-10,-9,-2:3
-9,-9,-2:3
-8,-9,-2:3
-7,-9,-2:3
-6,-9,-2:3
-5,-9,-2:3
-4,-9,-2:3
-3,-9,-2:98.0
-2,-9,-2:98.0
-1,-9,-2:98.0
0,-9,-2:98.0
1,-9,-2:98.0
2,-9,-2:98.0
3,-9,-2:98.0
4,-9,-2:98.0
5,-9,-2:98.0
6,-9,-2:98.0
7,-9,-2:98.0
8,-9,-2:98.0
9,-9,-2:98.0
10,-9,-2:3
11,-9,-2:3
12,-9,-2:3
13,-9,-2:3
14,-9,-2:3
15,-9,-2:3
-14,-8,-2:1
-13,-8,-2:3
-12,-8,-2:3
-11,-8,-2:3
-10,-8,-2:3
-9,-8,-2:3
-8,-8,-2:3
-7,-8,-2:3
-6,-8,-2:3
-5,-8,-2:3
-4,-8,-2:3
-3,-8,-2:98.0
-2,-8,-2:98.0
-1,-8,-2:98.0
0,-8,-2:98.0
1,-8,-2:98.0
2,-8,-2:98.1
3,-8,-2:98.1
4,-8,-2:98.1
5,-8,-2:98.1
6,-8,-2:98.1
7,-8,-2:98.1
8,-8,-2:98.0
9,-8,-2:98.0
10,-8,-2:3
11,-8,-2:3
12,-8,-2:3
13,-8,-2:3
14,-8,-2:3
15,-8,-2:3
-14,-7,-2:3
-13,-7,-2:3
-12,-7,-2:3
-11,-7,-2:3
-10,-7,-2:3
-9,-7,-2:3
-8,-7,-2:3
-7,-7,-2:3
-6,-7,-2:3
-5,-7,-2:3
-4,-7,-2:3
-3,-7,-2:98.0
-2,-7,-2:98.0
-1,-7,-2:98.0
0,-7,-2:98.0
1,-7,-2:98.0
2,-7,-2:98.1
3,-7,-2:98.1
4,-7,-2:98.1
5,-7,-2:98.1
6,-7,-2:98.1
7,-7,-2:98.0
8,-7,-2:98.0
9,-7,-2:98.0
10,-7,-2:3
11,-7,-2:3
12,-7,-2:3
13,-7,-2:3
14,-7,-2:3
15,-7,-2:3
-14,-6,-2:3
-13,-6,-2:3
-12,-6,-2:3
-11,-6,-2:3
-10,-6,-2:3
-9,-6,-2:3
-8,-6,-2:3
-7,-6,-2:98.0
-6,-6,-2:98.0
-5,-6,-2:98.0
-4,-6,-2:98.0
-3,-6,-2:98.0
-2,-6,-2:98.0
-1,-6,-2:98.0
0,-6,-2:98.0
1,-6,-2:98.0
2,-6,-2:98.0
3,-6,-2:98.0
4,-6,-2:98.0
5,-6,-2:98.0
6,-6,-2:98.0
7,-6,-2:98.0
8,-6,-2:98.0
9,-6,-2:98.0
10,-6,-2:3
11,-6,-2:3
12,-6,-2:3
13,-6,-2:3
14,-6,-2:3
15,-6,-2:3
-14,-5,-2:3
-13,-5,-2:3
-12,-5,-2:3
-11,-5,-2:3
-10,-5,-2:3
-9,-5,-2:3
-8,-5,-2:3
-7,-5,-2:98.0
-6,-5,-2:98.0
-5,-5,-2:98.0
-4,-5,-2:98.0
-3,-5,-2:98.0
-2,-5,-2:98.0
-1,-5,-2:98.0
0,-5,-2:98.0
1,-5,-2:98.0
2,-5,-2:98.0
3,-5,-2:98.0
4,-5,-2:98.0
5,-5,-2:98.0
6,-5,-2:98.0
7,-5,-2:98.0
8,-5,-2:17
9,-5,-2:98.0
10,-5,-2:3
11,-5,-2:3
12,-5,-2:3
13,-5,-2:3
14,-5,-2:3
15,-5,-2:3
-14,-4,-2:3
-13,-4,-2:3
-12,-4,-2:3
-11,-4,-2:3
-10,-4,-2:3
-9,-4,-2:3
-8,-4,-2:3
-7,-4,-2:98.0
-6,-4,-2:98.0
-5,-4,-2:98.0
-4,-4,-2:98.0
-3,-4,-2:98.0
-2,-4,-2:98.0
-1,-4,-2:98.0
0,-4,-2:98.0
1,-4,-2:98.0
2,-4,-2:98.0
3,-4,-2:98.0
4,-4,-2:98.0
5,-4,-2:98.0
6,-4,-2:98.0
7,-4,-2:3
8,-4,-2:3
9,-4,-2:98.0
10,-4,-2:3
11,-4,-2:3
12,-4,-2:3
13,-4,-2:3
14,-4,-2:3
15,-4,-2:3
-14,-3,-2:3
-13,-3,-2:3
-12,-3,-2:3
-11,-3,-2:3
-10,-3,-2:3
-9,-3,-2:3
-8,-3,-2:3
-7,-3,-2:98.0
-6,-3,-2:98.0
-5,-3,-2:98.0
-4,-3,-2:98.0
-3,-3,-2:98.0
-2,-3,-2:98.1
-1,-3,-2:98.1
0,-3,-2:98.0
1,-3,-2:98.0
2,-3,-2:98.0
3,-3,-2:98.0
4,-3,-2:98.0
5,-3,-2:98.1
6,-3,-2:98.1
7,-3,-2:98.0
8,-3,-2:98.0
9,-3,-2:98.0
10,-3,-2:3
11,-3,-2:3
12,-3,-2:3
13,-3,-2:3
14,-3,-2:3
15,-3,-2:3
-14,-2,-2:3
-13,-2,-2:3
-12,-2,-2:3
-11,-2,-2:3
-10,-2,-2:3
-9,-2,-2:3
-8,-2,-2:3
-7,-2,-2:98.0
-6,-2,-2:98.0
-5,-2,-2:98.0
-4,-2,-2:109.1
1,-2,-2:98.0
2,-2,-2:98.0
3,-2,-2:98.0
4,-2,-2:98.0
5,-2,-2:98.0
6,-2,-2:98.1
7,-2,-2:98.0
8,-2,-2:98.0
9,-2,-2:98.0
10,-2,-2:3
11,-2,-2:3
12,-2,-2:3
13,-2,-2:3
14,-2,-2:3
15,-2,-2:3
-14,-1,-2:3
-13,-1,-2:3
-12,-1,-2:3
-11,-1,-2:3
-10,-1,-2:3
-9,-1,-2:3
-8,-1,-2:3
-7,-1,-2:98.0
-6,-1,-2:98.0
-5,-1,-2:98.0
-4,-1,-2:109.1
0,-1,-2:30
1,-1,-2:98.0
2,-1,-2:98.0
3,-1,-2:98.1
4,-1,-2:98.1
5,-1,-2:98.0
6,-1,-2:98.0
7,-1,-2:98.0
8,-1,-2:98.0
9,-1,-2:98.0
10,-1,-2:3
11,-1,-2:3
12,-1,-2:3
13,-1,-2:3
14,-1,-2:3
15,-1,-2:3
-14,0,-2:3
-13,0,-2:3
-12,0,-2:3
-11,0,-2:3
-10,0,-2:3
-9,0,-2:3
-8,0,-2:3
-7,0,-2:98.0
-6,0,-2:98.0
-5,0,-2:98.0
-4,0,-2:98.0
-3,0,-2:98.0
-2,0,-2:98.0
-1,0,-2:98.0
0,0,-2:98.0
1,0,-2:98.0
2,0,-2:98.0
3,0,-2:98.0
4,0,-2:98.0
5,0,-2:98.0
6,0,-2:98.0
7,0,-2:98.0
8,0,-2:98.0
9,0,-2:98.0
10,0,-2:3
11,0,-2:3
12,0,-2:3
13,0,-2:3
14,0,-2:3
15,0,-2:3
-14,1,-2:3
-13,1,-2:3
-12,1,-2:3
-11,1,-2:3
-10,1,-2:3
-9,1,-2:3
-8,1,-2:3
-7,1,-2:98.0
-6,1,-2:98.0
-5,1,-2:18
-3,1,-2:98.0
-2,1,-2:98.0
-1,1,-2:98.0
0,1,-2:98.0
1,1,-2:98.1
2,1,-2:98.1
3,1,-2:98.0
4,1,-2:98.0
5,1,-2:98.0
6,1,-2:98.0
7,1,-2:98.0
8,1,-2:98.0
9,1,-2:98.0
10,1,-2:3
11,1,-2:3
12,1,-2:3
13,1,-2:3
14,1,-2:3
15,1,-2:3
-14,2,-2:3
-13,2,-2:3
-12,2,-2:3
-11,2,-2:3
-10,2,-2:3
-9,2,-2:3
-8,2,-2:3
-7,2,-2:98.0
-6,2,-2:17
-5,2,-2:18
-4,2,-2:98.0
-3,2,-2:98.0
-2,2,-2:98.0
-1,2,-2:98.0
0,2,-2:98.0
1,2,-2:98.1
2,2,-2:98.1
3,2,-2:98.0
4,2,-2:98.0
5,2,-2:98.0
6,2,-2:98.0
7,2,-2:98.0
8,2,-2:30
9,2,-2:98.0
10,2,-2:3
11,2,-2:3
12,2,-2:3
13,2,-2:3
14,2,-2:3
15,2,-2:3
-14,3,-2:3
-13,3,-2:3
-12,3,-2:3
-11,3,-2:3
-10,3,-2:3
-9,3,-2:3
-8,3,-2:3
-7,3,-2:98.0
-6,3,-2:98.0
-5,3,-2:98.0
-4,3,-2:98.1
-3,3,-2:98.0
-2,3,-2:98.0
-1,3,-2:98.0
0,3,-2:98.0
1,3,-2:98.0
2,3,-2:98.0
3,3,-2:98.0
4,3,-2:98.0
5,3,-2:98.0
6,3,-2:98.0
7,3,-2:98.0
8,3,-2:98.0
9,3,-2:98.0
10,3,-2:3
11,3,-2:3
12,3,-2:3
13,3,-2:3
14,3,-2:3
15,3,-2:3
-14,4,-2:3
-13,4,-2:3
-12,4,-2:3
-11,4,-2:3
-10,4,-2:3
-9,4,-2:3
-8,4,-2:3
-7,4,-2:98.0
-6,4,-2:98.0
-5,4,-2:98.0
-4,4,-2:98.1
-3,4,-2:98.0
-2,4,-2:98.1
-1,4,-2:98.0
0,4,-2:98.0
1,4,-2:98.1
2,4,-2:98.0
3,4,-2:98.0
4,4,-2:98.0
5,4,-2:98.0
6,4,-2:98.0
7,4,-2:98.0
8,4,-2:98.0
9,4,-2:98.0
10,4,-2:3
11,4,-2:3
12,4,-2:3
13,4,-2:3
14,4,-2:3
15,4,-2:3
-14,5,-2:3
-13,5,-2:3
-12,5,-2:3
-11,5,-2:3
-10,5,-2:3
-9,5,-2:3
-8,5,-2:3
-7,5,-2:98.0
-6,5,-2:98.0
-5,5,-2:98.0
-4,5,-2:98.0
-3,5,-2:98.1
-2,5,-2:98.0
-1,5,-2:98.0
0,5,-2:98.1
1,5,-2:98.1
2,5,-2:98.0
3,5,-2:98.0
4,5,-2:98.0
5,5,-2:98.0
6,5,-2:98.0
7,5,-2:98.0
8,5,-2:98.0
9,5,-2:98.0
10,5,-2:3
11,5,-2:3
12,5,-2:3
13,5,-2:3
14,5,-2:3
15,5,-2:3
-14,6,-2:3
-13,6,-2:3
-12,6,-2:3
-11,6,-2:3
-10,6,-2:3
-9,6,-2:3
-8,6,-2:3
-7,6,-2:98.0
-6,6,-2:98.0
-5,6,-2:98.0
-4,6,-2:98.0
-3,6,-2:98.0
-2,6,-2:98.0
-1,6,-2:98.0
0,6,-2:98.0
1,6,-2:98.0
2,6,-2:98.0
3,6,-2:98.0
4,6,-2:98.0
5,6,-2:98.0
6,6,-2:98.0
7,6,-2:98.0
8,6,-2:98.0
9,6,-2:98.0
10,6,-2:3
11,6,-2:3
12,6,-2:3
13,6,-2:3
14,6,-2:3
15,6,-2:3
-14,7,-2:3
-13,7,-2:3
-12,7,-2:3
-11,7,-2:3
-10,7,-2:3
-9,7,-2:3
-8,7,-2:3
-7,7,-2:98.0
-6,7,-2:98.0
-5,7,-2:98.0
-4,7,-2:98.0
-3,7,-2:98.0
-2,7,-2:98.0
-1,7,-2:98.0
0,7,-2:98.0
1,7,-2:98.0
2,7,-2:98.0
3,7,-2:98.0
4,7,-2:98.0
5,7,-2:98.0
6,7,-2:98.0
7,7,-2:98.0
8,7,-2:98.0
9,7,-2:98.0
10,7,-2:3
11,7,-2:3
12,7,-2:3
13,7,-2:3
14,7,-2:3
15,7,-2:3
-14,8,-2:3
-13,8,-2:3
-12,8,-2:3
-11,8,-2:3
-10,8,-2:3
-9,8,-2:3
-8,8,-2:3
-7,8,-2:3
-6,8,-2:3
-5,8,-2:3
-4,8,-2:3
-3,8,-2:3
-2,8,-2:3
2,8,-2:3
3,8,-2:3
4,8,-2:3
5,8,-2:3
6,8,-2:3
7,8,-2:3
8,8,-2:3
9,8,-2:3
10,8,-2:3
11,8,-2:3
12,8,-2:3
13,8,-2:3
14,8,-2:3
15,8,-2:3
-14,9,-2:3
-13,9,-2:3
-12,9,-2:3
-10,9,-2:3
-9,9,-2:3
-8,9,-2:3
-7,9,-2:3
-6,9,-2:3
-5,9,-2:3
-4,9,-2:3
-3,9,-2:3
-2,9,-2:3
-1,9,-2:3
0,9,-2:3
1,9,-2:3
2,9,-2:3
3,9,-2:3
4,9,-2:3
5,9,-2:3
6,9,-2:3
7,9,-2:3
8,9,-2:3
9,9,-2:3
10,9,-2:3
11,9,-2:3
12,9,-2:3
13,9,-2:3
14,9,-2:3
15,9,-2:3
-13,10,-2:3
-12,10,-2:3
-11,10,-2:3
-10,10,-2:3
-9,10,-2:3
-8,10,-2:3
-7,10,-2:3
-6,10,-2:3
-5,10,-2:3
-4,10,-2:3
-3,10,-2:3
-2,10,-2:3
-1,10,-2:3
0,10,-2:3
1,10,-2:3
2,10,-2:3
3,10,-2:3
4,10,-2:3
5,10,-2:3
6,10,-2:3
7,10,-2:3
8,10,-2:3
9,10,-2:3
10,10,-2:3
11,10,-2:3
12,10,-2:3
13,10,-2:3
14,10,-2:3
15,10,-2:3
-13,11,-2:3
-12,11,-2:3
-10,11,-2:3
-8,11,-2:3
-7,11,-2:3
-6,11,-2:3
-5,11,-2:3
-4,11,-2:3
-3,11,-2:3
-2,11,-2:3
-1,11,-2:3
0,11,-2:3
4,11,-2:3
5,11,-2:3
6,11,-2:3
7,11,-2:3
8,11,-2:3
9,11,-2:3
10,11,-2:3
11,11,-2:3
12,11,-2:3
13,11,-2:3
14,11,-2:3
15,11,-2:3
-12,12,-2:1
-11,12,-2:3
-10,12,-2:3
-9,12,-2:3
-8,12,-2:3
-7,12,-2:3
-6,12,-2:3
-5,12,-2:3
-4,12,-2:3
-3,12,-2:3
-2,12,-2:3
-1,12,-2:3
0,12,-2:3
1,12,-2:3
2,12,-2:3
3,12,-2:3
4,12,-2:3
5,12,-2:3
6,12,-2:3
7,12,-2:3
8,12,-2:3
9,12,-2:3
10,12,-2:3
11,12,-2:3
12,12,-2:3
13,12,-2:3
14,12,-2:3
-11,13,-2:3
-10,13,-2:3
-9,13,-2:3
-8,13,-2:3
-7,13,-2:3
-6,13,-2:3
-5,13,-2:3
-4,13,-2:3
-3,13,-2:3
-2,13,-2:3
-1,13,-2:3
0,13,-2:3
1,13,-2:3
2,13,-2:3
3,13,-2:3
4,13,-2:3
5,13,-2:3
6,13,-2:3
7,13,-2:3
8,13,-2:3
9,13,-2:3
10,13,-2:3
11,13,-2:3
12,13,-2:3
13,13,-2:3
-2,-1,-2:106
-3,-2,-2:0
-2,-2,-2:0
-3,-1,-2:0
-1,-2,-2:0
-1,-1,-2:0
0,-2,-2:0
-4,1,-2:0
-9,-16,-1:2
-8,-16,-1:2
-7,-16,-1:2
-6,-16,-1:2
-5,-16,-1:2
-4,-16,-1:2
-3,-16,-1:2
-2,-16,-1:2
-1,-16,-1:2
0,-16,-1:2
1,-16,-1:2
2,-16,-1:2
3,-16,-1:2
4,-16,-1:2
5,-16,-1:2
6,-16,-1:2
7,-16,-1:2
8,-16,-1:2
9,-16,-1:2
10,-16,-1:2
11,-16,-1:2
12,-16,-1:2
-11,-15,-1:2
-10,-15,-1:2
-9,-15,-1:2
-8,-15,-1:2
-7,-15,-1:2
-6,-15,-1:3
-5,-15,-1:2
-4,-15,-1:2
-3,-15,-1:2
-2,-15,-1:98.0
-1,-15,-1:2
0,-15,-1:2
1,-15,-1:3
2,-15,-1:3
3,-15,-1:2
4,-15,-1:2
5,-15,-1:2
6,-15,-1:2
7,-15,-1:2
8,-15,-1:2
9,-15,-1:2
10,-15,-1:2
11,-15,-1:2
12,-15,-1:2
13,-15,-1:2
-12,-14,-1:2
-11,-14,-1:98.0
-10,-14,-1:2
-9,-14,-1:2
-8,-14,-1:98.0
-7,-14,-1:2
-6,-14,-1:2
-5,-14,-1:2
-4,-14,-1:17.1
-3,-14,-1:2
-2,-14,-1:2
-1,-14,-1:2
0,-14,-1:3
1,-14,-1:3
2,-14,-1:3
3,-14,-1:98.0
4,-14,-1:3
5,-14,-1:2
6,-14,-1:2
7,-14,-1:2
8,-14,-1:2
9,-14,-1:2
10,-14,-1:2
11,-14,-1:2
12,-14,-1:2
13,-14,-1:2
14,-14,-1:2
-13,-13,-1:2
-12,-13,-1:2
-11,-13,-1:17.1
-10,-13,-1:2
-9,-13,-1:2
-8,-13,-1:2
-7,-13,-1:2
-6,-13,-1:2
-5,-13,-1:2
-4,-13,-1:2
-3,-13,-1:3
-2,-13,-1:3
-1,-13,-1:3
0,-13,-1:3
1,-13,-1:3
2,-13,-1:3
3,-13,-1:3
4,-13,-1:3
5,-13,-1:2
6,-13,-1:2
7,-13,-1:3
8,-13,-1:3
9,-13,-1:3
10,-13,-1:2
11,-13,-1:2
12,-13,-1:2
13,-13,-1:2
14,-13,-1:2
-14,-12,-1:2
-13,-12,-1:2
-12,-12,-1:2
-11,-12,-1:3
-10,-12,-1:3
-9,-12,-1:2
-8,-12,-1:2
-7,-12,-1:2
-6,-12,-1:98.2
-5,-12,-1:2
-4,-12,-1:2
-3,-12,-1:3
-2,-12,-1:3
-1,-12,-1:3
0,-12,-1:3
1,-12,-1:3
2,-12,-1:3
3,-12,-1:3
4,-12,-1:3
5,-12,-1:2
6,-12,-1:3
7,-12,-1:3
8,-12,-1:3
9,-12,-1:3
10,-12,-1:3
11,-12,-1:3
12,-12,-1:2
13,-12,-1:2
14,-12,-1:98.1
15,-12,-1:2
-15,-11,-1:2
-14,-11,-1:2
-13,-11,-1:2
-12,-11,-1:98.1
-11,-11,-1:3
-10,-11,-1:3
-9,-11,-1:3
-8,-11,-1:3
-7,-11,-1:3
-6,-11,-1:3
-5,-11,-1:3
-4,-11,-1:3
-3,-11,-1:3
-2,-11,-1:3
-1,-11,-1:3
0,-11,-1:3
1,-11,-1:3
2,-11,-1:3
3,-11,-1:3
4,-11,-1:3
5,-11,-1:3
6,-11,-1:3
7,-11,-1:3
8,-11,-1:3
9,-11,-1:3
10,-11,-1:3
11,-11,-1:3
12,-11,-1:3
13,-11,-1:2
14,-11,-1:2
15,-11,-1:98.1
16,-11,-1:2
-15,-10,-1:2
-14,-10,-1:2
-13,-10,-1:3
-12,-10,-1:3
-11,-10,-1:3
-10,-10,-1:3
-9,-10,-1:3
-8,-10,-1:3
-7,-10,-1:3
-6,-10,-1:3
-5,-10,-1:3
-4,-10,-1:3
-3,-10,-1:3
-2,-10,-1:3
-1,-10,-1:3
0,-10,-1:3
1,-10,-1:3
2,-10,-1:3
3,-10,-1:3
4,-10,-1:3
5,-10,-1:3
6,-10,-1:3
7,-10,-1:3
8,-10,-1:3
9,-10,-1:3
10,-10,-1:3
11,-10,-1:3
12,-10,-1:3
13,-10,-1:3
14,-10,-1:2
15,-10,-1:2
16,-10,-1:2
-15,-9,-1:2
-14,-9,-1:2
-13,-9,-1:2
-12,-9,-1:3
-11,-9,-1:3
-10,-9,-1:3
-9,-9,-1:3
-8,-9,-1:3
-7,-9,-1:3
-6,-9,-1:3
-5,-9,-1:3
-4,-9,-1:3
-3,-9,-1:3
-2,-9,-1:3
-1,-9,-1:3
0,-9,-1:3
1,-9,-1:3
2,-9,-1:3
3,-9,-1:3
4,-9,-1:3
5,-9,-1:3
6,-9,-1:3
7,-9,-1:3
8,-9,-1:3
9,-9,-1:3
10,-9,-1:3
11,-9,-1:3
12,-9,-1:3
13,-9,-1:3
14,-9,-1:3
15,-9,-1:2
16,-9,-1:2
-15,-8,-1:2
-14,-8,-1:2
-13,-8,-1:2
-12,-8,-1:2
-11,-8,-1:3
-10,-8,-1:3
-9,-8,-1:3
-8,-8,-1:3
-7,-8,-1:3
-6,-8,-1:3
-5,-8,-1:3
-4,-8,-1:3
-3,-8,-1:3
-2,-8,-1:3
-1,-8,-1:3
0,-8,-1:3
1,-8,-1:3
2,-8,-1:3
3,-8,-1:3
4,-8,-1:3
5,-8,-1:3
6,-8,-1:3
7,-8,-1:3
8,-8,-1:3
9,-8,-1:3
10,-8,-1:3
11,-8,-1:3
12,-8,-1:3
13,-8,-1:3
14,-8,-1:3
15,-8,-1:2
16,-8,-1:2
-15,-7,-1:2
-14,-7,-1:2
-13,-7,-1:2
-12,-7,-1:2
-11,-7,-1:2
-10,-7,-1:3
-9,-7,-1:3
-8,-7,-1:3
-7,-7,-1:3
-6,-7,-1:3
-5,-7,-1:3
-4,-7,-1:3
-3,-7,-1:3
-2,-7,-1:3
-1,-7,-1:3
0,-7,-1:3
1,-7,-1:3
2,-7,-1:3
3,-7,-1:3
4,-7,-1:3
5,-7,-1:3
6,-7,-1:3
7,-7,-1:3
8,-7,-1:3
9,-7,-1:3
10,-7,-1:3
11,-7,-1:3
12,-7,-1:3
13,-7,-1:3
14,-7,-1:3
15,-7,-1:3
16,-7,-1:2
-15,-6,-1:2
-14,-6,-1:2
-13,-6,-1:2
-12,-6,-1:17.1
-11,-6,-1:3
-10,-6,-1:3
-9,-6,-1:3
-8,-6,-1:3
-7,-6,-1:3
-6,-6,-1:3
-5,-6,-1:3
-4,-6,-1:3
-3,-6,-1:3
-2,-6,-1:3
-1,-6,-1:3
0,-6,-1:3
1,-6,-1:3
2,-6,-1:3
3,-6,-1:3
4,-6,-1:3
5,-6,-1:3
6,-6,-1:3
7,-6,-1:3
8,-6,-1:3
9,-6,-1:3
10,-6,-1:3
11,-6,-1:3
12,-6,-1:3
13,-6,-1:3
14,-6,-1:3
15,-6,-1:2
16,-6,-1:2
-15,-5,-1:2
-14,-5,-1:2
-13,-5,-1:2
-12,-5,-1:3
-11,-5,-1:3
-10,-5,-1:3
-9,-5,-1:3
-8,-5,-1:3
-7,-5,-1:3
-6,-5,-1:3
-5,-5,-1:3
-4,-5,-1:3
-3,-5,-1:3
-2,-5,-1:3
-1,-5,-1:3
0,-5,-1:3
1,-5,-1:3
2,-5,-1:3
3,-5,-1:3
4,-5,-1:3
5,-5,-1:3
6,-5,-1:3
7,-5,-1:3
8,-5,-1:3
9,-5,-1:3
10,-5,-1:3
11,-5,-1:3
12,-5,-1:3
13,-5,-1:3
14,-5,-1:3
15,-5,-1:3
16,-5,-1:2
-15,-4,-1:2
-14,-4,-1:2
-13,-4,-1:2
-12,-4,-1:3
-11,-4,-1:3
-10,-4,-1:3
-9,-4,-1:3
-8,-4,-1:3
-7,-4,-1:3
-6,-4,-1:3
-5,-4,-1:3
-4,-4,-1:3
-3,-4,-1:3
-2,-4,-1:3
-1,-4,-1:3
0,-4,-1:3
1,-4,-1:3
2,-4,-1:3
3,-4,-1:3
4,-4,-1:3
5,-4,-1:3
6,-4,-1:3
7,-4,-1:3
8,-4,-1:3
9,-4,-1:3
10,-4,-1:3
11,-4,-1:3
12,-4,-1:3
13,-4,-1:3
14,-4,-1:98.0
15,-4,-1:2
16,-4,-1:2
-15,-3,-1:2
-14,-3,-1:2
-13,-3,-1:2
-12,-3,-1:3
-11,-3,-1:3
-10,-3,-1:3
-9,-3,-1:3
-8,-3,-1:3
-7,-3,-1:3
-6,-3,-1:98.0
-5,-3,-1:98.0
-4,-3,-1:98.0
-3,-3,-1:98.1
-2,-3,-1:98.0
-1,-3,-1:98.0
0,-3,-1:3
1,-3,-1:3
2,-3,-1:3
3,-3,-1:3
4,-3,-1:3
5,-3,-1:3
6,-3,-1:3
7,-3,-1:3
8,-3,-1:3
9,-3,-1:3
10,-3,-1:3
11,-3,-1:3
12,-3,-1:3
13,-3,-1:3
14,-3,-1:98.0
15,-3,-1:2
16,-3,-1:2
-15,-2,-1:2
-14,-2,-1:2
-13,-2,-1:2
-12,-2,-1:3
-11,-2,-1:3
-10,-2,-1:3
-9,-2,-1:3
-8,-2,-1:3
-7,-2,-1:3
-6,-2,-1:98.0
-5,-2,-1:109.1
0,-2,-1:98.1
1,-2,-1:3
2,-2,-1:3
3,-2,-1:3
4,-2,-1:3
5,-2,-1:3
6,-2,-1:3
7,-2,-1:3
8,-2,-1:3
9,-2,-1:3
10,-2,-1:3
11,-2,-1:3
12,-2,-1:3
13,-2,-1:3
14,-2,-1:98.1
15,-2,-1:2
16,-2,-1:2
-15,-1,-1:2
-14,-1,-1:2
-13,-1,-1:2
-12,-1,-1:3
-11,-1,-1:3
-10,-1,-1:3
-9,-1,-1:3
-8,-1,-1:3
-7,-1,-1:3
-6,-1,-1:98.0
-5,-1,-1:109.1
0,-1,-1:98.1
1,-1,-1:3
2,-1,-1:3
3,-1,-1:3
4,-1,-1:3
5,-1,-1:3
6,-1,-1:3
7,-1,-1:3
8,-1,-1:3
9,-1,-1:3
10,-1,-1:3
11,-1,-1:3
12,-1,-1:3
13,-1,-1:3
14,-1,-1:98.0
15,-1,-1:2
16,-1,-1:2
-15,0,-1:2
-14,0,-1:2
-13,0,-1:2
-12,0,-1:3
-11,0,-1:3
-10,0,-1:3
-9,0,-1:3
-8,0,-1:3
-7,0,-1:3
-6,0,-1:98.0
-5,0,-1:98.0
-4,0,-1:98.0
-3,0,-1:98.1
-2,0,-1:98.0
-1,0,-1:98.0
0,0,-1:98.0
1,0,-1:98.0
2,0,-1:98.0
3,0,-1:3
4,0,-1:3
5,0,-1:3
6,0,-1:3
7,0,-1:3
8,0,-1:3
9,0,-1:3
10,0,-1:3
11,0,-1:3
12,0,-1:3
13,0,-1:3
14,0,-1:98.0
15,0,-1:98.1
16,0,-1:2
-15,1,-1:2
-14,1,-1:2
-13,1,-1:2
-12,1,-1:3
-11,1,-1:3
-10,1,-1:3
-9,1,-1:3
-8,1,-1:3
-7,1,-1:3
-6,1,-1:98.1
-5,1,-1:98.1
-4,1,-1:98.0
-3,1,-1:98.1
-2,1,-1:98.1
-1,1,-1:98.1
0,1,-1:98.1
1,1,-1:98.0
2,1,-1:98.0
3,1,-1:98.0
4,1,-1:3
5,1,-1:3
6,1,-1:3
7,1,-1:3
8,1,-1:3
9,1,-1:3
10,1,-1:3
11,1,-1:3
12,1,-1:3
13,1,-1:3
14,1,-1:98.0
15,1,-1:98.0
16,1,-1:2
-15,2,-1:2
-14,2,-1:2
-13,2,-1:2
-12,2,-1:3
-11,2,-1:3
-10,2,-1:3
-9,2,-1:3
-8,2,-1:3
-7,2,-1:3
-6,2,-1:17
-5,2,-1:98.0
-4,2,-1:98.1
-3,2,-1:98.1
-2,2,-1:98.1
-1,2,-1:98.1
0,2,-1:98.0
1,2,-1:98.1
2,2,-1:98.0
3,2,-1:3
4,2,-1:3
5,2,-1:3
6,2,-1:3
7,2,-1:3
8,2,-1:98.0
9,2,-1:3
10,2,-1:3
11,2,-1:3
12,2,-1:3
13,2,-1:3
14,2,-1:3
15,2,-1:3
16,2,-1:2
-15,3,-1:2
-14,3,-1:2
-13,3,-1:2
-12,3,-1:3
-11,3,-1:3
-10,3,-1:3
-9,3,-1:3
-8,3,-1:3
-7,3,-1:3
-6,3,-1:3
-5,3,-1:3
-4,3,-1:3
-3,3,-1:3
-2,3,-1:3
-1,3,-1:3
0,3,-1:3
1,3,-1:3
2,3,-1:3
3,3,-1:3
4,3,-1:3
5,3,-1:3
6,3,-1:3
7,3,-1:3
8,3,-1:3
9,3,-1:3
10,3,-1:3
11,3,-1:3
12,3,-1:2
13,3,-1:2
14,3,-1:2
15,3,-1:2
16,3,-1:2
-15,4,-1:2
-14,4,-1:2
-13,4,-1:2
-12,4,-1:2
-11,4,-1:2
-10,4,-1:3
-9,4,-1:3
-8,4,-1:3
-7,4,-1:3
-6,4,-1:3
-5,4,-1:3
-4,4,-1:3
-3,4,-1:3
-2,4,-1:3
-1,4,-1:3
0,4,-1:3
1,4,-1:3
2,4,-1:3
3,4,-1:3
4,4,-1:3
5,4,-1:3
6,4,-1:3
7,4,-1:3
8,4,-1:3
9,4,-1:3
10,4,-1:3
11,4,-1:3
12,4,-1:2
13,4,-1:2
14,4,-1:2
15,4,-1:2
16,4,-1:2
-15,5,-1:2
-14,5,-1:2
-13,5,-1:2
-12,5,-1:2
-11,5,-1:3
-10,5,-1:3
-9,5,-1:3
-8,5,-1:3
-7,5,-1:3
-6,5,-1:3
-5,5,-1:3
-4,5,-1:3
-3,5,-1:3
-2,5,-1:3
-1,5,-1:3
0,5,-1:3
1,5,-1:3
2,5,-1:3
3,5,-1:3
4,5,-1:3
5,5,-1:3
6,5,-1:3
7,5,-1:3
8,5,-1:3
9,5,-1:3
10,5,-1:3
11,5,-1:3
12,5,-1:2
13,5,-1:2
14,5,-1:2
15,5,-1:2
16,5,-1:2
-15,6,-1:2
-14,6,-1:2
-13,6,-1:2
-12,6,-1:3
-11,6,-1:3
-10,6,-1:3
-9,6,-1:3
-8,6,-1:3
-7,6,-1:3
-6,6,-1:3
-5,6,-1:3
-4,6,-1:3
-3,6,-1:3
-2,6,-1:3
-1,6,-1:3
0,6,-1:3
1,6,-1:3
2,6,-1:3
3,6,-1:3
4,6,-1:3
5,6,-1:3
6,6,-1:3
7,6,-1:3
8,6,-1:3
9,6,-1:3
10,6,-1:3
11,6,-1:3
12,6,-1:17.1
13,6,-1:2
14,6,-1:2
15,6,-1:2
16,6,-1:2
-15,7,-1:2
-14,7,-1:2
-13,7,-1:3
-12,7,-1:3
-11,7,-1:3
-10,7,-1:3
-9,7,-1:3
-8,7,-1:3
-7,7,-1:3
-6,7,-1:3
-5,7,-1:3
-4,7,-1:3
-3,7,-1:3
-2,7,-1:3
-1,7,-1:3
0,7,-1:3
1,7,-1:3
2,7,-1:3
3,7,-1:3
4,7,-1:3
5,7,-1:3
6,7,-1:3
7,7,-1:3
8,7,-1:3
9,7,-1:3
10,7,-1:3
11,7,-1:3
12,7,-1:3
13,7,-1:2
14,7,-1:2
15,7,-1:2
16,7,-1:2
-15,8,-1:2
-14,8,-1:2
-13,8,-1:2
-12,8,-1:3
-11,8,-1:3
-10,8,-1:3
-9,8,-1:3
-8,8,-1:3
-7,8,-1:3
-6,8,-1:3
-5,8,-1:3
-4,8,-1:3
-3,8,-1:3
-2,8,-1:3
-1,8,-1:3
0,8,-1:3
1,8,-1:3
2,8,-1:3
3,8,-1:3
4,8,-1:3
5,8,-1:3
6,8,-1:3
7,8,-1:3
8,8,-1:3
9,8,-1:3
10,8,-1:3
11,8,-1:3
12,8,-1:3
13,8,-1:2
14,8,-1:2
15,8,-1:2
16,8,-1:2
-15,9,-1:2
-14,9,-1:2
-13,9,-1:2
-12,9,-1:2
-11,9,-1:2
-10,9,-1:3
-9,9,-1:3
-8,9,-1:17.0
-7,9,-1:2
-6,9,-1:2
-5,9,-1:3
-4,9,-1:3
-3,9,-1:3
-2,9,-1:3
-1,9,-1:3
0,9,-1:3
1,9,-1:3
2,9,-1:3
3,9,-1:3
4,9,-1:3
5,9,-1:3
6,9,-1:2
7,9,-1:2
8,9,-1:2
9,9,-1:2
10,9,-1:2
11,9,-1:3
12,9,-1:2
13,9,-1:2
14,9,-1:2
15,9,-1:2
16,9,-1:2
-14,10,-1:2
-13,10,-1:2
-12,10,-1:2
-11,10,-1:2
-10,10,-1:2
-9,10,-1:2
-8,10,-1:2
-7,10,-1:2
-6,10,-1:2
-5,10,-1:3
-4,10,-1:3
-3,10,-1:3
-2,10,-1:3
-1,10,-1:3
0,10,-1:3
1,10,-1:3
2,10,-1:3
3,10,-1:3
4,10,-1:3
5,10,-1:17.1
6,10,-1:2
7,10,-1:2
8,10,-1:2
9,10,-1:2
10,10,-1:2
11,10,-1:2
12,10,-1:17.1
13,10,-1:2
14,10,-1:2
15,10,-1:2
16,10,-1:2
-13,11,-1:2
-12,11,-1:2
-11,11,-1:2
-10,11,-1:2
-9,11,-1:2
-8,11,-1:2
-7,11,-1:2
-6,11,-1:2
-5,11,-1:2
-4,11,-1:3
-3,11,-1:3
-2,11,-1:3
-1,11,-1:3
0,11,-1:2
1,11,-1:2
2,11,-1:2
3,11,-1:2
4,11,-1:2
5,11,-1:2
6,11,-1:2
7,11,-1:2
8,11,-1:2
9,11,-1:2
10,11,-1:2
11,11,-1:2
12,11,-1:2
13,11,-1:2
14,11,-1:2
15,11,-1:2
-12,12,-1:2
-11,12,-1:2
-10,12,-1:2
-9,12,-1:2
-8,12,-1:2
-7,12,-1:2
-6,12,-1:2
-5,12,-1:2
-4,12,-1:3
-3,12,-1:3
-2,12,-1:3
-1,12,-1:2
0,12,-1:2
1,12,-1:2
2,12,-1:2
3,12,-1:98.1
4,12,-1:2
5,12,-1:2
6,12,-1:2
7,12,-1:2
8,12,-1:2
9,12,-1:2
10,12,-1:2
11,12,-1:2
12,12,-1:2
13,12,-1:2
14,12,-1:2
-11,13,-1:2
-10,13,-1:2
-9,13,-1:2
-8,13,-1:2
-7,13,-1:2
-6,13,-1:2
-5,13,-1:2
-4,13,-1:2
-3,13,-1:2
-2,13,-1:2
-1,13,-1:2
0,13,-1:2
1,13,-1:2
2,13,-1:2
3,13,-1:2
4,13,-1:2
5,13,-1:2
6,13,-1:2
7,13,-1:2
8,13,-1:2
9,13,-1:2
10,13,-1:2
11,13,-1:2
12,13,-1:2
13,13,-1:2
-9,14,-1:2
-8,14,-1:2
-7,14,-1:2
-6,14,-1:2
-5,14,-1:2
-4,14,-1:2
-3,14,-1:2
-2,14,-1:2
-1,14,-1:2
0,14,-1:2
1,14,-1:2
2,14,-1:2
3,14,-1:2
4,14,-1:2
5,14,-1:2
6,14,-1:2
7,14,-1:2
8,14,-1:2
9,14,-1:2
10,14,-1:2
11,14,-1:2
12,14,-1:2
-2,-1,-1:106
-4,-2,-1:0
-4,-1,-1:0
-3,-1,-1:0
-3,-2,-1:0
-2,-2,-1:0
-1,-1,-1:0
-1,-2,-1:0
-3,-15,1:18
2,-15,1:18
-4,-14,1:18
-3,-14,1:17.1
-2,-14,1:18
1,-14,1:18
2,-14,1:18
3,-14,1:18
-11,-13,1:18
-10,-13,1:18
-4,-13,1:18
-3,-13,1:98.1
-2,-13,1:18
0,-13,1:18
1,-13,1:2
2,-13,1:3
3,-13,1:18
4,-13,1:98.1
8,-13,1:17.0
-11,-12,1:44.5
-10,-12,1:98.0
-9,-12,1:44.5
-4,-12,1:44.5
-3,-12,1:98.1
-2,-12,1:98.0
-1,-12,1:98.0
0,-12,1:98.1
1,-12,1:98.0
2,-12,1:98.0
3,-12,1:98.0
4,-12,1:98.0
5,-12,1:44.5
7,-12,1:2
8,-12,1:2
10,-12,1:44.5
11,-12,1:98.1
12,-12,1:44.5
-11,-11,1:98.0
-10,-11,1:98.0
-9,-11,1:98.0
-8,-11,1:98.0
-7,-11,1:98.1
-6,-11,1:98.0
-5,-11,1:98.0
-4,-11,1:98.0
3,-11,1:98.1
4,-11,1:98.0
5,-11,1:98.0
6,-11,1:98.0
7,-11,1:98.0
8,-11,1:98.0
9,-11,1:98.0
10,-11,1:98.0
11,-11,1:98.0
12,-11,1:98.1
-11,-10,1:44.5
-10,-10,1:98.0
-9,-10,1:98.0
-2,-10,1:98.1
-1,-10,1:98.1
0,-10,1:98.2
10,-10,1:98.0
11,-10,1:98.0
12,-10,1:44.5
-11,-9,1:2
-10,-9,1:98.0
-3,-9,1:98.1
-2,-9,1:98.1
-1,-9,1:98.1
0,-9,1:109.1
11,-9,1:98.0
12,-9,1:2
-10,-8,1:98.1
-6,-8,1:109.2
-3,-8,1:98.1
-2,-8,1:98.1
-1,-8,1:98.1
0,-8,1:109.1
11,-8,1:98.1
12,-8,1:3
13,-8,1:2
-12,-7,1:18
-11,-7,1:18
-10,-7,1:98.0
-7,-7,1:109.0
-6,-7,1:98.0
-5,-7,1:109.1
-3,-7,1:98.0
-2,-7,1:98.0
-1,-7,1:98.0
0,-7,1:44.5
7,-7,1:98.1
11,-7,1:98.1
12,-7,1:3
13,-7,1:2
-13,-6,1:18
-12,-6,1:17.1
-11,-6,1:44.5
-10,-6,1:98.1
-6,-6,1:109.3
-3,-6,1:98.1
-2,-6,1:98.1
-1,-6,1:98.1
0,-6,1:109.1
11,-6,1:98.0
12,-6,1:3
13,-6,1:2
-12,-5,1:98.0
-11,-5,1:98.0
-3,-5,1:98.1
-2,-5,1:98.1
-1,-5,1:98.1
0,-5,1:109.1
11,-5,1:44.5
12,-5,1:98.1
13,-5,1:98.1
14,-5,1:23.5
-11,-4,1:98.0
-2,-4,1:98.1
-1,-4,1:98.1
0,-4,1:98.2
12,-4,1:109.3
-11,-3,1:98.1
-9,-3,1:98.0
-6,-3,1:98.1
-4,-3,1:109.0
-1,-3,1:98.0
1,-3,1:98.2
2,-3,1:98.1
3,-3,1:98.0
4,-3,1:98.2
-11,-2,1:98.0
-9,-2,1:54
-1,-2,1:98.1
1,-2,1:98.0
2,-2,1:98.1
3,-2,1:98.0
4,-2,1:98.1
8,-2,1:44.5
-11,-1,1:98.1
-9,-1,1:54
-1,-1,1:98.0
1,-1,1:98.0
2,-1,1:98.1
3,-1,1:98.0
4,-1,1:98.0
10,-1,1:98.1
-11,0,1:98.0
-9,0,1:98.0
-6,0,1:98.0
-4,0,1:109.0
-1,0,1:98.0
1,0,1:98.2
2,0,1:98.0
3,0,1:98.1
4,0,1:98.2
-11,1,1:98.0
-2,1,1:98.1
-1,1,1:98.0
0,1,1:98.0
12,1,1:109.2
-12,2,1:98.0
-11,2,1:98.1
-6,2,1:17
-3,2,1:98.1
-2,2,1:98.0
-1,2,1:98.0
0,2,1:109.1
11,2,1:44.5
12,2,1:98.0
13,2,1:98.1
14,2,1:23.5
-13,3,1:18
-12,3,1:18
-11,3,1:44.5
-10,3,1:98.0
-6,3,1:109.2
-3,3,1:98.1
-2,3,1:98.0
-1,3,1:98.0
0,3,1:109.1
11,3,1:98.0
12,3,1:44.5
-11,4,1:18
-10,4,1:98.0
-7,4,1:109.0
-6,4,1:98.0
-5,4,1:109.1
-3,4,1:98.1
-2,4,1:98.0
-1,4,1:98.0
0,4,1:109.1
7,4,1:98.1
11,4,1:98.0
-10,5,1:98.1
-6,5,1:109.3
-3,5,1:98.1
-2,5,1:98.0
-1,5,1:98.0
0,5,1:44.5
11,5,1:98.1
12,5,1:18
-11,6,1:2
-10,6,1:98.1
-3,6,1:98.1
-2,6,1:98.0
-1,6,1:98.0
0,6,1:109.1
11,6,1:98.0
12,6,1:18
-12,7,1:2
-11,7,1:3
-10,7,1:98.0
-9,7,1:98.0
-2,7,1:98.1
-1,7,1:98.2
0,7,1:98.0
10,7,1:98.0
11,7,1:98.0
12,7,1:44.5
-11,8,1:98.0
-10,8,1:98.0
-9,8,1:98.0
-8,8,1:98.0
-7,8,1:98.0
-6,8,1:98.1
-5,8,1:98.0
-4,8,1:98.0
3,8,1:98.1
4,8,1:98.0
5,8,1:98.1
6,8,1:98.1
7,8,1:98.1
8,8,1:98.1
9,8,1:98.0
10,8,1:98.0
11,8,1:98.0
12,8,1:98.1
-11,9,1:44.5
-10,9,1:98.0
-9,9,1:44.5
-8,9,1:17.0
-7,9,1:18
-4,9,1:44.5
-3,9,1:98.0
-2,9,1:98.0
-1,9,1:98.0
0,9,1:98.0
1,9,1:98.1
2,9,1:98.0
3,9,1:98.0
4,9,1:98.1
5,9,1:44.5
10,9,1:44.5
11,9,1:98.1
12,9,1:44.5
-8,10,1:18
-7,10,1:18
-3,10,1:98.0
4,10,1:98.1
5,10,1:18
6,10,1:18
11,10,1:18
12,10,1:18
13,10,1:18
-3,11,1:2
5,11,1:18
12,11,1:18
12,12,1:106.4
-2,12,1:31.1
-3,12,1:31.1
-4,12,1:31.1
13,11,1:106.2
4,11,1:106.4
-2,11,1:31.1
-4,11,1:31.1
-8,11,1:106.4
-10,11,1:106.4
1,10,1:106.4
0,10,1:106.4
-2,10,1:106.4
-4,10,1:31.1
-5,10,1:31.1
-11,10,1:106
8,9,1:106.4
-5,9,1:31.1
-6,9,1:106.4
-12,9,1:106.8
13,8,1:106.2
2,8,1:106.1
1,8,1:106.1
0,8,1:106.1
-2,8,1:106.2
6,7,1:106.1
3,7,1:106.1
-4,7,1:106.8
7,6,1:106.1
3,6,1:106.1
-4,6,1:106.8
-9,6,1:106.2
-12,6,1:31.1
4,5,1:106.1
3,5,1:106.1
-5,5,1:106.8
-9,5,1:106.2
-11,5,1:31.1
12,4,1:106.2
10,4,1:106.8
6,4,1:106.8
-12,4,1:106.4
7,3,1:106.1
-5,3,1:106.8
9,2,1:106.8
-13,2,1:106.8
13,1,1:106.2
10,1,1:106.8
-3,1,1:106.8
10,0,1:106.8
0,0,1:106.2
-7,0,1:106.8
13,-1,1:106.2
5,-1,1:106.2
-2,-1,1:106.8
-7,-1,1:106.1
-8,-1,1:106.1
-2,-2,1:106.8
-6,-2,1:106.4
-10,-2,1:106.2
13,-3,1:106.2
10,-3,1:106.8
0,-3,1:106.2
-8,-3,1:106
10,-4,1:106.8
9,-4,1:106.8
2,-4,1:106.1
-6,-4,1:106.1
-12,-4,1:106.8
-13,-5,1:106.8
14,-6,1:31.1
-9,-6,1:106.2
14,-7,1:37
10,-7,1:106.8
4,-7,1:106.4
-9,-7,1:106.2
14,-8,1:31.1
9,-8,1:106.8
7,-8,1:106.4
6,-8,1:106.4
5,-8,1:106.4
-11,-8,1:106.8
14,-9,1:31.1
13,-9,1:31.1
-12,-9,1:31.1
13,-10,1:31.1
9,-10,1:106.4
4,-10,1:106.4
3,-10,1:106.4
-12,-10,1:31.1
-13,-10,1:31.1
13,-11,1:106.2
1,-11,1:106.4
-1,-11,1:106
-12,-11,1:31.1
9,-12,1:31.1
6,-12,1:37
-5,-12,1:106.1
-6,-12,1:106.1
-7,-12,1:106.1
-8,-12,1:106.1
11,-13,1:106.1
9,-13,1:31.1
-1,-13,1:106.1
7,-14,1:106.1
0,-14,1:31.1
3,-15,1:106
1,-15,1:31.1
2,-16,1:106.1
-3,-2,1:0
-4,-2,1:0
-5,-2,1:0
-5,-1,1:0
-4,-1,1:0
-3,-1,1:0
-6,-1,1:0
-5,-3,1:0
-5,-4,1:0
-4,-4,1:0
-3,-4,1:0
-3,-3,1:0
-2,-3,1:0
-2,0,1:0
-3,0,1:0
-5,0,1:0
-5,1,1:0
-4,1,1:0
2,-15,2:18
-4,-14,2:18
-3,-14,2:18
1,-14,2:18
2,-14,2:18
3,-14,2:18
-11,-13,2:18
-3,-13,2:98.0
-2,-13,2:18
0,-13,2:18
1,-13,2:18
2,-13,2:17.0
3,-13,2:18
4,-13,2:98.1
8,-13,2:17.0
-11,-12,2:44.5
-10,-12,2:98.2
-9,-12,2:44.5
-4,-12,2:44.5
-3,-12,2:98.1
-2,-12,2:98.0
-1,-12,2:98.0
0,-12,2:98.1
1,-12,2:98.1
2,-12,2:98.0
3,-12,2:98.0
4,-12,2:98.0
5,-12,2:44.5
10,-12,2:44.5
11,-12,2:98.2
12,-12,2:44.5
-11,-11,2:98.2
-10,-11,2:98.0
-9,-11,2:98.0
-8,-11,2:98.0
-7,-11,2:98.1
-6,-11,2:98.1
-5,-11,2:98.0
-4,-11,2:98.0
3,-11,2:98.1
4,-11,2:98.1
5,-11,2:98.0
6,-11,2:98.0
7,-11,2:98.1
8,-11,2:98.0
9,-11,2:98.0
10,-11,2:98.0
11,-11,2:98.0
12,-11,2:98.2
-11,-10,2:44.5
-10,-10,2:98.0
-9,-10,2:98.0
-2,-10,2:98.1
-1,-10,2:98.2
10,-10,2:98.0
11,-10,2:98.0
12,-10,2:44.5
-10,-9,2:98.0
-3,-9,2:98.1
-2,-9,2:98.1
-1,-9,2:109.1
11,-9,2:98.0
-10,-8,2:98.1
-3,-8,2:98.0
-2,-8,2:98.0
-1,-8,2:44.5
11,-8,2:98.0
12,-8,2:2
-12,-7,2:18
-10,-7,2:98.1
-6,-7,2:98.0
-3,-7,2:98.0
-2,-7,2:98.0
7,-7,2:98.1
11,-7,2:98.1
12,-7,2:17.0
13,-7,2:18
-13,-6,2:18
-12,-6,2:18
-11,-6,2:44.5
-10,-6,2:98.0
-3,-6,2:98.0
-2,-6,2:98.1
-1,-6,2:109.1
11,-6,2:98.1
12,-6,2:44.5
-12,-5,2:98.0
-11,-5,2:98.0
-3,-5,2:98.0
-2,-5,2:98.0
-1,-5,2:109.1
11,-5,2:43.5
12,-5,2:98.1
13,-5,2:98.0
14,-5,2:109.1
-11,-4,2:98.1
-2,-4,2:98.0
-1,-4,2:98.2
11,-4,2:44
12,-4,2:44
-11,-3,2:98.1
-9,-3,2:98.0
-6,-3,2:98.1
-5,-3,2:44.5
-4,-3,2:98.2
-1,-3,2:98.0
1,-3,2:98.2
2,-3,2:98.0
3,-3,2:98.1
4,-3,2:98.2
-11,-2,2:98.1
-4,-2,2:44.5
-1,-2,2:98.1
1,-2,2:98.0
2,-2,2:98.1
3,-2,2:98.0
4,-2,2:98.0
-11,-1,2:98.0
-4,-1,2:44.5
-1,-1,2:98.0
1,-1,2:98.0
2,-1,2:98.1
3,-1,2:98.0
4,-1,2:98.0
-11,0,2:98.0
-9,0,2:98.0
-6,0,2:98.0
-5,0,2:44.5
-4,0,2:98.2
-1,0,2:98.1
1,0,2:98.2
2,0,2:98.1
3,0,2:98.0
4,0,2:98.2
-11,1,2:98.0
-6,1,2:18
-2,1,2:98.0
-1,1,2:98.2
11,1,2:44
12,1,2:44
-12,2,2:98.1
-11,2,2:98.1
-7,2,2:18
-6,2,2:17
-5,2,2:18
-3,2,2:98.0
-2,2,2:98.0
-1,2,2:44.5
11,2,2:43.5
12,2,2:98.0
13,2,2:98.1
14,2,2:109.1
-12,3,2:18
-11,3,2:44.5
-10,3,2:98.0
-6,3,2:18
-3,3,2:98.1
-2,3,2:98.0
-1,3,2:44.5
11,3,2:98.0
12,3,2:44.5
-10,4,2:98.1
-6,4,2:98.0
-3,4,2:98.1
-2,4,2:98.0
-1,4,2:109.1
7,4,2:98.0
11,4,2:98.1
-10,5,2:98.1
-3,5,2:98.0
-2,5,2:98.0
-1,5,2:109.1
11,5,2:98.1
-10,6,2:98.1
-3,6,2:98.0
-2,6,2:98.0
-1,6,2:109.1
11,6,2:98.1
12,6,2:18
-11,7,2:2
-10,7,2:98.0
-9,7,2:98.0
-2,7,2:98.1
-1,7,2:98.2
10,7,2:98.0
11,7,2:98.0
12,7,2:44.5
-11,8,2:98.2
-10,8,2:98.0
-9,8,2:98.0
-8,8,2:98.1
-7,8,2:98.1
-6,8,2:98.1
-5,8,2:98.1
-4,8,2:98.0
3,8,2:98.1
4,8,2:98.0
5,8,2:98.0
6,8,2:98.1
7,8,2:98.1
8,8,2:98.0
9,8,2:98.0
10,8,2:98.0
11,8,2:98.0
12,8,2:98.2
-11,9,2:44.5
-10,9,2:98.2
-9,9,2:44.5
-8,9,2:17.0
-7,9,2:18
-4,9,2:44.5
-3,9,2:98.0
-2,9,2:98.0
-1,9,2:98.0
0,9,2:98.1
1,9,2:98.0
2,9,2:98.0
3,9,2:98.0
4,9,2:98.1
5,9,2:44.5
10,9,2:44.5
11,9,2:98.2
12,9,2:44.5
-8,10,2:18
-3,10,2:98.0
4,10,2:98.1
5,10,2:18
12,10,2:18
4,11,2:106.4
-3,11,2:106.4
-8,11,2:106.4
-9,11,2:106.4
-10,11,2:106.4
1,10,2:106.4
0,10,2:106.4
-2,10,2:106.4
-11,10,2:106
8,9,2:106.4
-5,9,2:106.4
-6,9,2:106.4
-12,9,2:106.8
13,8,2:106.2
2,8,2:106.1
1,8,2:106.1
0,8,2:106.1
-2,8,2:106.2
6,7,2:106.1
3,7,2:106.1
-4,7,2:106.8
-6,7,2:106.1
7,6,2:106.1
3,6,2:106.1
-4,6,2:106.8
-9,6,2:106.2
12,5,2:106.2
4,5,2:106.1
3,5,2:106.1
-5,5,2:106.8
-9,5,2:106.2
12,4,2:106.2
10,4,2:106.8
6,4,2:106.8
-7,4,2:106.8
-12,4,2:106.4
7,3,2:106.1
-5,3,2:106.8
-13,3,2:106.8
9,2,2:106.8
-13,2,2:106.8
13,1,2:106.2
10,1,2:106.8
-3,1,2:106.8
10,0,2:106.8
0,0,2:106.2
-7,0,2:106.8
13,-1,2:106.2
10,-1,2:106.8
5,-1,2:106.2
-2,-1,2:106.8
-7,-1,2:106.1
-8,-1,2:106.1
-10,-1,2:106.2
-2,-2,2:106.8
-6,-2,2:106.4
-10,-2,2:106.2
13,-3,2:106.2
10,-3,2:106.8
0,-3,2:106.2
-8,-3,2:106
10,-4,2:106.8
9,-4,2:106.8
2,-4,2:106.1
-6,-4,2:106.1
-12,-4,2:106.8
-13,-5,2:106.8
7,-6,2:106.4
-9,-6,2:106.2
10,-7,2:106.8
8,-7,2:106.2
4,-7,2:106.4
-9,-7,2:106.2
13,-8,2:31.1
9,-8,2:106.8
7,-8,2:106.4
6,-8,2:106.4
5,-8,2:106.4
-11,-8,2:106.8
12,-9,2:31.1
8,-9,2:106.4
7,-9,2:106.4
-11,-9,2:106.8
9,-10,2:106.4
8,-10,2:106.4
4,-10,2:106.4
3,-10,2:106.4
13,-11,2:106.2
1,-11,2:106.4
-1,-11,2:106.2
-12,-11,2:106.8
8,-12,2:31.1
7,-12,2:31.1
-5,-12,2:106.1
-6,-12,2:106.1
-7,-12,2:106.1
11,-13,2:106
-1,-13,2:106.1
-10,-13,2:106.1
7,-14,2:106.1
3,-15,2:106.1
2,-16,2:106.1
2,-14,3:18
8,-14,3:18
-11,-13,3:18
-3,-13,3:98.1
1,-13,3:18
2,-13,3:17.0
3,-13,3:18
4,-13,3:98.1
7,-13,3:18
8,-13,3:17.0
9,-13,3:18
-11,-12,3:44.5
-10,-12,3:98.0
-9,-12,3:44.5
-4,-12,3:44.5
-3,-12,3:98.0
-2,-12,3:98.0
-1,-12,3:98.0
0,-12,3:98.1
1,-12,3:98.1
2,-12,3:98.1
3,-12,3:98.0
4,-12,3:98.0
5,-12,3:44.5
8,-12,3:18
10,-12,3:44.5
11,-12,3:98.1
12,-12,3:44.5
-11,-11,3:98.0
-10,-11,3:98.0
-9,-11,3:98.0
-8,-11,3:98.2
-7,-11,3:98.1
-6,-11,3:98.0
-5,-11,3:98.2
-4,-11,3:98.0
-3,-11,3:98.0
-2,-11,3:98.0
3,-11,3:98.0
4,-11,3:98.1
5,-11,3:98.0
6,-11,3:98.2
7,-11,3:98.1
8,-11,3:98.0
9,-11,3:98.2
10,-11,3:98.0
11,-11,3:98.0
12,-11,3:98.1
-11,-10,3:44.5
-10,-10,3:98.0
-9,-10,3:98.0
-3,-10,3:98.1
-2,-10,3:98.2
10,-10,3:98.0
11,-10,3:98.0
12,-10,3:44.5
-10,-9,3:98.0
-3,-9,3:98.1
-2,-9,3:109.1
11,-9,3:98.1
-10,-8,3:98.2
-3,-8,3:98.1
-2,-8,3:109.1
11,-8,3:98.2
12,-8,3:18
13,-8,3:18
-10,-7,3:98.0
-6,-7,3:98.0
-3,-7,3:98.0
-2,-7,3:44.5
7,-7,3:98.1
11,-7,3:98.1
12,-7,3:17.0
13,-7,3:18
-12,-6,3:18
-11,-6,3:44.5
-10,-6,3:98.0
-3,-6,3:98.1
-2,-6,3:109.1
11,-6,3:98.1
12,-6,3:44.5
13,-6,3:18
-12,-5,3:98.0
-11,-5,3:98.0
-3,-5,3:98.1
-2,-5,3:109.1
11,-5,3:98.2
12,-5,3:98.0
13,-5,3:23.5
-11,-4,3:98.0
-3,-4,3:30
-2,-4,3:98.2
-1,-4,3:98.0
11,-4,3:109
12,-4,3:109
-11,-3,3:98.0
-9,-3,3:98.1
-6,-3,3:98.0
-4,-3,3:109
-1,-3,3:98.1
2,-3,3:98.0
3,-3,3:109.1
-11,-2,3:98.0
-1,-2,3:98.1
-11,-1,3:98.1
-1,-1,3:98.0
2,-1,3:98.0
3,-1,3:109.1
-11,0,3:98.0
-9,0,3:98.0
-6,0,3:98.1
-4,0,3:109
-1,0,3:98.0
3,0,3:113
-11,1,3:98.0
-6,1,3:18
-2,1,3:98.2
-1,1,3:98.0
11,1,3:109
12,1,3:109
-12,2,3:98.0
-11,2,3:98.0
-10,2,3:30
-7,2,3:18
-6,2,3:17
-5,2,3:18
-3,2,3:98.0
-2,2,3:109.1
11,2,3:98.2
12,2,3:98.0
13,2,3:23.5
-11,3,3:44.5
-10,3,3:98.0
-6,3,3:18
-3,3,3:98.0
-2,3,3:109.1
11,3,3:98.0
12,3,3:44.5
-10,4,3:98.1
-6,4,3:98.0
-3,4,3:98.1
-2,4,3:44.5
7,4,3:98.0
11,4,3:98.0
-10,5,3:98.2
-3,5,3:98.0
-2,5,3:109.1
11,5,3:98.2
-10,6,3:98.0
-3,6,3:98.0
-2,6,3:109.1
11,6,3:98.1
-11,7,3:44.5
-10,7,3:98.0
-9,7,3:98.0
-3,7,3:98.1
-2,7,3:98.2
10,7,3:98.0
11,7,3:98.0
12,7,3:44.5
-11,8,3:98.1
-10,8,3:98.0
-9,8,3:98.0
-8,8,3:98.2
-7,8,3:98.1
-6,8,3:98.1
-5,8,3:98.2
-4,8,3:98.0
-3,8,3:98.1
3,8,3:98.1
4,8,3:98.0
5,8,3:98.0
6,8,3:98.2
7,8,3:98.0
8,8,3:98.1
9,8,3:98.2
10,8,3:98.0
11,8,3:98.0
12,8,3:98.0
-11,9,3:44.5
-10,9,3:98.1
-9,9,3:44.5
-8,9,3:17.0
-7,9,3:18
-4,9,3:44.5
-3,9,3:98.0
-2,9,3:98.0
-1,9,3:98.0
0,9,3:98.1
1,9,3:98.1
2,9,3:98.0
3,9,3:98.0
4,9,3:98.0
5,9,3:44.5
10,9,3:44.5
11,9,3:98.0
12,9,3:44.5
-8,10,3:18
-3,10,3:98.1
4,10,3:98.1
4,11,3:106.4
-3,11,3:106.4
-8,11,3:106.4
-9,11,3:106.4
-10,11,3:106.4
1,10,3:106.4
0,10,3:106.4
-2,10,3:106.4
-11,10,3:106
8,9,3:106.4
-5,9,3:106.4
-6,9,3:106.4
-12,9,3:106.8
13,8,3:106.2
2,8,3:106.1
1,8,3:106.1
0,8,3:106.1
-2,8,3:106.2
6,7,3:106.1
3,7,3:106.1
0,7,3:106.1
-4,7,3:106.8
-6,7,3:106.1
7,6,3:106.1
6,6,3:106.1
5,6,3:106.1
3,6,3:106.1
-1,6,3:106.1
-4,6,3:106.8
-9,6,3:106.2
12,5,3:106.2
4,5,3:106.1
3,5,3:106.1
-5,5,3:106.8
-9,5,3:106.2
12,4,3:106.2
10,4,3:106.8
6,4,3:106.8
-7,4,3:106.8
7,3,3:106.1
-5,3,3:106.8
10,2,3:106.8
9,2,3:106.8
-13,2,3:106.8
13,1,3:106.2
10,1,3:106.8
-3,1,3:106.8
13,0,3:106.2
10,0,3:106.8
0,0,3:106.2
-7,0,3:106.8
13,-1,3:106.2
10,-1,3:106.8
-2,-1,3:106.8
-7,-1,3:106.1
-8,-1,3:106.1
-10,-1,3:106.2
-2,-2,3:106.8
-6,-2,3:106.4
-10,-2,3:106.2
13,-3,3:106.2
10,-3,3:106.8
8,-3,3:106.8
0,-3,3:106.2
-8,-3,3:106
10,-4,3:106.8
9,-4,3:106.8
2,-4,3:106.1
-6,-4,3:106.1
-12,-4,3:106.8
14,-5,3:106.2
8,-5,3:106.8
-13,-5,3:106.8
15,-6,3:106.2
7,-6,3:106.4
-9,-6,3:106.2
10,-7,3:106.8
9,-7,3:106.8
8,-7,3:106.2
4,-7,3:106.4
-9,-7,3:106.2
-11,-7,3:106.8
9,-8,3:106.8
7,-8,3:106.4
6,-8,3:106.4
5,-8,3:106.4
4,-8,3:106.4
-11,-8,3:106.8
12,-9,3:106.2
8,-9,3:106.4
7,-9,3:106.4
-11,-9,3:106.8
9,-10,3:106.4
8,-10,3:106.4
4,-10,3:106.4
3,-10,3:106.4
0,-10,3:106.4
13,-11,3:106.2
1,-11,3:106.4
-1,-11,3:106.2
-12,-11,3:106.8
-5,-12,3:106.1
-6,-12,3:106.1
11,-13,3:106
0,-13,3:106.1
-1,-13,3:106.1
-10,-13,3:106.1
7,-14,3:106.1
3,-14,3:106.1
1,-14,3:106.1
-3,-14,3:106.1
2,-15,3:106.1
2,-14,4:18
8,-14,4:18
9,-14,4:18
-3,-13,4:98.0
1,-13,4:18
2,-13,4:18
3,-13,4:18
4,-13,4:109.2
7,-13,4:18
8,-13,4:18
9,-13,4:18
10,-13,4:18
-11,-12,4:44.5
-10,-12,4:98.0
-9,-12,4:44.5
-4,-12,4:44.5
-3,-12,4:98.0
-2,-12,4:98.0
-1,-12,4:98.0
0,-12,4:98.1
1,-12,4:98.0
2,-12,4:98.0
3,-12,4:98.1
4,-12,4:98.0
5,-12,4:44.5
7,-12,4:18
8,-12,4:17.0
9,-12,4:18
10,-12,4:44.5
11,-12,4:98.1
12,-12,4:44.5
-11,-11,4:98.0
-10,-11,4:98.0
-9,-11,4:98.0
-8,-11,4:98.0
-7,-11,4:98.1
-6,-11,4:98.1
-5,-11,4:98.0
-4,-11,4:98.0
-3,-11,4:98.0
-2,-11,4:98.0
3,-11,4:98.0
4,-11,4:98.1
5,-11,4:98.1
6,-11,4:98.0
7,-11,4:98.1
8,-11,4:98.0
9,-11,4:98.0
10,-11,4:98.0
11,-11,4:98.0
12,-11,4:98.1
-11,-10,4:44.5
-10,-10,4:98.0
-9,-10,4:98.0
-8,-10,4:109
-5,-10,4:109
-4,-10,4:98.0
-3,-10,4:98.2
10,-10,4:98.0
11,-10,4:98.0
12,-10,4:44.5
-10,-9,4:98.0
-9,-9,4:30
-4,-9,4:98.0
-3,-9,4:109.1
11,-9,4:98.1
-10,-8,4:98.0
-6,-8,4:109
-4,-8,4:98.0
-3,-8,4:109.1
11,-8,4:98.1
12,-8,4:18
-10,-7,4:98.1
-7,-7,4:109
-6,-7,4:98.0
-4,-7,4:98.0
-3,-7,4:109.1
7,-7,4:98.1
11,-7,4:98.1
12,-7,4:17.0
13,-7,4:18
-11,-6,4:44.5
-10,-6,4:98.0
-6,-6,4:30
-4,-6,4:98.0
-3,-6,4:44.5
11,-6,4:98.0
12,-6,4:44.5
13,-6,4:18
-12,-5,4:109.0
-11,-5,4:98.0
-10,-5,4:98.0
-4,-5,4:98.0
-3,-5,4:109.1
11,-5,4:98.1
12,-5,4:98.0
13,-5,4:109.1
-11,-4,4:98.1
-10,-4,4:98.0
-9,-4,4:109
-4,-4,4:98.0
-3,-4,4:98.2
-2,-4,4:109.2
-1,-4,4:44.5
11,-4,4:98.0
12,-4,4:98.0
-11,-3,4:109.0
-10,-3,4:98.0
-9,-3,4:98.1
-6,-3,4:98.0
-4,-3,4:109.0
-3,-3,4:98.2
-2,-3,4:98.0
-1,-3,4:109.1
2,-3,4:98.0
11,-3,4:109
12,-3,4:109
-11,-2,4:98.0
-10,-2,4:98.0
-4,-2,4:98.1
-3,-2,4:98.1
-2,-2,4:98.1
-1,-2,4:109.1
-11,-1,4:98.0
-10,-1,4:98.0
-4,-1,4:98.0
-3,-1,4:98.0
-2,-1,4:98.1
-1,-1,4:109.1
2,-1,4:98.1
-11,0,4:44.5
-10,0,4:98.0
-9,0,4:98.1
-6,0,4:98.0
-4,0,4:109.0
-3,0,4:98.0
-2,0,4:98.0
-1,0,4:109.1
3,0,4:113
11,0,4:109
12,0,4:109
-11,1,4:98.0
-10,1,4:98.0
-9,1,4:109
-6,1,4:18
-4,1,4:98.0
-3,1,4:98.2
-2,1,4:109.3
-1,1,4:44.5
11,1,4:98.0
12,1,4:98.1
-12,2,4:109.0
-11,2,4:98.0
-10,2,4:98.0
-7,2,4:18
-6,2,4:17
-5,2,4:18
-4,2,4:98.0
-3,2,4:109.1
11,2,4:98.0
12,2,4:98.0
13,2,4:109.1
-11,3,4:44.5
-10,3,4:98.0
-6,3,4:18
-4,3,4:98.0
-3,3,4:109.1
11,3,4:98.0
12,3,4:44.5
-10,4,4:98.1
-6,4,4:98.0
-4,4,4:98.0
-3,4,4:109.1
7,4,4:98.0
11,4,4:98.0
-10,5,4:98.1
-6,5,4:109
-4,5,4:98.0
-3,5,4:109.1
11,5,4:98.0
-10,6,4:98.1
-4,6,4:98.0
-3,6,4:109.1
11,6,4:98.1
-11,7,4:44.5
-10,7,4:98.0
-9,7,4:98.0
-8,7,4:30
-4,7,4:98.0
-3,7,4:98.2
10,7,4:98.0
11,7,4:98.0
12,7,4:44.5
-11,8,4:98.0
-10,8,4:98.0
-9,8,4:98.0
-8,8,4:98.0
-7,8,4:98.0
-6,8,4:98.1
-5,8,4:98.0
-4,8,4:98.0
-3,8,4:98.0
-2,8,4:98.0
-1,8,4:98.0
0,8,4:98.1
1,8,4:98.0
2,8,4:98.0
3,8,4:98.0
4,8,4:98.0
5,8,4:98.0
6,8,4:98.0
7,8,4:98.0
8,8,4:98.1
9,8,4:98.0
10,8,4:98.0
11,8,4:98.0
12,8,4:98.0
-11,9,4:44.5
-10,9,4:98.0
-9,9,4:44.5
-8,9,4:17.0
-7,9,4:18
-4,9,4:44.5
-3,9,4:98.0
-2,9,4:98.1
-1,9,4:109.3
0,9,4:98.0
1,9,4:109.3
2,9,4:98.0
3,9,4:98.0
4,9,4:98.0
5,9,4:44.5
10,9,4:44.5
12,9,4:44.5
-8,10,4:18
-3,10,4:109.3
4,10,4:109.3
-8,11,4:106.4
-9,11,4:106.4
-10,11,4:106.4
0,10,4:106.4
-2,10,4:106.4
-11,10,4:106
8,9,4:106.4
-6,9,4:106.4
-12,9,4:106.8
13,8,4:106.2
6,7,4:106.1
3,7,4:106.1
0,7,4:106.1
-1,7,4:106.1
-2,7,4:106.1
-6,7,4:106.1
7,6,4:106.1
6,6,4:106.1
5,6,4:106.1
3,6,4:106.1
-1,6,4:106.1
-9,6,4:106.2
12,5,4:106.2
4,5,4:106.1
3,5,4:106.1
-5,5,4:106.8
-9,5,4:106.2
12,4,4:106.2
10,4,4:106.8
6,4,4:106.8
-7,4,4:106.8
7,3,4:106.1
-5,3,4:106.8
10,2,4:106.8
9,2,4:106.8
13,1,4:106.2
10,1,4:106.8
13,0,4:106.2
10,0,4:106.8
2,0,4:106.4
-7,0,4:106.8
13,-1,4:106.2
10,-1,4:106.8
-7,-1,4:106.1
-8,-1,4:106.1
9,-2,4:106.8
8,-2,4:106.8
3,-2,4:106.2
-6,-2,4:106.4
-8,-2,4:106.4
13,-3,4:106.2
10,-3,4:106.8
8,-3,4:106.8
3,-3,4:106.2
-8,-3,4:106
10,-4,4:106.8
9,-4,4:106.8
2,-4,4:106.1
-6,-4,4:106.1
-12,-4,4:106.8
14,-5,4:106.2
8,-5,4:106.8
15,-6,4:106.2
8,-6,4:106.8
7,-6,4:106.4
-9,-6,4:106.2
10,-7,4:106.8
9,-7,4:106.8
8,-7,4:106.2
4,-7,4:106.4
-9,-7,4:106.2
-11,-7,4:106.8
9,-8,4:106.8
7,-8,4:106.4
6,-8,4:106.4
5,-8,4:106.4
4,-8,4:106.4
-11,-8,4:106.8
12,-9,4:106.2
8,-9,4:106.4
7,-9,4:106.4
-11,-9,4:106.8
9,-10,4:106.4
8,-10,4:106.4
4,-10,4:106.4
3,-10,4:106.4
0,-10,4:106.4
13,-11,4:106.2
1,-11,4:106.4
-1,-11,4:106.2
-12,-11,4:106.8
-5,-12,4:106.1
-6,-12,4:106.1
11,-13,4:106
0,-13,4:106.1
-1,-13,4:106.1
-10,-13,4:106.1
7,-14,4:106.1
3,-14,4:106.1
1,-14,4:106.1
2,-15,4:106.1
9,-14,5:18
2,-13,5:18
7,-13,5:18
8,-13,5:18
9,-13,5:18
10,-13,5:18
-10,-12,5:109.2
-3,-12,5:109.2
4,-12,5:109.2
6,-12,5:18
7,-12,5:18
8,-12,5:17.0
9,-12,5:18
10,-12,5:18
11,-12,5:109.2
-11,-11,5:109.0
-10,-11,5:98.0
-9,-11,5:98.0
-8,-11,5:98.0
-7,-11,5:98.0
-6,-11,5:98.0
-5,-11,5:98.0
-4,-11,5:98.0
-3,-11,5:98.0
-2,-11,5:98.0
-1,-11,5:98.0
0,-11,5:98.1
1,-11,5:98.1
2,-11,5:98.0
3,-11,5:98.0
4,-11,5:98.0
5,-11,5:98.0
6,-11,5:98.1
7,-11,5:98.0
8,-11,5:98.0
9,-11,5:98.0
10,-11,5:98.0
11,-11,5:98.0
12,-11,5:109.1
-10,-10,5:98.0
-9,-10,5:98.0
-8,-10,5:98.0
-7,-10,5:98.0
-6,-10,5:98.0
-5,-10,5:98.0
-4,-10,5:98.2
10,-10,5:98.0
11,-10,5:98.0
-10,-9,5:98.0
-9,-9,5:98.0
-8,-9,5:98.1
-7,-9,5:98.0
-6,-9,5:98.0
-5,-9,5:98.0
-4,-9,5:109.1
10,-9,5:30
11,-9,5:98.1
-10,-8,5:98.0
-9,-8,5:98.0
-8,-8,5:98.0
-7,-8,5:98.0
-6,-8,5:98.0
-5,-8,5:98.0
11,-8,5:98.1
12,-8,5:18
13,-8,5:18
-10,-7,5:98.0
-9,-7,5:98.0
-8,-7,5:98.0
-7,-7,5:98.0
-6,-7,5:98.0
-5,-7,5:98.0
-4,-7,5:109.1
7,-7,5:98.1
11,-7,5:98.0
12,-7,5:17.0
13,-7,5:18
14,-7,5:18
-10,-6,5:98.0
-9,-6,5:98.0
-8,-6,5:98.1
-7,-6,5:98.1
-6,-6,5:98.1
-5,-6,5:98.1
-4,-6,5:109.1
11,-6,5:98.0
12,-6,5:17.0
13,-6,5:18
-11,-5,5:109.0
-10,-5,5:98.0
-9,-5,5:98.0
-8,-5,5:98.1
-7,-5,5:98.0
-6,-5,5:98.0
-5,-5,5:98.1
-4,-5,5:109.1
11,-5,5:98.1
12,-5,5:44.5
-10,-4,5:98.0
-9,-4,5:98.0
-8,-4,5:98.0
-7,-4,5:98.1
-6,-4,5:98.0
-5,-4,5:98.0
-4,-4,5:98.2
11,-4,5:98.0
12,-4,5:43.5
-10,-3,5:98.1
-9,-3,5:98.0
-6,-3,5:98.0
-5,-3,5:98.0
-4,-3,5:98.1
-3,-3,5:109.1
2,-3,5:98.0
11,-3,5:98.0
12,-3,5:98.1
-10,-2,5:98.1
-5,-2,5:98.0
2,-2,5:44
11,-2,5:109
12,-2,5:109
-10,-1,5:98.1
-6,-1,5:30
-5,-1,5:98.0
2,-1,5:98.1
11,-1,5:109
12,-1,5:109
-10,0,5:98.0
-9,0,5:98.0
-6,0,5:98.0
-5,0,5:98.0
-4,0,5:98.1
-3,0,5:109.1
3,0,5:113
11,0,5:98.0
12,0,5:98.1
-10,1,5:98.0
-9,1,5:98.0
-8,1,5:98.0
-7,1,5:98.0
-6,1,5:98.0
-5,1,5:98.0
-4,1,5:98.2
11,1,5:98.0
12,1,5:98.0
-11,2,5:109.0
-10,2,5:98.0
-9,2,5:98.0
-8,2,5:98.0
-7,2,5:98.0
-6,2,5:98.0
-5,2,5:98.0
-4,2,5:109.1
11,2,5:98.1
12,2,5:44.5
-10,3,5:98.0
-9,3,5:98.0
-8,3,5:98.0
-7,3,5:98.0
-6,3,5:98.0
-5,3,5:98.0
-4,3,5:109.1
11,3,5:98.0
-10,4,5:98.0
-9,4,5:98.0
-8,4,5:98.0
-7,4,5:98.0
-6,4,5:98.0
-5,4,5:98.0
-4,4,5:109.1
7,4,5:98.0
11,4,5:98.0
-10,5,5:98.1
-9,5,5:98.0
-8,5,5:98.0
-7,5,5:98.0
-6,5,5:98.0
-5,5,5:98.0
-4,5,5:44.5
11,5,5:98.0
-10,6,5:98.0
-9,6,5:98.0
-8,6,5:98.0
-7,6,5:98.0
-6,6,5:98.0
-5,6,5:98.0
-4,6,5:109.1
10,6,5:30
11,6,5:98.0
-10,7,5:98.0
-9,7,5:98.0
-8,7,5:98.0
-7,7,5:98.0
-6,7,5:98.0
-5,7,5:98.0
-4,7,5:98.2
10,7,5:98.0
11,7,5:98.0
-11,8,5:109.0
-10,8,5:98.0
-9,8,5:98.0
-8,8,5:98.0
-7,8,5:98.0
-6,8,5:98.1
-5,8,5:98.0
-4,8,5:98.0
-3,8,5:98.0
-2,8,5:98.0
-1,8,5:98.1
0,8,5:98.1
1,8,5:98.1
2,8,5:98.0
3,8,5:98.0
4,8,5:98.0
5,8,5:98.0
6,8,5:98.0
7,8,5:98.0
8,8,5:98.0
9,8,5:98.0
10,8,5:98.0
11,8,5:98.0
12,8,5:109.1
-10,9,5:109.3
-9,9,5:17.0
-8,9,5:18
-3,9,5:109.3
4,9,5:109.3
11,9,5:109.3
-9,10,5:18
-8,11,5:106.4
-9,11,5:106.4
-10,11,5:106.4
-11,10,5:106
8,9,5:106.4
2,9,5:106.4
0,9,5:106.4
-1,9,5:106.4
-6,9,5:106.4
-12,9,5:106.8
-12,8,5:106.8
12,7,5:106.2
6,7,5:106.1
3,7,5:106.1
0,7,5:106.1
-1,7,5:106.1
-2,7,5:106.1
7,6,5:106.1
6,6,5:106.1
5,6,5:106.1
3,6,5:106.1
-1,6,5:106.1
4,5,5:106.1
3,5,5:106.1
1,5,5:106.1
12,4,5:106.2
6,4,5:106.8
12,3,5:106.2
7,3,5:106.1
10,2,5:106.8
9,2,5:106.8
13,1,5:106.2
10,1,5:106.8
-11,1,5:106.8
13,0,5:106.2
10,0,5:106.8
2,0,5:106.4
-7,0,5:106.8
-11,0,5:106.8
13,-1,5:106.2
10,-1,5:106.8
-4,-1,5:106.2
-7,-1,5:106.1
-8,-1,5:106.1
9,-2,5:106.8
8,-2,5:106.8
3,-2,5:106.2
-4,-2,5:106.2
-6,-2,5:106.4
-8,-2,5:106.4
-11,-2,5:106.8
13,-3,5:106.2
10,-3,5:106.8
8,-3,5:106.8
3,-3,5:106.2
-8,-3,5:106.4
-11,-3,5:106.8
10,-4,5:106.8
9,-4,5:106.8
2,-4,5:106.1
-1,-4,5:106.1
-2,-4,5:106.1
14,-5,5:106.2
8,-5,5:106.8
15,-6,5:106.2
8,-6,5:106.8
7,-6,5:106.4
10,-7,5:106.8
9,-7,5:106.8
8,-7,5:106.2
4,-7,5:106.4
3,-7,5:106.4
-3,-7,5:106.4
-11,-7,5:106.8
9,-8,5:106.8
7,-8,5:106.4
6,-8,5:106.4
5,-8,5:106.4
4,-8,5:106.4
-4,-8,5:106.4
12,-9,5:106.2
8,-9,5:106.4
7,-9,5:106.4
6,-9,5:106.4
-3,-9,5:106.4
12,-10,5:106.2
9,-10,5:106.4
8,-10,5:106.4
4,-10,5:106.4
3,-10,5:106.4
0,-10,5:106.4
2,-12,5:106.1
1,-12,5:106.1
0,-12,5:106.1
-2,-12,5:106.1
-5,-12,5:106.1
11,-13,5:106.2
8,-14,5:106.1
2,-14,5:106.1
7,-13,6:18
8,-13,6:18
9,-13,6:18
7,-12,6:18
8,-12,6:18
9,-12,6:18
10,-12,6:18
-10,-11,6:44.5
-9,-11,6:98.1
-8,-11,6:44.5
-4,-11,6:44.5
-3,-11,6:98.0
-2,-11,6:98.1
-1,-11,6:98.0
0,-11,6:98.0
1,-11,6:98.0
2,-11,6:98.0
3,-11,6:98.0
4,-11,6:98.0
5,-11,6:44.5
7,-11,6:18
8,-11,6:17.0
9,-11,6:44.5
10,-11,6:98.0
11,-11,6:44.5
-10,-10,6:98.1
-9,-10,6:98.0
-8,-10,6:98.0
-7,-10,6:98.0
-6,-10,6:98.0
-5,-10,6:98.0
-4,-10,6:98.0
-3,-10,6:98.0
-2,-10,6:98.0
3,-10,6:98.0
4,-10,6:98.0
5,-10,6:98.0
6,-10,6:98.0
7,-10,6:98.0
8,-10,6:98.0
9,-10,6:98.0
10,-10,6:98.0
11,-10,6:98.0
-10,-9,6:44.5
-9,-9,6:98.0
10,-9,6:98.0
11,-9,6:44.5
-9,-8,6:98.0
10,-8,6:98.0
11,-8,6:18
12,-8,6:18
-9,-7,6:98.0
-6,-7,6:98.1
7,-7,6:98.0
10,-7,6:98.0
11,-7,6:18
12,-7,6:18
13,-7,6:18
-10,-6,6:44.5
-9,-6,6:98.0
10,-6,6:98.0
11,-6,6:44.5
12,-6,6:17.0
13,-6,6:17.0
14,-6,6:18
-10,-5,6:98.0
-9,-5,6:98.0
10,-5,6:98.0
11,-5,6:98.0
12,-5,6:18
13,-5,6:18
-10,-4,6:98.0
-9,-4,6:98.0
-8,-4,6:109.2
-6,-4,6:109.2
-5,-4,6:98.2
11,-4,6:98.1
-10,-3,6:98.1
-9,-3,6:98.0
-8,-3,6:98.0
-7,-3,6:109
-6,-3,6:98.0
-5,-3,6:98.2
-4,-3,6:109.1
2,-3,6:98.1
11,-3,6:98.0
12,-3,6:44.5
-10,-2,6:98.0
-9,-2,6:109
-6,-2,6:109
-5,-2,6:98.0
1,-2,6:109
2,-2,6:98.0
11,-2,6:98.0
12,-2,6:98.0
-10,-1,6:98.0
-9,-1,6:109
-6,-1,6:109
-5,-1,6:98.0
2,-1,6:98.0
11,-1,6:98.0
12,-1,6:98.1
-10,0,6:98.0
-9,0,6:98.0
-8,0,6:98.0
-7,0,6:98.0
-6,0,6:98.0
-5,0,6:98.2
-4,0,6:109.1
3,0,6:113
11,0,6:98.0
12,0,6:44.5
-10,1,6:98.1
-9,1,6:98.1
-8,1,6:109.3
-7,1,6:109.3
-6,1,6:109.3
-5,1,6:98.2
11,1,6:98.0
-10,2,6:98.0
-9,2,6:98.1
11,2,6:98.0
-10,3,6:44.5
-9,3,6:98.1
-5,3,6:44.5
10,3,6:98.1
11,3,6:44.5
-9,4,6:98.0
-6,4,6:98.0
7,4,6:98.0
10,4,6:98.0
-9,5,6:98.0
10,5,6:98.0
-10,6,6:44.5
-9,6,6:98.0
-8,6,6:98.0
9,6,6:98.1
10,6,6:98.0
11,6,6:44.5
-10,7,6:98.1
-9,7,6:98.0
-8,7,6:98.0
-7,7,6:98.1
-6,7,6:98.0
-5,7,6:98.0
-4,7,6:98.0
-3,7,6:98.0
3,7,6:98.1
4,7,6:98.0
5,7,6:98.0
6,7,6:98.1
7,7,6:98.1
8,7,6:98.0
9,7,6:98.0
10,7,6:98.0
11,7,6:98.0
-10,8,6:44.5
-9,8,6:98.0
-8,8,6:44.5
-4,8,6:44.5
-3,8,6:98.0
-2,8,6:98.0
-1,8,6:98.0
0,8,6:98.1
1,8,6:98.0
2,8,6:98.0
3,8,6:98.1
4,8,6:98.0
5,8,6:44.5
9,8,6:44.5
10,8,6:109.3
11,8,6:44.5
-11,9,6:18
-10,9,6:18
-9,9,6:17.0
-8,9,6:18
-9,10,6:18
-8,10,6:18
-8,11,6:106.4
-9,11,6:106.4
-10,11,6:106.4
-11,10,6:106
4,9,6:106.4
2,9,6:106.4
0,9,6:106.4
-1,9,6:106.4
-12,9,6:106.8
7,8,6:106.4
6,8,6:106.4
-6,8,6:106.4
-12,8,6:106.8
12,7,6:106.2
0,7,6:106.1
-1,7,6:106.1
-2,7,6:106.1
7,6,6:106.1
6,6,6:106.1
5,6,6:106.1
3,6,6:106.1
-1,6,6:106.1
11,5,6:106.2
4,5,6:106.1
3,5,6:106.1
1,5,6:106.1
-10,5,6:106
11,4,6:106.2
6,4,6:106.8
1,4,6:106.1
-8,4,6:106.2
-10,4,6:106.8
7,3,6:106.1
-7,3,6:106.2
-8,3,6:106.2
12,2,6:106.2
10,2,6:106.8
9,2,6:106.8
-7,2,6:106.2
-8,2,6:106.2
10,1,6:106.8
-11,1,6:106.8
10,0,6:106.8
8,0,6:106.8
2,0,6:106.4
-11,0,6:106.8
13,-1,6:106.2
10,-1,6:106.8
7,-1,6:106.8
-4,-1,6:106.2
-7,-1,6:106.1
-8,-1,6:106.1
9,-2,6:106.8
8,-2,6:106.8
3,-2,6:106.2
-4,-2,6:106.2
-7,-2,6:106
-8,-2,6:106.4
-11,-2,6:106.8
10,-3,6:106.8
9,-3,6:106.8
8,-3,6:106.8
3,-3,6:106.2
10,-4,6:106.8
9,-4,6:106.8
2,-4,6:106.1
-1,-4,6:106.1
-2,-4,6:106.1
14,-5,6:106.2
8,-5,6:106.8
15,-6,6:106.2
8,-6,6:106.8
7,-6,6:106.4
-6,-6,6:106.4
-8,-6,6:106.2
14,-7,6:106.1
9,-7,6:106.8
8,-7,6:106.2
6,-7,6:106.8
4,-7,6:106.4
3,-7,6:106.4
-3,-7,6:106.4
-5,-7,6:106.2
-10,-7,6:106.8
9,-8,6:106.8
7,-8,6:106.4
6,-8,6:106.4
5,-8,6:106.4
4,-8,6:106.4
2,-8,6:106.4
-4,-8,6:106.4
-5,-8,6:106.4
-8,-8,6:106.2
8,-9,6:106.4
7,-9,6:106.4
6,-9,6:106.4
1,-9,6:106.4
-3,-9,6:106.4
-5,-9,6:106.4
-7,-9,6:106.4
12,-10,6:106.2
0,-10,6:106.4
11,-12,6:106.2
2,-12,6:106.1
1,-12,6:106.1
0,-12,6:106.1
-2,-12,6:106.1
11,-13,6:106.2
9,-14,6:106.1
8,-14,6:106.1
8,-13,7:18
9,-13,7:18
7,-12,7:18
8,-12,7:18
9,-12,7:18
-10,-11,7:44.5
-9,-11,7:98.1
-8,-11,7:44.5
-4,-11,7:44.5
-3,-11,7:98.0
-2,-11,7:98.0
-1,-11,7:98.1
0,-11,7:98.1
1,-11,7:98.0
2,-11,7:98.1
3,-11,7:98.0
4,-11,7:98.0
5,-11,7:44.5
6,-11,7:18
7,-11,7:18
8,-11,7:17.0
9,-11,7:44.5
10,-11,7:98.0
11,-11,7:44.5
-10,-10,7:98.0
-9,-10,7:98.0
-8,-10,7:98.0
-7,-10,7:98.0
-6,-10,7:98.0
-5,-10,7:98.0
-4,-10,7:98.0
-3,-10,7:98.0
-2,-10,7:98.0
3,-10,7:98.0
4,-10,7:98.1
5,-10,7:98.0
6,-10,7:98.1
7,-10,7:98.0
8,-10,7:98.0
9,-10,7:98.0
10,-10,7:98.0
11,-10,7:98.0
-10,-9,7:44.5
-9,-9,7:98.0
10,-9,7:98.0
11,-9,7:44.5
-9,-8,7:98.1
10,-8,7:98.1
-9,-7,7:98.0
-6,-7,7:98.0
7,-7,7:98.0
10,-7,7:98.0
11,-7,7:18
12,-7,7:18
13,-7,7:18
-10,-6,7:44.5
-9,-6,7:98.0
10,-6,7:98.0
11,-6,7:44.5
12,-6,7:18
13,-6,7:17.0
14,-6,7:18
-10,-5,7:98.0
-9,-5,7:98.0
10,-5,7:98.0
11,-5,7:98.2
13,-5,7:18
-10,-4,7:98.1
-9,-4,7:98.0
2,-4,7:98.0
3,-4,7:109.1
11,-4,7:98.0
-10,-3,7:98.1
