[META]
version=2.0
spawnOnBlockType=2
spawnSunlight=True
spawnDarkness=True
spawnWater=False
spawnLava=False
underFill=False
randomRotation=True
dig=True
tree=True
branch=False
needsFoundation=True
rarity=10
collisionPercentage=2
spawnElevationMin=0
spawnElevationMax=245
spawnInBiome=Plains
[DATA]
1,-1,-4:1.0
0,-1,-3:3.0
1,-1,-3:1.0
2,-1,-3:17.0
1,-2,-2:3.0
-1,-1,-2:3.0
0,-1,-2:17.0
1,-1,-2:17.0
2,-1,-2:17.0
1,0,-2:3.0
0,-2,-1:2.0
1,-2,-1:2.0
2,-2,-1:2.0
-1,-1,-1:2.0
0,-1,-1:2.0
1,-1,-1:17.0
2,-1,-1:2.0
0,0,-1:2.0
1,0,-1:2.0
2,0,-1:2.0
1,-1,0:17.0
1,-1,1:17.0
1,-1,2:17.0
1,-2,3:17.0
1,-1,3:17.0
1,-4,4:18.12
0,-3,4:18.12
1,-3,4:17.0
2,-3,4:18.12
1,-2,4:18.4
1,-1,4:17.0
1,-3,5:18.12
1,-1,5:17.0
1,-1,6:17.0
2,-1,6:17.0
2,0,6:17.0
3,0,6:17.0
-1,-2,7:17.0
0,-2,7:17.0
2,-2,7:17.0
0,-1,7:17.0
1,-1,7:17.0
2,-1,7:17.0
5,-1,7:17.0
0,0,7:17.0
4,0,7:17.0
2,1,7:17.0
2,2,7:17.0
-2,-5,8:18.12
-3,-4,8:18.4
-1,-4,8:18.12
0,-4,8:18.12
1,-4,8:18.12
2,-4,8:18.4
-4,-3,8:18.12
-2,-3,8:17.0
0,-3,8:17.0
2,-3,8:17.0
3,-3,8:18.12
-4,-2,8:18.14
-3,-2,8:18.12
-2,-2,8:17.0
4,-2,8:18.12
5,-2,8:18.12
-3,-1,8:18.12
1,-1,8:17.0
6,-1,8:18.12
-2,0,8:18.12
-1,0,8:17.0
4,0,8:17.0
7,0,8:18.12
-1,1,8:18.12
6,1,8:18.12
0,2,8:18.12
3,2,8:17.0
5,2,8:18.12
1,3,8:18.12
2,3,8:18.12
3,3,8:18.12
4,3,8:18.12
-2,-6,9:18.12
-1,-6,9:18.12
0,-6,9:18.12
-3,-5,9:18.12
-2,-5,9:18.12
-1,-5,9:18.12
0,-5,9:18.12
1,-5,9:18.12
2,-5,9:18.12
-4,-4,9:18.12
-3,-4,9:17.0
-2,-4,9:18.12
-1,-4,9:18.12
0,-4,9:17.0
1,-4,9:18.12
2,-4,9:18.12
3,-4,9:18.12
4,-4,9:18.12
-5,-3,9:18.4
-4,-3,9:18.12
-3,-3,9:18.12
-2,-3,9:18.12
-1,-3,9:18.12
0,-3,9:18.12
1,-3,9:18.12
3,-3,9:18.12
4,-3,9:18.12
5,-3,9:18.12
-5,-2,9:18.12
-4,-2,9:18.12
-3,-2,9:18.12
-2,-2,9:18.12
0,-2,9:18.12
1,-2,9:17.0
2,-2,9:18.12
4,-2,9:18.12
5,-2,9:18.12
6,-2,9:18.12
-5,-1,9:18.4
-4,-1,9:18.12
-3,-1,9:18.12
-2,-1,9:18.12
1,-1,9:18.12
2,-1,9:18.12
3,-1,9:18.12
5,-1,9:18.12
6,-1,9:18.12
7,-1,9:18.12
-4,0,9:18.12
-3,0,9:18.12
-2,0,9:18.12
-1,0,9:18.12
0,0,9:18.4
1,0,9:17.0
4,0,9:18.12
5,0,9:17.0
6,0,9:18.12
7,0,9:18.12
-3,1,9:18.12
-2,1,9:18.12
-1,1,9:18.12
1,1,9:18.12
3,1,9:18.12
4,1,9:17.0
5,1,9:18.12
6,1,9:18.12
7,1,9:18.4
-2,2,9:18.12
-1,2,9:18.12
0,2,9:18.12
1,2,9:18.12
4,2,9:18.12
5,2,9:18.12
6,2,9:18.12
0,3,9:18.12
1,3,9:18.12
2,3,9:18.12
3,3,9:18.12
4,3,9:18.12
5,3,9:18.12
1,4,9:18.12
2,4,9:18.12
3,4,9:18.12
4,4,9:18.12
-2,-5,10:18.12
-1,-5,10:18.12
0,-5,10:18.4
-3,-4,10:18.12
-2,-4,10:18.12
-1,-4,10:18.12
0,-4,10:18.12
1,-4,10:18.12
2,-4,10:18.6
-3,-3,10:18.12
-2,-3,10:18.6
-1,-3,10:18.12
1,-3,10:18.12
2,-3,10:18.12
3,-3,10:18.12
4,-3,10:18.12
-3,-2,10:18.12
-2,-2,10:18.12
0,-2,10:18.12
1,-2,10:18.12
2,-2,10:18.12
3,-2,10:18.12
4,-2,10:18.12
5,-2,10:18.12
-3,-1,10:18.12
-2,-1,10:18.12
-1,-1,10:18.12
1,-1,10:18.12
3,-1,10:18.12
5,-1,10:18.12
6,-1,10:18.12
-3,0,10:18.6
-2,0,10:18.12
-1,0,10:18.12
0,0,10:18.12
1,0,10:18.12
2,0,10:18.12
4,0,10:18.12
5,0,10:18.12
6,0,10:18.12
-2,1,10:18.14
-1,1,10:18.12
0,1,10:18.12
1,1,10:18.12
2,1,10:18.12
3,1,10:18.12
4,1,10:18.12
5,1,10:18.12
6,1,10:18.12
0,2,10:18.12
1,2,10:18.12
2,2,10:18.12
4,2,10:18.12
5,2,10:18.12
1,3,10:18.12
2,3,10:18.12
3,3,10:18.12
4,3,10:18.12
-1,-3,11:18.12
0,-3,11:18.12
1,-3,11:18.12
-2,-2,11:18.12
-1,-2,11:18.12
0,-2,11:18.12
1,-2,11:18.12
2,-2,11:18.12
-1,-1,11:18.12
0,-1,11:18.4
1,-1,11:18.12
2,-1,11:18.12
3,-1,11:18.12
4,-1,11:18.12
0,0,11:18.12
1,0,11:18.12
2,0,11:18.12
3,0,11:18.12
4,0,11:18.12
5,0,11:18.12
1,1,11:18.12
2,1,11:18.12
3,1,11:18.12
4,1,11:18.12
2,2,11:18.4
3,2,11:18.12
2,0,0:31.1
1,0,0:31.1
0,0,0:31.1
0,-1,0:31.1
-1,-1,0:31.1
2,-2,0:31.1
1,-2,0:31.1
0,-2,0:31.1
