[META]
version=2.0
spawnOnBlockType=2
spawnSunlight=True
spawnDarkness=True
spawnWater=False
spawnLava=False
underFill=False
randomRotation=True
dig=True
tree=True
branch=False
needsFoundation=True
rarity=10
collisionPercentage=10
spawnElevationMin=0
spawnElevationMax=245
spawnInBiome=Plains
[DATA]
-2,0,-2:3.5
-1,0,-2:3.0
-2,1,-2:17.0
-1,1,-2:3.0
0,1,-2:17.0
-2,-1,-1:3.5
-1,-1,-1:17.0
-2,0,-1:3.0
-1,0,-1:3.0
0,0,-1:3.0
-2,1,-1:3.0
-1,1,-1:17.0
0,1,-1:3.5
-1,2,-1:3.5
-2,-1,0:2.0
-1,-1,0:2.0
-3,0,0:2.0
-2,0,0:2.0
-1,0,0:17.0
0,0,0:2.0
-2,1,0:2.0
-1,1,0:2.0
0,1,0:2.0
-1,2,0:2.0
-1,0,1:17.0
-1,-1,2:17.0
-1,0,2:17.0
-1,1,2:17.0
-1,-1,3:17.0
-2,1,3:17.0
-1,1,3:17.0
-1,-2,4:17.0
0,-2,4:17.0
-1,-1,4:17.0
-2,1,4:17.0
-2,2,4:17.0
0,-2,5:17.0
-2,2,5:17.0
-1,-2,6:17.0
0,-2,6:17.0
-3,-1,6:17.0
-2,0,6:17.0
0,0,6:18.14
-1,1,6:17.0
0,1,6:18.14
-2,2,6:17.0
1,2,6:18.14
-2,3,6:17.0
-1,3,6:17.0
0,3,6:18.14
0,4,6:18.14
-2,-5,7:18.14
-1,-5,7:18.14
0,-5,7:18.14
-3,-4,7:18.14
-2,-4,7:18.14
-1,-4,7:18.14
0,-4,7:18.14
1,-4,7:18.14
-4,-3,7:18.14
-3,-3,7:18.14
-2,-3,7:18.14
-1,-3,7:17.0
0,-3,7:18.14
1,-3,7:17.0
2,-3,7:18.14
-5,-2,7:18.14
-4,-2,7:18.14
-3,-2,7:18.14
-2,-2,7:18.6
-1,-2,7:17.0
0,-2,7:18.14
1,-2,7:18.14
2,-2,7:18.14
3,-2,7:18.14
-5,-1,7:18.14
-4,-1,7:18.14
-3,-1,7:18.14
-2,-1,7:18.14
-1,-1,7:17.0
0,-1,7:18.14
1,-1,7:17.0
2,-1,7:18.14
3,-1,7:18.14
-5,0,7:18.14
-4,0,7:18.14
-3,0,7:18.14
-2,0,7:18.14
-1,0,7:18.14
0,0,7:18.14
1,0,7:18.14
2,0,7:18.14
3,0,7:18.14
-4,1,7:18.14
-3,1,7:18.14
-2,1,7:18.14
-1,1,7:18.14
0,1,7:18.14
1,1,7:18.14
2,1,7:18.14
3,1,7:18.14
-3,2,7:18.14
-2,2,7:18.14
-1,2,7:18.14
0,2,7:18.14
1,2,7:18.14
2,2,7:18.14
-4,3,7:18.14
-3,3,7:17.0
-2,3,7:18.14
-1,3,7:18.14
0,3,7:18.14
1,3,7:18.14
-3,4,7:18.14
-2,4,7:18.14
-1,4,7:18.14
0,4,7:17.0
1,4,7:18.14
-2,5,7:18.14
-1,5,7:18.14
0,5,7:18.14
-1,-3,8:18.14
1,-3,8:18.14
-2,-2,8:18.14
-1,-2,8:18.14
0,-2,8:18.14
-2,-1,8:18.14
-1,-1,8:18.14
0,-1,8:18.14
1,-1,8:18.14
0,0,8:18.14
-1,1,8:18.14
-1,2,8:18.14
-3,3,8:17.0
0,3,8:18.14
0,4,8:18.14
-1,-2,9:18.14
-4,0,9:18.14
-3,0,9:18.14
-2,0,9:18.14
-5,1,9:18.14
-4,1,9:18.14
-3,1,9:18.14
-2,1,9:18.14
-1,1,9:18.14
-6,2,9:18.14
-5,2,9:18.14
-4,2,9:18.14
-3,2,9:17.0
-2,2,9:18.14
-1,2,9:18.14
0,2,9:18.14
-6,3,9:18.14
-5,3,9:18.14
-4,3,9:17.0
-3,3,9:18.14
-2,3,9:17.0
-1,3,9:18.14
0,3,9:18.14
-6,4,9:18.14
-5,4,9:18.14
-4,4,9:18.14
-3,4,9:17.0
-2,4,9:18.14
-1,4,9:18.14
0,4,9:18.14
-5,5,9:18.14
-4,5,9:18.14
-3,5,9:18.14
-2,5,9:18.14
-1,5,9:18.14
-4,6,9:18.14
-3,6,9:18.14
-2,6,9:18.14
-3,2,10:18.14
-4,3,10:18.14
-3,3,10:18.14
-2,3,10:18.14
-3,4,10:18.14
