[META]
version=2.0
spawnOnBlockType=2
spawnSunlight=True
spawnDarkness=True
spawnWater=False
spawnLava=False
underFill=False
randomRotation=True
dig=False
tree=False
branch=False
needsFoundation=True
rarity=1000
collisionPercentage=50
spawnElevationMin=0
spawnElevationMax=100
spawnInBiome=Forest2,Jungle
[DATA]
0,0,0:17.0
-2,-1,0:31.1
1,-2,0:31.2
0,1,0:17.0
0,-1,0:17.0
-1,0,0:17.0
1,0,0:17.0
1,2,0:31.1
-2,0,0:17.0
0,-2,0:17.0
-1,-1,0:17.0
2,0,0:17.0
0,2,0:17.0
1,1,0:17.0
-1,1,0:17.0
1,-1,0:17.0
0,-3,0:31.1
2,-1,0:31.2
-1,2,0:31.1
-2,1,0:31.2
-1,-2,0:31.1
2,1,0:106.2
-7,-4,0:17.0
3,6,0:17.0
2,6,0:18.0
1,6,0:18.0
1,5,0:18.0
4,6,0:18.0
4,5,0:18.0
3,5,0:18.0
5,6,0:18.0
3,7,0:18.0
5,7,0:18.0
6,7,0:18.0
-6,5,0:18.0
-6,4,0:18.0
-7,4,0:18.0
-7,3,0:18.0
-6,6,0:18.0
-7,6,0:18.0
-6,7,0:18.0
-5,6,0:18.0
-5,7,0:18.0
-5,4,0:18.0
-4,3,0:18.0
7,0,0:18.0
6,0,0:18.0
6,-1,0:18.0
5,-2,0:18.0
5,-1,0:18.0
7,1,0:18.0
7,2,0:18.0
7,3,0:18.0
8,2,0:18.0
6,3,0:18.0
1,-7,0:18.0
0,-7,0:18.0
-1,-7,0:18.0
-1,-8,0:18.0
2,-7,0:18.0
3,-7,0:18.0
3,-8,0:18.0
3,-6,0:18.0
0,-6,0:18.0
-2,-7,0:18.0
4,-6,0:18.0
-7,-5,0:18.0
-6,-5,0:18.0
-7,-6,0:18.0
-8,-4,0:18.0
-7,-3,0:18.0
-7,-2,0:18.0
-6,-2,0:18.0
-7,-1,0:18.0
7,-1,0:18.0
8,0,0:18.0
-5,5,0:106.1
0,-8,0:106.2
6,-2,0:106.2
7,-2,0:18.0
5,0,0:30
0,0,12:17.0
-1,0,12:17.0
0,-1,12:17.0
1,0,12:17.0
0,1,12:17.0
-1,1,12:106.8
-3,1,12:18.0
-4,1,12:18.0
-3,2,12:18.0
-3,0,12:18.0
-2,1,12:18.0
3,3,12:106.4
-1,-5,12:106.1
5,0,12:106.2
-5,5,12:106.1
0,0,11:17.0
-1,0,11:17.0
0,-1,11:17.0
0,1,11:17.0
1,0,11:17.0
-1,1,11:106.8
-2,0,11:17.0
-3,1,11:17.0
-4,1,11:18.0
-3,0,11:18.0
-3,2,11:18.0
-4,0,11:18.0
-3,-1,11:18.0
-5,1,11:18.0
-4,2,11:18.0
-3,3,11:18.0
-2,1,11:18.0
-2,2,11:18.0
-5,2,11:106.8
3,3,11:106.4
-1,-5,11:106.1
5,0,11:106.2
-5,5,11:106.1
0,0,10:17.0
-1,0,10:17.0
0,-1,10:17.0
0,1,10:17.0
1,0,10:17.0
-1,1,10:106.8
-3,1,10:18.0
-3,0,10:18.0
-4,1,10:18.0
-3,2,10:18.0
-5,2,10:106.8
3,3,10:106.4
-1,-5,10:106.1
5,0,10:106.2
-5,5,10:106.1
0,0,9:17.0
-1,0,9:17.0
0,-1,9:17.0
0,1,9:17.0
1,0,9:17.0
-1,1,9:106.8
-5,2,9:106.8
3,3,9:106.4
-1,-5,9:106.1
5,0,9:106.2
-5,5,9:106.1
0,0,8:17.0
-1,0,8:17.0
0,-1,8:17.0
0,1,8:17.0
1,0,8:17.0
-1,1,8:106.8
-5,2,8:106.8
3,3,8:106.4
-1,-5,8:106.1
5,0,8:106.2
-5,5,8:106.1
0,0,7:17.0
-1,0,7:17.0
0,-1,7:17.0
1,0,7:17.0
0,1,7:17.0
-1,-1,7:106.8
-5,2,7:106.8
3,3,7:106.4
-1,-5,7:106.1
5,0,7:106.2
-5,5,7:106.1
0,0,6:17.0
-1,0,6:17.0
0,-1,6:17.0
1,0,6:17.0
0,1,6:17.0
-1,-1,6:106.8
-5,2,6:106.8
3,3,6:106.4
-1,-5,6:106.1
-5,5,6:106.1
0,0,5:17.0
-1,0,5:17.0
1,0,5:17.0
0,-1,5:17.0
0,1,5:17.0
-1,-1,5:106.8
-5,2,5:106.8
3,3,5:106.4
-1,-5,5:106.1
-5,5,5:106.1
0,0,4:17.0
-1,0,4:17.0
0,-1,4:17.0
1,0,4:17.0
0,1,4:17.0
1,-1,4:106.1
-1,-1,4:106.8
-5,2,4:106.8
3,3,4:106.4
-1,-5,4:106.1
-5,5,4:106.1
0,0,3:17.0
-1,0,3:17.0
0,-1,3:17.0
0,1,3:17.0
1,0,3:17.0
-1,-1,3:17.0
1,-1,3:106.1
-1,-2,3:106.1
-5,2,3:106.8
3,3,3:106.4
-1,-5,3:106.1
-5,5,3:106.1
0,0,2:17.0
-1,0,2:17.0
0,-1,2:17.0
0,1,2:17.0
1,0,2:17.0
-1,-1,2:17.0
1,-1,2:106.1
-1,-2,2:106.1
-1,-5,2:106.1
1,5,2:18.0
2,5,2:18.0
4,5,2:18.0
6,6,2:18.0
0,6,2:18.0
-7,5,2:18.0
-6,3,2:18.0
-6,5,2:18.0
-6,4,2:18.0
-5,5,2:106.1
-6,6,2:18.0
-7,6,2:18.0
-7,-4,2:18.0
1,-7,2:18.0
0,-7,2:18.0
7,0,2:18.0
0,0,1:17.0
-1,0,1:17.0
0,-1,1:17.0
1,0,1:17.0
0,1,1:17.0
-1,-1,1:17.0
-2,0,1:17.0
2,0,1:17.0
1,-1,1:17.0
1,1,1:17.0
2,1,1:106.2
-1,-2,1:106.1
-7,4,1:18.0
-6,4,1:18.0
-6,5,1:18.0
-5,4,1:18.0
-7,6,1:18.0
-6,6,1:18.0
-6,7,1:18.0
-5,6,1:18.0
1,6,1:18.0
2,6,1:18.0
3,6,1:18.0
3,5,1:18.0
3,7,1:18.0
4,6,1:18.0
5,6,1:18.0
5,7,1:18.0
0,-7,1:18.0
-1,-7,1:18.0
1,-7,1:18.0
1,-6,1:18.0
0,-8,1:18.0
2,-7,1:18.0
2,-8,1:18.0
6,0,1:18.0
7,2,1:18.0
7,1,1:18.0
7,0,1:18.0
-7,-4,1:18.0
-6,-4,1:18.0
-6,-5,1:18.0
-6,-3,1:18.0
-7,-3,1:18.0
-7,-2,1:18.0
-7,-5,1:18.0
-8,-4,1:18.0
-5,5,1:106.1
6,-2,1:106.2
5,-2,1:18.0
6,-1,1:18.0
2,5,1:30
-7,5,1:30
2,-6,1:30
0,0,13:17.0
-1,0,13:17.0
0,-1,13:17.0
0,1,13:17.0
1,0,13:17.0
-1,1,13:106.8
-1,-3,13:18.0
-2,-3,13:18.0
-1,-4,13:18.0
0,-3,13:18.0
-1,-2,13:18.0
3,3,13:106.4
-1,-5,13:106.1
5,0,13:106.2
-5,5,13:106.1
0,0,18:17.0
-1,0,18:17.0
0,-1,18:17.0
0,1,18:17.0
1,0,18:17.0
2,-4,18:106.2
-2,2,18:106.4
-1,1,18:106.8
2,2,18:18.0
1,2,18:18.0
2,3,18:18.0
2,1,18:18.0
3,2,18:18.0
3,3,18:106.4
5,0,18:106.2
-5,5,18:106.1
0,0,19:17.0
0,1,19:17.0
-1,0,19:17.0
0,-1,19:17.0
1,0,19:17.0
2,-4,19:106.2
-2,2,19:106.4
-1,1,19:106.8
5,0,19:106.2
-5,5,19:106.1
0,0,20:17.0
0,-1,20:17.0
0,2,20:17.0
-1,0,20:17.0
1,0,20:17.0
5,0,20:106.2
2,-4,20:106.2
-2,2,20:106.4
0,1,20:106.4
-5,5,20:106.1
0,-2,21:17.0
0,2,21:17.0
0,0,21:17.0
-2,1,21:17.0
2,0,21:17.0
5,0,21:106.2
2,-4,21:106.2
-2,2,21:106.4
-2,-3,21:106.4
0,1,21:106.4
-5,5,21:106.1
0,0,22:17.0
-2,1,22:17.0
1,1,22:17.0
2,2,22:17.0
0,-3,22:17.0
-3,1,22:18.0
-2,0,22:18.0
-2,2,22:18.0
-1,3,22:17.0
0,4,22:18.0
1,3,22:18.0
2,3,22:18.0
3,2,22:18.0
2,1,22:18.0
2,-1,22:18.0
1,-2,22:18.0
2,0,22:18.0
0,-4,22:18.0
1,-3,22:18.0
-1,-3,22:18.0
-1,-2,22:18.0
-1,-1,22:18.0
2,-2,22:18.0
3,-1,22:18.0
3,0,22:18.0
3,1,22:18.0
-2,-1,22:18.0
-2,3,22:18.0
-1,4,22:18.0
5,0,22:106.2
2,-4,22:106.2
-2,-3,22:106.4
0,1,22:106.4
-5,5,22:106.1
0,0,23:17.0
-3,1,23:17.0
-4,2,23:17.0
0,4,23:17.0
2,3,23:17.0
3,2,23:17.0
4,1,23:17.0
-1,-3,23:17.0
1,-3,23:17.0
-2,-2,23:17.0
-2,-4,23:17.0
0,5,23:18.0
-1,4,23:18.0
-1,3,23:18.0
-3,3,23:18.0
-2,3,23:18.0
-4,3,23:18.0
-5,2,23:18.0
-4,1,23:18.0
-4,0,23:18.0
-3,-4,23:18.0
-3,-2,23:18.0
-3,-1,23:18.0
-2,-5,23:18.0
-1,-4,23:18.0
3,-3,23:18.0
2,-3,23:18.0
4,-2,23:18.0
4,-1,23:18.0
4,0,23:18.0
3,0,23:18.0
5,1,23:18.0
4,2,23:18.0
3,3,23:18.0
2,4,23:18.0
1,4,23:18.0
1,-4,23:18.0
-2,-3,23:106.4
0,-3,23:18.0
3,-2,23:18.0
-1,-2,23:18.0
-3,0,23:18.0
-2,-1,23:18.0
-3,2,23:18.0
0,3,23:18.0
2,0,23:17.0
5,0,23:106.2
2,-4,23:106.2
0,1,23:106.4
-5,5,23:106.1
0,0,24:17.0
-2,-1,24:17.0
-4,0,24:17.0
-3,-3,24:17.0
-3,-4,24:17.0
-3,3,24:17.0
-1,3,24:17.0
-1,4,24:17.0
3,3,24:17.0
3,0,24:17.0
4,0,24:17.0
2,-2,24:17.0
3,-2,24:17.0
3,-3,24:17.0
1,-4,24:17.0
0,1,24:18.0
0,2,24:18.0
0,3,24:18.0
0,4,24:18.0
1,0,24:18.0
2,0,24:18.0
5,0,24:18.0
-5,0,24:18.0
-3,0,24:18.0
-2,0,24:18.0
-1,0,24:18.0
0,-5,24:18.0
0,-4,24:18.0
0,-3,24:18.0
0,-2,24:18.0
0,-1,24:18.0
1,-5,24:18.0
-2,-5,24:18.0
-1,-4,24:18.0
-1,-3,24:18.0
-2,-3,24:18.0
-2,-4,24:18.0
-2,-2,24:18.0
-1,-2,24:18.0
-1,-1,24:18.0
-3,-5,24:18.0
-4,-4,24:18.0
-4,-3,24:18.0
-4,-2,24:18.0
-4,-1,24:18.0
-5,-1,24:18.0
-3,-1,24:18.0
-3,-2,24:18.0
-5,1,24:18.0
-4,3,24:18.0
-4,2,24:18.0
-4,1,24:18.0
-3,4,24:18.0
-2,4,24:18.0
-2,3,24:18.0
-2,2,24:18.0
-2,1,24:18.0
-3,1,24:18.0
-1,1,24:18.0
-1,2,24:18.0
-3,2,24:18.0
-1,5,24:18.0
1,3,24:18.0
1,2,24:18.0
1,1,24:18.0
1,-1,24:18.0
1,-2,24:18.0
1,-3,24:18.0
2,3,24:18.0
2,2,24:18.0
2,1,24:18.0
2,-1,24:18.0
3,4,24:17.0
4,2,24:18.0
4,1,24:18.0
3,1,24:18.0
3,2,24:18.0
5,2,24:18.0
5,1,24:18.0
2,-4,24:18.0
2,-3,24:18.0
3,-4,24:18.0
4,-3,24:18.0
4,-2,24:18.0
4,-1,24:18.0
3,-1,24:18.0
5,-1,24:18.0
4,3,24:18.0
0,5,24:18.0
1,4,24:18.0
2,4,24:18.0
1,5,24:18.0
-5,2,24:18.0
-1,-5,24:18.0
0,-6,24:18.0
-1,-6,24:18.0
-2,-6,24:18.0
-5,-3,24:18.0
-5,-2,24:18.0
-5,3,24:18.0
-4,4,24:18.0
-3,5,24:18.0
-2,5,24:18.0
2,5,24:18.0
3,5,24:18.0
4,4,24:18.0
5,-2,24:18.0
3,-5,24:18.0
2,-5,24:18.0
1,-6,24:18.0
-5,5,24:106.1
0,0,14:17.0
-1,0,14:17.0
0,-1,14:17.0
1,0,14:17.0
0,1,14:17.0
-1,1,14:106.8
0,-2,14:17.0
-1,-3,14:17.0
-2,-3,14:18.0
-1,-4,14:18.0
-1,-2,14:18.0
0,-3,14:18.0
-3,-3,14:18.0
-2,-4,14:18.0
-1,-5,14:18.0
0,-4,14:18.0
-2,-2,14:18.0
3,3,14:106.4
5,0,14:106.2
-5,5,14:106.1
0,0,15:17.0
-1,0,15:17.0
0,-1,15:17.0
0,1,15:17.0
1,0,15:17.0
-1,1,15:106.8
-1,-3,15:18.0
-2,-3,15:18.0
-1,-4,15:18.0
0,-3,15:18.0
3,3,15:106.4
5,0,15:106.2
-5,5,15:106.1
0,0,16:17.0
-1,0,16:17.0
0,-1,16:17.0
0,1,16:17.0
1,0,16:17.0
-1,1,16:106.8
2,2,16:18.0
1,2,16:18.0
2,1,16:18.0
2,3,16:18.0
3,2,16:18.0
3,3,16:106.4
5,0,16:106.2
-5,5,16:106.1
0,0,17:17.0
-1,0,17:17.0
0,-1,17:17.0
0,1,17:17.0
1,0,17:17.0
-2,2,17:106.4
-1,1,17:106.8
1,1,17:17.0
2,2,17:17.0
2,1,17:18.0
1,2,17:18.0
2,3,17:18.0
3,2,17:18.0
1,3,17:18.0
2,4,17:18.0
3,3,17:106.4
3,1,17:18.0
4,2,17:18.0
5,0,17:106.2
-5,5,17:106.1
0,0,25:18.0
-1,0,25:18.0
-2,0,25:18.0
-3,0,25:17.0
-4,0,25:18.0
-5,0,25:17.0
1,0,25:18.0
2,0,25:17.0
3,0,25:18.0
4,0,25:18.0
5,0,25:17.0
0,1,25:18.0
0,2,25:18.0
0,3,25:18.0
0,4,25:18.0
0,5,25:17.0
0,-1,25:18.0
0,-2,25:18.0
0,-3,25:18.0
0,-4,25:18.0
0,-5,25:18.0
1,-5,25:17.0
-1,-5,25:17.0
-2,-5,25:18.0
-5,-1,25:18.0
-5,2,25:18.0
-5,1,25:18.0
-1,5,25:18.0
1,5,25:18.0
5,-1,25:18.0
5,1,25:18.0
5,2,25:18.0
4,3,25:18.0
3,4,25:17.0
2,4,25:18.0
-2,4,25:18.0
-3,3,25:18.0
-4,3,25:17.0
-4,-2,25:18.0
-4,-3,25:18.0
-3,-4,25:18.0
2,-4,25:18.0
3,-4,25:17.0
4,-3,25:18.0
4,-2,25:18.0
-3,-2,25:18.0
-3,-3,25:18.0
-2,-3,25:18.0
-2,-4,25:17.0
-1,-4,25:18.0
-1,-3,25:18.0
-1,-2,25:18.0
-1,-1,25:18.0
-2,-1,25:18.0
-3,-1,25:18.0
-4,-1,25:17.0
-2,-2,25:18.0
-4,1,25:18.0
-3,1,25:18.0
-2,1,25:18.0
-1,1,25:18.0
-1,2,25:17.0
-2,2,25:18.0
-3,2,25:18.0
-4,2,25:18.0
-2,3,25:18.0
-1,3,25:18.0
-1,4,25:18.0
1,4,25:18.0
2,3,25:18.0
1,3,25:18.0
1,2,25:18.0
1,1,25:18.0
2,1,25:18.0
3,1,25:18.0
4,1,25:18.0
4,2,25:18.0
3,2,25:18.0
3,3,25:18.0
2,2,25:18.0
3,-1,25:18.0
4,-1,25:18.0
2,-1,25:18.0
1,-1,25:18.0
1,-2,25:17.0
2,-3,25:18.0
2,-2,25:18.0
3,-2,25:18.0
3,-3,25:18.0
1,-3,25:18.0
1,-4,25:18.0
-5,-2,25:18.0
-5,-3,25:18.0
-4,-4,25:18.0
-3,-5,25:18.0
-3,-6,25:18.0
-2,-6,25:18.0
-1,-6,25:18.0
0,-7,25:18.0
-1,-7,25:18.0
0,-6,25:18.0
1,-6,25:18.0
2,-6,25:17.0
2,-5,25:18.0
3,-5,25:18.0
4,-5,25:18.0
5,-4,25:18.0
4,-4,25:17.0
5,-3,25:18.0
5,-2,25:18.0
6,-1,25:18.0
6,0,25:17.0
6,1,25:18.0
5,3,25:18.0
5,4,25:18.0
4,4,25:18.0
2,5,25:18.0
3,5,25:17.0
1,6,25:18.0
0,6,25:18.0
-1,6,25:17.0
-2,5,25:18.0
-3,5,25:18.0
-3,4,25:18.0
-4,4,25:17.0
-5,3,25:18.0
-6,1,25:18.0
-6,0,25:18.0
-6,-1,25:18.0
-4,-5,25:18.0
7,0,25:18.0
8,0,25:18.0
7,1,25:18.0
7,-1,25:18.0
6,-2,25:18.0
6,-3,25:18.0
6,2,25:18.0
6,3,25:18.0
4,5,25:18.0
5,5,25:18.0
3,6,25:18.0
2,6,25:18.0
1,7,25:18.0
0,7,25:18.0
-1,7,25:18.0
-2,6,25:18.0
8,-1,25:18.0
7,-2,25:18.0
3,-6,25:18.0
4,-6,25:18.0
5,-5,25:18.0
6,-4,25:18.0
3,-7,25:18.0
2,-7,25:18.0
1,-7,25:18.0
1,-8,25:18.0
0,-8,25:18.0
2,-8,25:18.0
-2,-7,25:18.0
-3,-7,25:18.0
-4,-6,25:18.0
-5,-4,25:18.0
-1,-8,25:18.0
-6,-2,25:18.0
-7,0,25:18.0
-7,-1,25:18.0
-6,-3,25:18.0
-6,2,25:18.0
-7,1,25:18.0
-5,4,25:18.0
-6,3,25:18.0
-4,5,25:18.0
-3,6,25:18.0
-2,7,25:18.0
7,2,25:18.0
8,1,25:18.0
6,4,25:18.0
7,3,25:18.0
2,7,25:18.0
3,7,25:18.0
4,6,25:18.0
5,-6,25:18.0
6,-5,25:18.0
-1,8,25:18.0
7,-3,25:18.0
0,8,25:18.0
1,8,25:18.0
-5,5,25:106.1
-6,4,25:18.0
-5,6,25:18.0
-4,6,25:18.0
-6,5,25:18.0
-7,2,25:18.0
-3,0,26:18.0
-2,0,26:18.0
-1,0,26:18.0
0,0,26:18.0
1,0,26:18.0
2,0,26:18.0
0,-3,26:18.0
0,-2,26:18.0
0,-1,26:18.0
0,1,26:18.0
0,2,26:18.0
0,3,26:18.0
1,2,26:18.0
1,1,26:18.0
1,-2,26:18.0
1,-1,26:18.0
2,-1,26:18.0
2,1,26:18.0
-3,1,26:18.0
-2,-1,26:18.0
-2,1,26:18.0
-2,2,26:18.0
-1,3,26:18.0
-1,2,26:18.0
-1,1,26:18.0
-1,-1,26:18.0
-1,-2,26:18.0
-3,-1,26:18.0
-3,-2,26:18.0
-2,-2,26:18.0
-1,-3,26:18.0
0,-4,26:18.0
1,-4,26:18.0
1,-3,26:18.0
2,-3,26:18.0
2,-2,26:18.0
3,-1,26:18.0
3,0,26:18.0
3,-2,26:18.0
3,1,26:18.0
2,2,26:18.0
-2,-3,26:18.0
-1,-4,26:18.0
0,-5,26:18.0
1,3,26:18.0
3,-3,26:18.0
2,-4,26:18.0
1,-5,26:18.0
-2,-4,26:18.0
-1,-5,26:18.0
-3,-3,26:18.0
-4,0,26:18.0
-4,-1,26:18.0
4,-1,26:18.0
4,-2,26:18.0
-5,0,26:18.0
-4,-2,26:18.0
-5,-1,26:18.0
-5,-2,26:18.0
-3,-4,26:18.0
-4,-3,26:18.0
-2,-5,26:18.0
0,-6,26:18.0
1,-6,26:18.0
2,-6,26:18.0
2,-5,26:18.0
3,-4,26:18.0
4,-4,26:18.0
3,-5,26:18.0
4,-3,26:18.0
6,0,26:18.0
5,0,26:18.0
4,0,26:18.0
5,-1,26:18.0
5,-2,26:18.0
5,1,26:18.0
4,1,26:18.0
4,2,26:18.0
3,2,26:18.0
3,3,26:18.0
3,4,26:18.0
3,5,26:18.0
2,3,26:18.0
2,4,26:18.0
2,5,26:18.0
1,4,26:18.0
0,5,26:18.0
-1,5,26:18.0
-1,6,26:18.0
-1,4,26:18.0
0,4,26:18.0
-2,5,26:18.0
-2,4,26:18.0
-3,4,26:18.0
-3,3,26:18.0
-4,3,26:18.0
-2,3,26:18.0
-3,2,26:18.0
-4,1,26:18.0
-4,2,26:18.0
-5,1,26:18.0
4,3,26:18.0
5,2,26:18.0
6,1,26:18.0
4,4,26:18.0
1,5,26:18.0
0,6,26:18.0
1,6,26:18.0
-4,4,26:18.0
-5,2,26:18.0
-2,0,-1:2
-1,0,-1:17.0
0,0,-1:17.0
1,0,-1:17.0
2,0,-1:2
0,-2,-1:2
0,-1,-1:17.0
0,1,-1:17.0
0,2,-1:2
-1,1,-1:2
-1,-1,-1:2
1,-1,-1:2
1,1,-1:2
-2,1,-1:2
-2,2,-1:17.0
-1,2,-1:2
1,2,-1:2
2,1,-1:2
2,-1,-1:2
1,-2,-1:2
0,-3,-1:2
-1,-2,-1:2
-2,-1,-1:2
-6,5,-1:17.0
-7,-4,-1:17.0
1,-7,-1:17.0
7,0,-1:17.0
3,6,-1:17.0
-6,4,-1:2
-5,5,-1:2
2,6,-1:2
3,5,-1:2
6,0,-1:2
7,-1,-1:2
0,-6,-1:2
0,-7,-1:2
1,-8,-1:2
-6,-4,-1:2
-7,-3,-1:2
-3,0,-1:17.0
-2,-2,-1:17.0
1,-3,-1:17.0
2,-2,-1:17.0
3,0,-1:17.0
2,2,-1:17.0
0,3,-1:17.0
-6,3,-1:2
-5,4,-1:2
-4,5,-1:2
-4,1,-1:2
-3,1,-1:2
-4,3,-1:2
-5,2,-1:2
-3,3,-1:2
-2,3,-1:2
-2,4,-1:2
-3,4,-1:2
-2,5,-1:2
-1,5,-1:2
0,4,-1:2
1,5,-1:2
1,4,-1:2
2,4,-1:2
2,3,-1:2
3,4,-1:2
3,2,-1:2
4,2,-1:2
4,1,-1:2
5,1,-1:2
5,0,-1:2
5,-1,-1:17.0
4,-2,-1:2
3,-1,-1:2
4,0,-1:2
3,1,-1:2
4,-1,-1:2
3,-2,-1:2
2,-4,-1:17.0
1,-4,-1:2
1,-6,-1:2
0,-5,-1:2
2,-5,-1:2
3,-3,-1:2
1,-5,-1:2
-1,-5,-1:2
-2,-3,-1:2
-2,-4,-1:2
-3,-3,-1:2
-1,-3,-1:2
-1,-4,-1:17.0
-5,-3,-1:2
-4,-2,-1:2
-5,-2,-1:17.0
-6,-2,-1:2
-6,-1,-1:2
-5,-1,-1:2
-5,0,-1:2
-6,1,-1:2
-4,-1,-1:17.0
-5,1,-1:17.0
-6,2,-1:17.0
-4,2,-1:17.0
-5,3,-1:17.0
-1,4,-1:17.0
3,3,-1:17.0
-4,-4,-1:2
-3,-5,-1:2
-2,-5,-1:2
-1,-3,27:18.0
0,-3,27:18.0
0,-4,27:18.0
1,-4,27:18.0
2,-4,27:18.0
2,-3,27:18.0
2,-2,27:18.0
2,-1,27:18.0
1,-1,27:18.0
1,-2,27:18.0
0,-2,27:18.0
1,-3,27:18.0
-1,-2,27:18.0
-2,-2,27:18.0
0,-1,27:18.0
-2,-3,27:18.0
-2,-4,27:18.0
-1,-4,27:18.0
0,-5,27:18.0
1,-5,27:18.0
3,-3,27:18.0
3,-2,27:18.0
-1,-1,27:18.0
-3,-2,27:18.0
-3,1,27:18.0
-3,2,27:18.0
-3,3,27:18.0
-2,3,27:18.0
-2,4,27:18.0
-1,4,27:18.0
0,4,27:18.0
0,5,27:18.0
1,5,27:18.0
1,4,27:18.0
2,4,27:18.0
2,3,27:18.0
1,3,27:18.0
0,3,27:18.0
0,2,27:18.0
-1,2,27:18.0
-1,1,27:18.0
-2,1,27:18.0
-2,2,27:18.0
-1,3,27:18.0
1,2,27:18.0
3,3,27:18.0
-4,1,27:18.0
-4,0,27:18.0
-3,0,27:18.0
3,-1,27:18.0
3,0,27:18.0
4,0,27:18.0
4,-1,27:18.0
4,-2,27:18.0
2,0,27:18.0
4,1,27:18.0
5,0,27:18.0
-5,-2,-2:17.0
-4,-2,-2:3
0,-3,-2:3
-1,-4,-2:3
0,-4,-2:3
-2,-2,-2:3
-1,-1,-2:3
0,-1,-2:3
0,0,-2:3
0,3,-2:3
-1,4,-2:3
-2,2,-2:3
-1,2,-2:3
-3,4,-2:3
-3,3,-2:3
-4,3,-2:3
-5,2,-2:3
-5,1,-2:3
-4,1,-2:3
-3,1,-2:3
-4,0,-2:3
-2,-1,-2:3
-2,0,-2:3
2,-2,-2:3
4,1,-2:3
2,0,-2:3
2,1,-2:3
1,4,-2:3
1,1,-2:3
3,2,-2:3
2,3,-2:3
1,3,-2:3
-2,4,-2:3
-1,5,-2:3
1,2,-2:3
0,5,-2:3
-2,1,-2:3
-1,-2,-2:3
0,-2,-2:3
1,-2,-2:3
-2,-3,-2:3
-3,-2,-2:3
-4,-1,-2:3
-6,0,-2:3
-6,1,-2:3
-7,1,-2:3
-7,2,-2:17.0
3,0,-2:3
1,0,-2:3
2,-1,-2:3
2,4,-2:17.0
-1,6,-2:3
-1,1,-2:3
-3,-3,-2:17.0
-1,-5,-2:17.0
1,-3,-2:17.0
-1,0,-2:17.0
-3,-1,-2:17.0
-5,0,-2:17.0
-4,2,-2:17.0
-2,3,-2:17.0
0,1,-2:17.0
3,1,-2:17.0
0,4,-2:17.0
3,-2,-2:17.0
-3,5,-2:17.0
