[META]
version=2.0
spawnOnBlockType=2
spawnSunlight=True
spawnDarkness=True
spawnWater=False
spawnLava=False
underFill=False
randomRotation=True
dig=True
tree=true
branch=False
needsFoundation=True
rarity=100
collisionPercentage=60
spawnElevationMin=0
spawnElevationMax=245
spawnInBiome=Forest2,Plains
[DATA]
-1,-1,0:18
-1,0,0:17.0
0,0,0:18
-1,1,0:18
-2,2,0:31.1
0,1,0:106.2
-2,1,0:31.1
-3,1,0:37
-2,0,0:31.1
-3,0,0:31.1
-4,0,0:31.1
-2,-1,0:31.1
-3,-1,0:31.1
-2,-1,-3:17.0
-2,0,-3:3
-1,0,-3:3
0,0,-3:17.0
-2,1,-3:17.0
-2,-1,-2:3
-1,-1,-2:3
-3,0,-2:17.0
-2,0,-2:17.0
-1,0,-2:17.0
0,0,-2:3
-2,1,-2:17.0
-1,1,-2:3
-2,-2,-1:2
-3,-1,-1:2
-2,-1,-1:2
-1,-1,-1:2
0,-1,-1:2
-4,0,-1:2
-3,0,-1:2
-2,0,-1:2
-1,0,-1:17.0
0,0,-1:2
-3,1,-1:2
-2,1,-1:2
-1,1,-1:2
0,1,-1:2
-2,2,-1:2
-1,2,-1:2
-2,-1,1:18
-1,-1,1:18
-3,0,1:18
-2,0,1:17.0
-1,0,1:17.0
0,0,1:18
-2,1,1:18
-1,1,1:18
0,4,1:106.4
0,2,1:106.2
0,1,1:106.2
1,0,1:106.2
-2,-2,1:106.1
-2,-1,2:18
-3,0,2:18
-2,0,2:17.0
-1,0,2:18
-3,1,2:18
-2,1,2:17.0
-1,1,2:18
-2,2,2:18
0,4,2:106.4
0,2,2:106.2
0,1,2:106.2
-4,1,2:106.8
-4,0,2:106.8
-2,-2,2:106.1
-2,0,3:18
-3,1,3:18
-2,1,3:17.0
-1,1,3:18
-3,2,3:18
-2,2,3:17.0
-1,2,3:17.0
-2,3,3:18
-1,3,3:18
0,4,3:106.4
-1,4,3:106.4
0,3,3:106.2
2,2,3:106.2
0,2,3:106.2
-4,2,3:106.8
0,1,3:106.2
-4,1,3:106.8
0,-2,4:18
-1,-1,4:18
0,-1,4:18
0,0,4:18
-2,1,4:18
-1,1,4:18
0,1,4:18
-2,2,4:18
-1,2,4:17.0
0,2,4:17.0
1,2,4:18
-2,3,4:18
-1,3,4:18
0,3,4:18
0,4,4:106.4
-1,4,4:106.4
-2,4,4:106.4
2,2,4:106.2
2,1,4:106.2
1,-1,4:106.2
1,-2,4:106.2
0,-3,4:106.1
-1,-2,5:18
0,-2,5:18
-1,-1,5:18
0,-1,5:18
-1,0,5:18
0,0,5:18
1,0,5:18
-1,1,5:18
0,1,5:17.0
1,1,5:18
-1,2,5:18
0,2,5:17.0
1,2,5:18
-1,3,5:18
0,3,5:18
1,3,5:18
0,4,5:106.4
-1,4,5:106.4
2,3,5:106.2
2,1,5:106.2
1,-1,5:106.2
-1,-1,6:18
0,0,6:18
0,1,6:18
1,1,6:18
0,2,6:18
0,1,7:18
