[META]
version=2.0
spawnOnBlockType=2
spawnSunlight=True
spawnDarkness=True
spawnWater=False
spawnLava=False
underFill=False
randomRotation=True
dig=True
tree=True
branch=False
needsFoundation=True
rarity=30
collisionPercentage=80
spawnElevationMin=0
spawnElevationMax=116
spawnInBiome=Forest3
[DATA]
-1,-1,-4:3.0
-1,-2,-3:3.0
1,-2,-3:17.2
-2,-1,-3:3.0
-1,-1,-3:17.2
0,-1,-3:3.0
1,-1,-3:3.0
-2,0,-3:3.0
-1,0,-3:3.0
0,0,-3:3.0
-1,1,-3:17.2
-2,-2,-2:3.0
-1,-2,-2:3.0
0,-2,-2:3.5
1,-2,-2:3.5
-3,-1,-2:3.0
-2,-1,-2:3.0
-1,-1,-2:17.2
0,-1,-2:17.2
1,-1,-2:3.5
2,-1,-2:3.0
-3,0,-2:17.2
-2,0,-2:3.0
-1,0,-2:17.2
0,0,-2:3.0
1,0,-2:3.0
-2,1,-2:3.0
-1,1,-2:3.0
0,1,-2:3.0
-1,2,-2:3.0
-1,-4,-1:2.0
0,-4,-1:2.0
-2,-3,-1:2.0
-1,-3,-1:2.0
0,-3,-1:2.0
1,-3,-1:2.0
-3,-2,-1:2.0
-2,-2,-1:2.0
-1,-2,-1:17.2
0,-2,-1:17.2
1,-2,-1:2.0
2,-2,-1:2.0
-4,-1,-1:2.0
-3,-1,-1:2.0
-2,-1,-1:17.2
-1,-1,-1:17.2
0,-1,-1:17.2
1,-1,-1:17.2
2,-1,-1:2.0
3,-1,-1:2.0
-4,0,-1:2.0
-3,0,-1:2.0
-2,0,-1:17.2
-1,0,-1:17.2
0,0,-1:17.2
1,0,-1:2.0
2,0,-1:2.0
-3,1,-1:2.0
-2,1,-1:2.0
-1,1,-1:17.2
0,1,-1:2.0
1,1,-1:2.0
-2,2,-1:2.0
-1,2,-1:2.0
0,2,-1:2.0
-1,3,-1:2.0
-1,-3,0:18.12
0,-3,0:18.12
-2,-2,0:18.12
-1,-2,0:17.2
0,-2,0:17.2
1,-2,0:18.12
-3,-1,0:18.12
-2,-1,0:17.2
-1,-1,0:17.2
0,-1,0:17.2
1,-1,0:17.2
2,-1,0:18.12
-3,0,0:18.12
-2,0,0:17.2
-1,0,0:17.2
0,0,0:17.2
1,0,0:18.12
-2,1,0:18.12
-1,1,0:17.2
0,1,0:18.12
-1,2,0:18.12
-1,-2,1:18.12
0,-2,1:18.12
-2,-1,1:18.12
-1,-1,1:17.2
0,-1,1:17.2
1,-1,1:18.12
-2,0,1:18.12
-1,0,1:17.2
0,0,1:18.12
-1,1,1:18.12
0,1,1:103.5
-1,-1,2:18.12
0,-1,2:18.12
-2,0,2:18.12
-1,0,2:17.2
0,0,2:17.2
1,0,2:18.12
-1,1,2:18.12
0,1,2:18.12
0,-1,3:18.12
1,-1,3:18.12
-1,0,3:18.12
0,0,3:17.2
1,0,3:17.2
2,0,3:18.12
0,1,3:18.12
1,1,3:18.12
1,-2,4:18.12
0,-1,4:18.12
1,-1,4:17.2
2,-1,4:18.12
0,0,4:18.12
1,0,4:17.2
2,0,4:18.12
1,1,4:18.12
1,-3,5:18.12
0,-2,5:18.12
1,-2,5:17.2
2,-2,5:18.12
0,-1,5:18.12
1,-1,5:17.2
2,-1,5:18.12
1,0,5:18.12
0,-3,6:18.12
1,-3,6:18.12
-1,-2,6:18.12
0,-2,6:17.2
1,-2,6:17.2
2,-2,6:18.12
0,-1,6:18.12
1,-1,6:18.12
0,-3,7:18.12
-1,-2,7:18.12
0,-2,7:17.2
1,-2,7:18.12
0,-1,7:18.12
-1,-3,8:18.12
0,-3,8:18.12
-2,-2,8:18.12
-1,-2,8:17.2
0,-2,8:17.2
1,-2,8:18.12
-1,-1,8:18.12
0,-1,8:18.12
-2,-3,9:103.0
-1,-3,9:18.12
0,-3,9:103.0
-2,-2,9:18.12
-1,-2,9:17.2
0,-2,9:18.12
-2,-1,9:103.0
-1,-1,9:18.12
0,-1,9:103.0
-2,-3,10:103.0
-1,-3,10:18.12
0,-3,10:103.0
-2,-2,10:18.12
-1,-2,10:17.2
0,-2,10:18.12
-1,-1,10:18.12
0,-1,10:103.0
-1,-3,11:103.0
0,-3,11:103.0
-2,-2,11:103.0
-1,-2,11:18.4
0,-2,11:103.0
-1,-2,12:103.0
-1,3,0:31.1
0,2,0:31.2
-2,2,0:31.1
1,1,0:31.1
-3,1,0:31.2
2,0,0:31.1
-4,0,0:31.1
3,-1,0:31.1
-4,-1,0:31.1
2,-2,0:31.1
-3,-2,0:31.2
1,-3,0:31.2
-2,-3,0:31.2
0,-4,0:31.2
-1,-4,0:31.1
