[META]
version=2.0
spawnOnBlockType=2
spawnSunlight=True
spawnDarkness=True
spawnWater=False
spawnLava=False
underFill=False
randomRotation=True
dig=True
tree=True
branch=False
needsFoundation=True
rarity=10
collisionPercentage=10
spawnElevationMin=0
spawnElevationMax=245
spawnInBiome=Plains
[DATA]
-2,1,0:17.0
-2,1,-4:3
-2,1,-3:3
-3,2,-3:17.0
-2,2,-3:3
-1,2,-3:17.0
-2,0,-2:17.0
-3,1,-2:3
-2,1,-2:3
-1,1,-2:3
-3,2,-2:3
-2,2,-2:17.0
-3,0,-1:2
-2,0,-1:2
-4,1,-1:2
-3,1,-1:2
-2,1,-1:17.0
-1,1,-1:2
-3,2,-1:2
-2,2,-1:2
-1,2,-1:2
-2,3,-1:2
-2,0,1:17.0
-2,1,1:17.0
-2,2,1:17.0
-2,0,2:17.0
-3,2,2:17.0
-2,2,2:17.0
-2,-1,3:17.0
-1,-1,3:17.0
-2,0,3:17.0
-3,2,3:17.0
-3,3,3:17.0
-1,-1,4:17.0
-3,3,4:17.0
-2,-1,5:17.0
-1,-1,5:17.0
-1,1,5:18
-1,2,5:18
-3,3,5:17.0
0,3,5:18
-3,4,5:17.0
-2,4,5:17.0
-1,4,5:18
-1,5,5:18
-2,-3,6:18
-3,-2,6:18
-2,-2,6:17.0
-1,-2,6:18
-4,-1,6:18
-3,-1,6:18
-2,-1,6:18
-1,-1,6:18
0,-1,6:18
-4,0,6:18
-3,0,6:18
-2,0,6:18
-1,0,6:18
0,0,6:17.0
1,0,6:18
-4,1,6:18
-3,1,6:18
-2,1,6:18
-1,1,6:18
0,1,6:18
-3,2,6:18
-2,2,6:18
-1,2,6:18
0,2,6:18
1,2,6:18
-3,3,6:18
-2,3,6:18
-1,3,6:18
0,3,6:18
1,3,6:18
-4,4,6:17.0
-3,4,6:18
-2,4,6:18
-1,4,6:18
0,4,6:18
-2,5,6:18
-1,5,6:17.0
0,5,6:18
-1,6,6:18
-2,-2,7:18
-3,0,7:18
-2,0,7:18
-1,0,7:18
0,0,7:18
-1,1,7:18
-2,2,7:18
-2,3,7:18
-4,4,7:17.0
-1,4,7:18
-1,5,7:18
-3,2,8:18
-5,3,8:18
-4,3,8:18
-3,3,8:17.0
-2,3,8:18
-5,4,8:17.0
-4,4,8:18
-3,4,8:18
-5,5,8:18
-4,5,8:18
-3,5,8:18
-3,3,9:18
-5,4,9:18
