[META]
version=2.0
spawnOnBlockType=2
spawnSunlight=True
spawnDarkness=True
spawnWater=False
spawnLava=False
underFill=False
randomRotation=True
dig=True
tree=true
branch=False
needsFoundation=True
rarity=170
collisionPercentage=60
spawnElevationMin=0
spawnElevationMax=128
spawnInBiome=Urwald,Urwald2,Jungle
[DATA]
0,-3,0:17.3
1,-3,0:17.3
0,-2,0:17.3
1,-2,0:17.3
1,2,0:106.4
0,2,0:106.4
1,1,0:106.4
1,0,0:31.1
0,0,0:106.4
-1,0,0:31.1
-2,0,0:31.1
3,-1,0:106.2
2,-1,0:38
1,-1,0:37
0,-1,0:31.1
-1,-1,0:31.1
-2,-1,0:106.8
-3,-1,0:37
3,-2,0:38
2,-2,0:31.1
-1,-2,0:31.1
-2,-2,0:31.1
-3,-2,0:31.1
-4,-2,0:106.8
3,-3,0:31.1
2,-3,0:31.1
-1,-3,0:31.1
-2,-3,0:31.1
-3,-3,0:106.8
2,-4,0:31.1
1,-4,0:31.1
0,-4,0:31.1
-1,-4,0:37
-2,-4,0:106.1
2,-5,0:106.1
1,-5,0:31.1
0,-5,0:31.1
-1,-5,0:106.1
-2,-5,0:31.1
-3,-5,0:106.8
2,-6,0:106.1
-1,-6,0:31.1
-1,-7,0:106.1
15,-13,-5:35.0
-2,-6,-4:17.3
3,-6,-4:17.3
-4,-5,-4:17.3
-2,-5,-4:17.3
2,-5,-4:17.3
3,-5,-4:17.3
-4,-4,-4:17.3
-3,-4,-4:17.3
-2,-4,-4:17.3
-1,-4,-4:17.3
0,-4,-4:17.3
1,-4,-4:17.3
-1,-3,-4:17.3
0,-3,-4:17.3
-3,-2,-4:17.3
-2,-2,-4:17.3
0,-2,-4:17.3
-1,-1,-4:17.3
0,-1,-4:17.3
1,-1,-4:17.3
-2,0,-4:17.3
1,0,-4:17.3
-2,1,-4:17.3
-2,2,-4:17.3
3,-6,-3:17.3
-2,-5,-3:2
1,-5,-3:2
-3,-4,-3:2
-2,-4,-3:17.3
-1,-4,-3:17.3
0,-4,-3:17.3
1,-4,-3:17.3
2,-4,-3:2
-1,-3,-3:3
0,-3,-3:3
1,-3,-3:17.3
2,-3,-3:17.3
-2,-2,-3:3
-1,-2,-3:3
0,-2,-3:17.3
2,-2,-3:17.3
-1,-1,-3:17.3
0,-1,-3:3
1,-1,-3:3
-2,0,-3:3
-1,-5,-2:3
0,-5,-2:3
-2,-4,-2:3
-1,-4,-2:3
0,-4,-2:17.3
1,-4,-2:3
-2,-3,-2:3
-1,-3,-2:3
0,-3,-2:3
1,-3,-2:17.3
2,-3,-2:3
-2,-2,-2:3
-1,-2,-2:3
0,-2,-2:17.3
1,-2,-2:3
2,-2,-2:3
-2,-1,-2:3
-1,-1,-2:3
0,-1,-2:3
1,-1,-2:3
-2,0,-2:3
-1,0,-2:3
-1,-6,-1:2
-2,-5,-1:2
-1,-5,-1:2
0,-5,-1:2
1,-5,-1:2
-2,-4,-1:2
-1,-4,-1:2
0,-4,-1:2
1,-4,-1:2
2,-4,-1:2
-3,-3,-1:2
-2,-3,-1:2
-1,-3,-1:2
0,-3,-1:17.3
1,-3,-1:17.3
2,-3,-1:2
3,-3,-1:2
-3,-2,-1:2
-2,-2,-1:2
-1,-2,-1:2
0,-2,-1:17.3
1,-2,-1:17.3
2,-2,-1:2
3,-2,-1:2
-3,-1,-1:2
-2,-1,-1:2
-1,-1,-1:2
0,-1,-1:2
1,-1,-1:2
2,-1,-1:2
-2,0,-1:2
-1,0,-1:2
0,0,-1:2
1,0,-1:2
0,-3,1:17.3
1,-3,1:17.3
0,-2,1:17.3
1,-2,1:17.3
2,2,1:106.4
1,2,1:106.4
0,2,1:106.4
1,1,1:106.4
4,0,1:106.2
2,0,1:106.2
0,0,1:106.4
-1,0,1:106.4
-2,0,1:106.4
5,-1,1:106.2
3,-1,1:106.2
-2,-1,1:106.8
-3,-2,1:106.8
-4,-2,1:106.8
4,-3,1:106.2
-3,-3,1:106.8
-4,-3,1:106.8
3,-4,1:106.2
-2,-4,1:106.1
2,-5,1:106.1
1,-5,1:106.1
-1,-5,1:106.1
-3,-5,1:106.8
2,-6,1:106.1
-2,-6,1:106.1
-1,-7,1:106.1
-1,-4,2:18
0,-4,2:18
1,-4,2:18
2,-4,2:18
-2,-3,2:18
-1,-3,2:17.3
0,-3,2:17.3
1,-3,2:17.3
2,-3,2:18
3,-3,2:18
-2,-2,2:18
-1,-2,2:17.3
0,-2,2:17.3
1,-2,2:17.3
2,-2,2:18
3,-2,2:18
-1,-1,2:18
0,-1,2:18
1,-1,2:18
2,-1,2:18
1,0,2:18
2,2,2:106.4
1,2,2:106.4
0,2,2:106.4
1,1,2:106.4
-1,1,2:106.4
4,0,2:106.2
2,0,2:106.2
0,0,2:106.4
-1,0,2:106.4
-2,0,2:106.4
5,-1,2:106.2
3,-1,2:106.2
-2,-1,2:106.8
-3,-1,2:106.4
4,-2,2:106.2
-3,-2,2:106.8
-4,-2,2:106.8
4,-3,2:106.2
-3,-3,2:106.8
-4,-3,2:106.8
3,-4,2:106.2
-2,-4,2:106.1
-3,-4,2:106.8
3,-5,2:106.1
2,-5,2:106.1
1,-5,2:106.1
-1,-5,2:106.1
-3,-5,2:106.8
2,-6,2:106.1
-2,-6,2:106.1
-1,-7,2:106.1
-1,-6,3:18
0,-6,3:18
-2,-5,3:18
-1,-5,3:18
0,-5,3:18
1,-5,3:18
2,-5,3:18
-2,-4,3:18
-1,-4,3:18
0,-4,3:18
1,-4,3:18
2,-4,3:18
3,-4,3:18
-3,-3,3:18
-2,-3,3:18
-1,-3,3:17.3
0,-3,3:17.3
1,-3,3:17.3
2,-3,3:18
3,-3,3:18
4,-3,3:18
-3,-2,3:18
-2,-2,3:18
-1,-2,3:17.3
0,-2,3:17.3
1,-2,3:17.3
2,-2,3:18
3,-2,3:18
4,-2,3:18
-2,-1,3:18
-1,-1,3:18
0,-1,3:18
1,-1,3:18
2,-1,3:18
3,-1,3:18
4,-1,3:18
-1,0,3:18
0,0,3:18
1,0,3:18
2,0,3:18
3,0,3:18
0,1,3:18
1,1,3:18
2,1,3:18
2,2,3:106.4
1,2,3:106.4
0,2,3:106.4
3,1,3:106.4
-1,1,3:106.4
4,0,3:106.2
-2,0,3:106.4
5,-1,3:106.2
-3,-1,3:106.4
-4,-2,3:106.8
5,-3,3:106.2
-4,-3,3:106.8
4,-4,3:106.1
-3,-4,3:106.8
3,-5,3:106.1
-3,-5,3:106.8
2,-6,3:106.1
-2,-6,3:106.1
0,-7,3:106.1
-1,-7,3:106.1
-2,-5,4:18
-1,-5,4:18
0,-5,4:18
-3,-4,4:18
-2,-4,4:18
-1,-4,4:18
0,-4,4:18
1,-4,4:18
-3,-3,4:18
-2,-3,4:17.3
-1,-3,4:17.3
0,-3,4:17.3
1,-3,4:18
2,-3,4:18
-3,-2,4:18
-2,-2,4:17.3
-1,-2,4:17.3
0,-2,4:17.3
1,-2,4:18
2,-2,4:18
-3,-1,4:18
-2,-1,4:18
-1,-1,4:18
0,-1,4:18
1,-1,4:18
2,-1,4:18
-2,0,4:18
-1,0,4:18
0,0,4:18
1,0,4:18
-3,0,4:106.4
-4,-2,4:106.8
-2,-5,5:18
-3,-4,5:18
-2,-4,5:18
-1,-4,5:18
0,-4,5:18
-4,-3,5:18
-3,-3,5:18
-2,-3,5:17.3
-1,-3,5:17.3
0,-3,5:17.3
1,-3,5:18
-3,-2,5:18
-2,-2,5:17.3
-1,-2,5:17.3
0,-2,5:17.3
1,-2,5:18
-2,-1,5:18
-1,-1,5:18
0,-1,5:18
1,-1,5:18
5,0,5:106.2
-3,0,5:106.4
-4,-2,5:106.8
-3,-6,5:106.1
-3,-4,6:18
-2,-4,6:18
-1,-4,6:18
0,-4,6:18
-3,-3,6:18
-2,-3,6:17.3
-1,-3,6:17.3
0,-3,6:18
-3,-2,6:18
-2,-2,6:17.3
-1,-2,6:17.3
0,-2,6:18
-3,-1,6:18
-2,-1,6:18
-3,2,6:106.4
5,0,6:106.2
1,0,6:106.2
-3,0,6:106.4
2,-1,6:106.2
-4,-1,6:106.8
-4,-2,6:106.8
-6,-2,6:106.8
5,-3,6:106.2
-4,-3,6:106.8
-4,-4,6:106.8
-2,-6,6:106.1
-3,-6,6:106.1
-2,-4,7:18
-1,-4,7:18
-3,-3,7:18
-2,-3,7:17.3
-1,-3,7:17.3
0,-3,7:18
-3,-2,7:18
-2,-2,7:17.3
-1,-2,7:17.3
0,-2,7:18
1,-2,7:18
-3,-1,7:18
-2,-1,7:18
-1,-1,7:18
1,3,7:106.4
0,3,7:106.4
-3,2,7:106.4
5,0,7:106.2
1,0,7:106.2
-3,0,7:106.4
2,-1,7:106.2
-4,-1,7:106.8
-4,-2,7:106.8
-6,-2,7:106.8
5,-3,7:106.2
-4,-3,7:106.8
-4,-4,7:106.8
-2,-6,7:106.1
-3,-6,7:106.1
-2,-4,8:18
-1,-4,8:18
0,-4,8:18
-3,-3,8:18
-2,-3,8:17.3
-1,-3,8:17.3
0,-3,8:17.3
1,-3,8:18
-3,-2,8:18
-2,-2,8:17.3
-1,-2,8:17.3
0,-2,8:17.3
1,-2,8:18
2,-2,8:18
-3,-1,8:18
-2,-1,8:18
-1,-1,8:18
0,-1,8:18
1,-1,8:18
0,0,8:18
1,3,8:106.4
0,3,8:106.4
-3,2,8:106.4
5,0,8:106.2
1,0,8:106.2
-3,0,8:106.4
5,-1,8:106.2
2,-1,8:106.2
-4,-1,8:106.8
-6,-1,8:106.8
5,-2,8:106.2
-4,-2,8:106.8
-6,-2,8:106.8
5,-3,8:106.2
-4,-3,8:106.8
-6,-3,8:106.8
-4,-4,8:106.8
-6,-4,8:106.8
-4,-5,8:106.1
-2,-6,8:106.1
-3,-6,8:106.1
2,-7,8:106.1
-1,-7,8:106.1
-1,-6,9:18
-2,-5,9:18
-1,-5,9:18
1,-5,9:18
-3,-4,9:18
-2,-4,9:18
-1,-4,9:18
0,-4,9:18
1,-4,9:18
2,-4,9:18
-3,-3,9:18
-2,-3,9:17.3
-1,-3,9:17.3
0,-3,9:17.3
1,-3,9:18
2,-3,9:18
-4,-2,9:18
-3,-2,9:18
-2,-2,9:17.3
-1,-2,9:17.3
0,-2,9:17.3
1,-2,9:18
2,-2,9:18
3,-2,9:18
-4,-1,9:18
-3,-1,9:18
-2,-1,9:18
-1,-1,9:18
0,-1,9:18
1,-1,9:18
2,-1,9:18
-3,0,9:18
-2,0,9:18
-1,0,9:18
0,0,9:18
1,0,9:18
-2,1,9:18
1,3,9:106.4
0,3,9:106.4
-3,2,9:106.4
-4,1,9:106.4
5,0,9:106.2
5,-1,9:106.2
-6,-1,9:106.8
5,-2,9:106.2
-6,-2,9:106.8
5,-3,9:106.2
-4,-3,9:106.8
-6,-3,9:106.8
-4,-4,9:106.8
-6,-4,9:106.8
-4,-5,9:106.1
-5,-5,9:106.1
-2,-6,9:106.1
-3,-6,9:106.1
2,-7,9:106.1
0,-7,9:106.1
-1,-7,9:106.1
-1,-6,10:18
0,-6,10:18
1,-6,10:18
2,-6,10:18
-3,-5,10:18
-2,-5,10:18
-1,-5,10:18
0,-5,10:18
1,-5,10:18
2,-5,10:18
3,-5,10:18
-5,-4,10:18
-4,-4,10:18
-3,-4,10:18
-2,-4,10:18
-1,-4,10:18
0,-4,10:18
1,-4,10:18
2,-4,10:18
3,-4,10:18
-5,-3,10:18
-4,-3,10:18
-3,-3,10:18
-2,-3,10:18
-1,-3,10:17.3
0,-3,10:17.3
1,-3,10:17.3
2,-3,10:18
3,-3,10:18
4,-3,10:18
-5,-2,10:18
-4,-2,10:18
-3,-2,10:18
-2,-2,10:18
-1,-2,10:17.3
0,-2,10:17.3
1,-2,10:17.3
2,-2,10:18
3,-2,10:18
4,-2,10:18
-5,-1,10:18
-4,-1,10:18
-3,-1,10:18
-2,-1,10:18
-1,-1,10:18
0,-1,10:18
1,-1,10:18
2,-1,10:18
3,-1,10:18
4,-1,10:18
-4,0,10:18
-3,0,10:18
-2,0,10:18
-1,0,10:18
0,0,10:18
1,0,10:18
2,0,10:18
3,0,10:18
4,0,10:18
-3,1,10:18
-2,1,10:18
-1,1,10:18
0,1,10:18
1,1,10:18
2,1,10:18
-1,2,10:18
0,2,10:18
1,2,10:18
1,3,10:106.4
0,3,10:106.4
-1,3,10:106.4
-2,2,10:106.4
-3,2,10:106.4
-4,1,10:106.4
5,0,10:106.2
-5,0,10:106.4
5,-1,10:106.2
-6,-1,10:106.8
5,-2,10:106.2
-6,-2,10:106.8
5,-3,10:106.2
-6,-3,10:106.8
-6,-4,10:106.8
-4,-5,10:106.1
-5,-5,10:106.1
-3,-6,10:106.1
2,-7,10:106.1
0,-7,10:106.1
-1,-7,10:106.1
0,-5,11:18
1,-5,11:18
-2,-4,11:18
-1,-4,11:18
0,-4,11:18
1,-4,11:18
2,-4,11:18
-3,-3,11:18
-2,-3,11:18
-1,-3,11:18
0,-3,11:17.3
1,-3,11:17.3
2,-3,11:18
3,-3,11:18
-3,-2,11:18
-2,-2,11:18
-1,-2,11:18
0,-2,11:17.3
1,-2,11:17.3
2,-2,11:18
-3,-1,11:18
-2,-1,11:18
-1,-1,11:18
0,-1,11:18
1,-1,11:18
2,-1,11:18
-2,0,11:18
-1,0,11:18
0,0,11:18
1,0,11:18
0,1,11:18
0,2,11:106.4
2,1,11:106.4
-1,1,11:106
3,0,11:106
-3,0,11:106.8
-4,-1,11:106.8
-1,-5,11:106.8
0,-6,11:106.1
0,-4,12:18
1,-4,12:18
-1,-3,12:18
0,-3,12:17.3
1,-3,12:17.3
2,-3,12:18
-2,-2,12:18
-1,-2,12:18
0,-2,12:18
1,-2,12:17.3
2,-2,12:17.3
3,-2,12:18
-2,-1,12:18
-1,-1,12:18
0,-1,12:18
1,-1,12:17.3
2,-1,12:17.3
3,-1,12:18
-1,0,12:18
0,0,12:18
1,0,12:18
2,0,12:18
0,1,12:18
-2,3,12:106.4
0,2,12:106.4
2,1,12:106.4
-1,1,12:106
-5,1,12:106.8
3,0,12:106
-2,0,12:106.8
-3,0,12:106.8
-4,-1,12:106.8
1,-5,12:106.1
0,-5,12:106.1
1,-4,13:18
0,-3,13:18
1,-3,13:17.3
2,-3,13:18
-1,-2,13:18
0,-2,13:18
1,-2,13:17.3
2,-2,13:17.3
3,-2,13:18
0,-1,13:18
1,-1,13:17.3
2,-1,13:17.3
3,-1,13:18
0,0,13:18
1,0,13:18
2,0,13:18
-1,3,13:106.8
-2,3,13:106.4
2,1,13:106.4
-1,1,13:106.4
-5,1,13:106.8
4,0,13:106.2
3,0,13:106
-2,0,13:106.8
-3,0,13:106.8
-2,-1,13:106.8
-4,-1,13:106.8
-5,-2,13:106.8
4,-3,13:106.1
3,-4,13:106.1
0,-4,13:106.8
1,-5,13:106.1
0,-5,13:106.1
5,-6,13:106.1
1,-6,13:106.1
1,-3,14:18
2,-3,14:18
0,-2,14:18
1,-2,14:17.3
2,-2,14:17.3
3,-2,14:18
-1,-1,14:18
0,-1,14:17.3
1,-1,14:17.3
2,-1,14:17.3
3,-1,14:18
-1,0,14:18
0,0,14:17.3
1,0,14:17.3
2,0,14:18
0,1,14:18
1,1,14:18
2,4,14:106.4
3,3,14:106.4
-1,3,14:106.8
-2,3,14:106.4
2,1,14:106.4
-1,1,14:106.4
-5,1,14:106.8
4,0,14:106.2
3,0,14:106
-2,0,14:106.8
-3,0,14:106.8
7,-1,14:106.2
-2,-1,14:106.8
-4,-1,14:106.8
5,-2,14:106.2
-5,-2,14:106.8
4,-3,14:106.1
3,-4,14:106.1
0,-5,14:106.1
5,-6,14:106.1
1,-6,14:106.1
-2,-6,14:106.1
2,-3,15:18
3,-3,15:18
1,-2,15:18
2,-2,15:17.3
3,-2,15:18
4,-2,15:18
-1,-1,15:18
0,-1,15:17.3
1,-1,15:17.3
2,-1,15:17.3
3,-1,15:18
-1,0,15:18
0,0,15:17.3
1,0,15:17.3
2,0,15:18
0,1,15:18
1,1,15:18
2,4,15:106.4
0,4,15:106.4
3,3,15:106.4
1,3,15:106.4
0,3,15:106.4
-1,3,15:106.8
-2,3,15:106.4
4,2,15:106.2
0,2,15:106.4
4,1,15:106.2
2,1,15:106.4
-1,1,15:106.4
-5,1,15:106.8
4,0,15:106.2
3,0,15:106.4
-2,0,15:106.8
-3,0,15:106.8
7,-1,15:106.2
-2,-1,15:106.8
-4,-1,15:106.8
6,-2,15:106.2
5,-2,15:106.2
-5,-2,15:106.8
4,-3,15:106.1
1,-3,15:106.1
7,-4,15:106.2
3,-4,15:106.1
0,-5,15:106.1
5,-6,15:106.1
3,-6,15:106.1
1,-6,15:106.1
-2,-6,15:106.1
4,-7,15:106.1
1,-8,15:106.1
2,-3,16:18
3,-3,16:18
0,-2,16:18
1,-2,16:18
2,-2,16:18
3,-2,16:18
4,-2,16:18
-1,-1,16:18
0,-1,16:17.3
1,-1,16:17.3
2,-1,16:17.3
3,-1,16:18
-1,0,16:18
0,0,16:17.3
1,0,16:17.3
2,0,16:18
0,1,16:18
1,1,16:18
2,4,16:106.4
1,4,16:106.4
0,4,16:106.4
3,3,16:106.4
1,3,16:106.4
0,3,16:106.4
-1,3,16:106.8
-2,3,16:106.4
4,2,16:106.2
3,2,16:106.4
-3,2,16:106.8
-4,2,16:106.4
5,1,16:106.2
4,1,16:106.2
-1,1,16:106.4
-5,1,16:106.8
4,0,16:106.2
-3,0,16:106.8
7,-1,16:106.2
-4,-1,16:106.8
7,-2,16:106.2
6,-2,16:106.2
-5,-2,16:106.8
7,-3,16:106.2
4,-3,16:106.1
7,-4,16:106.2
3,-4,16:106.1
2,-4,16:106.1
0,-5,16:106.1
-3,-5,16:106.8
5,-6,16:106.1
3,-6,16:106.1
1,-6,16:106.1
0,-6,16:106.1
-2,-6,16:106.1
4,-7,16:106.1
1,-8,16:106.1
-2,-5,17:18
-2,-4,17:18
-1,-4,17:18
0,-4,17:18
-1,-3,17:18
0,-3,17:18
1,-3,17:18
2,-3,17:18
3,-3,17:18
-2,-2,17:18
-1,-2,17:18
0,-2,17:18
1,-2,17:18
2,-2,17:18
3,-2,17:18
4,-2,17:18
5,-2,17:18
-3,-1,17:18
-2,-1,17:18
-1,-1,17:18
0,-1,17:17.3
1,-1,17:17.3
2,-1,17:18
3,-1,17:18
4,-1,17:18
-2,0,17:18
-1,0,17:18
0,0,17:17.3
1,0,17:17.3
2,0,17:18
3,0,17:18
0,1,17:18
1,1,17:18
2,1,17:18
3,1,17:18
0,2,17:18
1,2,17:18
2,4,17:106.4
1,4,17:106.4
0,4,17:106.4
3,3,17:106.4
1,3,17:106.4
0,3,17:106.4
-1,3,17:106.8
-2,3,17:106.4
4,2,17:106.2
3,2,17:106.4
-3,2,17:106
-4,2,17:106.4
5,1,17:106.2
4,1,17:106.2
-1,1,17:106.4
-5,1,17:106.8
6,0,17:106.2
4,0,17:106.2
-3,0,17:106.8
-5,0,17:106.8
7,-1,17:106.2
-4,-1,17:106.8
-5,-1,17:106.8
7,-2,17:106.2
6,-2,17:106.2
-5,-2,17:106.8
7,-3,17:106.2
4,-3,17:106.1
7,-4,17:106.2
3,-4,17:106.1
0,-5,17:106.1
-3,-5,17:106.8
5,-6,17:106.1
3,-6,17:106.1
2,-6,17:106.1
1,-6,17:106.1
0,-6,17:106.1
-2,-6,17:106.1
4,-7,17:106.1
1,-8,17:106.1
-2,-6,18:18
-1,-6,18:18
-3,-5,18:18
-2,-5,18:18
-1,-5,18:18
0,-5,18:18
1,-5,18:18
2,-5,18:18
3,-5,18:18
4,-5,18:18
5,-5,18:18
-3,-4,18:18
-2,-4,18:18
-1,-4,18:18
0,-4,18:18
1,-4,18:18
2,-4,18:18
3,-4,18:18
4,-4,18:18
5,-4,18:18
6,-4,18:18
-4,-3,18:18
-3,-3,18:18
-2,-3,18:18
-1,-3,18:18
0,-3,18:18
1,-3,18:18
2,-3,18:18
3,-3,18:18
4,-3,18:18
5,-3,18:18
6,-3,18:18
-4,-2,18:18
-3,-2,18:18
-2,-2,18:18
-1,-2,18:18
0,-2,18:17.3
1,-2,18:18
2,-2,18:18
3,-2,18:18
4,-2,18:18
5,-2,18:18
6,-2,18:18
-4,-1,18:18
-3,-1,18:18
-2,-1,18:18
-1,-1,18:17.3
0,-1,18:17.3
1,-1,18:17.3
2,-1,18:18
3,-1,18:18
4,-1,18:18
5,-1,18:18
6,-1,18:18
-4,0,18:18
-3,0,18:18
-2,0,18:18
-1,0,18:18
0,0,18:17.3
1,0,18:17.3
2,0,18:18
3,0,18:18
4,0,18:18
5,0,18:18
-4,1,18:18
-3,1,18:18
-2,1,18:18
-1,1,18:18
0,1,18:18
1,1,18:18
2,1,18:18
3,1,18:18
4,1,18:18
-2,2,18:18
-1,2,18:18
0,2,18:18
1,2,18:18
2,2,18:18
3,2,18:18
0,3,18:18
1,3,18:18
2,3,18:18
2,4,18:106.4
1,4,18:106.4
0,4,18:106.4
3,3,18:106.4
-1,3,18:106.8
-2,3,18:106.4
4,2,18:106.2
-3,2,18:106
-4,2,18:106.4
5,1,18:106.2
-5,1,18:106.8
13,0,18:106.4
6,0,18:106.2
-5,0,18:106.8
7,-1,18:106.2
-5,-1,18:106.8
7,-2,18:106.2
-5,-2,18:106.8
7,-3,18:106.2
7,-4,18:106.2
12,-5,18:106.1
11,-6,18:106.1
5,-6,18:106.1
3,-6,18:106.1
2,-6,18:106.1
1,-6,18:106.1
0,-6,18:106.1
6,-7,18:106.1
4,-7,18:106.1
6,-8,18:106.1
5,-8,18:106.1
1,-8,18:106.1
-2,-4,19:18
-1,-4,19:18
0,-4,19:18
1,-4,19:18
2,-4,19:18
3,-4,19:18
4,-4,19:18
-3,-3,19:18
-2,-3,19:18
-1,-3,19:18
0,-3,19:18
1,-3,19:18
2,-3,19:18
3,-3,19:18
4,-3,19:18
-3,-2,19:18
-2,-2,19:18
-1,-2,19:17.3
0,-2,19:17.3
1,-2,19:18
2,-2,19:18
3,-2,19:18
4,-2,19:18
-2,-1,19:18
-1,-1,19:17.3
0,-1,19:17.3
1,-1,19:18
2,-1,19:18
3,-1,19:18
4,-1,19:18
-3,0,19:18
-2,0,19:18
-1,0,19:18
0,0,19:18
1,0,19:18
2,0,19:18
3,0,19:18
-1,1,19:18
0,1,19:18
1,1,19:18
2,1,19:18
2,2,19:18
4,3,19:106.2
-2,2,19:106.4
-3,2,19:106.4
13,0,19:106.4
5,-2,19:106.2
14,-3,19:106.2
7,-4,19:106.2
12,-5,19:106.1
-2,-5,19:106.1
11,-6,19:106.1
3,-6,19:106.1
-1,-6,19:106.1
8,-7,19:106.2
6,-7,19:106.1
5,-7,19:106.1
4,-7,19:106.1
6,-8,19:106.1
5,-8,19:106.1
1,-8,19:106.1
-1,-4,20:18
0,-4,20:18
1,-4,20:18
2,-4,20:18
3,-4,20:18
4,-4,20:18
-2,-3,20:18
-1,-3,20:18
0,-3,20:17.3
1,-3,20:17.3
2,-3,20:17.3
3,-3,20:18
-2,-2,20:18
-1,-2,20:17.3
0,-2,20:17.3
1,-2,20:17.3
2,-2,20:18
3,-2,20:18
-2,-1,20:18
-1,-1,20:18
0,-1,20:18
1,-1,20:18
2,-1,20:18
-1,0,20:18
0,0,20:18
2,0,20:18
3,4,20:106.4
4,3,20:106.2
0,3,20:106.4
-2,2,20:106.4
-3,2,20:106.4
-4,2,20:106.4
13,0,20:106.4
14,-1,20:106.2
-4,-1,20:106.8
5,-2,20:106.2
-3,-2,20:106.8
14,-3,20:106.2
5,-3,20:106.2
7,-4,20:106.2
6,-4,20:106.2
-2,-4,20:106.1
13,-5,20:106.1
12,-5,20:106.1
-2,-5,20:106.1
11,-6,20:106.1
8,-6,20:106.2
3,-6,20:106.1
-1,-6,20:106.1
8,-7,20:106.2
6,-7,20:106.1
5,-7,20:106.1
4,-7,20:106.1
1,-7,20:106.1
8,-8,20:106.2
6,-8,20:106.1
5,-8,20:106.1
2,-8,20:106.1
1,-8,20:106.1
-1,-8,20:106.1
-3,-8,20:106.2
3,-9,20:106.1
1,-9,20:106.1
5,-10,20:106.1
4,-6,21:18
5,-6,21:18
6,-6,21:18
-1,-5,21:18
3,-5,21:18
4,-5,21:18
5,-5,21:18
-2,-4,21:18
-1,-4,21:17.3
0,-4,21:18
1,-4,21:18
2,-4,21:18
3,-4,21:17.3
4,-4,21:17.3
5,-4,21:18
-2,-3,21:18
-1,-3,21:17.3
0,-3,21:17.3
1,-3,21:18
2,-3,21:17.3
3,-3,21:17.3
4,-3,21:18
-2,-2,21:18
-1,-2,21:17.3
0,-2,21:17.3
1,-2,21:18
2,-2,21:18
3,-2,21:18
-3,-1,21:18
-2,-1,21:18
-1,-1,21:18
0,-1,21:18
1,-1,21:18
2,-1,21:18
-1,0,21:18
0,0,21:18
6,6,21:106.4
3,5,21:106.4
4,4,21:106.4
3,4,21:106.4
4,3,21:106.2
0,3,21:106.4
7,2,21:106.2
4,2,21:106.2
1,2,21:106.4
-2,2,21:106.4
-3,2,21:106.4
-4,2,21:106.4
13,0,21:106.4
14,-1,21:106.2
-4,-1,21:106.8
-5,-1,21:106.8
5,-2,21:106.2
14,-3,21:106.2
5,-3,21:106.2
13,-4,21:106.1
7,-4,21:106.2
6,-4,21:106.2
13,-5,21:106.1
12,-5,21:106.1
7,-5,21:106.2
-2,-5,21:106.1
11,-6,21:106.1
8,-6,21:106.2
3,-6,21:106.1
-1,-6,21:106.1
8,-7,21:106.2
6,-7,21:106.1
5,-7,21:106.1
4,-7,21:106.1
1,-7,21:106.1
8,-8,21:106.2
6,-8,21:106.1
5,-8,21:106.1
3,-8,21:106.1
2,-8,21:106.1
1,-8,21:106.1
0,-8,21:106.1
-1,-8,21:106.1
-2,-8,21:106.1
-3,-8,21:106.2
6,-9,21:106.1
3,-9,21:106.1
1,-9,21:106.1
-1,-9,21:106.1
5,-10,21:106.1
4,-10,21:106.1
8,-11,21:106.1
5,-7,22:18
6,-7,22:18
-3,-6,22:18
-2,-6,22:18
1,-6,22:18
4,-6,22:18
5,-6,22:17.3
6,-6,22:18
-4,-5,22:18
-3,-5,22:17.3
-2,-5,22:17.3
-1,-5,22:18
1,-5,22:18
2,-5,22:18
3,-5,22:18
4,-5,22:17.3
5,-5,22:17.3
6,-5,22:18
-3,-4,22:18
-2,-4,22:17.3
-1,-4,22:17.3
0,-4,22:18
1,-4,22:18
2,-4,22:18
3,-4,22:18
4,-4,22:17.3
5,-4,22:18
-2,-3,22:18
-1,-3,22:17.3
0,-3,22:18
1,-3,22:18
2,-3,22:18
3,-3,22:18
4,-3,22:18
-3,-2,22:18
-2,-2,22:17.3
-1,-2,22:17.3
0,-2,22:17.3
1,-2,22:18
2,-2,22:18
3,-2,22:18
4,-2,22:18
-3,-1,22:18
-2,-1,22:18
-1,-1,22:18
0,-1,22:17.3
1,-1,22:18
2,-1,22:18
-2,0,22:18
-1,0,22:18
0,0,22:18
1,0,22:18
2,0,22:18
0,1,22:18
2,1,22:18
6,6,22:106.4
3,5,22:106.4
4,4,22:106.4
3,4,22:106.4
4,3,22:106.2
0,3,22:106.4
9,2,22:106.4
7,2,22:106.2
4,2,22:106.2
1,2,22:106.4
-2,2,22:106.4
-3,2,22:106.4
-4,2,22:106.4
13,0,22:106.4
12,0,22:106.4
14,-1,22:106.2
-4,-1,22:106.8
-5,-1,22:106.8
-6,-1,22:106.8
5,-2,22:106.2
14,-3,22:106.2
5,-3,22:106.2
-6,-3,22:106.8
13,-4,22:106.1
7,-4,22:106.2
6,-4,22:106.2
14,-5,22:106.1
13,-5,22:106.1
12,-5,22:106.1
7,-5,22:106.2
11,-6,22:106.1
8,-6,22:106.2
8,-7,22:106.2
4,-7,22:106.1
1,-7,22:106.1
8,-8,22:106.2
6,-8,22:106.1
5,-8,22:106.1
3,-8,22:106.1
2,-8,22:106.1
1,-8,22:106.1
0,-8,22:106.1
-1,-8,22:106.1
-2,-8,22:106.1
-3,-8,22:106.2
-5,-8,22:106.8
9,-9,22:106.2
6,-9,22:106.1
4,-9,22:106.1
3,-9,22:106.1
1,-9,22:106.1
-1,-9,22:106.1
9,-10,22:106.2
5,-10,22:106.1
4,-10,22:106.1
3,-10,22:106.1
2,-10,22:106.1
8,-11,22:106.1
8,-12,22:106.1
6,-8,23:18
-4,-7,23:18
-3,-7,23:18
-2,-7,23:18
1,-7,23:18
5,-7,23:18
6,-7,23:17.3
7,-7,23:18
-5,-6,23:18
-4,-6,23:17.3
-3,-6,23:17.3
-2,-6,23:18
-1,-6,23:18
0,-6,23:18
1,-6,23:18
2,-6,23:18
4,-6,23:18
5,-6,23:17.3
6,-6,23:17.3
7,-6,23:18
-4,-5,23:18
-3,-5,23:17.3
-2,-5,23:18
-1,-5,23:18
0,-5,23:18
1,-5,23:17.1
2,-5,23:18
3,-5,23:18
4,-5,23:18
5,-5,23:18
6,-5,23:18
-4,-4,23:18
-3,-4,23:18
-2,-4,23:18
-1,-4,23:18
0,-4,23:18
1,-4,23:18
2,-4,23:18
3,-4,23:18
4,-4,23:17.3
5,-4,23:18
-5,-3,23:18
-4,-3,23:18
-3,-3,23:18
-2,-3,23:18
-1,-3,23:18
0,-3,23:17.1
1,-3,23:18
2,-3,23:18
3,-3,23:18
4,-3,23:18
5,-3,23:18
-4,-2,23:18
-3,-2,23:18
-2,-2,23:17.3
-1,-2,23:18
0,-2,23:18
1,-2,23:18
2,-2,23:18
3,-2,23:18
-4,-1,23:18
-3,-1,23:17.3
-2,-1,23:18
-1,-1,23:18
0,-1,23:17.3
1,-1,23:17.3
2,-1,23:18
-3,0,23:18
-2,0,23:18
-1,0,23:18
0,0,23:18
1,0,23:17.3
2,0,23:18
-4,1,23:18
-3,1,23:18
-2,1,23:18
-1,1,23:18
0,1,23:18
1,1,23:18
2,1,23:17.3
3,1,23:18
2,2,23:18
3,2,23:18
6,6,23:106.4
3,5,23:106.4
7,4,23:106.2
4,4,23:106.4
3,4,23:106.4
-2,4,23:106.4
4,3,23:106.2
0,3,23:106.4
9,2,23:106.4
7,2,23:106.2
4,2,23:106.2
1,2,23:106.4
-1,2,23:106.4
-2,2,23:106.4
-3,2,23:106.4
-4,2,23:106.4
-5,2,23:106.4
13,0,23:106.4
12,0,23:106.4
14,-1,23:106.2
13,-1,23:106.2
-5,-1,23:106.8
-6,-1,23:106.8
-7,-1,23:106.1
15,-3,23:106.2
14,-3,23:106.2
-6,-3,23:106.8
13,-4,23:106.1
7,-4,23:106.2
14,-5,23:106.1
13,-5,23:106.1
12,-5,23:106.1
11,-6,23:106.1
8,-6,23:106.2
-6,-6,23:106.8
8,-7,23:106.2
4,-7,23:106.1
8,-8,23:106.2
5,-8,23:106.1
3,-8,23:106.1
2,-8,23:106.1
1,-8,23:106.1
0,-8,23:106.1
-1,-8,23:106.1
-2,-8,23:106.1
-3,-8,23:106.2
-5,-8,23:106.8
9,-9,23:106.2
6,-9,23:106.1
4,-9,23:106.1
3,-9,23:106.1
1,-9,23:106.1
-1,-9,23:106.1
-2,-9,23:106.1
-4,-9,23:106.1
-5,-9,23:106.1
9,-10,23:106.2
5,-10,23:106.1
4,-10,23:106.1
3,-10,23:106.1
2,-10,23:106.1
8,-11,23:106.1
8,-12,23:106.1
-4,-8,24:18
6,-8,24:18
7,-8,24:18
-5,-7,24:18
-4,-7,24:17.3
-3,-7,24:18
-2,-7,24:18
-1,-7,24:18
0,-7,24:18
1,-7,24:18
2,-7,24:18
3,-7,24:18
5,-7,24:18
6,-7,24:17.3
7,-7,24:18
-5,-6,24:18
-4,-6,24:17.3
-3,-6,24:18
-2,-6,24:18
-1,-6,24:18
0,-6,24:18
1,-6,24:18
2,-6,24:17.1
3,-6,24:18
4,-6,24:18
5,-6,24:18
6,-6,24:18
-4,-5,24:18
-3,-5,24:18
-2,-5,24:18
-1,-5,24:18
0,-5,24:18
1,-5,24:18
2,-5,24:18
3,-5,24:18
4,-5,24:18
5,-5,24:18
6,-5,24:18
-4,-4,24:18
-3,-4,24:18
-2,-4,24:18
0,-4,24:17.3
1,-4,24:18
2,-4,24:18
3,-4,24:18
4,-4,24:17.3
5,-4,24:18
6,-4,24:18
-4,-3,24:18
-3,-3,24:18
-2,-3,24:18
-1,-3,24:18
0,-3,24:17.3
1,-3,24:18
2,-3,24:18
3,-3,24:18
4,-3,24:18
5,-3,24:17.3
6,-3,24:18
-4,-2,24:18
-3,-2,24:18
-2,-2,24:18
-1,-2,24:18
0,-2,24:18
1,-2,24:18
2,-2,24:18
3,-2,24:18
5,-2,24:18
6,-2,24:18
7,-2,24:18
-5,-1,24:18
-4,-1,24:17.3
-3,-1,24:17.3
-2,-1,24:18
-1,-1,24:18
0,-1,24:18
1,-1,24:18
2,-1,24:18
3,-1,24:18
-4,0,24:18
-3,0,24:18
-2,0,24:18
-1,0,24:18
0,0,24:18
1,0,24:17.3
2,0,24:18
3,0,24:18
-3,1,24:18
-2,1,24:18
-1,1,24:18
0,1,24:18
1,1,24:18
2,1,24:17.3
3,1,24:17.3
4,1,24:18
-1,2,24:18
2,2,24:18
3,2,24:17.3
4,2,24:18
3,3,24:18
6,6,24:106.4
6,5,24:106.4
3,5,24:106.4
7,4,24:106.2
4,4,24:106.4
3,4,24:106.4
2,4,24:106.4
-2,4,24:106.4
7,3,24:106.2
4,3,24:106.2
1,3,24:106.4
0,3,24:106.4
-1,3,24:106.4
9,2,24:106.4
7,2,24:106.2
-5,2,24:106.4
11,1,24:106.4
-7,1,24:106.8
13,0,24:106.4
12,0,24:106.4
14,-1,24:106.2
13,-1,24:106.2
-6,-1,24:106.8
-7,-1,24:106.1
-7,-2,24:106.8
15,-3,24:106.2
14,-3,24:106.2
-5,-3,24:106.8
13,-4,24:106.1
7,-4,24:106.2
14,-5,24:106.1
13,-5,24:106.1
12,-5,24:106.1
9,-5,24:106.1
7,-5,24:106.2
11,-6,24:106.1
-6,-7,24:106.8
8,-8,24:106.2
3,-8,24:106.1
2,-8,24:106.1
1,-8,24:106.1
0,-8,24:106.1
-1,-8,24:106.1
-2,-8,24:106.1
-3,-8,24:106.2
-5,-8,24:106.8
-7,-8,24:106.8
9,-9,24:106.2
6,-9,24:106.1
4,-9,24:106.1
3,-9,24:106.1
1,-9,24:106.1
-1,-9,24:106.1
-2,-9,24:106.1
-4,-9,24:106.1
-5,-9,24:106.1
-6,-9,24:106.1
9,-10,24:106.2
5,-10,24:106.1
4,-10,24:106.1
3,-10,24:106.1
2,-10,24:106.1
8,-11,24:106.1
7,-11,24:106.1
0,-11,24:106.1
-1,-11,24:106.1
8,-12,24:106.1
6,-12,24:106.1
8,-13,24:106.1
0,-9,25:18
7,-9,25:18
-6,-8,25:18
-5,-8,25:18
-1,-8,25:18
0,-8,25:18
1,-8,25:18
2,-8,25:18
3,-8,25:18
4,-8,25:18
5,-8,25:18
6,-8,25:18
7,-8,25:18
-5,-7,25:18
-4,-7,25:18
-2,-7,25:18
-1,-7,25:18
0,-7,25:18
1,-7,25:18
2,-7,25:18
3,-7,25:17.1
4,-7,25:18
5,-7,25:18
6,-7,25:18
7,-7,25:18
-4,-6,25:18
-3,-6,25:18
-2,-6,25:18
-1,-6,25:18
0,-6,25:18
1,-6,25:18
2,-6,25:17.1
3,-6,25:18
4,-6,25:18
5,-6,25:18
6,-6,25:18
-4,-5,25:18
-3,-5,25:18
-2,-5,25:18
-1,-5,25:17.3
0,-5,25:18
1,-5,25:18
2,-5,25:18
3,-5,25:18
4,-5,25:18
5,-5,25:18
6,-5,25:18
-4,-4,25:18
-3,-4,25:18
-2,-4,25:18
-1,-4,25:17.3
0,-4,25:17.3
1,-4,25:18
2,-4,25:18
3,-4,25:18
4,-4,25:18
5,-4,25:18
6,-4,25:18
-4,-3,25:18
-3,-3,25:18
-2,-3,25:18
-1,-3,25:18
0,-3,25:17.3
1,-3,25:18
2,-3,25:18
3,-3,25:18
4,-3,25:18
5,-3,25:17.3
6,-3,25:18
7,-3,25:18
8,-3,25:18
-4,-2,25:18
-3,-2,25:18
-2,-2,25:18
-1,-2,25:18
0,-2,25:18
1,-2,25:18
2,-2,25:18
3,-2,25:18
4,-2,25:18
5,-2,25:18
6,-2,25:17.3
7,-2,25:18
8,-2,25:18
9,-2,25:18
10,-2,25:18
-5,-1,25:18
-4,-1,25:17.3
-3,-1,25:18
-2,-1,25:18
-1,-1,25:18
0,-1,25:18
1,-1,25:18
2,-1,25:18
3,-1,25:18
4,-1,25:18
6,-1,25:18
7,-1,25:18
8,-1,25:18
9,-1,25:18
-5,0,25:18
-4,0,25:17.3
-3,0,25:18
-2,0,25:18
-1,0,25:18
0,0,25:18
1,0,25:18
2,0,25:18
3,0,25:18
4,0,25:18
7,0,25:18
8,0,25:18
9,0,25:18
-4,1,25:18
-3,1,25:18
-2,1,25:18
-1,1,25:18
0,1,25:18
1,1,25:18
2,1,25:18
3,1,25:18
4,1,25:18
5,1,25:18
-2,2,25:18
-1,2,25:18
0,2,25:18
1,2,25:18
2,2,25:18
3,2,25:17.3
4,2,25:17.3
5,2,25:18
-2,3,25:18
3,3,25:18
4,3,25:18
5,3,25:18
6,6,25:106.4
6,5,25:106.4
3,5,25:106.4
8,4,25:106.2
7,4,25:106.2
4,4,25:106.4
2,4,25:106.4
-2,4,25:106.4
7,3,25:106.2
1,3,25:106.4
0,3,25:106.4
-1,3,25:106.4
-5,3,25:106.4
-6,3,25:106.4
9,2,25:106.4
8,2,25:106.4
7,2,25:106.2
-5,2,25:106.4
-7,2,25:106.8
-9,2,25:106.8
11,1,25:106.4
-7,1,25:106.8
13,0,25:106.4
12,0,25:106.4
-8,0,25:106.8
14,-1,25:106.2
13,-1,25:106.2
-7,-1,25:106.1
15,-2,25:106.2
-7,-2,25:106.8
15,-3,25:106.2
14,-3,25:106.2
-5,-3,25:106.8
-7,-3,25:106.8
15,-4,25:106.2
13,-4,25:106.1
-7,-4,25:106.8
14,-5,25:106.1
13,-5,25:106.1
12,-5,25:106.1
10,-5,25:106.1
9,-5,25:106.1
7,-5,25:106.2
11,-6,25:106.1
-5,-6,25:106.8
8,-8,25:106.2
-7,-8,25:106.8
9,-9,25:106.2
4,-9,25:106.1
3,-9,25:106.1
1,-9,25:106.1
-1,-9,25:106.1
-2,-9,25:106.1
-5,-9,25:106.1
-6,-9,25:106.1
9,-10,25:106.2
5,-10,25:106.1
4,-10,25:106.1
3,-10,25:106.1
2,-10,25:106.1
0,-10,25:106.1
8,-11,25:106.1
7,-11,25:106.1
1,-11,25:106.1
0,-11,25:106.1
-1,-11,25:106.1
9,-12,25:106.2
8,-12,25:106.1
6,-12,25:106.1
8,-13,25:106.1
7,-10,26:18
8,-10,26:18
1,-9,26:18
2,-9,26:18
4,-9,26:18
5,-9,26:18
6,-9,26:18
7,-9,26:18
-6,-8,26:18
-5,-8,26:18
-3,-8,26:18
-2,-8,26:18
-1,-8,26:18
0,-8,26:18
1,-8,26:18
2,-8,26:18
3,-8,26:18
4,-8,26:17.1
5,-8,26:18
6,-8,26:18
7,-8,26:18
-5,-7,26:18
-4,-7,26:18
-3,-7,26:18
-2,-7,26:18
-1,-7,26:18
0,-7,26:18
1,-7,26:18
2,-7,26:18
3,-7,26:17.1
4,-7,26:18
5,-7,26:18
-5,-6,26:18
-4,-6,26:18
-3,-6,26:18
-2,-6,26:18
-1,-6,26:18
0,-6,26:18
1,-6,26:18
2,-6,26:18
3,-6,26:18
4,-6,26:18
5,-6,26:18
-5,-5,26:18
-4,-5,26:18
-3,-5,26:18
-2,-5,26:17.3
-1,-5,26:18
0,-5,26:18
1,-5,26:18
2,-5,26:18
3,-5,26:18
4,-5,26:18
5,-5,26:18
6,-5,26:18
-6,-4,26:18
-5,-4,26:18
-4,-4,26:18
-3,-4,26:18
-2,-4,26:18
-1,-4,26:18
0,-4,26:18
1,-4,26:18
2,-4,26:18
3,-4,26:18
4,-4,26:18
5,-4,26:18
6,-4,26:18
7,-4,26:18
9,-4,26:18
-6,-3,26:18
-5,-3,26:18
-4,-3,26:18
-3,-3,26:18
-2,-3,26:18
-1,-3,26:18
0,-3,26:18
1,-3,26:17.3
2,-3,26:18
3,-3,26:18
4,-3,26:18
5,-3,26:18
6,-3,26:18
7,-3,26:18
8,-3,26:18
9,-3,26:18
10,-3,26:18
12,-3,26:18
13,-3,26:18
-6,-2,26:18
-5,-2,26:18
-4,-2,26:18
-3,-2,26:18
-2,-2,26:18
-1,-2,26:18
0,-2,26:18
1,-2,26:18
2,-2,26:17.3
3,-2,26:18
4,-2,26:18
5,-2,26:18
6,-2,26:17.3
7,-2,26:17.3
8,-2,26:17.1
9,-2,26:17.3
10,-2,26:18
11,-2,26:18
-5,-1,26:18
-4,-1,26:18
-3,-1,26:18
-2,-1,26:18
-1,-1,26:18
0,-1,26:18
1,-1,26:18
2,-1,26:18
3,-1,26:18
4,-1,26:18
5,-1,26:18
6,-1,26:18
7,-1,26:18
8,-1,26:18
9,-1,26:18
10,-1,26:18
-6,0,26:18
-5,0,26:17.3
-4,0,26:17.3
-3,0,26:18
-2,0,26:18
-1,0,26:18
0,0,26:18
1,0,26:18
2,0,26:18
3,0,26:18
4,0,26:18
5,0,26:18
6,0,26:18
7,0,26:18
8,0,26:18
9,0,26:18
-6,1,26:18
-5,1,26:18
-4,1,26:18
-3,1,26:18
-2,1,26:18
-1,1,26:18
0,1,26:18
1,1,26:18
2,1,26:18
3,1,26:18
4,1,26:18
5,1,26:18
6,1,26:18
7,1,26:18
8,1,26:18
9,1,26:18
-6,2,26:18
-3,2,26:18
-2,2,26:18
-1,2,26:18
1,2,26:18
2,2,26:18
3,2,26:18
4,2,26:18
5,2,26:18
6,2,26:18
-1,3,26:18
2,3,26:18
3,3,26:18
4,3,26:18
5,3,26:18
6,3,26:18
3,4,26:18
5,4,26:18
6,4,26:18
7,6,26:106.4
6,6,26:106.4
6,5,26:106.4
5,5,26:106.4
3,5,26:106.4
8,4,26:106.2
7,4,26:106.2
4,4,26:106.4
2,4,26:106.4
7,3,26:106.2
1,3,26:106.4
-2,3,26:106.4
-5,3,26:106.4
-6,3,26:106.4
-8,3,26:106.4
10,2,26:106.4
9,2,26:106.4
8,2,26:106.4
7,2,26:106.2
-4,2,26:106.4
-5,2,26:106.4
-7,2,26:106
-9,2,26:106.8
11,1,26:106.4
-7,1,26:106.8
-9,1,26:106.8
13,0,26:106.4
12,0,26:106.4
-8,0,26:106.8
14,-1,26:106.2
13,-1,26:106.2
-7,-1,26:106
15,-2,26:106.2
-7,-2,26:106.8
15,-3,26:106.2
14,-3,26:106.2
-7,-3,26:106.8
15,-4,26:106.2
13,-4,26:106.1
-7,-4,26:106.8
14,-5,26:106.1
13,-5,26:106.1
12,-5,26:106.1
10,-5,26:106.1
9,-5,26:106.1
8,-5,26:106.2
7,-5,26:106.2
11,-6,26:106.1
6,-7,26:106.4
8,-8,26:106.2
-7,-8,26:106.8
9,-9,26:106.2
0,-9,26:106.1
-1,-9,26:106.1
-2,-9,26:106.1
-3,-9,26:106.1
-5,-9,26:106.1
-6,-9,26:106.1
9,-10,26:106.2
5,-10,26:106.1
4,-10,26:106.1
3,-10,26:106.1
2,-10,26:106.1
-4,-10,26:106.1
-6,-10,26:106.1
9,-11,26:106.2
8,-11,26:106.1
7,-11,26:106.1
1,-11,26:106.1
0,-11,26:106.1
-1,-11,26:106.1
-7,-11,26:106.1
9,-12,26:106.2
8,-12,26:106.1
6,-12,26:106.1
8,-13,26:106.1
7,-12,27:18
6,-11,27:18
7,-11,27:18
8,-11,27:18
-1,-10,27:18
0,-10,27:18
1,-10,27:18
4,-10,27:18
5,-10,27:18
6,-10,27:18
7,-10,27:18
8,-10,27:18
-6,-9,27:18
-5,-9,27:18
-4,-9,27:18
-1,-9,27:18
0,-9,27:18
1,-9,27:18
2,-9,27:18
3,-9,27:18
4,-9,27:18
5,-9,27:18
6,-9,27:18
7,-9,27:18
8,-9,27:18
-6,-8,27:18
-5,-8,27:18
-4,-8,27:18
-3,-8,27:18
-2,-8,27:18
-1,-8,27:18
0,-8,27:18
1,-8,27:18
2,-8,27:18
3,-8,27:18
4,-8,27:18
5,-8,27:18
6,-8,27:18
7,-8,27:18
-5,-7,27:18
-4,-7,27:18
-3,-7,27:18
-2,-7,27:18
-1,-7,27:18
0,-7,27:18
1,-7,27:18
2,-7,27:18
3,-7,27:18
4,-7,27:18
5,-7,27:18
-4,-6,27:18
-3,-6,27:18
-2,-6,27:18
-1,-6,27:17.1
0,-6,27:18
1,-6,27:18
2,-6,27:18
3,-6,27:18
4,-6,27:18
5,-6,27:18
6,-6,27:18
-3,-5,27:18
-2,-5,27:18
0,-5,27:18
1,-5,27:18
2,-5,27:18
3,-5,27:18
4,-5,27:18
5,-5,27:18
6,-5,27:18
7,-5,27:18
11,-5,27:18
-5,-4,27:18
-4,-4,27:18
-3,-4,27:18
-2,-4,27:18
-1,-4,27:18
0,-4,27:18
1,-4,27:18
2,-4,27:18
3,-4,27:18
4,-4,27:18
5,-4,27:18
6,-4,27:18
7,-4,27:18
8,-4,27:18
9,-4,27:18
10,-4,27:18
11,-4,27:18
12,-4,27:18
13,-4,27:18
-6,-3,27:18
-5,-3,27:18
-4,-3,27:18
-3,-3,27:18
-2,-3,27:18
-1,-3,27:18
0,-3,27:18
1,-3,27:18
2,-3,27:18
3,-3,27:18
4,-3,27:18
5,-3,27:18
6,-3,27:18
7,-3,27:18
8,-3,27:18
9,-3,27:18
10,-3,27:18
11,-3,27:17.3
12,-3,27:18
13,-3,27:18
-6,-2,27:18
-5,-2,27:18
-4,-2,27:18
-3,-2,27:18
-2,-2,27:18
-1,-2,27:18
0,-2,27:18
1,-2,27:18
2,-2,27:18
3,-2,27:18
4,-2,27:18
6,-2,27:18
7,-2,27:18
8,-2,27:18
9,-2,27:18
10,-2,27:17.3
11,-2,27:17.3
12,-2,27:18
13,-2,27:18
-6,-1,27:18
-5,-1,27:18
-4,-1,27:18
-3,-1,27:18
-2,-1,27:18
-1,-1,27:18
0,-1,27:18
1,-1,27:18
2,-1,27:18
3,-1,27:18
4,-1,27:18
5,-1,27:18
6,-1,27:18
7,-1,27:18
8,-1,27:18
9,-1,27:18
10,-1,27:18
11,-1,27:18
12,-1,27:18
-7,0,27:18
-6,0,27:18
-5,0,27:17.3
-4,0,27:18
-3,0,27:18
-2,0,27:18
-1,0,27:18
0,0,27:18
1,0,27:18
2,0,27:18
3,0,27:18
4,0,27:18
5,0,27:18
6,0,27:18
7,0,27:18
8,0,27:18
9,0,27:18
10,0,27:18
11,0,27:18
-7,1,27:18
-6,1,27:18
-5,1,27:18
-4,1,27:18
-2,1,27:18
2,1,27:18
3,1,27:18
4,1,27:18
5,1,27:18
6,1,27:18
10,1,27:18
-6,2,27:18
-2,2,27:18
3,2,27:18
4,2,27:18
5,2,27:18
6,2,27:18
4,3,27:18
5,3,27:18
5,4,27:18
6,4,27:18
7,6,27:106.4
6,6,27:106.4
8,5,27:106.2
6,5,27:106.4
5,5,27:106.4
8,4,27:106.2
7,4,27:106.2
6,3,27:106.4
-5,3,27:106.4
-6,3,27:106.4
-7,3,27:106.4
-8,3,27:106.4
10,2,27:106.4
7,2,27:106.2
-4,2,27:106.4
-5,2,27:106.4
-7,2,27:106.4
-9,2,27:106.8
11,1,27:106.4
8,1,27:106.4
7,1,27:106.2
-1,1,27:106.4
-8,1,27:106.8
-9,1,27:106.8
13,0,27:106.4
12,0,27:106.4
-8,0,27:106.8
14,-1,27:106.2
13,-1,27:106.2
-7,-1,27:106
15,-2,27:106.2
15,-3,27:106.2
15,-4,27:106.2
14,-5,27:106.1
13,-5,27:106.1
12,-5,27:106.1
10,-5,27:106.1
9,-5,27:106.1
8,-5,27:106.2
11,-6,27:106.1
6,-7,27:106.4
8,-8,27:106.2
-7,-8,27:106.8
9,-9,27:106.2
-2,-9,27:106.1
9,-10,27:106.2
3,-10,27:106.1
-4,-10,27:106.1
-6,-10,27:106.1
9,-11,27:106.2
5,-11,27:106.1
1,-11,27:106.1
0,-11,27:106.1
-1,-11,27:106.1
-5,-11,27:106.1
-6,-11,27:106.1
-7,-11,27:106.1
9,-12,27:106.2
8,-12,27:106.1
6,-12,27:106.1
8,-13,27:106.1
7,-13,27:106.1
8,-12,28:18
7,-11,28:18
-7,-10,28:18
-6,-10,28:18
-5,-10,28:18
5,-10,28:18
6,-10,28:18
7,-10,28:18
-8,-9,28:18
-7,-9,28:18
-6,-9,28:18
-5,-9,28:18
0,-9,28:18
4,-9,28:18
5,-9,28:18
6,-9,28:18
-7,-8,28:18
-6,-8,28:18
-5,-8,28:18
-4,-8,28:18
-1,-8,28:18
0,-8,28:18
1,-8,28:18
4,-8,28:18
-5,-7,28:18
-4,-7,28:18
1,-7,28:18
2,-7,28:18
3,-7,28:18
4,-7,28:18
-3,-6,28:18
-2,-6,28:18
-1,-6,28:18
0,-6,28:18
1,-6,28:18
2,-6,28:18
3,-6,28:18
5,-6,28:18
6,-6,28:18
-1,-5,28:18
0,-5,28:18
1,-5,28:18
2,-5,28:18
3,-5,28:18
11,-5,28:18
-4,-4,28:18
-2,-4,28:18
-1,-4,28:18
0,-4,28:18
1,-4,28:18
2,-4,28:18
3,-4,28:18
4,-4,28:18
8,-4,28:18
11,-4,28:18
12,-4,28:18
13,-4,28:18
14,-4,28:18
-5,-3,28:18
-4,-3,28:18
-3,-3,28:18
-2,-3,28:18
-1,-3,28:18
0,-3,28:18
1,-3,28:18
2,-3,28:18
3,-3,28:18
7,-3,28:18
10,-3,28:18
11,-3,28:18
12,-3,28:18
13,-3,28:18
14,-3,28:18
-4,-2,28:18
-3,-2,28:18
-2,-2,28:18
-1,-2,28:18
0,-2,28:18
1,-2,28:18
2,-2,28:18
3,-2,28:18
6,-2,28:18
8,-2,28:18
9,-2,28:18
10,-2,28:18
11,-2,28:18
12,-2,28:18
13,-2,28:18
14,-2,28:18
-5,-1,28:18
-4,-1,28:18
-2,-1,28:18
-1,-1,28:18
0,-1,28:18
2,-1,28:18
3,-1,28:18
7,-1,28:18
9,-1,28:18
10,-1,28:18
11,-1,28:18
13,-1,28:18
-7,0,28:18
-6,0,28:18
-5,0,28:18
-4,0,28:18
-3,0,28:18
5,0,28:18
-8,1,28:18
-7,1,28:18
-6,1,28:18
-5,1,28:18
-4,1,28:18
4,1,28:18
5,1,28:18
-8,2,28:18
-7,2,28:18
-6,2,28:18
-5,2,28:18
4,2,28:18
4,3,28:18
5,3,28:18
5,4,28:18
6,4,28:18
7,4,28:18
6,5,28:18
7,5,28:18
7,6,28:106.4
6,6,28:106.4
8,5,28:106.2
8,4,28:106.2
-5,3,28:106.4
-6,3,28:106.4
-7,3,28:106.4
-8,3,28:106.4
-4,2,28:106.4
-9,2,28:106.8
-9,1,28:106.8
13,0,28:106.4
11,0,28:106.4
-1,0,28:106.4
-8,0,28:106.1
14,-1,28:106.2
12,-1,28:106.2
8,-1,28:106.2
-7,-1,28:106.1
15,-2,28:106.2
7,-2,28:106.2
15,-3,28:106.2
9,-3,28:106.1
15,-4,28:106.2
10,-4,28:106.1
9,-4,28:106.2
14,-5,28:106.1
13,-5,28:106.1
12,-5,28:106.1
11,-6,28:106.1
-1,-7,28:106.1
0,-10,28:106.1
-8,-10,28:106.1
6,-11,28:106.8
5,-11,28:106.1
-5,-11,28:106.1
-6,-11,28:106.1
-7,-11,28:106.1
9,-12,28:106.2
8,-13,28:106.1
8,-12,29:18
7,-11,29:18
-7,-9,29:18
-6,-9,29:18
-4,-7,29:18
-2,-6,29:18
0,-5,29:18
1,-5,29:18
12,-5,29:18
-1,-4,29:18
0,-4,29:18
1,-4,29:18
2,-4,29:18
11,-4,29:18
12,-4,29:18
13,-4,29:18
14,-4,29:18
-2,-3,29:18
-1,-3,29:18
0,-3,29:18
1,-3,29:18
11,-3,29:18
12,-3,29:18
13,-3,29:18
-2,-2,29:18
-1,-2,29:18
9,-2,29:18
10,-2,29:18
11,-2,29:18
12,-2,29:18
13,-2,29:18
11,-1,29:18
-8,1,29:18
-7,1,29:18
-5,1,29:18
-7,2,29:18
7,5,29:18
7,6,29:106.4
-7,3,29:106.4
11,0,29:106.4
12,-1,29:106.2
10,-3,29:106.1
9,-3,29:106.1
15,-4,29:106.2
14,-5,29:106.1
13,-5,29:106.1
9,-12,29:106.2
7,-12,29:106.1
8,-13,29:106.1
0,-4,30:18
1,-4,30:18
-1,-3,30:18
0,-3,30:18
11,-1,30:18
11,0,30:106.4
12,-1,30:106.2
1,-3,30:106.4
2,-4,30:106.2
1,-5,30:106.1
0,-5,30:106.1
