[META]
version=2.0
spawnOnBlockType=2
spawnSunlight=True
spawnDarkness=True
spawnWater=False
spawnLava=False
underFill=False
randomRotation=True
dig=False
tree=true
branch=False
needsFoundation=True
rarity=100
collisionPercentage=70
spawnElevationMin=0
spawnElevationMax=100
spawnInBiome=Forest3
[DATA]
-1,-1,-4:3.0
0,-1,-4:3.5
-1,-2,-3:3.0
0,-2,-3:3.0
1,-2,-3:3.5
-2,-1,-3:3.0
-1,-1,-3:17.2
0,-1,-3:3.0
1,-1,-3:3.0
-2,0,-3:3.0
-1,0,-3:3.0
0,0,-3:3.0
-1,1,-3:3.0
0,1,-3:17.2
-1,-3,-2:3.0
0,-3,-2:3.0
1,-3,-2:17.2
-2,-2,-2:3.0
-1,-2,-2:3.0
0,-2,-2:3.0
1,-2,-2:3.0
-3,-1,-2:3.0
-2,-1,-2:3.0
-1,-1,-2:17.2
0,-1,-2:17.2
1,-1,-2:3.0
2,-1,-2:17.2
-3,0,-2:3.0
-2,0,-2:3.0
-1,0,-2:17.2
0,0,-2:3.0
1,0,-2:3.0
-2,1,-2:17.2
-1,1,-2:3.0
-1,2,-2:3.0
-1,-4,-1:2.0
0,-4,-1:2.0
-2,-3,-1:2.0
-1,-3,-1:2.0
0,-3,-1:2.0
1,-3,-1:2.0
-3,-2,-1:2.0
-2,-2,-1:2.0
-1,-2,-1:17.2
0,-2,-1:17.2
1,-2,-1:2.0
2,-2,-1:2.0
-4,-1,-1:2.0
-3,-1,-1:2.0
-2,-1,-1:17.2
-1,-1,-1:17.2
0,-1,-1:17.2
1,-1,-1:17.2
2,-1,-1:2.0
3,-1,-1:2.0
-4,0,-1:2.0
-3,0,-1:2.0
-2,0,-1:17.2
-1,0,-1:17.2
0,0,-1:17.2
1,0,-1:2.0
2,0,-1:2.0
-3,1,-1:2.0
-2,1,-1:2.0
-1,1,-1:17.2
0,1,-1:2.0
1,1,-1:2.0
-2,2,-1:2.0
-1,2,-1:2.0
0,2,-1:2.0
-1,3,-1:2.0
-1,-3,0:18.12
0,-3,0:18.12
-2,-2,0:18.12
-1,-2,0:17.2
0,-2,0:17.2
1,-2,0:18.12
-3,-1,0:18.12
-2,-1,0:17.2
-1,-1,0:17.2
0,-1,0:17.2
1,-1,0:17.2
2,-1,0:18.12
-3,0,0:18.12
-2,0,0:17.2
-1,0,0:17.2
0,0,0:17.2
1,0,0:18.12
-2,1,0:18.12
-1,1,0:17.2
0,1,0:18.12
-1,2,0:18.12
-1,-2,1:18.12
0,-2,1:18.12
-2,-1,1:18.12
-1,-1,1:17.2
0,-1,1:17.2
1,-1,1:18.12
-2,0,1:18.12
-1,0,1:17.2
0,0,1:18.12
-1,1,1:18.12
-1,-1,2:18.12
0,-1,2:18.12
-2,0,2:18.12
-1,0,2:17.2
0,0,2:17.2
1,0,2:18.12
-1,1,2:18.12
0,1,2:18.12
0,-1,3:18.12
1,-1,3:18.12
-1,0,3:18.12
0,0,3:17.2
1,0,3:17.2
2,0,3:18.12
0,1,3:18.12
1,1,3:18.12
1,-2,4:18.12
0,-1,4:18.12
1,-1,4:17.2
2,-1,4:18.12
0,0,4:18.12
1,0,4:17.2
2,0,4:18.12
1,1,4:18.12
1,-3,5:18.12
0,-2,5:18.12
1,-2,5:17.2
2,-2,5:18.12
0,-1,5:18.12
1,-1,5:17.2
2,-1,5:18.12
1,0,5:18.12
0,-3,6:18.12
1,-3,6:18.12
-1,-2,6:18.12
0,-2,6:17.2
1,-2,6:17.2
2,-2,6:18.12
0,-1,6:18.12
1,-1,6:18.12
0,-3,7:18.12
-1,-2,7:18.12
0,-2,7:17.2
1,-2,7:18.12
0,-1,7:18.12
-1,-3,8:18.12
0,-3,8:18.12
-2,-2,8:18.12
-1,-2,8:17.2
0,-2,8:17.2
1,-2,8:18.12
-1,-1,8:18.12
0,-1,8:18.12
-1,-3,9:18.12
-2,-2,9:18.12
-1,-2,9:17.2
0,-2,9:18.12
-1,-1,9:18.12
-1,-3,10:18.12
-2,-2,10:18.12
-1,-2,10:17.2
0,-2,10:18.12
-2,-1,10:18.12
-1,-1,10:17.2
0,-1,10:18.12
-1,0,10:18.12
-1,-2,11:18.12
-2,-1,11:18.12
-1,-1,11:17.2
0,-1,11:18.12
-1,0,11:18.12
-1,-2,12:18.12
-2,-1,12:18.12
-1,-1,12:17.2
0,-1,12:18.12
-1,0,12:18.12
-2,-2,13:18.12
-1,-2,13:18.12
-3,-1,13:18.12
-2,-1,13:17.2
-1,-1,13:17.2
0,-1,13:18.4
-2,0,13:18.12
-1,0,13:18.12
-2,-2,14:18.12
-3,-1,14:18.12
-2,-1,14:17.2
-1,-1,14:18.12
-2,0,14:18.12
-2,-2,15:18.12
-3,-1,15:18.12
-2,-1,15:17.2
-1,-1,15:18.12
-2,0,15:18.12
-2,-2,16:18.12
-3,-1,16:18.12
-2,-1,16:17.2
-1,-1,16:18.12
-3,0,16:18.12
-2,0,16:17.2
-1,0,16:18.12
-2,1,16:18.12
-2,-1,17:18.12
-3,0,17:18.12
-2,0,17:17.2
-1,0,17:18.12
-3,1,17:18.12
-2,1,17:17.2
-1,1,17:18.12
-2,2,17:18.12
-2,0,18:18.12
-3,1,18:18.12
-2,1,18:17.2
-1,1,18:18.12
-2,2,18:18.12
-2,0,19:18.12
-1,0,19:18.12
-3,1,19:18.4
-2,1,19:17.2
-1,1,19:17.2
0,1,19:18.12
-2,2,19:18.12
-1,2,19:18.12
-1,0,20:18.12
-2,1,20:18.12
-1,1,20:17.2
0,1,20:18.4
-1,2,20:18.12
-1,1,21:18.12
-2,3,19:106.4
-3,2,19:106.8
1,1,19:106.2
0,0,19:106.1
-2,3,18:106.4
-3,2,18:106.8
1,1,18:106.2
0,0,18:106.1
-2,3,17:106.4
-3,2,17:106.12
1,1,17:106.2
0,1,17:106.2
-4,1,17:106.8
0,0,17:106.1
-4,0,17:106.8
-2,3,16:106.4
-3,2,16:106.12
1,1,16:106.2
0,1,16:106.2
-4,1,16:106.8
0,0,16:106.1
-4,0,16:106.8
-4,-1,16:106.8
-2,3,15:106.4
-3,2,15:106.12
1,1,15:106.2
0,1,15:106.2
-4,1,15:106.8
0,0,15:106.1
-4,0,15:106.8
-4,-1,15:106.8
-3,-2,15:106.8
-2,3,14:106.4
-3,2,14:106.12
1,1,14:106.2
0,1,14:106.2
-4,1,14:106.8
0,0,14:106.1
-4,0,14:106.8
-4,-1,14:106.8
-3,-2,14:106.9
-2,3,13:106.4
-3,2,13:106.12
1,1,13:106.2
0,1,13:106.2
-4,1,13:106.8
0,0,13:106.1
-4,0,13:106.8
1,-1,13:106.2
-4,-1,13:106.8
-3,-2,13:106.9
-2,3,12:106.4
-3,2,12:106.12
1,1,12:106.2
0,1,12:106.2
-4,1,12:106.8
0,0,12:106.1
-4,0,12:106.8
1,-1,12:106.2
-4,-1,12:106.8
0,-2,12:106.2
-2,-2,12:106.1
-3,-2,12:106.9
-1,-3,12:106.1
-2,3,11:106.4
-3,2,11:106.4
1,1,11:106.2
0,1,11:106.2
-4,1,11:106.8
-4,0,11:106.8
1,-1,11:106.2
-4,-1,11:106.8
0,-2,11:106.2
-2,-2,11:106.1
-3,-2,11:106.9
-1,-3,11:106.1
-2,3,10:106.4
-3,2,10:106.4
1,1,10:106.2
0,1,10:106.2
-4,1,10:106.8
-4,0,10:106.8
1,-1,10:106.2
-4,-1,10:106.8
-3,-2,10:106.9
-1,-4,10:106.1
-2,3,9:106.4
1,1,9:106.2
0,1,9:106.2
-4,1,9:106.8
-4,0,9:106.8
1,-1,9:106.2
0,-1,9:106.2
-4,-1,9:106.8
-3,-2,9:106.9
-1,-4,9:106.1
-2,3,8:106.4
1,1,8:106.2
0,1,8:106.2
-4,1,8:106.8
-4,0,8:106.8
1,-1,8:106.2
-4,-1,8:106.8
-3,-2,8:106.9
-1,-4,8:106.1
-2,3,7:106.4
1,1,7:106.2
0,1,7:106.2
-4,1,7:106.8
-4,0,7:106.8
1,-1,7:106.2
-4,-1,7:106.8
-2,-2,7:106.8
-3,-2,7:106.9
1,-3,7:106.1
-1,-3,7:106.1
0,-4,7:106.1
-1,-4,7:106.1
-2,3,6:106.4
1,1,6:106.2
0,1,6:106.2
-4,1,6:106.8
1,0,6:106.4
-4,0,6:106.8
-1,-1,6:106.8
-4,-1,6:106.8
3,-2,6:106.2
-2,-2,6:106.8
-3,-2,6:106.9
2,-3,6:106.1
-1,-3,6:106.1
0,-4,6:106.1
-1,-4,6:106.1
-2,3,5:106.4
1,1,5:106.2
0,1,5:106.2
-4,1,5:106.8
-4,0,5:106.8
3,-1,5:106.2
-1,-1,5:106.8
-4,-1,5:106.8
3,-2,5:106.2
-2,-2,5:106.8
-3,-2,5:106.9
2,-3,5:106.1
0,-3,5:106.1
-1,-3,5:106.1
1,-4,5:106.1
0,-4,5:106.1
-1,-4,5:106.1
-2,3,4:106.4
2,1,4:106.2
0,1,4:106.2
-4,1,4:106.8
3,0,4:106.2
-4,0,4:106.8
3,-1,4:106.2
-1,-1,4:106.8
-4,-1,4:106.8
3,-2,4:106.2
0,-2,4:106.1
-2,-2,4:106.8
-3,-2,4:106.9
2,-3,4:106.1
1,-3,4:106.1
0,-3,4:106.1
-1,-3,4:106.1
1,-4,4:106.1
0,-4,4:106.1
-1,-4,4:106.1
-2,3,3:106.4
2,1,3:106.2
-4,1,3:106.8
3,0,3:106.2
-4,0,3:106.8
3,-1,3:106.2
-1,-1,3:106.8
-4,-1,3:106.8
3,-2,3:106.2
0,-2,3:106.1
-2,-2,3:106.8
-3,-2,3:106.8
2,-3,3:106.1
1,-3,3:106.1
0,-3,3:106.1
-1,-3,3:106.1
1,-4,3:106.1
0,-4,3:106.1
-1,-4,3:106.1
-2,3,2:106.4
2,1,2:106.2
-4,1,2:106.8
3,0,2:106.2
-4,0,2:106.8
3,-1,2:106.2
-2,-1,2:106.8
-4,-1,2:106.8
3,-2,2:106.2
0,-2,2:106.1
-1,-2,2:106.1
-2,-2,2:106.8
-3,-2,2:106.8
2,-3,2:106.1
1,-3,2:106.1
0,-3,2:106.1
-1,-3,2:106.1
1,-4,2:106.1
0,-4,2:106.1
-1,-4,2:106.1
-2,3,1:106.4
2,1,1:106.2
-4,1,1:106.8
3,0,1:106.2
-4,0,1:106.8
3,-1,1:106.2
-4,-1,1:106.8
3,-2,1:106.2
-2,-2,1:106.9
-3,-2,1:106.8
2,-3,1:106.1
1,-3,1:106.1
0,-3,1:106.1
-1,-3,1:106.1
1,-4,1:106.1
0,-4,1:106.1
-1,-4,1:106.1
-1,3,0:31.1
-2,3,0:106.4
0,2,0:31.2
-2,2,0:31.1
2,1,0:106.2
1,1,0:31.1
-3,1,0:31.2
-4,1,0:106.8
3,0,0:106.2
2,0,0:31.1
-4,0,0:31.1
3,-1,0:31.1
-4,-1,0:31.1
3,-2,0:106.2
2,-2,0:31.1
-3,-2,0:31.2
2,-3,0:106.1
1,-3,0:31.2
-2,-3,0:31.2
1,-4,0:106.1
0,-4,0:31.2
-1,-4,0:31.1
