[META]
version=2.0
spawnOnBlockType=8,9
spawnSunlight=True
spawnDarkness=True
spawnWater=False
spawnLava=False
underFill=False
randomRotation=True
dig=True
tree=False
branch=False
needsFoundation=True
rarity=100
collisionPercentage=10
spawnElevationMin=0
spawnElevationMax=100
spawnInBiome=Forest3
[DATA]
1,-2,0:17.0
-2,-1,0:17.0
-2,0,0:17.0
0,1,0:17.0
1,1,0:17.0
0,2,0:17.0
1,2,0:18
1,-4,-6:17.0
0,-3,-6:17.0
1,-3,-6:17.0
2,-3,-6:17.0
-3,-2,-6:17.0
-2,-2,-6:17.0
0,-2,-6:17.0
1,-2,-6:17.0
2,-2,-6:17.0
3,-2,-6:17.0
-3,-1,-6:17.0
-2,-1,-6:17.0
1,-1,-6:17.0
2,-1,-6:17.0
3,-1,-6:17.0
0,0,-6:17.0
1,0,-6:17.0
-1,1,-6:17.0
0,1,-6:17.0
1,1,-6:17.0
0,2,-6:17.0
1,-4,-5:17.0
-2,-3,-5:17.0
0,-3,-5:17.0
1,-3,-5:17.0
2,-3,-5:17.0
-3,-2,-5:17.0
-2,-2,-5:17.0
-1,-2,-5:17.0
0,-2,-5:17.0
1,-2,-5:17.0
2,-2,-5:17.0
3,-2,-5:17.0
-4,-1,-5:17.0
-3,-1,-5:17.0
-2,-1,-5:17.0
-1,-1,-5:17.0
1,-1,-5:17.0
2,-1,-5:17.0
3,-1,-5:17.0
-2,0,-5:17.0
1,0,-5:17.0
-1,1,-5:17.0
0,1,-5:17.0
1,1,-5:17.0
-1,2,-5:17.0
0,2,-5:17.0
0,3,-5:17.0
1,-4,-4:17.0
-2,-3,-4:17.0
1,-3,-4:17.0
2,-3,-4:17.0
-3,-2,-4:17.0
-2,-2,-4:17.0
-1,-2,-4:17.0
0,-2,-4:17.0
1,-2,-4:17.0
2,-2,-4:17.0
-4,-1,-4:17.0
-3,-1,-4:17.0
-2,-1,-4:17.0
-1,-1,-4:17.0
2,-1,-4:17.0
3,-1,-4:17.0
-2,0,-4:17.0
1,0,-4:17.0
-2,1,-4:17.0
-1,1,-4:17.0
0,1,-4:17.0
1,1,-4:17.0
2,1,-4:17.0
-1,2,-4:17.0
0,2,-4:17.0
1,2,-4:17.0
0,3,-4:17.0
-2,-3,-3:17.0
1,-3,-3:17.0
-3,-2,-3:17.0
-2,-2,-3:17.0
-1,-2,-3:17.0
1,-2,-3:17.0
2,-2,-3:17.0
-4,-1,-3:17.0
-3,-1,-3:17.0
-2,-1,-3:17.0
-1,-1,-3:17.0
-3,0,-3:17.0
-2,0,-3:17.0
0,0,-3:17.0
-2,1,-3:17.0
-1,1,-3:17.0
0,1,-3:17.0
1,1,-3:17.0
2,1,-3:17.0
-1,2,-3:17.0
0,2,-3:17.0
1,2,-3:17.0
0,3,-3:17.0
-2,-2,-2:17.0
1,-2,-2:17.0
-3,-1,-2:17.0
-2,-1,-2:17.0
-1,-1,-2:17.0
-2,0,-2:17.0
0,0,-2:17.0
-2,1,-2:17.0
-1,1,-2:17.0
0,1,-2:17.0
1,1,-2:17.0
0,2,-2:17.0
1,2,-2:17.0
1,-2,-1:17.0
-3,-1,-1:17.0
-2,-1,-1:17.0
-2,0,-1:17.0
-1,1,-1:17.0
0,1,-1:17.0
1,1,-1:17.0
0,2,-1:17.0
1,2,-1:17.0
1,-2,1:18
-2,-1,1:17.0
-2,0,1:18
0,1,1:17.0
1,1,1:17.0
0,2,1:18
0,3,1:106.4
1,2,1:106.4
-1,2,1:106.8
2,1,1:106.2
-1,1,1:106.8
-2,1,1:106.4
1,0,1:106.1
0,0,1:106.1
-1,0,1:106.2
-3,0,1:106.8
1,-1,1:106.4
-1,-1,1:106.2
-3,-1,1:106.8
2,-2,1:106.2
0,-2,1:106.8
-2,-2,1:106.1
1,-3,1:106.1
-2,-1,2:18
0,1,2:17.0
1,1,2:18
1,2,2:106.4
0,2,2:106.4
2,1,2:106.2
-1,1,2:106.8
1,0,2:106.1
0,0,2:106.1
-2,0,2:106.4
-1,-1,2:106.2
-3,-1,2:106.8
-2,-2,2:106.1
0,1,3:18
0,2,3:106.4
1,1,3:106.2
-1,1,3:106.8
0,0,3:106.1
