[META]
version=2.0
spawnOnBlockType=2
spawnSunlight=True
spawnDarkness=True
spawnWater=False
spawnLava=False
underFill=False
randomRotation=True
dig=True
tree=True
branch=False
needsFoundation=True
rarity=20
collisionPercentage=2
spawnElevationMin=0
spawnElevationMax=245
spawnInBiome=Plains
[DATA]
0,-2,-3:1.5
0,-3,-2:3.0
-1,-2,-2:3.0
0,-2,-2:1.5
1,-2,-2:3.0
0,-1,-2:3.5
0,-4,-1:2.5
-1,-3,-1:2.5
0,-3,-1:2.5
1,-3,-1:2.5
-2,-2,-1:2.5
-1,-2,-1:2.5
0,-2,-1:3.0
1,-2,-1:2.5
2,-2,-1:2.5
-1,-1,-1:2.5
0,-1,-1:2.5
1,-1,-1:2.5
0,0,-1:2.5
0,-3,0:18.12
-1,-2,0:18.12
0,-2,0:17.0
1,-2,0:18.12
0,-1,0:18.4
0,-2,1:17.0
-1,-2,2:18.4
0,-2,2:17.0
0,-2,3:17.0
0,-2,4:17.0
0,-1,4:18.12
0,-2,5:17.0
0,-3,6:18.12
-1,-2,6:18.4
0,-2,6:17.0
1,-2,6:18.4
0,-1,6:17.0
-1,0,6:17.0
0,0,6:17.0
-1,-3,7:18.12
0,-3,7:18.12
1,-3,7:18.12
3,-3,7:18.12
-1,-2,7:18.12
0,-2,7:17.0
1,-2,7:17.0
2,-2,7:17.0
3,-2,7:17.0
4,-2,7:18.12
-1,-1,7:18.12
0,-1,7:18.12
1,-1,7:18.12
3,-1,7:17.0
4,-1,7:18.12
-2,0,7:18.12
-1,0,7:17.0
0,0,7:18.12
3,0,7:18.12
-2,1,7:17.0
-1,1,7:17.0
-3,2,7:18.12
-2,2,7:17.0
-1,2,7:18.4
-2,3,7:18.12
-4,-6,8:18.12
-3,-6,8:18.12
-5,-5,8:18.12
-4,-5,8:17.0
-3,-5,8:17.0
-2,-5,8:18.12
-4,-4,8:18.12
-3,-4,8:17.0
-2,-4,8:18.12
-1,-4,8:18.12
0,-4,8:18.4
-4,-3,8:18.12
-3,-3,8:17.0
-2,-3,8:17.0
-1,-3,8:17.0
0,-3,8:18.12
1,-3,8:18.12
2,-3,8:18.12
3,-3,8:18.12
4,-3,8:18.12
-3,-2,8:18.12
-2,-2,8:18.12
-1,-2,8:17.0
0,-2,8:17.0
1,-2,8:18.12
2,-2,8:18.12
3,-2,8:18.12
4,-2,8:18.12
5,-2,8:18.12
-2,-1,8:18.12
-1,-1,8:18.12
0,-1,8:18.12
1,-1,8:18.12
2,-1,8:18.12
3,-1,8:17.0
4,-1,8:17.0
5,-1,8:17.0
6,-1,8:18.12
-3,0,8:18.12
-2,0,8:18.12
-1,0,8:18.12
0,0,8:18.12
1,0,8:18.12
2,0,8:18.12
3,0,8:18.12
4,0,8:18.12
5,0,8:18.12
-4,1,8:18.12
-3,1,8:18.12
-2,1,8:18.12
-1,1,8:18.12
0,1,8:18.12
2,1,8:18.12
3,1,8:18.12
4,1,8:18.12
-4,2,8:18.12
-3,2,8:18.12
-2,2,8:17.0
-1,2,8:18.12
0,2,8:18.12
3,2,8:18.4
-4,3,8:18.12
-3,3,8:18.12
-2,3,8:18.12
-1,3,8:18.12
-3,4,8:18.12
-2,4,8:18.12
-5,-7,9:18.12
-4,-7,9:18.12
-3,-7,9:18.12
-6,-6,9:18.12
-5,-6,9:18.12
-4,-6,9:18.12
-3,-6,9:18.12
-2,-6,9:18.12
-1,-6,9:18.12
-6,-5,9:18.12
-5,-5,9:18.12
-4,-5,9:17.0
-3,-5,9:18.12
-2,-5,9:18.12
-1,-5,9:18.12
0,-5,9:18.12
2,-5,9:18.4
3,-5,9:18.12
-6,-4,9:18.12
-5,-4,9:18.12
-4,-4,9:18.12
-3,-4,9:18.12
-2,-4,9:18.12
-1,-4,9:18.12
0,-4,9:18.12
1,-4,9:18.12
2,-4,9:18.12
3,-4,9:18.12
4,-4,9:18.12
-5,-3,9:18.12
-4,-3,9:18.12
-3,-3,9:18.12
-2,-3,9:18.12
-1,-3,9:18.12
0,-3,9:18.12
1,-3,9:18.12
2,-3,9:18.12
3,-3,9:18.12
4,-3,9:18.12
5,-3,9:18.12
-3,-2,9:18.12
-2,-2,9:18.12
-1,-2,9:18.12
0,-2,9:18.12
1,-2,9:18.12
2,-2,9:18.12
3,-2,9:18.12
4,-2,9:18.12
5,-2,9:18.12
6,-2,9:18.12
-2,-1,9:18.12
-1,-1,9:18.12
0,-1,9:18.12
1,-1,9:18.12
2,-1,9:18.12
3,-1,9:18.12
4,-1,9:18.12
5,-1,9:17.0
6,-1,9:18.12
7,-1,9:18.12
-1,0,9:18.12
0,0,9:18.12
2,0,9:18.12
3,0,9:18.12
4,0,9:18.12
5,0,9:18.12
6,0,9:18.12
-2,1,9:18.12
-1,1,9:18.12
3,1,9:18.12
-3,2,9:18.12
-2,2,9:18.12
-1,2,9:18.12
-2,3,9:18.12
-4,-6,10:18.12
-3,-6,10:18.12
-5,-5,10:18.12
-4,-5,10:18.12
-3,-5,10:18.12
-2,-5,10:18.12
-4,-4,10:18.12
-3,-4,10:18.12
-2,-4,10:18.12
0,-4,10:18.4
0,-3,10:18.12
1,-3,10:18.12
-1,-2,10:18.12
0,-2,10:18.12
1,-2,10:18.12
2,-2,10:18.12
4,-2,10:18.12
5,-2,10:18.12
0,-1,10:18.12
3,-1,10:18.12
4,-1,10:18.12
5,-1,10:18.12
6,-1,10:18.12
4,0,10:18.12
5,0,10:18.12
-1,1,10:18.12
-2,2,10:18.12
0,0,0:31.1
1,-1,0:31.1
-1,-1,0:31.1
2,-2,0:31.1
-2,-2,0:31.1
1,-3,0:31.1
-1,-3,0:31.1
0,-4,0:31.1
