[META]
version=2.0
spawnOnBlockType=2
spawnSunlight=True
spawnDarkness=True
spawnWater=False
spawnLava=False
underFill=False
randomRotation=True
dig=True
tree=False
branch=False
needsFoundation=True
rarity=200
collisionPercentage=50
spawnElevationMin=0
spawnElevationMax=200
spawnInBiome=Forest2
[DATA]
0,-1,-4:17.3
0,0,-4:3.5
0,1,-4:17.3
-1,-2,-3:3.5
0,-2,-3:17.3
-1,-1,-3:17.3
0,-1,-3:3.5
1,-1,-3:17.3
-1,0,-3:3.5
0,0,-3:3.5
1,0,-3:3.5
-1,1,-3:3.5
0,1,-3:17.3
1,1,-3:3.5
0,2,-3:3.5
-4,-5,-2:17.3
-2,-5,-2:3.5
-6,-4,-2:17.3
-3,-4,-2:3.5
3,-4,-2:3.5
-5,-3,-2:3.5
-2,-3,-2:3.5
-1,-3,-2:3.5
0,-3,-2:17.3
2,-3,-2:3.5
3,-3,-2:17.3
-3,-2,-2:3.5
-2,-2,-2:17.3
-1,-2,-2:3.5
0,-2,-2:3.5
1,-2,-2:3.5
-3,-1,-2:3.5
-2,-1,-2:3.5
-1,-1,-2:3.5
0,-1,-2:3.5
1,-1,-2:3.5
2,-1,-2:3.5
-2,0,-2:17.3
-1,0,-2:3.5
0,0,-2:3.5
1,0,-2:3.5
2,0,-2:3.5
-4,1,-2:3.5
-2,1,-2:3.5
-1,1,-2:3.5
0,1,-2:3.5
1,1,-2:3.5
2,1,-2:3.5
3,1,-2:3.5
-5,2,-2:17.3
-3,2,-2:3.5
-1,2,-2:3.5
0,2,-2:17.3
1,2,-2:3.5
3,2,-2:17.3
0,3,-2:17.3
2,3,-2:3.5
1,4,-2:17.3
-4,-6,-1:17.3
-3,-6,-1:2.5
-4,-5,-1:2.5
-3,-5,-1:2.5
-2,-5,-1:2.5
2,-5,-1:2.5
3,-5,-1:2.5
4,-5,-1:2.5
-7,-4,-1:17.3
-6,-4,-1:2.5
-4,-4,-1:2.0
-3,-4,-1:2.5
-2,-4,-1:2.5
-1,-4,-1:3.0
0,-4,-1:17.3
1,-4,-1:2.5
2,-4,-1:2.5
3,-4,-1:2.5
4,-4,-1:17.3
-6,-3,-1:2.5
-5,-3,-1:2.5
-4,-3,-1:2.0
-3,-3,-1:17.3
-2,-3,-1:3.0
-1,-3,-1:3.0
0,-3,-1:2.5
1,-3,-1:3.0
2,-3,-1:2.5
3,-3,-1:2.5
-5,-2,-1:2.5
-4,-2,-1:2.5
-3,-2,-1:3.0
-2,-2,-1:2.5
-1,-2,-1:3.0
0,-2,-1:3.0
1,-2,-1:3.0
2,-2,-1:3.0
3,-2,-1:2.5
-4,-1,-1:2.5
-3,-1,-1:3.0
-2,-1,-1:3.0
-1,-1,-1:3.0
0,-1,-1:2.5
1,-1,-1:3.0
2,-1,-1:17.3
3,-1,-1:2.0
-4,0,-1:2.5
-3,0,-1:17.3
-2,0,-1:3.0
-1,0,-1:3.0
0,0,-1:3.0
1,0,-1:2.5
2,0,-1:17.3
3,0,-1:2.5
-5,1,-1:2.5
-4,1,-1:2.5
-3,1,-1:3.0
-2,1,-1:3.0
-1,1,-1:3.0
0,1,-1:3.0
1,1,-1:3.0
2,1,-1:3.0
3,1,-1:2.5
4,1,-1:2.5
-6,2,-1:2.5
-5,2,-1:2.5
-4,2,-1:2.5
-3,2,-1:2.5
-2,2,-1:2.5
-1,2,-1:3.0
0,2,-1:2.5
1,2,-1:3.0
2,2,-1:2.5
3,2,-1:2.5
4,2,-1:2.5
-6,3,-1:17.3
-5,3,-1:2.5
-3,3,-1:2.5
-2,3,-1:2.5
-1,3,-1:3.0
0,3,-1:17.3
1,3,-1:2.5
2,3,-1:2.5
3,3,-1:2.5
4,3,-1:17.3
-1,4,-1:2.5
0,4,-1:2.5
1,4,-1:2.5
2,4,-1:2.5
0,5,-1:17.3
1,5,-1:17.3
2,5,-1:2.5
1,6,-1:2.5
-4,-7,0:18.3
-4,-6,0:18.3
3,-6,0:18.3
-7,-5,0:18.13
2,-5,0:18.3
3,-5,0:18.3
4,-5,0:18.3
5,-5,0:18.3
-8,-4,0:18.13
-7,-4,0:18.13
-2,-4,0:18.3
-1,-4,0:17.3
0,-4,0:18.3
4,-4,0:17.3
5,-4,0:18.3
6,-4,0:18.3
-7,-3,0:18.13
-6,-3,0:18.13
-2,-3,0:17.3
-1,-3,0:17.3
0,-3,0:18.3
1,-3,0:17.3
4,-3,0:18.3
5,-3,0:18.3
-6,-2,0:18.13
-3,-2,0:17.3
-2,-2,0:18.3
-1,-2,0:17.3
0,-2,0:17.3
1,-2,0:17.3
2,-2,0:17.3
4,-2,0:18.3
-3,-1,0:17.3
-2,-1,0:17.3
-1,-1,0:17.3
1,-1,0:17.3
-3,0,0:18.3
-2,0,0:17.3
-1,0,0:17.3
0,0,0:17.3
-6,1,0:18.3
-3,1,0:17.3
-2,1,0:17.3
-1,1,0:17.3
0,1,0:17.3
1,1,0:17.3
2,1,0:17.3
5,1,0:18.13
-6,2,0:18.3
-2,2,0:18.3
-1,2,0:17.3
1,2,0:17.3
5,2,0:18.13
-6,3,0:17.3
-5,3,0:18.3
-2,3,0:18.3
-1,3,0:17.3
3,3,0:18.13
4,3,0:18.13
5,3,0:18.13
-6,4,0:18.3
4,4,0:18.13
5,4,0:18.13
-1,5,0:18.3
0,5,0:18.3
1,5,0:18.3
4,5,0:18.13
-1,6,0:18.3
1,6,0:18.3
-7,-6,1:18.13
-5,-6,1:18.3
-4,-6,1:18.3
-3,-6,1:30.0
-7,-5,1:18.13
3,-5,1:18.3
4,-5,1:18.3
-8,-4,1:18.13
-7,-4,1:18.13
-1,-4,1:18.3
3,-4,1:30.0
4,-4,1:18.3
-7,-3,1:18.13
-2,-3,1:18.3
-1,-3,1:17.3
0,-3,1:18.3
4,-3,1:18.3
-2,-2,1:18.3
-1,-2,1:17.3
0,-2,1:17.3
1,-2,1:17.3
2,-2,1:18.3
-3,-1,1:17.3
-2,-1,1:17.3
-1,-1,1:17.3
1,-1,1:17.3
-2,0,1:17.3
-1,0,1:17.3
0,0,1:17.3
-2,1,1:17.3
-1,1,1:17.3
0,1,1:17.3
1,1,1:17.3
-6,2,1:18.3
-2,2,1:18.3
-1,2,1:17.3
4,2,1:30.0
-7,3,1:18.3
-6,3,1:18.3
-5,3,1:18.3
-4,3,1:18.3
4,3,1:18.13
5,3,1:18.13
-6,4,1:18.3
2,4,1:18.3
4,4,1:18.13
0,5,1:18.3
1,5,1:18.3
2,5,1:18.3
-4,-6,2:18.3
-3,-6,2:18.3
-7,-5,2:18.13
-7,-4,2:18.13
-6,-4,2:18.13
3,-4,2:18.3
4,-4,2:18.3
5,-4,2:18.3
-1,-3,2:17.3
0,-3,2:18.3
4,-3,2:18.3
-2,-2,2:18.3
-1,-2,2:17.3
0,-2,2:17.3
1,-2,2:17.3
2,-2,2:18.3
3,-2,2:18.3
4,-2,2:18.3
-3,-1,2:17.3
-2,-1,2:17.3
-1,-1,2:17.3
1,-1,2:17.3
-2,0,2:17.3
-1,0,2:17.3
0,0,2:17.3
-6,1,2:18.3
-2,1,2:17.3
-1,1,2:17.3
0,1,2:17.3
-6,2,2:18.3
-5,2,2:18.3
-1,2,2:18.3
0,2,2:18.3
4,2,2:18.13
-7,3,2:18.3
-6,3,2:18.3
-5,3,2:18.3
4,3,2:18.13
-6,4,2:18.3
0,4,2:18.3
0,5,2:18.3
1,5,2:18.3
2,5,2:18.3
0,6,2:18.3
-4,-6,3:18.3
4,-4,3:18.3
-1,-3,3:17.3
-3,-2,3:18.3
-1,-2,3:17.3
0,-2,3:17.3
1,-2,3:17.3
-3,-1,3:17.3
-2,-1,3:17.3
-1,-1,3:17.3
1,-1,3:17.3
-2,0,3:17.3
-1,0,3:17.3
0,0,3:17.3
-1,1,3:17.3
0,1,3:17.3
-6,2,3:18.3
0,2,3:18.3
-6,3,3:18.3
-1,-2,4:17.3
0,-2,4:17.3
-2,-1,4:17.3
-1,-1,4:17.3
1,-1,4:17.3
-3,0,4:18.3
-2,0,4:17.3
-1,0,4:17.3
0,0,4:17.3
-2,1,4:18.3
-1,1,4:17.3
0,1,4:17.3
1,1,4:18.3
-1,2,4:18.3
0,2,4:18.3
-1,-2,5:17.3
0,-2,5:17.3
-2,-1,5:17.3
-1,-1,5:17.3
1,-1,5:17.3
-2,0,5:17.3
-1,0,5:17.3
0,0,5:17.3
1,0,5:18.3
2,0,5:18.3
-1,1,5:17.3
0,1,5:17.3
1,1,5:18.3
2,1,5:18.3
0,-3,6:18.3
-1,-2,6:17.3
0,-2,6:17.3
1,-2,6:18.3
-2,-1,6:17.3
-1,-1,6:17.3
1,-1,6:17.3
2,-1,6:18.3
-2,0,6:17.3
-1,0,6:17.3
0,0,6:17.3
-1,1,6:17.3
0,1,6:17.3
0,-3,7:18.4
-1,-2,7:17.3
0,-2,7:17.3
-2,-1,7:17.3
-1,-1,7:17.3
1,-1,7:17.3
2,-1,7:18.3
-2,0,7:17.3
-1,0,7:17.3
0,0,7:17.3
-1,1,7:17.3
0,1,7:17.3
-1,-3,8:18.3
0,-3,8:18.3
-1,-2,8:17.3
0,-2,8:17.3
-2,-1,8:17.3
-1,-1,8:17.3
1,-1,8:17.3
-2,0,8:17.3
-1,0,8:17.3
0,0,8:17.3
-1,1,8:17.3
0,1,8:17.3
-2,-2,9:18.3
-1,-2,9:17.3
0,-2,9:17.3
-2,-1,9:17.3
-1,-1,9:17.3
1,-1,9:17.3
-2,0,9:17.3
-1,0,9:17.3
0,0,9:17.3
-1,1,9:17.3
0,1,9:17.3
-2,-2,10:18.3
-1,-2,10:17.3
0,-2,10:17.3
-2,-1,10:17.3
-1,-1,10:17.3
1,-1,10:17.3
-2,0,10:17.3
-1,0,10:17.3
0,0,10:17.3
-1,1,10:17.3
0,1,10:17.3
-3,-2,11:18.3
-2,-2,11:18.3
-1,-2,11:17.3
0,-2,11:17.3
-2,-1,11:17.3
-1,-1,11:17.3
1,-1,11:17.3
-2,0,11:17.3
-1,0,11:17.3
0,0,11:17.3
-1,1,11:17.3
0,1,11:17.3
-1,-3,12:18.3
-1,-2,12:17.3
0,-2,12:17.3
-3,-1,12:18.3
-2,-1,12:17.3
-1,-1,12:17.3
1,-1,12:17.3
-2,0,12:17.3
-1,0,12:17.3
0,0,12:17.3
-1,1,12:17.3
0,1,12:17.3
0,-3,13:18.3
-1,-2,13:17.3
0,-2,13:17.3
-2,-1,13:17.3
-1,-1,13:17.3
1,-1,13:17.3
-3,0,13:18.3
-2,0,13:17.3
-1,0,13:17.3
0,0,13:17.3
-1,1,13:17.3
0,1,13:17.3
-1,-2,14:17.3
0,-2,14:17.3
1,-2,14:18.3
-2,-1,14:17.3
-1,-1,14:17.3
1,-1,14:17.3
-2,0,14:17.3
-1,0,14:17.3
0,0,14:17.3
-2,1,14:18.3
-1,1,14:17.3
0,1,14:17.3
-1,-2,15:17.3
0,-2,15:17.3
-2,-1,15:17.3
-1,-1,15:17.3
1,-1,15:17.3
2,-1,15:18.3
-3,0,15:18.3
-2,0,15:17.3
-1,0,15:17.3
0,0,15:17.3
-1,1,15:17.3
0,1,15:17.3
-1,2,15:18.3
0,2,15:18.3
-1,-2,16:17.3
0,-2,16:17.3
-2,-1,16:17.3
-1,-1,16:17.3
1,-1,16:17.3
-3,0,16:18.3
-2,0,16:17.3
-1,0,16:17.3
0,0,16:17.3
1,0,16:18.3
-2,1,16:18.3
-1,1,16:17.3
0,1,16:17.3
0,2,16:18.3
-1,-2,17:17.3
0,-2,17:17.3
-2,-1,17:17.3
-1,-1,17:17.3
1,-1,17:17.3
-2,0,17:17.3
-1,0,17:17.3
0,0,17:17.3
-1,1,17:17.3
0,1,17:17.3
1,1,17:18.3
-1,2,17:18.3
-1,-2,18:17.3
0,-2,18:17.3
-2,-1,18:17.3
-1,-1,18:17.3
1,-1,18:17.3
-2,0,18:17.3
-1,0,18:17.3
0,0,18:17.3
-1,1,18:17.3
0,1,18:17.3
1,1,18:18.3
-1,2,18:18.3
-1,-2,19:17.3
0,-2,19:17.3
-2,-1,19:17.3
1,-1,19:17.3
2,-1,19:18.3
-2,0,19:17.3
-1,0,19:17.3
0,0,19:17.3
-1,1,19:17.3
0,1,19:17.3
1,1,19:18.3
0,2,19:18.3
-1,-2,20:17.3
0,-2,20:17.3
1,-2,20:18.3
-2,-1,20:17.3
1,-1,20:17.3
-2,0,20:17.3
-1,0,20:17.3
0,0,20:17.3
1,0,20:18.3
-1,1,20:17.3
0,1,20:17.3
1,1,20:18.3
-5,-5,21:18.3
-1,-3,21:18.3
0,-3,21:18.3
-1,-2,21:17.3
0,-2,21:17.3
-1,-1,21:17.3
1,-1,21:18.3
-2,0,21:17.3
-1,0,21:17.3
0,0,21:17.3
-1,1,21:17.3
0,1,21:17.3
0,3,21:18.3
-5,-5,22:18.3
-2,-3,22:18.3
-1,-3,22:18.3
0,-3,22:18.3
-2,-2,22:18.3
-1,-2,22:17.3
0,-2,22:17.3
-1,-1,22:17.3
0,-1,22:17.3
-1,0,22:17.3
0,0,22:17.3
4,0,22:18.3
0,3,22:18.3
-5,-5,23:18.3
4,-4,23:18.3
-2,-3,23:18.3
-1,-2,23:17.3
-2,-1,23:18.3
-1,-1,23:17.3
0,-1,23:17.3
-1,0,23:17.3
0,0,23:17.3
4,0,23:18.3
0,3,23:18.3
-4,4,23:18.3
5,4,23:18.3
-5,-5,24:18.3
4,-4,24:18.3
-1,-1,24:17.3
0,-1,24:17.3
-2,0,24:18.3
-1,0,24:17.3
0,0,24:17.3
4,0,24:18.3
-1,1,24:17.3
0,3,24:18.3
-4,4,24:18.3
5,4,24:18.3
-5,-5,25:18.3
4,-4,25:18.3
-1,-2,25:17.3
0,-1,25:17.3
-1,0,25:18.3
4,0,25:18.3
-1,1,25:18.3
1,1,25:17.3
-2,2,25:17.3
0,3,25:18.3
-4,4,25:18.3
5,4,25:18.3
-5,-5,26:18.3
1,-5,26:18.3
2,-5,26:18.3
3,-5,26:18.3
4,-5,26:18.3
5,-5,26:18.3
-6,-4,26:18.3
-5,-4,26:18.3
-4,-4,26:17.3
-3,-4,26:18.3
-2,-4,26:18.3
0,-4,26:18.3
1,-4,26:17.3
2,-4,26:18.3
3,-4,26:18.3
4,-4,26:18.3
-4,-3,26:18.3
-3,-3,26:17.3
-2,-3,26:17.3
0,-3,26:18.3
1,-3,26:17.3
2,-3,26:18.3
-4,-2,26:18.3
-1,-2,26:18.3
1,-2,26:17.3
2,-2,26:17.3
-1,-1,26:18.3
0,-1,26:18.3
-1,0,26:18.3
4,0,26:18.3
1,1,26:18.3
2,1,26:18.3
4,1,26:18.3
5,1,26:18.3
-2,2,26:18.3
-1,2,26:18.3
1,2,26:18.3
2,2,26:17.3
3,2,26:17.3
4,2,26:18.3
5,2,26:18.3
6,2,26:18.3
-4,3,26:18.3
-3,3,26:17.3
-2,3,26:18.3
-1,3,26:18.3
0,3,26:17.3
2,3,26:18.3
3,3,26:18.3
4,3,26:18.3
5,3,26:18.3
-4,4,26:17.3
-3,4,26:17.3
-2,4,26:18.3
-1,4,26:18.3
3,4,26:18.3
4,4,26:17.3
5,4,26:18.3
-3,5,26:18.3
-2,5,26:18.3
-1,5,26:18.3
2,-8,27:18.3
3,-8,27:18.3
1,-7,27:18.3
2,-7,27:18.3
3,-7,27:18.3
4,-7,27:18.3
-5,-6,27:18.3
-4,-6,27:18.3
0,-6,27:18.3
1,-6,27:18.3
2,-6,27:18.3
3,-6,27:17.3
4,-6,27:18.3
5,-6,27:18.3
-6,-5,27:18.3
-5,-5,27:18.3
-4,-5,27:18.3
-3,-5,27:18.3
0,-5,27:18.3
1,-5,27:17.3
2,-5,27:18.3
3,-5,27:18.3
4,-5,27:18.3
5,-5,27:18.3
-7,-4,27:18.3
-6,-4,27:18.3
-5,-4,27:18.3
-4,-4,27:17.3
-3,-4,27:18.3
1,-4,27:18.3
2,-4,27:18.3
3,-4,27:18.3
4,-4,27:18.3
5,-4,27:18.3
6,-4,27:18.4
-8,-3,27:18.3
-7,-3,27:18.3
-6,-3,27:17.3
-5,-3,27:18.3
-4,-3,27:18.3
-3,-3,27:18.3
-2,-3,27:18.3
1,-3,27:18.3
2,-3,27:18.3
3,-3,27:18.3
4,-3,27:18.3
5,-3,27:18.3
-7,-2,27:18.3
-6,-2,27:18.3
-5,-2,27:18.3
-4,-2,27:18.3
-3,-2,27:18.3
1,-2,27:18.3
3,-2,27:17.3
4,-2,27:18.3
-6,-1,27:18.3
-3,-1,27:18.3
-2,-1,27:18.3
1,-1,27:18.3
3,-1,27:18.3
4,-1,27:18.3
3,0,27:18.3
4,0,27:18.3
5,0,27:18.3
-4,1,27:18.3
-3,1,27:18.3
-2,1,27:18.3
2,1,27:18.3
3,1,27:18.3
4,1,27:18.3
5,1,27:18.3
-4,2,27:18.3
-3,2,27:18.3
-2,2,27:18.3
2,2,27:18.3
3,2,27:18.3
4,2,27:17.3
5,2,27:18.3
6,2,27:18.3
-5,3,27:18.3
-4,3,27:18.3
-3,3,27:18.3
-2,3,27:18.3
-1,3,27:18.3
1,3,27:18.3
2,3,27:18.3
3,3,27:18.3
4,3,27:18.3
5,3,27:18.3
6,3,27:18.3
-6,4,27:18.3
-5,4,27:18.3
-4,4,27:17.3
-3,4,27:18.3
-2,4,27:18.3
-1,4,27:18.3
0,4,27:18.3
2,4,27:18.3
3,4,27:18.3
4,4,27:18.3
5,4,27:18.3
-6,5,27:18.3
-5,5,27:18.3
-4,5,27:18.3
-3,5,27:18.3
-2,5,27:18.3
-1,5,27:18.3
0,5,27:18.3
3,5,27:18.3
-6,6,27:18.3
-5,6,27:18.3
-4,6,27:18.3
-3,6,27:17.3
-2,6,27:18.3
-1,6,27:18.3
-5,7,27:18.3
-3,7,27:18.3
-2,7,27:18.3
2,-7,28:18.4
3,-7,28:18.3
1,-6,28:18.3
2,-6,28:18.3
3,-6,28:18.3
4,-6,28:18.3
-5,-5,28:18.3
-4,-5,28:18.3
1,-5,28:18.3
2,-5,28:18.3
3,-5,28:18.3
4,-5,28:18.3
5,-5,28:18.3
6,-5,28:18.3
-7,-4,28:18.3
-6,-4,28:17.3
-5,-4,28:18.3
-4,-4,28:18.3
-3,-4,28:18.3
1,-4,28:18.3
2,-4,28:18.3
3,-4,28:18.3
4,-4,28:18.3
5,-4,28:18.3
-7,-3,28:18.3
-6,-3,28:18.3
-5,-3,28:18.3
-4,-3,28:18.3
-3,-3,28:18.3
-2,-3,28:18.3
2,-3,28:18.3
3,-3,28:18.3
4,-3,28:18.3
-5,-2,28:18.3
-4,-2,28:18.3
-3,-2,28:18.3
-2,-2,28:18.3
1,-2,28:18.3
3,-2,28:18.3
-6,-1,28:18.3
-3,-1,28:18.3
-2,-1,28:18.3
-3,0,28:18.3
-2,0,28:18.3
4,0,28:18.3
-3,1,28:17.3
2,1,28:18.3
3,1,28:18.3
4,1,28:18.3
5,1,28:18.3
6,1,28:18.4
-3,2,28:18.3
1,2,28:18.3
2,2,28:18.3
3,2,28:18.3
4,2,28:18.3
5,2,28:18.3
6,2,28:17.3
7,2,28:18.3
-4,3,28:18.3
-3,3,28:18.3
-2,3,28:18.3
-1,3,28:18.3
3,3,28:17.3
4,3,28:18.3
5,3,28:18.3
-5,4,28:18.3
-4,4,28:18.3
-3,4,28:18.3
-2,4,28:18.3
3,4,28:18.3
4,4,28:18.3
-6,5,28:18.3
-5,5,28:18.3
-4,5,28:18.3
-3,5,28:18.3
-2,5,28:18.3
-1,5,28:18.3
-5,6,28:18.3
-4,6,28:18.3
-3,6,28:18.3
-2,6,28:18.3
-3,7,28:18.3
2,-5,29:18.3
3,-5,29:18.3
-6,-4,29:18.3
-5,-4,29:18.3
-4,-4,29:18.3
3,-4,29:18.3
4,-4,29:18.3
-6,-3,29:18.3
-5,-3,29:18.3
-4,-3,29:18.3
-2,-3,29:18.3
3,-3,29:18.3
4,-3,29:18.3
-5,-2,29:18.3
-4,-2,29:18.3
-3,-2,29:18.3
-6,-1,29:18.3
-3,-1,29:18.3
2,1,29:18.3
3,1,29:18.3
4,1,29:18.3
-3,2,29:18.3
-2,2,29:18.3
3,2,29:18.3
4,2,29:18.3
5,2,29:18.3
6,2,29:18.3
-3,3,29:18.3
-2,3,29:18.3
-1,3,29:18.3
3,3,29:18.3
4,3,29:18.3
5,3,29:18.3
-5,4,29:18.3
-4,4,29:18.3
-3,4,29:18.3
-2,4,29:18.3
-5,5,29:18.3
-4,5,29:18.3
-3,5,29:18.3
-2,5,29:18.3
-1,5,29:18.3
-5,-3,30:18.3
-4,-3,30:18.4
3,-3,30:18.4
-3,-1,30:18.3
4,2,30:18.3
3,3,30:18.3
-3,4,30:18.3
-3,-5,26:106.1
-4,-5,26:106.3
-5,-6,26:106.1
6,4,25:106.2
-3,4,25:106.2
-5,4,25:106.8
-2,3,25:106.4
4,1,25:106.4
4,-3,25:106.4
3,-4,25:106.8
2,-4,25:106.0
2,-5,25:106.0
-3,-5,25:106.1
-4,-5,25:106.3
-5,-6,25:106.1
5,5,24:106.4
6,4,24:106.2
0,4,24:106.4
-3,4,24:106.2
-5,4,24:106.8
-2,3,24:106.4
4,1,24:106.4
4,-3,24:106.4
3,-4,24:106.8
-3,-5,24:106.1
-4,-5,24:106.3
-5,-6,24:106.1
5,5,23:106.4
6,4,23:106.2
0,4,23:106.4
-3,4,23:106.2
-5,4,23:106.8
-2,3,23:106.4
4,1,23:106.4
4,-3,23:106.4
3,-4,23:106.8
-3,-5,23:106.1
-4,-5,23:106.3
-5,-6,23:106.1
5,5,22:106.4
6,4,22:106.2
0,4,22:106.4
-3,4,22:106.2
-5,4,22:106.8
-2,3,22:106.4
4,1,22:106.4
4,-3,22:106.4
3,-4,22:106.8
-3,-5,22:106.1
-4,-5,22:106.3
-6,-5,22:106.8
-5,-6,22:106.1
5,5,21:106.4
6,4,21:106.2
0,4,21:106.4
-3,4,21:106.2
-5,4,21:106.8
-2,3,21:106.4
4,1,21:106.4
-3,0,21:106.8
-2,-1,21:106.1
4,-3,21:106.4
3,-4,21:106.8
-3,-5,21:106.1
-4,-5,21:106.3
-6,-5,21:106.8
-5,-6,21:106.1
5,5,20:106.4
6,4,20:106.2
0,4,20:106.4
-3,4,20:106.2
-5,4,20:106.8
-2,3,20:106.4
4,1,20:106.4
-3,0,20:106.8
-2,-2,20:106.8
4,-3,20:106.4
-1,-3,20:106.1
3,-4,20:106.8
-3,-5,20:106.1
-4,-5,20:106.3
-6,-5,20:106.8
-5,-6,20:106.1
5,5,19:106.4
6,4,19:106.2
0,4,19:106.4
-3,4,19:106.2
-5,4,19:106.8
-2,3,19:106.4
4,1,19:106.4
-3,0,19:106.8
-2,-2,19:106.8
4,-3,19:106.4
-1,-3,19:106.1
3,-4,19:106.8
-3,-5,19:106.1
-4,-5,19:106.3
-6,-5,19:106.8
-5,-6,19:106.1
5,5,18:106.4
6,4,18:106.2
0,4,18:106.4
-3,4,18:106.2
-5,4,18:106.8
-1,3,18:106.4
-2,3,18:106.4
4,1,18:106.4
-3,0,18:106.8
2,-1,18:106.2
-2,-2,18:106.8
4,-3,18:106.4
-1,-3,18:106.1
3,-4,18:106.8
-3,-5,18:106.1
-4,-5,18:106.3
-6,-5,18:106.8
-5,-6,18:106.1
5,5,17:106.4
6,4,17:106.2
0,4,17:106.4
-3,4,17:106.2
-5,4,17:106.8
-1,3,17:106.4
-2,3,17:106.4
4,1,17:106.4
-3,0,17:106.8
2,-1,17:106.2
-2,-2,17:106.8
4,-3,17:106.4
-1,-3,17:106.1
3,-4,17:106.8
-3,-5,17:106.1
-4,-5,17:106.3
-6,-5,17:106.8
-5,-6,17:106.1
5,5,16:106.4
6,4,16:106.2
0,4,16:106.4
-3,4,16:106.2
-5,4,16:106.8
-1,3,16:106.4
-2,3,16:106.4
4,1,16:106.4
1,1,16:106.2
2,-1,16:106.2
-2,-2,16:106.8
4,-3,16:106.4
-1,-3,16:106.1
3,-4,16:106.8
-3,-5,16:106.1
-4,-5,16:106.3
-6,-5,16:106.8
-5,-6,16:106.1
5,5,15:106.4
6,4,15:106.2
0,4,15:106.4
-3,4,15:106.2
-5,4,15:106.8
-1,3,15:106.4
-2,3,15:106.4
4,1,15:106.4
1,1,15:106.2
-2,-2,15:106.8
4,-3,15:106.4
-1,-3,15:106.1
3,-4,15:106.8
-3,-5,15:106.1
-4,-5,15:106.3
-6,-5,15:106.8
-5,-6,15:106.1
5,5,14:106.4
6,4,14:106.2
0,4,14:106.4
-3,4,14:106.2
-5,4,14:106.8
-1,3,14:106.4
-2,3,14:106.4
-1,2,14:106.4
4,1,14:106.4
1,1,14:106.2
-2,-2,14:106.8
4,-3,14:106.4
-1,-3,14:106.1
3,-4,14:106.8
-3,-5,14:106.1
-4,-5,14:106.3
-6,-5,14:106.8
-5,-6,14:106.1
5,5,13:106.4
6,4,13:106.2
0,4,13:106.4
-3,4,13:106.2
-5,4,13:106.8
-1,3,13:106.4
-2,3,13:106.4
-1,2,13:106.4
4,1,13:106.4
1,1,13:106.2
1,-2,13:106.2
-2,-2,13:106.8
4,-3,13:106.4
-1,-3,13:106.1
3,-4,13:106.8
-3,-5,13:106.1
-4,-5,13:106.3
-6,-5,13:106.8
-5,-6,13:106.1
5,5,12:106.4
6,4,12:106.2
0,4,12:106.4
-3,4,12:106.2
-5,4,12:106.8
-1,3,12:106.4
-2,3,12:106.4
-1,2,12:106.4
4,1,12:106.4
1,1,12:106.2
1,0,12:106.4
1,-2,12:106.2
-2,-2,12:106.8
4,-3,12:106.4
3,-4,12:106.8
-3,-5,12:106.1
-4,-5,12:106.3
-6,-5,12:106.8
-5,-6,12:106.1
5,5,11:106.4
6,4,11:106.2
0,4,11:106.4
-3,4,11:106.2
-5,4,11:106.8
-1,3,11:106.4
-2,3,11:106.4
-1,2,11:106.4
4,1,11:106.4
1,1,11:106.2
-2,1,11:106.8
1,0,11:106.4
-3,-1,11:106.8
1,-2,11:106.2
4,-3,11:106.4
0,-3,11:106.1
3,-4,11:106.8
-3,-5,11:106.1
-4,-5,11:106.3
-6,-5,11:106.8
-5,-6,11:106.1
5,5,10:106.4
6,4,10:106.2
0,4,10:106.4
-3,4,10:106.2
-5,4,10:106.8
-1,3,10:106.4
-2,3,10:106.4
-1,2,10:106.4
4,1,10:106.4
1,1,10:106.2
-2,1,10:106.8
1,0,10:106.4
-3,-1,10:106.8
1,-2,10:106.2
4,-3,10:106.4
0,-3,10:106.1
-2,-3,10:106.1
3,-4,10:106.8
-3,-5,10:106.1
-4,-5,10:106.3
-6,-5,10:106.8
-5,-6,10:106.1
5,5,9:106.4
6,4,9:106.2
0,4,9:106.4
-3,4,9:106.2
-5,4,9:106.8
-1,3,9:106.4
-2,3,9:106.4
-1,2,9:106.4
4,1,9:106.4
1,1,9:106.2
-2,1,9:106.8
1,0,9:106.4
-3,-1,9:106.8
1,-2,9:106.2
4,-3,9:106.4
0,-3,9:106.1
-2,-3,9:106.1
3,-4,9:106.8
-3,-5,9:106.1
-4,-5,9:106.3
-6,-5,9:106.8
-5,-6,9:106.1
5,5,8:106.4
6,4,8:106.2
0,4,8:106.4
-3,4,8:106.2
-5,4,8:106.8
-1,3,8:106.4
-2,3,8:106.4
-1,2,8:106.4
4,1,8:106.4
1,1,8:106.2
-2,1,8:106.8
1,0,8:106.4
-3,-1,8:106.8
1,-2,8:106.2
4,-3,8:106.4
-2,-3,8:106.1
3,-4,8:106.8
-3,-5,8:106.1
-4,-5,8:106.3
-6,-5,8:106.8
-5,-6,8:106.1
5,5,7:106.4
6,4,7:106.2
0,4,7:106.4
-3,4,7:106.2
-5,4,7:106.8
-1,3,7:106.4
-2,3,7:106.4
-1,2,7:106.4
4,1,7:106.4
1,1,7:106.2
-2,1,7:106.8
1,0,7:106.4
-3,-1,7:106.8
1,-2,7:106.2
4,-3,7:106.4
-2,-3,7:106.1
3,-4,7:106.8
-4,-5,7:106.3
-6,-5,7:106.8
-5,-6,7:106.1
6,4,6:106.2
0,4,6:106.4
-3,4,6:106.2
-5,4,6:106.8
-1,3,6:106.4
-2,3,6:106.4
-1,2,6:106.4
4,1,6:106.4
1,1,6:106.2
-2,1,6:106.8
1,0,6:106.4
-3,-1,6:106.8
4,-3,6:106.4
-2,-3,6:106.1
3,-4,6:106.8
-4,-5,6:106.3
-5,-6,6:106.1
6,4,5:106.2
0,4,5:106.4
-3,4,5:106.2
-5,4,5:106.8
-1,3,5:106.4
-2,3,5:106.4
-1,2,5:106.4
4,1,5:106.4
-2,1,5:106.8
-3,-1,5:106.8
4,-3,5:106.4
-2,-3,5:106.1
3,-4,5:106.8
-4,-5,5:106.3
-5,-6,5:106.1
6,4,4:106.2
0,4,4:106.4
-3,4,4:106.2
-5,4,4:106.8
-1,3,4:106.4
-2,3,4:106.4
4,1,4:106.4
2,-1,4:106.2
-3,-1,4:106.8
4,-3,4:106.4
-2,-3,4:106.1
3,-4,4:106.8
-4,-5,4:106.3
6,4,3:106.2
0,4,3:106.4
-3,4,3:106.2
-5,4,3:106.8
-1,3,3:106.4
4,1,3:106.4
2,-1,3:106.2
-4,-1,3:106.8
4,-3,3:106.4
-2,-3,3:106.1
3,-4,3:106.8
-4,-5,3:106.3
0,7,2:106.4
6,4,2:106.2
1,4,2:106.2
-1,4,2:106.8
-3,4,2:106.2
-5,4,2:106.8
0,3,2:106.1
-1,3,2:106.4
5,2,2:106.2
3,2,2:106.8
-2,2,2:106.4
4,1,2:106.5
-3,1,2:106.8
1,0,2:106.2
2,-1,2:106.2
-4,-1,2:106.8
5,-2,2:106.2
5,-3,2:106.4
3,-3,2:106.4
1,-3,2:106.1
-2,-3,2:106.1
-6,-3,2:106.4
6,-4,2:106.2
2,-4,2:106.8
0,-4,2:106.1
-5,-4,2:106.2
-3,-5,2:106.4
-4,-5,2:106.3
-2,-6,2:106.2
-3,-7,2:106.1
0,7,1:106.4
0,6,1:106.4
6,4,1:106.2
1,4,1:106.2
-1,4,1:106.8
-3,4,1:106.2
-5,4,1:106.8
0,3,1:106.1
-1,3,1:106.4
5,2,1:106.2
3,2,1:106.8
1,2,1:106.4
-5,2,1:106.2
4,1,1:106.5
-3,1,1:106.8
1,0,1:106.2
2,-1,1:106.2
-4,-1,1:106.8
5,-2,1:106.2
5,-3,1:106.4
3,-3,1:106.4
1,-3,1:106.1
-6,-3,1:106.4
6,-4,1:106.2
2,-4,1:106.8
0,-4,1:106.1
-5,-4,1:106.2
-3,-5,1:106.4
-4,-5,1:106.1
-3,-7,1:106.1
0,7,0:106.4
0,6,0:106.4
2,5,0:31.1
2,4,0:31.1
1,4,0:31.1
0,4,0:31.2
-1,4,0:31.1
-3,4,0:106.2
-5,4,0:106.8
2,3,0:31.2
1,3,0:37.0
0,3,0:106.1
-3,3,0:31.1
4,2,0:31.1
3,2,0:31.1
2,2,0:31.1
0,2,0:31.1
-3,2,0:31.1
-4,2,0:31.1
-5,2,0:106.2
4,1,0:31.1
3,1,0:31.2
-4,1,0:31.1
-5,1,0:31.1
3,0,0:31.1
1,0,0:31.1
-4,0,0:31.1
3,-1,0:31.1
2,-1,0:106.2
-4,-1,0:31.1
5,-2,0:106.2
3,-2,0:31.1
-4,-2,0:31.1
-5,-2,0:31.1
3,-3,0:31.1
2,-3,0:31.1
-4,-3,0:31.1
-5,-3,0:31.2
3,-4,0:31.1
2,-4,0:31.1
1,-4,0:31.2
-3,-4,0:31.1
-4,-4,0:31.1
-5,-4,0:106.2
-6,-4,0:31.1
-2,-5,0:31.1
-3,-5,0:31.2
-4,-5,0:31.1
-3,-6,0:31.1
-3,-7,0:106.1
0,6,-1:106.4
5,-2,-1:106.2
-5,-4,-1:106.3
