[META]
version=2.0
spawnOnBlockType=2
spawnSunlight=True
spawnDarkness=True
spawnWater=False
spawnLava=False
underFill=False
randomRotation=True
dig=False
tree=true
branch=False
needsFoundation=True
rarity=100
collisionPercentage=80
spawnElevationMin=0
spawnElevationMax=100
spawnInBiome=Forest3
[DATA]
0,0,-4:3.0
-1,-1,-3:3.0
0,-1,-3:3.0
-1,0,-3:3.0
0,0,-3:17.1
1,0,-3:3.0
0,1,-3:3.0
0,-2,-2:3.0
-1,-1,-2:17.1
0,-1,-2:17.1
1,-1,-2:3.0
-2,0,-2:3.0
-1,0,-2:17.1
0,0,-2:17.1
1,0,-2:17.1
2,0,-2:17.1
-2,1,-2:3.0
-1,1,-2:3.0
0,1,-2:17.1
1,1,-2:17.1
-1,2,-2:3.0
0,2,-2:3.0
0,-2,-1:2.0
1,-2,-1:17.1
-2,-1,-1:17.1
-1,-1,-1:2.0
0,-1,-1:17.1
1,-1,-1:17.1
2,-1,-1:2.0
-2,0,-1:2.0
-1,0,-1:17.1
0,0,-1:17.1
1,0,-1:2.0
2,0,-1:17.1
-2,1,-1:2.0
-1,1,-1:17.1
0,1,-1:3.0
1,1,-1:17.1
-1,2,-1:2.0
0,2,-1:2.0
0,0,0:17.1
0,1,0:17.1
0,0,1:17.1
0,0,2:17.1
0,0,3:17.1
0,-1,4:18.6
-1,0,4:18.14
0,0,4:17.1
1,0,4:18.14
0,1,4:18.14
0,-2,5:18.14
-1,-1,5:18.14
0,-1,5:17.1
1,-1,5:18.14
2,-1,5:18.6
-2,0,5:18.14
-1,0,5:17.1
0,0,5:17.1
1,0,5:17.1
2,0,5:18.14
-1,1,5:18.14
0,1,5:17.1
1,1,5:18.14
2,1,5:18.6
0,2,5:18.14
0,-3,6:18.14
-1,-2,6:18.14
0,-2,6:17.1
1,-2,6:18.14
2,-2,6:18.14
-2,-1,6:18.14
0,-1,6:18.14
1,-1,6:18.14
2,-1,6:17.1
3,-1,6:18.14
-3,0,6:18.14
-2,0,6:17.1
-1,0,6:18.14
0,0,6:17.1
1,0,6:18.14
2,0,6:18.14
-2,1,6:18.14
0,1,6:18.14
1,1,6:18.14
2,1,6:17.1
3,1,6:18.14
-1,2,6:18.14
0,2,6:17.1
1,2,6:18.14
2,2,6:18.14
0,3,6:18.14
0,-3,7:18.14
-3,-2,7:18.6
-2,-2,7:18.14
-1,-2,7:18.14
0,-2,7:17.1
1,-2,7:18.14
2,-2,7:18.14
3,-2,7:18.6
-3,-1,7:18.14
-2,-1,7:17.1
-1,-1,7:18.14
0,-1,7:18.14
1,-1,7:18.14
2,-1,7:17.1
3,-1,7:18.14
-2,0,7:18.14
-1,0,7:18.14
0,0,7:17.1
1,0,7:18.14
2,0,7:18.14
-3,1,7:18.14
-2,1,7:17.1
-1,1,7:18.14
0,1,7:18.14
1,1,7:18.14
2,1,7:17.1
3,1,7:18.14
-3,2,7:18.6
-2,2,7:18.14
-1,2,7:18.14
0,2,7:17.1
1,2,7:18.14
2,2,7:18.14
3,2,7:18.6
-1,3,7:18.6
0,3,7:18.14
0,-4,8:18.14
-3,-3,8:18.14
-1,-3,8:18.14
0,-3,8:17.1
1,-3,8:18.14
3,-3,8:18.14
-4,-2,8:18.14
-3,-2,8:17.1
-2,-2,8:18.14
0,-2,8:18.14
2,-2,8:18.14
3,-2,8:17.1
4,-2,8:18.14
-3,-1,8:18.14
-2,-1,8:18.14
0,-1,8:18.14
2,-1,8:18.14
3,-1,8:18.14
-1,0,8:18.14
0,0,8:17.1
1,0,8:18.14
-3,1,8:18.14
-2,1,8:18.14
0,1,8:18.14
2,1,8:18.14
3,1,8:18.14
-4,2,8:18.14
-3,2,8:17.1
-2,2,8:18.14
0,2,8:18.14
2,2,8:18.14
3,2,8:17.1
4,2,8:18.14
-3,3,8:18.14
-2,3,8:18.14
-1,3,8:17.1
0,3,8:18.14
3,3,8:18.14
-1,4,8:18.14
0,-3,9:18.14
-3,-2,9:18.6
3,-2,9:18.6
0,-1,9:18.14
1,-1,9:18.14
-1,0,9:18.14
0,0,9:17.1
1,0,9:17.1
2,0,9:18.14
-2,1,9:18.14
-1,1,9:17.1
0,1,9:18.14
1,1,9:18.14
-3,2,9:18.14
-1,2,9:18.14
3,2,9:18.6
-1,3,9:18.14
-1,-2,10:18.6
0,-2,10:18.14
-1,-1,10:18.14
0,-1,10:17.1
1,-1,10:18.14
2,-1,10:18.14
-1,0,10:18.14
0,0,10:17.1
1,0,10:18.14
2,0,10:17.1
3,0,10:18.14
-2,1,10:18.14
-1,1,10:18.14
0,1,10:18.14
2,1,10:18.14
-3,2,10:18.14
-2,2,10:17.1
-1,2,10:18.14
-2,3,10:18.14
-1,-3,11:18.14
-2,-2,11:18.14
-1,-2,11:17.1
0,-2,11:18.14
-1,-1,11:18.14
0,-1,11:18.14
1,-1,11:18.6
3,-1,11:18.14
-1,0,11:18.14
0,0,11:17.1
1,0,11:18.14
2,0,11:18.14
3,0,11:17.1
4,0,11:18.14
-1,1,11:18.14
0,1,11:17.1
1,1,11:18.14
3,1,11:18.14
-2,2,11:18.6
0,2,11:18.14
-1,-2,12:18.6
1,-2,12:18.14
0,-1,12:18.14
1,-1,12:17.1
2,-1,12:18.14
-1,0,12:18.14
0,0,12:17.1
1,0,12:18.14
3,0,12:18.6
0,1,12:18.14
0,-1,13:18.14
1,-1,13:18.14
-1,0,13:18.14
0,0,13:17.1
1,0,13:18.14
0,1,13:18.14
0,0,14:18.14
0,2,0:31.2
-1,2,0:31.2
-2,1,0:31.2
1,0,0:31.2
-2,0,0:31.2
2,-1,0:31.2
-1,-1,0:31.2
0,-2,0:31.2
