[META]
version=2.0
spawnOnBlockType=3,2
spawnSunlight=True
spawnDarkness=True
spawnWater=False
spawnLava=False
underFill=False
randomRotation=False
dig=True
tree=True
branch=False
needsFoundation=True
rarity=70
collisionPercentage=20
spawnElevationMin=0
spawnElevationMax=240
spawnInBiome=Forest3
[DATA]
-2,1,-6:1.5
-1,1,-6:1.5
-2,2,-6:1.5
-3,-2,-5:17.0
-2,0,-5:1.5
-1,0,-5:1.5
-5,1,-5:17.0
-3,1,-5:1.5
-2,1,-5:1.5
-1,1,-5:1.5
0,1,-5:1.5
-2,2,-5:1.5
-1,2,-5:1.5
2,2,-5:17.0
-2,3,-5:1.5
-2,4,-5:17.0
-2,5,-5:17.0
-3,-2,-4:17.0
-2,-2,-4:17.0
-2,-1,-4:17.0
-1,-1,-4:88.5
1,-1,-4:17.0
-2,0,-4:3.5
-1,0,-4:3.5
0,0,-4:3.5
-5,1,-4:17.0
-4,1,-4:17.0
-3,1,-4:3.5
-2,1,-4:3.5
-1,1,-4:3.5
0,1,-4:88.5
-3,2,-4:3.5
-2,2,-4:3.5
1,2,-4:17.0
2,2,-4:17.0
-2,3,-4:17.0
-2,4,-4:17.0
-1,-2,-3:3.5
-2,-1,-3:17.0
-1,-1,-3:3.5
0,-1,-3:3.5
-3,0,-3:88.5
-2,0,-3:17.0
-1,0,-3:3.5
0,0,-3:17.0
1,0,-3:17.0
-4,1,-3:17.0
-3,1,-3:17.0
-2,1,-3:3.5
-1,1,-3:3.5
0,1,-3:3.5
1,1,-3:88.5
-3,2,-3:3.5
-2,2,-3:3.5
-1,2,-3:3.5
0,2,-3:17.0
1,2,-3:17.0
-3,3,-3:88.5
-2,3,-3:17.0
-1,3,-3:88.5
-2,4,-3:88.5
-1,-3,-2:88.5
0,-3,-2:88.5
-2,-2,-2:88.5
-1,-2,-2:3.5
0,-2,-2:88.5
-3,-1,-2:88.5
-2,-1,-2:3.5
-1,-1,-2:3.5
0,-1,-2:3.5
1,-1,-2:88.5
-3,0,-2:3.5
-2,0,-2:17.0
-1,0,-2:88.5
0,0,-2:17.0
-3,1,-2:17.0
-2,1,-2:17.0
-1,1,-2:17.0
0,1,-2:3.5
1,1,-2:3.5
-3,2,-2:88.5
-2,2,-2:17.0
-1,2,-2:17.0
0,2,-2:17.0
-4,3,-2:3.5
-3,3,-2:88.5
-2,3,-2:17.0
-1,3,-2:17.0
0,3,-2:3.5
-4,4,-2:88.5
-3,4,-2:3.5
-2,4,-2:3.5
-1,4,-2:88.5
0,-4,-1:110.5
-1,-3,-1:110.5
0,-3,-1:3.0
1,-3,-1:110.5
-2,-2,-1:2.5
-1,-2,-1:2.5
0,-2,-1:110.5
-3,-1,-1:110.5
-2,-1,-1:2.5
-1,-1,-1:110.5
0,-1,-1:110.5
1,-1,-1:2.5
-3,0,-1:2.5
-2,0,-1:17.0
-1,0,-1:17.0
0,0,-1:17.0
1,0,-1:110.5
-3,1,-1:110.5
-2,1,-1:17.0
-1,1,-1:17.0
0,1,-1:17.0
1,1,-1:110.5
-4,2,-1:110.5
-3,2,-1:2.5
-2,2,-1:17.0
-1,2,-1:17.0
0,2,-1:17.0
1,2,-1:2.5
-4,3,-1:110.5
-3,3,-1:110.5
-2,3,-1:110.5
-1,3,-1:110.5
0,3,-1:2.5
-5,4,-1:110.5
-4,4,-1:3.0
-3,4,-1:110.5
-2,4,-1:110.5
-1,4,-1:2.5
-4,5,-1:110.5
-3,5,-1:110.5
0,-3,0:99.10
-1,0,0:17.0
0,0,0:17.0
-2,1,0:17.0
-1,1,0:17.0
0,1,0:17.0
-2,2,0:17.0
-1,2,0:17.0
0,2,0:17.0
-4,4,0:99.10
0,-3,1:99.10
-2,0,1:99.1
-1,0,1:17.0
-2,1,1:17.0
-1,1,1:17.0
0,1,1:17.0
-1,2,1:17.0
-5,3,1:99.1
-4,3,1:99.2
-3,3,1:99.3
-5,4,1:99.4
-4,4,1:99.3
-3,4,1:99.3
-5,5,1:99.7
-4,5,1:99.8
-3,5,1:99.9
0,-3,2:99.10
-1,0,2:17.0
0,0,2:99.3
-2,1,2:17.0
-1,1,2:17.0
0,1,2:17.0
-1,2,2:17.0
-1,-4,3:99.1
0,-4,3:99.2
1,-4,3:99.3
-1,-3,3:99.4
0,-3,3:99.8
1,-3,3:99.3
-1,-2,3:99.7
0,-2,3:99.8
1,-2,3:99.9
-1,0,3:17.0
-2,1,3:17.0
-1,1,3:17.0
0,1,3:17.0
-1,2,3:17.0
-1,3,3:17.0
-1,4,3:17.0
0,-1,4:17.0
-1,0,4:17.0
0,0,4:17.0
-2,1,4:17.0
-1,1,4:17.0
0,1,4:17.0
1,1,4:99.3
-2,2,4:17.0
-1,2,4:17.0
0,2,4:99.9
1,2,4:99.9
-1,5,4:17.0
1,-1,5:17.0
-2,0,5:17.0
-1,0,5:17.0
-2,1,5:17.0
-1,1,5:17.0
0,1,5:17.0
-2,2,5:17.0
-1,2,5:17.0
-1,-1,6:17.0
-2,0,6:17.0
-1,0,6:17.0
-3,1,6:17.0
-2,1,6:17.0
-1,1,6:17.0
0,1,6:17.0
-2,2,6:17.0
-1,2,6:17.0
0,2,6:17.0
-3,-3,7:17.0
-1,-2,7:17.0
-2,-1,7:99.1
-1,-1,7:17.0
-3,0,7:99.1
-2,0,7:17.0
-1,0,7:17.0
-3,1,7:17.0
-2,1,7:17.0
0,1,7:17.0
1,1,7:17.0
-2,2,7:17.0
-2,3,7:17.0
-2,4,7:17.0
-2,-3,8:17.0
-1,-3,8:17.0
-1,-2,8:17.0
0,-2,8:17.0
1,-2,8:17.0
-5,0,8:17.0
-2,0,8:99.1
-5,1,8:17.0
-4,1,8:17.0
-3,1,8:17.0
-2,1,8:17.0
1,1,8:17.0
2,1,8:17.0
-2,2,8:17.0
2,2,8:17.0
-5,4,8:17.0
-2,4,8:17.0
-1,4,8:17.0
0,4,8:17.0
-2,5,8:17.0
1,5,8:17.0
1,6,8:17.0
-1,-4,9:17.0
-3,-3,9:17.0
-1,-3,9:17.0
2,-3,9:17.0
-5,-2,9:17.0
1,-2,9:17.0
-5,-1,9:17.0
-6,1,9:17.0
-2,1,9:17.0
-4,2,9:17.0
2,2,9:17.0
-6,3,9:17.0
-5,3,9:17.0
2,3,9:17.0
0,4,9:17.0
-2,5,9:17.0
-3,6,9:17.0
-2,6,9:17.0
2,6,9:17.0
-1,-5,10:17.0
-6,-2,10:17.0
2,-2,10:17.0
-2,0,10:17.0
-2,1,10:17.0
2,3,10:17.0
3,3,10:17.0
3,4,10:17.0
-4,6,10:17.0
-2,7,10:17.0
2,7,10:17.0
-2,-5,11:17.0
-6,-3,11:17.0
-6,-1,11:17.0
0,-1,11:17.0
-1,0,11:17.0
0,0,11:17.0
-2,2,11:17.0
-4,5,11:17.0
-5,6,11:17.0
1,0,12:17.0
-2,3,12:17.0
-2,2,9:39.5
-4,1,9:39.5
-1,-2,9:39.5
-1,0,8:39.5
-1,3,4:39.5
0,0,1:40.5
-4,5,0:39.5
-2,4,0:39.0
-5,4,0:39.5
0,3,0:31.1
-2,3,0:39.0
-3,3,0:39.5
1,2,0:31.1
-3,2,0:31.1
1,1,0:40.0
1,0,0:40.0
-3,0,0:31.1
1,-1,0:31.1
0,-1,0:40.0
-1,-1,0:39.0
0,-2,0:39.5
-1,-2,0:31.1
