[META]
version=2.0
spawnOnBlockType=2,1,3
spawnSunlight=True
spawnDarkness=True
spawnWater=False
spawnLava=False
underFill=False
randomRotation=True
dig=False
tree=True
branch=False
needsFoundation=True
rarity=1000
collisionPercentage=100
spawnElevationMin=0
spawnElevationMax=125
spawnInBiome=Urwald,Urwald2,Jungle,Extreme Hills
[DATA]
0,0,0:17.0
-2,-1,0:31.1
1,-2,0:31.2
0,1,0:17.0
0,-1,0:17.0
-1,0,0:17.0
1,0,0:17.0
1,2,0:31.1
-2,0,0:17.0
0,-2,0:17.0
-1,-1,0:17.0
2,0,0:17.0
0,2,0:17.0
1,1,0:17.0
-1,1,0:17.0
1,-1,0:17.0
-2,2,0:31.1
0,-3,0:31.1
2,-1,0:31.2
-1,2,0:31.1
-2,1,0:31.2
2,1,0:31.1
-1,-2,0:31.1
0,0,12:17.0
0,0,11:17.0
0,0,10:17.0
0,0,9:17.0
0,0,8:17.0
0,0,7:17.0
0,0,6:17.0
0,0,5:17.0
0,0,4:17.0
-1,0,4:17.0
1,0,4:17.0
0,-1,4:17.0
0,1,4:17.0
0,0,3:17.0
-1,0,3:17.0
0,-1,3:17.0
1,0,3:17.0
0,1,3:17.0
0,0,2:17.0
-1,0,2:17.0
0,-1,2:17.0
1,0,2:17.0
0,1,2:17.0
0,-2,2:17.0
2,0,2:17.0
0,2,2:17.0
-2,0,2:17.0
0,0,1:17.0
-1,0,1:17.0
0,-1,1:17.0
1,0,1:17.0
0,1,1:17.0
-2,0,1:17.0
-1,-1,1:17.0
0,-2,1:17.0
1,-1,1:17.0
2,0,1:17.0
1,1,1:17.0
0,2,1:17.0
-1,1,1:17.0
0,0,13:17.0
0,0,18:17.0
0,0,19:17.0
0,0,20:17.0
0,0,21:17.0
0,0,22:17.0
0,0,23:17.0
0,0,24:17.0
0,0,14:17.0
0,0,15:17.0
0,0,16:17.0
0,0,17:17.0
0,0,25:17.0
-3,-4,25:85
0,0,26:17.0
-3,-4,26:85
-2,0,-1:2
-1,0,-1:2
0,0,-1:2
1,0,-1:2
2,0,-1:2
0,-2,-1:2
0,-1,-1:2
0,1,-1:2
0,2,-1:2
-1,1,-1:2
-1,-1,-1:2
1,-1,-1:2
1,1,-1:2
-2,1,-1:2
-2,2,-1:2
-1,2,-1:2
1,2,-1:2
2,1,-1:2
2,-1,-1:2
1,-2,-1:2
0,-3,-1:2
-1,-2,-1:2
-2,-1,-1:2
0,0,27:17.0
0,1,27:17.0
-1,4,27:85
-3,-4,27:85
0,0,28:17.0
0,-1,28:17.0
0,2,28:17.0
-1,0,28:17.0
1,0,28:17.0
-1,4,28:85
4,-4,28:85
-3,-4,28:85
0,-2,29:17.0
0,2,29:17.0
0,0,29:17.0
-2,1,29:17.0
2,0,29:17.0
-1,4,29:85
4,-4,29:85
-3,-4,29:85
0,0,30:17.0
-2,1,30:17.0
1,1,30:17.0
2,2,30:17.0
0,-3,30:17.0
-1,3,30:17.0
-1,4,30:85
4,-4,30:85
-3,-4,30:85
0,0,31:17.0
-3,1,31:17.0
-4,2,31:17.0
0,4,31:17.0
2,3,31:17.0
3,2,31:17.0
4,1,31:17.0
-1,-3,31:17.0
1,-3,31:17.0
-2,-2,31:17.0
-2,-4,31:17.0
2,0,31:17.0
-1,4,31:85
4,-4,31:85
-3,-4,31:85
0,0,32:17.0
-2,-1,32:17.0
-4,0,32:17.0
-3,-3,32:17.0
-3,-4,32:17.0
-3,3,32:17.0
-1,3,32:17.0
-1,4,32:17.0
3,3,32:17.0
3,0,32:17.0
4,0,32:17.0
2,-2,32:17.0
3,-2,32:17.0
3,-3,32:17.0
1,-4,32:17.0
0,4,32:18.0
5,0,32:18.0
-5,0,32:18.0
0,-5,32:18.0
1,-5,32:18.0
-2,-5,32:18.0
-2,-4,32:18.0
-3,-5,32:18.0
-4,-4,32:18.0
-4,-3,32:18.0
-4,-2,32:18.0
-4,-1,32:18.0
-5,-1,32:18.0
-5,1,32:18.0
-4,3,32:18.0
-4,2,32:18.0
-4,1,32:18.0
-3,4,32:18.0
-2,4,32:18.0
-1,5,32:18.0
3,4,32:17.0
4,2,32:18.0
4,1,32:18.0
5,2,32:18.0
5,1,32:18.0
2,-4,32:18.0
2,-3,32:18.0
3,-4,32:18.0
4,-3,32:18.0
4,-2,32:18.0
4,-1,32:18.0
3,-1,32:18.0
5,-1,32:18.0
4,3,32:18.0
0,5,32:18.0
2,4,32:18.0
1,5,32:18.0
-5,2,32:18.0
-1,-5,32:18.0
0,-6,32:18.0
-1,-6,32:18.0
-2,-6,32:18.0
-5,-3,32:18.0
-5,-2,32:18.0
-5,3,32:18.0
-4,4,32:18.0
-3,5,32:18.0
-2,5,32:18.0
2,5,32:18.0
3,5,32:18.0
4,4,32:18.0
5,-2,32:18.0
3,-5,32:18.0
2,-5,32:18.0
1,-6,32:18.0
4,-4,32:85
1,4,32:18.0
0,0,33:18.0
-1,0,33:18.0
-2,0,33:18.0
-3,0,33:17.0
-4,0,33:18.0
-5,0,33:17.0
1,0,33:18.0
2,0,33:17.0
3,0,33:18.0
4,0,33:18.0
5,0,33:17.0
0,1,33:18.0
0,2,33:18.0
0,3,33:18.0
0,4,33:18.0
0,5,33:17.0
0,-1,33:18.0
0,-2,33:18.0
0,-3,33:18.0
0,-4,33:18.0
0,-5,33:18.0
1,-5,33:17.0
-1,-5,33:17.0
-2,-5,33:18.0
-5,-1,33:18.0
-5,2,33:18.0
-5,1,33:18.0
-1,5,33:18.0
1,5,33:18.0
5,-1,33:18.0
5,1,33:18.0
5,2,33:18.0
4,3,33:18.0
3,4,33:17.0
2,4,33:18.0
-2,4,33:18.0
-3,3,33:18.0
-4,3,33:17.0
-4,-2,33:18.0
-4,-3,33:18.0
-3,-4,33:18.0
2,-4,33:18.0
3,-4,33:17.0
4,-3,33:18.0
4,-2,33:18.0
-3,-2,33:18.0
-3,-3,33:18.0
-2,-3,33:18.0
-2,-4,33:17.0
-1,-4,33:18.0
-1,-3,33:18.0
-1,-2,33:18.0
-1,-1,33:18.0
-2,-1,33:18.0
-3,-1,33:18.0
-4,-1,33:17.0
-2,-2,33:18.0
-4,1,33:18.0
-3,1,33:18.0
-2,1,33:18.0
-1,1,33:18.0
-1,2,33:17.0
-2,2,33:18.0
-3,2,33:18.0
-4,2,33:18.0
-2,3,33:18.0
-1,3,33:18.0
-1,4,33:18.0
1,4,33:18.0
2,3,33:18.0
1,3,33:18.0
1,2,33:18.0
1,1,33:18.0
2,1,33:18.0
3,1,33:18.0
4,1,33:18.0
4,2,33:18.0
3,2,33:18.0
3,3,33:18.0
2,2,33:18.0
3,-1,33:18.0
4,-1,33:18.0
2,-1,33:18.0
1,-1,33:18.0
1,-2,33:17.0
2,-3,33:18.0
2,-2,33:18.0
3,-2,33:18.0
3,-3,33:18.0
1,-3,33:18.0
1,-4,33:18.0
-5,-2,33:18.0
-5,-3,33:18.0
-4,-4,33:18.0
-3,-5,33:18.0
-3,-6,33:18.0
-2,-6,33:18.0
-1,-6,33:18.0
0,-7,33:18.0
-1,-7,33:18.0
0,-6,33:18.0
1,-6,33:18.0
2,-6,33:17.0
2,-5,33:18.0
3,-5,33:18.0
4,-5,33:18.0
5,-4,33:18.0
4,-4,33:17.0
5,-3,33:18.0
5,-2,33:18.0
6,-1,33:18.0
6,0,33:17.0
6,1,33:18.0
5,3,33:18.0
5,4,33:18.0
4,4,33:18.0
2,5,33:18.0
3,5,33:17.0
1,6,33:18.0
0,6,33:18.0
-1,6,33:17.0
-2,5,33:18.0
-3,5,33:18.0
-3,4,33:18.0
-4,4,33:18.0
-5,3,33:18.0
-6,1,33:18.0
-6,0,33:18.0
-6,-1,33:18.0
-4,-5,33:18.0
7,0,33:18.0
8,0,33:18.0
7,1,33:18.0
7,-1,33:18.0
6,-2,33:18.0
6,-3,33:18.0
6,2,33:18.0
6,3,33:18.0
4,5,33:18.0
5,5,33:18.0
3,6,33:18.0
2,6,33:18.0
1,7,33:18.0
0,7,33:18.0
-1,7,33:18.0
-2,6,33:18.0
8,-1,33:18.0
7,-2,33:18.0
3,-6,33:18.0
4,-6,33:18.0
5,-5,33:18.0
6,-4,33:18.0
3,-7,33:18.0
2,-7,33:18.0
1,-7,33:18.0
1,-8,33:18.0
0,-8,33:18.0
2,-8,33:18.0
-2,-7,33:18.0
-3,-7,33:18.0
-4,-6,33:18.0
-5,-4,33:18.0
-1,-8,33:18.0
-6,-2,33:18.0
-7,0,33:18.0
-7,-1,33:18.0
-6,-3,33:18.0
-6,2,33:18.0
-7,1,33:18.0
-5,4,33:18.0
-6,3,33:18.0
-4,5,33:18.0
-3,6,33:18.0
-2,7,33:18.0
7,2,33:18.0
8,1,33:18.0
6,4,33:18.0
7,3,33:18.0
2,7,33:18.0
3,7,33:18.0
4,6,33:18.0
5,-6,33:18.0
6,-5,33:18.0
-3,0,34:18.0
-2,0,34:18.0
-1,0,34:18.0
0,0,34:18.0
1,0,34:18.0
2,0,34:18.0
0,-3,34:18.0
0,-2,34:18.0
0,-1,34:18.0
0,1,34:18.0
0,2,34:18.0
0,3,34:18.0
1,2,34:18.0
1,1,34:18.0
1,-2,34:18.0
1,-1,34:18.0
2,-1,34:18.0
2,1,34:18.0
-3,1,34:18.0
-2,-1,34:18.0
-2,1,34:18.0
-2,2,34:18.0
-1,3,34:18.0
-1,2,34:18.0
-1,1,34:18.0
-1,-1,34:18.0
-1,-2,34:18.0
-3,-1,34:18.0
-3,-2,34:18.0
-2,-2,34:18.0
-1,-3,34:18.0
0,-4,34:18.0
1,-4,34:18.0
1,-3,34:18.0
2,-3,34:18.0
2,-2,34:18.0
3,-1,34:18.0
3,0,34:18.0
3,-2,34:18.0
3,1,34:18.0
2,2,34:18.0
-2,-3,34:18.0
-1,-4,34:18.0
0,-5,34:18.0
1,3,34:18.0
3,-3,34:18.0
2,-4,34:18.0
1,-5,34:18.0
-2,-4,34:18.0
-1,-5,34:18.0
-3,-3,34:18.0
-4,0,34:18.0
-4,-1,34:18.0
4,-1,34:18.0
4,-2,34:18.0
-5,0,34:18.0
-4,-2,34:18.0
-5,-1,34:18.0
-5,-2,34:18.0
-3,-4,34:18.0
-4,-3,34:18.0
-2,-5,34:18.0
0,-6,34:18.0
1,-6,34:18.0
2,-6,34:18.0
2,-5,34:18.0
3,-4,34:18.0
4,-4,34:18.0
3,-5,34:18.0
4,-3,34:18.0
6,0,34:18.0
5,0,34:18.0
4,0,34:18.0
5,-1,34:18.0
5,-2,34:18.0
5,1,34:18.0
4,1,34:18.0
4,2,34:18.0
3,2,34:18.0
3,3,34:18.0
3,4,34:18.0
3,5,34:18.0
2,3,34:18.0
2,4,34:18.0
2,5,34:18.0
1,4,34:18.0
0,5,34:18.0
-1,5,34:18.0
-1,6,34:18.0
-1,4,34:18.0
0,4,34:18.0
-2,5,34:18.0
-2,4,34:18.0
-3,4,34:18.0
-3,3,34:18.0
-4,3,34:18.0
-2,3,34:18.0
-3,2,34:18.0
-4,1,34:18.0
-4,2,34:18.0
-5,1,34:18.0
4,3,34:18.0
5,2,34:18.0
6,1,34:18.0
4,4,34:18.0
1,5,34:18.0
0,6,34:18.0
1,6,34:18.0
