[META]
version=2.0
spawnOnBlockType=2,12
spawnSunlight=True
spawnDarkness=False
spawnWater=False
spawnLava=False
underFill=False
randomRotation=True
dig=False
tree=True
branch=False
needsFoundation=True
rarity=15
collisionPercentage=0
spawnElevationMin=0
spawnElevationMax=245
spawnInBiome=Plains
[DATA]
0,0,0:17.0
0,0,1:17.0
0,0,2:17.0
0,0,3:17.0
0,0,4:17.0
0,0,5:17.0
0,0,6:17.0
0,1,6:17.0
0,0,7:17.0
0,-1,7:17.0
0,2,7:17.0
0,-1,8:17.0
0,2,8:17.0
0,3,9:17.0
0,-2,9:17.0
0,-3,9:17.0
0,1,9:17.0
0,-4,10:17.0
0,-5,10:17.0
0,4,10:17.0
0,5,10:17.0
-1,-4,10:17.0
0,0,10:17.0
0,-1,10:18.0
-1,0,10:18.0
1,0,10:18.0
0,6,11:17.0
-1,-6,11:17.0
1,-6,11:17.0
-2,-4,11:17.0
0,-3,11:17.0
0,3,11:17.0
0,0,11:18.0
-1,5,12:17.0
0,6,12:17.0
0,7,12:17.0
0,-2,12:17.0
0,2,12:17.0
-1,-1,12:17.0
1,-1,12:17.0
2,-1,12:17.0
-1,2,12:17.0
1,3,12:17.0
2,-6,12:17.0
-2,-6,12:17.0
-3,-4,12:17.0
3,-2,13:17.0
-2,2,13:17.0
2,3,13:17.0
3,4,13:17.0
-2,5,13:17.0
1,8,13:17.0
-3,-3,13:17.0
-2,-7,13:17.0
3,-7,13:17.0
2,7,13:17.0
0,9,13:17.0
3,-5,13:17.0
-3,-6,13:17.0
-4,-4,13:17.0
-2,-4,13:17.0
1,-6,13:17.0
3,0,13:17.0
-2,-1,13:17.0
-1,-8,13:18.0
-2,-8,13:18.0
-3,-7,13:18.0
-4,-6,13:18.0
-5,-4,13:18.0
-4,-3,13:18.0
-3,-2,13:18.0
-3,0,13:18.0
-3,-1,13:18.0
-2,0,13:18.0
2,-8,13:18.0
3,-8,13:18.0
4,-7,13:18.0
4,-6,13:18.0
4,-5,13:18.0
3,-4,13:18.0
3,-3,13:18.0
4,-2,13:18.0
4,-1,13:18.0
4,0,13:18.0
3,1,13:18.0
2,1,13:18.0
0,0,13:18.0
-1,0,13:18.0
1,0,13:18.0
2,0,13:18.0
3,3,13:18.0
4,4,13:18.0
4,5,13:18.0
3,6,13:18.0
3,5,13:18.0
3,7,13:18.0
2,8,13:18.0
1,9,13:18.0
0,10,13:18.0
-1,9,13:18.0
-3,5,13:18.0
-3,3,13:18.0
-3,2,13:18.0
-2,1,13:18.0
-2,3,13:18.0
-2,4,13:18.0
-2,6,13:18.0
-1,2,13:18.0
1,3,13:18.0
1,2,13:18.0
2,2,13:18.0
-3,3,14:17.0
-3,6,14:17.0
-1,9,14:17.0
1,10,14:17.0
2,8,14:17.0
2,6,14:17.0
4,4,14:17.0
4,5,14:17.0
4,-3,14:17.0
2,-2,14:17.0
-1,2,14:17.0
1,3,14:17.0
-1,6,14:17.0
-1,-3,14:17.0
-1,0,14:17.0
-1,-8,14:17.0
-4,-7,14:17.0
-1,-6,14:17.0
3,-8,14:17.0
4,-7,14:17.0
4,-5,14:17.0
-1,-10,14:18.0
0,-10,14:18.0
1,-10,14:18.0
2,-10,14:18.0
2,-9,14:18.0
-1,-9,14:18.0
0,-9,14:18.0
1,-9,14:18.0
-2,-9,14:18.0
-2,-8,14:18.0
-3,-8,14:18.0
-3,-7,14:18.0
-4,-8,14:18.0
-5,-7,14:18.0
-4,-6,14:18.0
3,-9,14:18.0
4,-8,14:18.0
5,-7,14:18.0
4,-6,14:18.0
5,-6,14:18.0
5,-5,14:18.0
5,-4,14:18.0
4,-4,14:18.0
5,-3,14:18.0
4,-2,14:18.0
3,-2,14:18.0
3,-1,14:18.0
2,-1,14:18.0
1,-1,14:18.0
0,-1,14:18.0
-1,-1,14:18.0
-1,-2,14:18.0
-2,-2,14:18.0
-2,-3,14:18.0
-3,-3,14:18.0
-3,-4,14:18.0
-4,-4,14:18.0
-4,-5,14:18.0
-2,-1,14:18.0
-2,0,14:18.0
1,0,14:18.0
0,0,14:18.0
-2,1,14:18.0
-1,1,14:18.0
-3,-1,14:18.0
-3,-2,14:18.0
-4,-3,14:18.0
2,0,14:18.0
3,0,14:18.0
4,-1,14:18.0
5,-2,14:18.0
2,1,14:18.0
1,1,14:18.0
0,1,14:18.0
4,0,14:18.0
4,2,14:18.0
3,2,14:18.0
3,1,14:18.0
1,-2,14:18.0
0,-2,14:18.0
3,-3,14:18.0
3,-4,14:18.0
3,-5,14:18.0
2,-7,14:18.0
2,-8,14:18.0
3,-7,14:18.0
3,-6,14:18.0
0,-8,14:18.0
-2,-7,14:18.0
-2,-6,14:18.0
-3,-6,14:18.0
-1,-7,14:18.0
-2,-4,14:18.0
-3,-5,14:18.0
-5,-6,14:18.0
-5,-5,14:18.0
-5,-4,14:18.0
-5,-3,14:18.0
-4,-2,14:18.0
-4,3,14:18.0
-5,4,14:18.0
-5,5,14:18.0
-5,6,14:18.0
-4,6,14:18.0
-4,7,14:18.0
-4,8,14:18.0
-4,9,14:18.0
-3,9,14:18.0
-3,8,14:18.0
-2,8,14:18.0
-2,9,14:18.0
-2,7,14:18.0
-3,7,14:18.0
-2,10,14:18.0
-1,10,14:18.0
0,10,14:18.0
0,11,14:18.0
1,11,14:18.0
2,11,14:18.0
2,10,14:18.0
2,9,14:18.0
3,9,14:18.0
3,8,14:18.0
3,7,14:18.0
4,7,14:18.0
4,6,14:18.0
5,6,14:18.0
5,5,14:18.0
5,4,14:18.0
4,3,14:18.0
5,7,14:18.0
5,8,14:18.0
4,8,14:18.0
4,9,14:18.0
3,10,14:18.0
-3,2,14:18.0
-2,2,14:18.0
-2,3,14:18.0
-4,4,14:18.0
-3,4,14:18.0
-4,5,14:18.0
-3,5,14:18.0
-2,6,14:18.0
-1,7,14:18.0
-1,8,14:18.0
0,9,14:18.0
1,9,14:18.0
1,8,14:18.0
2,7,14:18.0
3,6,14:18.0
3,4,14:18.0
3,3,14:18.0
2,2,14:18.0
0,2,14:18.0
5,3,14:18.0
-4,-7,15:18.0
-4,-6,15:18.0
-4,-5,15:18.0
-4,-4,15:18.0
-1,-9,15:17.0
0,-9,15:18.0
4,-6,15:18.0
4,-5,15:18.0
0,-5,15:17.0
-3,-4,15:18.0
3,-4,15:18.0
4,-4,15:18.0
-2,-3,15:18.0
-3,-3,15:18.0
2,-3,15:18.0
3,-3,15:18.0
4,-3,15:18.0
2,-2,15:18.0
1,-2,15:17.0
0,-2,15:18.0
-1,-2,15:18.0
3,-2,15:17.0
-2,-2,15:17.0
-3,-7,15:18.0
4,-7,15:18.0
1,-8,15:18.0
0,-8,15:17.0
-1,-8,15:18.0
-2,-8,15:18.0
1,-9,15:18.0
2,-9,15:18.0
-3,3,15:18.0
-3,4,15:18.0
-3,5,15:18.0
-3,6,15:18.0
-2,6,15:18.0
-1,6,15:18.0
-1,7,15:18.0
-1,8,15:18.0
-1,9,15:18.0
0,9,15:18.0
1,9,15:18.0
1,10,15:18.0
2,9,15:18.0
2,8,15:18.0
2,7,15:18.0
2,6,15:18.0
3,6,15:18.0
3,5,15:18.0
4,5,15:18.0
4,4,15:18.0
3,4,15:18.0
2,4,15:18.0
2,3,15:18.0
1,3,15:18.0
1,2,15:18.0
0,2,15:18.0
-1,2,15:18.0
-2,2,15:18.0
-2,3,15:18.0
-2,4,15:18.0
-1,4,15:18.0
0,4,15:18.0
0,3,15:18.0
1,4,15:18.0
0,5,15:18.0
-1,5,15:18.0
-1,3,15:18.0
-2,5,15:18.0
-2,7,15:18.0
0,8,15:18.0
0,7,15:18.0
0,6,15:18.0
1,5,15:18.0
1,6,15:18.0
1,8,15:18.0
3,7,15:18.0
1,7,15:18.0
2,5,15:18.0
3,3,15:18.0
2,2,15:18.0
3,8,15:18.0
4,6,15:18.0
0,10,15:18.0
-2,8,15:18.0
-3,7,15:18.0
0,-1,15:18.0
1,-1,15:18.0
2,-1,15:18.0
-1,-1,15:18.0
-4,-8,15:17.0
-5,-7,15:17.0
5,-3,15:17.0
5,-5,15:17.0
5,-8,15:17.0
4,-9,15:17.0
-2,0,15:17.0
-3,-2,15:18.0
-2,-1,15:18.0
-3,0,15:18.0
-3,-1,15:18.0
-2,1,15:18.0
-1,0,15:18.0
0,0,15:18.0
3,-1,15:18.0
4,-2,15:18.0
5,-2,15:18.0
5,-4,15:18.0
6,-3,15:18.0
5,-6,15:18.0
6,-5,15:18.0
5,-7,15:18.0
6,-8,15:18.0
5,-9,15:18.0
4,-8,15:18.0
6,-7,15:18.0
3,-9,15:18.0
4,-10,15:18.0
0,-10,15:18.0
-1,-10,15:18.0
-2,-9,15:18.0
-3,-8,15:18.0
-3,-9,15:18.0
-4,-9,15:18.0
-5,-9,15:18.0
-5,-8,15:18.0
-6,-7,15:18.0
-6,-6,15:18.0
-5,-6,15:18.0
-5,-5,15:18.0
-2,-10,15:18.0
1,-10,15:18.0
3,-10,15:18.0
2,-10,15:18.0
-4,-3,15:18.0
-5,-4,15:18.0
1,-4,15:17.0
1,-6,15:17.0
6,-6,15:18.0
6,-4,15:18.0
1,0,15:18.0
-2,-3,16:18.0
-1,-3,16:18.0
0,-3,16:18.0
1,-3,16:18.0
2,-3,16:18.0
2,-4,16:18.0
3,-4,16:18.0
3,-3,16:18.0
2,-5,16:18.0
3,-5,16:18.0
2,-6,16:18.0
1,-6,16:18.0
1,-5,16:18.0
1,-4,16:18.0
0,-4,16:18.0
0,-5,16:18.0
-1,-5,16:18.0
-1,-4,16:18.0
-2,-4,16:18.0
-2,-5,16:18.0
-3,-5,16:18.0
-2,4,16:18.0
-2,5,16:18.0
-2,6,16:18.0
-2,7,16:18.0
-1,7,16:18.0
0,7,16:18.0
0,8,16:18.0
1,8,16:18.0
2,7,16:18.0
3,6,16:18.0
3,5,16:18.0
2,4,16:18.0
2,3,16:18.0
1,3,16:18.0
0,4,16:18.0
-1,4,16:18.0
1,4,16:18.0
0,3,16:18.0
0,5,16:18.0
-1,5,16:18.0
1,5,16:18.0
2,5,16:18.0
2,6,16:18.0
1,6,16:18.0
0,6,16:18.0
-1,6,16:18.0
1,7,16:18.0
-2,-6,16:18.0
-1,-6,16:18.0
0,-6,16:18.0
0,-7,16:18.0
1,-7,16:18.0
2,-7,16:18.0
-1,-7,16:18.0
0,-2,16:18.0
1,-2,16:18.0
-1,-2,16:18.0
-3,-4,16:18.0
-2,0,16:18.0
-2,-1,16:18.0
-2,-2,16:18.0
-1,-1,16:18.0
-3,-2,16:18.0
-3,-3,16:18.0
-4,-5,16:18.0
-4,-6,16:18.0
-5,-6,16:18.0
-5,-7,16:18.0
-4,-7,16:18.0
-4,-8,16:18.0
-3,-8,16:18.0
-2,-9,16:18.0
-1,-9,16:18.0
-1,-8,16:18.0
-2,-8,16:18.0
-2,-7,16:18.0
-3,-7,16:18.0
-3,-6,16:18.0
0,-8,16:18.0
0,-9,16:18.0
1,-9,16:18.0
1,-8,16:18.0
2,-9,16:18.0
3,-9,16:18.0
4,-9,16:18.0
4,-8,16:18.0
3,-8,16:18.0
5,-8,16:18.0
5,-7,16:18.0
4,-7,16:18.0
2,-8,16:18.0
3,-7,16:18.0
4,-6,16:18.0
4,-5,16:18.0
5,-6,16:18.0
5,-5,16:18.0
5,-4,16:18.0
4,-4,16:18.0
4,-3,16:18.0
5,-3,16:18.0
3,-2,16:18.0
2,-2,16:18.0
1,-1,16:18.0
0,-1,16:18.0
4,-2,16:18.0
3,-6,16:18.0
-2,-7,17:18.0
-1,-7,17:18.0
0,-7,17:18.0
1,-7,17:18.0
2,-7,17:18.0
3,-7,17:18.0
3,-6,17:18.0
2,-6,17:18.0
1,-6,17:18.0
0,-6,17:18.0
-1,-6,17:18.0
0,-8,17:18.0
1,-8,17:18.0
2,-8,17:18.0
-1,-8,17:18.0
-1,-5,17:18.0
0,-5,17:18.0
1,-5,17:18.0
1,-4,17:18.0
2,-4,17:18.0
2,-5,17:18.0
0,-4,17:18.0
-2,-6,17:18.0
-1,-4,17:18.0
-2,-5,17:18.0
0,-3,17:18.0
1,-3,17:18.0
3,-5,17:18.0
-1,-3,17:18.0
2,-3,17:18.0
-1,-2,17:18.0
0,-2,17:18.0
-2,-4,17:18.0
